Workbook

Sheet 0930
B1: 屏榮 大溪廠組合室生產人時性分析
B3: 日期 | C3: 114.09.30星期二 | E3: 訂單量 | F3: ='0930(18度C)'!D1+'0930(4度C)'!D1 -> 268017 | H3: 營業額 | I3: ='0930(18度C)'!F1+'0930(4度C)'!F1 -> 8504391
B4: 人時性 | C4: 項目 | E4: ➀ | G4: ➁ | I4: ➂ | K4: ④ | M4: ⑤
C5: 組合室 | E5: 全溫層 | G5: 4度C-各編組展開(一配) | I5: 4度C-各編組展開(二配) | K5: 18度C-各編組展開(一配) | M5: 18度C-各編組展開(二配)
C6: 排關平均 | E6: =AVERAGE(D13:O13,D27:X27) -> 449.1891 | F6: =AVERAGE(#REF!,D13:K13) -> #REF! | G6: =AVERAGE(D13:K13) -> 195.33142 | I6: =AVERAGE(L13:O13) -> 94.130676 | K6: =AVERAGE(D27:O27) -> 619.22203 | M6: =AVERAGE(P27:X27) -> 742.57374
C7: 實績平均 | E7: =AVERAGE(D14:O14,D28:X28) -> 387.95051 | F7: =AVERAGE(#REF!,D14:K14) -> #REF! | G7: =AVERAGE(D14:K14) -> 171.66999 | I7: =AVERAGE(L14:O14) -> 82.178043 | K7: =AVERAGE(D28:O28) -> 531.78779 | M7: =AVERAGE(P28:X28) -> 640.44748
C8: 達成率平均 | E8: =AVERAGE(D15:O15,D29:X29) -> 0.86391389 | F8: =AVERAGE(D15:K15,#REF!) -> #REF! | G8: =AVERAGE(D15:K15) -> 0.87148872 | I8: =AVERAGE(L15:O15) -> 0.87302069 | K8: =AVERAGE(D29:O29) -> 0.85441315 | M8: =AVERAGE(P29:X29) -> 0.86106729 | O8: ※現行日本鮮食廠以達成率80%為基本(即為現行KPI)
B10: 溫層 | D10: ➁4度C-各編組展開 | L10: ➂4度C-各編組展開
B11: 編組 | D11: 1 | E11: 2 | F11: 3 | G11: 4 | H11: 5 | I11: 6 | J11: 7 | K11: 8 | L11: 1 | M11: 2 | N11: 3 | O11: 4
D12: 便當一線 | E12: 便當二線 | F12: 涼麵一線 | G12: 涼麵二線 | H12: 涼麵三線 | I12: 自動包裝機 | J12: 自動包裝機2 | K12: 自動包裝機3 | L12: 便當一線 | M12: 便當二線 | N12: 涼麵一線 | O12: 涼麵二線
B13: 人時性 | C13: 排關 | D13: 115.15152 | E13: 78.651685 | F13: 90.625 | G13: 85.714286 | H13: 159.67742 | I13: 248.4 | J13: - | K13: 589.1 | L13: - | M13: 93.023256 | N13: 95.238095 | O13: -
C14: 實績 | D14: 102.12069 | E14: 68.817133 | F14: 78.733153 | G14: 72.885019 | H14: 138.3865 | I14: 212.79097 | J14: - | K14: 527.95647 | L14: - | M14: 81.209914 | N14: 83.146172 | O14: -
C15: 達成率 | D15: =D14/D13 -> 0.88683757 | E15: =E14/E13 -> 0.87496069 | F15: =F14/F13 -> 0.86877962 | G15: =G14/G13 -> 0.85032523 | H15: =H14/H13 -> 0.86666294 | I15: =I14/I13 -> 0.85664643 | J15: - | K15: =K14/K13 -> 0.89620857 | L15: - | M15: 0.87300657 | N15: 0.8730348 | O15: -
B16: 作業 時間 | C16: 開始 | D16: 0.25016204 | E16: 0.25 | F16: 0.25016204 | G16: 0.16666667 | H16: 0.16666667 | I16: 0.16693287 | J16: - | K16: 0.25013889 | L16: - | M16: 0.75347222 | N16: 0.70833333 | O16: -
C17: 結束 | D17: 0.55103009 | E17: 0.73333333 | F17: 0.55347222 | G17: 0.74236111 | H17: 0.71736111 | I17: 0.53680556 | J17: - | K17: 0.35694444 | L17: - | M17: 0.86319444 | N17: 0.86944444 | O17: -
B18: 配置人數 | D18: 16.5 | E18: 25.428571 | F18: 21.333333 | G18: 23.333333 | H18: 20.666667 | I18: 13.2 | J18: - | K18: 6 | L18: - | M18: 21.5 | N18: 21 | O18: -
B19: 主要應用設備 | D19: L型封口機 | E19: ET-55 | F19: ET-55 | G19: ET-55 | H19: ET-600 | I19: 伺服包裝機 | J19: 伺服包裝機 | K19: 伺服包裝機 | L19: L型封口機 | M19: ET-55 | N19: ET-55 | O19: ET-55
B20: 次要應用設備 | D20: 伺服包裝機 | H20: 伺服包裝機
B21: 備註 | H21: 涼麵+烤飯糰 | I21: 大口飯糰線 | K21: 烤飯糰+手卷
B24: 溫層 | D24: ➃18度C-各編組展開 (一配) | P24: ⑤18度C-各編組展開 (二配)
B25: 編組 | D25: 1 | E25: 2 | F25: 3 | G25: 4 | H25: 5 | I25: 6 | J25: 7 | K25: 8 | L25: 9 | M25: 10 | N25: 11 | O25: 12 | P25: 1 | Q25: 2 | R25: 3 | S25: 4 | T25: 5 | U25: 6 | V25: 7 | W25: 8 | X25: 9
D26: 便當一線 | E26: 涼麵一線 | F26: 涼麵三線 | G26: 自動包裝機 | H26: 自動包裝機2 | I26: 自動包裝機3 | J26: 味付飯糰線B | K26: (舊) 3300型飯糰線 | L26: 3000型飯糰線 | M26: (新) 3300型飯糰機 | N26: GKK3600型 飯糰機 | O26: GKK3600型 飯糰機2 | P26: 自動包裝機 | Q26: 自動包裝機2 | R26: 自動包裝機3 | S26: 味付飯糰線B | T26: (舊) 3300型飯糰線 | U26: 3000型飯糰線 | V26: (新) 3300型飯糰機 | W26: GKK3600型 飯糰機 | X26: GKK3600型 飯糰機2
B27: 人時性 | C27: 排關 | D27: 211.76471 | E27: - | F27: - | G27: 313.04348 | H27: 433.33333 | I27: - | J27: - | K27: - | L27: - | M27: 860.86957 | N27: 1061.5385 | O27: 834.78261 | P27: 282.35294 | Q27: - | R27: - | S27: - | T27: 840 | U27: - | V27: 761.53846 | W27: 872.72727 | X27: 956.25
C28: 實績 | D28: 176.87081 | E28: - | F28: - | G28: 265.1288 | H28: 368.39982 | I28: - | J28: - | K28: - | L28: - | M28: 753.14229 | N28: 898.56352 | O28: 728.6215 | P28: 239.50201 | Q28: - | R28: - | S28: - | T28: 730.94538 | U28: - | V28: 667.36709 | W28: 745.27757 | X28: 819.14534
C29: 達成率 | D29: =D28/D27 -> 0.83522329 | E29: - | F29: - | G29: =G28/G27 -> 0.84693922 | H29: =H28/H27 -> 0.85015343 | I29: - | J29: - | K29: - | L29: - | M29: =M28/M27 -> 0.87486226 | N29: =N28/N27 -> 0.84647288 | O29: =O28/O27 -> 0.87282784 | P29: =P28/P27 -> 0.8482363 | Q29: - | R29: - | S29: - | T29: =T28/T27 -> 0.87017307 | U29: - | V29: =V28/V27 -> 0.87634062 | W29: =W28/W27 -> 0.85396389 | X29: =X28/X27 -> 0.85662257
B30: 作業 時間 | C30: 開始 | D30: 0.38824074 | E30: - | F30: - | G30: 0.23015046 | H30: 0.25025463 | I30: - | J30: - | K30: - | L30: - | M30: 0.16666667 | N30: 0.16666667 | O30: 0.1669213 | P30: 0.70849537 | Q30: - | R30: - | S30: - | T30: 0.70865741 | U30: - | V30: 0.70833333 | W30: 0.70866898 | X30: 0.70833333
C31: 結束 | D31: 0.46201389 | E31: - | F31: - | G31: 0.26527778 | H31: 0.43611111 | I31: - | J31: - | K31: - | L31: - | M31: 0.47013889 | N31: 0.4869213 | O31: 0.475 | P31: 0.84166667 | Q31: - | R31: - | S31: - | T31: 0.90241898 | U31: - | V31: 0.91342593 | W31: 1.0833333 | X31: 1.1
B32: 配置人數 | D32: 17 | E32: - | F32: - | G32: 11.5 | H32: 6 | I32: - | J32: - | K32: - | L32: - | M32: 3.8333333 | N32: 3.25 | O32: 3.8333333 | P32: 12.75 | Q32: - | R32: - | S32: - | T32: 3.75 | U32: - | V32: 4.3333333 | W32: 3.6666667 | X32: 3.5555556
B33: 主要應用設備 | D33: 伺服包裝機 | E33: ET-55 | F33: ET-600 | G33: 夾心型 | H33: 伺服包裝機 | I33: 伺服包裝機 | J33: 夾心型 | K33: 3300型 | L33: 3300型 | M33: 3300型 | N33: GKK | O33: GKK | P33: 夾心型 | Q33: 伺服包裝機 | R33: 伺服包裝機 | S33: 夾心型 | T33: 3300型 | U33: 3300型 | V33: 3300型 | W33: GKK | X33: GKK
B34: 次要應用設備
B35: 備註

Sheet 0930(18度C)
A1: 大溪廠日報分析 | C1: 總生產量 | D1: =SUM(F5:F191) -> 145209 | E1: 營業額 | F1: =SUM(G5:G191) -> 2803226.5 | G1: 出勤人數 | H1: =L21+L38+L55+L72+L89+L106+L123+L140+L157+L174+L191 -> 73.472222 | I1: 產線配置圖 | L1: 生產實績 | O1: 人時性差異分析 | S1: 日報登錄 | Y1: 分析說明 | AA1: 產能差異分析
A2: 45930 | C2: 人時性 | D2: =AVERAGE(N21,N38,N55,N72,N89,N106,N123,N140,N157,N174,N191) -> 581.17856 | E2: 平均廠價 | F2: =F1/D1 -> 19.304771 | G2: 多次生產數 | H2: =COUNT(H5:H191) -> 5
A3: 線別 | B3: 品類 | C3: 品名 | E3: 廠價 | F3: 生產量 | G3: 營收 | H3: 多次 生產 | I3: 人數 | J3: 產能/時 | K3: 人時性 | L3: 人數 | M3: 產能/時 | N3: 人時性 | O3: 人數 | P3: 人時性 | Q3: 達成率 | R3: 達成率 平均 | S3: 生產時間 | U3: 換線、休息/分 | V3: 稼動時間/分 | W3: 休息時間 | Y3: (屏榮回填) | AA3: 產能/時 | AB3: 達成率 | AC3: 達成率平均
S4: 開始 | T4: 結束 | W4: 開始 | X4: 結束
A5: 便當一線 | B5: 18℃-壽司手卷 | C5: 一配海饌雙手卷 | E5: 29.85 | F5: 2554 | G5: =E5*F5 -> 76236.9 | I5: 17 | J5: 3600 | K5: =J5/I5 -> 211.76471 | L5: 17 | M5: =F5/V5*60 -> 3008.6387 | N5: =M5/L5 -> 176.97875 | O5: =L5-I5 -> 0 | P5: =N5-K5 -> -34.785956 | Q5: =N5/K5 -> 0.83573298 | R5: =Q21 -> 0.83522329 | S5: 0.38824074 | T5: 0.42361111 | U5: 5.0666667 | V5: 50.933333 | AA5: =M5-J5 -> -591.36126 | AB5: =M5/J5 -> 0.83573298 | AC5: =AB21 -> 0.83522329
B6: 18℃-壽司手卷 | C6: 一配雙饗雙手卷 | E6: 29.52 | F6: 2419 | G6: =E6*F6 -> 71408.88 | I6: 17 | J6: 3600 | K6: =J6/I6 -> 211.76471 | L6: 17 | M6: =F6/V6*60 -> 3004.9689 | N6: =M6/L6 -> 176.76288 | O6: =L6-I6 -> 0 | P6: =N6-K6 -> -35.001827 | Q6: =N6/K6 -> 0.8347136 | S6: 0.42847222 | T6: 0.46201389 | U6: 7 | V6: 48.3 | W6: 0.46201389 | X6: 0.50347222 | AA6: =M6-J6 -> -595.03106 | AB6: =M6/J6 -> 0.8347136
B21: 平均 | I21: =AVERAGE(I5:I20) -> 17 | J21: =AVERAGE(J5:J20) -> 3600 | K21: =J21/I21 -> 211.76471 | L21: =AVERAGE(L5:L20) -> 17 | M21: =AVERAGE(M5:M20) -> 3006.8038 | N21: =M21/L21 -> 176.87081 | O21: =L21-I21 -> 0 | P21: =N21-K21 -> -34.893892 | Q21: =N21/K21 -> 0.83522329 | S21: =S5 -> 0.38824074 | T21: =INDEX(T5:T20,COUNTA(T5:T20)) -> 0.46201389 | AA21: =M21-J21 -> -593.19616 | AB21: =M21/J21 -> 0.83522329
A22: 自動包裝機 | B22: 18℃-壽司手卷 | C22: 一配新之助的豆皮壽司喔 | E22: 25.52 | F22: 281 | G22: =E22*F22 -> 7171.12 | I22: 12 | J22: 3600 | K22: =J22/I22 -> 300 | L22: 12 | M22: =F22/V22*60 -> 3019.7015 | N22: =M22/L22 -> 251.64179 | O22: =L22-I22 -> 0 | P22: =N22-K22 -> -48.358209 | Q22: =N22/K22 -> 0.83880597 | R22: =Q38 -> 0.84693922 | S22: 0.23015046 | T22: 0.23402778 | U22: 8.25 | V22: 5.5833333 | AA22: =M22-J22 -> -580.29851 | AB22: =M22/J22 -> 0.83880597 | AC22: =AB38 -> 0.84693922
B23: 18℃-壽司手卷 | C23: 一配長野稻荷壽司 | E23: 25.64 | F23: 1947 | G23: =E23*F23 -> 49921.08 | I23: 11 | J23: 3600 | K23: =J23/I23 -> 327.27273 | L23: 11 | M23: =F23/V23*60 -> 3078.2609 | N23: =M23/L23 -> 279.8419 | O23: =L23-I23 -> 0 | P23: =N23-K23 -> -47.43083 | Q23: =N23/K23 -> 0.85507246 | S23: 0.23892361 | T23: 0.26527778 | U23: 7.05 | V23: 37.95 | AA23: =M23-J23 -> -521.73913 | AB23: =M23/J23 -> 0.85507246
B38: 平均 | I38: =AVERAGE(I22:I37) -> 11.5 | J38: =AVERAGE(J22:J37) -> 3600 | K38: =J38/I38 -> 313.04348 | L38: =AVERAGE(L22:L37) -> 11.5 | M38: =AVERAGE(M22:M37) -> 3048.9812 | N38: =M38/L38 -> 265.1288 | O38: =L38-I38 -> 0 | P38: =N38-K38 -> -47.91468 | Q38: =N38/K38 -> 0.84693922 | S38: =S22 -> 0.23015046 | T38: =INDEX(T22:T37,COUNTA(T22:T37)) -> 0.26527778 | AA38: =M38-J38 -> -551.01882 | AB38: =M38/J38 -> 0.84693922
A39: 自動包裝機2 | B39: 18℃-壽司手卷 | C39: 一配芝麻海苔香鬆細卷 | E39: 14.06 | F39: 1025 | G39: =E39*F39 -> 14411.5 | I39: 6 | J39: 2600 | K39: =J39/I39 -> 433.33333 | L39: 6 | M39: =F39/V39*60 -> 2225.573 | N39: =M39/L39 -> 370.92883 | O39: =L39-I39 -> 0 | P39: =N39-K39 -> -62.404503 | Q39: =N39/K39 -> 0.85598961 | R39: =Q55 -> 0.85015343 | S39: 0.25025463 | T39: 0.26944444 | V39: 27.633333 | AA39: =M39-J39 -> -374.42702 | AB39: =M39/J39 -> 0.85598961 | AC39: =AB55 -> 0.85015343
B40: 18℃-壽司手卷 | C40: 一配香濃起司蟹風味棒細卷 | E40: 17.73 | F40: 3532 | G40: =E40*F40 -> 62622.36 | I40: 6 | J40: 2600 | K40: =J40/I40 -> 433.33333 | L40: 6 | M40: =F40/V40*60 -> 2266.9282 | N40: =M40/L40 -> 377.82136 | O40: =L40-I40 -> 0 | P40: =N40-K40 -> -55.511975 | Q40: =N40/K40 -> 0.87189544 | S40: 0.27222222 | T40: 0.3371412 | U40: 4 | V40: 93.483333 | AA40: =M40-J40 -> -333.07185 | AB40: =M40/J40 -> 0.87189544
B41: 18℃-壽司手卷 | C41: 一配經典鮪魚沙拉細卷 | E41: 13.58 | F41: 4919 | G41: =E41*F41 -> 66800.02 | I41: 6 | J41: 2600 | K41: =J41/I41 -> 433.33333 | L41: 6 | M41: =F41/V41*60 -> 2138.6957 | N41: =M41/L41 -> 356.44928 | O41: =L41-I41 -> 0 | P41: =N41-K41 -> -76.884058 | Q41: =N41/K41 -> 0.82257525 | S41: 0.34027778 | T41: 0.43611111 | U41: 4.5166667 | V41: 138 | AA41: =M41-J41 -> -461.30435 | AB41: =M41/J41 -> 0.82257525
B55: 平均 | I55: =AVERAGE(I39:I54) -> 6 | J55: =AVERAGE(J39:J54) -> 2600 | K55: =J55/I55 -> 433.33333 | L55: =AVERAGE(L39:L54) -> 6 | M55: =AVERAGE(M39:M54) -> 2210.3989 | N55: =M55/L55 -> 368.39982 | O55: =L55-I55 -> 0 | P55: =N55-K55 -> -64.933512 | Q55: =N55/K55 -> 0.85015343 | S55: =S39 -> 0.25025463 | T55: =INDEX(T39:T54,COUNTA(T39:T54)) -> 0.43611111 | AA55: =M55-J55 -> -389.60107 | AB55: =M55/J55 -> 0.85015343
A56: (新) 3300型飯糰機 | B56: 18℃-飯糰 | C56: 一配三杯辣海瓜子飯糰 | E56: 21.45 | F56: 1047 | G56: =E56*F56 -> 22458.15 | I56: 3 | J56: 3300 | K56: =J56/I56 -> 1100 | L56: 3 | M56: =F56/V56*60 -> 2848.9796 | N56: =M56/L56 -> 949.65986 | O56: =L56-I56 -> 0 | P56: =N56-K56 -> -150.34014 | Q56: =N56/K56 -> 0.86332715 | R56: =Q72 -> 0.87486226 | S56: 0.16666667 | T56: 0.18197917 | V56: 22.05 | AA56: =M56-J56 -> -451.02041 | AB56: =M56/J56 -> 0.86332715 | AC56: =AB72 -> 0.87486226
B57: 18℃-飯糰 | C57: 一配哇沙米魚卵沙拉飯糰 | E57: 15.71 | F57: 2527 | G57: =E57*F57 -> 39699.17 | I57: 3 | J57: 3300 | K57: =J57/I57 -> 1100 | L57: 3 | M57: =F57/V57*60 -> 2887.0835 | N57: =M57/L57 -> 962.36116 | O57: =L57-I57 -> 0 | P57: =N57-K57 -> -137.63884 | Q57: =N57/K57 -> 0.87487378 | S57: 0.1871412 | T57: 0.22361111 | U57: 7.4333333 | V57: 52.516667 | AA57: =M57-J57 -> -412.91653 | AB57: =M57/J57 -> 0.87487378
B58: 18℃-飯糰 | C58: 一配壹號醬炙烤牛飯糰 | E58: 22.28 | F58: 1514 | G58: =E58*F58 -> 33731.92 | I58: 5 | J58: 3300 | K58: =J58/I58 -> 660 | L58: 5 | M58: =F58/V58*60 -> 2858.1017 | N58: =M58/L58 -> 571.62035 | O58: =L58-I58 -> 0 | P58: =N58-K58 -> -88.379654 | Q58: =N58/K58 -> 0.86609143 | S58: 0.22792824 | T58: 0.25 | U58: 6.2166667 | V58: 31.783333 | AA58: =M58-J58 -> -441.89827 | AB58: =M58/J58 -> 0.86609143
B59: 18℃-飯糰 | C59: 一配鹽蔥燒肉飯糰 | E59: 17.89 | F59: 4022 | G59: =E59*F59 -> 71953.58 | I59: 4 | J59: 3300 | K59: =J59/I59 -> 825 | L59: 4 | M59: =F59/V59*60 -> 2905.1364 | N59: =M59/L59 -> 726.28411 | O59: =L59-I59 -> 0 | P59: =N59-K59 -> -98.715891 | Q59: =N59/K59 -> 0.88034437 | S59: 0.25347222 | T59: 0.31115741 | U59: 5 | V59: 83.066667 | AA59: =M59-J59 -> -394.86356 | AB59: =M59/J59 -> 0.88034437
B60: 18℃-飯糰 | C60: 一配照燒雞肉飯糰 | E60: 21.45 | F60: 4716 | G60: =E60*F60 -> 101158.2 | I60: 4 | J60: 3300 | K60: =J60/I60 -> 825 | L60: 4 | M60: =F60/V60*60 -> 2909.6144 | N60: =M60/L60 -> 727.4036 | O60: =L60-I60 -> 0 | P60: =N60-K60 -> -97.596401 | Q60: =N60/K60 -> 0.88170133 | S60: 0.31597222 | T60: 0.38350694 | U60: 6.9333333 | V60: 97.25 | AA60: =M60-J60 -> -390.3856 | AB60: =M60/J60 -> 0.88170133
B61: 18℃-飯糰 | C61: 一配雞肉飯飯糰 | E61: 16.66 | F61: 5677 | G61: =E61*F61 -> 94578.82 | I61: 4 | J61: 3300 | K61: =J61/I61 -> 825 | L61: 4 | M61: =F61/V61*60 -> 2913.3571 | N61: =M61/L61 -> 728.33927 | O61: =L61-I61 -> 0 | P61: =N61-K61 -> -96.660727 | Q61: =N61/K61 -> 0.88283548 | S61: 0.38894676 | T61: 0.47013889 | U61: 7.8333333 | V61: 116.91667 | AA61: =M61-J61 -> -386.64291 | AB61: =M61/J61 -> 0.88283548
B72: 平均 | I72: =AVERAGE(I56:I71) -> 3.8333333 | J72: =AVERAGE(J56:J71) -> 3300 | K72: =J72/I72 -> 860.86957 | L72: =AVERAGE(L56:L71) -> 3.8333333 | M72: =AVERAGE(M56:M71) -> 2887.0455 | N72: =M72/L72 -> 753.14229 | O72: =L72-I72 -> 0 | P72: =N72-K72 -> -107.72727 | Q72: =N72/K72 -> 0.87486226 | S72: =S56 -> 0.16666667 | T72: =INDEX(T56:T71,COUNTA(T56:T71)) -> 0.47013889 | AA72: =M72-J72 -> -412.95455 | AB72: =M72/J72 -> 0.87486226
A73: GKK3600型 飯糰機 | B73: 18℃-飯糰 | C73: 一配蔬食鮪魚飯糰 | E73: 18.18 | F73: 2190 | G73: =E73*F73 -> 39814.2 | I73: 3 | J73: 3600 | K73: =J73/I73 -> 1200 | L73: 3 | M73: =F73/V73*60 -> 3027.6498 | N73: =M73/L73 -> 1009.2166 | O73: =L73-I73 -> 0 | P73: =N73-K73 -> -190.78341 | Q73: =N73/K73 -> 0.84101382 | R73: =Q89 -> 0.84647288 | S73: 0.16666667 | T73: 0.19680556 | V73: 43.4 | AA73: =M73-J73 -> -572.35023 | AB73: =M73/J73 -> 0.84101382 | AC73: =AB89 -> 0.84647288
B74: 18℃-飯糰 | C74: 一配明太子龍蝦風味沙拉飯糰 | E74: 18.18 | F74: 2815 | G74: =E74*F74 -> 51176.7 | I74: 3 | J74: 3600 | K74: =J74/I74 -> 1200 | L74: 3 | M74: =F74/V74*60 -> 3035.0404 | N74: =M74/L74 -> 1011.6801 | O74: =L74-I74 -> 0 | P74: =N74-K74 -> -188.31986 | Q74: =N74/K74 -> 0.84306679 | S74: 0.20927083 | T74: 0.24791667 | U74: 17.95 | V74: 55.65 | AA74: =M74-J74 -> -564.95957 | AB74: =M74/J74 -> 0.84306679
B75: 18℃-飯糰 | C75: 一配經典肉鬆飯糰 | E75: 13.25 | F75: 6809 | G75: =E75*F75 -> 90219.25 | I75: 4 | J75: 3000 | K75: =J75/I75 -> 750 | L75: 4 | M75: =F75/V75*60 -> 2580.2526 | N75: =M75/L75 -> 645.06316 | O75: =L75-I75 -> 0 | P75: =N75-K75 -> -104.93684 | Q75: =N75/K75 -> 0.86008421 | S75: 0.25972222 | T75: 0.36967593 | U75: 17 | V75: 158.33333 | AA75: =M75-J75 -> -419.74737 | AB75: =M75/J75 -> 0.86008421
B76: 18℃-飯糰 | C76: 一配鮪魚飯糰 | E76: 14.28 | F76: 7098 | G76: =E76*F76 -> 101359.44 | I76: 3 | J76: 3600 | K76: =J76/I76 -> 1200 | L76: 3 | M76: =F76/V76*60 -> 3038.3829 | N76: =M76/L76 -> 1012.7943 | O76: =L76-I76 -> 0 | P76: =N76-K76 -> -187.20571 | Q76: =N76/K76 -> 0.84399524 | S76: 0.38958333 | T76: 0.4869213 | U76: 28.666667 | V76: 140.16667 | AA76: =M76-J76 -> -561.61712 | AB76: =M76/J76 -> 0.84399524
B89: 平均 | I89: =AVERAGE(I73:I88) -> 3.25 | J89: =AVERAGE(J73:J88) -> 3450 | K89: =J89/I89 -> 1061.5385 | L89: =AVERAGE(L73:L88) -> 3.25 | M89: =AVERAGE(M73:M88) -> 2920.3314 | N89: =M89/L89 -> 898.56352 | O89: =L89-I89 -> 0 | P89: =N89-K89 -> -162.97495 | Q89: =N89/K89 -> 0.84647288 | S89: =S73 -> 0.16666667 | T89: =INDEX(T73:T88,COUNTA(T73:T88)) -> 0.4869213 | AA89: =M89-J89 -> -529.66857 | AB89: =M89/J89 -> 0.84647288
A90: GKK3600型 飯糰機2 | B90: 18℃-飯糰 | C90: 一配熟成紅鮭飯糰 | E90: 25.03 | F90: 2414 | G90: =E90*F90 -> 60422.42 | I90: 4 | J90: 3300 | K90: =J90/I90 -> 825 | L90: 4 | M90: =F90/V90*60 -> 2860.5662 | N90: =M90/L90 -> 715.14154 | O90: =L90-I90 -> 0 | P90: =N90-K90 -> -109.85846 | Q90: =N90/K90 -> 0.86683823 | R90: =Q106 -> 0.87282784 | S90: 0.1669213 | T90: 0.20208333 | V90: 50.633333 | AA90: =M90-J90 -> -439.43384 | AB90: =M90/J90 -> 0.86683823 | AC90: =AB106 -> 0.87282784
B91: 18℃-飯糰 | C91: 一配博多明太子奶油飯糰 | E91: 25.45 | F91: 2640 | G91: =E91*F91 -> 67188 | I91: 4 | J91: 3300 | K91: =J91/I91 -> 825 | L91: 4 | M91: =F91/V91*60 -> 2872.1668 | N91: =M91/L91 -> 718.0417 | O91: =L91-I91 -> 0 | P91: =N91-K91 -> -106.9583 | Q91: =N91/K91 -> 0.87035358 | S91: 0.21319444 | T91: 0.25149306 | U91: 16 | V91: 55.15 | AA91: =M91-J91 -> -427.83318 | AB91: =M91/J91 -> 0.87035358
B92: 18℃-飯糰 | C92: 一配照燒鰤魚大根飯糰 | E92: 26.73 | F92: 1577 | G92: =E92*F92 -> 42153.21 | I92: 4 | J92: 3300 | K92: =J92/I92 -> 825 | L92: 4 | M92: =F92/V92*60 -> 2840.02 | N92: =M92/L92 -> 710.005 | O92: =L92-I92 -> 0 | P92: =N92-K92 -> -114.995 | Q92: =N92/K92 -> 0.86061212 | S92: 0.26527778 | T92: 0.28841435 | U92: 19.85 | V92: 33.316667 | AA92: =M92-J92 -> -459.97999 | AB92: =M92/J92 -> 0.86061212
B93: 18℃-飯糰 | C93: 一配北海道秋鮭親子飯糰 | E93: 24.82 | F93: 2555 | G93: =E93*F93 -> 63415.1 | I93: 4 | J93: 3300 | K93: =J93/I93 -> 825 | L93: 4 | M93: =F93/V93*60 -> 2866.3135 | N93: =M93/L93 -> 716.57837 | O93: =L93-I93 -> 0 | P93: =N93-K93 -> -108.42163 | Q93: =N93/K93 -> 0.86857985 | S93: 0.30138889 | T93: 0.33853009 | U93: 18.683333 | V93: 53.483333 | AA93: =M93-J93 -> -433.68651 | AB93: =M93/J93 -> 0.86857985
B94: 18℃-飯糰 | C94: 一配筋子銀鮭飯糰 | E94: 30 | F94: 3339 | G94: =E94*F94 -> 100170 | I94: 4 | J94: 3000 | K94: =J94/I94 -> 750 | L94: 4 | M94: =F94/V94*60 -> 2657.6166 | N94: =M94/L94 -> 664.40416 | O94: =L94-I94 -> 0 | P94: =N94-K94 -> -85.595843 | Q94: =N94/K94 -> 0.88587221 | S94: 0.35138889 | T94: 0.40373843 | U94: 18.516667 | V94: 75.383333 | AA94: =M94-J94 -> -342.38337 | AB94: =M94/J94 -> 0.88587221
B95: 18℃-飯糰 | C95: 一配贅沢鮭魚肚飯糰 | E95: 30 | F95: 3900 | G95: =E95*F95 -> 117000 | I95: 3 | J95: 3000 | K95: =J95/I95 -> 1000 | L95: 3 | M95: =F95/V95*60 -> 2661.6114 | N95: =M95/L95 -> 887.20379 | O95: =L95-I95 -> 0 | P95: =N95-K95 -> -112.79621 | Q95: =N95/K95 -> 0.88720379 | S95: 0.41394676 | T95: 0.475 | U95: 14.7 | V95: 87.916667 | AA95: =M95-J95 -> -338.38863 | AB95: =M95/J95 -> 0.88720379
B106: 平均 | I106: =AVERAGE(I90:I105) -> 3.8333333 | J106: =AVERAGE(J90:J105) -> 3200 | K106: =J106/I106 -> 834.78261 | L106: =AVERAGE(L90:L105) -> 3.8333333 | M106: =AVERAGE(M90:M105) -> 2793.0491 | N106: =M106/L106 -> 728.6215 | O106: =L106-I106 -> 0 | P106: =N106-K106 -> -106.16111 | Q106: =N106/K106 -> 0.87282784 | S106: =S90 -> 0.1669213 | T106: =INDEX(T90:T105,COUNTA(T90:T105)) -> 0.475 | AA106: =M106-J106 -> -406.95092 | AB106: =M106/J106 -> 0.87282784
A107: 自動包裝機 (二配) | B107: 18℃-飯糰 | C107: 二配兔兔昆布飯糰 | E107: 13.42 | F107: 1438 | G107: =E107*F107 -> 19297.96 | I107: 6 | J107: 3600 | K107: =J107/I107 -> 600 | L107: 6 | M107: =F107/V107*60 -> 3107.3229 | N107: =M107/L107 -> 517.88715 | O107: =L107-I107 -> 0 | P107: =N107-K107 -> -82.112845 | Q107: =N107/K107 -> 0.86314526 | R107: =Q123 -> 0.8482363 | S107: 0.70849537 | T107: 0.72777778 | V107: 27.766667 | AA107: =M107-J107 -> -492.67707 | AB107: =M107/J107 -> 0.86314526 | AC107: =AB123 -> 0.8482363
B108: 18℃-壽司手卷 | C108: 二配長野稻荷壽司 | E108: 25.64 | F108: 2160 | G108: =E108*F108 -> 55382.4 | I108: 11 | J108: 3600 | K108: =J108/I108 -> 327.27273 | L108: 11 | M108: =F108/V108*60 -> 3084.4903 | N108: =M108/L108 -> 280.40821 | O108: =L108-I108 -> 0 | P108: =N108-K108 -> -46.86452 | Q108: =N108/K108 -> 0.85680286 | S108: 0.73125 | T108: 0.76042824 | U108: 5 | V108: 42.016667 | AA108: =M108-J108 -> -515.50972 | AB108: =M108/J108 -> 0.85680286
B109: 18℃-壽司手卷 | C109: 二配雙饗雙手卷 | E109: 29.52 | F109: 2574 | G109: =E109*F109 -> 75984.48 | I109: 17 | J109: 3600 | K109: =J109/I109 -> 211.76471 | L109: 17 | M109: =F109/V109*60 -> 3008.5714 | N109: =M109/L109 -> 176.97479 | O109: =L109-I109 -> 0 | P109: =N109-K109 -> -34.789916 | Q109: =N109/K109 -> 0.83571429 | S109: 0.76388889 | T109: 0.79953704 | U109: 4.9833333 | V109: 51.333333 | AA109: =M109-J109 -> -591.42857 | AB109: =M109/J109 -> 0.83571429
B110: 18℃-壽司手卷 | C110: 二配海饌雙手卷 | E110: 29.85 | F110: 2650 | G110: =E110*F110 -> 79102.5 | I110: 17 | J110: 3600 | K110: =J110/I110 -> 211.76471 | L110: 17 | M110: =F110/V110*60 -> 3014.218 | N110: =M110/L110 -> 177.30694 | O110: =L110-I110 -> 0 | P110: =N110-K110 -> -34.457764 | Q110: =N110/K110 -> 0.83728278 | S110: 0.80503472 | T110: 0.84166667 | U110: 7.9166667 | V110: 52.75 | AA110: =M110-J110 -> -585.78199 | AB110: =M110/J110 -> 0.83728278
B123: 平均 | I123: =AVERAGE(I107:I122) -> 12.75 | J123: =AVERAGE(J107:J122) -> 3600 | K123: =J123/I123 -> 282.35294 | L123: =AVERAGE(L107:L122) -> 12.75 | M123: =AVERAGE(M107:M122) -> 3053.6507 | N123: =M123/L123 -> 239.50201 | O123: =L123-I123 -> 0 | P123: =N123-K123 -> -42.850928 | Q123: =N123/K123 -> 0.8482363 | S123: =S107 -> 0.70849537 | T123: =INDEX(T107:T122,COUNTA(T107:T122)) -> 0.84166667 | AA123: =M123-J123 -> -546.34934 | AB123: =M123/J123 -> 0.8482363
A124: (舊) 3300型飯糰線 (二配) | B124: 18℃-飯糰 | C124: 二配大飯糰韓式炸雞 | E124: 27.58 | F124: 1484 | G124: =E124*F124 -> 40928.72 | I124: 4 | J124: 3000 | K124: =J124/I124 -> 750 | L124: 4 | M124: =F124/V124*60 -> 2578.3784 | N124: =M124/L124 -> 644.59459 | O124: =L124-I124 -> 0 | P124: =N124-K124 -> -105.40541 | Q124: =N124/K124 -> 0.85945946 | R124: =Q140 -> 0.87017307 | S124: 0.70865741 | T124: 0.73263889 | V124: 34.533333 | AA124: =M124-J124 -> -421.62162 | AB124: =M124/J124 -> 0.85945946 | AC124: =AB140 -> 0.87017307
B125: 18℃-飯糰 | C125: 二配大飯糰春川風味辣炒雞 | E125: 24.15 | F125: 1168 | G125: =E125*F125 -> 28207.2 | I125: 4 | J125: 3000 | K125: =J125/I125 -> 750 | L125: 4 | M125: =F125/V125*60 -> 2570.1711 | N125: =M125/L125 -> 642.54279 | O125: =L125-I125 -> 0 | P125: =N125-K125 -> -107.45721 | Q125: =N125/K125 -> 0.85672372 | S125: 0.7375 | T125: 0.75643519 | U125: 7 | V125: 27.266667 | AA125: =M125-J125 -> -429.82885 | AB125: =M125/J125 -> 0.85672372
...

Sheet 0930(4度C)
A1: 大溪廠日報分析 | C1: 總生產量 | D1: =SUM(F5:F157) -> 122808 | E1: 營業額 | F1: =SUM(G5:G157) -> 5701164.5 | G1: 出勤人數 | H1: =L21+L38+L55+L72+L89+L106+L123+L140+L157 -> 168.9619 | I1: 產線配置圖 | L1: 生產實績 | O1: 人時性差異分析 | S1: 日報登錄 | Y1: 分析說明 | AA1: 產能差異分析
A2: 45930 | C2: 人時性 | D2: =AVERAGE(N21,N38,N55,N72,N89,N106,N123,N140,N157) -> 151.78289 | E2: 平均廠價 | F2: =F1/D1 -> 46.423396 | G2: 多次生產數 | H2: =COUNT(H5:H157) -> 3
A3: 線別 | B3: 品類 | C3: 品名 | E3: 廠價 | F3: 生產量 | G3: 營收 | H3: 多次 生產 | I3: 人數 | J3: 產能/時 | K3: 人時性 | L3: 人數 | M3: 產能/時 | N3: 人時性 | O3: 人數 | P3: 人時性 | Q3: 達成率 | R3: 達成率 平均 | S3: 生產時間 | U3: 換線、休息/分 | V3: 稼動時間/分 | W3: 休息時間 | Y3: (屏榮回填) | AA3: 產能/時 | AB3: 達成率 | AC3: 達成率平均
S4: 開始 | T4: 結束 | W4: 開始 | X4: 結束
A5: 便當一線 | B5: 微波小吃 | C5: 日式茶碗蒸 | E5: 19.7 | F5: 3456 | G5: =E5*F5 -> 68083.2 | I5: 13 | J5: 1200 | K5: =J5/I5 -> 92.307692 | L5: 13 | M5: =F5/V5*60 -> 1070.1531 | N5: =M5/L5 -> 82.31947 | O5: =L5-I5 -> 0 | P5: =N5-K5 -> -9.9882227 | Q5: =N5/K5 -> 0.89179425 | R5: =Q21 -> 0.88683757 | S5: 0.25016204 | T5: 0.38472222 | V5: 193.76667 | AA5: =M5-J5 -> -129.84689 | AB5: =M5/J5 -> 0.89179425 | AC5: =AB21 -> 0.88683757
B6: 4℃-飯糰 | C6: 麻油雞飯糰 | E6: 29.97 | F6: 2625 | G6: =E6*F6 -> 78671.25 | I6: 20 | J6: 2600 | K6: =J6/I6 -> 130 | L6: 20 | M6: =F6/V6*60 -> 2299.8296 | N6: =M6/L6 -> 114.99148 | O6: =L6-I6 -> 0 | P6: =N6-K6 -> -15.008518 | Q6: =N6/K6 -> 0.88454986 | S6: 0.50347222 | T6: 0.55103009 | U6: 59.7 | V6: 68.483333 | AA6: =M6-J6 -> -300.17036 | AB6: =M6/J6 -> 0.88454986
B21: 平均 | I21: =AVERAGE(I5:I20) -> 16.5 | J21: =AVERAGE(J5:J20) -> 1900 | K21: =J21/I21 -> 115.15152 | L21: =AVERAGE(L5:L20) -> 16.5 | M21: =AVERAGE(M5:M20) -> 1684.9914 | N21: =M21/L21 -> 102.12069 | O21: =L21-I21 -> 0 | P21: =N21-K21 -> -13.030826 | Q21: =N21/K21 -> 0.88683757 | S21: =S5 -> 0.25016204 | T21: =INDEX(T5:T20,COUNTA(T5:T20)) -> 0.55103009 | AA21: =M21-J21 -> -215.00863 | AB21: =M21/J21 -> 0.88683757
A22: 便當二線 | B22: 微波主食 | C22: 柚見極炙烤牛 | E22: 57.3 | F22: 956 | G22: =E22*F22 -> 54778.8 | I22: 26 | J22: 2000 | K22: =J22/I22 -> 76.923077 | L22: 26 | M22: =F22/V22*60 -> 1722.5225 | N22: =M22/L22 -> 66.250866 | O22: =L22-I22 -> 0 | P22: =N22-K22 -> -10.672211 | Q22: =N22/K22 -> 0.86126126 | R22: =Q38 -> 0.87496069 | S22: 0.25 | T22: 0.273125 | V22: 33.3 | AA22: =M22-J22 -> -277.47748 | AB22: =M22/J22 -> 0.86126126 | AC22: =AB38 -> 0.87496069
B23: 微波主食 | C23: 糖燻野郎三十天熟成牛飯 | E23: 56.77 | F23: 4383 | G23: =E23*F23 -> 248822.91 | I23: 26 | J23: 2000 | K23: =J23/I23 -> 76.923077 | L23: 26 | M23: =F23/V23*60 -> 1765.9541 | N23: =M23/L23 -> 67.921312 | O23: =L23-I23 -> 0 | P23: =N23-K23 -> -9.0017649 | Q23: =N23/K23 -> 0.88297706 | S23: 0.27853009 | T23: 0.38194444 | U23: 7.7833333 | V23: 148.91667 | AA23: =M23-J23 -> -234.04589 | AB23: =M23/J23 -> 0.88297706
B24: 微波主食 | C24: 蒜蒜燒豚飯 | E24: 51.86 | F24: 1524 | G24: =E24*F24 -> 79034.64 | I24: 26 | J24: 2000 | K24: =J24/I24 -> 76.923077 | L24: 26 | M24: =F24/V24*60 -> 1732.9122 | N24: =M24/L24 -> 66.650469 | O24: =L24-I24 -> 0 | P24: =N24-K24 -> -10.272608 | Q24: =N24/K24 -> 0.8664561 | S24: 0.38488426 | T24: 0.42152778 | U24: 4.2333333 | V24: 52.766667 | AA24: =M24-J24 -> -267.08781 | AB24: =M24/J24 -> 0.8664561
B25: 微波主食 | C25: 姨次滿足熟成牛豚雙拼 | E25: 57.3 | F25: 1376 | G25: =E25*F25 -> 78844.8 | I25: 25 | J25: 2000 | K25: =J25/I25 -> 80 | L25: 25 | M25: =F25/V25*60 -> 1731.4226 | N25: =M25/L25 -> 69.256903 | O25: =L25-I25 -> 0 | P25: =N25-K25 -> -10.743097 | Q25: =N25/K25 -> 0.86571129 | S25: 0.4266088 | T25: 0.45972222 | U25: 7.3166667 | V25: 47.683333 | AA25: =M25-J25 -> -268.57742 | AB25: =M25/J25 -> 0.86571129
B26: 便當 | C26: 健身G肉餐盒 | E26: 59.52 | F26: 1015 | G26: =E26*F26 -> 60412.8 | H26: 2 | I26: 25 | J26: 2000 | K26: =J26/I26 -> 80 | L26: 25 | M26: =F26/V26*60 -> 1766.0706 | N26: =M26/L26 -> 70.642823 | O26: =L26-I26 -> 0 | P26: =N26-K26 -> -9.3571774 | Q26: =N26/K26 -> 0.88303528 | S26: 0.46319444 | T26: 0.4871412 | U26: 5 | V26: 34.483333 | W26: 0.4871412 | X26: 0.52731481 | AA26: =M26-J26 -> -233.92943 | AB26: =M26/J26 -> 0.88303528
B27: 便當 | C27: 嫩烤香料雞胸排蔬滿盒 | E27: 77.34 | F27: 3305 | G27: =E27*F27 -> 255608.7 | I27: 25 | J27: 2000 | K27: =J27/I27 -> 80 | L27: 25 | M27: =F27/V27*60 -> 1760.0592 | N27: =M27/L27 -> 70.402367 | O27: =L27-I27 -> 0 | P27: =N27-K27 -> -9.5976331 | Q27: =N27/K27 -> 0.88002959 | S27: 0.52731481 | T27: 0.60555556 | U27: 57.85 | V27: 112.66667 | AA27: =M27-J27 -> -239.94083 | AB27: =M27/J27 -> 0.88002959
B28: 便當 | C28: 健身G肉餐盒 | E28: 59.52 | F28: 5223 | G28: =E28*F28 -> 310872.96 | I28: 25 | J28: 2000 | K28: =J28/I28 -> 80 | L28: 25 | M28: =F28/V28*60 -> 1770.5085 | N28: =M28/L28 -> 70.820339 | O28: =L28-I28 -> 0 | P28: =N28-K28 -> -9.179661 | Q28: =N28/K28 -> 0.88525424 | S28: 0.61041667 | T28: 0.73333333 | U28: 7 | V28: 177 | AA28: =M28-J28 -> -229.49153 | AB28: =M28/J28 -> 0.88525424
AQ29: =AI8 -> 0
B38: 平均 | I38: =AVERAGE(I22:I37) -> 25.428571 | J38: =AVERAGE(J22:J37) -> 2000 | K38: =J38/I38 -> 78.651685 | L38: =AVERAGE(L22:L37) -> 25.428571 | M38: =AVERAGE(M22:M37) -> 1749.9214 | N38: =M38/L38 -> 68.817133 | O38: =L38-I38 -> 0 | P38: =N38-K38 -> -9.8345527 | Q38: =N38/K38 -> 0.87496069 | S38: =S22 -> 0.25 | T38: =INDEX(T22:T37,COUNTA(T22:T37)) -> 0.73333333 | AA38: =M38-J38 -> -250.07863 | AB38: =M38/J38 -> 0.87496069
A39: 涼麵一線 | B39: 熱食義麵 | C39: 金沙豆腐細扁麵 | E39: 49.52 | F39: 1671 | G39: =E39*F39 -> 82747.92 | I39: 24 | J39: 2000 | K39: =J39/I39 -> 83.333333 | L39: 24 | M39: =F39/V39*60 -> 1735.603 | N39: =M39/L39 -> 72.316792 | O39: =L39-I39 -> 0 | P39: =N39-K39 -> -11.016542 | Q39: =N39/K39 -> 0.8678015 | R39: =Q55 -> 0.86877962 | S39: 0.25016204 | T39: 0.29027778 | V39: 57.766667 | AA39: =M39-J39 -> -264.397 | AB39: =M39/J39 -> 0.8678015 | AC39: =AB55 -> 0.86877962
B40: 便當 | C40: 紅燒肉日式高湯咖哩便當 | E40: 65.84 | F40: 964 | G40: =E40*F40 -> 63469.76 | I40: 21 | J40: 2000 | K40: =J40/I40 -> 95.238095 | L40: 21 | M40: =F40/V40*60 -> 1725.7086 | N40: =M40/L40 -> 82.1766 | O40: =L40-I40 -> 0 | P40: =N40-K40 -> -13.061495 | Q40: =N40/K40 -> 0.8628543 | S40: 0.2933912 | T40: 0.31666667 | U40: 4.4833333 | V40: 33.516667 | AA40: =M40-J40 -> -274.2914 | AB40: =M40/J40 -> 0.8628543
B41: 微波小吃 | C41: 越式牛肉寬粉 | E41: 51.82 | F41: 1940 | G41: =E41*F41 -> 100530.8 | I41: 22 | J41: 1800 | K41: =J41/I41 -> 81.818182 | L41: 22 | M41: =F41/V41*60 -> 1574.7463 | N41: =M41/L41 -> 71.579379 | O41: =L41-I41 -> 0 | P41: =N41-K41 -> -10.238803 | Q41: =N41/K41 -> 0.87485908 | S41: 0.31950231 | T41: 0.37083333 | U41: 4.0833333 | V41: 73.916667 | AA41: =M41-J41 -> -225.25366 | AB41: =M41/J41 -> 0.87485908
B42: 微波小吃 | C42: 擔仔炊粉湯 | E42: 45.66 | F42: 1450 | G42: =E42*F42 -> 66207 | I42: 20 | J42: 1800 | K42: =J42/I42 -> 90 | L42: 20 | M42: =F42/V42*60 -> 1563.8107 | N42: =M42/L42 -> 78.190533 | O42: =L42-I42 -> 0 | P42: =N42-K42 -> -11.809467 | Q42: =N42/K42 -> 0.8687837 | S42: 0.37456019 | T42: 0.41319444 | U42: 5.3666667 | V42: 55.633333 | AA42: =M42-J42 -> -236.18933 | AB42: =M42/J42 -> 0.8687837
B43: 微波主食 | C43: 妮妮家漢堡排 | E43: 57.3 | F43: 1815 | G43: =E43*F43 -> 103999.5 | I43: 20 | J43: 2000 | K43: =J43/I43 -> 100 | L43: 20 | M43: =F43/V43*60 -> 1737.766 | N43: =M43/L43 -> 86.888298 | O43: =L43-I43 -> 0 | P43: =N43-K43 -> -13.111702 | Q43: =N43/K43 -> 0.86888298 | S43: 0.41828704 | T43: 0.46180556 | U43: 7.3333333 | V43: 62.666667 | W43: 0.46180556 | X43: 0.50364583 | AA43: =M43-J43 -> -262.23404 | AB43: =M43/J43 -> 0.86888298
B44: 便當 | C44: 經典滷肉飯 | E44: 47.37 | F44: 2081 | G44: =E44*F44 -> 98576.97 | I44: 21 | J44: 2000 | K44: =J44/I44 -> 95.238095 | L44: 21 | M44: =F44/V44*60 -> 1740.2091 | N44: =M44/L44 -> 82.867098 | O44: =L44-I44 -> 0 | P44: =N44-K44 -> -12.370997 | Q44: =N44/K44 -> 0.87010453 | S44: 0.50364583 | T44: 0.55347222 | U44: 60.25 | V44: 71.75 | AA44: =M44-J44 -> -259.79094 | AB44: =M44/J44 -> 0.87010453
B55: 平均 | I55: =AVERAGE(I39:I54) -> 21.333333 | J55: =AVERAGE(J39:J54) -> 1933.3333 | K55: =J55/I55 -> 90.625 | L55: =AVERAGE(L39:L54) -> 21.333333 | M55: =AVERAGE(M39:M54) -> 1679.6406 | N55: =M55/L55 -> 78.733153 | O55: =L55-I55 -> 0 | P55: =N55-K55 -> -11.891847 | Q55: =N55/K55 -> 0.86877962 | S55: =S39 -> 0.25016204 | T55: =INDEX(T39:T54,COUNTA(T39:T54)) -> 0.55347222 | AA55: =M55-J55 -> -253.69273 | AB55: =M55/J55 -> 0.86877962
A56: 涼麵二線 | B56: 微波主食 | C56: 壹號醬雞豚雙拼 | E56: 56.43 | F56: 2726 | G56: =E56*F56 -> 153828.18 | I56: 22 | J56: 2000 | K56: =J56/I56 -> 90.909091 | L56: 22 | M56: =F56/V56*60 -> 1757.1352 | N56: =M56/L56 -> 79.869781 | O56: =L56-I56 -> 0 | P56: =N56-K56 -> -11.03931 | Q56: =N56/K56 -> 0.87856759 | R56: =Q72 -> 0.85032523 | S56: 0.16666667 | T56: 0.23130787 | V56: 93.083333 | AA56: =M56-J56 -> -242.86482 | AB56: =M56/J56 -> 0.87856759 | AC56: =AB72 -> 0.85032523
B57: 便當 | C57: 美式雞丁餐盒 | E57: 59.34 | F57: 2854 | G57: =E57*F57 -> 169356.36 | I57: 24 | J57: 2000 | K57: =J57/I57 -> 83.333333 | L57: 24 | M57: =F57/V57*60 -> 1756.0075 | N57: =M57/L57 -> 73.16698 | O57: =L57-I57 -> 0 | P57: =N57-K57 -> -10.166353 | Q57: =N57/K57 -> 0.87800376 | S57: 0.23644676 | T57: 0.30416667 | U57: 7.4 | V57: 97.516667 | AA57: =M57-J57 -> -243.99248 | AB57: =M57/J57 -> 0.87800376
B58: 便當 | C58: 蔬活腿排補力餐盒 | E58: 68.4 | F58: 5382 | G58: =E58*F58 -> 368128.8 | I58: 24 | J58: 2000 | K58: =J58/I58 -> 83.333333 | L58: 24 | M58: =F58/V58*60 -> 1647.551 | N58: =M58/L58 -> 68.647959 | O58: =L58-I58 -> 0 | P58: =N58-K58 -> -14.685374 | Q58: =N58/K58 -> 0.82377551 | S58: 0.30902778 | T58: 0.44513889 | U58: 7 | V58: 196 | AA58: =M58-J58 -> -352.44898 | AB58: =M58/J58 -> 0.82377551
B59: 便當 | C59: 海陸雙拼肉肉餐盒 | E59: 56.92 | F59: 1517 | G59: =E59*F59 -> 86347.64 | H59: 2 | I59: 23 | J59: 2000 | K59: =J59/I59 -> 86.956522 | L59: 23 | M59: =F59/V59*60 -> 1632.6457 | N59: =M59/L59 -> 70.984597 | O59: =L59-I59 -> 0 | P59: =N59-K59 -> -15.971924 | Q59: =N59/K59 -> 0.81632287 | S59: 0.45225694 | T59: 0.49097222 | U59: 10.25 | V59: 55.75 | W59: 0.49097222 | X59: 0.53194444 | AA59: =M59-J59 -> -367.35426 | AB59: =M59/J59 -> 0.81632287
B60: 便當 | C60: 烤蛋白餐盒 | E60: 58.67 | F60: 4516 | G60: =E60*F60 -> 264953.72 | I60: 24 | J60: 2000 | K60: =J60/I60 -> 83.333333 | L60: 24 | M60: =F60/V60*60 -> 1767.1304 | N60: =M60/L60 -> 73.630435 | O60: =L60-I60 -> 0 | P60: =N60-K60 -> -9.7028986 | Q60: =N60/K60 -> 0.88356522 | S60: 0.53194444 | T60: 0.63842593 | U60: 59 | V60: 153.33333 | AA60: =M60-J60 -> -232.86957 | AB60: =M60/J60 -> 0.88356522
B61: 便當 | C61: 海陸雙拼肉肉餐盒 | E61: 56.92 | F61: 3931 | G61: =E61*F61 -> 223752.52 | I61: 23 | J61: 2000 | K61: =J61/I61 -> 86.956522 | L61: 23 | M61: =F61/V61*60 -> 1643.4328 | N61: =M61/L61 -> 71.453601 | O61: =L61-I61 -> 0 | P61: =N61-K61 -> -15.502921 | Q61: =N61/K61 -> 0.82171641 | S61: 0.64269676 | T61: 0.74236111 | U61: 6.15 | V61: 143.51667 | AA61: =M61-J61 -> -356.56718 | AB61: =M61/J61 -> 0.82171641
B72: 平均 | I72: =AVERAGE(I56:I71) -> 23.333333 | J72: =AVERAGE(J56:J71) -> 2000 | K72: =J72/I72 -> 85.714286 | L72: =AVERAGE(L56:L71) -> 23.333333 | M72: =AVERAGE(M56:M71) -> 1700.6505 | N72: =M72/L72 -> 72.885019 | O72: =L72-I72 -> 0 | P72: =N72-K72 -> -12.829266 | Q72: =N72/K72 -> 0.85032523 | S72: =S56 -> 0.16666667 | T72: =INDEX(T56:T71,COUNTA(T56:T71)) -> 0.74236111 | AA72: =M72-J72 -> -299.34955 | AB72: =M72/J72 -> 0.85032523
A73: 涼麵三線 | B73: 季節調理麵 | C73: 椒麻香蔥雞涼拌麵 | E73: 37.94 | F73: 7119 | G73: =E73*F73 -> 270094.86 | I73: 21 | J73: 3600 | K73: =J73/I73 -> 171.42857 | L73: 21 | M73: =F73/V73*60 -> 3043.3915 | N73: =M73/L73 -> 144.92341 | O73: =L73-I73 -> 0 | P73: =N73-K73 -> -26.505166 | Q73: =N73/K73 -> 0.84538653 | R73: =Q89 -> 0.86666294 | S73: 0.16666667 | T73: 0.26413194 | V73: 140.35 | AA73: =M73-J73 -> -556.60848 | AB73: =M73/J73 -> 0.84538653 | AC73: =AB89 -> 0.86666294
B74: 季節調理麵 | C74: 台式麻醬涼麵 | E74: 31.27 | F74: 4008 | G74: =E74*F74 -> 125330.16 | I74: 19 | J74: 3600 | K74: =J74/I74 -> 189.47368 | L74: 19 | M74: =F74/V74*60 -> 3034.4479 | N74: =M74/L74 -> 159.70779 | O74: =L74-I74 -> 0 | P74: =N74-K74 -> -29.765897 | Q74: =N74/K74 -> 0.84290221 | S74: 0.27013889 | T74: 0.32517361 | U74: 8.65 | V74: 79.25 | AA74: =M74-J74 -> -565.55205 | AB74: =M74/J74 -> 0.84290221
B75: 微波小吃 | C75: 韓式部隊鍋 | E75: 55.12 | F75: 5107 | G75: =E75*F75 -> 281497.84 | I75: 22 | J75: 1800 | K75: =J75/I75 -> 81.818182 | L75: 22 | M75: =F75/V75*60 -> 1475.5377 | N75: =M75/L75 -> 67.069896 | O75: =L75-I75 -> 0 | P75: =N75-K75 -> -14.748285 | Q75: =N75/K75 -> 0.81974318 | S75: 0.32939815 | T75: 0.47361111 | U75: 6.0833333 | V75: 207.66667 | W75: 0.47361111 | X75: 0.51678241 | AA75: =M75-J75 -> -324.46228 | AB75: =M75/J75 -> 0.81974318
B76: 季節調理麵 | C76: 大滿足麻醬涼麵 | E76: 38 | F76: 2333 | G76: =E76*F76 -> 88654 | H76: 2 | I76: 21 | J76: 3600 | K76: =J76/I76 -> 171.42857 | L76: 21 | M76: =F76/V76*60 -> 3193.4601 | N76: =M76/L76 -> 152.06953 | O76: =L76-I76 -> 0 | P76: =N76-K76 -> -19.359044 | Q76: =N76/K76 -> 0.88707224 | S76: 0.51678241 | T76: 0.54722222 | U76: 62.166667 | V76: 43.833333 | AA76: =M76-J76 -> -406.53992 | AB76: =M76/J76 -> 0.88707224
B77: 季節調理麵 | C77: 大滿足香辣涼麵 | E77: 38.63 | F77: 6386 | G77: =E77*F77 -> 246691.18 | I77: 20 | J77: 3600 | K77: =J77/I77 -> 180 | L77: 20 | M77: =F77/V77*60 -> 3208.5973 | N77: =M77/L77 -> 160.42987 | O77: =L77-I77 -> 0 | P77: =N77-K77 -> -19.570133 | Q77: =N77/K77 -> 0.89127704 | S77: 0.55208333 | T77: 0.63501157 | U77: 7 | V77: 119.41667 | AA77: =M77-J77 -> -391.40265 | AB77: =M77/J77 -> 0.89127704
B78: 季節調理麵 | C78: 大滿足麻醬涼麵 | E78: 38 | F78: 5866 | G78: =E78*F78 -> 222908 | I78: 21 | J78: 3600 | K78: =J78/I78 -> 171.42857 | L78: 21 | M78: =F78/V78*60 -> 3204.4917 | N78: =M78/L78 -> 152.59484 | O78: =L78-I78 -> 0 | P78: =N78-K78 -> -18.833731 | Q78: =N78/K78 -> 0.89013657 | S78: 0.64108796 | T78: 0.71736111 | U78: 8.75 | V78: 109.83333 | AA78: =M78-J78 -> -395.50835 | AB78: =M78/J78 -> 0.89013657
B89: 平均 | I89: =AVERAGE(I73:I88) -> 20.666667 | J89: =AVERAGE(J73:J88) -> 3300 | K89: =J89/I89 -> 159.67742 | L89: =AVERAGE(L73:L88) -> 20.666667 | M89: =AVERAGE(M73:M88) -> 2859.9877 | N89: =M89/L89 -> 138.3865 | O89: =L89-I89 -> 0 | P89: =N89-K89 -> -21.290917 | Q89: =N89/K89 -> 0.86666294 | S89: =S73 -> 0.16666667 | T89: =INDEX(T73:T88,COUNTA(T73:T88)) -> 0.71736111 | AA89: =M89-J89 -> -440.01229 | AB89: =M89/J89 -> 0.86666294
A90: 自動包裝機 | B90: 4℃-飯糰 | C90: 大口蒜味香腸燒肉雙拼飯糰 | E90: 34.23 | F90: 1849 | G90: =E90*F90 -> 63291.27 | I90: 16 | J90: 3000 | K90: =J90/I90 -> 187.5 | L90: 16 | M90: =F90/V90*60 -> 2603.2069 | N90: =M90/L90 -> 162.70043 | O90: =L90-I90 -> 0 | P90: =N90-K90 -> -24.79957 | Q90: =N90/K90 -> 0.86773563 | R90: =Q106 -> 0.85664643 | S90: 0.16693287 | T90: 0.19652778 | V90: 42.616667 | AA90: =M90-J90 -> -396.79312 | AB90: =M90/J90 -> 0.86773563 | AC90: =AB106 -> 0.8698256
B91: 4℃-飯糰 | C91: 大口花椒香麻雞飯糰 | E91: 34.77 | F91: 1519 | G91: =E91*F91 -> 52815.63 | I91: 11 | J91: 3000 | K91: =J91/I91 -> 272.72727 | L91: 11 | M91: =F91/V91*60 -> 2591.6588 | N91: =M91/L91 -> 235.60534 | O91: =L91-I91 -> 0 | P91: =N91-K91 -> -37.12193 | Q91: =N91/K91 -> 0.86388626 | S91: 0.2 | T91: 0.2244213 | U91: 5 | V91: 35.166667 | AA91: =M91-J91 -> -408.34123 | AB91: =M91/J91 -> 0.86388626
B92: 4℃-飯糰 | C92: 大口法式蕈菇起司雞排飯糰 | E92: 35.83 | F92: 6177 | G92: =E92*F92 -> 221321.91 | I92: 12 | J92: 3273 | K92: =J92/I92 -> 272.75 | L92: 12 | M92: =F92/V92*60 -> 2895.8458 | N92: =M92/L92 -> 241.32048 | O92: =L92-I92 -> 0 | P92: =N92-K92 -> -31.429516 | Q92: =N92/K92 -> 0.88476805 | S92: 0.26945602 | T92: 0.35833333 | U92: 6.0166667 | V92: 127.98333 | AA92: =M92-J92 -> -377.15419 | AB92: =M92/J92 -> 0.88476805
...

Sheet 0929
B1: 屏榮 大溪廠組合室生產人時性分析
B3: 日期 | C3: 114.09.29星期一 | E3: 訂單量 | F3: ='0929(18度C)'!D1+'0929(4度C)'!D1 -> 252448 | H3: 營業額 | I3: ='0929(18度C)'!F1+'0929(4度C)'!F1 -> 7679816.1
B4: 人時性 | C4: 項目 | E4: ➀ | G4: ➁ | I4: ➂ | K4: ④ | M4: ⑤
C5: 組合室 | E5: 全溫層 | G5: 4度C-各編組展開(一配) | I5: 4度C-各編組展開(二配) | K5: 18度C-各編組展開(一配) | M5: 18度C-各編組展開(二配)
C6: 排關平均 | E6: =AVERAGE(D13:O13,D27:X27) -> 479.11105 | F6: =AVERAGE(#REF!,D13:K13) -> #REF! | G6: =AVERAGE(D13:K13) -> 198.7478 | I6: =AVERAGE(L13:O13) -> 94.130676 | K6: =AVERAGE(D27:O27) -> 652.68716 | M6: =AVERAGE(P27:X27) -> 747.88998
C7: 實績平均 | E7: =AVERAGE(D14:O14,D28:X28) -> 415.86257 | F7: =AVERAGE(#REF!,D14:K14) -> #REF! | G7: =AVERAGE(D14:K14) -> 175.45171 | I7: =AVERAGE(L14:O14) -> 82.138871 | K7: =AVERAGE(D28:O28) -> 566.88041 | M7: =AVERAGE(P28:X28) -> 644.29873
C8: 達成率平均 | E8: =AVERAGE(D15:O15,D29:X29) -> 0.86943486 | F8: =AVERAGE(D15:K15,#REF!) -> #REF! | G8: =AVERAGE(D15:K15) -> 0.87679652 | I8: =AVERAGE(L15:O15) -> 0.87260749 | K8: =AVERAGE(D29:O29) -> 0.86678721 | M8: =AVERAGE(P29:X29) -> 0.86209572 | O8: ※現行日本鮮食廠以達成率80%為基本(即為現行KPI)
B10: 溫層 | D10: ➁4度C-各編組展開 | L10: ➂4度C-各編組展開
B11: 編組 | D11: 1 | E11: 2 | F11: 3 | G11: 4 | H11: 5 | I11: 6 | J11: 7 | K11: 8 | L11: 1 | M11: 2 | N11: 3 | O11: 4
D12: 便當一線 | E12: 便當二線 | F12: 涼麵一線 | G12: 涼麵二線 | H12: 涼麵三線 | I12: 自動包裝機 | J12: 自動包裝機2 | K12: 自動包裝機3 | L12: 便當一線 | M12: 便當二線 | N12: 涼麵一線 | O12: 涼麵二線
B13: 人時性 | C13: 排關 | D13: 115.15152 | E13: 78.431373 | F13: 89.719626 | G13: 87.912088 | H13: 180 | I13: 250.92 | J13: - | K13: 589.1 | L13: - | M13: - | N13: 95.238095 | O13: 93.023256
C14: 實績 | D14: 102.10036 | E14: 68.52277 | F14: 77.824562 | G14: 77.046127 | H14: 155.31705 | I14: 219.38941 | J14: - | K14: 527.96168 | L14: - | M14: - | N14: 83.082994 | O14: 81.194748
C15: 達成率 | D15: =D14/D13 -> 0.88666101 | E15: =E14/E13 -> 0.87366531 | F15: =F14/F13 -> 0.86741959 | G15: =G14/G13 -> 0.87639969 | H15: =H14/H13 -> 0.86287252 | I15: =I14/I13 -> 0.87434006 | J15: - | K15: =K14/K13 -> 0.89621742 | L15: - | M15: - | N15: =N14/N13 -> 0.87237143 | O15: =O14/O13 -> 0.87284354
B16: 作業 時間 | C16: 開始 | D16: 0.25 | E16: 0.16695602 | F16: 0.25012731 | G16: 0.25033565 | H16: 0.20833333 | I16: 0.25015046 | J16: - | K16: 0.37986111 | L16: - | M16: - | N16: 0.70844907 | O16: 0.70864583
C17: 結束 | D17: 0.56041667 | E17: 0.66666667 | F17: 0.51736111 | G17: 0.61828704 | H17: 0.63981481 | I17: 0.56111111 | J17: - | K17: 0.50277778 | L17: - | M17: - | N17: 0.87638889 | O17: 0.82291667
B18: 配置人數 | D18: 16.5 | E18: 25.5 | F18: 21.4 | G18: 22.75 | H18: 20 | I18: 12.5 | J18: - | K18: 6 | L18: - | M18: - | N18: 21 | O18: 21.5
B19: 主要應用設備 | D19: L型封口機 | E19: ET-55 | F19: ET-55 | G19: ET-55 | H19: ET-600 | I19: 伺服包裝機 | J19: 伺服包裝機 | K19: 伺服包裝機 | L19: L型封口機 | M19: ET-55 | N19: ET-55 | O19: ET-55
B20: 次要應用設備 | D20: 伺服包裝機 | H20: 伺服包裝機
B21: 備註 | H21: 涼麵+烤飯糰 | I21: 大口飯糰線 | K21: 烤飯糰+手卷
B24: 溫層 | D24: ➃18度C-各編組展開 (一配) | P24: ⑤18度C-各編組展開 (二配)
B25: 編組 | D25: 1 | E25: 2 | F25: 3 | G25: 4 | H25: 5 | I25: 6 | J25: 7 | K25: 8 | L25: 9 | M25: 10 | N25: 11 | O25: 12 | P25: 1 | Q25: 2 | R25: 3 | S25: 4 | T25: 5 | U25: 6 | V25: 7 | W25: 8 | X25: 9
D26: 便當一線 | E26: 涼麵一線 | F26: 涼麵三線 | G26: 自動包裝機 | H26: 自動包裝機2 | I26: 自動包裝機3 | J26: 味付飯糰線B | K26: (舊) 3300型飯糰線 | L26: 3000型飯糰線 | M26: (新) 3300型飯糰機 | N26: GKK3600型 飯糰機 | O26: GKK3600型 飯糰機2 | P26: 自動包裝機 | Q26: 自動包裝機2 | R26: 自動包裝機3 | S26: 味付飯糰線B | T26: (舊) 3300型飯糰線 | U26: 3000型飯糰線 | V26: (新) 3300型飯糰機 | W26: GKK3600型 飯糰機 | X26: GKK3600型 飯糰機2
B27: 人時性 | C27: 排關 | D27: 192.52941 | E27: - | F27: - | G27: 313.04348 | H27: 433.33333 | I27: - | J27: 675 | K27: 825 | L27: - | M27: 868.42105 | N27: 1061.5385 | O27: 852.63158 | P27: 271.03125 | Q27: - | R27: - | S27: - | T27: 840 | U27: - | V27: 776.47059 | W27: 942.85714 | X27: 909.09091
C28: 實績 | D28: 165.93142 | E28: - | F28: - | G28: 265.09769 | H28: 373.16173 | I28: - | J28: 599.67626 | K28: 727.28155 | L28: - | M28: 757.62748 | N28: 904.30716 | O28: 741.95995 | P28: 233.31179 | Q28: - | R28: - | S28: - | T28: 730.73211 | U28: - | V28: 681.04635 | W28: 797.56736 | X28: 778.83606
C29: 達成率 | D29: =D28/D27 -> 0.86184974 | E29: - | F29: - | G29: =G28/G27 -> 0.84683983 | H29: =H28/H27 -> 0.86114244 | I29: - | J29: =J28/J27 -> 0.88840927 | K29: =K28/K27 -> 0.8815534 | L29: - | M29: =M28/M27 -> 0.87241953 | N29: =N28/N27 -> 0.85188356 | O29: =O28/O27 -> 0.87019994 | P29: =P28/P27 -> 0.86082985 | Q29: - | R29: - | S29: - | T29: =T28/T27 -> 0.86991918 | U29: - | V29: =V28/V27 -> 0.87710514 | W29: =W28/W27 -> 0.84590477 | X29: =X28/X27 -> 0.85671967
B30: 作業 時間 | C30: 開始 | D30: 0.39375 | E30: - | F30: - | G30: 0.31957176 | H30: 0.25 | I30: - | J30: 0.25 | K30: 0.37222222 | L30: - | M30: 0.16666667 | N30: 0.16666667 | O30: 0.16666667 | P30: 0.7083912 | Q30: - | R30: - | S30: - | T30: 0.70866898 | U30: - | V30: 0.70847222 | W30: 0.70842593 | X30: 0.70833333
C31: 結束 | D31: 0.47253472 | E31: - | F31: - | G31: 0.35555556 | H31: 0.37569444 | I31: - | J31: 0.34652778 | K31: 0.44375 | L31: - | M31: 0.39027778 | N31: 0.4259838 | O31: 0.42164352 | P31: 0.86693287 | Q31: - | R31: - | S31: - | T31: 0.89930556 | U31: - | V31: 0.95555556 | W31: 1.1009491 | X31: 1.1013889
B32: 配置人數 | D32: 17 | E32: - | F32: - | G32: 11.5 | H32: 6 | I32: - | J32: 4 | K32: 4 | L32: - | M32: 3.8 | N32: 3.25 | O32: 3.8 | P32: 12.8 | Q32: - | R32: - | S32: - | T32: 3.75 | U32: - | V32: 4.25 | W32: 3.5 | X32: 3.6666667
B33: 主要應用設備 | D33: 伺服包裝機 | E33: ET-55 | F33: ET-600 | G33: 夾心型 | H33: 伺服包裝機 | I33: 伺服包裝機 | J33: 夾心型 | K33: 3300型 | L33: 3300型 | M33: 3300型 | N33: GKK | O33: GKK | P33: 夾心型 | Q33: 伺服包裝機 | R33: 伺服包裝機 | S33: 夾心型 | T33: 3300型 | U33: 3300型 | V33: 3300型 | W33: GKK | X33: GKK
B34: 次要應用設備
B35: 備註

Sheet 0929(18度C)
A1: 大溪廠日報分析 | C1: 總生產量 | D1: =SUM(F5:F225) -> 143311 | E1: 營業額 | F1: =SUM(G5:G225) -> 2817296.6 | G1: 出勤人數 | H1: =L21+L38+L55+L72+L89+L106+L123+L140+L157+L174+L191+L208+L225 -> 81.316667 | I1: 產線配置圖 | L1: 生產實績 | O1: 人時性差異分析 | S1: 日報登錄 | Y1: 分析說明 | AA1: 產能差異分析
A2: 45929 | C2: 人時性 | D2: =AVERAGE(N21,N38,N55,N72,N89,N106,N123,N140,N157,N174,N191,N208,N225) -> 596.65669 | E2: 平均廠價 | F2: =F1/D1 -> 19.658621 | G2: 多次生產數 | H2: =COUNT(H5:H225) -> 6
A3: 線別 | B3: 品類 | C3: 品名 | E3: 廠價 | F3: 生產量 | G3: 營收 | H3: 多次 生產 | I3: 人數 | J3: 產能/時 | K3: 人時性 | L3: 人數 | M3: 產能/時 | N3: 人時性 | O3: 人數 | P3: 人時性 | Q3: 達成率 | R3: 達成率 平均 | S3: 生產時間 | U3: 換線、休息/分 | V3: 稼動時間/分 | W3: 休息時間 | Y3: (屏榮回填) | AA3: 產能/時 | AB3: 達成率 | AC3: 達成率平均
S4: 開始 | T4: 結束 | W4: 開始 | X4: 結束
A5: 便當一線 | B5: 18℃-壽司手卷 | C5: 一配海饌雙手卷 | E5: 29.85 | F5: 2606 | G5: =E5*F5 -> 77789.1 | I5: 17 | J5: 3273 | K5: =J5/I5 -> 192.52941 | L5: 17 | M5: =F5/V5*60 -> 2824.0819 | N5: =M5/L5 -> 166.12246 | O5: =L5-I5 -> 0 | P5: =N5-K5 -> -26.406948 | Q5: =N5/K5 -> 0.862842 | R5: =Q21 -> 0.86184974 | S5: 0.39375 | T5: 0.43219907 | U5: 7 | V5: 55.366667 | AA5: =M5-J5 -> -448.91812 | AB5: =M5/J5 -> 0.862842 | AC5: =AB21 -> 0.86184974
B6: 18℃-壽司手卷 | C6: 一配雙饗雙手卷 | E6: 29.52 | F6: 2510 | G6: =E6*F6 -> 74095.2 | I6: 17 | J6: 3273 | K6: =J6/I6 -> 192.52941 | L6: 17 | M6: =F6/V6*60 -> 2817.5865 | N6: =M6/L6 -> 165.74038 | O6: =L6-I6 -> 0 | P6: =N6-K6 -> -26.789028 | Q6: =N6/K6 -> 0.86085748 | S6: 0.43541667 | T6: 0.47253472 | U6: 4.6333333 | V6: 53.45 | W6: 0.47253472 | X6: 0.51342593 | AA6: =M6-J6 -> -455.41347 | AB6: =M6/J6 -> 0.86085748
B21: 平均 | I21: =AVERAGE(I5:I20) -> 17 | J21: =AVERAGE(J5:J20) -> 3273 | K21: =J21/I21 -> 192.52941 | L21: =AVERAGE(L5:L20) -> 17 | M21: =AVERAGE(M5:M20) -> 2820.8342 | N21: =M21/L21 -> 165.93142 | O21: =L21-I21 -> 0 | P21: =N21-K21 -> -26.597988 | Q21: =N21/K21 -> 0.86184974 | S21: =S5 -> 0.39375 | T21: =INDEX(T5:T20,COUNTA(T5:T20)) -> 0.47253472 | AA21: =M21-J21 -> -452.1658 | AB21: =M21/J21 -> 0.86184974
A22: 自動包裝機 | B22: 18℃-壽司手卷 | C22: 一配新之助的豆皮壽司喔 | E22: 25.52 | F22: 343 | G22: =E22*F22 -> 8753.36 | I22: 12 | J22: 3600 | K22: =J22/I22 -> 300 | L22: 12 | M22: =F22/V22*60 -> 3019.0709 | N22: =M22/L22 -> 251.58924 | O22: =L22-I22 -> 0 | P22: =N22-K22 -> -48.410758 | Q22: =N22/K22 -> 0.83863081 | R22: =Q38 -> 0.84683983 | S22: 0.31957176 | T22: 0.32430556 | U22: 4.7166667 | V22: 6.8166667 | AA22: =M22-J22 -> -580.9291 | AB22: =M22/J22 -> 0.83863081 | AC22: =AB38 -> 0.84683983
B23: 18℃-壽司手卷 | C23: 一配長野稻荷壽司 | E23: 25.64 | F23: 2100 | G23: =E23*F23 -> 53844 | I23: 11 | J23: 3600 | K23: =J23/I23 -> 327.27273 | L23: 11 | M23: =F23/V23*60 -> 3078.1759 | N23: =M23/L23 -> 279.83417 | O23: =L23-I23 -> 0 | P23: =N23-K23 -> -47.438555 | Q23: =N23/K23 -> 0.85504886 | S23: 0.32712963 | T23: 0.35555556 | U23: 4.0666667 | V23: 40.933333 | AA23: =M23-J23 -> -521.8241 | AB23: =M23/J23 -> 0.85504886
B38: 平均 | I38: =AVERAGE(I22:I37) -> 11.5 | J38: =AVERAGE(J22:J37) -> 3600 | K38: =J38/I38 -> 313.04348 | L38: =AVERAGE(L22:L37) -> 11.5 | M38: =AVERAGE(M22:M37) -> 3048.6234 | N38: =M38/L38 -> 265.09769 | O38: =L38-I38 -> 0 | P38: =N38-K38 -> -47.945791 | Q38: =N38/K38 -> 0.84683983 | S38: =S22 -> 0.31957176 | T38: =INDEX(T22:T37,COUNTA(T22:T37)) -> 0.35555556 | AA38: =M38-J38 -> -551.3766 | AB38: =M38/J38 -> 0.84683983
A39: 自動包裝機2 | B39: 18℃-壽司手卷 | C39: 一配芝麻海苔香鬆細卷 | E39: 14.06 | F39: 1264 | G39: =E39*F39 -> 17771.84 | I39: 6 | J39: 2600 | K39: =J39/I39 -> 433.33333 | L39: 6 | M39: =F39/V39*60 -> 2225.1345 | N39: =M39/L39 -> 370.85575 | O39: =L39-I39 -> 0 | P39: =N39-K39 -> -62.477588 | Q39: =N39/K39 -> 0.85582095 | R39: =Q55 -> 0.86114244 | S39: 0.25 | T39: 0.27366898 | V39: 34.083333 | AA39: =M39-J39 -> -374.86553 | AB39: =M39/J39 -> 0.85582095 | AC39: =AB55 -> 0.86114244
B40: 18℃-壽司手卷 | C40: 一配鮪魚沙拉細卷 | E40: 14.81 | F40: 1253 | G40: =E40*F40 -> 18556.93 | I40: 6 | J40: 2600 | K40: =J40/I40 -> 433.33333 | L40: 6 | M40: =F40/V40*60 -> 2225.3577 | N40: =M40/L40 -> 370.89295 | O40: =L40-I40 -> 0 | P40: =N40-K40 -> -62.440388 | Q40: =N40/K40 -> 0.8559068 | S40: 0.27931713 | T40: 0.30277778 | U40: 8.1333333 | V40: 33.783333 | AA40: =M40-J40 -> -374.64233 | AB40: =M40/J40 -> 0.8559068
B41: 18℃-壽司手卷 | C41: 一配香濃起司蟹風味棒細卷 | E41: 17.73 | F41: 3727 | G41: =E41*F41 -> 66079.71 | I41: 6 | J41: 2600 | K41: =J41/I41 -> 433.33333 | L41: 6 | M41: =F41/V41*60 -> 2266.4189 | N41: =M41/L41 -> 377.73649 | O41: =L41-I41 -> 0 | P41: =N41-K41 -> -55.596847 | Q41: =N41/K41 -> 0.87169958 | S41: 0.30717593 | T41: 0.37569444 | U41: 6.3333333 | V41: 98.666667 | AA41: =M41-J41 -> -333.58108 | AB41: =M41/J41 -> 0.87169958
B55: 平均 | I55: =AVERAGE(I39:I54) -> 6 | J55: =AVERAGE(J39:J54) -> 2600 | K55: =J55/I55 -> 433.33333 | L55: =AVERAGE(L39:L54) -> 6 | M55: =AVERAGE(M39:M54) -> 2238.9704 | N55: =M55/L55 -> 373.16173 | O55: =L55-I55 -> 0 | P55: =N55-K55 -> -60.171608 | Q55: =N55/K55 -> 0.86114244 | S55: =S39 -> 0.25 | T55: =INDEX(T39:T54,COUNTA(T39:T54)) -> 0.37569444 | AA55: =M55-J55 -> -361.02965 | AB55: =M55/J55 -> 0.86114244
A56: 味付飯糰線B | B56: 18℃-飯糰 | C56: 一配經典肉鬆飯糰 | E56: 14.03 | F56: 5557 | G56: =E56*F56 -> 77964.71 | I56: 4 | J56: 2700 | K56: =J56/I56 -> 675 | L56: 4 | M56: =F56/V56*60 -> 2398.705 | N56: =M56/L56 -> 599.67626 | O56: =L56-I56 -> 0 | P56: =N56-K56 -> -75.323741 | Q56: =N56/K56 -> 0.88840927 | R56: =Q72 -> 0.88840927 | S56: 0.25 | T56: 0.34652778 | V56: 139 | AA56: =M56-J56 -> -301.29496 | AB56: =M56/J56 -> 0.88840927 | AC56: =AB72 -> 0.88840927
B72: 平均 | I72: =AVERAGE(I56:I71) -> 4 | J72: =AVERAGE(J56:J71) -> 2700 | K72: =J72/I72 -> 675 | L72: =AVERAGE(L56:L71) -> 4 | M72: =AVERAGE(M56:M71) -> 2398.705 | N72: =M72/L72 -> 599.67626 | O72: =L72-I72 -> 0 | P72: =N72-K72 -> -75.323741 | Q72: =N72/K72 -> 0.88840927 | S72: =S56 -> 0.25 | T72: =INDEX(T56:T71,COUNTA(T56:T71)) -> 0.34652778 | AA72: =M72-J72 -> -301.29496 | AB72: =M72/J72 -> 0.88840927
A73: (舊) 3300型飯糰線 | B73: 18℃-飯糰 | C73: 一配照燒雞肉飯糰 | E73: 21.45 | F73: 4994 | G73: =E73*F73 -> 107121.3 | I73: 4 | J73: 3300 | K73: =J73/I73 -> 825 | L73: 4 | M73: =F73/V73*60 -> 2909.1262 | N73: =M73/L73 -> 727.28155 | O73: =L73-I73 -> 0 | P73: =N73-K73 -> -97.718447 | Q73: =N73/K73 -> 0.8815534 | R73: =Q89 -> 0.8815534 | S73: 0.37222222 | T73: 0.44375 | V73: 103 | AA73: =M73-J73 -> -390.87379 | AB73: =M73/J73 -> 0.8815534 | AC73: =AB89 -> 0.8815534
B89: 平均 | I89: =AVERAGE(I73:I88) -> 4 | J89: =AVERAGE(J73:J88) -> 3300 | K89: =J89/I89 -> 825 | L89: =AVERAGE(L73:L88) -> 4 | M89: =AVERAGE(M73:M88) -> 2909.1262 | N89: =M89/L89 -> 727.28155 | O89: =L89-I89 -> 0 | P89: =N89-K89 -> -97.718447 | Q89: =N89/K89 -> 0.8815534 | S89: =S73 -> 0.37222222 | T89: =INDEX(T73:T88,COUNTA(T73:T88)) -> 0.44375 | AA89: =M89-J89 -> -390.87379 | AB89: =M89/J89 -> 0.8815534
A90: (新) 3300型飯糰機 | B90: 18℃-飯糰 | C90: 一配三杯辣海瓜子飯糰 | E90: 21.45 | F90: 1107 | G90: =E90*F90 -> 23745.15 | I90: 3 | J90: 3300 | K90: =J90/I90 -> 1100 | L90: 3 | M90: =F90/V90*60 -> 2848.6061 | N90: =M90/L90 -> 949.53538 | O90: =L90-I90 -> 0 | P90: =N90-K90 -> -150.46462 | Q90: =N90/K90 -> 0.86321398 | R90: =Q106 -> 0.87241953 | S90: 0.16666667 | T90: 0.1828588 | V90: 23.316667 | AA90: =M90-J90 -> -451.39385 | AB90: =M90/J90 -> 0.86321398 | AC90: =AB106 -> 0.87241953
B91: 18℃-飯糰 | C91: 一配哇沙米魚卵沙拉飯糰 | E91: 15.71 | F91: 2638 | G91: =E91*F91 -> 41442.98 | I91: 3 | J91: 3300 | K91: =J91/I91 -> 1100 | L91: 3 | M91: =F91/V91*60 -> 2878.6905 | N91: =M91/L91 -> 959.5635 | O91: =L91-I91 -> 0 | P91: =N91-K91 -> -140.4365 | Q91: =N91/K91 -> 0.87233046 | S91: 0.18612269 | T91: 0.22430556 | U91: 4.7 | V91: 54.983333 | AA91: =M91-J91 -> -421.30949 | AB91: =M91/J91 -> 0.87233046
B92: 18℃-飯糰 | C92: 一配壹號醬炙烤牛飯糰 | E92: 22.28 | F92: 1497 | G92: =E92*F92 -> 33353.16 | I92: 5 | J92: 3300 | K92: =J92/I92 -> 660 | L92: 5 | M92: =F92/V92*60 -> 2857.4761 | N92: =M92/L92 -> 571.49523 | O92: =L92-I92 -> 0 | P92: =N92-K92 -> -88.504772 | Q92: =N92/K92 -> 0.86590186 | S92: 0.22916667 | T92: 0.25099537 | U92: 7 | V92: 31.433333 | AA92: =M92-J92 -> -442.52386 | AB92: =M92/J92 -> 0.86590186
B93: 18℃-飯糰 | C93: 一配鹽蔥燒肉飯糰 | E93: 17.89 | F93: 3465 | G93: =E93*F93 -> 61988.85 | I93: 4 | J93: 3300 | K93: =J93/I93 -> 825 | L93: 4 | M93: =F93/V93*60 -> 2897.561 | N93: =M93/L93 -> 724.39024 | O93: =L93-I93 -> 0 | P93: =N93-K93 -> -100.60976 | Q93: =N93/K93 -> 0.87804878 | S93: 0.25503472 | T93: 0.30486111 | U93: 5.8166667 | V93: 71.75 | AA93: =M93-J93 -> -402.43902 | AB93: =M93/J93 -> 0.87804878
B94: 18℃-飯糰 | C94: 一配雞肉飯飯糰 | E94: 16.66 | F94: 5720 | G94: =E94*F94 -> 95295.2 | I94: 4 | J94: 3300 | K94: =J94/I94 -> 825 | L94: 4 | M94: =F94/V94*60 -> 2912.5884 | N94: =M94/L94 -> 728.1471 | O94: =L94-I94 -> 0 | P94: =N94-K94 -> -96.8529 | Q94: =N94/K94 -> 0.88260255 | S94: 0.30844907 | T94: 0.39027778 | U94: 5.1666667 | V94: 117.83333 | AA94: =M94-J94 -> -387.4116 | AB94: =M94/J94 -> 0.88260255
B106: 平均 | I106: =AVERAGE(I90:I105) -> 3.8 | J106: =AVERAGE(J90:J105) -> 3300 | K106: =J106/I106 -> 868.42105 | L106: =AVERAGE(L90:L105) -> 3.8 | M106: =AVERAGE(M90:M105) -> 2878.9844 | N106: =M106/L106 -> 757.62748 | O106: =L106-I106 -> 0 | P106: =N106-K106 -> -110.79357 | Q106: =N106/K106 -> 0.87241953 | S106: =S90 -> 0.16666667 | T106: =INDEX(T90:T105,COUNTA(T90:T105)) -> 0.39027778 | AA106: =M106-J106 -> -421.01556 | AB106: =M106/J106 -> 0.87241953
A107: GKK3600型 飯糰機 | B107: 18℃-飯糰 | C107: 一配筋子銀鮭飯糰 | E107: 30 | F107: 3510 | G107: =E107*F107 -> 105300 | I107: 4 | J107: 3000 | K107: =J107/I107 -> 750 | L107: 4 | M107: =F107/V107*60 -> 2657.4132 | N107: =M107/L107 -> 664.35331 | O107: =L107-I107 -> 0 | P107: =N107-K107 -> -85.646688 | Q107: =N107/K107 -> 0.88580442 | R107: =Q123 -> 0.85188356 | S107: 0.16666667 | T107: 0.22170139 | V107: 79.25 | AA107: =M107-J107 -> -342.58675 | AB107: =M107/J107 -> 0.88580442 | AC107: =AB123 -> 0.85188356
B108: 18℃-飯糰 | C108: 一配蔬食鮪魚飯糰 | E108: 18.18 | F108: 2270 | G108: =E108*F108 -> 41268.6 | I108: 3 | J108: 3600 | K108: =J108/I108 -> 1200 | L108: 3 | M108: =F108/V108*60 -> 3026.6667 | N108: =M108/L108 -> 1008.8889 | O108: =L108-I108 -> 0 | P108: =N108-K108 -> -191.11111 | Q108: =N108/K108 -> 0.84074074 | S108: 0.23541667 | T108: 0.26666667 | U108: 19.75 | V108: 45 | AA108: =M108-J108 -> -573.33333 | AB108: =M108/J108 -> 0.84074074
B109: 18℃-飯糰 | C109: 一配明太子龍蝦風味沙拉飯糰 | E109: 18.18 | F109: 2821 | G109: =E109*F109 -> 51285.78 | I109: 3 | J109: 3600 | K109: =J109/I109 -> 1200 | L109: 3 | M109: =F109/V109*60 -> 3034.2396 | N109: =M109/L109 -> 1011.4132 | O109: =L109-I109 -> 0 | P109: =N109-K109 -> -188.58679 | Q109: =N109/K109 -> 0.84284434 | S109: 0.27931713 | T109: 0.31805556 | U109: 18.216667 | V109: 55.783333 | AA109: =M109-J109 -> -565.76038 | AB109: =M109/J109 -> 0.84284434
B110: 18℃-飯糰 | C110: 一配鮪魚飯糰 | E110: 14.28 | F110: 7109 | G110: =E110*F110 -> 101516.52 | I110: 3 | J110: 3600 | K110: =J110/I110 -> 1200 | L110: 3 | M110: =F110/V110*60 -> 3037.6736 | N110: =M110/L110 -> 1012.5579 | O110: =L110-I110 -> 0 | P110: =N110-K110 -> -187.44214 | Q110: =N110/K110 -> 0.84379822 | S110: 0.32847222 | T110: 0.4259838 | U110: 15 | V110: 140.41667 | AA110: =M110-J110 -> -562.32641 | AB110: =M110/J110 -> 0.84379822
B123: 平均 | I123: =AVERAGE(I107:I122) -> 3.25 | J123: =AVERAGE(J107:J122) -> 3450 | K123: =J123/I123 -> 1061.5385 | L123: =AVERAGE(L107:L122) -> 3.25 | M123: =AVERAGE(M107:M122) -> 2938.9983 | N123: =M123/L123 -> 904.30716 | O123: =L123-I123 -> 0 | P123: =N123-K123 -> -157.2313 | Q123: =N123/K123 -> 0.85188356 | S123: =S107 -> 0.16666667 | T123: =INDEX(T107:T122,COUNTA(T107:T122)) -> 0.4259838 | AA123: =M123-J123 -> -511.00172 | AB123: =M123/J123 -> 0.85188356
A124: GKK3600型 飯糰機2 | B124: 18℃-飯糰 | C124: 一配熟成紅鮭飯糰 | E124: 25.03 | F124: 2484 | G124: =E124*F124 -> 62174.52 | I124: 4 | J124: 3300 | K124: =J124/I124 -> 825 | L124: 4 | M124: =F124/V124*60 -> 2859.7378 | N124: =M124/L124 -> 714.93444 | O124: =L124-I124 -> 0 | P124: =N124-K124 -> -110.06556 | Q124: =N124/K124 -> 0.8665872 | R124: =Q140 -> 0.87019994 | S124: 0.16666667 | T124: 0.2028588 | V124: 52.116667 | AA124: =M124-J124 -> -440.26223 | AB124: =M124/J124 -> 0.8665872 | AC124: =AB140 -> 0.87019994
B125: 18℃-飯糰 | C125: 一配博多明太子奶油飯糰 | E125: 25.45 | F125: 2817 | G125: =E125*F125 -> 71692.65 | I125: 4 | J125: 3300 | K125: =J125/I125 -> 825 | L125: 4 | M125: =F125/V125*60 -> 2872.0476 | N125: =M125/L125 -> 718.01189 | O125: =L125-I125 -> 0 | P125: =N125-K125 -> -106.98811 | Q125: =N125/K125 -> 0.87031745 | S125: 0.21538194 | T125: 0.25625 | U125: 18.033333 | V125: 58.85 | AA125: =M125-J125 -> -427.95242 | AB125: =M125/J125 -> 0.87031745
B126: 18℃-飯糰 | C126: 一配照燒鰤魚大根飯糰 | E126: 26.73 | F126: 1894 | G126: =E126*F126 -> 50626.62 | I126: 4 | J126: 3300 | K126: =J126/I126 -> 825 | L126: 4 | M126: =F126/V126*60 -> 2838.6345 | N126: =M126/L126 -> 709.65862 | O126: =L126-I126 -> 0 | P126: =N126-K126 -> -115.34138 | Q126: =N126/K126 -> 0.86019226 | S126: 0.26944444 | T126: 0.29724537 | U126: 19 | V126: 40.033333 | AA126: =M126-J126 -> -461.36553 | AB126: =M126/J126 -> 0.86019226
B127: 18℃-飯糰 | C127: 一配北海道秋鮭親子飯糰 | E127: 24.82 | F127: 2571 | G127: =E127*F127 -> 63812.22 | I127: 4 | J127: 3300 | K127: =J127/I127 -> 825 | L127: 4 | M127: =F127/V127*60 -> 2865.5108 | N127: =M127/L127 -> 716.37771 | O127: =L127-I127 -> 0 | P127: =N127-K127 -> -108.62229 | Q127: =N127/K127 -> 0.86833662 | S127: 0.30983796 | T127: 0.34722222 | U127: 18.133333 | V127: 53.833333 | AA127: =M127-J127 -> -434.48916 | AB127: =M127/J127 -> 0.86833662
B128: 18℃-飯糰 | C128: 一配贅沢鮭魚肚飯糰 | E128: 30 | F128: 3955 | G128: =E128*F128 -> 118650 | I128: 3 | J128: 3000 | K128: =J128/I128 -> 1000 | L128: 3 | M128: =F128/V128*60 -> 2661.3084 | N128: =M128/L128 -> 887.1028 | O128: =L128-I128 -> 0 | P128: =N128-K128 -> -112.8972 | Q128: =N128/K128 -> 0.8871028 | S128: 0.35972222 | T128: 0.42164352 | U128: 18 | V128: 89.166667 | AA128: =M128-J128 -> -338.69159 | AB128: =M128/J128 -> 0.8871028
B140: 平均 | I140: =AVERAGE(I124:I139) -> 3.8 | J140: =AVERAGE(J124:J139) -> 3240 | K140: =J140/I140 -> 852.63158 | L140: =AVERAGE(L124:L139) -> 3.8 | M140: =AVERAGE(M124:M139) -> 2819.4478 | N140: =M140/L140 -> 741.95995 | O140: =L140-I140 -> 0 | P140: =N140-K140 -> -110.67163 | Q140: =N140/K140 -> 0.87019994 | S140: =S124 -> 0.16666667 | T140: =INDEX(T124:T139,COUNTA(T124:T139)) -> 0.42164352 | AA140: =M140-J140 -> -420.55219 | AB140: =M140/J140 -> 0.87019994
A141: 自動包裝機 (二配) | B141: 18℃-飯糰 | C141: 二配兔兔昆布飯糰 | E141: 13.42 | F141: 1445 | G141: =E141*F141 -> 19391.9 | I141: 6 | J141: 3600 | K141: =J141/I141 -> 600 | L141: 6 | M141: =F141/V141*60 -> 3105.6716 | N141: =M141/L141 -> 517.61194 | O141: =L141-I141 -> 0 | P141: =N141-K141 -> -82.38806 | Q141: =N141/K141 -> 0.86268657 | R141: =Q157 -> 0.86082985 | S141: 0.7083912 | T141: 0.72777778 | V141: 27.916667 | AA141: =M141-J141 -> -494.32836 | AB141: =M141/J141 -> 0.86268657 | AC141: =AB157 -> 0.86082985
B142: 18℃-飯糰 | C142: 二配兩粒飯糰(鮪魚&培根蛋沙拉) | E142: 28.57 | F142: 1018 | G142: =E142*F142 -> 29084.26 | I142: 13 | J142: 3600 | K142: =J142/I142 -> 276.92308 | L142: 13 | M142: =F142/V142*60 -> 3103.1329 | N142: =M142/L142 -> 238.70253 | O142: =L142-I142 -> 0 | P142: =N142-K142 -> -38.220543 | Q142: =N142/K142 -> 0.86198137 | S142: 0.7328588 | T142: 0.74652778 | U142: 7.3166667 | V142: 19.683333 | AA142: =M142-J142 -> -496.86706 | AB142: =M142/J142 -> 0.86198137
B143: 18℃-壽司手卷 | C143: 二配長野稻荷壽司 | E143: 25.64 | F143: 2204 | G143: =E143*F143 -> 56510.56 | I143: 11 | J143: 3600 | K143: =J143/I143 -> 327.27273 | L143: 11 | M143: =F143/V143*60 -> 3083.7155 | N143: =M143/L143 -> 280.33777 | O143: =L143-I143 -> 0 | P143: =N143-K143 -> -46.934954 | Q143: =N143/K143 -> 0.85658764 | S143: 0.75146991 | T143: 0.78125 | U143: 7.1166667 | V143: 42.883333 | AA143: =M143-J143 -> -516.28449 | AB143: =M143/J143 -> 0.85658764
B144: 18℃-壽司手卷 | C144: 二配雙饗雙手卷 | E144: 29.52 | F144: 2472 | G144: =E144*F144 -> 72973.44 | I144: 17 | J144: 3273 | K144: =J144/I144 -> 192.52941 | L144: 17 | M144: =F144/V144*60 -> 2816.2025 | N144: =M144/L144 -> 165.65897 | O144: =L144-I144 -> 0 | P144: =N144-K144 -> -26.870439 | Q144: =N144/K144 -> 0.86043463 | S144: 0.78703704 | T144: 0.82361111 | U144: 8.3333333 | V144: 52.666667 | W144: 0.82361111 | X144: 0.82847222 | AA144: =M144-J144 -> -456.79747 | AB144: =M144/J144 -> 0.86043463
B145: 18℃-壽司手卷 | C145: 二配海饌雙手卷 | E145: 29.85 | F145: 2606 | G145: =E145*F145 -> 77789.1 | I145: 17 | J145: 3273 | K145: =J145/I145 -> 192.52941 | L145: 17 | M145: =F145/V145*60 -> 2823.232 | N145: =M145/L145 -> 166.07247 | O145: =L145-I145 -> 0 | P145: =N145-K145 -> -26.45694 | Q145: =N145/K145 -> 0.86258235 | S145: 0.82847222 | T145: 0.86693287 | U145: 7 | V145: 55.383333 | AA145: =M145-J145 -> -449.76798 | AB145: =M145/J145 -> 0.86258235
...

Sheet 0929(4度C)
A1: 大溪廠日報分析 | C1: 總生產量 | D1: =SUM(F5:F157) -> 109137 | E1: 營業額 | F1: =SUM(G5:G157) -> 4862519.5 | G1: 出勤人數 | H1: =L21+L38+L55+L72+L89+L106+L123+L140+L157 -> 167.15 | I1: 產線配置圖 | L1: 生產實績 | O1: 人時性差異分析 | S1: 日報登錄 | Y1: 分析說明 | AA1: 產能差異分析
