Workbook

Sheet 1031
B1: 屏榮 大溪廠組合室生產人時性分析
B3: 日期 | C3: 114.10.31星期五 | E3: 訂單量 | F3: ='1031(18度C)'!D1+'1031(4度C)'!D1 -> 181372 | H3: 營業額 | I3: ='1031(18度C)'!F1+'1031(4度C)'!F1 -> 5667008.8
B4: 人時性 | C4: 項目 | E4: ➀ | G4: ➁ | I4: ➂ | K4: ④ | M4: ⑤
C5: 組合室 | E5: 全溫層 | G5: 4度C-各編組展開(一配) | I5: 4度C-各編組展開(二配) | K5: 18度C-各編組展開(一配) | M5: 18度C-各編組展開(二配)
C6: 排關平均 | E6: =AVERAGE(D13:O13,D27:X27) -> 460.16867 | F6: =AVERAGE(#REF!,D13:K13) -> #REF! | G6: =AVERAGE(D13:K13) -> 195.87163 | I6: =AVERAGE(L13:O13) -> 95.202399 | K6: =AVERAGE(D27:O27) -> 597.79868 | M6: =AVERAGE(P27:X27) -> 783.48901
C7: 實績平均 | E7: =AVERAGE(D14:O14,D28:X28) -> 405.40262 | F7: =AVERAGE(#REF!,D14:K14) -> #REF! | G7: =AVERAGE(D14:K14) -> 175.07503 | I7: =AVERAGE(L14:O14) -> 84.051324 | K7: =AVERAGE(D28:O28) -> 525.24375 | M7: =AVERAGE(P28:X28) -> 688.62419
C8: 達成率平均 | E8: =AVERAGE(D15:O15,D29:X29) -> 0.8815121 | F8: =AVERAGE(D15:K15,#REF!) -> #REF! | G8: =AVERAGE(D15:K15) -> 0.88730687 | I8: =AVERAGE(L15:O15) -> 0.88289148 | K8: =AVERAGE(D29:O29) -> 0.8776696 | M8: =AVERAGE(P29:X29) -> 0.87822717 | O8: ※現行日本鮮食廠以達成率80%為基本(即為現行KPI)
B10: 溫層 | D10: ➁4度C-各編組展開 | L10: ➂4度C-各編組展開
B11: 編組 | D11: 1 | E11: 2 | F11: 3 | G11: 4 | H11: 5 | I11: 6 | J11: 7 | K11: 8 | L11: 1 | M11: 2 | N11: 3 | O11: 4
D12: 便當一線 | E12: 便當二線 | F12: 涼麵一線 | G12: 涼麵二線 | H12: 涼麵三線 | I12: 自動包裝機 | J12: 自動包裝機2 | K12: 自動包裝機3 | L12: 便當一線 | M12: 便當二線 | N12: 涼麵一線 | O12: 涼麵二線
B13: 人時性 | C13: 排關 | D13: 115.15152 | E13: 80 | F13: 88.073394 | G13: 86.956522 | H13: 150 | I13: 250.92 | J13: - | K13: 600 | L13: - | M13: - | N13: 103.44828 | O13: 86.956522
C14: 實績 | D14: 102.47747 | E14: 70.872698 | F14: 77.470747 | G14: 76.772177 | H14: 132.95467 | I14: 220.59256 | J14: - | K14: 544.38487 | L14: - | M14: - | N14: 91.307729 | O14: 76.794919
C15: 達成率 | D15: =D14/D13 -> 0.88993591 | E15: =E14/E13 -> 0.88590872 | F15: =F14/F13 -> 0.87961577 | G15: =G14/G13 -> 0.88288004 | H15: =H14/H13 -> 0.88636447 | I15: =I14/I13 -> 0.87913503 | J15: - | K15: =K14/K13 -> 0.90730812 | L15: - | M15: - | N15: =N14/N13 -> 0.88264138 | O15: =O14/O13 -> 0.88314157
B16: 作業 時間 | C16: 開始 | D16: 0.25 | E16: 0.25 | F16: 0.25 | G16: 0.25013889 | H16: 0.25 | I16: 0.25010417 | J16: - | K16: 0.25 | L16: - | M16: - | N16: 0.70833333 | O16: 0.70833333
C17: 結束 | D17: 0.50555556 | E17: 0.53498843 | F17: 0.57222222 | G17: 0.58541667 | H17: 0.52649306 | I17: 0.52392361 | J17: - | K17: 0.3 | L17: - | M17: - | N17: 0.81269676 | O17: 0.83207176
B18: 配置人數 | D18: 16.5 | E18: 25 | F18: 21.8 | G18: 23 | H18: 20.571429 | I18: 12.5 | J18: - | K18: 6 | L18: - | M18: - | N18: 19.333333 | O18: 23
B19: 主要應用設備 | D19: L型封口機 | E19: ET-55 | F19: ET-55 | G19: ET-55 | H19: ET-600 | I19: 伺服包裝機 | J19: 伺服包裝機 | K19: 伺服包裝機 | L19: L型封口機 | M19: ET-55 | N19: ET-55 | O19: ET-55
B20: 次要應用設備 | D20: 伺服包裝機 | H20: 伺服包裝機
B21: 備註 | H21: 涼麵+烤飯糰 | I21: 大口飯糰線 | K21: 烤飯糰+手卷
B24: 溫層 | D24: ➃18度C-各編組展開 (一配) | P24: ⑤18度C-各編組展開 (二配)
B25: 編組 | D25: 1 | E25: 2 | F25: 3 | G25: 4 | H25: 5 | I25: 6 | J25: 7 | K25: 8 | L25: 9 | M25: 10 | N25: 11 | O25: 12 | P25: 1 | Q25: 2 | R25: 3 | S25: 4 | T25: 5 | U25: 6 | V25: 7 | W25: 8 | X25: 9
D26: 便當一線 | E26: 涼麵一線 | F26: 涼麵三線 | G26: 自動包裝機 | H26: 自動包裝機2 | I26: 自動包裝機3 | J26: 味付飯糰線B | K26: (舊) 3300型飯糰線 | L26: 3000型飯糰線 | M26: (新) 3300型飯糰機 | N26: GKK3600型 飯糰機 | O26: GKK3600型 飯糰機2 | P26: 自動包裝機 | Q26: 自動包裝機2 | R26: 自動包裝機3 | S26: 味付飯糰線B | T26: (舊) 3300型飯糰線 | U26: 3000型飯糰線 | V26: (新) 3300型飯糰機 | W26: GKK3600型 飯糰機 | X26: GKK3600型 飯糰機2
B27: 人時性 | C27: 排關 | D27: 211.76471 | E27: - | F27: - | G27: 313.04348 | H27: 433.33333 | I27: 416.66667 | J27: - | K27: - | L27: - | M27: 825 | N27: 1150 | O27: 834.78261 | P27: 285.71429 | Q27: - | R27: - | S27: - | T27: 787.5 | U27: - | V27: 825 | W27: 969.23077 | X27: 1050
C28: 實績 | D28: 183.00011 | E28: - | F28: - | G28: 271.35578 | H28: 383.37151 | I28: 369.57268 | J28: - | K28: - | L28: - | M28: 733.92219 | N28: 997.57969 | O28: 737.9043 | P28: 248.34067 | Q28: - | R28: - | S28: - | T28: 695.94116 | U28: - | V28: 733.54135 | W28: 854.67902 | X28: 910.61876
C29: 達成率 | D29: =D28/D27 -> 0.86416718 | E29: - | F29: - | G29: =G28/G27 -> 0.86683096 | H29: =H28/H27 -> 0.88470347 | I29: =I28/I27 -> 0.88697444 | J29: - | K29: - | L29: - | M29: =M28/M27 -> 0.88960265 | N29: =N28/N27 -> 0.8674606 | O29: =O28/O27 -> 0.88394786 | P29: =P28/P27 -> 0.86919235 | Q29: - | R29: - | S29: - | T29: =T28/T27 -> 0.88373481 | U29: - | V29: =V28/V27 -> 0.88914103 | W29: =W28/W27 -> 0.88181169 | X29: =X28/X27 -> 0.86725596
B30: 作業 時間 | C30: 開始 | D30: 0.37292824 | E30: - | F30: - | G30: 0.35694444 | H30: 0.25018519 | I30: 0.30440972 | J30: - | K30: - | L30: - | M30: 0.25018519 | N30: 0.2503125 | O30: 0.2500463 | P30: 0.70833333 | Q30: - | R30: - | S30: - | T30: 0.70858796 | U30: - | V30: 0.70833333 | W30: 0.7084838 | X30: 0.70833333
C31: 結束 | D31: 0.42650463 | E31: - | F31: - | G31: 0.43402778 | H31: 0.34934028 | I31: 0.39027778 | J31: - | K31: - | L31: - | M31: 0.44100694 | N31: 0.44930556 | O31: 0.42986111 | P31: 0.84450231 | Q31: - | R31: - | S31: - | T31: 0.85863426 | U31: - | V31: 0.87873843 | W31: 0.98480324 | X31: 0.98409722
B32: 配置人數 | D32: 17 | E32: - | F32: - | G32: 11.5 | H32: 6 | I32: 6 | J32: - | K32: - | L32: - | M32: 4 | N32: 3 | O32: 3.8333333 | P32: 12.6 | Q32: - | R32: - | S32: - | T32: 4 | U32: - | V32: 4 | W32: 3.25 | X32: 3.3333333
B33: 主要應用設備 | D33: 伺服包裝機 | E33: ET-55 | F33: ET-600 | G33: 夾心型 | H33: 伺服包裝機 | I33: 伺服包裝機 | J33: 夾心型 | K33: 3300型 | L33: 3300型 | M33: 3300型 | N33: GKK | O33: GKK | P33: 夾心型 | Q33: 伺服包裝機 | R33: 伺服包裝機 | S33: 夾心型 | T33: 3300型 | U33: 3300型 | V33: 3300型 | W33: GKK | X33: GKK
B34: 次要應用設備
B35: 備註

Sheet 1031(18度C)
A1: 大溪廠日報分析 | C1: 總生產量 | D1: =SUM(F5:F208) -> 107592 | E1: 營業額 | F1: =SUM(G5:G208) -> 2163308.8 | G1: 出勤人數 | H1: =L21+L38+L55+L72+L89+L106+L123+L140+L157+L174+L191+L208 -> 78.516667 | I1: 產線配置圖 | L1: 生產實績 | O1: 人時性差異分析 | S1: 日報登錄 | Y1: 分析說明 | AA1: 產能差異分析
A2: 45961 | C2: 人時性 | D2: =AVERAGE(N21,N38,N55,N72,N89,N106,N123,N140,N157,N174,N191,N208) -> 593.31893 | E2: 平均廠價 | F2: =F1/D1 -> 20.106596 | G2: 多次生產數 | H2: =COUNT(H5:H208) -> 3
A3: 線別 | B3: 品類 | C3: 品名 | E3: 廠價 | F3: 生產量 | G3: 營收 | H3: 多次 生產 | I3: 人數 | J3: 產能/時 | K3: 人時性 | L3: 人數 | M3: 產能/時 | N3: 人時性 | O3: 人數 | P3: 人時性 | Q3: 達成率 | R3: 達成率 平均 | S3: 生產時間 | U3: 換線、休息/分 | V3: 稼動時間/分 | W3: 休息時間 | Y3: (屏榮回填) | AA3: 產能/時 | AB3: 達成率 | AC3: 達成率平均
S4: 開始 | T4: 結束 | W4: 開始 | X4: 結束
A5: 便當一線 | B5: 18℃-壽司手卷 | C5: 一配海饌雙手卷 | E5: 29.85 | F5: 1918 | G5: =E5*F5 -> 57252.3 | I5: 17 | J5: 3600 | K5: =J5/I5 -> 211.76471 | L5: 17 | M5: =F5/V5*60 -> 3111.6719 | N5: =M5/L5 -> 183.03952 | O5: =L5-I5 -> 0 | P5: =N5-K5 -> -28.725181 | Q5: =N5/K5 -> 0.86435331 | R5: =Q21 -> 0.86416718 | S5: 0.37292824 | T5: 0.39861111 | U5: 5.9333333 | V5: 36.983333 | AA5: =M5-J5 -> -488.32808 | AB5: =M5/J5 -> 0.86435331 | AC5: =AB21 -> 0.86416718
B6: 18℃-壽司手卷 | C6: 一配雙饗雙手卷 | E6: 29.52 | F6: 1823 | G6: =E6*F6 -> 53814.96 | I6: 17 | J6: 3600 | K6: =J6/I6 -> 211.76471 | L6: 17 | M6: =F6/V6*60 -> 3110.3318 | N6: =M6/L6 -> 182.96069 | O6: =L6-I6 -> 0 | P6: =N6-K6 -> -28.804014 | Q6: =N6/K6 -> 0.86398104 | S6: 0.40208333 | T6: 0.42650463 | U6: 5 | V6: 35.166667 | W6: 0.42650463 | X6: 0.46677083 | AA6: =M6-J6 -> -489.66825 | AB6: =M6/J6 -> 0.86398104
B21: 平均 | I21: =AVERAGE(I5:I20) -> 17 | J21: =AVERAGE(J5:J20) -> 3600 | K21: =J21/I21 -> 211.76471 | L21: =AVERAGE(L5:L20) -> 17 | M21: =AVERAGE(M5:M20) -> 3111.0018 | N21: =M21/L21 -> 183.00011 | O21: =L21-I21 -> 0 | P21: =N21-K21 -> -28.764598 | Q21: =N21/K21 -> 0.86416718 | S21: =S5 -> 0.37292824 | T21: =INDEX(T5:T20,COUNTA(T5:T20)) -> 0.42650463 | AA21: =M21-J21 -> -488.99816 | AB21: =M21/J21 -> 0.86416718
A22: 自動包裝機 | B22: 18℃-壽司手卷 | C22: 一配長野稻荷壽司 | E22: 25.64 | F22: 1150 | G22: =E22*F22 -> 29486 | I22: 11 | J22: 3600 | K22: =J22/I22 -> 327.27273 | L22: 11 | M22: =F22/V22*60 -> 3136.3636 | N22: =M22/L22 -> 285.12397 | O22: =L22-I22 -> 0 | P22: =N22-K22 -> -42.14876 | Q22: =N22/K22 -> 0.87121212 | R22: =Q38 -> 0.86683096 | S22: 0.35694444 | T22: 0.37222222 | U22: 5 | V22: 22 | AA22: =M22-J22 -> -463.63636 | AB22: =M22/J22 -> 0.87121212 | AC22: =AB38 -> 0.86683096
B23: 18℃-飯糰 | C23: 一配兩粒飯糰(鮪魚.焦糖鮭魚) | E23: 28.57 | F23: 4295 | G23: =E23*F23 -> 122708.15 | I23: 12 | J23: 3600 | K23: =J23/I23 -> 300 | L23: 12 | M23: =F23/V23*60 -> 3104.8193 | N23: =M23/L23 -> 258.73494 | O23: =L23-I23 -> 0 | P23: =N23-K23 -> -41.26506 | Q23: =N23/K23 -> 0.8624498 | S23: 0.37638889 | T23: 0.43402778 | U23: 6 | V23: 83 | AA23: =M23-J23 -> -495.18072 | AB23: =M23/J23 -> 0.8624498
B38: 平均 | I38: =AVERAGE(I22:I37) -> 11.5 | J38: =AVERAGE(J22:J37) -> 3600 | K38: =J38/I38 -> 313.04348 | L38: =AVERAGE(L22:L37) -> 11.5 | M38: =AVERAGE(M22:M37) -> 3120.5915 | N38: =M38/L38 -> 271.35578 | O38: =L38-I38 -> 0 | P38: =N38-K38 -> -41.687699 | Q38: =N38/K38 -> 0.86683096 | S38: =S22 -> 0.35694444 | T38: =INDEX(T22:T37,COUNTA(T22:T37)) -> 0.43402778 | AA38: =M38-J38 -> -479.40854 | AB38: =M38/J38 -> 0.86683096
A39: 自動包裝機2 | B39: 18℃-壽司手卷 | C39: 一配雙鬆細卷 | E39: 14.03 | F39: 2098 | G39: =E39*F39 -> 29434.94 | I39: 6 | J39: 2600 | K39: =J39/I39 -> 433.33333 | L39: 6 | M39: =F39/V39*60 -> 2299.8782 | N39: =M39/L39 -> 383.31303 | O39: =L39-I39 -> 0 | P39: =N39-K39 -> -50.0203 | Q39: =N39/K39 -> 0.88456854 | R39: =Q55 -> 0.88470347 | S39: 0.25018519 | T39: 0.28819444 | V39: 54.733333 | AA39: =M39-J39 -> -300.1218 | AB39: =M39/J39 -> 0.88456854 | AC39: =AB55 -> 0.88470347
B40: 18℃-壽司手卷 | C40: 一配香濃起司蟹風味棒細卷 | E40: 17.73 | F40: 1282 | G40: =E40*F40 -> 22729.86 | I40: 6 | J40: 2600 | K40: =J40/I40 -> 433.33333 | L40: 6 | M40: =F40/V40*60 -> 2300.6979 | N40: =M40/L40 -> 383.44965 | O40: =L40-I40 -> 0 | P40: =N40-K40 -> -49.883682 | Q40: =N40/K40 -> 0.88488381 | S40: 0.29166667 | T40: 0.31488426 | U40: 5 | V40: 33.433333 | AA40: =M40-J40 -> -299.30209 | AB40: =M40/J40 -> 0.88488381
B41: 18℃-壽司手卷 | C41: 一配經典鮪魚沙拉細卷 | E41: 14.49 | F41: 1727 | G41: =E41*F41 -> 25024.23 | I41: 6 | J41: 2600 | K41: =J41/I41 -> 433.33333 | L41: 6 | M41: =F41/V41*60 -> 2300.111 | N41: =M41/L41 -> 383.35183 | O41: =L41-I41 -> 0 | P41: =N41-K41 -> -49.981502 | Q41: =N41/K41 -> 0.88465807 | S41: 0.31805556 | T41: 0.34934028 | U41: 4.5666667 | V41: 45.05 | AA41: =M41-J41 -> -299.88901 | AB41: =M41/J41 -> 0.88465807
B55: 平均 | I55: =AVERAGE(I39:I54) -> 6 | J55: =AVERAGE(J39:J54) -> 2600 | K55: =J55/I55 -> 433.33333 | L55: =AVERAGE(L39:L54) -> 6 | M55: =AVERAGE(M39:M54) -> 2300.229 | N55: =M55/L55 -> 383.37151 | O55: =L55-I55 -> 0 | P55: =N55-K55 -> -49.961828 | Q55: =N55/K55 -> 0.88470347 | S55: =S39 -> 0.25018519 | T55: =INDEX(T39:T54,COUNTA(T39:T54)) -> 0.34934028 | AA55: =M55-J55 -> -299.77097 | AB55: =M55/J55 -> 0.88470347
A56: 自動包裝機3 | B56: 18℃-壽司手卷 | C56: 一配滿滿海鮮沙拉脆卷 | E56: 19.39 | F56: 1687 | G56: =E56*F56 -> 32710.93 | I56: 6 | J56: 2500 | K56: =J56/I56 -> 416.66667 | L56: 6 | M56: =F56/V56*60 -> 2217.3056 | N56: =M56/L56 -> 369.55093 | O56: =L56-I56 -> 0 | P56: =N56-K56 -> -47.115736 | Q56: =N56/K56 -> 0.88692223 | R56: =Q72 -> 0.88697444 | S56: 0.30440972 | T56: 0.33611111 | U56: 6.35 | V56: 45.65 | AA56: =M56-J56 -> -282.69441 | AB56: =M56/J56 -> 0.88692223 | AC56: =AB72 -> 0.88697444
B57: 18℃-壽司手卷 | C57: 一配明太子玉子脆卷 | E57: 19.7 | F57: 2658 | G57: =E57*F57 -> 52362.6 | I57: 6 | J57: 2500 | K57: =J57/I57 -> 416.66667 | L57: 6 | M57: =F57/V57*60 -> 2217.5666 | N57: =M57/L57 -> 369.59444 | O57: =L57-I57 -> 0 | P57: =N57-K57 -> -47.072229 | Q57: =N57/K57 -> 0.88702665 | S57: 0.34033565 | T57: 0.39027778 | U57: 6.0833333 | V57: 71.916667 | AA57: =M57-J57 -> -282.43337 | AB57: =M57/J57 -> 0.88702665
B72: 平均 | I72: =AVERAGE(I56:I71) -> 6 | J72: =AVERAGE(J56:J71) -> 2500 | K72: =J72/I72 -> 416.66667 | L72: =AVERAGE(L56:L71) -> 6 | M72: =AVERAGE(M56:M71) -> 2217.4361 | N72: =M72/L72 -> 369.57268 | O72: =L72-I72 -> 0 | P72: =N72-K72 -> -47.093982 | Q72: =N72/K72 -> 0.88697444 | S72: =S56 -> 0.30440972 | T72: =INDEX(T56:T71,COUNTA(T56:T71)) -> 0.39027778 | AA72: =M72-J72 -> -282.56389 | AB72: =M72/J72 -> 0.88697444
A73: (新) 3300型飯糰機 | B73: 18℃-飯糰 | C73: 一配照燒雞肉飯糰 | E73: 21.45 | F73: 2242 | G73: =E73*F73 -> 48090.9 | I73: 4 | J73: 3300 | K73: =J73/I73 -> 825 | L73: 4 | M73: =F73/V73*60 -> 2941.3994 | N73: =M73/L73 -> 735.34985 | O73: =L73-I73 -> 0 | P73: =N73-K73 -> -89.650146 | Q73: =N73/K73 -> 0.89133316 | R73: =Q89 -> 0.88960265 | S73: 0.25018519 | T73: 0.28194444 | V73: 45.733333 | AA73: =M73-J73 -> -358.60058 | AB73: =M73/J73 -> 0.89133316 | AC73: =AB89 -> 0.88960265
B74: 18℃-飯糰 | C74: 一配鹽蔥燒肉飯糰 | E74: 17.89 | F74: 2312 | G74: =E74*F74 -> 41361.68 | I74: 4 | J74: 3300 | K74: =J74/I74 -> 825 | L74: 4 | M74: =F74/V74*60 -> 2936.909 | N74: =M74/L74 -> 734.22724 | O74: =L74-I74 -> 0 | P74: =N74-K74 -> -90.772759 | Q74: =N74/K74 -> 0.88997241 | S74: 0.28541667 | T74: 0.31821759 | U74: 5 | V74: 47.233333 | AA74: =M74-J74 -> -363.09104 | AB74: =M74/J74 -> 0.88997241
B75: 18℃-飯糰 | C75: 一配壹號醬炙烤牛飯糰 | E75: 22.28 | F75: 953 | G75: =E75*F75 -> 21232.84 | I75: 5 | J75: 3300 | K75: =J75/I75 -> 660 | L75: 5 | M75: =F75/V75*60 -> 2934.8161 | N75: =M75/L75 -> 586.96322 | O75: =L75-I75 -> 0 | P75: =N75-K75 -> -73.036784 | Q75: =N75/K75 -> 0.88933821 | S75: 0.32222222 | T75: 0.33575231 | U75: 5.7666667 | V75: 19.483333 | AA75: =M75-J75 -> -365.18392 | AB75: =M75/J75 -> 0.88933821
B76: 18℃-飯糰 | C76: 一配椒鹽檸檬鯖魚飯糰 | E76: 21.45 | F76: 3112 | G76: =E76*F76 -> 66752.4 | I76: 3 | J76: 3300 | K76: =J76/I76 -> 1100 | L76: 3 | M76: =F76/V76*60 -> 2932.7749 | N76: =M76/L76 -> 977.59162 | O76: =L76-I76 -> 0 | P76: =N76-K76 -> -122.40838 | Q76: =N76/K76 -> 0.88871966 | S76: 0.33981481 | T76: 0.38402778 | U76: 5.85 | V76: 63.666667 | AA76: =M76-J76 -> -367.22513 | AB76: =M76/J76 -> 0.88871966
B77: 18℃-飯糰 | C77: 一配雞肉飯飯糰 | E77: 16.66 | F77: 3717 | G77: =E77*F77 -> 61925.22 | I77: 4 | J77: 3300 | K77: =J77/I77 -> 825 | L77: 4 | M77: =F77/V77*60 -> 2932.5444 | N77: =M77/L77 -> 733.13609 | O77: =L77-I77 -> 0 | P77: =N77-K77 -> -91.863905 | Q77: =N77/K77 -> 0.88864981 | S77: 0.38819444 | T77: 0.44100694 | U77: 6 | V77: 76.05 | AA77: =M77-J77 -> -367.45562 | AB77: =M77/J77 -> 0.88864981
B89: 平均 | I89: =AVERAGE(I73:I88) -> 4 | J89: =AVERAGE(J73:J88) -> 3300 | K89: =J89/I89 -> 825 | L89: =AVERAGE(L73:L88) -> 4 | M89: =AVERAGE(M73:M88) -> 2935.6887 | N89: =M89/L89 -> 733.92219 | O89: =L89-I89 -> 0 | P89: =N89-K89 -> -91.077815 | Q89: =N89/K89 -> 0.88960265 | S89: =S73 -> 0.25018519 | T89: =INDEX(T73:T88,COUNTA(T73:T88)) -> 0.44100694 | AA89: =M89-J89 -> -364.31126 | AB89: =M89/J89 -> 0.88960265
A90: GKK3600型 飯糰機 | B90: 18℃-飯糰 | C90: 一配蔬食鮪魚飯糰 | E90: 18.18 | F90: 1320 | G90: =E90*F90 -> 23997.6 | I90: 3 | J90: 3600 | K90: =J90/I90 -> 1200 | L90: 3 | M90: =F90/V90*60 -> 3099.8043 | N90: =M90/L90 -> 1033.2681 | O90: =L90-I90 -> 0 | P90: =N90-K90 -> -166.7319 | Q90: =N90/K90 -> 0.86105675 | R90: =Q106 -> 0.8674606 | S90: 0.2503125 | T90: 0.26805556 | V90: 25.55 | AA90: =M90-J90 -> -500.19569 | AB90: =M90/J90 -> 0.86105675 | AC90: =AB106 -> 0.8674606
B91: 18℃-飯糰 | C91: 一配明太子龍蝦風味沙拉飯糰 | E91: 18.18 | F91: 1914 | G91: =E91*F91 -> 34796.52 | I91: 3 | J91: 3600 | K91: =J91/I91 -> 1200 | L91: 3 | M91: =F91/V91*60 -> 3099.5951 | N91: =M91/L91 -> 1033.1984 | O91: =L91-I91 -> 0 | P91: =N91-K91 -> -166.80162 | Q91: =N91/K91 -> 0.86099865 | S91: 0.27986111 | T91: 0.30559028 | U91: 17 | V91: 37.05 | AA91: =M91-J91 -> -500.40486 | AB91: =M91/J91 -> 0.86099865
B92: 18℃-飯糰 | C92: 一配鮪魚飯糰 | E92: 14.28 | F92: 4584 | G92: =E92*F92 -> 65459.52 | I92: 3 | J92: 3600 | K92: =J92/I92 -> 1200 | L92: 3 | M92: =F92/V92*60 -> 3101.3719 | N92: =M92/L92 -> 1033.7906 | O92: =L92-I92 -> 0 | P92: =N92-K92 -> -166.20936 | Q92: =N92/K92 -> 0.8614922 | S92: 0.31688657 | T92: 0.37847222 | U92: 16.266667 | V92: 88.683333 | AA92: =M92-J92 -> -498.62808 | AB92: =M92/J92 -> 0.8614922
B93: 18℃-飯糰 | C93: 一配經典肉鬆飯糰 | E93: 14.03 | F93: 3851 | G93: =E93*F93 -> 54029.53 | I93: 3 | J93: 3000 | K93: =J93/I93 -> 1000 | L93: 3 | M93: =F93/V93*60 -> 2670.1849 | N93: =M93/L93 -> 890.06163 | O93: =L93-I93 -> 0 | P93: =N93-K93 -> -109.93837 | Q93: =N93/K93 -> 0.89006163 | S93: 0.38921296 | T93: 0.44930556 | U93: 15.466667 | V93: 86.533333 | AA93: =M93-J93 -> -329.8151 | AB93: =M93/J93 -> 0.89006163
B106: 平均 | I106: =AVERAGE(I90:I105) -> 3 | J106: =AVERAGE(J90:J105) -> 3450 | K106: =J106/I106 -> 1150 | L106: =AVERAGE(L90:L105) -> 3 | M106: =AVERAGE(M90:M105) -> 2992.7391 | N106: =M106/L106 -> 997.57969 | O106: =L106-I106 -> 0 | P106: =N106-K106 -> -152.42031 | Q106: =N106/K106 -> 0.8674606 | S106: =S90 -> 0.2503125 | T106: =INDEX(T90:T105,COUNTA(T90:T105)) -> 0.44930556 | AA106: =M106-J106 -> -457.26093 | AB106: =M106/J106 -> 0.8674606
A107: GKK3600型 飯糰機2 | B107: 18℃-飯糰 | C107: 一配熟成紅鮭飯糰 | E107: 25.03 | F107: 1303 | G107: =E107*F107 -> 32614.09 | I107: 4 | J107: 3300 | K107: =J107/I107 -> 825 | L107: 4 | M107: =F107/V107*60 -> 2902.7228 | N107: =M107/L107 -> 725.68069 | O107: =L107-I107 -> 0 | P107: =N107-K107 -> -99.319307 | Q107: =N107/K107 -> 0.87961296 | R107: =Q123 -> 0.88394786 | S107: 0.2500463 | T107: 0.26875 | V107: 26.933333 | AA107: =M107-J107 -> -397.27723 | AB107: =M107/J107 -> 0.87961296 | AC107: =AB123 -> 0.88394786
B108: 18℃-飯糰 | C108: 一配博多明太子奶油飯糰 | E108: 25.45 | F108: 1069 | G108: =E108*F108 -> 27206.05 | I108: 4 | J108: 3300 | K108: =J108/I108 -> 825 | L108: 4 | M108: =F108/V108*60 -> 2904.4528 | N108: =M108/L108 -> 726.11321 | O108: =L108-I108 -> 0 | P108: =N108-K108 -> -98.886792 | Q108: =N108/K108 -> 0.88013722 | S108: 0.27916667 | T108: 0.29450231 | U108: 15 | V108: 22.083333 | AA108: =M108-J108 -> -395.54717 | AB108: =M108/J108 -> 0.88013722
B109: 18℃-飯糰 | C109: 一配照燒鰤魚大根飯糰 | E109: 26.73 | F109: 229 | G109: =E109*F109 -> 6121.17 | I109: 4 | J109: 3300 | K109: =J109/I109 -> 825 | L109: 4 | M109: =F109/V109*60 -> 2902.8169 | N109: =M109/L109 -> 725.70423 | O109: =L109-I109 -> 0 | P109: =N109-K109 -> -99.295775 | Q109: =N109/K109 -> 0.87964149 | S109: 0.3050463 | T109: 0.30833333 | U109: 15.183333 | V109: 4.7333333 | AA109: =M109-J109 -> -397.1831 | AB109: =M109/J109 -> 0.87964149
B110: 18℃-飯糰 | C110: 一配筋子銀鮭飯糰 | E110: 30 | F110: 1691 | G110: =E110*F110 -> 50730 | I110: 4 | J110: 3000 | K110: =J110/I110 -> 750 | L110: 4 | M110: =F110/V110*60 -> 2679.4014 | N110: =M110/L110 -> 669.85035 | O110: =L110-I110 -> 0 | P110: =N110-K110 -> -80.149648 | Q110: =N110/K110 -> 0.8931338 | S110: 0.32023148 | T110: 0.34652778 | U110: 17.133333 | V110: 37.866667 | AA110: =M110-J110 -> -320.59859 | AB110: =M110/J110 -> 0.8931338
B111: 18℃-飯糰 | C111: 一配北海道秋鮭親子飯糰 | E111: 24.82 | F111: 1527 | G111: =E111*F111 -> 37900.14 | I111: 4 | J111: 3300 | K111: =J111/I111 -> 825 | L111: 4 | M111: =F111/V111*60 -> 2903.962 | N111: =M111/L111 -> 725.99049 | O111: =L111-I111 -> 0 | P111: =N111-K111 -> -99.009509 | Q111: =N111/K111 -> 0.87998847 | S111: 0.35725694 | T111: 0.37916667 | U111: 15.45 | V111: 31.55 | AA111: =M111-J111 -> -396.03803 | AB111: =M111/J111 -> 0.87998847
B112: 18℃-飯糰 | C112: 一配贅沢鮭魚肚飯糰 | E112: 30 | F112: 2485 | G112: =E112*F112 -> 74550 | I112: 3 | J112: 3000 | K112: =J112/I112 -> 1000 | L112: 3 | M112: =F112/V112*60 -> 2678.4431 | N112: =M112/L112 -> 892.81437 | O112: =L112-I112 -> 0 | P112: =N112-K112 -> -107.18563 | Q112: =N112/K112 -> 0.89281437 | S112: 0.3912037 | T112: 0.42986111 | U112: 17.333333 | V112: 55.666667 | AA112: =M112-J112 -> -321.55689 | AB112: =M112/J112 -> 0.89281437
B123: 平均 | I123: =AVERAGE(I107:I122) -> 3.8333333 | J123: =AVERAGE(J107:J122) -> 3200 | K123: =J123/I123 -> 834.78261 | L123: =AVERAGE(L107:L122) -> 3.8333333 | M123: =AVERAGE(M107:M122) -> 2828.6332 | N123: =M123/L123 -> 737.9043 | O123: =L123-I123 -> 0 | P123: =N123-K123 -> -96.878305 | Q123: =N123/K123 -> 0.88394786 | S123: =S107 -> 0.2500463 | T123: =INDEX(T107:T122,COUNTA(T107:T122)) -> 0.42986111 | AA123: =M123-J123 -> -371.36683 | AB123: =M123/J123 -> 0.88394786
A124: 自動包裝機 (二配) | B124: 18℃-飯糰 | C124: 二配兔兔昆布飯糰 | E124: 13.42 | F124: 268 | G124: =E124*F124 -> 3596.56 | I124: 6 | J124: 3600 | K124: =J124/I124 -> 600 | L124: 6 | M124: =F124/V124*60 -> 3184.1584 | N124: =M124/L124 -> 530.69307 | O124: =L124-I124 -> 0 | P124: =N124-K124 -> -69.306931 | Q124: =N124/K124 -> 0.88448845 | R124: =Q140 -> 0.86919235 | S124: 0.70833333 | T124: 0.71184028 | V124: 5.05 | AA124: =M124-J124 -> -415.84158 | AB124: =M124/J124 -> 0.88448845 | AC124: =AB140 -> 0.86919235
B125: 18℃-壽司手卷 | C125: 二配長野稻荷壽司 | E125: 25.64 | F125: 1633 | G125: =E125*F125 -> 41870.12 | I125: 11 | J125: 3600 | K125: =J125/I125 -> 327.27273 | L125: 11 | M125: =F125/V125*60 -> 3137.0331 | N125: =M125/L125 -> 285.18483 | O125: =L125-I125 -> 0 | P125: =N125-K125 -> -42.087901 | Q125: =N125/K125 -> 0.87139808 | S125: 0.71527778 | T125: 0.73696759 | U125: 4.95 | V125: 31.233333 | AA125: =M125-J125 -> -462.96692 | AB125: =M125/J125 -> 0.87139808
B126: 18℃-壽司手卷 | C126: 二配雙饗雙手卷 | E126: 29.52 | F126: 1878 | G126: =E126*F126 -> 55438.56 | I126: 17 | J126: 3600 | K126: =J126/I126 -> 211.76471 | L126: 17 | M126: =F126/V126*60 -> 3109.8436 | N126: =M126/L126 -> 182.93198 | O126: =L126-I126 -> 0 | P126: =N126-K126 -> -28.832729 | Q126: =N126/K126 -> 0.86384545 | S126: 0.74166667 | T126: 0.7668287 | U126: 6.7666667 | V126: 36.233333 | AA126: =M126-J126 -> -490.15639 | AB126: =M126/J126 -> 0.86384545
B127: 18℃-壽司手卷 | C127: 二配海饌雙手卷 | E127: 29.85 | F127: 1989 | G127: =E127*F127 -> 59371.65 | I127: 17 | J127: 3600 | K127: =J127/I127 -> 211.76471 | L127: 17 | M127: =F127/V127*60 -> 3111.8644 | N127: =M127/L127 -> 183.05085 | O127: =L127-I127 -> 0 | P127: =N127-K127 -> -28.713858 | Q127: =N127/K127 -> 0.86440678 | S127: 0.77013889 | T127: 0.79677083 | U127: 4.7666667 | V127: 38.35 | AA127: =M127-J127 -> -488.13559 | AB127: =M127/J127 -> 0.86440678
B128: 18℃-飯糰 | C128: 二配兩粒飯糰(鮪魚.焦糖鮭魚) | E128: 28.57 | F128: 3262 | G128: =E128*F128 -> 93195.34 | I128: 12 | J128: 3600 | K128: =J128/I128 -> 300 | L128: 12 | M128: =F128/V128*60 -> 3102.5627 | N128: =M128/L128 -> 258.5469 | O128: =L128-I128 -> 0 | P128: =N128-K128 -> -41.453104 | Q128: =N128/K128 -> 0.86182299 | S128: 0.80069444 | T128: 0.84450231 | U128: 5.65 | V128: 63.083333 | AA128: =M128-J128 -> -497.43725 | AB128: =M128/J128 -> 0.86182299
...

Sheet 1031(4度C)
A1: 大溪廠日報分析 | C1: 總生產量 | D1: =SUM(F5:F157) -> 73780 | E1: 營業額 | F1: =SUM(G5:G157) -> 3503699.9 | G1: 出勤人數 | H1: =L21+L38+L55+L72+L89+L106+L123+L140+L157 -> 167.70476 | I1: 產線配置圖 | L1: 生產實績 | O1: 人時性差異分析 | S1: 日報登錄 | Y1: 分析說明 | AA1: 產能差異分析
A2: 45961 | C2: 人時性 | D2: =AVERAGE(N21,N38,N55,N72,N89,N106,N123,N140,N157) -> 154.84754 | E2: 平均廠價 | F2: =F1/D1 -> 47.488478 | G2: 多次生產數 | H2: =COUNT(H5:H157) -> 0
A3: 線別 | B3: 品類 | C3: 品名 | E3: 廠價 | F3: 生產量 | G3: 營收 | H3: 多次 生產 | I3: 人數 | J3: 產能/時 | K3: 人時性 | L3: 人數 | M3: 產能/時 | N3: 人時性 | O3: 人數 | P3: 人時性 | Q3: 達成率 | R3: 達成率 平均 | S3: 生產時間 | U3: 換線、休息/分 | V3: 稼動時間/分 | W3: 休息時間 | Y3: (屏榮回填) | AA3: 產能/時 | AB3: 達成率 | AC3: 達成率平均
S4: 開始 | T4: 結束 | W4: 開始 | X4: 結束
A5: 便當一線 | B5: 微波小吃 | C5: 日式茶碗蒸 | E5: 19.7 | F5: 3072 | G5: =E5*F5 -> 60518.4 | I5: 13 | J5: 1200 | K5: =J5/I5 -> 92.307692 | L5: 13 | M5: =F5/V5*60 -> 1077.3697 | N5: =M5/L5 -> 82.874593 | O5: =L5-I5 -> 0 | P5: =N5-K5 -> -9.4330998 | Q5: =N5/K5 -> 0.89780809 | R5: =Q21 -> 0.88993591 | S5: 0.25 | T5: 0.36880787 | V5: 171.08333 | AA5: =M5-J5 -> -122.6303 | AB5: =M5/J5 -> 0.89780809 | AC5: =AB21 -> 0.88993591
B6: 4℃-飯糰 | C6: 麻油雞飯糰 | E6: 29.97 | F6: 2145 | G6: =E6*F6 -> 64285.65 | I6: 20 | J6: 2600 | K6: =J6/I6 -> 130 | L6: 20 | M6: =F6/V6*60 -> 2304.3868 | N6: =M6/L6 -> 115.21934 | O6: =L6-I6 -> 0 | P6: =N6-K6 -> -14.780662 | Q6: =N6/K6 -> 0.8863026 | S6: 0.46677083 | T6: 0.50555556 | U6: 57.983333 | V6: 55.85 | AA6: =M6-J6 -> -295.61325 | AB6: =M6/J6 -> 0.8863026
B21: 平均 | I21: =AVERAGE(I5:I20) -> 16.5 | J21: =AVERAGE(J5:J20) -> 1900 | K21: =J21/I21 -> 115.15152 | L21: =AVERAGE(L5:L20) -> 16.5 | M21: =AVERAGE(M5:M20) -> 1690.8782 | N21: =M21/L21 -> 102.47747 | O21: =L21-I21 -> 0 | P21: =N21-K21 -> -12.674047 | Q21: =N21/K21 -> 0.88993591 | S21: =S5 -> 0.25 | T21: =INDEX(T5:T20,COUNTA(T5:T20)) -> 0.50555556 | AA21: =M21-J21 -> -209.12177 | AB21: =M21/J21 -> 0.88993591
A22: 便當二線 | B22: 微波主食 | C22: 糖燻野郎三十天熟成牛飯 | E22: 56.77 | F22: 3706 | G22: =E22*F22 -> 210389.62 | I22: 25 | J22: 2000 | K22: =J22/I22 -> 80 | L22: 25 | M22: =F22/V22*60 -> 1773.2057 | N22: =M22/L22 -> 70.92823 | O22: =L22-I22 -> 0 | P22: =N22-K22 -> -9.0717703 | Q22: =N22/K22 -> 0.88660287 | R22: =Q38 -> 0.88590872 | S22: 0.25 | T22: 0.33708333 | V22: 125.4 | AA22: =M22-J22 -> -226.79426 | AB22: =M22/J22 -> 0.88660287 | AC22: =AB38 -> 0.88590872
B23: 便當 | C23: 嫩烤香料雞胸排蔬滿盒 | E23: 77.34 | F23: 1738 | G23: =E23*F23 -> 134416.92 | I23: 25 | J23: 2000 | K23: =J23/I23 -> 80 | L23: 25 | M23: =F23/V23*60 -> 1772.4646 | N23: =M23/L23 -> 70.898584 | O23: =L23-I23 -> 0 | P23: =N23-K23 -> -9.1014164 | Q23: =N23/K23 -> 0.88623229 | S23: 0.34178241 | T23: 0.38263889 | U23: 6.7666667 | V23: 58.833333 | AA23: =M23-J23 -> -227.53541 | AB23: =M23/J23 -> 0.88623229
B24: 便當 | C24: 健身G肉餐盒 | E24: 59.52 | F24: 3365 | G24: =E24*F24 -> 200284.8 | I24: 25 | J24: 2000 | K24: =J24/I24 -> 80 | L24: 25 | M24: =F24/V24*60 -> 1781.4706 | N24: =M24/L24 -> 71.258824 | O24: =L24-I24 -> 0 | P24: =N24-K24 -> -8.7411765 | Q24: =N24/K24 -> 0.89073529 | S24: 0.38680556 | T24: 0.46550926 | U24: 6 | V24: 113.33333 | W24: 0.46550926 | X24: 0.50625 | AA24: =M24-J24 -> -218.52941 | AB24: =M24/J24 -> 0.89073529
B25: 微波主食 | C25: 蒜蒜燒豚飯 | E25: 51.86 | F25: 1214 | G25: =E25*F25 -> 62958.04 | I25: 25 | J25: 2000 | K25: =J25/I25 -> 80 | L25: 25 | M25: =F25/V25*60 -> 1760.1289 | N25: =M25/L25 -> 70.405155 | O25: =L25-I25 -> 0 | P25: =N25-K25 -> -9.5948449 | Q25: =N25/K25 -> 0.88006444 | S25: 0.50625 | T25: 0.53498843 | U25: 58.666667 | V25: 41.383333 | AA25: =M25-J25 -> -239.87112 | AB25: =M25/J25 -> 0.88006444
B38: 平均 | I38: =AVERAGE(I22:I37) -> 25 | J38: =AVERAGE(J22:J37) -> 2000 | K38: =J38/I38 -> 80 | L38: =AVERAGE(L22:L37) -> 25 | M38: =AVERAGE(M22:M37) -> 1771.8174 | N38: =M38/L38 -> 70.872698 | O38: =L38-I38 -> 0 | P38: =N38-K38 -> -9.127302 | Q38: =N38/K38 -> 0.88590872 | S38: =S22 -> 0.25 | T38: =INDEX(T22:T37,COUNTA(T22:T37)) -> 0.53498843 | AA38: =M38-J38 -> -228.18255 | AB38: =M38/J38 -> 0.88590872
A39: 涼麵一線 | B39: 熱食義麵 | C39: 焗烤蕃茄起司四方麵 | E39: 57.3 | F39: 3687 | G39: =E39*F39 -> 211265.1 | I39: 25 | J39: 1800 | K39: =J39/I39 -> 72 | L39: 25 | M39: =F39/V39*60 -> 1590.7478 | N39: =M39/L39 -> 63.629914 | O39: =L39-I39 -> 0 | P39: =N39-K39 -> -8.3700863 | Q39: =N39/K39 -> 0.8837488 | R39: =Q55 -> 0.87961577 | S39: 0.25 | T39: 0.34657407 | V39: 139.06667 | AA39: =M39-J39 -> -209.25216 | AB39: =M39/J39 -> 0.8837488 | AC39: =AB55 -> 0.87961577
B40: 微波小吃 | C40: 日式壽喜燒 | E40: 57.73 | F40: 1860 | G40: =E40*F40 -> 107377.8 | I40: 22 | J40: 1800 | K40: =J40/I40 -> 81.818182 | L40: 22 | M40: =F40/V40*60 -> 1571.831 | N40: =M40/L40 -> 71.446863 | O40: =L40-I40 -> 0 | P40: =N40-K40 -> -10.371319 | Q40: =N40/K40 -> 0.87323944 | S40: 0.35069444 | T40: 0.4 | U40: 5.9333333 | V40: 71 | AA40: =M40-J40 -> -228.16901 | AB40: =M40/J40 -> 0.87323944
B41: 微波主食 | C41: 妮妮家漢堡排 | E41: 57.3 | F41: 755 | G41: =E41*F41 -> 43261.5 | I41: 20 | J41: 2000 | K41: =J41/I41 -> 100 | L41: 20 | M41: =F41/V41*60 -> 1763.7897 | N41: =M41/L41 -> 88.189487 | O41: =L41-I41 -> 0 | P41: =N41-K41 -> -11.810513 | Q41: =N41/K41 -> 0.88189487 | S41: 0.40438657 | T41: 0.42222222 | U41: 6.3166667 | V41: 25.683333 | AA41: =M41-J41 -> -236.21025 | AB41: =M41/J41 -> 0.88189487
B42: 便當 | C42: 照燒豬排纖食餐盒 | E42: 59.36 | F42: 1301 | G42: =E42*F42 -> 77227.36 | I42: 20 | J42: 2000 | K42: =J42/I42 -> 100 | L42: 20 | M42: =F42/V42*60 -> 1764.0678 | N42: =M42/L42 -> 88.20339 | O42: =L42-I42 -> 0 | P42: =N42-K42 -> -11.79661 | Q42: =N42/K42 -> 0.8820339 | S42: 0.42569444 | T42: 0.45642361 | U42: 5 | V42: 44.25 | W42: 0.45642361 | X42: 0.49814815 | AA42: =M42-J42 -> -235.9322 | AB42: =M42/J42 -> 0.8820339
B43: 便當 | C43: 香腸腿排雙拼便當 | E43: 53.76 | F43: 3118 | G43: =E43*F43 -> 167623.68 | I43: 22 | J43: 2000 | K43: =J43/I43 -> 90.909091 | L43: 22 | M43: =F43/V43*60 -> 1753.875 | N43: =M43/L43 -> 79.721591 | O43: =L43-I43 -> 0 | P43: =N43-K43 -> -11.1875 | Q43: =N43/K43 -> 0.8769375 | S43: 0.49814815 | T43: 0.57222222 | U43: 60.083333 | V43: 106.66667 | AA43: =M43-J43 -> -246.125 | AB43: =M43/J43 -> 0.8769375
B55: 平均 | I55: =AVERAGE(I39:I54) -> 21.8 | J55: =AVERAGE(J39:J54) -> 1920 | K55: =J55/I55 -> 88.073394 | L55: =AVERAGE(L39:L54) -> 21.8 | M55: =AVERAGE(M39:M54) -> 1688.8623 | N55: =M55/L55 -> 77.470747 | O55: =L55-I55 -> 0 | P55: =N55-K55 -> -10.602648 | Q55: =N55/K55 -> 0.87961577 | S55: =S39 -> 0.25 | T55: =INDEX(T39:T54,COUNTA(T39:T54)) -> 0.57222222 | AA55: =M55-J55 -> -231.13773 | AB55: =M55/J55 -> 0.87961577
A56: 涼麵二線 | B56: 便當 | C56: 美式雞丁餐盒 | E56: 59.34 | F56: 1317 | G56: =E56*F56 -> 78150.78 | I56: 24 | J56: 2000 | K56: =J56/I56 -> 83.333333 | L56: 24 | M56: =F56/V56*60 -> 1763.8393 | N56: =M56/L56 -> 73.493304 | O56: =L56-I56 -> 0 | P56: =N56-K56 -> -9.8400298 | Q56: =N56/K56 -> 0.88191964 | R56: =Q72 -> 0.88288004 | S56: 0.25013889 | T56: 0.28125 | V56: 44.8 | AA56: =M56-J56 -> -236.16071 | AB56: =M56/J56 -> 0.88191964 | AC56: =AB72 -> 0.88288004
B57: 便當 | C57: 烤蛋白餐盒 | E57: 58.67 | F57: 2217 | G57: =E57*F57 -> 130071.39 | I57: 24 | J57: 2000 | K57: =J57/I57 -> 83.333333 | L57: 24 | M57: =F57/V57*60 -> 1772.4184 | N57: =M57/L57 -> 73.850766 | O57: =L57-I57 -> 0 | P57: =N57-K57 -> -9.4825672 | Q57: =N57/K57 -> 0.88620919 | S57: 0.28472222 | T57: 0.33684028 | U57: 5 | V57: 75.05 | AA57: =M57-J57 -> -227.58161 | AB57: =M57/J57 -> 0.88620919
B58: 便當 | C58: 蔬活腿排補力餐盒 | E58: 71.55 | F58: 2094 | G58: =E58*F58 -> 149825.7 | I58: 24 | J58: 2000 | K58: =J58/I58 -> 83.333333 | L58: 24 | M58: =F58/V58*60 -> 1764.1938 | N58: =M58/L58 -> 73.508074 | O58: =L58-I58 -> 0 | P58: =N58-K58 -> -9.8252594 | Q58: =N58/K58 -> 0.88209689 | S58: 0.34097222 | T58: 0.39042824 | U58: 5.95 | V58: 71.216667 | AA58: =M58-J58 -> -235.80623 | AB58: =M58/J58 -> 0.88209689
B59: 便當 | C59: 經典滷肉飯 | E59: 47.37 | F59: 1253 | G59: =E59*F59 -> 59354.61 | I59: 21 | J59: 2000 | K59: =J59/I59 -> 95.238095 | L59: 21 | M59: =F59/V59*60 -> 1763.4089 | N59: =M59/L59 -> 83.971853 | O59: =L59-I59 -> 0 | P59: =N59-K59 -> -11.266242 | Q59: =N59/K59 -> 0.88170446 | S59: 0.39400463 | T59: 0.42361111 | U59: 5.15 | V59: 42.633333 | AA59: =M59-J59 -> -236.59109 | AB59: =M59/J59 -> 0.88170446
B60: 微波主食 | C60: 壹號醬雞豚雙拼 | E60: 56.43 | F60: 2197 | G60: =E60*F60 -> 123976.71 | I60: 22 | J60: 2000 | K60: =J60/I60 -> 90.909091 | L60: 22 | M60: =F60/V60*60 -> 1766.2349 | N60: =M60/L60 -> 80.283406 | O60: =L60-I60 -> 0 | P60: =N60-K60 -> -10.625685 | Q60: =N60/K60 -> 0.88311746 | S60: 0.42803241 | T60: 0.47986111 | U60: 6.3666667 | V60: 74.633333 | W60: 0.47986111 | X60: 0.52092593 | AA60: =M60-J60 -> -233.76507 | AB60: =M60/J60 -> 0.88311746
B61: 便當 | C61: 海陸雙拼肉肉餐盒 | E61: 59.54 | F61: 2731 | G61: =E61*F61 -> 162603.74 | I61: 23 | J61: 2000 | K61: =J61/I61 -> 86.956522 | L61: 23 | M61: =F61/V61*60 -> 1764.4652 | N61: =M61/L61 -> 76.715878 | O61: =L61-I61 -> 0 | P61: =N61-K61 -> -10.240644 | Q61: =N61/K61 -> 0.88223259 | S61: 0.52092593 | T61: 0.58541667 | U61: 59.133333 | V61: 92.866667 | AA61: =M61-J61 -> -235.53482 | AB61: =M61/J61 -> 0.88223259
B72: 平均 | I72: =AVERAGE(I56:I71) -> 23 | J72: =AVERAGE(J56:J71) -> 2000 | K72: =J72/I72 -> 86.956522 | L72: =AVERAGE(L56:L71) -> 23 | M72: =AVERAGE(M56:M71) -> 1765.7601 | N72: =M72/L72 -> 76.772177 | O72: =L72-I72 -> 0 | P72: =N72-K72 -> -10.184344 | Q72: =N72/K72 -> 0.88288004 | S72: =S56 -> 0.25013889 | T72: =INDEX(T56:T71,COUNTA(T56:T71)) -> 0.58541667 | AA72: =M72-J72 -> -234.23992 | AB72: =M72/J72 -> 0.88288004
A73: 涼麵三線 | B73: 季節調理麵 | C73: 大滿足香辣涼麵 | E73: 38.63 | F73: 2352 | G73: =E73*F73 -> 90857.76 | I73: 20 | J73: 3600 | K73: =J73/I73 -> 180 | L73: 20 | M73: =F73/V73*60 -> 3249.1174 | N73: =M73/L73 -> 162.45587 | O73: =L73-I73 -> 0 | P73: =N73-K73 -> -17.544129 | Q73: =N73/K73 -> 0.90253262 | R73: =Q89 -> 0.88636447 | S73: 0.25 | T73: 0.28016204 | V73: 43.433333 | AA73: =M73-J73 -> -350.88258 | AB73: =M73/J73 -> 0.90253262 | AC73: =AB89 -> 0.88636447
B74: 季節調理麵 | C74: 大滿足麻醬涼麵 | E74: 38 | F74: 2730 | G74: =E74*F74 -> 103740 | I74: 21 | J74: 3600 | K74: =J74/I74 -> 171.42857 | L74: 21 | M74: =F74/V74*60 -> 3250 | N74: =M74/L74 -> 154.7619 | O74: =L74-I74 -> 0 | P74: =N74-K74 -> -16.666667 | Q74: =N74/K74 -> 0.90277778 | S74: 0.28402778 | T74: 0.31902778 | U74: 5.5666667 | V74: 50.4 | AA74: =M74-J74 -> -350 | AB74: =M74/J74 -> 0.90277778
B75: 季節調理麵 | C75: 日式蕎麥沾麵 | E75: 36.86 | F75: 1909 | G75: =E75*F75 -> 70365.74 | I75: 21 | J75: 3600 | K75: =J75/I75 -> 171.42857 | L75: 21 | M75: =F75/V75*60 -> 3249.3617 | N75: =M75/L75 -> 154.73151 | O75: =L75-I75 -> 0 | P75: =N75-K75 -> -16.697062 | Q75: =N75/K75 -> 0.90260047 | S75: 0.32291667 | T75: 0.34739583 | U75: 5.6 | V75: 35.25 | AA75: =M75-J75 -> -350.6383 | AB75: =M75/J75 -> 0.90260047
B76: 季節調理麵 | C76: 台式麻醬涼麵 | E76: 31.27 | F76: 1876 | G76: =E76*F76 -> 58662.52 | I76: 19 | J76: 3600 | K76: =J76/I76 -> 189.47368 | L76: 19 | M76: =F76/V76*60 -> 3107.9613 | N76: =M76/L76 -> 163.57691 | O76: =L76-I76 -> 0 | P76: =N76-K76 -> -25.896771 | Q76: =N76/K76 -> 0.8633226 | S76: 0.35069444 | T76: 0.37584491 | U76: 4.75 | V76: 36.216667 | AA76: =M76-J76 -> -492.03866 | AB76: =M76/J76 -> 0.8633226
B77: 季節調理麵 | C77: 椒麻香蔥雞涼拌麵 | E77: 37.94 | F77: 2576 | G77: =E77*F77 -> 97733.44 | I77: 21 | J77: 3600 | K77: =J77/I77 -> 171.42857 | L77: 21 | M77: =F77/V77*60 -> 3107.7748 | N77: =M77/L77 -> 147.98928 | O77: =L77-I77 -> 0 | P77: =N77-K77 -> -23.439295 | Q77: =N77/K77 -> 0.86327078 | S77: 0.37935185 | T77: 0.41388889 | U77: 5.05 | V77: 49.733333 | AA77: =M77-J77 -> -492.2252 | AB77: =M77/J77 -> 0.86327078
B78: 微波小吃 | C78: 擔仔炊粉湯 | E78: 45.66 | F78: 711 | G78: =E78*F78 -> 32464.26 | I78: 20 | J78: 1800 | K78: =J78/I78 -> 90 | L78: 20 | M78: =F78/V78*60 -> 1590.8017 | N78: =M78/L78 -> 79.540087 | O78: =L78-I78 -> 0 | P78: =N78-K78 -> -10.459913 | Q78: =N78/K78 -> 0.88377874 | S78: 0.41818287 | T78: 0.43680556 | U78: 6.1833333 | V78: 26.816667 | W78: 0.43680556 | X78: 0.47847222 | AA78: =M78-J78 -> -209.19826 | AB78: =M78/J78 -> 0.88377874
B79: 微波小吃 | C79: 韓式部隊鍋 | E79: 57.73 | F79: 1833 | G79: =E79*F79 -> 105819.09 | I79: 22 | J79: 1800 | K79: =J79/I79 -> 81.818182 | L79: 22 | M79: =F79/V79*60 -> 1590.4555 | N79: =M79/L79 -> 72.293433 | O79: =L79-I79 -> 0 | P79: =N79-K79 -> -9.5247486 | Q79: =N79/K79 -> 0.88358641 | S79: 0.47847222 | T79: 0.52649306 | U79: 60 | V79: 69.15 | AA79: =M79-J79 -> -209.54447 | AB79: =M79/J79 -> 0.88358641
B89: 平均 | I89: =AVERAGE(I73:I88) -> 20.571429 | J89: =AVERAGE(J73:J88) -> 3085.7143 | K89: =J89/I89 -> 150 | L89: =AVERAGE(L73:L88) -> 20.571429 | M89: =AVERAGE(M73:M88) -> 2735.0675 | N89: =M89/L89 -> 132.95467 | O89: =L89-I89 -> 0 | P89: =N89-K89 -> -17.04533 | Q89: =N89/K89 -> 0.88636447 | S89: =S73 -> 0.25 | T89: =INDEX(T73:T88,COUNTA(T73:T88)) -> 0.52649306 | AA89: =M89-J89 -> -350.64678 | AB89: =M89/J89 -> 0.88636447
A90: 自動包裝機 | B90: 4℃-飯糰 | C90: 大口法式蕈菇起司雞排飯糰 | E90: 35.83 | F90: 3770 | G90: =E90*F90 -> 135079.1 | I90: 12 | J90: 3273 | K90: =J90/I90 -> 272.75 | L90: 12 | M90: =F90/V90*60 -> 2905.5877 | N90: =M90/L90 -> 242.13231 | O90: =L90-I90 -> 0 | P90: =N90-K90 -> -30.617694 | Q90: =N90/K90 -> 0.88774448 | R90: =Q106 -> 0.87913503 | S90: 0.25010417 | T90: 0.30416667 | V90: 77.85 | AA90: =M90-J90 -> -367.41233 | AB90: =M90/J90 -> 0.88774448 | AC90: =AB106 -> 0.87913503
B91: 4℃-飯糰 | C91: 大口義式香草雞腿排飯糰 | E91: 36.41 | F91: 3179 | G91: =E91*F91 -> 115747.39 | I91: 11 | J91: 3273 | K91: =J91/I91 -> 297.54545 | L91: 11 | M91: =F91/V91*60 -> 2905.4075 | N91: =M91/L91 -> 264.12795 | O91: =L91-I91 -> 0 | P91: =N91-K91 -> -33.417503 | Q91: =N91/K91 -> 0.88768942 | S91: 0.30788194 | T91: 0.35347222 | U91: 5.35 | V91: 65.65 | AA91: =M91-J91 -> -367.59254 | AB91: =M91/J91 -> 0.88768942
B92: 4℃-飯糰 | C92: 大口花椒香麻雞飯糰 | E92: 34.77 | F92: 1249 | G92: =E92*F92 -> 43427.73 | I92: 11 | J92: 3000 | K92: =J92/I92 -> 272.72727 | L92: 11 | M92: =F92/V92*60 -> 2609.6344 | N92: =M92/L92 -> 237.23949 | O92: =L92-I92 -> 0 | P92: =N92-K92 -> -35.487786 | Q92: =N92/K92 -> 0.86987812 | S92: 0.4383912 | T92: 0.45833333 | U92: 6.2833333 | V92: 28.716667 | W92: 0.45833333 | X92: 0.5 | AA92: =M92-J92 -> -390.36564 | AB92: =M92/J92 -> 0.86987812
B93: 4℃-飯糰 | C93: 大口蒜味香腸燒肉雙拼飯糰 | E93: 34.23 | F93: 1498 | G93: =E93*F93 -> 51276.54 | I93: 16 | J93: 3000 | K93: =J93/I93 -> 187.5 | L93: 16 | M93: =F93/V93*60 -> 2608.9985 | N93: =M93/L93 -> 163.06241 | O93: =L93-I93 -> 0 | P93: =N93-K93 -> -24.437591 | Q93: =N93/K93 -> 0.86966618 | S93: 0.5 | T93: 0.52392361 | U93: 60 | V93: 34.45 | AA93: =M93-J93 -> -391.00145 | AB93: =M93/J93 -> 0.86966618
B106: 平均 | I106: =AVERAGE(I90:I105) -> 12.5 | J106: =AVERAGE(J90:J105) -> 3136.5 | K106: =J106/I106 -> 250.92 | L106: =AVERAGE(L90:L105) -> 12.5 | M106: =AVERAGE(M90:M105) -> 2757.407 | N106: =M106/L106 -> 220.59256 | O106: =L106-I106 -> 0 | P106: =N106-K106 -> -30.327439 | Q106: =N106/K106 -> 0.87913503 | S106: =S90 -> 0.25010417 | T106: =INDEX(T90:T105,COUNTA(T90:T105)) -> 0.52392361 | AA106: =M106-J106 -> -379.09299 | AB106: =M106/J106 -> 0.87913503
A107: 自動包裝機3 | B107: 4℃-飯糰 | C107: 肉燥烤飯糰 | E107: 20.11 | F107: 462 | G107: =E107*F107 -> 9290.82 | I107: 6 | J107: 3600 | K107: =J107/I107 -> 600 | L107: 6 | M107: =F107/V107*60 -> 3267.5835 | N107: =M107/L107 -> 544.59725 | O107: =L107-I107 -> 0 | P107: =N107-K107 -> -55.40275 | Q107: =N107/K107 -> 0.90766208 | R107: =Q123 -> 0.90730812 | S107: 0.25 | T107: 0.2558912 | V107: 8.4833333 | AA107: =M107-J107 -> -332.4165 | AB107: =M107/J107 -> 0.90766208 | AC107: =AB123 -> 0.90730812
B108: 4℃-飯糰 | C108: 淡麗清酒蒸蛤蜊烤飯糰 | E108: 24.73 | F108: 1528 | G108: =E108*F108 -> 37787.44 | I108: 6 | J108: 3600 | K108: =J108/I108 -> 600 | L108: 6 | M108: =F108/V108*60 -> 3266.5083 | N108: =M108/L108 -> 544.41805 | O108: =L108-I108 -> 0 | P108: =N108-K108 -> -55.581948 | Q108: =N108/K108 -> 0.90736342 | S108: 0.25902778 | T108: 0.27851852 | U108: 4.5166667 | V108: 28.066667 | AA108: =M108-J108 -> -333.49169 | AB108: =M108/J108 -> 0.90736342
...

Sheet 1030
B1: 屏榮 大溪廠組合室生產人時性分析
B3: 日期 | C3: 114.10.30星期四 | E3: 訂單量 | F3: ='1030(18度C)'!D1+'1030(4度C)'!D1 -> 222624 | H3: 營業額 | I3: ='1030(18度C)'!F1+'1030(4度C)'!F1 -> 6961611.1
B4: 人時性 | C4: 項目 | E4: ➀ | G4: ➁ | I4: ➂ | K4: ④ | M4: ⑤
C5: 組合室 | E5: 全溫層 | G5: 4度C-各編組展開(一配) | I5: 4度C-各編組展開(二配) | K5: 18度C-各編組展開(一配) | M5: 18度C-各編組展開(二配)
C6: 排關平均 | E6: =AVERAGE(D13:O13,D27:X27) -> 460.0931 | F6: =AVERAGE(#REF!,D13:K13) -> #REF! | G6: =AVERAGE(D13:K13) -> 195.64493 | I6: =AVERAGE(L13:O13) -> 95.202399 | K6: =AVERAGE(D27:O27) -> 597.79868 | M6: =AVERAGE(P27:X27) -> 783.48901
C7: 實績平均 | E7: =AVERAGE(D14:O14,D28:X28) -> 405.2499 | F7: =AVERAGE(#REF!,D14:K14) -> #REF! | G7: =AVERAGE(D14:K14) -> 174.68318 | I7: =AVERAGE(L14:O14) -> 84.049539 | K7: =AVERAGE(D28:O28) -> 525.38272 | M7: =AVERAGE(P28:X28) -> 688.33749
C8: 達成率平均 | E8: =AVERAGE(D15:O15,D29:X29) -> 0.88108105 | F8: =AVERAGE(D15:K15,#REF!) -> #REF! | G8: =AVERAGE(D15:K15) -> 0.88563629 | I8: =AVERAGE(L15:O15) -> 0.88287375 | K8: =AVERAGE(D29:O29) -> 0.87816173 | M8: =AVERAGE(P29:X29) -> 0.87807369 | O8: ※現行日本鮮食廠以達成率80%為基本(即為現行KPI)
B10: 溫層 | D10: ➁4度C-各編組展開 | L10: ➂4度C-各編組展開
B11: 編組 | D11: 1 | E11: 2 | F11: 3 | G11: 4 | H11: 5 | I11: 6 | J11: 7 | K11: 8 | L11: 1 | M11: 2 | N11: 3 | O11: 4
D12: 便當一線 | E12: 便當二線 | F12: 涼麵一線 | G12: 涼麵二線 | H12: 涼麵三線 | I12: 自動包裝機 | J12: 自動包裝機2 | K12: 自動包裝機3 | L12: 便當一線 | M12: 便當二線 | N12: 涼麵一線 | O12: 涼麵二線
B13: 人時性 | C13: 排關 | D13: 115.15152 | E13: 80 | F13: 86.486486 | G13: 86.956522 | H13: 150 | I13: 250.92 | J13: - | K13: 600 | L13: - | M13: - | N13: 103.44828 | O13: 86.956522
C14: 實績 | D14: 102.48339 | E14: 70.873946 | F14: 75.134409 | G14: 76.76512 | H14: 132.93228 | I14: 220.58565 | J14: - | K14: 544.00749 | L14: - | M14: - | N14: 91.304672 | O14: 76.794406
C15: 達成率 | D15: =D14/D13 -> 0.88998736 | E15: =E14/E13 -> 0.88592433 | F15: =F14/F13 -> 0.86874161 | G15: =G14/G13 -> 0.88279888 | H15: =H14/H13 -> 0.8862152 | I15: =I14/I13 -> 0.87910749 | J15: - | K15: =K14/K13 -> 0.90667916 | L15: - | M15: - | N15: =N14/N13 -> 0.88261183 | O15: =O14/O13 -> 0.88313567
B16: 作業 時間 | C16: 開始 | D16: 0.25 | E16: 0.25 | F16: 0.16678241 | G16: 0.1669213 | H16: 0.2502662 | I16: 0.16667824 | J16: - | K16: 0.25 | L16: - | M16: - | N16: 0.70833333 | O16: 0.70833333
C17: 結束 | D17: 0.55771991 | E17: 0.59166667 | F17: 0.54861111 | G17: 0.59733796 | H17: 0.55138889 | I17: 0.50283565 | J17: - | K17: 0.31458333 | L17: - | M17: - | N17: 0.82083333 | O17: 0.83958333
B18: 配置人數 | D18: 16.5 | E18: 25 | F18: 22.2 | G18: 23 | H18: 20.571429 | I18: 12.5 | J18: - | K18: 6 | L18: - | M18: - | N18: 19.333333 | O18: 23
B19: 主要應用設備 | D19: L型封口機 | E19: ET-55 | F19: ET-55 | G19: ET-55 | H19: ET-600 | I19: 伺服包裝機 | J19: 伺服包裝機 | K19: 伺服包裝機 | L19: L型封口機 | M19: ET-55 | N19: ET-55 | O19: ET-55
B20: 次要應用設備 | D20: 伺服包裝機 | H20: 伺服包裝機
B21: 備註 | H21: 涼麵+烤飯糰 | I21: 大口飯糰線 | K21: 烤飯糰+手卷
B24: 溫層 | D24: ➃18度C-各編組展開 (一配) | P24: ⑤18度C-各編組展開 (二配)
B25: 編組 | D25: 1 | E25: 2 | F25: 3 | G25: 4 | H25: 5 | I25: 6 | J25: 7 | K25: 8 | L25: 9 | M25: 10 | N25: 11 | O25: 12 | P25: 1 | Q25: 2 | R25: 3 | S25: 4 | T25: 5 | U25: 6 | V25: 7 | W25: 8 | X25: 9
D26: 便當一線 | E26: 涼麵一線 | F26: 涼麵三線 | G26: 自動包裝機 | H26: 自動包裝機2 | I26: 自動包裝機3 | J26: 味付飯糰線B | K26: (舊) 3300型飯糰線 | L26: 3000型飯糰線 | M26: (新) 3300型飯糰機 | N26: GKK3600型 飯糰機 | O26: GKK3600型 飯糰機2 | P26: 自動包裝機 | Q26: 自動包裝機2 | R26: 自動包裝機3 | S26: 味付飯糰線B | T26: (舊) 3300型飯糰線 | U26: 3000型飯糰線 | V26: (新) 3300型飯糰機 | W26: GKK3600型 飯糰機 | X26: GKK3600型 飯糰機2
B27: 人時性 | C27: 排關 | D27: 211.76471 | E27: - | F27: - | G27: 313.04348 | H27: 433.33333 | I27: 416.66667 | J27: - | K27: - | L27: - | M27: 825 | N27: 1150 | O27: 834.78261 | P27: 285.71429 | Q27: - | R27: - | S27: - | T27: 787.5 | U27: - | V27: 825 | W27: 969.23077 | X27: 1050
C28: 實績 | D28: 182.99097 | E28: - | F28: - | G28: 272.53827 | H28: 383.33307 | I28: 369.55494 | J28: - | K28: - | L28: - | M28: 733.74161 | N28: 997.52653 | O28: 737.99366 | P28: 248.79832 | Q28: - | R28: - | S28: - | T28: 694.21774 | U28: - | V28: 733.48545 | W28: 854.59769 | X28: 910.58826
C29: 達成率 | D29: =D28/D27 -> 0.86412404 | E29: - | F29: - | G29: =G28/G27 -> 0.87060837 | H29: =H28/H27 -> 0.88461478 | I29: =I28/I27 -> 0.88693186 | J29: - | K29: - | L29: - | M29: =M28/M27 -> 0.88938377 | N29: =N28/N27 -> 0.86741437 | O29: =O28/O27 -> 0.88405491 | P29: =P28/P27 -> 0.87079413 | Q29: - | R29: - | S29: - | T29: =T28/T27 -> 0.88154633 | U29: - | V29: =V28/V27 -> 0.88907327 | W29: =W28/W27 -> 0.88172777 | X29: =X28/X27 -> 0.86722692
B30: 作業 時間 | C30: 開始 | D30: 0.39603009 | E30: - | F30: - | G30: 0.32708333 | H30: 0.25 | I30: 0.3181713 | J30: - | K30: - | L30: - | M30: 0.16666667 | N30: 0.1668287 | O30: 0.16666667 | P30: 0.7083912 | Q30: - | R30: - | S30: - | T30: 0.70833333 | U30: - | V30: 0.70866898 | W30: 0.70833333 | X30: 0.70833333
C31: 結束 | D31: 0.46697917 | E31: - | F31: - | G31: 0.40277778 | H31: 0.36895833 | I31: 0.42152778 | J31: - | K31: - | L31: - | M31: 0.42013889 | N31: 0.43201389 | O31: 0.39586806 | P31: 0.87013889 | Q31: - | R31: - | S31: - | T31: 0.88967593 | U31: - | V31: 0.89877315 | W31: 1.0029745 | X31: 1.0034722
B32: 配置人數 | D32: 17 | E32: - | F32: - | G32: 11.5 | H32: 6 | I32: 6 | J32: - | K32: - | L32: - | M32: 4 | N32: 3 | O32: 3.8333333 | P32: 12.6 | Q32: - | R32: - | S32: - | T32: 4 | U32: - | V32: 4 | W32: 3.25 | X32: 3.3333333
B33: 主要應用設備 | D33: 伺服包裝機 | E33: ET-55 | F33: ET-600 | G33: 夾心型 | H33: 伺服包裝機 | I33: 伺服包裝機 | J33: 夾心型 | K33: 3300型 | L33: 3300型 | M33: 3300型 | N33: GKK | O33: GKK | P33: 夾心型 | Q33: 伺服包裝機 | R33: 伺服包裝機 | S33: 夾心型 | T33: 3300型 | U33: 3300型 | V33: 3300型 | W33: GKK | X33: GKK
B34: 次要應用設備
B35: 備註

Sheet 1030(18度C)
A1: 大溪廠日報分析 | C1: 總生產量 | D1: =SUM(F5:F208) -> 131185 | E1: 營業額 | F1: =SUM(G5:G208) -> 2638791.4 | G1: 出勤人數 | H1: =L21+L38+L55+L72+L89+L106+L123+L140+L157+L174+L191+L208 -> 78.516667 | I1: 產線配置圖 | L1: 生產實績 | O1: 人時性差異分析 | S1: 日報登錄 | Y1: 分析說明 | AA1: 產能差異分析
A2: 45960 | C2: 人時性 | D2: =AVERAGE(N21,N38,N55,N72,N89,N106,N123,N140,N157,N174,N191,N208) -> 593.28054 | E2: 平均廠價 | F2: =F1/D1 -> 20.115039 | G2: 多次生產數 | H2: =COUNT(H5:H208) -> 3
A3: 線別 | B3: 品類 | C3: 品名 | E3: 廠價 | F3: 生產量 | G3: 營收 | H3: 多次 生產 | I3: 人數 | J3: 產能/時 | K3: 人時性 | L3: 人數 | M3: 產能/時 | N3: 人時性 | O3: 人數 | P3: 人時性 | Q3: 達成率 | R3: 達成率 平均 | S3: 生產時間 | U3: 換線、休息/分 | V3: 稼動時間/分 | W3: 休息時間 | Y3: (屏榮回填) | AA3: 產能/時 | AB3: 達成率 | AC3: 達成率平均
S4: 開始 | T4: 結束 | W4: 開始 | X4: 結束
A5: 便當一線 | B5: 18℃-壽司手卷 | C5: 一配海饌雙手卷 | E5: 29.85 | F5: 2526 | G5: =E5*F5 -> 75401.1 | I5: 17 | J5: 3600 | K5: =J5/I5 -> 211.76471 | L5: 17 | M5: =F5/V5*60 -> 3111.0503 | N5: =M5/L5 -> 183.00296 | O5: =L5-I5 -> 0 | P5: =N5-K5 -> -28.761748 | Q5: =N5/K5 -> 0.86418064 | R5: =Q21 -> 0.86412404 | S5: 0.39603009 | T5: 0.42986111 | U5: 6.2833333 | V5: 48.716667 | AA5: =M5-J5 -> -488.94971 | AB5: =M5/J5 -> 0.86418064 | AC5: =AB21 -> 0.86412404
B6: 18℃-壽司手卷 | C6: 一配雙饗雙手卷 | E6: 29.52 | F6: 2460 | G6: =E6*F6 -> 72619.2 | I6: 17 | J6: 3600 | K6: =J6/I6 -> 211.76471 | L6: 17 | M6: =F6/V6*60 -> 3110.6428 | N6: =M6/L6 -> 182.97899 | O6: =L6-I6 -> 0 | P6: =N6-K6 -> -28.785719 | Q6: =N6/K6 -> 0.86406744 | S6: 0.43402778 | T6: 0.46697917 | U6: 6 | V6: 47.45 | W6: 0.46697917 | X6: 0.50763889 | AA6: =M6-J6 -> -489.35722 | AB6: =M6/J6 -> 0.86406744
B21: 平均 | I21: =AVERAGE(I5:I20) -> 17 | J21: =AVERAGE(J5:J20) -> 3600 | K21: =J21/I21 -> 211.76471 | L21: =AVERAGE(L5:L20) -> 17 | M21: =AVERAGE(M5:M20) -> 3110.8465 | N21: =M21/L21 -> 182.99097 | O21: =L21-I21 -> 0 | P21: =N21-K21 -> -28.773733 | Q21: =N21/K21 -> 0.86412404 | S21: =S5 -> 0.39603009 | T21: =INDEX(T5:T20,COUNTA(T5:T20)) -> 0.46697917 | AA21: =M21-J21 -> -489.15346 | AB21: =M21/J21 -> 0.86412404
A22: 自動包裝機 | B22: 18℃-壽司手卷 | C22: 一配長野稻荷壽司 | E22: 25.64 | F22: 1517 | G22: =E22*F22 -> 38895.88 | I22: 11 | J22: 3600 | K22: =J22/I22 -> 327.27273 | L22: 11 | M22: =F22/V22*60 -> 3135.0172 | N22: =M22/L22 -> 285.00157 | O22: =L22-I22 -> 0 | P22: =N22-K22 -> -42.271162 | Q22: =N22/K22 -> 0.87083812 | R22: =Q38 -> 0.87060837 | S22: 0.32708333 | T22: 0.34724537 | U22: 4.6166667 | V22: 29.033333 | AA22: =M22-J22 -> -464.98278 | AB22: =M22/J22 -> 0.87083812 | AC22: =AB38 -> 0.87060837
B23: 18℃-飯糰 | C23: 一配兩粒飯糰(鮪魚.焦糖鮭魚) | E23: 27.14 | F23: 3908 | G23: =E23*F23 -> 106063.12 | I23: 12 | J23: 3600 | K23: =J23/I23 -> 300 | L23: 12 | M23: =F23/V23*60 -> 3133.363 | N23: =M23/L23 -> 261.11359 | O23: =L23-I23 -> 0 | P23: =N23-K23 -> -38.886414 | Q23: =N23/K23 -> 0.87037862 | S23: 0.35081019 | T23: 0.40277778 | U23: 5.1333333 | V23: 74.833333 | AA23: =M23-J23 -> -466.63697 | AB23: =M23/J23 -> 0.87037862
B38: 平均 | I38: =AVERAGE(I22:I37) -> 11.5 | J38: =AVERAGE(J22:J37) -> 3600 | K38: =J38/I38 -> 313.04348 | L38: =AVERAGE(L22:L37) -> 11.5 | M38: =AVERAGE(M22:M37) -> 3134.1901 | N38: =M38/L38 -> 272.53827 | O38: =L38-I38 -> 0 | P38: =N38-K38 -> -40.505206 | Q38: =N38/K38 -> 0.87060837 | S38: =S22 -> 0.32708333 | T38: =INDEX(T22:T37,COUNTA(T22:T37)) -> 0.40277778 | AA38: =M38-J38 -> -465.80987 | AB38: =M38/J38 -> 0.87060837
A39: 自動包裝機2 | B39: 18℃-壽司手卷 | C39: 一配雙鬆細卷 | E39: 14.03 | F39: 2457 | G39: =E39*F39 -> 34471.71 | I39: 6 | J39: 2600 | K39: =J39/I39 -> 433.33333 | L39: 6 | M39: =F39/V39*60 -> 2299.844 | N39: =M39/L39 -> 383.30733 | O39: =L39-I39 -> 0 | P39: =N39-K39 -> -50.026001 | Q39: =N39/K39 -> 0.88455538 | R39: =Q55 -> 0.88461478 | S39: 0.25 | T39: 0.29451389 | V39: 64.1 | AA39: =M39-J39 -> -300.15601 | AB39: =M39/J39 -> 0.88455538 | AC39: =AB55 -> 0.88461478
B40: 18℃-壽司手卷 | C40: 一配香濃起司蟹風味棒細卷 | E40: 17.73 | F40: 1554 | G40: =E40*F40 -> 27552.42 | I40: 6 | J40: 2600 | K40: =J40/I40 -> 433.33333 | L40: 6 | M40: =F40/V40*60 -> 2300.3289 | N40: =M40/L40 -> 383.38816 | O40: =L40-I40 -> 0 | P40: =N40-K40 -> -49.945175 | Q40: =N40/K40 -> 0.8847419 | S40: 0.29824074 | T40: 0.32638889 | U40: 5.3666667 | V40: 40.533333 | AA40: =M40-J40 -> -299.67105 | AB40: =M40/J40 -> 0.8847419
B41: 18℃-壽司手卷 | C41: 一配經典鮪魚沙拉細卷 | E41: 14.49 | F41: 2158 | G41: =E41*F41 -> 31269.42 | I41: 6 | J41: 2600 | K41: =J41/I41 -> 433.33333 | L41: 6 | M41: =F41/V41*60 -> 2299.8224 | N41: =M41/L41 -> 383.30373 | O41: =L41-I41 -> 0 | P41: =N41-K41 -> -50.029603 | Q41: =N41/K41 -> 0.88454707 | S41: 0.32986111 | T41: 0.36895833 | U41: 5 | V41: 56.3 | AA41: =M41-J41 -> -300.17762 | AB41: =M41/J41 -> 0.88454707
B55: 平均 | I55: =AVERAGE(I39:I54) -> 6 | J55: =AVERAGE(J39:J54) -> 2600 | K55: =J55/I55 -> 433.33333 | L55: =AVERAGE(L39:L54) -> 6 | M55: =AVERAGE(M39:M54) -> 2299.9984 | N55: =M55/L55 -> 383.33307 | O55: =L55-I55 -> 0 | P55: =N55-K55 -> -50.00026 | Q55: =N55/K55 -> 0.88461478 | S55: =S39 -> 0.25 | T55: =INDEX(T39:T54,COUNTA(T39:T54)) -> 0.36895833 | AA55: =M55-J55 -> -300.00156 | AB55: =M55/J55 -> 0.88461478
A56: 自動包裝機3 | B56: 18℃-壽司手卷 | C56: 一配滿滿海鮮沙拉脆卷 | E56: 19.39 | F56: 2100 | G56: =E56*F56 -> 40719 | I56: 6 | J56: 2500 | K56: =J56/I56 -> 416.66667 | L56: 6 | M56: =F56/V56*60 -> 2217.0088 | N56: =M56/L56 -> 369.50147 | O56: =L56-I56 -> 0 | P56: =N56-K56 -> -47.1652 | Q56: =N56/K56 -> 0.88680352 | R56: =Q72 -> 0.88693186 | S56: 0.3181713 | T56: 0.35763889 | U56: 5.1666667 | V56: 56.833333 | AA56: =M56-J56 -> -282.9912 | AB56: =M56/J56 -> 0.88680352 | AC56: =AB72 -> 0.88693186
B57: 18℃-壽司手卷 | C57: 一配明太子玉子脆卷 | E57: 19.7 | F57: 3162 | G57: =E57*F57 -> 62291.4 | I57: 6 | J57: 2500 | K57: =J57/I57 -> 416.66667 | L57: 6 | M57: =F57/V57*60 -> 2217.6505 | N57: =M57/L57 -> 369.60842 | O57: =L57-I57 -> 0 | P57: =N57-K57 -> -47.058251 | Q57: =N57/K57 -> 0.8870602 | S57: 0.36211806 | T57: 0.42152778 | U57: 6.45 | V57: 85.55 | AA57: =M57-J57 -> -282.3495 | AB57: =M57/J57 -> 0.8870602
B72: 平均 | I72: =AVERAGE(I56:I71) -> 6 | J72: =AVERAGE(J56:J71) -> 2500 | K72: =J72/I72 -> 416.66667 | L72: =AVERAGE(L56:L71) -> 6 | M72: =AVERAGE(M56:M71) -> 2217.3296 | N72: =M72/L72 -> 369.55494 | O72: =L72-I72 -> 0 | P72: =N72-K72 -> -47.111725 | Q72: =N72/K72 -> 0.88693186 | S72: =S56 -> 0.3181713 | T72: =INDEX(T56:T71,COUNTA(T56:T71)) -> 0.42152778 | AA72: =M72-J72 -> -282.67035 | AB72: =M72/J72 -> 0.88693186
A73: (新) 3300型飯糰機 | B73: 18℃-飯糰 | C73: 一配照燒雞肉飯糰 | E73: 21.45 | F73: 2899 | G73: =E73*F73 -> 62183.55 | I73: 4 | J73: 3300 | K73: =J73/I73 -> 825 | L73: 4 | M73: =F73/V73*60 -> 2940.6593 | N73: =M73/L73 -> 735.16484 | O73: =L73-I73 -> 0 | P73: =N73-K73 -> -89.835165 | Q73: =N73/K73 -> 0.89110889 | R73: =Q89 -> 0.88938377 | S73: 0.16666667 | T73: 0.20774306 | V73: 59.15 | AA73: =M73-J73 -> -359.34066 | AB73: =M73/J73 -> 0.89110889 | AC73: =AB89 -> 0.88938377
B74: 18℃-飯糰 | C74: 一配鹽蔥燒肉飯糰 | E74: 17.89 | F74: 3221 | G74: =E74*F74 -> 57623.69 | I74: 4 | J74: 3300 | K74: =J74/I74 -> 825 | L74: 4 | M74: =F74/V74*60 -> 2936.3383 | N74: =M74/L74 -> 734.08458 | O74: =L74-I74 -> 0 | P74: =N74-K74 -> -90.915422 | Q74: =N74/K74 -> 0.88979949 | S74: 0.21193287 | T74: 0.25763889 | U74: 6.0333333 | V74: 65.816667 | AA74: =M74-J74 -> -363.66169 | AB74: =M74/J74 -> 0.88979949
B75: 18℃-飯糰 | C75: 一配壹號醬炙烤牛飯糰 | E75: 22.28 | F75: 1336 | G75: =E75*F75 -> 29766.08 | I75: 5 | J75: 3300 | K75: =J75/I75 -> 660 | L75: 5 | M75: =F75/V75*60 -> 2932.6829 | N75: =M75/L75 -> 586.53659 | O75: =L75-I75 -> 0 | P75: =N75-K75 -> -73.463415 | Q75: =N75/K75 -> 0.8886918 | S75: 0.26111111 | T75: 0.28009259 | U75: 5 | V75: 27.333333 | AA75: =M75-J75 -> -367.31707 | AB75: =M75/J75 -> 0.8886918
B76: 18℃-飯糰 | C76: 一配椒鹽檸檬鯖魚飯糰 | E76: 21.45 | F76: 4033 | G76: =E76*F76 -> 86507.85 | I76: 3 | J76: 3300 | K76: =J76/I76 -> 1100 | L76: 3 | M76: =F76/V76*60 -> 2932.4985 | N76: =M76/L76 -> 977.4995 | O76: =L76-I76 -> 0 | P76: =N76-K76 -> -122.5005 | Q76: =N76/K76 -> 0.8886359 | S76: 0.28366898 | T76: 0.34097222 | U76: 5.15 | V76: 82.516667 | AA76: =M76-J76 -> -367.50151 | AB76: =M76/J76 -> 0.8886359
B77: 18℃-飯糰 | C77: 一配雞肉飯飯糰 | E77: 16.66 | F77: 5269 | G77: =E77*F77 -> 87781.54 | I77: 4 | J77: 3300 | K77: =J77/I77 -> 825 | L77: 4 | M77: =F77/V77*60 -> 2932.6531 | N77: =M77/L77 -> 733.16327 | O77: =L77-I77 -> 0 | P77: =N77-K77 -> -91.836735 | Q77: =N77/K77 -> 0.88868275 | S77: 0.34527778 | T77: 0.42013889 | U77: 6.2 | V77: 107.8 | AA77: =M77-J77 -> -367.34694 | AB77: =M77/J77 -> 0.88868275
B89: 平均 | I89: =AVERAGE(I73:I88) -> 4 | J89: =AVERAGE(J73:J88) -> 3300 | K89: =J89/I89 -> 825 | L89: =AVERAGE(L73:L88) -> 4 | M89: =AVERAGE(M73:M88) -> 2934.9664 | N89: =M89/L89 -> 733.74161 | O89: =L89-I89 -> 0 | P89: =N89-K89 -> -91.258394 | Q89: =N89/K89 -> 0.88938377 | S89: =S73 -> 0.16666667 | T89: =INDEX(T73:T88,COUNTA(T73:T88)) -> 0.42013889 | AA89: =M89-J89 -> -365.03357 | AB89: =M89/J89 -> 0.88938377
A90: GKK3600型 飯糰機 | B90: 18℃-飯糰 | C90: 一配蔬食鮪魚飯糰 | E90: 18.18 | F90: 1796 | G90: =E90*F90 -> 32651.28 | I90: 3 | J90: 3600 | K90: =J90/I90 -> 1200 | L90: 3 | M90: =F90/V90*60 -> 3099.5206 | N90: =M90/L90 -> 1033.1735 | O90: =L90-I90 -> 0 | P90: =N90-K90 -> -166.82646 | Q90: =N90/K90 -> 0.86097795 | R90: =Q106 -> 0.86741437 | S90: 0.1668287 | T90: 0.19097222 | V90: 34.766667 | AA90: =M90-J90 -> -500.47939 | AB90: =M90/J90 -> 0.86097795 | AC90: =AB106 -> 0.86741437
B91: 18℃-飯糰 | C91: 一配明太子龍蝦風味沙拉飯糰 | E91: 18.18 | F91: 2592 | G91: =E91*F91 -> 47122.56 | I91: 3 | J91: 3600 | K91: =J91/I91 -> 1200 | L91: 3 | M91: =F91/V91*60 -> 3100.0664 | N91: =M91/L91 -> 1033.3555 | O91: =L91-I91 -> 0 | P91: =N91-K91 -> -166.64452 | Q91: =N91/K91 -> 0.86112957 | S91: 0.20277778 | T91: 0.23761574 | U91: 17 | V91: 50.166667 | AA91: =M91-J91 -> -499.93355 | AB91: =M91/J91 -> 0.86112957
B92: 18℃-飯糰 | C92: 一配鮪魚飯糰 | E92: 14.28 | F92: 6512 | G92: =E92*F92 -> 92991.36 | I92: 3 | J92: 3600 | K92: =J92/I92 -> 1200 | L92: 3 | M92: =F92/V92*60 -> 3100.9524 | N92: =M92/L92 -> 1033.6508 | O92: =L92-I92 -> 0 | P92: =N92-K92 -> -166.34921 | Q92: =N92/K92 -> 0.86137566 | S92: 0.24861111 | T92: 0.33611111 | U92: 15.833333 | V92: 126 | AA92: =M92-J92 -> -499.04762 | AB92: =M92/J92 -> 0.86137566
B93: 18℃-飯糰 | C93: 一配經典肉鬆飯糰 | E93: 14.03 | F93: 5433 | G93: =E93*F93 -> 76224.99 | I93: 3 | J93: 3000 | K93: =J93/I93 -> 1000 | L93: 3 | M93: =F93/V93*60 -> 2669.7789 | N93: =M93/L93 -> 889.92629 | O93: =L93-I93 -> 0 | P93: =N93-K93 -> -110.07371 | Q93: =N93/K93 -> 0.88992629 | S93: 0.34722222 | T93: 0.43201389 | U93: 16 | V93: 122.1 | AA93: =M93-J93 -> -330.22113 | AB93: =M93/J93 -> 0.88992629
B106: 平均 | I106: =AVERAGE(I90:I105) -> 3 | J106: =AVERAGE(J90:J105) -> 3450 | K106: =J106/I106 -> 1150 | L106: =AVERAGE(L90:L105) -> 3 | M106: =AVERAGE(M90:M105) -> 2992.5796 | N106: =M106/L106 -> 997.52653 | O106: =L106-I106 -> 0 | P106: =N106-K106 -> -152.47347 | Q106: =N106/K106 -> 0.86741437 | S106: =S90 -> 0.1668287 | T106: =INDEX(T90:T105,COUNTA(T90:T105)) -> 0.43201389 | AA106: =M106-J106 -> -457.42042 | AB106: =M106/J106 -> 0.86741437
A107: GKK3600型 飯糰機2 | B107: 18℃-飯糰 | C107: 一配熟成紅鮭飯糰 | E107: 25.03 | F107: 1896 | G107: =E107*F107 -> 47456.88 | I107: 4 | J107: 3300 | K107: =J107/I107 -> 825 | L107: 4 | M107: =F107/V107*60 -> 2903.2752 | N107: =M107/L107 -> 725.8188 | O107: =L107-I107 -> 0 | P107: =N107-K107 -> -99.181199 | Q107: =N107/K107 -> 0.87978036 | R107: =Q123 -> 0.88405491 | S107: 0.16666667 | T107: 0.19387731 | V107: 39.183333 | AA107: =M107-J107 -> -396.7248 | AB107: =M107/J107 -> 0.87978036 | AC107: =AB123 -> 0.88405491
B108: 18℃-飯糰 | C108: 一配博多明太子奶油飯糰 | E108: 25.45 | F108: 1528 | G108: =E108*F108 -> 38887.6 | I108: 4 | J108: 3300 | K108: =J108/I108 -> 825 | L108: 4 | M108: =F108/V108*60 -> 2902.7968 | N108: =M108/L108 -> 725.69921 | O108: =L108-I108 -> 0 | P108: =N108-K108 -> -99.300792 | Q108: =N108/K108 -> 0.8796354 | S108: 0.20515046 | T108: 0.22708333 | U108: 16.233333 | V108: 31.583333 | AA108: =M108-J108 -> -397.20317 | AB108: =M108/J108 -> 0.8796354
B109: 18℃-飯糰 | C109: 一配照燒鰤魚大根飯糰 | E109: 26.73 | F109: 415 | G109: =E109*F109 -> 11092.95 | I109: 4 | J109: 3300 | K109: =J109/I109 -> 825 | L109: 4 | M109: =F109/V109*60 -> 2906.6148 | N109: =M109/L109 -> 726.6537 | O109: =L109-I109 -> 0 | P109: =N109-K109 -> -98.346304 | Q109: =N109/K109 -> 0.88079236 | S109: 0.23918981 | T109: 0.24513889 | U109: 17.433333 | V109: 8.5666667 | AA109: =M109-J109 -> -393.38521 | AB109: =M109/J109 -> 0.88079236
B110: 18℃-飯糰 | C110: 一配筋子銀鮭飯糰 | E110: 30 | F110: 2223 | G110: =E110*F110 -> 66690 | I110: 4 | J110: 3000 | K110: =J110/I110 -> 750 | L110: 4 | M110: =F110/V110*60 -> 2679.2099 | N110: =M110/L110 -> 669.80248 | O110: =L110-I110 -> 0 | P110: =N110-K110 -> -80.197523 | Q110: =N110/K110 -> 0.89306997 | S110: 0.25570602 | T110: 0.29027778 | U110: 15.216667 | V110: 49.783333 | AA110: =M110-J110 -> -320.79009 | AB110: =M110/J110 -> 0.89306997
B111: 18℃-飯糰 | C111: 一配北海道秋鮭親子飯糰 | E111: 24.82 | F111: 2030 | G111: =E111*F111 -> 50384.6 | I111: 4 | J111: 3300 | K111: =J111/I111 -> 825 | L111: 4 | M111: =F111/V111*60 -> 2903.4565 | N111: =M111/L111 -> 725.86412 | O111: =L111-I111 -> 0 | P111: =N111-K111 -> -99.135876 | Q111: =N111/K111 -> 0.8798353 | S111: 0.30211806 | T111: 0.33125 | U111: 17.05 | V111: 41.95 | AA111: =M111-J111 -> -396.5435 | AB111: =M111/J111 -> 0.8798353
B112: 18℃-飯糰 | C112: 一配贅沢鮭魚肚飯糰 | E112: 30 | F112: 3395 | G112: =E112*F112 -> 101850 | I112: 3 | J112: 3000 | K112: =J112/I112 -> 1000 | L112: 3 | M112: =F112/V112*60 -> 2678.501 | N112: =M112/L112 -> 892.83366 | O112: =L112-I112 -> 0 | P112: =N112-K112 -> -107.16634 | Q112: =N112/K112 -> 0.89283366 | S112: 0.34305556 | T112: 0.39586806 | U112: 17 | V112: 76.05 | AA112: =M112-J112 -> -321.49901 | AB112: =M112/J112 -> 0.89283366
B123: 平均 | I123: =AVERAGE(I107:I122) -> 3.8333333 | J123: =AVERAGE(J107:J122) -> 3200 | K123: =J123/I123 -> 834.78261 | L123: =AVERAGE(L107:L122) -> 3.8333333 | M123: =AVERAGE(M107:M122) -> 2828.9757 | N123: =M123/L123 -> 737.99366 | O123: =L123-I123 -> 0 | P123: =N123-K123 -> -96.788947 | Q123: =N123/K123 -> 0.88405491 | S123: =S107 -> 0.16666667 | T123: =INDEX(T107:T122,COUNTA(T107:T122)) -> 0.39586806 | AA123: =M123-J123 -> -371.0243 | AB123: =M123/J123 -> 0.88405491
A124: 自動包裝機 (二配) | B124: 18℃-飯糰 | C124: 二配兔兔昆布飯糰 | E124: 13.42 | F124: 314 | G124: =E124*F124 -> 4213.88 | I124: 6 | J124: 3600 | K124: =J124/I124 -> 600 | L124: 6 | M124: =F124/V124*60 -> 3184.2254 | N124: =M124/L124 -> 530.70423 | O124: =L124-I124 -> 0 | P124: =N124-K124 -> -69.295775 | Q124: =N124/K124 -> 0.88450704 | R124: =Q140 -> 0.87079413 | S124: 0.7083912 | T124: 0.7125 | V124: 5.9166667 | AA124: =M124-J124 -> -415.77465 | AB124: =M124/J124 -> 0.88450704 | AC124: =AB140 -> 0.87079413
B125: 18℃-壽司手卷 | C125: 二配長野稻荷壽司 | E125: 25.64 | F125: 1943 | G125: =E125*F125 -> 49818.52 | I125: 11 | J125: 3600 | K125: =J125/I125 -> 327.27273 | L125: 11 | M125: =F125/V125*60 -> 3136.6816 | N125: =M125/L125 -> 285.15287 | O125: =L125-I125 -> 0 | P125: =N125-K125 -> -42.119853 | Q125: =N125/K125 -> 0.87130045 | S125: 0.71597222 | T125: 0.74178241 | U125: 5 | V125: 37.166667 | AA125: =M125-J125 -> -463.31839 | AB125: =M125/J125 -> 0.87130045
B126: 18℃-壽司手卷 | C126: 二配雙饗雙手卷 | E126: 29.52 | F126: 2348 | G126: =E126*F126 -> 69312.96 | I126: 17 | J126: 3600 | K126: =J126/I126 -> 211.76471 | L126: 17 | M126: =F126/V126*60 -> 3108.79 | N126: =M126/L126 -> 182.87 | O126: =L126-I126 -> 0 | P126: =N126-K126 -> -28.894706 | Q126: =N126/K126 -> 0.86355278 | S126: 0.74513889 | T126: 0.7766088 | U126: 4.8333333 | V126: 45.316667 | AA126: =M126-J126 -> -491.21 | AB126: =M126/J126 -> 0.86355278
B127: 18℃-壽司手卷 | C127: 二配海饌雙手卷 | E127: 29.85 | F127: 2394 | G127: =E127*F127 -> 71460.9 | I127: 17 | J127: 3600 | K127: =J127/I127 -> 211.76471 | L127: 17 | M127: =F127/V127*60 -> 3111.3357 | N127: =M127/L127 -> 183.01975 | O127: =L127-I127 -> 0 | P127: =N127-K127 -> -28.744956 | Q127: =N127/K127 -> 0.86425993 | S127: 0.78055556 | T127: 0.81261574 | U127: 5.6833333 | V127: 46.166667 | AA127: =M127-J127 -> -488.66426 | AB127: =M127/J127 -> 0.86425993
B128: 18℃-飯糰 | C128: 二配兩粒飯糰(鮪魚.焦糖鮭魚) | E128: 28.57 | F128: 4048 | G128: =E128*F128 -> 115651.36 | I128: 12 | J128: 3600 | K128: =J128/I128 -> 300 | L128: 12 | M128: =F128/V128*60 -> 3133.2617 | N128: =M128/L128 -> 261.10514 | O128: =L128-I128 -> 0 | P128: =N128-K128 -> -38.894861 | Q128: =N128/K128 -> 0.87035046 | S128: 0.81630787 | T128: 0.87013889 | U128: 5.3166667 | V128: 77.516667 | AA128: =M128-J128 -> -466.73834 | AB128: =M128/J128 -> 0.87035046
...

Sheet 1030(4度C)
