Workbook

Sheet 1231
B1: 屏榮 大溪廠組合室生產人時性分析
B3: 日期 | C3: 114.12.31星期三 | E3: 訂單量 | F3: ='1231(18度C)'!D1+'1231(4度C)'!D1 -> 129015 | H3: 營業額 | I3: ='1231(18度C)'!F1+'1231(4度C)'!F1 -> 3992684.9
B4: 人時性 | C4: 項目 | E4: ➀ | G4: ➁ | I4: ➂ | K4: ④ | M4: ⑤ | O4: 異常停線 | Q4: 短暫停線
C5: 組合室 | E5: 全溫層 | G5: 4度C-各編組展開(一配) | I5: 4度C-各編組展開(二配) | K5: 18度C-各編組展開(一配) | M5: 18度C-各編組展開(二配) | O5: 合計次數 | P5: 時間 | Q5: 合計次數 | R5: 設備次數
C6: 排關平均 | E6: =AVERAGE(D14:O14,D32:X32) -> 498.79134 | F6: =AVERAGE(#REF!,D14:K14) -> #REF! | G6: =AVERAGE(D14:K14) -> 196.89372 | I6: =AVERAGE(L14:O14) -> 96.103896 | K6: =AVERAGE(D32:O32) -> 703.4 | M6: =AVERAGE(P32:X32) -> 757.15528 | O6: ='[1]1201(4度C)'!Y2 -> 0 | P6: ='[1]1201(4度C)'!Z2 -> 0 | Q6: ='[1]1201(4度C)'!AC2 -> 0 | R6: ='[1]1201(4度C)'!AD2 -> 0
C7: 實績平均 | E7: =AVERAGE(D15:O15,D33:X33) -> 440.80433 | F7: =AVERAGE(#REF!,D15:K15) -> #REF! | G7: =AVERAGE(D15:K15) -> 176.83643 | I7: =AVERAGE(L15:O15) -> 85.109593 | K7: =AVERAGE(D33:O33) -> 619.06698 | M7: =AVERAGE(P33:X33) -> 668.78748
C8: 達成率平均 | E8: =AVERAGE(D16:O16,D34:X34) -> 0.88455089 | F8: =AVERAGE(D16:K16,#REF!) -> #REF! | G8: =AVERAGE(D16:K16) -> 0.89075379 | I8: =AVERAGE(L16:O16) -> 0.88559533 | K8: =AVERAGE(D34:O34) -> 0.88082517 | M8: =AVERAGE(P34:X34) -> 0.88165592
O9: ※現行日本鮮食廠以達成率80%為基本(即為現行KPI)
B11: 溫層 | D11: ➁4度C-各編組展開 | L11: ➂4度C-各編組展開
B12: 編組 | D12: 1 | E12: 2 | F12: 3 | G12: 4 | H12: 5 | I12: 6 | J12: 7 | K12: 8 | L12: 1 | M12: 2 | N12: 3 | O12: 4
D13: 便當一線 | E13: 便當二線 | F13: 涼麵一線 | G13: 涼麵二線 | H13: 涼麵三線 | I13: 自動包裝機 | J13: 自動包裝機2 | K13: 自動包裝機3 | L13: 便當一線 | M13: 便當二線 | N13: 涼麵一線 | O13: 涼麵二線
B14: 人時性 | C14: 排關 | D14: - | E14: 97.391304 | F14: 96.842105 | G14: 86.956522 | H14: 103.27869 | I14: 600 | J14: - | K14: - | L14: - | M14: 101.2987 | N14: 90.909091 | O14: -
C15: 實績 | D15: - | E15: 86.52022 | F15: 85.942399 | G15: 77.079454 | H15: 91.542846 | I15: 543.09724 | J15: - | K15: - | L15: - | M15: 89.718071 | N15: 80.501115 | O15: -
C16: 達成率 | D16: - | E16: =E15/E14 -> 0.88837726 | F16: =F15/F14 -> 0.88744868 | G16: =G15/G14 -> 0.88641372 | H16: =H15/H14 -> 0.88636724 | I16: =I15/I14 -> 0.90516206 | J16: - | K16: - | L16: - | M16: =M15/M14 -> 0.8856784 | N16: =N15/N14 -> 0.88551226 | O16: -
B17: 作業 時間 | C17: 開始 | D17: - | E17: 0.29166667 | F17: 0.29166667 | G17: 0.29185185 | H17: 0.29166667 | I17: 0.34730324 | J17: - | K17: - | L17: - | M17: 0.70855324 | N17: 0.70833333 | O17: -
C18: 結束 | D18: - | E18: 0.56478009 | F18: 0.58974537 | G18: 0.4619213 | H18: 0.44469907 | I18: 0.35694444 | J18: - | K18: - | L18: - | M18: 0.85373843 | N18: 0.86666667 | O18: -
B19: 產線異常 (5分鐘以上) | C19: 次數
C20: 時間/分
B21: 短暫停線 (5分鐘以下) | C21: 次數
C22: 設備次數
B23: 配置人數 | D23: - | E23: 23 | F23: 19 | G23: 23 | H23: 20.333333 | I23: 6 | J23: - | K23: - | L23: - | M23: 19.25 | N23: 22 | O23: -
B24: 主要應用設備 | D24: L型封口機 | E24: ET-55 | F24: ET-55 | G24: ET-55 | H24: ET-600 | I24: 伺服包裝機 | J24: 伺服包裝機 | K24: 伺服包裝機 | L24: L型封口機 | M24: ET-55 | N24: ET-55 | O24: ET-55
B25: 次要應用設備 | D25: 伺服包裝機 | H25: 伺服包裝機
B26: 備註 | H26: 涼麵+烤飯糰 | I26: 大口飯糰線 | K26: 烤飯糰+手卷
B29: 溫層 | D29: ➃18度C-各編組展開 (一配) | P29: ⑤18度C-各編組展開 (二配)
B30: 編組 | D30: 1 | E30: 2 | F30: 3 | G30: 4 | H30: 5 | I30: 6 | J30: 7 | K30: 8 | L30: 9 | M30: 10 | N30: 11 | O30: 12 | P30: 1 | Q30: 2 | R30: 3 | S30: 4 | T30: 5 | U30: 6 | V30: 7 | W30: 8 | X30: 9
D31: 便當一線 | E31: 涼麵一線 | F31: 涼麵三線 | G31: 自動包裝機 | H31: 自動包裝機2 | I31: 自動包裝機3 | J31: 味付飯糰線B | K31: (舊) 3300型飯糰線 | L31: 3000型飯糰線 | M31: (新) 3300型飯糰機 | N31: GKK3600型 飯糰機 | O31: GKK3600型 飯糰機2 | P31: 自動包裝機 | Q31: 自動包裝機2 | R31: 自動包裝機3 | S31: 味付飯糰線B | T31: (舊) 3300型飯糰線 | U31: 3000型飯糰線 | V31: (新) 3300型飯糰機 | W31: GKK3600型 飯糰機 | X31: GKK3600型 飯糰機2
B32: 人時性 | C32: 排關 | D32: - | E32: - | F32: - | G32: 248.66667 | H32: 433.33333 | I32: - | J32: - | K32: - | L32: - | M32: 825 | N32: 1150 | O32: 860 | P32: 252.63158 | Q32: - | R32: - | S32: - | T32: 715.38462 | U32: - | V32: 825 | W32: 969.23077 | X32: 1023.5294
C33: 實績 | D33: - | E33: - | F33: - | G33: 217.14412 | H33: 386.15046 | I33: - | J33: - | K33: - | L33: - | M33: 726.47999 | N33: 1001.9022 | O33: 763.65813 | P33: 219.27271 | Q33: - | R33: - | S33: - | T33: 635.25076 | U33: - | V33: 736.35028 | W33: 859.25734 | X33: 893.80628
C34: 達成率 | D34: - | E34: - | F34: - | G34: =G33/G32 -> 0.87323371 | H34: =H33/H32 -> 0.89111644 | I34: - | J34: - | K34: - | L34: - | M34: =M33/M32 -> 0.88058181 | N34: =N33/N32 -> 0.87121931 | O34: =O33/O32 -> 0.88797457 | P34: =P33/P32 -> 0.86795449 | Q34: - | R34: - | S34: - | T34: =T33/T32 -> 0.88798493 | U34: - | V34: =V33/V32 -> 0.8925458 | W34: =W33/W32 -> 0.88653535 | X34: =X33/X32 -> 0.87325901
B35: 作業 時間 | C35: 開始 | D35: - | E35: - | F35: - | G35: 0.36052083 | H35: 0.29177083 | I35: - | J35: - | K35: - | L35: - | M35: 0.29172454 | N35: 0.29200231 | O35: 0.29166667 | P35: 0.70833333 | Q35: - | R35: - | S35: - | T35: 0.70833333 | U35: - | V35: 0.70866898 | W35: 0.70849537 | X35: 0.70862269
C36: 結束 | D36: - | E36: - | F36: - | G36: 0.54583333 | H36: 0.32777778 | I36: - | J36: - | K36: - | L36: - | M36: 0.45921296 | N36: 0.46041667 | O36: 0.40167824 | P36: 0.80013889 | Q36: - | R36: - | S36: - | T36: 0.85347222 | U36: - | V36: 0.86741898 | W36: 0.96041667 | X36: 0.95972222
B37: 配置人數 | D37: - | E37: - | F37: - | G37: 12.5 | H37: 6 | I37: - | J37: - | K37: - | L37: - | M37: 4 | N37: 3 | O37: 3.75 | P37: 14.25 | Q37: - | R37: - | S37: - | T37: 4.3333333 | U37: - | V37: 4 | W37: 3.25 | X37: 3.4
B38: 主要應用設備 | D38: 伺服包裝機 | E38: ET-55 | F38: ET-600 | G38: 夾心型 | H38: 伺服包裝機 | I38: 伺服包裝機 | J38: 夾心型 | K38: 3300型 | L38: 3300型 | M38: 3300型 | N38: GKK | O38: GKK | P38: 夾心型 | Q38: 伺服包裝機 | R38: 伺服包裝機 | S38: 夾心型 | T38: 3300型 | U38: 3300型 | V38: 3300型 | W38: GKK | X38: GKK
B39: 次要應用設備
B40: 備註

Sheet 1231(18度C)
A1: 大溪廠日報分析 | C1: 總生產量 | D1: =SUM(F5:F174) -> 85616 | E1: 營業額 | F1: =SUM(G5:G174) -> 1705140.7 | G1: 出勤人數 | H1: =L21+L38+L55+L72+L89+L106+L123+L140+L157+L174 -> 58.483333 | I1: 產線配置圖 | L1: 生產實績 | O1: 人時性差異分析 | S1: 日報登錄 | Y1: 分析說明 | AA1: 產能差異分析
A2: 46022 | C2: 人時性 | D2: =AVERAGE(N21,N38,N55,N72,N89,N106,N123,N140,N157,N174) -> 643.92723 | E2: 平均廠價 | F2: =F1/D1 -> 19.916146 | G2: 多次生產數 | H2: =COUNT(H5:H174) -> 2
A3: 線別 | B3: 品類 | C3: 品名 | E3: 廠價 | F3: 生產量 | G3: 營收 | H3: 多次 生產 | I3: 人數 | J3: 產能/時 | K3: 人時性 | L3: 人數 | M3: 產能/時 | N3: 人時性 | O3: 人數 | P3: 人時性 | Q3: 達成率 | R3: 達成率 平均 | S3: 生產時間 | U3: 換線、休息/分 | V3: 稼動時間/分 | W3: 休息時間 | Y3: (屏榮回填) | AA3: 產能/時 | AB3: 達成率 | AC3: 達成率平均
S4: 開始 | T4: 結束 | W4: 開始 | X4: 結束
A5: 自動包裝機 | B5: 18℃-壽司手卷 | C5: 一配明太子玉子脆卷 | E5: 19.7 | F5: 558 | G5: =E5*F5 -> 10992.6 | I5: 6 | J5: 2500 | K5: =J5/I5 -> 416.66667 | L5: 6 | M5: =F5/V5*60 -> 2254.5455 | N5: =M5/L5 -> 375.75758 | O5: =L5-I5 -> 0 | P5: =N5-K5 -> -40.909091 | Q5: =N5/K5 -> 0.90181818 | R5: =Q21 -> 0.87323371 | S5: 0.36052083 | T5: 0.37083333 | U5: 5.15 | V5: 14.85 | AA5: =M5-J5 -> -245.45455 | AB5: =M5/J5 -> 0.90181818 | AC5: =AB21 -> 0.87323371
B6: 18℃-飯糰 | C6: 一配兩粒飯糰(鮪魚.焦糖鮭魚) | E6: 28.57 | F6: 1838 | G6: =E6*F6 -> 52511.66 | I6: 12 | J6: 3600 | K6: =J6/I6 -> 300 | L6: 12 | M6: =F6/V6*60 -> 3110.8604 | N6: =M6/L6 -> 259.23836 | O6: =L6-I6 -> 0 | P6: =N6-K6 -> -40.761636 | Q6: =N6/K6 -> 0.86412788 | S6: 0.37430556 | T6: 0.39892361 | U6: 5 | V6: 35.45 | AA6: =M6-J6 -> -489.13963 | AB6: =M6/J6 -> 0.86412788
B7: 18℃-壽司手卷 | C7: 一配海饌雙手卷 | E7: 29.85 | F7: 1554 | G7: =E7*F7 -> 46386.9 | I7: 17 | J7: 3600 | K7: =J7/I7 -> 211.76471 | L7: 17 | M7: =F7/V7*60 -> 3118.3946 | N7: =M7/L7 -> 183.43498 | O7: =L7-I7 -> 0 | P7: =N7-K7 -> -28.329727 | Q7: =N7/K7 -> 0.86622074 | S7: 0.40215278 | T7: 0.42291667 | U7: 4.65 | V7: 29.9 | AA7: =M7-J7 -> -481.60535 | AB7: =M7/J7 -> 0.86622074
B8: 18℃-壽司手卷 | C8: 一配雙饗雙手卷 | E8: 29.52 | F8: 1466 | G8: =E8*F8 -> 43276.32 | I8: 17 | J8: 3600 | K8: =J8/I8 -> 211.76471 | L8: 17 | M8: =F8/V8*60 -> 3119.1489 | N8: =M8/L8 -> 183.47935 | O8: =L8-I8 -> 0 | P8: =N8-K8 -> -28.285357 | Q8: =N8/K8 -> 0.86643026 | S8: 0.42638889 | T8: 0.44597222 | U8: 5 | V8: 28.2 | AA8: =M8-J8 -> -480.85106 | AB8: =M8/J8 -> 0.86643026
B9: 18℃-壽司手卷 | C9: 一配長野稻荷壽司 | E9: 25.64 | F9: 1016 | G9: =E9*F9 -> 26050.24 | I9: 11 | J9: 3600 | K9: =J9/I9 -> 327.27273 | L9: 11 | M9: =F9/V9*60 -> 3150.3876 | N9: =M9/L9 -> 286.39887 | O9: =L9-I9 -> 0 | P9: =N9-K9 -> -40.873855 | Q9: =N9/K9 -> 0.87510767 | S9: 0.44930556 | T9: 0.46274306 | U9: 4.8 | V9: 19.35 | W9: 0.46274306 | X9: 0.50284722 | AA9: =M9-J9 -> -449.6124 | AB9: =M9/J9 -> 0.87510767
B10: 18℃-壽司手卷 | C10: 一配核桃腰果稻荷壽司組 | E10: 30.95 | F10: 1581 | G10: =E10*F10 -> 48931.95 | I10: 12 | J10: 1750 | K10: =J10/I10 -> 145.83333 | L10: 12 | M10: =F10/V10*60 -> 1532.4717 | N10: =M10/L10 -> 127.70598 | O10: =L10-I10 -> 0 | P10: =N10-K10 -> -18.127356 | Q10: =N10/K10 -> 0.87569813 | S10: 0.50284722 | T10: 0.54583333 | U10: 57.75 | V10: 61.9 | AA10: =M10-J10 -> -217.52827 | AB10: =M10/J10 -> 0.87569813
B21: 平均 | I21: =AVERAGE(I5:I20) -> 12.5 | J21: =AVERAGE(J5:J20) -> 3108.3333 | K21: =J21/I21 -> 248.66667 | L21: =AVERAGE(L5:L20) -> 12.5 | M21: =AVERAGE(M5:M20) -> 2714.3015 | N21: =M21/L21 -> 217.14412 | O21: =L21-I21 -> 0 | P21: =N21-K21 -> -31.52255 | Q21: =N21/K21 -> 0.87323371 | S21: =S5 -> 0.36052083 | T21: =INDEX(T5:T20,COUNTA(T5:T20)) -> 0.54583333 | AA21: =M21-J21 -> -394.03188 | AB21: =M21/J21 -> 0.87323371
A22: 自動包裝機2 | B22: 18℃-壽司手卷 | C22: 一配雙鬆細卷 | E22: 14.03 | F22: 844 | G22: =E22*F22 -> 11841.32 | I22: 6 | J22: 2600 | K22: =J22/I22 -> 433.33333 | L22: 6 | M22: =F22/V22*60 -> 2317.6201 | N22: =M22/L22 -> 386.27002 | O22: =L22-I22 -> 0 | P22: =N22-K22 -> -47.06331 | Q22: =N22/K22 -> 0.89139236 | R22: =Q38 -> 0.89111644 | S22: 0.29177083 | T22: 0.30694444 | V22: 21.85 | AA22: =M22-J22 -> -282.37986 | AB22: =M22/J22 -> 0.89139236 | AC22: =AB38 -> 0.89111644
B23: 18℃-壽司手卷 | C23: 一配經典鮪魚沙拉細卷 | E23: 14.49 | F23: 958 | G23: =E23*F23 -> 13881.42 | I23: 6 | J23: 2600 | K23: =J23/I23 -> 433.33333 | L23: 6 | M23: =F23/V23*60 -> 2316.1854 | N23: =M23/L23 -> 386.03089 | O23: =L23-I23 -> 0 | P23: =N23-K23 -> -47.30244 | Q23: =N23/K23 -> 0.89084052 | S23: 0.31054398 | T23: 0.32777778 | U23: 5.1833333 | V23: 24.816667 | AA23: =M23-J23 -> -283.81464 | AB23: =M23/J23 -> 0.89084052
B38: 平均 | I38: =AVERAGE(I22:I37) -> 6 | J38: =AVERAGE(J22:J37) -> 2600 | K38: =J38/I38 -> 433.33333 | L38: =AVERAGE(L22:L37) -> 6 | M38: =AVERAGE(M22:M37) -> 2316.9027 | N38: =M38/L38 -> 386.15046 | O38: =L38-I38 -> 0 | P38: =N38-K38 -> -47.182875 | Q38: =N38/K38 -> 0.89111644 | S38: =S22 -> 0.29177083 | T38: =INDEX(T22:T37,COUNTA(T22:T37)) -> 0.32777778 | AA38: =M38-J38 -> -283.09725 | AB38: =M38/J38 -> 0.89111644
A39: (新) 3300型飯糰機 | B39: 18℃-飯糰 | C39: 一配照燒雞肉飯糰 | E39: 21.45 | F39: 1423 | G39: =E39*F39 -> 30523.35 | I39: 4 | J39: 3300 | K39: =J39/I39 -> 825 | L39: 4 | M39: =F39/V39*60 -> 2952.6225 | N39: =M39/L39 -> 738.15562 | O39: =L39-I39 -> 0 | P39: =N39-K39 -> -86.84438 | Q39: =N39/K39 -> 0.89473408 | R39: =Q55 -> 0.88058181 | S39: 0.29172454 | T39: 0.31180556 | V39: 28.916667 | AA39: =M39-J39 -> -347.37752 | AB39: =M39/J39 -> 0.89473408 | AC39: =AB55 -> 0.88058181
B40: 18℃-飯糰 | C40: 一配壹號醬炙烤牛飯糰 | E40: 22.28 | F40: 818 | G40: =E40*F40 -> 18225.04 | I40: 5 | J40: 3300 | K40: =J40/I40 -> 660 | L40: 5 | M40: =F40/V40*60 -> 2950.7014 | N40: =M40/L40 -> 590.14028 | O40: =L40-I40 -> 0 | P40: =N40-K40 -> -69.859719 | Q40: =N40/K40 -> 0.89415194 | S40: 0.31553241 | T40: 0.32708333 | U40: 5.3666667 | V40: 16.633333 | AA40: =M40-J40 -> -349.2986 | AB40: =M40/J40 -> 0.89415194
B41: 18℃-飯糰 | C41: 一配鹽蔥燒肉飯糰 | E41: 17.89 | F41: 2059 | G41: =E41*F41 -> 36835.51 | I41: 4 | J41: 3300 | K41: =J41/I41 -> 825 | L41: 4 | M41: =F41/V41*60 -> 2947.2763 | N41: =M41/L41 -> 736.81909 | O41: =L41-I41 -> 0 | P41: =N41-K41 -> -88.180915 | Q41: =N41/K41 -> 0.89311404 | S41: 0.33061343 | T41: 0.35972222 | U41: 5.0833333 | V41: 41.916667 | AA41: =M41-J41 -> -352.72366 | AB41: =M41/J41 -> 0.89311404
B42: 18℃-飯糰 | C42: 一配鮭魚奶油醬油飯糰 | E42: 17.62 | F42: 3068 | G42: =E42*F42 -> 54058.16 | I42: 3 | J42: 3300 | K42: =J42/I42 -> 1100 | L42: 3 | M42: =F42/V42*60 -> 2737.2491 | N42: =M42/L42 -> 912.41636 | O42: =L42-I42 -> 0 | P42: =N42-K42 -> -187.58364 | Q42: =N42/K42 -> 0.82946942 | S42: 0.36319444 | T42: 0.40989583 | U42: 5 | V42: 67.25 | AA42: =M42-J42 -> -562.75093 | AB42: =M42/J42 -> 0.82946942
B43: 18℃-飯糰 | C43: 一配雞肉飯飯糰 | E43: 16.66 | F43: 3249 | G43: =E43*F43 -> 54128.34 | I43: 4 | J43: 3300 | K43: =J43/I43 -> 825 | L43: 4 | M43: =F43/V43*60 -> 2941.7505 | N43: =M43/L43 -> 735.43763 | O43: =L43-I43 -> 0 | P43: =N43-K43 -> -89.562374 | Q43: =N43/K43 -> 0.89143955 | S43: 0.41319444 | T43: 0.45921296 | U43: 4.75 | V43: 66.266667 | AA43: =M43-J43 -> -358.2495 | AB43: =M43/J43 -> 0.89143955
B55: 平均 | I55: =AVERAGE(I39:I54) -> 4 | J55: =AVERAGE(J39:J54) -> 3300 | K55: =J55/I55 -> 825 | L55: =AVERAGE(L39:L54) -> 4 | M55: =AVERAGE(M39:M54) -> 2905.92 | N55: =M55/L55 -> 726.47999 | O55: =L55-I55 -> 0 | P55: =N55-K55 -> -98.52001 | Q55: =N55/K55 -> 0.88058181 | S55: =S39 -> 0.29172454 | T55: =INDEX(T39:T54,COUNTA(T39:T54)) -> 0.45921296 | AA55: =M55-J55 -> -394.08004 | AB55: =M55/J55 -> 0.88058181
A56: GKK3600型 飯糰機 | B56: 18℃-飯糰 | C56: 一配蔬食鮪魚飯糰 | E56: 18.18 | F56: 909 | G56: =E56*F56 -> 16525.62 | I56: 3 | J56: 3600 | K56: =J56/I56 -> 1200 | L56: 3 | M56: =F56/V56*60 -> 3113.6061 | N56: =M56/L56 -> 1037.8687 | O56: =L56-I56 -> 0 | P56: =N56-K56 -> -162.1313 | Q56: =N56/K56 -> 0.86489058 | R56: =Q72 -> 0.87121931 | S56: 0.29200231 | T56: 0.30416667 | V56: 17.516667 | AA56: =M56-J56 -> -486.39391 | AB56: =M56/J56 -> 0.86489058 | AC56: =AB72 -> 0.87121931
B57: 18℃-飯糰 | C57: 一配經典肉鬆飯糰 | E57: 14.03 | F57: 3113 | G57: =E57*F57 -> 43675.39 | I57: 3 | J57: 3000 | K57: =J57/I57 -> 1000 | L57: 3 | M57: =F57/V57*60 -> 2683.6207 | N57: =M57/L57 -> 894.54023 | O57: =L57-I57 -> 0 | P57: =N57-K57 -> -105.45977 | Q57: =N57/K57 -> 0.89454023 | S57: 0.31486111 | T57: 0.36319444 | U57: 15.4 | V57: 69.6 | AA57: =M57-J57 -> -316.37931 | AB57: =M57/J57 -> 0.89454023
B58: 18℃-飯糰 | C58: 一配明太子龍蝦風味沙拉飯糰 | E58: 18.18 | F58: 1681 | G58: =E58*F58 -> 30560.58 | I58: 3 | J58: 3600 | K58: =J58/I58 -> 1200 | L58: 3 | M58: =F58/V58*60 -> 3112.963 | N58: =M58/L58 -> 1037.6543 | O58: =L58-I58 -> 0 | P58: =N58-K58 -> -162.34568 | Q58: =N58/K58 -> 0.86471193 | S58: 0.37361111 | T58: 0.39611111 | U58: 15 | V58: 32.4 | AA58: =M58-J58 -> -487.03704 | AB58: =M58/J58 -> 0.86471193
B59: 18℃-飯糰 | C59: 一配鮪魚飯糰 | E59: 14.28 | F59: 4030 | G59: =E59*F59 -> 57548.4 | I59: 3 | J59: 3600 | K59: =J59/I59 -> 1200 | L59: 3 | M59: =F59/V59*60 -> 3112.6368 | N59: =M59/L59 -> 1037.5456 | O59: =L59-I59 -> 0 | P59: =N59-K59 -> -162.45441 | Q59: =N59/K59 -> 0.86462133 | S59: 0.40646991 | T59: 0.46041667 | U59: 14.916667 | V59: 77.683333 | AA59: =M59-J59 -> -487.36323 | AB59: =M59/J59 -> 0.86462133
B72: 平均 | I72: =AVERAGE(I56:I71) -> 3 | J72: =AVERAGE(J56:J71) -> 3450 | K72: =J72/I72 -> 1150 | L72: =AVERAGE(L56:L71) -> 3 | M72: =AVERAGE(M56:M71) -> 3005.7066 | N72: =M72/L72 -> 1001.9022 | O72: =L72-I72 -> 0 | P72: =N72-K72 -> -148.09779 | Q72: =N72/K72 -> 0.87121931 | S72: =S56 -> 0.29200231 | T72: =INDEX(T56:T71,COUNTA(T56:T71)) -> 0.46041667 | AA72: =M72-J72 -> -444.29337 | AB72: =M72/J72 -> 0.87121931
A73: GKK3600型 飯糰機2 | B73: 18℃-飯糰 | C73: 一配博多明太子奶油飯糰 | E73: 25.45 | F73: 591 | G73: =E73*F73 -> 15040.95 | I73: 4 | J73: 3300 | K73: =J73/I73 -> 825 | L73: 4 | M73: =F73/V73*60 -> 2922.5275 | N73: =M73/L73 -> 730.63187 | O73: =L73-I73 -> 0 | P73: =N73-K73 -> -94.368132 | Q73: =N73/K73 -> 0.88561439 | R73: =Q89 -> 0.88797457 | S73: 0.29166667 | T73: 0.30009259 | V73: 12.133333 | AA73: =M73-J73 -> -377.47253 | AB73: =M73/J73 -> 0.88561439 | AC73: =AB89 -> 0.88797457
B74: 18℃-飯糰 | C74: 一配熟成紅鮭飯糰 | E74: 25.03 | F74: 1121 | G74: =E74*F74 -> 28058.63 | I74: 4 | J74: 3300 | K74: =J74/I74 -> 825 | L74: 4 | M74: =F74/V74*60 -> 2922.2303 | N74: =M74/L74 -> 730.55757 | O74: =L74-I74 -> 0 | P74: =N74-K74 -> -94.442433 | Q74: =N74/K74 -> 0.88552432 | S74: 0.31041667 | T74: 0.32640046 | U74: 14.866667 | V74: 23.016667 | AA74: =M74-J74 -> -377.76973 | AB74: =M74/J74 -> 0.88552432
B75: 18℃-飯糰 | C75: 一配北海道秋鮭親子飯糰 | E75: 24.82 | F75: 1395 | G75: =E75*F75 -> 34623.9 | I75: 4 | J75: 3300 | K75: =J75/I75 -> 825 | L75: 4 | M75: =F75/V75*60 -> 2923.1665 | N75: =M75/L75 -> 730.79162 | O75: =L75-I75 -> 0 | P75: =N75-K75 -> -94.208382 | Q75: =N75/K75 -> 0.88580802 | S75: 0.33706019 | T75: 0.35694444 | U75: 15.35 | V75: 28.633333 | AA75: =M75-J75 -> -376.83353 | AB75: =M75/J75 -> 0.88580802
B76: 18℃-飯糰 | C76: 一配贅沢鮭魚肚飯糰 | E76: 30 | F76: 2213 | G76: =E76*F76 -> 66390 | I76: 3 | J76: 3000 | K76: =J76/I76 -> 1000 | L76: 3 | M76: =F76/V76*60 -> 2686.9477 | N76: =M76/L76 -> 895.64924 | O76: =L76-I76 -> 0 | P76: =N76-K76 -> -104.35076 | Q76: =N76/K76 -> 0.89564924 | S76: 0.36736111 | T76: 0.40167824 | U76: 15 | V76: 49.416667 | AA76: =M76-J76 -> -313.05228 | AB76: =M76/J76 -> 0.89564924
B89: 平均 | I89: =AVERAGE(I73:I88) -> 3.75 | J89: =AVERAGE(J73:J88) -> 3225 | K89: =J89/I89 -> 860 | L89: =AVERAGE(L73:L88) -> 3.75 | M89: =AVERAGE(M73:M88) -> 2863.718 | N89: =M89/L89 -> 763.65813 | O89: =L89-I89 -> 0 | P89: =N89-K89 -> -96.341871 | Q89: =N89/K89 -> 0.88797457 | S89: =S73 -> 0.29166667 | T89: =INDEX(T73:T88,COUNTA(T73:T88)) -> 0.40167824 | AA89: =M89-J89 -> -361.28202 | AB89: =M89/J89 -> 0.88797457
A90: 自動包裝機 (二配) | B90: 18℃-壽司手卷 | C90: 二配長野稻荷壽司 | E90: 25.64 | F90: 1275 | G90: =E90*F90 -> 32691 | I90: 11 | J90: 3600 | K90: =J90/I90 -> 327.27273 | L90: 11 | M90: =F90/V90*60 -> 3152.4725 | N90: =M90/L90 -> 286.58841 | O90: =L90-I90 -> 0 | P90: =N90-K90 -> -40.684316 | Q90: =N90/K90 -> 0.87568681 | R90: =Q106 -> 0.86795449 | S90: 0.70833333 | T90: 0.72518519 | V90: 24.266667 | AA90: =M90-J90 -> -447.52747 | AB90: =M90/J90 -> 0.87568681 | AC90: =AB106 -> 0.86795449
B91: 18℃-壽司手卷 | C91: 二配雙饗雙手卷 | E91: 29.52 | F91: 1576 | G91: =E91*F91 -> 46523.52 | I91: 17 | J91: 3600 | K91: =J91/I91 -> 211.76471 | L91: 17 | M91: =F91/V91*60 -> 3117.3626 | N91: =M91/L91 -> 183.37427 | O91: =L91-I91 -> 0 | P91: =N91-K91 -> -28.390433 | Q91: =N91/K91 -> 0.86593407 | S91: 0.72847222 | T91: 0.74953704 | U91: 4.7333333 | V91: 30.333333 | AA91: =M91-J91 -> -482.63736 | AB91: =M91/J91 -> 0.86593407
B92: 18℃-壽司手卷 | C92: 二配海饌雙手卷 | E92: 29.85 | F92: 1613 | G92: =E92*F92 -> 48148.05 | I92: 17 | J92: 3600 | K92: =J92/I92 -> 211.76471 | L92: 17 | M92: =F92/V92*60 -> 3116.9082 | N92: =M92/L92 -> 183.34754 | O92: =L92-I92 -> 0 | P92: =N92-K92 -> -28.417164 | Q92: =N92/K92 -> 0.86580784 | S92: 0.75277778 | T92: 0.77434028 | U92: 4.6666667 | V92: 31.05 | AA92: =M92-J92 -> -483.09179 | AB92: =M92/J92 -> 0.86580784
B93: 18℃-飯糰 | C93: 二配兩粒飯糰(鮪魚.焦糖鮭魚) | E93: 28.57 | F93: 1670 | G93: =E93*F93 -> 47711.9 | I93: 12 | J93: 3600 | K93: =J93/I93 -> 300 | L93: 12 | M93: =F93/V93*60 -> 3111.8012 | N93: =M93/L93 -> 259.31677 | O93: =L93-I93 -> 0 | P93: =N93-K93 -> -40.68323 | Q93: =N93/K93 -> 0.86438923 | S93: 0.77777778 | T93: 0.80013889 | U93: 4.95 | V93: 32.2 | AA93: =M93-J93 -> -488.19876 | AB93: =M93/J93 -> 0.86438923
B106: 平均 | I106: =AVERAGE(I90:I105) -> 14.25 | J106: =AVERAGE(J90:J105) -> 3600 | K106: =J106/I106 -> 252.63158 | L106: =AVERAGE(L90:L105) -> 14.25 | M106: =AVERAGE(M90:M105) -> 3124.6362 | N106: =M106/L106 -> 219.27271 | O106: =L106-I106 -> 0 | P106: =N106-K106 -> -33.358866 | Q106: =N106/K106 -> 0.86795449 | S106: =S90 -> 0.70833333 | T106: =INDEX(T90:T105,COUNTA(T90:T105)) -> 0.80013889 | AA106: =M106-J106 -> -475.36385 | AB106: =M106/J106 -> 0.86795449
A107: (舊) 3300型飯糰線 (二配) | B107: 18℃-飯糰 | C107: 二配大飯糰滷肉飯加蛋 | E107: 22.48 | F107: 2589 | G107: =E107*F107 -> 58200.72 | I107: 5 | J107: 3000 | K107: =J107/I107 -> 600 | L107: 5 | M107: =F107/V107*60 -> 2659.1726 | N107: =M107/L107 -> 531.83452 | O107: =L107-I107 -> 0 | P107: =N107-K107 -> -68.165478 | Q107: =N107/K107 -> 0.88639087 | R107: =Q123 -> 0.88798493 | S107: 0.70833333 | T107: 0.74890046 | V107: 58.416667 | AA107: =M107-J107 -> -340.82739 | AB107: =M107/J107 -> 0.88639087 | AC107: =AB123 -> 0.88798493
B108: 18℃-飯糰 | C108: 二配大飯糰韓式蒜烤豬五花 | E108: 24.54 | F108: 2410 | G108: =E108*F108 -> 59141.4 | I108: 4 | J108: 3000 | K108: =J108/I108 -> 750 | L108: 4 | M108: =F108/V108*60 -> 2656.4605 | N108: =M108/L108 -> 664.11513 | O108: =L108-I108 -> 0 | P108: =N108-K108 -> -85.884874 | Q108: =N108/K108 -> 0.88548683 | S108: 0.75208333 | T108: 0.78988426 | U108: 4.5833333 | V108: 54.433333 | AA108: =M108-J108 -> -343.5395 | AB108: =M108/J108 -> 0.88548683
B109: 18℃-飯糰 | C109: 二配鹽蔥燒肉飯糰 | E109: 17.89 | F109: 4257 | G109: =E109*F109 -> 76157.73 | I109: 4 | J109: 3300 | K109: =J109/I109 -> 825 | L109: 4 | M109: =F109/V109*60 -> 2942.6267 | N109: =M109/L109 -> 735.65668 | O109: =L109-I109 -> 0 | P109: =N109-K109 -> -89.343318 | Q109: =N109/K109 -> 0.89170507 | S109: 0.79319444 | T109: 0.85347222 | U109: 4.7666667 | V109: 86.8 | AA109: =M109-J109 -> -357.37327 | AB109: =M109/J109 -> 0.89170507
B123: 平均 | I123: =AVERAGE(I107:I122) -> 4.3333333 | J123: =AVERAGE(J107:J122) -> 3100 | K123: =J123/I123 -> 715.38462 | L123: =AVERAGE(L107:L122) -> 4.3333333 | M123: =AVERAGE(M107:M122) -> 2752.7533 | N123: =M123/L123 -> 635.25076 | O123: =L123-I123 -> 0 | P123: =N123-K123 -> -80.133858 | Q123: =N123/K123 -> 0.88798493 | S123: =S107 -> 0.70833333 | T123: =INDEX(T107:T122,COUNTA(T107:T122)) -> 0.85347222 | AA123: =M123-J123 -> -347.24672 | AB123: =M123/J123 -> 0.88798493
A124: (新) 3300型飯糰機 (二配) | B124: 18℃-飯糰 | C124: 二配三杯醬爆菇菇飯糰 | E124: 16.7 | F124: 1746 | G124: =E124*F124 -> 29158.2 | I124: 3 | J124: 3300 | K124: =J124/I124 -> 1100 | L124: 3 | M124: =F124/V124*60 -> 2949.6011 | N124: =M124/L124 -> 983.20038 | O124: =L124-I124 -> 0 | P124: =N124-K124 -> -116.79962 | Q124: =N124/K124 -> 0.89381852 | R124: =Q140 -> 0.8925458 | S124: 0.70866898 | T124: 0.73333333 | V124: 35.516667 | AA124: =M124-J124 -> -350.39887 | AB124: =M124/J124 -> 0.89381852 | AC124: =AB140 -> 0.8925458
...

Sheet 1231(4度C)
A1: 大溪廠日報分析 | C1: 總生產量 | D1: =SUM(F5:F123) -> 43399 | E1: 營業額 | F1: =SUM(G5:G123) -> 2287544.1 | G1: 出勤人數 | H1: =L21+L38+L55+L72+L89+L106+L123 -> 132.58333 | I1: 產線配置圖 | L1: 生產實績 | O1: 人時性差異分析 | S1: 日報登錄 | Y1: 合計次數 | Z1: 合計(時間/分) | AA1: 產線異常 分析說明(5分鐘以上) | AC1: 合計次數 | AD1: 合計(時間/分) | AE1: 短暫停線 分析說明(5分鐘以下) | AG1: 短暫停線 分析說明(5分鐘以下) | AI1: 產能差異分析
A2: 46022 | C2: 人時性 | D2: =AVERAGE(N21,N38,N55,N72,N89,N106,N123) -> 150.62876 | E2: 平均廠價 | F2: =F1/D1 -> 52.709605 | G2: 多次生產數 | H2: =COUNT(H5:H123) -> 0 | Y2: =SUM(Y21+Y38+Y55+Y72+Y89+Y106+Y123) -> 0 | Z2: =SUM(Z21+Z38+Z55+Z72+Z89+Z106+Z123) -> 0 | AC2: =SUM(AC21+AC38+AC55+AC72+AC89+AC106+AC123) -> 0 | AD2: =SUM(AD21+AD38+AD55+AD72+AD89+AD106+AD123) -> 0
A3: 線別 | B3: 品類 | C3: 品名 | E3: 廠價 | F3: 生產量 | G3: 營收 | H3: 多次 生產 | I3: 人數 | J3: 產能/時 | K3: 人時性 | L3: 人數 | M3: 產能/時 | N3: 人時性 | O3: 人數 | P3: 人時性 | Q3: 達成率 | R3: 達成率 平均 | S3: 生產時間 | U3: 換線、休息/分 | V3: 稼動時間/分 | W3: 休息時間 | Y3: 產線異常統計 | AA3: (屏榮回填) | AC3: 短暫停線統計 | AE3: (屏榮回填) | AG3: (屏榮回填) | AI3: 產能/時 | AJ3: 達成率 | AK3: 達成率平均
S4: 開始 | T4: 結束 | W4: 開始 | X4: 結束 | Y4: 次數 | Z4: 時間/分 | AC4: 總次數 | AD4: 設備因素(次數)
A5: 便當二線 | B5: 微波主食 | C5: 糖燻野郎三十天熟成牛飯 | E5: 56.77 | F5: 3262 | G5: =E5*F5 -> 185183.74 | I5: 25 | J5: 2000 | K5: =J5/I5 -> 80 | L5: 25 | M5: =F5/V5*60 -> 1776.5809 | N5: =M5/L5 -> 71.063238 | O5: =L5-I5 -> 0 | P5: =N5-K5 -> -8.9367625 | Q5: =N5/K5 -> 0.88829047 | R5: =Q21 -> 0.88837726 | S5: 0.29166667 | T5: 0.3681713 | V5: 110.16667 | AI5: =M5-J5 -> -223.41906 | AJ5: =M5/J5 -> 0.88829047 | AK5: =AJ21 -> 0.88837726
B6: 4℃-飯糰 | C6: 韓素燒若飯糰 | E6: 24.07 | F6: 696 | G6: =E6*F6 -> 16752.72 | I6: 20 | J6: 2600 | K6: =J6/I6 -> 130 | L6: 20 | M6: =F6/V6*60 -> 2307.1823 | N6: =M6/L6 -> 115.35912 | O6: =L6-I6 -> 0 | P6: =N6-K6 -> -14.640884 | Q6: =N6/K6 -> 0.88737782 | S6: 0.37152778 | T6: 0.38409722 | U6: 4.8333333 | V6: 18.1 | AI6: =M6-J6 -> -292.81768 | AJ6: =M6/J6 -> 0.88737782
B7: 4℃-飯糰 | C7: 麻油雞飯糰 | E7: 29.97 | F7: 2201 | G7: =E7*F7 -> 65963.97 | I7: 20 | J7: 2600 | K7: =J7/I7 -> 130 | L7: 20 | M7: =F7/V7*60 -> 2307.3966 | N7: =M7/L7 -> 115.36983 | O7: =L7-I7 -> 0 | P7: =N7-K7 -> -14.630169 | Q7: =N7/K7 -> 0.88746024 | S7: 0.3875 | T7: 0.42724537 | U7: 4.9 | V7: 57.233333 | AI7: =M7-J7 -> -292.60338 | AJ7: =M7/J7 -> 0.88746024
B8: 便當 | C8: 嫩烤香料雞胸排蔬滿盒 | E8: 77.34 | F8: 1474 | G8: =E8*F8 -> 113999.16 | I8: 25 | J8: 2000 | K8: =J8/I8 -> 80 | L8: 25 | M8: =F8/V8*60 -> 1777.0931 | N8: =M8/L8 -> 71.083724 | O8: =L8-I8 -> 0 | P8: =N8-K8 -> -8.916276 | Q8: =N8/K8 -> 0.88854655 | S8: 0.43071759 | T8: 0.46527778 | U8: 5 | V8: 49.766667 | W8: 0.46527778 | X8: 0.50486111 | AI8: =M8-J8 -> -222.9069 | AJ8: =M8/J8 -> 0.88854655
B9: 便當 | C9: 健身G肉餐盒 | E9: 59.52 | F9: 2562 | G9: =E9*F9 -> 152490.24 | I9: 25 | J9: 2000 | K9: =J9/I9 -> 80 | L9: 25 | M9: =F9/V9*60 -> 1781.5723 | N9: =M9/L9 -> 71.262894 | O9: =L9-I9 -> 0 | P9: =N9-K9 -> -8.7371064 | Q9: =N9/K9 -> 0.89078617 | S9: 0.50486111 | T9: 0.56478009 | U9: 57 | V9: 86.283333 | AI9: =M9-J9 -> -218.42766 | AJ9: =M9/J9 -> 0.89078617
B21: 平均 | I21: =AVERAGE(I5:I20) -> 23 | J21: =AVERAGE(J5:J20) -> 2240 | K21: =J21/I21 -> 97.391304 | L21: =AVERAGE(L5:L20) -> 23 | M21: =AVERAGE(M5:M20) -> 1989.9651 | N21: =M21/L21 -> 86.52022 | O21: =L21-I21 -> 0 | P21: =N21-K21 -> -10.871084 | Q21: =N21/K21 -> 0.88837726 | S21: =S5 -> 0.29166667 | T21: =INDEX(T5:T20,COUNTA(T5:T20)) -> 0.56478009 | Y21: =SUM(Y5:Y20) -> 0 | Z21: =SUM(Z5:Z20) -> 0 | AC21: =SUM(AC5:AC20) -> 0 | AD21: =SUM(AD5:AD20) -> 0 | AI21: =M21-J21 -> -250.03494 | AJ21: =M21/J21 -> 0.88837726
A22: 涼麵一線 | B22: 微波小吃 | C22: 日式茶碗蒸 | E22: 19.7 | F22: 3042 | G22: =E22*F22 -> 59927.4 | I22: 13 | J22: 1200 | K22: =J22/I22 -> 92.307692 | L22: 13 | M22: =F22/V22*60 -> 1077.4498 | N22: =M22/L22 -> 82.880756 | O22: =L22-I22 -> 0 | P22: =N22-K22 -> -9.4269367 | Q22: =N22/K22 -> 0.89787485 | R22: =Q38 -> 0.88744868 | S22: 0.29166667 | T22: 0.40930556 | V22: 169.4 | AI22: =M22-J22 -> -122.55018 | AJ22: =M22/J22 -> 0.89787485 | AK22: =AJ38 -> 0.88744868
B23: 便當 | C23: 經典滷肉飯 | E23: 47.37 | F23: 1309 | G23: =E23*F23 -> 62007.33 | I23: 21 | J23: 2000 | K23: =J23/I23 -> 95.238095 | L23: 21 | M23: =F23/V23*60 -> 1772.2452 | N23: =M23/L23 -> 84.392629 | O23: =L23-I23 -> 0 | P23: =N23-K23 -> -10.845466 | Q23: =N23/K23 -> 0.8861226 | S23: 0.4125 | T23: 0.44327546 | U23: 4.6 | V23: 44.316667 | AI23: =M23-J23 -> -227.7548 | AJ23: =M23/J23 -> 0.8861226
B24: 便當 | C24: 香腸腿排雙拼便當 | E24: 53.76 | F24: 2740 | G24: =E24*F24 -> 147302.4 | I24: 20 | J24: 2000 | K24: =J24/I24 -> 100 | L24: 20 | M24: =F24/V24*60 -> 1771.2336 | N24: =M24/L24 -> 88.561681 | O24: =L24-I24 -> 0 | P24: =N24-K24 -> -11.438319 | Q24: =N24/K24 -> 0.88561681 | S24: 0.44665509 | T24: 0.51111111 | U24: 4.8666667 | V24: 92.816667 | W24: 0.51111111 | X24: 0.55071759 | AI24: =M24-J24 -> -228.76639 | AJ24: =M24/J24 -> 0.88561681
B25: 便當 | C25: 香烤藍尾鱈魚五行餐盒 | E25: 64.97 | F25: 619 | G25: =E25*F25 -> 40216.43 | I25: 20 | J25: 2000 | K25: =J25/I25 -> 100 | L25: 20 | M25: =F25/V25*60 -> 1771.3831 | N25: =M25/L25 -> 88.569157 | O25: =L25-I25 -> 0 | P25: =N25-K25 -> -11.430843 | Q25: =N25/K25 -> 0.88569157 | S25: 0.55071759 | T25: 0.56527778 | U25: 57.033333 | V25: 20.966667 | AI25: =M25-J25 -> -228.61685 | AJ25: =M25/J25 -> 0.88569157
B26: 熱食義麵 | C26: 明太子雞叉燒拌麵 | E26: 57.3 | F26: 893 | G26: =E26*F26 -> 51168.9 | I26: 21 | J26: 2000 | K26: =J26/I26 -> 95.238095 | L26: 21 | M26: =F26/V26*60 -> 1772.2161 | N26: =M26/L26 -> 84.391243 | O26: =L26-I26 -> 0 | P26: =N26-K26 -> -10.846853 | Q26: =N26/K26 -> 0.88610805 | S26: 0.56875 | T26: 0.58974537 | U26: 5 | V26: 30.233333 | AI26: =M26-J26 -> -227.7839 | AJ26: =M26/J26 -> 0.88610805
B38: 平均 | I38: =AVERAGE(I22:I37) -> 19 | J38: =AVERAGE(J22:J37) -> 1840 | K38: =J38/I38 -> 96.842105 | L38: =AVERAGE(L22:L37) -> 19 | M38: =AVERAGE(M22:M37) -> 1632.9056 | N38: =M38/L38 -> 85.942399 | O38: =L38-I38 -> 0 | P38: =N38-K38 -> -10.899706 | Q38: =N38/K38 -> 0.88744868 | S38: =S22 -> 0.29166667 | T38: =INDEX(T22:T37,COUNTA(T22:T37)) -> 0.58974537 | Y38: =SUM(Y22:Y37) -> 0 | Z38: =SUM(Z22:Z37) -> 0 | AC38: =SUM(AC22:AC37) -> 0 | AD38: =SUM(AD22:AD37) -> 0 | AI38: =M38-J38 -> -207.09442 | AJ38: =M38/J38 -> 0.88744868
A39: 涼麵二線 | B39: 便當 | C39: 美式雞丁餐盒 | E39: 59.34 | F39: 1085 | G39: =E39*F39 -> 64383.9 | I39: 24 | J39: 2000 | K39: =J39/I39 -> 83.333333 | L39: 24 | M39: =F39/V39*60 -> 1772.2323 | N39: =M39/L39 -> 73.843013 | O39: =L39-I39 -> 0 | P39: =N39-K39 -> -9.4903206 | Q39: =N39/K39 -> 0.88611615 | R39: =Q55 -> 0.88641372 | S39: 0.29185185 | T39: 0.31736111 | V39: 36.733333 | AI39: =M39-J39 -> -227.7677 | AJ39: =M39/J39 -> 0.88611615 | AK39: =AJ55 -> 0.88641372
B40: 便當 | C40: 烤蛋白餐盒 | E40: 58.67 | F40: 2096 | G40: =E40*F40 -> 122972.32 | I40: 23 | J40: 2000 | K40: =J40/I40 -> 86.956522 | L40: 23 | M40: =F40/V40*60 -> 1776.2712 | N40: =M40/L40 -> 77.229182 | O40: =L40-I40 -> 0 | P40: =N40-K40 -> -9.7273397 | Q40: =N40/K40 -> 0.88813559 | S40: 0.32097222 | T40: 0.37013889 | U40: 5.2 | V40: 70.8 | AI40: =M40-J40 -> -223.72881 | AJ40: =M40/J40 -> 0.88813559
B41: 便當 | C41: 海陸雙拼肉肉餐盒 | E41: 59.54 | F41: 2028 | G41: =E41*F41 -> 120747.12 | I41: 23 | J41: 2000 | K41: =J41/I41 -> 86.956522 | L41: 23 | M41: =F41/V41*60 -> 1769.8909 | N41: =M41/L41 -> 76.951779 | O41: =L41-I41 -> 0 | P41: =N41-K41 -> -10.004743 | Q41: =N41/K41 -> 0.88494545 | S41: 0.37378472 | T41: 0.42152778 | U41: 5.25 | V41: 68.75 | AI41: =M41-J41 -> -230.10909 | AJ41: =M41/J41 -> 0.88494545
B42: 便當 | C42: 蔬活腿排補力餐盒 | E42: 71.55 | F42: 1571 | G42: =E42*F42 -> 112405.05 | I42: 22 | J42: 2000 | K42: =J42/I42 -> 90.909091 | L42: 22 | M42: =F42/V42*60 -> 1772.9154 | N42: =M42/L42 -> 80.587062 | O42: =L42-I42 -> 0 | P42: =N42-K42 -> -10.322029 | Q42: =N42/K42 -> 0.88645768 | S42: 0.425 | T42: 0.4619213 | U42: 5 | V42: 53.166667 | AI42: =M42-J42 -> -227.08464 | AJ42: =M42/J42 -> 0.88645768
B55: 平均 | I55: =AVERAGE(I39:I54) -> 23 | J55: =AVERAGE(J39:J54) -> 2000 | K55: =J55/I55 -> 86.956522 | L55: =AVERAGE(L39:L54) -> 23 | M55: =AVERAGE(M39:M54) -> 1772.8274 | N55: =M55/L55 -> 77.079454 | O55: =L55-I55 -> 0 | P55: =N55-K55 -> -9.8770678 | Q55: =N55/K55 -> 0.88641372 | S55: =S39 -> 0.29185185 | T55: =INDEX(T39:T54,COUNTA(T39:T54)) -> 0.4619213 | Y55: =SUM(Y39:Y54) -> 0 | Z55: =SUM(Z39:Z54) -> 0 | AC55: =SUM(AC39:AC54) -> 0 | AD55: =SUM(AD39:AD54) -> 0 | AI55: =M55-J55 -> -227.17256 | AJ55: =M55/J55 -> 0.88641372
A56: 涼麵三線 | B56: 熱食義麵 | C56: 焗烤蕃茄起司四方麵 | E56: 57.3 | F56: 1998 | G56: =E56*F56 -> 114485.4 | I56: 22 | J56: 1800 | K56: =J56/I56 -> 81.818182 | L56: 22 | M56: =F56/V56*60 -> 1595.2096 | N56: =M56/L56 -> 72.509526 | O56: =L56-I56 -> 0 | P56: =N56-K56 -> -9.3086554 | Q56: =N56/K56 -> 0.88622754 | R56: =Q72 -> 0.88636724 | S56: 0.29166667 | T56: 0.34385417 | V56: 75.15 | AI56: =M56-J56 -> -204.79042 | AJ56: =M56/J56 -> 0.88622754 | AK56: =AJ72 -> 0.88636724
B57: 季節調理麵 | C57: 東京豚骨風味拉麵 | E57: 71.84 | F57: 762 | G57: =E57*F57 -> 54742.08 | I57: 19 | J57: 1800 | K57: =J57/I57 -> 94.736842 | L57: 19 | M57: =F57/V57*60 -> 1597.6704 | N57: =M57/L57 -> 84.087913 | O57: =L57-I57 -> 0 | P57: =N57-K57 -> -10.648929 | Q57: =N57/K57 -> 0.88759464 | S57: 0.34748843 | T57: 0.36736111 | U57: 5.2333333 | V57: 28.616667 | AI57: =M57-J57 -> -202.32964 | AJ57: =M57/J57 -> 0.88759464
B58: 季節調理麵 | C58: 醬油叉燒拉麵 | E58: 72.4 | F58: 546 | G58: =E58*F58 -> 39530.4 | I58: 18 | J58: 1800 | K58: =J58/I58 -> 100 | L58: 18 | M58: =F58/V58*60 -> 1599.3491 | N58: =M58/L58 -> 88.852726 | O58: =L58-I58 -> 0 | P58: =N58-K58 -> -11.147274 | Q58: =N58/K58 -> 0.88852726 | S58: 0.37083333 | T58: 0.38505787 | U58: 5 | V58: 20.483333 | AI58: =M58-J58 -> -200.65094 | AJ58: =M58/J58 -> 0.88852726
B59: 季節調理麵 | C59: 和風匠製胡麻涼麵 | E59: 32.06 | F59: 344 | G59: =E59*F59 -> 11028.64 | I59: 19 | J59: 3600 | K59: =J59/I59 -> 189.47368 | L59: 19 | M59: =F59/V59*60 -> 3183.5476 | N59: =M59/L59 -> 167.55513 | O59: =L59-I59 -> 0 | P59: =N59-K59 -> -21.91855 | Q59: =N59/K59 -> 0.88431877 | S59: 0.38819444 | T59: 0.39269676 | U59: 4.5166667 | V59: 6.4833333 | AI59: =M59-J59 -> -416.45244 | AJ59: =M59/J59 -> 0.88431877
B60: 微波小吃 | C60: 日式壽喜燒 | E60: 57.73 | F60: 768 | G60: =E60*F60 -> 44336.64 | I60: 22 | J60: 1800 | K60: =J60/I60 -> 81.818182 | L60: 22 | M60: =F60/V60*60 -> 1595.3837 | N60: =M60/L60 -> 72.517442 | O60: =L60-I60 -> 0 | P60: =N60-K60 -> -9.3007397 | Q60: =N60/K60 -> 0.88632429 | S60: 0.39591435 | T60: 0.41597222 | U60: 4.6333333 | V60: 28.883333 | AI60: =M60-J60 -> -204.61627 | AJ60: =M60/J60 -> 0.88632429
B61: 微波小吃 | C61: 韓式部隊鍋 | E61: 57.73 | F61: 968 | G61: =E61*F61 -> 55882.64 | I61: 22 | J61: 1800 | K61: =J61/I61 -> 81.818182 | L61: 22 | M61: =F61/V61*60 -> 1597.0669 | N61: =M61/L61 -> 72.593951 | O61: =L61-I61 -> 0 | P61: =N61-K61 -> -9.2242313 | Q61: =N61/K61 -> 0.8872594 | S61: 0.41944444 | T61: 0.44469907 | U61: 5 | V61: 36.366667 | AI61: =M61-J61 -> -202.93309 | AJ61: =M61/J61 -> 0.8872594
B72: 平均 | I72: =AVERAGE(I56:I71) -> 20.333333 | J72: =AVERAGE(J56:J71) -> 2100 | K72: =J72/I72 -> 103.27869 | L72: =AVERAGE(L56:L71) -> 20.333333 | M72: =AVERAGE(M56:M71) -> 1861.3712 | N72: =M72/L72 -> 91.542846 | O72: =L72-I72 -> 0 | P72: =N72-K72 -> -11.735843 | Q72: =N72/K72 -> 0.88636724 | S72: =S56 -> 0.29166667 | T72: =INDEX(T56:T71,COUNTA(T56:T71)) -> 0.44469907 | Y72: =SUM(Y56:Y71) -> 0 | Z72: =SUM(Z56:Z71) -> 0 | AC72: =SUM(AC56:AC71) -> 0 | AD72: =SUM(AD56:AD71) -> 0 | AI72: =M72-J72 -> -238.6288 | AJ72: =M72/J72 -> 0.88636724
A73: 自動包裝機 | B73: 4℃-飯糰 | C73: 和風牛肉咖哩炸飯糰 | E73: 21.74 | F73: 754 | G73: =E73*F73 -> 16391.96 | I73: 6 | J73: 3600 | K73: =J73/I73 -> 600 | L73: 6 | M73: =F73/V73*60 -> 3258.5834 | N73: =M73/L73 -> 543.09724 | O73: =L73-I73 -> 0 | P73: =N73-K73 -> -56.902761 | Q73: =N73/K73 -> 0.90516206 | R73: =Q89 -> 0.90516206 | S73: 0.34730324 | T73: 0.35694444 | V73: 13.883333 | AI73: =M73-J73 -> -341.41657 | AJ73: =M73/J73 -> 0.90516206 | AK73: =AJ89 -> 0.90516206
B89: 平均 | I89: =AVERAGE(I73:I88) -> 6 | J89: =AVERAGE(J73:J88) -> 3600 | K89: =J89/I89 -> 600 | L89: =AVERAGE(L73:L88) -> 6 | M89: =AVERAGE(M73:M88) -> 3258.5834 | N89: =M89/L89 -> 543.09724 | O89: =L89-I89 -> 0 | P89: =N89-K89 -> -56.902761 | Q89: =N89/K89 -> 0.90516206 | S89: =S73 -> 0.34730324 | T89: =INDEX(T73:T88,COUNTA(T73:T88)) -> 0.35694444 | Y89: =SUM(Y73:Y88) -> 0 | Z89: =SUM(Z73:Z88) -> 0 | AC89: =SUM(AC73:AC88) -> 0 | AD89: =SUM(AD73:AD88) -> 0 | AI89: =M89-J89 -> -341.41657 | AJ89: =M89/J89 -> 0.90516206
A90: 便當二線 (二配) | B90: 微波主食 | C90: 二配鐵板蘑菇肉醬起司焗飯 | E90: 44.3 | F90: 759 | G90: =E90*F90 -> 33623.7 | I90: 17 | J90: 2000 | K90: =J90/I90 -> 117.64706 | L90: 17 | M90: =F90/V90*60 -> 1773.1343 | N90: =M90/L90 -> 104.30202 | O90: =L90-I90 -> 0 | P90: =N90-K90 -> -13.34504 | Q90: =N90/K90 -> 0.88656716 | R90: =Q106 -> 0.8856784 | S90: 0.70855324 | T90: 0.72638889 | V90: 25.683333 | AI90: =M90-J90 -> -226.86567 | AJ90: =M90/J90 -> 0.88656716 | AK90: =AJ106 -> 0.8856784
B91: 微波主食 | C91: 二配蒙古風味烤肉飯 | E91: 58.17 | F91: 2786 | G91: =E91*F91 -> 162061.62 | I91: 19 | J91: 1800 | K91: =J91/I91 -> 94.736842 | L91: 19 | M91: =F91/V91*60 -> 1597.3244 | N91: =M91/L91 -> 84.069706 | O91: =L91-I91 -> 0 | P91: =N91-K91 -> -10.667136 | Q91: =N91/K91 -> 0.88740245 | S91: 0.73010417 | T91: 0.80277778 | U91: 5.35 | V91: 104.65 | AI91: =M91-J91 -> -202.67559 | AJ91: =M91/J91 -> 0.88740245
B92: 微波主食 | C92: 二配乳酪燻腸紅醬焗飯 | E92: 50.67 | F92: 613 | G92: =E92*F92 -> 31060.71 | I92: 20 | J92: 2000 | K92: =J92/I92 -> 100 | L92: 20 | M92: =F92/V92*60 -> 1768.2692 | N92: =M92/L92 -> 88.413462 | O92: =L92-I92 -> 0 | P92: =N92-K92 -> -11.586538 | Q92: =N92/K92 -> 0.88413462 | S92: 0.80638889 | T92: 0.82083333 | U92: 5.2 | V92: 20.8 | AI92: =M92-J92 -> -231.73077 | AJ92: =M92/J92 -> 0.88413462
B93: 微波主食 | C93: 二配西班牙風味海鮮燉飯 | E93: 57.3 | F93: 1250 | G93: =E93*F93 -> 71625 | I93: 21 | J93: 2000 | K93: =J93/I93 -> 95.238095 | L93: 21 | M93: =F93/V93*60 -> 1769.5635 | N93: =M93/L93 -> 84.264929 | O93: =L93-I93 -> 0 | P93: =N93-K93 -> -10.973166 | Q93: =N93/K93 -> 0.88478175 | S93: 0.82430556 | T93: 0.85373843 | U93: 5 | V93: 42.383333 | AI93: =M93-J93 -> -230.43649 | AJ93: =M93/J93 -> 0.88478175
B106: 平均 | I106: =AVERAGE(I90:I105) -> 19.25 | J106: =AVERAGE(J90:J105) -> 1950 | K106: =J106/I106 -> 101.2987 | L106: =AVERAGE(L90:L105) -> 19.25 | M106: =AVERAGE(M90:M105) -> 1727.0729 | N106: =M106/L106 -> 89.718071 | O106: =L106-I106 -> 0 | P106: =N106-K106 -> -11.58063 | Q106: =N106/K106 -> 0.8856784 | S106: =S90 -> 0.70855324 | T106: =INDEX(T90:T105,COUNTA(T90:T105)) -> 0.85373843 | Y106: =SUM(Y90:Y105) -> 0 | Z106: =SUM(Z90:Z105) -> 0 | AC106: =SUM(AC90:AC105) -> 0 | AD106: =SUM(AD90:AD105) -> 0 | AI106: =M106-J106 -> -222.92713 | AJ106: =M106/J106 -> 0.8856784
A107: 涼麵一線 (二配) | B107: 微波主食 | C107: 二配里肌豬排可可咖哩歐姆蛋飯 | E107: 56.79 | F107: 1485 | G107: =E107*F107 -> 84333.15 | I107: 23 | J107: 2000 | K107: =J107/I107 -> 86.956522 | L107: 23 | M107: =F107/V107*60 -> 1771.3718 | N107: =M107/L107 -> 77.016164 | O107: =L107-I107 -> 0 | P107: =N107-K107 -> -9.9403579 | Q107: =N107/K107 -> 0.88568588 | R107: =Q123 -> 0.88551226 | S107: 0.70833333 | T107: 0.74326389 | V107: 50.3 | AI107: =M107-J107 -> -228.62823 | AJ107: =M107/J107 -> 0.88568588 | AK107: =AJ123 -> 0.88551226
B108: 微波主食 | C108: 二配黃金雞排蘑菇白醬歐姆蛋飯 | E108: 56.87 | F108: 1109 | G108: =E108*F108 -> 63068.83 | I108: 23 | J108: 2000 | K108: =J108/I108 -> 86.956522 | L108: 23 | M108: =F108/V108*60 -> 1772.8242 | N108: =M108/L108 -> 77.079311 | O108: =L108-I108 -> 0 | P108: =N108-K108 -> -9.8772106 | Q108: =N108/K108 -> 0.88641208 | S108: 0.74685185 | T108: 0.77291667 | U108: 5.1666667 | V108: 37.533333 | AI108: =M108-J108 -> -227.17584 | AJ108: =M108/J108 -> 0.88641208
B109: 微波主食 | C109: 二配哞哞培根奶香海陸焗飯 | E109: 47.6 | F109: 1409 | G109: =E109*F109 -> 67068.4 | I109: 23 | J109: 2000 | K109: =J109/I109 -> 86.956522 | L109: 23 | M109: =F109/V109*60 -> 1768.0028 | N109: =M109/L109 -> 76.869686 | O109: =L109-I109 -> 0 | P109: =N109-K109 -> -10.086835 | Q109: =N109/K109 -> 0.88400139 | S109: 0.7765162 | T109: 0.80972222 | U109: 5.1833333 | V109: 47.816667 | AI109: =M109-J109 -> -231.99721 | AJ109: =M109/J109 -> 0.88400139
B110: 微波主食 | C110: 二配失控起司薯餅焗飯 | E110: 54.09 | F110: 2270 | G110: =E110*F110 -> 122784.3 | I110: 19 | J110: 2000 | K110: =J110/I110 -> 105.26316 | L110: 19 | M110: =F110/V110*60 -> 1771.8994 | N110: =M110/L110 -> 93.257863 | O110: =L110-I110 -> 0 | P110: =N110-K110 -> -12.005295 | Q110: =N110/K110 -> 0.8859497 | S110: 0.81328704 | T110: 0.86666667 | U110: 5.1333333 | V110: 76.866667 | AI110: =M110-J110 -> -228.10061 | AJ110: =M110/J110 -> 0.8859497
B123: 平均 | I123: =AVERAGE(I107:I122) -> 22 | J123: =AVERAGE(J107:J122) -> 2000 | K123: =J123/I123 -> 90.909091 | L123: =AVERAGE(L107:L122) -> 22 | M123: =AVERAGE(M107:M122) -> 1771.0245 | N123: =M123/L123 -> 80.501115 | O123: =L123-I123 -> 0 | P123: =N123-K123 -> -10.407976 | Q123: =N123/K123 -> 0.88551226 | S123: =S107 -> 0.70833333 | T123: =INDEX(T107:T122,COUNTA(T107:T122)) -> 0.86666667 | Y123: =SUM(Y107:Y122) -> 0 | Z123: =SUM(Z107:Z122) -> 0 | AC123: =SUM(AC107:AC122) -> 0 | AD123: =SUM(AD107:AD122) -> 0 | AI123: =M123-J123 -> -228.97547 | AJ123: =M123/J123 -> 0.88551226
...

Sheet 1230
B1: 屏榮 大溪廠組合室生產人時性分析
B3: 日期 | C3: 114.12.30星期二 | E3: 訂單量 | F3: ='1230(18度C)'!D1+'1230(4度C)'!D1 -> 160010 | H3: 營業額 | I3: ='1230(18度C)'!F1+'1230(4度C)'!F1 -> 4991542.2
B4: 人時性 | C4: 項目 | E4: ➀ | G4: ➁ | I4: ➂ | K4: ④ | M4: ⑤ | O4: 異常停線 | Q4: 短暫停線
C5: 組合室 | E5: 全溫層 | G5: 4度C-各編組展開(一配) | I5: 4度C-各編組展開(二配) | K5: 18度C-各編組展開(一配) | M5: 18度C-各編組展開(二配) | O5: 合計次數 | P5: 時間 | Q5: 合計次數 | R5: 設備次數
C6: 排關平均 | E6: =AVERAGE(D14:O14,D32:X32) -> 498.79134 | F6: =AVERAGE(#REF!,D14:K14) -> #REF! | G6: =AVERAGE(D14:K14) -> 196.89372 | I6: =AVERAGE(L14:O14) -> 96.103896 | K6: =AVERAGE(D32:O32) -> 703.4 | M6: =AVERAGE(P32:X32) -> 757.15528 | O6: ='[1]1201(4度C)'!Y2 -> 0 | P6: ='[1]1201(4度C)'!Z2 -> 0 | Q6: ='[1]1201(4度C)'!AC2 -> 0 | R6: ='[1]1201(4度C)'!AD2 -> 0
C7: 實績平均 | E7: =AVERAGE(D15:O15,D33:X33) -> 440.60228 | F7: =AVERAGE(#REF!,D15:K15) -> #REF! | G7: =AVERAGE(D15:K15) -> 176.76271 | I7: =AVERAGE(L15:O15) -> 85.106945 | K7: =AVERAGE(D33:O33) -> 618.48124 | M7: =AVERAGE(P33:X33) -> 668.76103
C8: 達成率平均 | E8: =AVERAGE(D16:O16,D34:X34) -> 0.88426879 | F8: =AVERAGE(D16:K16,#REF!) -> #REF! | G8: =AVERAGE(D16:K16) -> 0.89057336 | I8: =AVERAGE(L16:O16) -> 0.88556926 | K8: =AVERAGE(D34:O34) -> 0.8800812 | M8: =AVERAGE(P34:X34) -> 0.8816316
O9: ※現行日本鮮食廠以達成率80%為基本(即為現行KPI)
B11: 溫層 | D11: ➁4度C-各編組展開 | L11: ➂4度C-各編組展開
B12: 編組 | D12: 1 | E12: 2 | F12: 3 | G12: 4 | H12: 5 | I12: 6 | J12: 7 | K12: 8 | L12: 1 | M12: 2 | N12: 3 | O12: 4
D13: 便當一線 | E13: 便當二線 | F13: 涼麵一線 | G13: 涼麵二線 | H13: 涼麵三線 | I13: 自動包裝機 | J13: 自動包裝機2 | K13: 自動包裝機3 | L13: 便當一線 | M13: 便當二線 | N13: 涼麵一線 | O13: 涼麵二線
B14: 人時性 | C14: 排關 | D14: - | E14: 97.391304 | F14: 96.842105 | G14: 86.956522 | H14: 103.27869 | I14: 600 | J14: - | K14: - | L14: - | M14: 101.2987 | N14: 90.909091 | O14: -
C15: 實績 | D15: - | E15: 86.511406 | F15: 85.936069 | G15: 77.071253 | H15: 91.533302 | I15: 542.76151 | J15: - | K15: - | L15: - | M15: 89.712644 | N15: 80.501246 | O15: -
C16: 達成率 | D16: - | E16: =E15/E14 -> 0.88828676 | F16: =F15/F14 -> 0.88738332 | G16: =G15/G14 -> 0.88631941 | H16: =H15/H14 -> 0.88627483 | I16: =I15/I14 -> 0.90460251 | J16: - | K16: - | L16: - | M16: =M15/M14 -> 0.88562481 | N16: =N15/N14 -> 0.88551371 | O16: -
B17: 作業 時間 | C17: 開始 | D17: - | E17: 0.25021991 | F17: 0.20833333 | G17: 0.29166667 | H17: 0.29180556 | I17: 0.31811343 | J17: - | K17: - | L17: - | M17: 0.70861111 | N17: 0.70835648 | O17: -
C18: 結束 | D18: - | E18: 0.60849537 | F18: 0.55902778 | G18: 0.56111111 | H18: 0.4625 | I18: 0.33194444 | J18: - | K18: - | L18: - | M18: 0.87166667 | N18: 0.87646991 | O18: -
B19: 產線異常 (5分鐘以上) | C19: 次數
C20: 時間/分
B21: 短暫停線 (5分鐘以下) | C21: 次數
C22: 設備次數
B23: 配置人數 | D23: - | E23: 23 | F23: 19 | G23: 23 | H23: 20.333333 | I23: 6 | J23: - | K23: - | L23: - | M23: 19.25 | N23: 22 | O23: -
B24: 主要應用設備 | D24: L型封口機 | E24: ET-55 | F24: ET-55 | G24: ET-55 | H24: ET-600 | I24: 伺服包裝機 | J24: 伺服包裝機 | K24: 伺服包裝機 | L24: L型封口機 | M24: ET-55 | N24: ET-55 | O24: ET-55
B25: 次要應用設備 | D25: 伺服包裝機 | H25: 伺服包裝機
B26: 備註 | H26: 涼麵+烤飯糰 | I26: 大口飯糰線 | K26: 烤飯糰+手卷
B29: 溫層 | D29: ➃18度C-各編組展開 (一配) | P29: ⑤18度C-各編組展開 (二配)
B30: 編組 | D30: 1 | E30: 2 | F30: 3 | G30: 4 | H30: 5 | I30: 6 | J30: 7 | K30: 8 | L30: 9 | M30: 10 | N30: 11 | O30: 12 | P30: 1 | Q30: 2 | R30: 3 | S30: 4 | T30: 5 | U30: 6 | V30: 7 | W30: 8 | X30: 9
D31: 便當一線 | E31: 涼麵一線 | F31: 涼麵三線 | G31: 自動包裝機 | H31: 自動包裝機2 | I31: 自動包裝機3 | J31: 味付飯糰線B | K31: (舊) 3300型飯糰線 | L31: 3000型飯糰線 | M31: (新) 3300型飯糰機 | N31: GKK3600型 飯糰機 | O31: GKK3600型 飯糰機2 | P31: 自動包裝機 | Q31: 自動包裝機2 | R31: 自動包裝機3 | S31: 味付飯糰線B | T31: (舊) 3300型飯糰線 | U31: 3000型飯糰線 | V31: (新) 3300型飯糰機 | W31: GKK3600型 飯糰機 | X31: GKK3600型 飯糰機2
B32: 人時性 | C32: 排關 | D32: - | E32: - | F32: - | G32: 248.66667 | H32: 433.33333 | I32: - | J32: - | K32: - | L32: - | M32: 825 | N32: 1150 | O32: 860 | P32: 252.63158 | Q32: - | R32: - | S32: - | T32: 715.38462 | U32: - | V32: 825 | W32: 969.23077 | X32: 1023.5294
C33: 實績 | D33: - | E33: - | F33: - | G33: 217.10311 | H33: 386.08689 | I33: - | J33: - | K33: - | L33: - | M33: 723.84189 | N33: 1001.8825 | O33: 763.49186 | P33: 219.29012 | Q33: - | R33: - | S33: - | T33: 635.22382 | U33: - | V33: 736.2081 | W33: 859.266 | X33: 893.81712
C34: 達成率 | D34: - | E34: - | F34: - | G34: =G33/G32 -> 0.87306879 | H34: =H33/H32 -> 0.89096974 | I34: - | J34: - | K34: - | L34: - | M34: =M33/M32 -> 0.8773841 | N34: =N33/N32 -> 0.87120215 | O34: =O33/O32 -> 0.88778124 | P34: =P33/P32 -> 0.86802337 | Q34: - | R34: - | S34: - | T34: =T33/T32 -> 0.88794728 | U34: - | V34: =V33/V32 -> 0.89237346 | W34: =W33/W32 -> 0.88654428 | X34: =X33/X32 -> 0.8732696
B35: 作業 時間 | C35: 開始 | D35: - | E35: - | F35: - | G35: 0.3362037 | H35: 0.25008102 | I35: - | J35: - | K35: - | L35: - | M35: 0.20833333 | N35: 0.20833333 | O35: 0.25012731 | P35: 0.70854167 | Q35: - | R35: - | S35: - | T35: 0.70833333 | U35: - | V35: 0.70833333 | W35: 0.70833333 | X35: 0.70833333
C36: 結束 | D36: - | E36: - | F36: - | G36: 0.55773148 | H36: 0.29747685 | I36: - | J36: - | K36: - | L36: - | M36: 0.45974537 | N36: 0.4419213 | O36: 0.39802083 | P36: 0.81388889 | Q36: - | R36: - | S36: - | T36: 0.86458333 | U36: - | V36: 0.87638889 | W36: 0.97446759 | X36: 0.97361111
B37: 配置人數 | D37: - | E37: - | F37: - | G37: 12.5 | H37: 6 | I37: - | J37: - | K37: - | L37: - | M37: 4 | N37: 3 | O37: 3.75 | P37: 14.25 | Q37: - | R37: - | S37: - | T37: 4.3333333 | U37: - | V37: 4 | W37: 3.25 | X37: 3.4
B38: 主要應用設備 | D38: 伺服包裝機 | E38: ET-55 | F38: ET-600 | G38: 夾心型 | H38: 伺服包裝機 | I38: 伺服包裝機 | J38: 夾心型 | K38: 3300型 | L38: 3300型 | M38: 3300型 | N38: GKK | O38: GKK | P38: 夾心型 | Q38: 伺服包裝機 | R38: 伺服包裝機 | S38: 夾心型 | T38: 3300型 | U38: 3300型 | V38: 3300型 | W38: GKK | X38: GKK
B39: 次要應用設備
B40: 備註

Sheet 1230(18度C)
A1: 大溪廠日報分析 | C1: 總生產量 | D1: =SUM(F5:F174) -> 105992 | E1: 營業額 | F1: =SUM(G5:G174) -> 2115740.8 | G1: 出勤人數 | H1: =L21+L38+L55+L72+L89+L106+L123+L140+L157+L174 -> 58.483333 | I1: 產線配置圖 | L1: 生產實績 | O1: 人時性差異分析 | S1: 日報登錄 | Y1: 分析說明 | AA1: 產能差異分析
A2: 46021 | C2: 人時性 | D2: =AVERAGE(N21,N38,N55,N72,N89,N106,N123,N140,N157,N174) -> 643.62114 | E2: 平均廠價 | F2: =F1/D1 -> 19.961326 | G2: 多次生產數 | H2: =COUNT(H5:H174) -> 2
A3: 線別 | B3: 品類 | C3: 品名 | E3: 廠價 | F3: 生產量 | G3: 營收 | H3: 多次 生產 | I3: 人數 | J3: 產能/時 | K3: 人時性 | L3: 人數 | M3: 產能/時 | N3: 人時性 | O3: 人數 | P3: 人時性 | Q3: 達成率 | R3: 達成率 平均 | S3: 生產時間 | U3: 換線、休息/分 | V3: 稼動時間/分 | W3: 休息時間 | Y3: (屏榮回填) | AA3: 產能/時 | AB3: 達成率 | AC3: 達成率平均
S4: 開始 | T4: 結束 | W4: 開始 | X4: 結束
A5: 自動包裝機 | B5: 18℃-壽司手卷 | C5: 一配明太子玉子脆卷 | E5: 19.7 | F5: 709 | G5: =E5*F5 -> 13967.3 | I5: 6 | J5: 2500 | K5: =J5/I5 -> 416.66667 | L5: 6 | M5: =F5/V5*60 -> 2254.7703 | N5: =M5/L5 -> 375.79505 | O5: =L5-I5 -> 0 | P5: =N5-K5 -> -40.871614 | Q5: =N5/K5 -> 0.90190813 | R5: =Q21 -> 0.87306879 | S5: 0.3362037 | T5: 0.34930556 | U5: 6.1333333 | V5: 18.866667 | AA5: =M5-J5 -> -245.22968 | AB5: =M5/J5 -> 0.90190813 | AC5: =AB21 -> 0.87306879
B6: 18℃-飯糰 | C6: 一配兩粒飯糰(鮪魚.焦糖鮭魚) | E6: 28.57 | F6: 2560 | G6: =E6*F6 -> 73139.2 | I6: 12 | J6: 3600 | K6: =J6/I6 -> 300 | L6: 12 | M6: =F6/V6*60 -> 3110.3611 | N6: =M6/L6 -> 259.19676 | O6: =L6-I6 -> 0 | P6: =N6-K6 -> -40.80324 | Q6: =N6/K6 -> 0.8639892 | S6: 0.35277778 | T6: 0.38707176 | U6: 5 | V6: 49.383333 | AA6: =M6-J6 -> -489.63888 | AB6: =M6/J6 -> 0.8639892
B7: 18℃-壽司手卷 | C7: 一配海饌雙手卷 | E7: 29.85 | F7: 2101 | G7: =E7*F7 -> 62714.85 | I7: 17 | J7: 3600 | K7: =J7/I7 -> 211.76471 | L7: 17 | M7: =F7/V7*60 -> 3117.7246 | N7: =M7/L7 -> 183.39557 | O7: =L7-I7 -> 0 | P7: =N7-K7 -> -28.369138 | Q7: =N7/K7 -> 0.86603462 | S7: 0.39027778 | T7: 0.41835648 | U7: 4.6166667 | V7: 40.433333 | AA7: =M7-J7 -> -482.27535 | AB7: =M7/J7 -> 0.86603462
B8: 18℃-壽司手卷 | C8: 一配雙饗雙手卷 | E8: 29.52 | F8: 1987 | G8: =E8*F8 -> 58656.24 | I8: 17 | J8: 3600 | K8: =J8/I8 -> 211.76471 | L8: 17 | M8: =F8/V8*60 -> 3118.2214 | N8: =M8/L8 -> 183.42479 | O8: =L8-I8 -> 0 | P8: =N8-K8 -> -28.339915 | Q8: =N8/K8 -> 0.86617262 | S8: 0.42152778 | T8: 0.4480787 | U8: 4.5666667 | V8: 38.233333 | AA8: =M8-J8 -> -481.77855 | AB8: =M8/J8 -> 0.86617262
B9: 18℃-壽司手卷 | C9: 一配長野稻荷壽司 | E9: 25.64 | F9: 1384 | G9: =E9*F9 -> 35485.76 | I9: 11 | J9: 3600 | K9: =J9/I9 -> 327.27273 | L9: 11 | M9: =F9/V9*60 -> 3149.4311 | N9: =M9/L9 -> 286.31192 | O9: =L9-I9 -> 0 | P9: =N9-K9 -> -40.960809 | Q9: =N9/K9 -> 0.87484197 | S9: 0.45138889 | T9: 0.46969907 | U9: 4.7666667 | V9: 26.366667 | W9: 0.46969907 | X9: 0.50902778 | AA9: =M9-J9 -> -450.5689 | AB9: =M9/J9 -> 0.87484197
B10: 18℃-壽司手卷 | C10: 一配核桃腰果稻荷壽司組 | E10: 30.95 | F10: 1791 | G10: =E10*F10 -> 55431.45 | I10: 12 | J10: 1750 | K10: =J10/I10 -> 145.83333 | L10: 12 | M10: =F10/V10*60 -> 1532.2243 | N10: =M10/L10 -> 127.68536 | O10: =L10-I10 -> 0 | P10: =N10-K10 -> -18.147972 | Q10: =N10/K10 -> 0.87555676 | S10: 0.50902778 | T10: 0.55773148 | U10: 56.633333 | V10: 70.133333 | AA10: =M10-J10 -> -217.77567 | AB10: =M10/J10 -> 0.87555676
B21: 平均 | I21: =AVERAGE(I5:I20) -> 12.5 | J21: =AVERAGE(J5:J20) -> 3108.3333 | K21: =J21/I21 -> 248.66667 | L21: =AVERAGE(L5:L20) -> 12.5 | M21: =AVERAGE(M5:M20) -> 2713.7888 | N21: =M21/L21 -> 217.10311 | O21: =L21-I21 -> 0 | P21: =N21-K21 -> -31.56356 | Q21: =N21/K21 -> 0.87306879 | S21: =S5 -> 0.3362037 | T21: =INDEX(T5:T20,COUNTA(T5:T20)) -> 0.55773148 | AA21: =M21-J21 -> -394.54451 | AB21: =M21/J21 -> 0.87306879
A22: 自動包裝機2 | B22: 18℃-壽司手卷 | C22: 一配雙鬆細卷 | E22: 14.03 | F22: 1231 | G22: =E22*F22 -> 17270.93 | I22: 6 | J22: 2600 | K22: =J22/I22 -> 433.33333 | L22: 6 | M22: =F22/V22*60 -> 2316.5708 | N22: =M22/L22 -> 386.09514 | O22: =L22-I22 -> 0 | P22: =N22-K22 -> -47.238195 | Q22: =N22/K22 -> 0.89098878 | R22: =Q38 -> 0.89096974 | S22: 0.25008102 | T22: 0.27222222 | V22: 31.883333 | AA22: =M22-J22 -> -283.42917 | AB22: =M22/J22 -> 0.89098878 | AC22: =AB38 -> 0.89096974
B23: 18℃-壽司手卷 | C23: 一配經典鮪魚沙拉細卷 | E23: 14.49 | F23: 1211 | G23: =E23*F23 -> 17547.39 | I23: 6 | J23: 2600 | K23: =J23/I23 -> 433.33333 | L23: 6 | M23: =F23/V23*60 -> 2316.4718 | N23: =M23/L23 -> 386.07864 | O23: =L23-I23 -> 0 | P23: =N23-K23 -> -47.254694 | Q23: =N23/K23 -> 0.89095071 | S23: 0.27569444 | T23: 0.29747685 | U23: 5 | V23: 31.366667 | AA23: =M23-J23 -> -283.52816 | AB23: =M23/J23 -> 0.89095071
B38: 平均 | I38: =AVERAGE(I22:I37) -> 6 | J38: =AVERAGE(J22:J37) -> 2600 | K38: =J38/I38 -> 433.33333 | L38: =AVERAGE(L22:L37) -> 6 | M38: =AVERAGE(M22:M37) -> 2316.5213 | N38: =M38/L38 -> 386.08689 | O38: =L38-I38 -> 0 | P38: =N38-K38 -> -47.246444 | Q38: =N38/K38 -> 0.89096974 | S38: =S22 -> 0.25008102 | T38: =INDEX(T22:T37,COUNTA(T22:T37)) -> 0.29747685 | AA38: =M38-J38 -> -283.47867 | AB38: =M38/J38 -> 0.89096974
A39: (新) 3300型飯糰機 | B39: 18℃-飯糰 | C39: 一配照燒雞肉飯糰 | E39: 21.45 | F39: 1931 | G39: =E39*F39 -> 41419.95 | I39: 4 | J39: 3300 | K39: =J39/I39 -> 825 | L39: 4 | M39: =F39/V39*60 -> 2951.8471 | N39: =M39/L39 -> 737.96178 | O39: =L39-I39 -> 0 | P39: =N39-K39 -> -87.038217 | Q39: =N39/K39 -> 0.89449913 | R39: =Q55 -> 0.8773841 | S39: 0.20833333 | T39: 0.23559028 | V39: 39.25 | AA39: =M39-J39 -> -348.15287 | AB39: =M39/J39 -> 0.89449913 | AC39: =AB55 -> 0.8773841
B40: 18℃-飯糰 | C40: 一配壹號醬炙烤牛飯糰 | E40: 22.28 | F40: 1291 | G40: =E40*F40 -> 28763.48 | I40: 5 | J40: 3300 | K40: =J40/I40 -> 660 | L40: 5 | M40: =F40/V40*60 -> 2948.9848 | N40: =M40/L40 -> 589.79695 | O40: =L40-I40 -> 0 | P40: =N40-K40 -> -70.203046 | Q40: =N40/K40 -> 0.89363175 | S40: 0.23888889 | T40: 0.25712963 | U40: 4.75 | V40: 26.266667 | AA40: =M40-J40 -> -351.01523 | AB40: =M40/J40 -> 0.89363175
B41: 18℃-飯糰 | C41: 一配鹽蔥燒肉飯糰 | E41: 17.89 | F41: 2953 | G41: =E41*F41 -> 52829.17 | I41: 4 | J41: 3300 | K41: =J41/I41 -> 825 | L41: 4 | M41: =F41/V41*60 -> 2947.2692 | N41: =M41/L41 -> 736.8173 | O41: =L41-I41 -> 0 | P41: =N41-K41 -> -88.1827 | Q41: =N41/K41 -> 0.89311188 | S41: 0.26041667 | T41: 0.30216435 | U41: 4.7333333 | V41: 60.116667 | AA41: =M41-J41 -> -352.7308 | AB41: =M41/J41 -> 0.89311188
B42: 18℃-飯糰 | C42: 一配鮭魚奶油醬油飯糰 | E42: 17.62 | F42: 5285 | G42: =E42*F42 -> 93121.7 | I42: 3 | J42: 3300 | K42: =J42/I42 -> 1100 | L42: 3 | M42: =F42/V42*60 -> 2687.2881 | N42: =M42/L42 -> 895.76271 | O42: =L42-I42 -> 0 | P42: =N42-K42 -> -204.23729 | Q42: =N42/K42 -> 0.81432974 | S42: 0.30625 | T42: 0.38819444 | U42: 5.8833333 | V42: 118 | AA42: =M42-J42 -> -612.71186 | AB42: =M42/J42 -> 0.81432974
B43: 18℃-飯糰 | C43: 一配雞肉飯飯糰 | E43: 16.66 | F43: 4806 | G43: =E43*F43 -> 80067.96 | I43: 4 | J43: 3300 | K43: =J43/I43 -> 825 | L43: 4 | M43: =F43/V43*60 -> 2941.4485 | N43: =M43/L43 -> 735.36212 | O43: =L43-I43 -> 0 | P43: =N43-K43 -> -89.637878 | Q43: =N43/K43 -> 0.89134803 | S43: 0.39166667 | T43: 0.45974537 | U43: 5 | V43: 98.033333 | AA43: =M43-J43 -> -358.55151 | AB43: =M43/J43 -> 0.89134803
B55: 平均 | I55: =AVERAGE(I39:I54) -> 4 | J55: =AVERAGE(J39:J54) -> 3300 | K55: =J55/I55 -> 825 | L55: =AVERAGE(L39:L54) -> 4 | M55: =AVERAGE(M39:M54) -> 2895.3675 | N55: =M55/L55 -> 723.84189 | O55: =L55-I55 -> 0 | P55: =N55-K55 -> -101.15811 | Q55: =N55/K55 -> 0.8773841 | S55: =S39 -> 0.20833333 | T55: =INDEX(T39:T54,COUNTA(T39:T54)) -> 0.45974537 | AA55: =M55-J55 -> -404.63245 | AB55: =M55/J55 -> 0.8773841
A56: GKK3600型 飯糰機 | B56: 18℃-飯糰 | C56: 一配蔬食鮪魚飯糰 | E56: 18.18 | F56: 1364 | G56: =E56*F56 -> 24797.52 | I56: 3 | J56: 3600 | K56: =J56/I56 -> 1200 | L56: 3 | M56: =F56/V56*60 -> 3113.7603 | N56: =M56/L56 -> 1037.9201 | O56: =L56-I56 -> 0 | P56: =N56-K56 -> -162.0799 | Q56: =N56/K56 -> 0.86493342 | R56: =Q72 -> 0.87120215 | S56: 0.20833333 | T56: 0.22658565 | V56: 26.283333 | AA56: =M56-J56 -> -486.2397 | AB56: =M56/J56 -> 0.86493342 | AC56: =AB72 -> 0.87120215
B57: 18℃-飯糰 | C57: 一配經典肉鬆飯糰 | E57: 14.03 | F57: 4548 | G57: =E57*F57 -> 63808.44 | I57: 3 | J57: 3000 | K57: =J57/I57 -> 1000 | L57: 3 | M57: =F57/V57*60 -> 2683.1858 | N57: =M57/L57 -> 894.39528 | O57: =L57-I57 -> 0 | P57: =N57-K57 -> -105.60472 | Q57: =N57/K57 -> 0.89439528 | S57: 0.23701389 | T57: 0.30763889 | U57: 15.016667 | V57: 101.7 | AA57: =M57-J57 -> -316.81416 | AB57: =M57/J57 -> 0.89439528
B58: 18℃-飯糰 | C58: 一配明太子龍蝦風味沙拉飯糰 | E58: 18.18 | F58: 2454 | G58: =E58*F58 -> 44613.72 | I58: 3 | J58: 3600 | K58: =J58/I58 -> 1200 | L58: 3 | M58: =F58/V58*60 -> 3112.8964 | N58: =M58/L58 -> 1037.6321 | O58: =L58-I58 -> 0 | P58: =N58-K58 -> -162.36786 | Q58: =N58/K58 -> 0.86469345 | S58: 0.31805556 | T58: 0.35090278 | U58: 15 | V58: 47.3 | AA58: =M58-J58 -> -487.10359 | AB58: =M58/J58 -> 0.86469345
B59: 18℃-飯糰 | C59: 一配鮪魚飯糰 | E59: 14.28 | F59: 6037 | G59: =E59*F59 -> 86208.36 | I59: 3 | J59: 3600 | K59: =J59/I59 -> 1200 | L59: 3 | M59: =F59/V59*60 -> 3112.7471 | N59: =M59/L59 -> 1037.5824 | O59: =L59-I59 -> 0 | P59: =N59-K59 -> -162.41765 | Q59: =N59/K59 -> 0.86465196 | S59: 0.36111111 | T59: 0.4419213 | U59: 14.7 | V59: 116.36667 | AA59: =M59-J59 -> -487.25294 | AB59: =M59/J59 -> 0.86465196
B72: 平均 | I72: =AVERAGE(I56:I71) -> 3 | J72: =AVERAGE(J56:J71) -> 3450 | K72: =J72/I72 -> 1150 | L72: =AVERAGE(L56:L71) -> 3 | M72: =AVERAGE(M56:M71) -> 3005.6474 | N72: =M72/L72 -> 1001.8825 | O72: =L72-I72 -> 0 | P72: =N72-K72 -> -148.11753 | Q72: =N72/K72 -> 0.87120215 | S72: =S56 -> 0.20833333 | T72: =INDEX(T56:T71,COUNTA(T56:T71)) -> 0.4419213 | AA72: =M72-J72 -> -444.3526 | AB72: =M72/J72 -> 0.87120215
A73: GKK3600型 飯糰機2 | B73: 18℃-飯糰 | C73: 一配博多明太子奶油飯糰 | E73: 25.45 | F73: 965 | G73: =E73*F73 -> 24559.25 | I73: 4 | J73: 3300 | K73: =J73/I73 -> 825 | L73: 4 | M73: =F73/V73*60 -> 2921.783 | N73: =M73/L73 -> 730.44575 | O73: =L73-I73 -> 0 | P73: =N73-K73 -> -94.554247 | Q73: =N73/K73 -> 0.88538879 | R73: =Q89 -> 0.88778124 | S73: 0.25012731 | T73: 0.26388889 | V73: 19.816667 | AA73: =M73-J73 -> -378.21699 | AB73: =M73/J73 -> 0.88538879 | AC73: =AB89 -> 0.88778124
B74: 18℃-飯糰 | C74: 一配熟成紅鮭飯糰 | E74: 25.03 | F74: 1738 | G74: =E74*F74 -> 43502.14 | I74: 4 | J74: 3300 | K74: =J74/I74 -> 825 | L74: 4 | M74: =F74/V74*60 -> 2921.0084 | N74: =M74/L74 -> 730.2521 | O74: =L74-I74 -> 0 | P74: =N74-K74 -> -94.747899 | Q74: =N74/K74 -> 0.88515406 | S74: 0.27451389 | T74: 0.29930556 | U74: 15.3 | V74: 35.7 | AA74: =M74-J74 -> -378.9916 | AB74: =M74/J74 -> 0.88515406
B75: 18℃-飯糰 | C75: 一配北海道秋鮭親子飯糰 | E75: 24.82 | F75: 1972 | G75: =E75*F75 -> 48945.04 | I75: 4 | J75: 3300 | K75: =J75/I75 -> 825 | L75: 4 | M75: =F75/V75*60 -> 2922.6842 | N75: =M75/L75 -> 730.67106 | O75: =L75-I75 -> 0 | P75: =N75-K75 -> -94.328942 | Q75: =N75/K75 -> 0.88566189 | S75: 0.30972222 | T75: 0.33783565 | U75: 15 | V75: 40.483333 | AA75: =M75-J75 -> -377.31577 | AB75: =M75/J75 -> 0.88566189
B76: 18℃-飯糰 | C76: 一配贅沢鮭魚肚飯糰 | E76: 30 | F76: 3231 | G76: =E76*F76 -> 96930 | I76: 3 | J76: 3000 | K76: =J76/I76 -> 1000 | L76: 3 | M76: =F76/V76*60 -> 2686.9023 | N76: =M76/L76 -> 895.6341 | O76: =L76-I76 -> 0 | P76: =N76-K76 -> -104.3659 | Q76: =N76/K76 -> 0.8956341 | S76: 0.34791667 | T76: 0.39802083 | U76: 14.516667 | V76: 72.15 | AA76: =M76-J76 -> -313.09771 | AB76: =M76/J76 -> 0.8956341
B89: 平均 | I89: =AVERAGE(I73:I88) -> 3.75 | J89: =AVERAGE(J73:J88) -> 3225 | K89: =J89/I89 -> 860 | L89: =AVERAGE(L73:L88) -> 3.75 | M89: =AVERAGE(M73:M88) -> 2863.0945 | N89: =M89/L89 -> 763.49186 | O89: =L89-I89 -> 0 | P89: =N89-K89 -> -96.508138 | Q89: =N89/K89 -> 0.88778124 | S89: =S73 -> 0.25012731 | T89: =INDEX(T73:T88,COUNTA(T73:T88)) -> 0.39802083 | AA89: =M89-J89 -> -361.90552 | AB89: =M89/J89 -> 0.88778124
A90: 自動包裝機 (二配) | B90: 18℃-壽司手卷 | C90: 二配長野稻荷壽司 | E90: 25.64 | F90: 1455 | G90: =E90*F90 -> 37306.2 | I90: 11 | J90: 3600 | K90: =J90/I90 -> 327.27273 | L90: 11 | M90: =F90/V90*60 -> 3151.6245 | N90: =M90/L90 -> 286.51132 | O90: =L90-I90 -> 0 | P90: =N90-K90 -> -40.761405 | Q90: =N90/K90 -> 0.87545126 | R90: =Q106 -> 0.86802337 | S90: 0.70854167 | T90: 0.72777778 | V90: 27.7 | AA90: =M90-J90 -> -448.37545 | AB90: =M90/J90 -> 0.87545126 | AC90: =AB106 -> 0.86802337
B91: 18℃-壽司手卷 | C91: 二配雙饗雙手卷 | E91: 29.52 | F91: 1920 | G91: =E91*F91 -> 56678.4 | I91: 17 | J91: 3600 | K91: =J91/I91 -> 211.76471 | L91: 17 | M91: =F91/V91*60 -> 3117.7267 | N91: =M91/L91 -> 183.39569 | O91: =L91-I91 -> 0 | P91: =N91-K91 -> -28.36902 | Q91: =N91/K91 -> 0.86603518 | S91: 0.73128472 | T91: 0.75694444 | U91: 5.05 | V91: 36.95 | AA91: =M91-J91 -> -482.27334 | AB91: =M91/J91 -> 0.86603518
B92: 18℃-壽司手卷 | C92: 二配海饌雙手卷 | E92: 29.85 | F92: 2043 | G92: =E92*F92 -> 60983.55 | I92: 17 | J92: 3600 | K92: =J92/I92 -> 211.76471 | L92: 17 | M92: =F92/V92*60 -> 3117.7618 | N92: =M92/L92 -> 183.39775 | O92: =L92-I92 -> 0 | P92: =N92-K92 -> -28.366955 | Q92: =N92/K92 -> 0.86604493 | S92: 0.76041667 | T92: 0.78771991 | U92: 5 | V92: 39.316667 | AA92: =M92-J92 -> -482.23824 | AB92: =M92/J92 -> 0.86604493
B93: 18℃-飯糰 | C93: 二配兩粒飯糰(鮪魚.焦糖鮭魚) | E93: 28.57 | F93: 1698 | G93: =E93*F93 -> 48511.86 | I93: 12 | J93: 3600 | K93: =J93/I93 -> 300 | L93: 12 | M93: =F93/V93*60 -> 3112.4236 | N93: =M93/L93 -> 259.36864 | O93: =L93-I93 -> 0 | P93: =N93-K93 -> -40.631365 | Q93: =N93/K93 -> 0.86456212 | S93: 0.79115741 | T93: 0.81388889 | U93: 4.95 | V93: 32.733333 | AA93: =M93-J93 -> -487.57637 | AB93: =M93/J93 -> 0.86456212
B106: 平均 | I106: =AVERAGE(I90:I105) -> 14.25 | J106: =AVERAGE(J90:J105) -> 3600 | K106: =J106/I106 -> 252.63158 | L106: =AVERAGE(L90:L105) -> 14.25 | M106: =AVERAGE(M90:M105) -> 3124.8841 | N106: =M106/L106 -> 219.29012 | O106: =L106-I106 -> 0 | P106: =N106-K106 -> -33.341463 | Q106: =N106/K106 -> 0.86802337 | S106: =S90 -> 0.70854167 | T106: =INDEX(T90:T105,COUNTA(T90:T105)) -> 0.81388889 | AA106: =M106-J106 -> -475.11585 | AB106: =M106/J106 -> 0.86802337
A107: (舊) 3300型飯糰線 (二配) | B107: 18℃-飯糰 | C107: 二配大飯糰滷肉飯加蛋 | E107: 22.48 | F107: 2722 | G107: =E107*F107 -> 61190.56 | I107: 5 | J107: 3000 | K107: =J107/I107 -> 600 | L107: 5 | M107: =F107/V107*60 -> 2659.213 | N107: =M107/L107 -> 531.84261 | O107: =L107-I107 -> 0 | P107: =N107-K107 -> -68.157395 | Q107: =N107/K107 -> 0.88640434 | R107: =Q123 -> 0.88794728 | S107: 0.70833333 | T107: 0.7509838 | V107: 61.416667 | AA107: =M107-J107 -> -340.78697 | AB107: =M107/J107 -> 0.88640434 | AC107: =AB123 -> 0.88794728
B108: 18℃-飯糰 | C108: 二配大飯糰韓式蒜烤豬五花 | E108: 24.54 | F108: 2525 | G108: =E108*F108 -> 61963.5 | I108: 4 | J108: 3000 | K108: =J108/I108 -> 750 | L108: 4 | M108: =F108/V108*60 -> 2656.3413 | N108: =M108/L108 -> 664.08533 | O108: =L108-I108 -> 0 | P108: =N108-K108 -> -85.91467 | Q108: =N108/K108 -> 0.88544711 | S108: 0.75416667 | T108: 0.79377315 | U108: 4.5833333 | V108: 57.033333 | AA108: =M108-J108 -> -343.65868 | AB108: =M108/J108 -> 0.88544711
B109: 18℃-飯糰 | C109: 二配鹽蔥燒肉飯糰 | E109: 17.89 | F109: 4747 | G109: =E109*F109 -> 84923.83 | I109: 4 | J109: 3300 | K109: =J109/I109 -> 825 | L109: 4 | M109: =F109/V109*60 -> 2942.3554 | N109: =M109/L109 -> 735.58884 | O109: =L109-I109 -> 0 | P109: =N109-K109 -> -89.411157 | Q109: =N109/K109 -> 0.89162284 | S109: 0.79736111 | T109: 0.86458333 | U109: 5.1666667 | V109: 96.8 | AA109: =M109-J109 -> -357.64463 | AB109: =M109/J109 -> 0.89162284
B123: 平均 | I123: =AVERAGE(I107:I122) -> 4.3333333 | J123: =AVERAGE(J107:J122) -> 3100 | K123: =J123/I123 -> 715.38462 | L123: =AVERAGE(L107:L122) -> 4.3333333 | M123: =AVERAGE(M107:M122) -> 2752.6366 | N123: =M123/L123 -> 635.22382 | O123: =L123-I123 -> 0 | P123: =N123-K123 -> -80.160791 | Q123: =N123/K123 -> 0.88794728 | S123: =S107 -> 0.70833333 | T123: =INDEX(T107:T122,COUNTA(T107:T122)) -> 0.86458333 | AA123: =M123-J123 -> -347.36343 | AB123: =M123/J123 -> 0.88794728
