Workbook

Sheet 0831
B1: 屏榮 大溪廠組合室生產人時性分析
B3: 日期 | C3: 114.08.31星期日 | E3: 訂單量 | F3: ='0831(18度C)'!D1+'0831(4度C)'!D1 -> 251694 | H3: 營業額 | I3: ='0831(18度C)'!F1+'0831(4度C)'!F1 -> 7725142.4
B4: 人時性 | C4: 項目 | E4: ➀ | G4: ➁ | I4: ➂ | K4: ④ | M4: ⑤
C5: 組合室 | E5: 全溫層 | G5: 4度C-各編組展開(一配) | I5: 4度C-各編組展開(二配) | K5: 18度C-各編組展開(一配) | M5: 18度C-各編組展開(二配)
C6: 排關平均 | E6: =AVERAGE(D13:O13,D27:X27) -> 492.99534 | F6: =AVERAGE(#REF!,D13:K13) -> #REF! | G6: =AVERAGE(D13:K13) -> 174.7978 | I6: =AVERAGE(L13:O13) -> 91.865358 | K6: =AVERAGE(D27:O27) -> 671.63502 | M6: =AVERAGE(P27:X27) -> 759.74955
C7: 實績平均 | E7: =AVERAGE(D14:O14,D28:X28) -> 421.57475 | F7: =AVERAGE(#REF!,D14:K14) -> #REF! | G7: =AVERAGE(D14:K14) -> 149.85211 | I7: =AVERAGE(L14:O14) -> 78.698736 | K7: =AVERAGE(D28:O28) -> 573.6167 | M7: =AVERAGE(P28:X28) -> 650.15391
C8: 達成率平均 | E8: =AVERAGE(D15:O15,D29:X29) -> 0.85713781 | F8: =AVERAGE(D15:K15,#REF!) -> #REF! | G8: =AVERAGE(D15:K15) -> 0.85996396 | I8: =AVERAGE(L15:O15) -> 0.85674037 | K8: =AVERAGE(D29:O29) -> 0.85438899 | M8: =AVERAGE(P29:X29) -> 0.85763822 | O8: ※現行日本鮮食廠以達成率80%為基本(即為現行KPI)
B10: 溫層 | D10: ➁4度C-各編組展開 | L10: ➂4度C-各編組展開
B11: 編組 | D11: 1 | E11: 2 | F11: 3 | G11: 4 | H11: 5 | I11: 6 | J11: 7 | K11: 8 | L11: 1 | M11: 2 | N11: 3 | O11: 4
D12: 便當一線 | E12: 便當二線 | F12: 涼麵一線 | G12: 涼麵二線 | H12: 涼麵三線 | I12: 自動包裝機 | J12: 自動包裝機2 | K12: 自動包裝機3 | L12: 便當一線 | M12: 便當二線 | N12: 涼麵一線 | O12: 涼麵二線
B13: 人時性 | C13: 排關 | D13: 115.15152 | E13: 79.545455 | F13: 82.105263 | G13: 84.507042 | H13: 178.02198 | I13: 250.92 | J13: - | K13: 433.33333 | L13: - | M13: - | N13: 86.956522 | O13: 96.774194
C14: 實績 | D14: 100.80313 | E14: 68.090971 | F14: 70.588589 | G14: 72.868101 | H14: 152.41134 | I14: 215.80781 | J14: - | K14: 368.39485 | L14: - | M14: - | N14: 74.605881 | O14: 82.791591
C15: 達成率 | D15: =D14/D13 -> 0.87539561 | E15: =E14/E13 -> 0.85600078 | F15: =F14/F13 -> 0.85973281 | G15: =G14/G13 -> 0.86227253 | H15: =H14/H13 -> 0.8561378 | I15: =I14/I13 -> 0.8600662 | J15: - | K15: =K14/K13 -> 0.85014197 | L15: - | M15: - | N15: =N14/N13 -> 0.85796763 | O15: =O14/O13 -> 0.85551311
B16: 作業 時間 | C16: 開始 | D16: 0.25 | E16: 0.25 | F16: 0.25030093 | G16: 0.25023148 | H16: 0.16666667 | I16: 0.25 | J16: - | K16: 0.32016204 | L16: - | M16: - | N16: 0.70841435 | O16: 0.70844907
C17: 結束 | D17: 0.56681713 | E17: 0.67638889 | F17: 0.61738426 | G17: 0.61180556 | H17: 0.73402778 | I17: 0.59664352 | J17: - | K17: 0.50033565 | L17: - | M17: - | N17: 0.82309028 | O17: 0.8544213
B18: 配置人數 | D18: 16.5 | E18: 25.142857 | F18: 23.75 | G18: 23.666667 | H18: 20.222222 | I18: 12.5 | J18: - | K18: 6 | L18: - | M18: - | N18: 23 | O18: 20.666667
B19: 主要應用設備 | D19: L型封口機 | E19: ET-55 | F19: ET-55 | G19: ET-55 | H19: ET-600 | I19: 伺服包裝機 | J19: 伺服包裝機 | K19: 伺服包裝機 | L19: L型封口機 | M19: ET-55 | N19: ET-55 | O19: ET-55
B20: 次要應用設備 | D20: 伺服包裝機 | H20: 伺服包裝機
B21: 備註 | H21: 涼麵+烤飯糰 | I21: 大口飯糰線 | K21: 烤飯糰+手卷
B24: 溫層 | D24: ➃18度C-各編組展開 (一配) | P24: ⑤18度C-各編組展開 (二配)
B25: 編組 | D25: 1 | E25: 2 | F25: 3 | G25: 4 | H25: 5 | I25: 6 | J25: 7 | K25: 8 | L25: 9 | M25: 10 | N25: 11 | O25: 12 | P25: 1 | Q25: 2 | R25: 3 | S25: 4 | T25: 5 | U25: 6 | V25: 7 | W25: 8 | X25: 9
D26: 便當一線 | E26: 涼麵一線 | F26: 涼麵三線 | G26: 自動包裝機 | H26: 自動包裝機2 | I26: 自動包裝機3 | J26: 味付飯糰線B | K26: (舊) 3300型飯糰線 | L26: 3000型飯糰線 | M26: (新) 3300型飯糰機 | N26: GKK3600型 飯糰機 | O26: GKK3600型 飯糰機2 | P26: 自動包裝機 | Q26: 自動包裝機2 | R26: 自動包裝機3 | S26: 味付飯糰線B | T26: (舊) 3300型飯糰線 | U26: 3000型飯糰線 | V26: (新) 3300型飯糰機 | W26: GKK3600型 飯糰機 | X26: GKK3600型 飯糰機2
B27: 人時性 | C27: 排關 | D27: 226.15 | E27: - | F27: - | G27: 260.86957 | H27: 433.33333 | I27: - | J27: 675 | K27: 825 | L27: - | M27: 880 | N27: 1200 | O27: 872.72727 | P27: 226.65517 | Q27: - | R27: - | S27: 675 | T27: 836.84211 | U27: - | V27: 776.47059 | W27: 1020 | X27: 1023.5294
C28: 實績 | D28: 193.15701 | E28: - | F28: - | G28: 223.49379 | H28: 359.33288 | I28: - | J28: 594.50634 | K28: 712.87129 | L28: - | M28: 753.79419 | N28: 1003.5862 | O28: 748.19185 | P28: 193.56617 | Q28: - | R28: - | S28: 600.84507 | T28: 714.91033 | U28: - | V28: 668.59423 | W28: 862.19214 | X28: 860.8155
C29: 達成率 | D29: =D28/D27 -> 0.85411015 | E29: - | F29: - | G29: =G28/G27 -> 0.85672619 | H29: =H28/H27 -> 0.82922973 | I29: - | J29: =J28/J27 -> 0.88075014 | K29: =K28/K27 -> 0.86408641 | L29: - | M29: =M28/M27 -> 0.85658431 | N29: =N28/N27 -> 0.83632187 | O29: =O28/O27 -> 0.85730316 | P29: =P28/P27 -> 0.85401172 | Q29: - | R29: - | S29: =S28/S27 -> 0.89014085 | T29: =T28/T27 -> 0.85429536 | U29: - | V29: =V28/V27 -> 0.86106833 | W29: =W28/W27 -> 0.84528641 | X29: =X28/X27 -> 0.84102664
B30: 作業 時間 | C30: 開始 | D30: 0.3765625 | E30: - | F30: - | G30: 0.32013889 | H30: 0.25 | I30: - | J30: 0.25 | K30: 0.35833333 | L30: - | M30: 0.25 | N30: 0.25023148 | O30: 0.25 | P30: 0.70833333 | Q30: - | R30: - | S30: 0.70833333 | T30: 0.70833333 | U30: - | V30: 0.70833333 | W30: 0.70834491 | X30: 0.70861111
C31: 結束 | D31: 0.47672454 | E31: - | F31: - | G31: 0.40416667 | H31: 0.31597222 | I31: - | J31: 0.35491898 | K31: 0.44600694 | L31: - | M31: 0.43912037 | N31: 0.46180556 | O31: 0.41806713 | P31: 0.86041667 | Q31: - | R31: - | S31: 0.89322917 | T31: 0.95902778 | U31: - | V31: 0.96137731 | W31: 0.98853009 | X31: 0.97361111
B32: 配置人數 | D32: 13.333333 | E32: - | F32: - | G32: 11.5 | H32: 6 | I32: - | J32: 4 | K32: 4 | L32: - | M32: 3.75 | N32: 3 | O32: 3.6666667 | P32: 14.5 | Q32: - | R32: - | S32: 4 | T32: 3.8 | U32: - | V32: 4.25 | W32: 3.3333333 | X32: 3.4
B33: 主要應用設備 | D33: 伺服包裝機 | E33: ET-55 | F33: ET-600 | G33: 夾心型 | H33: 伺服包裝機 | I33: 伺服包裝機 | J33: 夾心型 | K33: 3300型 | L33: 3300型 | M33: 3300型 | N33: GKK | O33: GKK | P33: 夾心型 | Q33: 伺服包裝機 | R33: 伺服包裝機 | S33: 夾心型 | T33: 3300型 | U33: 3300型 | V33: 3300型 | W33: GKK | X33: GKK
B34: 次要應用設備
B35: 備註

Sheet 0831(18度C)
A1: 大溪廠日報分析 | C1: 總生產量 | D1: =SUM(F5:F242) -> 135198 | E1: 營業額 | F1: =SUM(G5:G242) -> 2606903.3 | G1: 出勤人數 | H1: =L21+L38+L55+L72+L89+L106+L123+L140+L157+L293+L191+L208+L225+L242 -> 78.533333 | I1: 產線配置圖 | L1: 生產實績 | O1: 人時性差異分析 | S1: 日報登錄 | Y1: 分析說明 | AA1: 產能差異分析
A2: 45900 | C2: 人時性 | D2: =AVERAGE(N21,N38,N55,N72,N89,N106,N123,N140,N157,N174,N191,N208,N225,N242) -> 606.41836 | E2: 平均廠價 | F2: =F1/D1 -> 19.282114 | G2: 多次生產數 | H2: =COUNT(H5:H242) -> 4
A3: 線別 | B3: 品類 | C3: 品名 | E3: 廠價 | F3: 生產量 | G3: 營收 | H3: 多次 生產 | I3: 人數 | J3: 產能/時 | K3: 人時性 | L3: 人數 | M3: 產能/時 | N3: 人時性 | O3: 人數 | P3: 人時性 | Q3: 達成率 | R3: 達成率 平均 | S3: 生產時間 | U3: 換線、休息/分 | V3: 稼動時間/分 | W3: 休息時間 | Y3: (屏榮回填) | AA3: 產能/時 | AB3: 達成率 | AC3: 達成率平均
S4: 開始 | T4: 結束 | W4: 開始 | X4: 結束
A5: 便當一線 | B5: 18℃-壽司手卷 | C5: 一配海饌雙手卷 | E5: 29.85 | F5: 2418 | G5: =E5*F5 -> 72177.3 | I5: 17 | J5: 3273 | K5: =J5/I5 -> 192.52941 | L5: 17 | M5: =F5/V5*60 -> 2802.5757 | N5: =M5/L5 -> 164.85739 | O5: =L5-I5 -> 0 | P5: =N5-K5 -> -27.67202 | Q5: =N5/K5 -> 0.85627121 | R5: =Q21 -> 0.85411015 | S5: 0.3765625 | T5: 0.41251157 | U5: 6.8333333 | V5: 51.766667 | AA5: =M5-J5 -> -470.42434 | AB5: =M5/J5 -> 0.85627121 | AC5: =AB21 -> 0.85411015
B6: 18℃-壽司手卷 | C6: 一配雙饗雙手卷 | E6: 29.52 | F6: 2445 | G6: =E6*F6 -> 72176.4 | I6: 17 | J6: 3273 | K6: =J6/I6 -> 192.52941 | L6: 17 | M6: =F6/V6*60 -> 2803.1847 | N6: =M6/L6 -> 164.89322 | O6: =L6-I6 -> 0 | P6: =N6-K6 -> -27.636193 | Q6: =N6/K6 -> 0.85645729 | S6: 0.41666667 | T6: 0.45300926 | U6: 5.9833333 | V6: 52.333333 | AA6: =M6-J6 -> -469.81529 | AB6: =M6/J6 -> 0.85645729
B7: 18℃-壽司手卷 | C7: 一配日式厚蛋脆卷 | E7: 21.61 | F7: 1042 | G7: =E7*F7 -> 22517.62 | I7: 6 | J7: 2500 | K7: =J7/I7 -> 416.66667 | L7: 6 | M7: =F7/V7*60 -> 2120.5201 | N7: =M7/L7 -> 353.42001 | O7: =L7-I7 -> 0 | P7: =N7-K7 -> -63.246655 | Q7: =N7/K7 -> 0.84820803 | S7: 0.45625 | T7: 0.47672454 | U7: 4.6666667 | V7: 29.483333 | W7: 0.47672454 | X7: 0.51666667 | AA7: =M7-J7 -> -379.47993 | AB7: =M7/J7 -> 0.84820803
B21: 平均 | I21: =AVERAGE(I5:I20) -> 13.333333 | J21: =AVERAGE(J5:J20) -> 3015.3333 | K21: =J21/I21 -> 226.15 | L21: =AVERAGE(L5:L20) -> 13.333333 | M21: =AVERAGE(M5:M20) -> 2575.4268 | N21: =M21/L21 -> 193.15701 | O21: =L21-I21 -> 0 | P21: =N21-K21 -> -32.992989 | Q21: =N21/K21 -> 0.85411015 | S21: =S5 -> 0.3765625 | T21: =INDEX(T5:T20,COUNTA(T5:T20)) -> 0.47672454 | AA21: =M21-J21 -> -439.90652 | AB21: =M21/J21 -> 0.85411015
A22: 自動包裝機 | B22: 18℃-壽司手卷 | C22: 一配新之助的豆皮壽司喔 | E22: 25.52 | F22: 2570 | G22: =E22*F22 -> 65586.4 | I22: 12 | J22: 3000 | K22: =J22/I22 -> 250 | L22: 12 | M22: =F22/V22*60 -> 2570 | N22: =M22/L22 -> 214.16667 | O22: =L22-I22 -> 0 | P22: =N22-K22 -> -35.833333 | Q22: =N22/K22 -> 0.85666667 | R22: =Q38 -> 0.85672619 | S22: 0.32013889 | T22: 0.36180556 | U22: 7 | V22: 60 | AA22: =M22-J22 -> -430 | AB22: =M22/J22 -> 0.85666667 | AC22: =AB38 -> 0.85672619
B23: 18℃-壽司手卷 | C23: 一配長野稻荷壽司 | E23: 25.64 | F23: 2399 | G23: =E23*F23 -> 61510.36 | I23: 11 | J23: 3000 | K23: =J23/I23 -> 272.72727 | L23: 11 | M23: =F23/V23*60 -> 2570.3571 | N23: =M23/L23 -> 233.66883 | O23: =L23-I23 -> 0 | P23: =N23-K23 -> -39.058442 | Q23: =N23/K23 -> 0.85678571 | S23: 0.36527778 | T23: 0.40416667 | U23: 5 | V23: 56 | AA23: =M23-J23 -> -429.64286 | AB23: =M23/J23 -> 0.85678571
B38: 平均 | I38: =AVERAGE(I22:I37) -> 11.5 | J38: =AVERAGE(J22:J37) -> 3000 | K38: =J38/I38 -> 260.86957 | L38: =AVERAGE(L22:L37) -> 11.5 | M38: =AVERAGE(M22:M37) -> 2570.1786 | N38: =M38/L38 -> 223.49379 | O38: =L38-I38 -> 0 | P38: =N38-K38 -> -37.375776 | Q38: =N38/K38 -> 0.85672619 | S38: =S22 -> 0.32013889 | T38: =INDEX(T22:T37,COUNTA(T22:T37)) -> 0.40416667 | AA38: =M38-J38 -> -429.82143 | AB38: =M38/J38 -> 0.85672619
A39: 自動包裝機2 | B39: 18℃-壽司手卷 | C39: 一配芝麻海苔香鬆細卷 | E39: 14.06 | F39: 1096 | G39: =E39*F39 -> 15409.76 | I39: 6 | J39: 2600 | K39: =J39/I39 -> 433.33333 | L39: 6 | M39: =F39/V39*60 -> 2165.5324 | N39: =M39/L39 -> 360.92206 | O39: =L39-I39 -> 0 | P39: =N39-K39 -> -72.41127 | Q39: =N39/K39 -> 0.83289707 | R39: =Q55 -> 0.82922973 | S39: 0.25 | T39: 0.27108796 | V39: 30.366667 | AA39: =M39-J39 -> -434.46762 | AB39: =M39/J39 -> 0.83289707 | AC39: =AB55 -> 0.82922973
B40: 18℃-壽司手卷 | C40: 一配鮪魚沙拉細卷 | E40: 14.81 | F40: 1255 | G40: =E40*F40 -> 18586.55 | I40: 6 | J40: 2600 | K40: =J40/I40 -> 433.33333 | L40: 6 | M40: =F40/V40*60 -> 2167.9463 | N40: =M40/L40 -> 361.32438 | O40: =L40-I40 -> 0 | P40: =N40-K40 -> -72.008957 | Q40: =N40/K40 -> 0.83382548 | S40: 0.27450231 | T40: 0.29862269 | U40: 4.9166667 | V40: 34.733333 | AA40: =M40-J40 -> -432.05374 | AB40: =M40/J40 -> 0.83382548
B41: 18℃-壽司手卷 | C41: 一配炙烤焦糖鮭魚細卷 | E41: 17.87 | F41: 737 | G41: =E41*F41 -> 13170.19 | I41: 6 | J41: 2600 | K41: =J41/I41 -> 433.33333 | L41: 6 | M41: =F41/V41*60 -> 2134.5133 | N41: =M41/L41 -> 355.75221 | O41: =L41-I41 -> 0 | P41: =N41-K41 -> -77.581121 | Q41: =N41/K41 -> 0.82096664 | S41: 0.30158565 | T41: 0.31597222 | U41: 4.2666667 | V41: 20.716667 | AA41: =M41-J41 -> -465.48673 | AB41: =M41/J41 -> 0.82096664
B55: 平均 | I55: =AVERAGE(I39:I54) -> 6 | J55: =AVERAGE(J39:J54) -> 2600 | K55: =J55/I55 -> 433.33333 | L55: =AVERAGE(L39:L54) -> 6 | M55: =AVERAGE(M39:M54) -> 2155.9973 | N55: =M55/L55 -> 359.33288 | O55: =L55-I55 -> 0 | P55: =N55-K55 -> -74.000449 | Q55: =N55/K55 -> 0.82922973 | S55: =S39 -> 0.25 | T55: =INDEX(T39:T54,COUNTA(T39:T54)) -> 0.31597222 | AA55: =M55-J55 -> -444.0027 | AB55: =M55/J55 -> 0.82922973
A56: 味付飯糰線B | B56: 18℃-飯糰 | C56: 一配經典肉鬆飯糰 | E56: 14.03 | F56: 5988 | G56: =E56*F56 -> 84011.64 | I56: 4 | J56: 2700 | K56: =J56/I56 -> 675 | L56: 4 | M56: =F56/V56*60 -> 2378.0254 | N56: =M56/L56 -> 594.50634 | O56: =L56-I56 -> 0 | P56: =N56-K56 -> -80.493657 | Q56: =N56/K56 -> 0.88075014 | R56: =Q72 -> 0.88075014 | S56: 0.25 | T56: 0.35491898 | V56: 151.08333 | AA56: =M56-J56 -> -321.97463 | AB56: =M56/J56 -> 0.88075014 | AC56: =AB72 -> 0.88075014
B72: 平均 | I72: =AVERAGE(I56:I71) -> 4 | J72: =AVERAGE(J56:J71) -> 2700 | K72: =J72/I72 -> 675 | L72: =AVERAGE(L56:L71) -> 4 | M72: =AVERAGE(M56:M71) -> 2378.0254 | N72: =M72/L72 -> 594.50634 | O72: =L72-I72 -> 0 | P72: =N72-K72 -> -80.493657 | Q72: =N72/K72 -> 0.88075014 | S72: =S56 -> 0.25 | T72: =INDEX(T56:T71,COUNTA(T56:T71)) -> 0.35491898 | AA72: =M72-J72 -> -321.97463 | AB72: =M72/J72 -> 0.88075014
A73: (舊) 3300型飯糰線 | B73: 18℃-飯糰 | C73: 一配雞肉飯飯糰 | E73: 16.66 | F73: 6000 | G73: =E73*F73 -> 99960 | I73: 4 | J73: 3300 | K73: =J73/I73 -> 825 | L73: 4 | M73: =F73/V73*60 -> 2851.4851 | N73: =M73/L73 -> 712.87129 | O73: =L73-I73 -> 0 | P73: =N73-K73 -> -112.12871 | Q73: =N73/K73 -> 0.86408641 | R73: =Q89 -> 0.86408641 | S73: 0.35833333 | T73: 0.44600694 | V73: 126.25 | AA73: =M73-J73 -> -448.51485 | AB73: =M73/J73 -> 0.86408641 | AC73: =AB89 -> 0.86408641
B89: 平均 | I89: =AVERAGE(I73:I88) -> 4 | J89: =AVERAGE(J73:J88) -> 3300 | K89: =J89/I89 -> 825 | L89: =AVERAGE(L73:L88) -> 4 | M89: =AVERAGE(M73:M88) -> 2851.4851 | N89: =M89/L89 -> 712.87129 | O89: =L89-I89 -> 0 | P89: =N89-K89 -> -112.12871 | Q89: =N89/K89 -> 0.86408641 | S89: =S73 -> 0.35833333 | T89: =INDEX(T73:T88,COUNTA(T73:T88)) -> 0.44600694 | AA89: =M89-J89 -> -448.51485 | AB89: =M89/J89 -> 0.86408641
A90: (新) 3300型飯糰機 | B90: 18℃-飯糰 | C90: 一配三杯辣海瓜子飯糰 | E90: 21.45 | F90: 1802 | G90: =E90*F90 -> 38652.9 | I90: 3 | J90: 3300 | K90: =J90/I90 -> 1100 | L90: 3 | M90: =F90/V90*60 -> 2821.7486 | N90: =M90/L90 -> 940.58286 | O90: =L90-I90 -> 0 | P90: =N90-K90 -> -159.41714 | Q90: =N90/K90 -> 0.85507533 | R90: =Q106 -> 0.85658431 | S90: 0.25 | T90: 0.2766088 | V90: 38.316667 | AA90: =M90-J90 -> -478.25141 | AB90: =M90/J90 -> 0.85507533 | AC90: =AB106 -> 0.85658431
B91: 18℃-飯糰 | C91: 一配哇沙米魚卵沙拉飯糰 | E91: 15.71 | F91: 4855 | G91: =E91*F91 -> 76272.05 | I91: 3 | J91: 3300 | K91: =J91/I91 -> 1100 | L91: 3 | M91: =F91/V91*60 -> 2838.2592 | N91: =M91/L91 -> 946.08639 | O91: =L91-I91 -> 0 | P91: =N91-K91 -> -153.91361 | Q91: =N91/K91 -> 0.86007854 | S91: 0.28219907 | T91: 0.35347222 | U91: 8.05 | V91: 102.63333 | AA91: =M91-J91 -> -461.74082 | AB91: =M91/J91 -> 0.86007854
B92: 18℃-飯糰 | C92: 一配鹽蔥燒肉飯糰 | E92: 17.89 | F92: 3639 | G92: =E92*F92 -> 65101.71 | I92: 4 | J92: 3300 | K92: =J92/I92 -> 825 | L92: 4 | M92: =F92/V92*60 -> 2833.1315 | N92: =M92/L92 -> 708.28287 | O92: =L92-I92 -> 0 | P92: =N92-K92 -> -116.71713 | Q92: =N92/K92 -> 0.85852469 | S92: 0.35625 | T92: 0.40976852 | U92: 4 | V92: 77.066667 | AA92: =M92-J92 -> -466.86851 | AB92: =M92/J92 -> 0.85852469
B93: 18℃-飯糰 | C93: 一配壹號醬炙烤牛飯糰 | E93: 22.28 | F93: 1657 | G93: =E93*F93 -> 36917.96 | I93: 5 | J93: 3300 | K93: =J93/I93 -> 660 | L93: 5 | M93: =F93/V93*60 -> 2813.7736 | N93: =M93/L93 -> 562.75472 | O93: =L93-I93 -> 0 | P93: =N93-K93 -> -97.245283 | Q93: =N93/K93 -> 0.85265866 | S93: 0.41458333 | T93: 0.43912037 | U93: 6.9333333 | V93: 35.333333 | AA93: =M93-J93 -> -486.22642 | AB93: =M93/J93 -> 0.85265866
B106: 平均 | I106: =AVERAGE(I90:I105) -> 3.75 | J106: =AVERAGE(J90:J105) -> 3300 | K106: =J106/I106 -> 880 | L106: =AVERAGE(L90:L105) -> 3.75 | M106: =AVERAGE(M90:M105) -> 2826.7282 | N106: =M106/L106 -> 753.79419 | O106: =L106-I106 -> 0 | P106: =N106-K106 -> -126.20581 | Q106: =N106/K106 -> 0.85658431 | S106: =S90 -> 0.25 | T106: =INDEX(T90:T105,COUNTA(T90:T105)) -> 0.43912037 | AA106: =M106-J106 -> -473.27179 | AB106: =M106/J106 -> 0.85658431
A107: GKK3600型 飯糰機 | B107: 18℃-飯糰 | C107: 一配明太子龍蝦風味沙拉飯糰 | E107: 18.18 | F107: 3141 | G107: =E107*F107 -> 57103.38 | I107: 3 | J107: 3600 | K107: =J107/I107 -> 1200 | L107: 3 | M107: =F107/V107*60 -> 3006.5408 | N107: =M107/L107 -> 1002.1803 | O107: =L107-I107 -> 0 | P107: =N107-K107 -> -197.81973 | Q107: =N107/K107 -> 0.83515023 | R107: =Q123 -> 0.83632187 | S107: 0.25023148 | T107: 0.29376157 | V107: 62.683333 | AA107: =M107-J107 -> -593.45919 | AB107: =M107/J107 -> 0.83515023 | AC107: =AB123 -> 0.83632187
B108: 18℃-飯糰 | C108: 一配蔬食鮪魚飯糰 | E108: 18.18 | F108: 2863 | G108: =E108*F108 -> 52049.34 | I108: 3 | J108: 3600 | K108: =J108/I108 -> 1200 | L108: 3 | M108: =F108/V108*60 -> 3003.1469 | N108: =M108/L108 -> 1001.049 | O108: =L108-I108 -> 0 | P108: =N108-K108 -> -198.95105 | Q108: =N108/K108 -> 0.83420746 | S108: 0.30763889 | T108: 0.34736111 | U108: 19.983333 | V108: 57.2 | AA108: =M108-J108 -> -596.85315 | AB108: =M108/J108 -> 0.83420746
B109: 18℃-飯糰 | C109: 一配鮪魚飯糰 | E109: 14.28 | F109: 7538 | G109: =E109*F109 -> 107642.64 | I109: 3 | J109: 3600 | K109: =J109/I109 -> 1200 | L109: 3 | M109: =F109/V109*60 -> 3022.5885 | N109: =M109/L109 -> 1007.5295 | O109: =L109-I109 -> 0 | P109: =N109-K109 -> -192.47048 | Q109: =N109/K109 -> 0.83960793 | S109: 0.35789352 | T109: 0.46180556 | U109: 15.166667 | V109: 149.63333 | AA109: =M109-J109 -> -577.41145 | AB109: =M109/J109 -> 0.83960793
B123: 平均 | I123: =AVERAGE(I107:I122) -> 3 | J123: =AVERAGE(J107:J122) -> 3600 | K123: =J123/I123 -> 1200 | L123: =AVERAGE(L107:L122) -> 3 | M123: =AVERAGE(M107:M122) -> 3010.7587 | N123: =M123/L123 -> 1003.5862 | O123: =L123-I123 -> 0 | P123: =N123-K123 -> -196.41375 | Q123: =N123/K123 -> 0.83632187 | S123: =S107 -> 0.25023148 | T123: =INDEX(T107:T122,COUNTA(T107:T122)) -> 0.46180556 | AA123: =M123-J123 -> -589.24126 | AB123: =M123/J123 -> 0.83632187
A124: GKK3600型 飯糰機2 | B124: 18℃-飯糰 | C124: 一配贅沢鮭魚肚飯糰 | E124: 30 | F124: 4282 | G124: =E124*F124 -> 128460 | I124: 3 | J124: 3000 | K124: =J124/I124 -> 1000 | L124: 3 | M124: =F124/V124*60 -> 2585.5753 | N124: =M124/L124 -> 861.85844 | O124: =L124-I124 -> 0 | P124: =N124-K124 -> -138.14156 | Q124: =N124/K124 -> 0.86185844 | R124: =Q140 -> 0.85730316 | S124: 0.25 | T124: 0.31900463 | V124: 99.366667 | AA124: =M124-J124 -> -414.42469 | AB124: =M124/J124 -> 0.86185844 | AC124: =AB140 -> 0.85730316
B125: 18℃-飯糰 | C125: 一配熟成紅鮭飯糰 | E125: 25.03 | F125: 2279 | G125: =E125*F125 -> 57043.37 | I125: 4 | J125: 3300 | K125: =J125/I125 -> 825 | L125: 4 | M125: =F125/V125*60 -> 2820.3506 | N125: =M125/L125 -> 705.08766 | O125: =L125-I125 -> 0 | P125: =N125-K125 -> -119.91234 | Q125: =N125/K125 -> 0.85465171 | S125: 0.33263889 | T125: 0.36630787 | U125: 19.633333 | V125: 48.483333 | AA125: =M125-J125 -> -479.64936 | AB125: =M125/J125 -> 0.85465171
B126: 18℃-飯糰 | C126: 一配北海道秋鮭親子飯糰 | E126: 24.83 | F126: 2621 | G126: =E126*F126 -> 65079.43 | I126: 4 | J126: 3300 | K126: =J126/I126 -> 825 | L126: 4 | M126: =F126/V126*60 -> 2824.1844 | N126: =M126/L126 -> 706.04609 | O126: =L126-I126 -> 0 | P126: =N126-K126 -> -118.95391 | Q126: =N126/K126 -> 0.85581345 | S126: 0.37939815 | T126: 0.41806713 | U126: 18.85 | V126: 55.683333 | AA126: =M126-J126 -> -475.81562 | AB126: =M126/J126 -> 0.85581345
B140: 平均 | I140: =AVERAGE(I124:I139) -> 3.6666667 | J140: =AVERAGE(J124:J139) -> 3200 | K140: =J140/I140 -> 872.72727 | L140: =AVERAGE(L124:L139) -> 3.6666667 | M140: =AVERAGE(M124:M139) -> 2743.3701 | N140: =M140/L140 -> 748.19185 | O140: =L140-I140 -> 0 | P140: =N140-K140 -> -124.53543 | Q140: =N140/K140 -> 0.85730316 | S140: =S124 -> 0.25 | T140: =INDEX(T124:T139,COUNTA(T124:T139)) -> 0.41806713 | AA140: =M140-J140 -> -456.62989 | AB140: =M140/J140 -> 0.85730316
A141: 自動包裝機 (二配) | B141: 18℃-壽司手卷 | C141: 二配雙饗雙手卷 | E141: 29.52 | F141: 2404 | G141: =E141*F141 -> 70966.08 | I141: 17 | J141: 3273 | K141: =J141/I141 -> 192.52941 | L141: 17 | M141: =F141/V141*60 -> 2801.6834 | N141: =M141/L141 -> 164.80491 | O141: =L141-I141 -> 0 | P141: =N141-K141 -> -27.724506 | Q141: =N141/K141 -> 0.85599859 | R141: =Q157 -> 0.85401172 | S141: 0.70833333 | T141: 0.74408565 | V141: 51.483333 | AA141: =M141-J141 -> -471.31661 | AB141: =M141/J141 -> 0.85599859 | AC141: =AB157 -> 0.85401172
B142: 18℃-壽司手卷 | C142: 二配海饌雙手卷 | E142: 29.85 | F142: 2459 | G142: =E142*F142 -> 73401.15 | I142: 17 | J142: 3273 | K142: =J142/I142 -> 192.52941 | L142: 17 | M142: =F142/V142*60 -> 2803.1666 | N142: =M142/L142 -> 164.89215 | O142: =L142-I142 -> 0 | P142: =N142-K142 -> -27.637261 | Q142: =N142/K142 -> 0.85645174 | S142: 0.74956019 | T142: 0.78611111 | U142: 7.8833333 | V142: 52.633333 | AA142: =M142-J142 -> -469.83344 | AB142: =M142/J142 -> 0.85645174
B143: 18℃-飯糰 | C143: 二配兩粒飯糰(鮪魚&培根蛋沙拉) | E143: 28.57 | F143: 1889 | G143: =E143*F143 -> 53968.73 | I143: 13 | J143: 3600 | K143: =J143/I143 -> 276.92308 | L143: 13 | M143: =F143/V143*60 -> 3052.2442 | N143: =M143/L143 -> 234.78801 | O143: =L143-I143 -> 0 | P143: =N143-K143 -> -42.135064 | Q143: =N143/K143 -> 0.8478456 | S143: 0.79097222 | T143: 0.81675926 | U143: 7 | V143: 37.133333 | AA143: =M143-J143 -> -547.75583 | AB143: =M143/J143 -> 0.8478456
B144: 18℃-壽司手卷 | C144: 二配長野稻荷壽司 | E144: 25.64 | F144: 2397 | G144: =E144*F144 -> 61459.08 | I144: 11 | J144: 3000 | K144: =J144/I144 -> 272.72727 | L144: 11 | M144: =F144/V144*60 -> 2569.7439 | N144: =M144/L144 -> 233.61308 | O144: =L144-I144 -> 0 | P144: =N144-K144 -> -39.114191 | Q144: =N144/K144 -> 0.8565813 | S144: 0.82155093 | T144: 0.86041667 | U144: 6.9 | V144: 55.966667 | AA144: =M144-J144 -> -430.2561 | AB144: =M144/J144 -> 0.8565813
B157: 平均 | I157: =AVERAGE(I141:I156) -> 14.5 | J157: =AVERAGE(J141:J156) -> 3286.5 | K157: =J157/I157 -> 226.65517 | L157: =AVERAGE(L141:L156) -> 14.5 | M157: =AVERAGE(M141:M156) -> 2806.7095 | N157: =M157/L157 -> 193.56617 | O157: =L157-I157 -> 0 | P157: =N157-K157 -> -33.089 | Q157: =N157/K157 -> 0.85401172 | S157: =S141 -> 0.70833333 | T157: =INDEX(T141:T156,COUNTA(T141:T156)) -> 0.86041667 | AA157: =M157-J157 -> -479.7905 | AB157: =M157/J157 -> 0.85401172
A158: 味付飯糰線B (二配) | B158: 18℃-飯糰 | C158: 二配經典肉鬆飯糰 | E158: 14.03 | F158: 10665 | G158: =E158*F158 -> 149629.95 | I158: 4 | J158: 2700 | K158: =J158/I158 -> 675 | L158: 4 | M158: =F158/V158*60 -> 2403.3803 | N158: =M158/L158 -> 600.84507 | O158: =L158-I158 -> 0 | P158: =N158-K158 -> -74.15493 | Q158: =N158/K158 -> 0.89014085 | R158: =Q174 -> 0.89014085 | S158: 0.70833333 | T158: 0.89322917 | V158: 266.25 | AA158: =M158-J158 -> -296.61972 | AB158: =M158/J158 -> 0.89014085 | AC158: =AB174 -> 0.89014085
B174: 平均 | I174: =AVERAGE(I158:I173) -> 4 | J174: =AVERAGE(J158:J173) -> 2700 | K174: =J174/I174 -> 675 | L174: =AVERAGE(L158:L173) -> 4 | M174: =AVERAGE(M158:M173) -> 2403.3803 | N174: =M174/L174 -> 600.84507 | O174: =L174-I174 -> 0 | P174: =N174-K174 -> -74.15493 | Q174: =N174/K174 -> 0.89014085 | S174: =S158 -> 0.70833333 | T174: =INDEX(T158:T173,COUNTA(T158:T173)) -> 0.89322917 | AA174: =M174-J174 -> -296.61972 | AB174: =M174/J174 -> 0.89014085
A175: (舊) 3300型飯糰線 (二配) | B175: 18℃-飯糰 | C175: 二配大飯糰韓式炸雞 | E175: 27.58 | F175: 1617 | G175: =E175*F175 -> 44596.86 | I175: 4 | J175: 3000 | K175: =J175/I175 -> 750 | L175: 4 | M175: =F175/V175*60 -> 2530.9565 | N175: =M175/L175 -> 632.73913 | O175: =L175-I175 -> 0 | P175: =N175-K175 -> -117.26087 | Q175: =N175/K175 -> 0.84365217 | R175: =Q191 -> 0.85429536 | S175: 0.70833333 | T175: 0.7349537 | V175: 38.333333 | AA175: =M175-J175 -> -469.04348 | AB175: =M175/J175 -> 0.84365217 | AC175: =AB191 -> 0.85429536
...

Sheet 0831(4度C)
A1: 大溪廠日報分析 | C1: 總生產量 | D1: =SUM(F5:F157) -> 116496 | E1: 營業額 | F1: =SUM(G5:G157) -> 5118239.1 | G1: 出勤人數 | H1: =L21+L38+L55+L72+L89+L106+L123+L140+L157+L293 -> 171.44841 | I1: 產線配置圖 | L1: 生產實績 | O1: 人時性差異分析 | S1: 日報登錄 | Y1: 分析說明 | AA1: 產能差異分析
A2: 45900 | C2: 人時性 | D2: =AVERAGE(N21,N38,N55,N72,N89,N106,N123,N140,N157) -> 134.04025 | E2: 平均廠價 | F2: =F1/D1 -> 43.934891 | G2: 多次生產數 | H2: =COUNT(H5:H157) -> 1
A3: 線別 | B3: 品類 | C3: 品名 | E3: 廠價 | F3: 生產量 | G3: 營收 | H3: 多次 生產 | I3: 人數 | J3: 產能/時 | K3: 人時性 | L3: 人數 | M3: 產能/時 | N3: 人時性 | O3: 人數 | P3: 人時性 | Q3: 達成率 | R3: 達成率 平均 | S3: 生產時間 | U3: 換線、休息/分 | V3: 稼動時間/分 | W3: 休息時間 | Y3: (屏榮回填) | AA3: 產能/時 | AB3: 達成率 | AC3: 達成率平均
S4: 開始 | T4: 結束 | W4: 開始 | X4: 結束
A5: 便當一線 | B5: 微波小吃 | C5: 日式茶碗蒸 | E5: 19.7 | F5: 3099 | G5: =E5*F5 -> 61050.3 | I5: 13 | J5: 1200 | K5: =J5/I5 -> 92.307692 | L5: 13 | M5: =F5/V5*60 -> 1059.9905 | N5: =M5/L5 -> 81.537731 | O5: =L5-I5 -> 0 | P5: =N5-K5 -> -10.769962 | Q5: =N5/K5 -> 0.88332542 | R5: =Q21 -> 0.87539561 | S5: 0.25 | T5: 0.37181713 | V5: 175.41667 | AA5: =M5-J5 -> -140.0095 | AB5: =M5/J5 -> 0.88332542 | AC5: =AB21 -> 0.87539561
B6: 4℃-飯糰 | C6: 麻油雞飯糰 | E6: 29.97 | F6: 2728 | G6: =E6*F6 -> 81758.16 | I6: 20 | J6: 2600 | K6: =J6/I6 -> 130 | L6: 20 | M6: =F6/V6*60 -> 2266.5128 | N6: =M6/L6 -> 113.32564 | O6: =L6-I6 -> 0 | P6: =N6-K6 -> -16.67436 | Q6: =N6/K6 -> 0.8717357 | S6: 0.51666667 | T6: 0.56681713 | U6: 57.516667 | V6: 72.216667 | AA6: =M6-J6 -> -333.48719 | AB6: =M6/J6 -> 0.8717357
B21: 平均 | I21: =AVERAGE(I5:I20) -> 16.5 | J21: =AVERAGE(J5:J20) -> 1900 | K21: =J21/I21 -> 115.15152 | L21: =AVERAGE(L5:L20) -> 16.5 | M21: =AVERAGE(M5:M20) -> 1663.2517 | N21: =M21/L21 -> 100.80313 | O21: =L21-I21 -> 0 | P21: =N21-K21 -> -14.348385 | Q21: =N21/K21 -> 0.87539561 | S21: =S5 -> 0.25 | T21: =INDEX(T5:T20,COUNTA(T5:T20)) -> 0.56681713 | AA21: =M21-J21 -> -236.74835 | AB21: =M21/J21 -> 0.87539561
A22: 便當二線 | B22: 便當 | C22: 鰻牛雙饗匠食盒 | E22: 71.88 | F22: 1629 | G22: =E22*F22 -> 117092.52 | I22: 26 | J22: 2000 | K22: =J22/I22 -> 76.923077 | L22: 26 | M22: =F22/V22*60 -> 1702.7875 | N22: =M22/L22 -> 65.491825 | O22: =L22-I22 -> 0 | P22: =N22-K22 -> -11.431252 | Q22: =N22/K22 -> 0.85139373 | R22: =Q38 -> 0.85600078 | S22: 0.25 | T22: 0.28986111 | V22: 57.4 | AA22: =M22-J22 -> -297.21254 | AB22: =M22/J22 -> 0.85139373 | AC22: =AB38 -> 0.85600078
B23: 微波主食 | C23: 糖燻野郎三十天熟成牛飯 | E23: 56.77 | F23: 4709 | G23: =E23*F23 -> 267329.93 | I23: 26 | J23: 2000 | K23: =J23/I23 -> 76.923077 | L23: 26 | M23: =F23/V23*60 -> 1742.9981 | N23: =M23/L23 -> 67.03839 | O23: =L23-I23 -> 0 | P23: =N23-K23 -> -9.8846866 | Q23: =N23/K23 -> 0.87149907 | S23: 0.29444444 | T23: 0.40701389 | U23: 6.6 | V23: 162.1 | AA23: =M23-J23 -> -257.00185 | AB23: =M23/J23 -> 0.87149907
B24: 微波主食 | C24: 柚見極炙烤牛 | E24: 57.3 | F24: 1640 | G24: =E24*F24 -> 93972 | I24: 26 | J24: 2000 | K24: =J24/I24 -> 76.923077 | L24: 26 | M24: =F24/V24*60 -> 1702.4221 | N24: =M24/L24 -> 65.477775 | O24: =L24-I24 -> 0 | P24: =N24-K24 -> -11.445302 | Q24: =N24/K24 -> 0.85121107 | S24: 0.41125 | T24: 0.45138889 | U24: 6.1 | V24: 57.8 | AA24: =M24-J24 -> -297.57785 | AB24: =M24/J24 -> 0.85121107
B25: 微波主食 | C25: 蒜蒜燒豚飯 | E25: 51.86 | F25: 1842 | G25: =E25*F25 -> 95526.12 | I25: 26 | J25: 2000 | K25: =J25/I25 -> 76.923077 | L25: 26 | M25: =F25/V25*60 -> 1705.5556 | N25: =M25/L25 -> 65.598291 | O25: =L25-I25 -> 0 | P25: =N25-K25 -> -11.324786 | Q25: =N25/K25 -> 0.85277778 | S25: 0.45569444 | T25: 0.50069444 | U25: 6.2 | V25: 64.8 | W25: 0.50069444 | X25: 0.54173611 | AA25: =M25-J25 -> -294.44444 | AB25: =M25/J25 -> 0.85277778
B26: 微波主食 | C26: 姨次滿足熟成牛豚雙拼 | E26: 57.3 | F26: 594 | G26: =E26*F26 -> 34036.2 | H26: 2 | I26: 25 | J26: 2000 | K26: =J26/I26 -> 80 | L26: 25 | M26: =F26/V26*60 -> 1705.2632 | N26: =M26/L26 -> 68.210526 | O26: =L26-I26 -> 0 | P26: =N26-K26 -> -11.789474 | Q26: =N26/K26 -> 0.85263158 | S26: 0.54173611 | T26: 0.55625 | U26: 59.1 | V26: 20.9 | AA26: =M26-J26 -> -294.73684 | AB26: =M26/J26 -> 0.85263158
B27: 微波主食 | C27: 壹號醬雞豚雙拼 | E27: 56.43 | F27: 2933 | G27: =E27*F27 -> 165509.19 | I27: 22 | J27: 2000 | K27: =J27/I27 -> 90.909091 | L27: 22 | M27: =F27/V27*60 -> 1714.6476 | N27: =M27/L27 -> 77.938528 | O27: =L27-I27 -> 0 | P27: =N27-K27 -> -12.970563 | Q27: =N27/K27 -> 0.85732381 | S27: 0.55997685 | T27: 0.63125 | U27: 5.3666667 | V27: 102.63333 | AA27: =M27-J27 -> -285.35239 | AB27: =M27/J27 -> 0.85732381
B28: 微波主食 | C28: 姨次滿足熟成牛豚雙拼 | E28: 57.3 | F28: 1650 | G28: =E28*F28 -> 94545 | I28: 25 | J28: 2000 | K28: =J28/I28 -> 80 | L28: 25 | M28: =F28/V28*60 -> 1710.3369 | N28: =M28/L28 -> 68.413475 | O28: =L28-I28 -> 0 | P28: =N28-K28 -> -11.586525 | Q28: =N28/K28 -> 0.85516844 | S28: 0.63619213 | T28: 0.67638889 | U28: 7.1166667 | V28: 57.883333 | AA28: =M28-J28 -> -289.66312 | AB28: =M28/J28 -> 0.85516844
AQ29: =AI8 -> 0
B38: 平均 | I38: =AVERAGE(I22:I37) -> 25.142857 | J38: =AVERAGE(J22:J37) -> 2000 | K38: =J38/I38 -> 79.545455 | L38: =AVERAGE(L22:L37) -> 25.142857 | M38: =AVERAGE(M22:M37) -> 1712.0016 | N38: =M38/L38 -> 68.090971 | O38: =L38-I38 -> 0 | P38: =N38-K38 -> -11.454483 | Q38: =N38/K38 -> 0.85600078 | S38: =S22 -> 0.25 | T38: =INDEX(T22:T37,COUNTA(T22:T37)) -> 0.67638889 | AA38: =M38-J38 -> -287.99843 | AB38: =M38/J38 -> 0.85600078
A39: 涼麵一線 | B39: 熱食義麵 | C39: 金沙豆腐細扁麵 | E39: 49.52 | F39: 2277 | G39: =E39*F39 -> 112757.04 | I39: 24 | J39: 2000 | K39: =J39/I39 -> 83.333333 | L39: 24 | M39: =F39/V39*60 -> 1717.0507 | N39: =M39/L39 -> 71.543779 | O39: =L39-I39 -> 0 | P39: =N39-K39 -> -11.789555 | Q39: =N39/K39 -> 0.85852535 | R39: =Q55 -> 0.85973281 | S39: 0.25030093 | T39: 0.30555556 | V39: 79.566667 | AA39: =M39-J39 -> -282.94931 | AB39: =M39/J39 -> 0.85852535 | AC39: =AB55 -> 0.85973281
B40: 微波小吃 | C40: 越式牛肉寬粉 | E40: 51.82 | F40: 2482 | G40: =E40*F40 -> 128617.24 | I40: 23 | J40: 1800 | K40: =J40/I40 -> 78.26087 | L40: 23 | M40: =F40/V40*60 -> 1544.5462 | N40: =M40/L40 -> 67.154184 | O40: =L40-I40 -> 0 | P40: =N40-K40 -> -11.106685 | Q40: =N40/K40 -> 0.85808124 | S40: 0.30902778 | T40: 0.3759838 | U40: 5 | V40: 96.416667 | AA40: =M40-J40 -> -255.45376 | AB40: =M40/J40 -> 0.85808124
B41: 便當 | C41: 美式雞丁餐盒 | E41: 59.34 | F41: 2729 | G41: =E41*F41 -> 161938.86 | I41: 24 | J41: 2000 | K41: =J41/I41 -> 83.333333 | L41: 24 | M41: =F41/V41*60 -> 1716.0524 | N41: =M41/L41 -> 71.502183 | O41: =L41-I41 -> 0 | P41: =N41-K41 -> -11.83115 | Q41: =N41/K41 -> 0.8580262 | S41: 0.38125 | T41: 0.44751157 | U41: 7.5833333 | V41: 95.416667 | W41: 0.44751157 | X41: 0.48611111 | AA41: =M41-J41 -> -283.9476 | AB41: =M41/J41 -> 0.8580262
B42: 便當 | C42: 烤蛋白餐盒 | E42: 58.67 | F42: 5445 | G42: =E42*F42 -> 319458.15 | I42: 24 | J42: 2000 | K42: =J42/I42 -> 83.333333 | L42: 24 | M42: =F42/V42*60 -> 1728.2666 | N42: =M42/L42 -> 72.011109 | O42: =L42-I42 -> 0 | P42: =N42-K42 -> -11.322224 | Q42: =N42/K42 -> 0.86413331 | S42: 0.48611111 | T42: 0.61738426 | U42: 55.583333 | V42: 189.03333 | AA42: =M42-J42 -> -271.73338 | AB42: =M42/J42 -> 0.86413331
B55: 平均 | I55: =AVERAGE(I39:I54) -> 23.75 | J55: =AVERAGE(J39:J54) -> 1950 | K55: =J55/I55 -> 82.105263 | L55: =AVERAGE(L39:L54) -> 23.75 | M55: =AVERAGE(M39:M54) -> 1676.479 | N55: =M55/L55 -> 70.588589 | O55: =L55-I55 -> 0 | P55: =N55-K55 -> -11.516674 | Q55: =N55/K55 -> 0.85973281 | S55: =S39 -> 0.25030093 | T55: =INDEX(T39:T54,COUNTA(T39:T54)) -> 0.61738426 | AA55: =M55-J55 -> -273.52101 | AB55: =M55/J55 -> 0.85973281
A56: 涼麵二線 | B56: 便當 | C56: 經典滷肉飯 | E56: 47.37 | F56: 2153 | G56: =E56*F56 -> 101987.61 | I56: 21 | J56: 2000 | K56: =J56/I56 -> 95.238095 | L56: 21 | M56: =F56/V56*60 -> 1706.8487 | N56: =M56/L56 -> 81.27851 | O56: =L56-I56 -> 0 | P56: =N56-K56 -> -13.959585 | Q56: =N56/K56 -> 0.85342436 | R56: =Q72 -> 0.86227253 | S56: 0.25023148 | T56: 0.30278935 | V56: 75.683333 | AA56: =M56-J56 -> -293.15129 | AB56: =M56/J56 -> 0.85342436 | AC56: =AB72 -> 0.86227253
B57: 便當 | C57: 健身G肉餐盒 | E57: 59.52 | F57: 7449 | G57: =E57*F57 -> 443364.48 | I57: 25 | J57: 2000 | K57: =J57/I57 -> 80 | L57: 25 | M57: =F57/V57*60 -> 1749.39 | N57: =M57/L57 -> 69.975602 | O57: =L57-I57 -> 0 | P57: =N57-K57 -> -10.024398 | Q57: =N57/K57 -> 0.87469502 | S57: 0.30625 | T57: 0.48366898 | U57: 4.9833333 | V57: 255.48333 | W57: 0.48366898 | X57: 0.52378472 | AA57: =M57-J57 -> -250.60995 | AB57: =M57/J57 -> 0.87469502
B58: 便當 | C58: 嫩烤香料雞胸排蔬滿盒 | E58: 77.34 | F58: 3628 | G58: =E58*F58 -> 280589.52 | I58: 25 | J58: 2000 | K58: =J58/I58 -> 80 | L58: 25 | M58: =F58/V58*60 -> 1717.3964 | N58: =M58/L58 -> 68.695858 | O58: =L58-I58 -> 0 | P58: =N58-K58 -> -11.304142 | Q58: =N58/K58 -> 0.85869822 | S58: 0.52378472 | T58: 0.61180556 | U58: 57.766667 | V58: 126.75 | AA58: =M58-J58 -> -282.60355 | AB58: =M58/J58 -> 0.85869822
B72: 平均 | I72: =AVERAGE(I56:I71) -> 23.666667 | J72: =AVERAGE(J56:J71) -> 2000 | K72: =J72/I72 -> 84.507042 | L72: =AVERAGE(L56:L71) -> 23.666667 | M72: =AVERAGE(M56:M71) -> 1724.5451 | N72: =M72/L72 -> 72.868101 | O72: =L72-I72 -> 0 | P72: =N72-K72 -> -11.638941 | Q72: =N72/K72 -> 0.86227253 | S72: =S56 -> 0.25023148 | T72: =INDEX(T56:T71,COUNTA(T56:T71)) -> 0.61180556 | AA72: =M72-J72 -> -275.45493 | AB72: =M72/J72 -> 0.86227253
A73: 涼麵三線 | B73: 季節調理麵 | C73: 椒麻香蔥雞涼拌麵 | E73: 37.94 | F73: 5223 | G73: =E73*F73 -> 198160.62 | I73: 21 | J73: 3600 | K73: =J73/I73 -> 171.42857 | L73: 21 | M73: =F73/V73*60 -> 3010.8567 | N73: =M73/L73 -> 143.37413 | O73: =L73-I73 -> 0 | P73: =N73-K73 -> -28.054444 | Q73: =N73/K73 -> 0.83634908 | R73: =Q89 -> 0.8561378 | S73: 0.16666667 | T73: 0.23894676 | V73: 104.08333 | AA73: =M73-J73 -> -589.14331 | AB73: =M73/J73 -> 0.83634908 | AC73: =AB89 -> 0.8561378
B74: 季節調理麵 | C74: 酸辣麻醬細冷麵 | E74: 32.06 | F74: 2820 | G74: =E74*F74 -> 90409.2 | I74: 21 | J74: 3600 | K74: =J74/I74 -> 171.42857 | L74: 21 | M74: =F74/V74*60 -> 3004.4392 | N74: =M74/L74 -> 143.06853 | O74: =L74-I74 -> 0 | P74: =N74-K74 -> -28.360039 | Q74: =N74/K74 -> 0.83456644 | S74: 0.24444444 | T74: 0.28355324 | U74: 7.9166667 | V74: 56.316667 | AA74: =M74-J74 -> -595.56082 | AB74: =M74/J74 -> 0.83456644
B75: 季節調理麵 | C75: 和風涓絲冷麵 | E75: 28.29 | F75: 4401 | G75: =E75*F75 -> 124504.29 | I75: 19 | J75: 3600 | K75: =J75/I75 -> 189.47368 | L75: 19 | M75: =F75/V75*60 -> 3009.8024 | N75: =M75/L75 -> 158.41065 | O75: =L75-I75 -> 0 | P75: =N75-K75 -> -31.06303 | Q75: =N75/K75 -> 0.83605623 | S75: 0.2883912 | T75: 0.34931713 | U75: 6.9666667 | V75: 87.733333 | AA75: =M75-J75 -> -590.19757 | AB75: =M75/J75 -> 0.83605623
B76: 季節調理麵 | C76: 芝麻鰹魚烏龍冷麵 | E76: 38.99 | F76: 2475 | G76: =E76*F76 -> 96500.25 | I76: 19 | J76: 3600 | K76: =J76/I76 -> 189.47368 | L76: 19 | M76: =F76/V76*60 -> 2994.958 | N76: =M76/L76 -> 157.62937 | O76: =L76-I76 -> 0 | P76: =N76-K76 -> -31.844317 | Q76: =N76/K76 -> 0.83193277 | S76: 0.35445602 | T76: 0.38888889 | U76: 7.4 | V76: 49.583333 | AA76: =M76-J76 -> -605.04202 | AB76: =M76/J76 -> 0.83193277
B77: 季節調理麵 | C77: 台式麻醬涼麵 | E77: 31.27 | F77: 4233 | G77: =E77*F77 -> 132365.91 | I77: 19 | J77: 3600 | K77: =J77/I77 -> 189.47368 | L77: 19 | M77: =F77/V77*60 -> 3004.4953 | N77: =M77/L77 -> 158.13133 | O77: =L77-I77 -> 0 | P77: =N77-K77 -> -31.342354 | Q77: =N77/K77 -> 0.83458202 | S77: 0.39269676 | T77: 0.45140046 | U77: 5.4833333 | V77: 84.533333 | W77: 0.45140046 | X77: 0.49166667 | AA77: =M77-J77 -> -595.50473 | AB77: =M77/J77 -> 0.83458202
B78: 季節調理麵 | C78: 日式蕎麥沾麵 | E78: 36.86 | F78: 3925 | G78: =E78*F78 -> 144675.5 | I78: 21 | J78: 3600 | K78: =J78/I78 -> 171.42857 | L78: 21 | M78: =F78/V78*60 -> 3178.8526 | N78: =M78/L78 -> 151.37394 | O78: =L78-I78 -> 0 | P78: =N78-K78 -> -20.054636 | Q78: =N78/K78 -> 0.88301462 | S78: 0.49166667 | T78: 0.54311343 | U78: 57.983333 | V78: 74.083333 | AA78: =M78-J78 -> -421.14736 | AB78: =M78/J78 -> 0.88301462
B79: 季節調理麵 | C79: 大滿足麻醬涼麵 | E79: 38 | F79: 365 | G79: =E79*F79 -> 13870 | I79: 21 | J79: 3600 | K79: =J79/I79 -> 171.42857 | L79: 21 | M79: =F79/V79*60 -> 3158.6538 | N79: =M79/L79 -> 150.41209 | O79: =L79-I79 -> 0 | P79: =N79-K79 -> -21.016484 | Q79: =N79/K79 -> 0.87740385 | S79: 0.54799769 | T79: 0.5528125 | U79: 7.0333333 | V79: 6.9333333 | AA79: =M79-J79 -> -441.34615 | AB79: =M79/J79 -> 0.87740385
B80: 季節調理麵 | C80: 大滿足香辣涼麵 | E80: 38.63 | F80: 5857 | G80: =E80*F80 -> 226255.91 | I80: 20 | J80: 3600 | K80: =J80/I80 -> 180 | L80: 20 | M80: =F80/V80*60 -> 3187.483 | N80: =M80/L80 -> 159.37415 | O80: =L80-I80 -> 0 | P80: =N80-K80 -> -20.62585 | Q80: =N80/K80 -> 0.88541194 | S80: 0.55763889 | T80: 0.63420139 | U80: 6.95 | V80: 110.25 | AA80: =M80-J80 -> -412.51701 | AB80: =M80/J80 -> 0.88541194
B81: 季節調理麵 | C81: 大滿足麻醬涼麵 | E81: 38 | F81: 7269 | G81: =E81*F81 -> 276222 | I81: 21 | J81: 3600 | K81: =J81/I81 -> 171.42857 | L81: 21 | M81: =F81/V81*60 -> 3189.3236 | N81: =M81/L81 -> 151.87255 | O81: =L81-I81 -> 0 | P81: =N81-K81 -> -19.55602 | Q81: =N81/K81 -> 0.88592322 | S81: 0.6390625 | T81: 0.73402778 | U81: 7 | V81: 136.75 | AA81: =M81-J81 -> -410.67642 | AB81: =M81/J81 -> 0.88592322
B89: 平均 | I89: =AVERAGE(I73:I88) -> 20.222222 | J89: =AVERAGE(J73:J88) -> 3600 | K89: =J89/I89 -> 178.02198 | L89: =AVERAGE(L73:L88) -> 20.222222 | M89: =AVERAGE(M73:M88) -> 3082.0961 | N89: =M89/L89 -> 152.41134 | O89: =L89-I89 -> 0 | P89: =N89-K89 -> -25.610634 | Q89: =N89/K89 -> 0.8561378 | S89: =S73 -> 0.16666667 | T89: =INDEX(T73:T88,COUNTA(T73:T88)) -> 0.73402778 | AA89: =M89-J89 -> -517.90393 | AB89: =M89/J89 -> 0.8561378
A90: 自動包裝機 | B90: 4℃-飯糰 | C90: 大口蒜味香腸燒肉雙拼飯糰 | E90: 34.23 | F90: 2141 | G90: =E90*F90 -> 73286.43 | I90: 16 | J90: 3000 | K90: =J90/I90 -> 187.5 | L90: 16 | M90: =F90/V90*60 -> 2556.4179 | N90: =M90/L90 -> 159.77612 | O90: =L90-I90 -> 0 | P90: =N90-K90 -> -27.723881 | Q90: =N90/K90 -> 0.8521393 | R90: =Q106 -> 0.8600662 | S90: 0.25 | T90: 0.28489583 | V90: 50.25 | AA90: =M90-J90 -> -443.58209 | AB90: =M90/J90 -> 0.8521393 | AC90: =AB106 -> 0.8600662
B91: 4℃-飯糰 | C91: 大口花椒香麻雞飯糰 | E91: 34.77 | F91: 1596 | G91: =E91*F91 -> 55492.92 | I91: 11 | J91: 3000 | K91: =J91/I91 -> 272.72727 | L91: 11 | M91: =F91/V91*60 -> 2550.1997 | N91: =M91/L91 -> 231.83634 | O91: =L91-I91 -> 0 | P91: =N91-K91 -> -40.890933 | Q91: =N91/K91 -> 0.85006658 | S91: 0.28920139 | T91: 0.31527778 | U91: 6.2 | V91: 37.55 | AA91: =M91-J91 -> -449.80027 | AB91: =M91/J91 -> 0.85006658
B92: 4℃-飯糰 | C92: 大口法式蕈菇起司雞排飯糰 | E92: 35.83 | F92: 5526 | G92: =E92*F92 -> 197996.58 | I92: 12 | J92: 3273 | K92: =J92/I92 -> 272.75 | L92: 12 | M92: =F92/V92*60 -> 2846.8231 | N92: =M92/L92 -> 237.23526 | O92: =L92-I92 -> 0 | P92: =N92-K92 -> -35.51474 | Q92: =N92/K92 -> 0.86979014 | S92: 0.40763889 | T92: 0.48851852 | U92: 5 | V92: 116.46667 | W92: 0.48851852 | X92: 0.52986111 | AA92: =M92-J92 -> -426.17687 | AB92: =M92/J92 -> 0.86979014
B93: 4℃-飯糰 | C93: 大口義式香草雞腿排飯糰 | E93: 36.41 | F93: 4547 | G93: =E93*F93 -> 165556.27 | I93: 11 | J93: 3273 | K93: =J93/I93 -> 297.54545 | L93: 11 | M93: =F93/V93*60 -> 2836.9497 | N93: =M93/L93 -> 257.90452 | O93: =L93-I93 -> 0 | P93: =N93-K93 -> -39.640933 | Q93: =N93/K93 -> 0.86677352 | S93: 0.52986111 | T93: 0.59664352 | U93: 59.533333 | V93: 96.166667 | AA93: =M93-J93 -> -436.05026 | AB93: =M93/J93 -> 0.86677352
B106: 平均 | I106: =AVERAGE(I90:I105) -> 12.5 | J106: =AVERAGE(J90:J105) -> 3136.5 | K106: =J106/I106 -> 250.92 | L106: =AVERAGE(L90:L105) -> 12.5 | M106: =AVERAGE(M90:M105) -> 2697.5976 | N106: =M106/L106 -> 215.80781 | O106: =L106-I106 -> 0 | P106: =N106-K106 -> -35.11219 | Q106: =N106/K106 -> 0.8600662 | S106: =S90 -> 0.25 | T106: =INDEX(T90:T105,COUNTA(T90:T105)) -> 0.59664352 | AA106: =M106-J106 -> -438.90237 | AB106: =M106/J106 -> 0.8600662
...

Sheet 0830
B1: 屏榮 大溪廠組合室生產人時性分析
B3: 日期 | C3: 114.08.30星期六 | E3: 訂單量 | F3: ='0830(18度C)'!D1+'0830(4度C)'!D1 -> 202704 | H3: 營業額 | I3: ='0830(18度C)'!F1+'0830(4度C)'!F1 -> 6161593.8
B4: 人時性 | C4: 項目 | E4: ➀ | G4: ➁ | I4: ➂ | K4: ④ | M4: ⑤
C5: 組合室 | E5: 全溫層 | G5: 4度C-各編組展開(一配) | I5: 4度C-各編組展開(二配) | K5: 18度C-各編組展開(一配) | M5: 18度C-各編組展開(二配)
C6: 排關平均 | E6: =AVERAGE(D13:O13,D27:X27) -> 475.60069 | F6: =AVERAGE(#REF!,D13:K13) -> #REF! | G6: =AVERAGE(D13:K13) -> 175.56964 | I6: =AVERAGE(L13:O13) -> 91.865358 | K6: =AVERAGE(D27:O27) -> 643.39628 | M6: =AVERAGE(P27:X27) -> 757.78717
C7: 實績平均 | E7: =AVERAGE(D14:O14,D28:X28) -> 406.13914 | F7: =AVERAGE(#REF!,D14:K14) -> #REF! | G7: =AVERAGE(D14:K14) -> 150.36454 | I7: =AVERAGE(L14:O14) -> 78.680783 | K7: =AVERAGE(D28:O28) -> 548.27943 | M7: =AVERAGE(P28:X28) -> 647.86528
C8: 達成率平均 | E8: =AVERAGE(D15:O15,D29:X29) -> 0.85627247 | F8: =AVERAGE(D15:K15,#REF!) -> #REF! | G8: =AVERAGE(D15:K15) -> 0.85896549 | I8: =AVERAGE(L15:O15) -> 0.85654868 | K8: =AVERAGE(D29:O29) -> 0.85290977 | M8: =AVERAGE(P29:X29) -> 0.85696169 | O8: ※現行日本鮮食廠以達成率80%為基本(即為現行KPI)
B10: 溫層 | D10: ➁4度C-各編組展開 | L10: ➂4度C-各編組展開
B11: 編組 | D11: 1 | E11: 2 | F11: 3 | G11: 4 | H11: 5 | I11: 6 | J11: 7 | K11: 8 | L11: 1 | M11: 2 | N11: 3 | O11: 4
D12: 便當一線 | E12: 便當二線 | F12: 涼麵一線 | G12: 涼麵二線 | H12: 涼麵三線 | I12: 自動包裝機 | J12: 自動包裝機2 | K12: 自動包裝機3 | L12: 便當一線 | M12: 便當二線 | N12: 涼麵一線 | O12: 涼麵二線
B13: 人時性 | C13: 排關 | D13: 115.15152 | E13: 79.470199 | F13: 82.105263 | G13: 83.333333 | H13: 178.88199 | I13: 256.71186 | J13: - | K13: 433.33333 | L13: - | M13: - | N13: 86.956522 | O13: 96.774194
C14: 實績 | D14: 100.79054 | E14: 68.050855 | F14: 70.583545 | G14: 71.57614 | H14: 152.65219 | I14: 220.577 | J14: - | K14: 368.32151 | L14: - | M14: - | N14: 74.595294 | O14: 82.766272
C15: 達成率 | D15: =D14/D13 -> 0.87528627 | E15: =E14/E13 -> 0.8563066 | F15: =F14/F13 -> 0.85967138 | G15: =G14/G13 -> 0.85891368 | H15: =H14/H13 -> 0.85336816 | I15: =I14/I13 -> 0.85923961 | J15: - | K15: =K14/K13 -> 0.84997272 | L15: - | M15: - | N15: =N14/N13 -> 0.85784588 | O15: =O14/O13 -> 0.85525148
B16: 作業 時間 | C16: 開始 | D16: 0.29166667 | E16: 0.25033565 | F16: 0.33333333 | G16: 0.33333333 | H16: 0.16689815 | I16: 0.25 | J16: - | K16: 0.30017361 | L16: - | M16: - | N16: 0.70853009 | O16: 0.70847222
C17: 結束 | D17: 0.57594907 | E17: 0.5875 | F17: 0.59953704 | G17: 0.59546296 | H17: 0.65902778 | I17: 0.54814815 | J17: - | K17: 0.44305556 | L17: - | M17: - | N17: 0.82847222 | O17: 0.86541667
B18: 配置人數 | D18: 16.5 | E18: 25.166667 | F18: 23.75 | G18: 24 | H18: 20.125 | I18: 11.8 | J18: - | K18: 6 | L18: - | M18: - | N18: 23 | O18: 20.666667
B19: 主要應用設備 | D19: L型封口機 | E19: ET-55 | F19: ET-55 | G19: ET-55 | H19: ET-600 | I19: 伺服包裝機 | J19: 伺服包裝機 | K19: 伺服包裝機 | L19: L型封口機 | M19: ET-55 | N19: ET-55 | O19: ET-55
B20: 次要應用設備 | D20: 伺服包裝機 | H20: 伺服包裝機
B21: 備註 | H21: 涼麵+烤飯糰 | I21: 大口飯糰線 | K21: 烤飯糰+手卷
B24: 溫層 | D24: ➃18度C-各編組展開 (一配) | P24: ⑤18度C-各編組展開 (二配)
B25: 編組 | D25: 1 | E25: 2 | F25: 3 | G25: 4 | H25: 5 | I25: 6 | J25: 7 | K25: 8 | L25: 9 | M25: 10 | N25: 11 | O25: 12 | P25: 1 | Q25: 2 | R25: 3 | S25: 4 | T25: 5 | U25: 6 | V25: 7 | W25: 8 | X25: 9
D26: 便當一線 | E26: 涼麵一線 | F26: 涼麵三線 | G26: 自動包裝機 | H26: 自動包裝機2 | I26: 自動包裝機3 | J26: 味付飯糰線B | K26: (舊) 3300型飯糰線 | L26: 3000型飯糰線 | M26: (新) 3300型飯糰機 | N26: GKK3600型 飯糰機 | O26: GKK3600型 飯糰機2 | P26: 自動包裝機 | Q26: 自動包裝機2 | R26: 自動包裝機3 | S26: 味付飯糰線B | T26: (舊) 3300型飯糰線 | U26: 3000型飯糰線 | V26: (新) 3300型飯糰機 | W26: GKK3600型 飯糰機 | X26: GKK3600型 飯糰機2
B27: 人時性 | C27: 排關 | D27: 226.15 | E27: - | F27: - | G27: 260.86957 | H27: 433.33333 | I27: - | J27: 675 | K27: - | L27: - | M27: 868.42105 | N27: 1200 | O27: 840 | P27: 226.65517 | Q27: - | R27: - | S27: 675 | T27: 840 | U27: - | V27: 761.53846 | W27: 1020 | X27: 1023.5294
C28: 實績 | D28: 193.09081 | E28: - | F28: - | G28: 223.40936 | H28: 359.31846 | I28: - | J28: 594.39394 | K28: - | L28: - | M28: 745.19014 | N28: 1003.4867 | O28: 719.06666 | P28: 193.55072 | Q28: - | R28: - | S28: 600.81259 | T28: 715.75966 | U28: - | V28: 655.42852 | W28: 861.70017 | X28: 859.94
C29: 達成率 | D29: =D28/D27 -> 0.85381742 | E29: - | F29: - | G29: =G28/G27 -> 0.85640255 | H29: =H28/H27 -> 0.82919644 | I29: - | J29: =J28/J27 -> 0.88058361 | K29: - | L29: - | M29: =M28/M27 -> 0.85809773 | N29: =N28/N27 -> 0.83623888 | O29: =O28/O27 -> 0.85603173 | P29: =P28/P27 -> 0.85394352 | Q29: - | R29: - | S29: =S28/S27 -> 0.89009273 | T29: =T28/T27 -> 0.85209483 | U29: - | V29: =V28/V27 -> 0.86066371 | W29: =W28/W27 -> 0.84480409 | X29: =X28/X27 -> 0.84017126
B30: 作業 時間 | C30: 開始 | D30: 0.43263889 | E30: - | F30: - | G30: 0.30356481 | H30: 0.25 | I30: - | J30: 0.25 | K30: - | L30: - | M30: 0.25 | N30: 0.25002315 | O30: 0.25013889 | P30: 0.70833333 | Q30: - | R30: - | S30: 0.70856481 | T30: 0.7083912 | U30: - | V30: 0.70835648 | W30: 0.70862269 | X30: 0.70833333
C31: 結束 | D31: 0.5034838 | E31: - | F31: - | G31: 0.36265046 | H31: 0.29755787 | I31: - | J31: 0.31875 | K31: - | L31: - | M31: 0.44236111 | N31: 0.39722222 | O31: 0.39446759 | P31: 0.83819444 | Q31: - | R31: - | S31: 0.86666667 | T31: 0.89652778 | U31: - | V31: 0.89861111 | W31: 0.96059028 | X31: 0.9746412
B32: 配置人數 | D32: 13.333333 | E32: - | F32: - | G32: 11.5 | H32: 6 | I32: - | J32: 4 | K32: - | L32: - | M32: 3.8 | N32: 3 | O32: 3.75 | P32: 14.5 | Q32: - | R32: - | S32: 4 | T32: 3.75 | U32: - | V32: 4.3333333 | W32: 3.3333333 | X32: 3.4
B33: 主要應用設備 | D33: 伺服包裝機 | E33: ET-55 | F33: ET-600 | G33: 夾心型 | H33: 伺服包裝機 | I33: 伺服包裝機 | J33: 夾心型 | K33: 3300型 | L33: 3300型 | M33: 3300型 | N33: GKK | O33: GKK | P33: 夾心型 | Q33: 伺服包裝機 | R33: 伺服包裝機 | S33: 夾心型 | T33: 3300型 | U33: 3300型 | V33: 3300型 | W33: GKK | X33: GKK
B34: 次要應用設備
B35: 備註

Sheet 0830(18度C)
A1: 大溪廠日報分析 | C1: 總生產量 | D1: =SUM(F5:F225) -> 107641 | E1: 營業額 | F1: =SUM(G5:G225) -> 2085917.9 | G1: 出勤人數 | H1: =L21+L38+L55+L72+L89+L106+L123+L140+L157+L174+L191+L208+L225 -> 78.7 | I1: 產線配置圖 | L1: 生產實績 | O1: 人時性差異分析 | S1: 日報登錄 | Y1: 分析說明 | AA1: 產能差異分析
A2: 45899 | C2: 人時性 | D2: =AVERAGE(N21,N38,N55,N72,N89,N106,N123,N140,N157,N174,N191,N208,N225) -> 594.24213 | E2: 平均廠價 | F2: =F1/D1 -> 19.37847 | G2: 多次生產數 | H2: =COUNT(H5:H225) -> 2
A3: 線別 | B3: 品類 | C3: 品名 | E3: 廠價 | F3: 生產量 | G3: 營收 | H3: 多次 生產 | I3: 人數 | J3: 產能/時 | K3: 人時性 | L3: 人數 | M3: 產能/時 | N3: 人時性 | O3: 人數 | P3: 人時性 | Q3: 達成率 | R3: 達成率 平均 | S3: 生產時間 | U3: 換線、休息/分 | V3: 稼動時間/分 | W3: 休息時間 | Y3: (屏榮回填) | AA3: 產能/時 | AB3: 達成率 | AC3: 達成率平均
S4: 開始 | T4: 結束 | W4: 開始 | X4: 結束
A5: 便當一線 | B5: 18℃-壽司手卷 | C5: 一配海饌雙手卷 | E5: 29.85 | F5: 1741 | G5: =E5*F5 -> 51968.85 | I5: 17 | J5: 3273 | K5: =J5/I5 -> 192.52941 | L5: 17 | M5: =F5/V5*60 -> 2803.0411 | N5: =M5/L5 -> 164.88477 | O5: =L5-I5 -> 0 | P5: =N5-K5 -> -27.644639 | Q5: =N5/K5 -> 0.85641343 | R5: =Q21 -> 0.85381742 | S5: 0.43263889 | T5: 0.45851852 | U5: 6.5166667 | V5: 37.266667 | AA5: =M5-J5 -> -469.95886 | AB5: =M5/J5 -> 0.85641343 | AC5: =AB21 -> 0.85381742
B6: 18℃-壽司手卷 | C6: 一配雙饗雙手卷 | E6: 29.52 | F6: 1708 | G6: =E6*F6 -> 50420.16 | I6: 17 | J6: 3273 | K6: =J6/I6 -> 192.52941 | L6: 17 | M6: =F6/V6*60 -> 2802.5524 | N6: =M6/L6 -> 164.85602 | O6: =L6-I6 -> 0 | P6: =N6-K6 -> -27.673387 | Q6: =N6/K6 -> 0.85626411 | S6: 0.46210648 | T6: 0.4875 | U6: 5.1666667 | V6: 36.566667 | AA6: =M6-J6 -> -470.44758 | AB6: =M6/J6 -> 0.85626411
B7: 18℃-壽司手卷 | C7: 一配日式厚蛋脆卷 | E7: 21.61 | F7: 636 | G7: =E7*F7 -> 13743.96 | I7: 6 | J7: 2500 | K7: =J7/I7 -> 416.66667 | L7: 6 | M7: =F7/V7*60 -> 2118.0389 | N7: =M7/L7 -> 353.00648 | O7: =L7-I7 -> 0 | P7: =N7-K7 -> -63.660191 | Q7: =N7/K7 -> 0.84721554 | S7: 0.49097222 | T7: 0.5034838 | U7: 5 | V7: 18.016667 | W7: 0.5034838 | X7: 0.54305556 | AA7: =M7-J7 -> -381.96115 | AB7: =M7/J7 -> 0.84721554
B21: 平均 | I21: =AVERAGE(I5:I20) -> 13.333333 | J21: =AVERAGE(J5:J20) -> 3015.3333 | K21: =J21/I21 -> 226.15 | L21: =AVERAGE(L5:L20) -> 13.333333 | M21: =AVERAGE(M5:M20) -> 2574.5441 | N21: =M21/L21 -> 193.09081 | O21: =L21-I21 -> 0 | P21: =N21-K21 -> -33.05919 | Q21: =N21/K21 -> 0.85381742 | S21: =S5 -> 0.43263889 | T21: =INDEX(T5:T20,COUNTA(T5:T20)) -> 0.5034838 | AA21: =M21-J21 -> -440.7892 | AB21: =M21/J21 -> 0.85381742
A22: 自動包裝機 | B22: 18℃-壽司手卷 | C22: 一配新之助的豆皮壽司喔 | E22: 25.52 | F22: 1750 | G22: =E22*F22 -> 44660 | I22: 12 | J22: 3000 | K22: =J22/I22 -> 250 | L22: 12 | M22: =F22/V22*60 -> 2569.3312 | N22: =M22/L22 -> 214.11093 | O22: =L22-I22 -> 0 | P22: =N22-K22 -> -35.88907 | Q22: =N22/K22 -> 0.85644372 | R22: =Q38 -> 0.85640255 | S22: 0.30356481 | T22: 0.33194444 | U22: 5.9 | V22: 40.866667 | AA22: =M22-J22 -> -430.66884 | AB22: =M22/J22 -> 0.85644372 | AC22: =AB38 -> 0.85640255
B23: 18℃-壽司手卷 | C23: 一配長野稻荷壽司 | E23: 25.64 | F23: 1722 | G23: =E23*F23 -> 44152.08 | I23: 11 | J23: 3000 | K23: =J23/I23 -> 272.72727 | L23: 11 | M23: =F23/V23*60 -> 2569.0841 | N23: =M23/L23 -> 233.5531 | O23: =L23-I23 -> 0 | P23: =N23-K23 -> -39.17417 | Q23: =N23/K23 -> 0.85636138 | S23: 0.33472222 | T23: 0.36265046 | U23: 4 | V23: 40.216667 | AA23: =M23-J23 -> -430.91587 | AB23: =M23/J23 -> 0.85636138
B38: 平均 | I38: =AVERAGE(I22:I37) -> 11.5 | J38: =AVERAGE(J22:J37) -> 3000 | K38: =J38/I38 -> 260.86957 | L38: =AVERAGE(L22:L37) -> 11.5 | M38: =AVERAGE(M22:M37) -> 2569.2076 | N38: =M38/L38 -> 223.40936 | O38: =L38-I38 -> 0 | P38: =N38-K38 -> -37.460205 | Q38: =N38/K38 -> 0.85640255 | S38: =S22 -> 0.30356481 | T38: =INDEX(T22:T37,COUNTA(T22:T37)) -> 0.36265046 | AA38: =M38-J38 -> -430.79236 | AB38: =M38/J38 -> 0.85640255
A39: 自動包裝機2 | B39: 18℃-壽司手卷 | C39: 一配芝麻海苔香鬆細卷 | E39: 14.06 | F39: 722 | G39: =E39*F39 -> 10151.32 | I39: 6 | J39: 2600 | K39: =J39/I39 -> 433.33333 | L39: 6 | M39: =F39/V39*60 -> 2166 | N39: =M39/L39 -> 361 | O39: =L39-I39 -> 0 | P39: =N39-K39 -> -72.333333 | Q39: =N39/K39 -> 0.83307692 | R39: =Q55 -> 0.82919644 | S39: 0.25 | T39: 0.26388889 | V39: 20 | AA39: =M39-J39 -> -434 | AB39: =M39/J39 -> 0.83307692 | AC39: =AB55 -> 0.82919644
B40: 18℃-壽司手卷 | C40: 一配鮪魚沙拉細卷 | E40: 14.81 | F40: 846 | G40: =E40*F40 -> 12529.26 | I40: 6 | J40: 2600 | K40: =J40/I40 -> 433.33333 | L40: 6 | M40: =F40/V40*60 -> 2167.6868 | N40: =M40/L40 -> 361.28114 | O40: =L40-I40 -> 0 | P40: =N40-K40 -> -72.052195 | Q40: =N40/K40 -> 0.8337257 | S40: 0.26805556 | T40: 0.28431713 | U40: 6 | V40: 23.416667 | AA40: =M40-J40 -> -432.31317 | AB40: =M40/J40 -> 0.8337257
B41: 18℃-壽司手卷 | C41: 一配炙烤焦糖鮭魚細卷 | E41: 17.87 | F41: 444 | G41: =E41*F41 -> 7934.28 | I41: 6 | J41: 2600 | K41: =J41/I41 -> 433.33333 | L41: 6 | M41: =F41/V41*60 -> 2134.0454 | N41: =M41/L41 -> 355.67423 | O41: =L41-I41 -> 0 | P41: =N41-K41 -> -77.659101 | Q41: =N41/K41 -> 0.82078669 | S41: 0.28888889 | T41: 0.29755787 | U41: 6.5833333 | V41: 12.483333 | AA41: =M41-J41 -> -465.95461 | AB41: =M41/J41 -> 0.82078669
B55: 平均 | I55: =AVERAGE(I39:I54) -> 6 | J55: =AVERAGE(J39:J54) -> 2600 | K55: =J55/I55 -> 433.33333 | L55: =AVERAGE(L39:L54) -> 6 | M55: =AVERAGE(M39:M54) -> 2155.9107 | N55: =M55/L55 -> 359.31846 | O55: =L55-I55 -> 0 | P55: =N55-K55 -> -74.014876 | Q55: =N55/K55 -> 0.82919644 | S55: =S39 -> 0.25 | T55: =INDEX(T39:T54,COUNTA(T39:T54)) -> 0.29755787 | AA55: =M55-J55 -> -444.08926 | AB55: =M55/J55 -> 0.82919644
A56: 味付飯糰線B | B56: 18℃-飯糰 | C56: 一配經典肉鬆飯糰 | E56: 14.03 | F56: 3923 | G56: =E56*F56 -> 55039.69 | I56: 4 | J56: 2700 | K56: =J56/I56 -> 675 | L56: 4 | M56: =F56/V56*60 -> 2377.5758 | N56: =M56/L56 -> 594.39394 | O56: =L56-I56 -> 0 | P56: =N56-K56 -> -80.606061 | Q56: =N56/K56 -> 0.88058361 | R56: =Q72 -> 0.88058361 | S56: 0.25 | T56: 0.31875 | V56: 99 | AA56: =M56-J56 -> -322.42424 | AB56: =M56/J56 -> 0.88058361 | AC56: =AB72 -> 0.88058361
B72: 平均 | I72: =AVERAGE(I56:I71) -> 4 | J72: =AVERAGE(J56:J71) -> 2700 | K72: =J72/I72 -> 675 | L72: =AVERAGE(L56:L71) -> 4 | M72: =AVERAGE(M56:M71) -> 2377.5758 | N72: =M72/L72 -> 594.39394 | O72: =L72-I72 -> 0 | P72: =N72-K72 -> -80.606061 | Q72: =N72/K72 -> 0.88058361 | S72: =S56 -> 0.25 | T72: =INDEX(T56:T71,COUNTA(T56:T71)) -> 0.31875 | AA72: =M72-J72 -> -322.42424 | AB72: =M72/J72 -> 0.88058361
A73: (新) 3300型飯糰機 | B73: 18℃-飯糰 | C73: 一配三杯辣海瓜子飯糰 | E73: 21.45 | F73: 1186 | G73: =E73*F73 -> 25439.7 | I73: 3 | J73: 3300 | K73: =J73/I73 -> 1100 | L73: 3 | M73: =F73/V73*60 -> 2821.9432 | N73: =M73/L73 -> 940.64772 | O73: =L73-I73 -> 0 | P73: =N73-K73 -> -159.35228 | Q73: =N73/K73 -> 0.85513429 | R73: =Q89 -> 0.85809773 | S73: 0.25 | T73: 0.26751157 | V73: 25.216667 | AA73: =M73-J73 -> -478.05684 | AB73: =M73/J73 -> 0.85513429 | AC73: =AB89 -> 0.85809773
B74: 18℃-飯糰 | C74: 一配哇沙米魚卵沙拉飯糰 | E74: 15.71 | F74: 3487 | G74: =E74*F74 -> 54780.77 | I74: 3 | J74: 3300 | K74: =J74/I74 -> 1100 | L74: 3 | M74: =F74/V74*60 -> 2838.1641 | N74: =M74/L74 -> 946.05471 | O74: =L74-I74 -> 0 | P74: =N74-K74 -> -153.94529 | Q74: =N74/K74 -> 0.86004974 | S74: 0.27172454 | T74: 0.32291667 | U74: 6.0666667 | V74: 73.716667 | AA74: =M74-J74 -> -461.83586 | AB74: =M74/J74 -> 0.86004974
B75: 18℃-飯糰 | C75: 一配鹽蔥燒肉飯糰 | E75: 17.89 | F75: 2464 | G75: =E75*F75 -> 44080.96 | I75: 4 | J75: 3300 | K75: =J75/I75 -> 825 | L75: 4 | M75: =F75/V75*60 -> 2833.0885 | N75: =M75/L75 -> 708.27212 | O75: =L75-I75 -> 0 | P75: =N75-K75 -> -116.72788 | Q75: =N75/K75 -> 0.85851166 | S75: 0.32569444 | T75: 0.36193287 | U75: 4 | V75: 52.183333 | AA75: =M75-J75 -> -466.91153 | AB75: =M75/J75 -> 0.85851166
B76: 18℃-飯糰 | C76: 一配雞肉飯飯糰 | E76: 16.66 | F76: 3817 | G76: =E76*F76 -> 63591.22 | I76: 4 | J76: 3300 | K76: =J76/I76 -> 825 | L76: 4 | M76: =F76/V76*60 -> 2850.8714 | N76: =M76/L76 -> 712.71784 | O76: =L76-I76 -> 0 | P76: =N76-K76 -> -112.28216 | Q76: =N76/K76 -> 0.86390041 | S76: 0.36666667 | T76: 0.4224537 | U76: 6.8166667 | V76: 80.333333 | AA76: =M76-J76 -> -449.12863 | AB76: =M76/J76 -> 0.86390041
B77: 18℃-飯糰 | C77: 一配壹號醬炙烤牛飯糰 | E77: 22.28 | F77: 1118 | G77: =E77*F77 -> 24909.04 | I77: 5 | J77: 3300 | K77: =J77/I77 -> 660 | L77: 5 | M77: =F77/V77*60 -> 2814.5455 | N77: =M77/L77 -> 562.90909 | O77: =L77-I77 -> 0 | P77: =N77-K77 -> -97.090909 | Q77: =N77/K77 -> 0.85289256 | S77: 0.42581019 | T77: 0.44236111 | U77: 4.8333333 | V77: 23.833333 | AA77: =M77-J77 -> -485.45455 | AB77: =M77/J77 -> 0.85289256
B89: 平均 | I89: =AVERAGE(I73:I88) -> 3.8 | J89: =AVERAGE(J73:J88) -> 3300 | K89: =J89/I89 -> 868.42105 | L89: =AVERAGE(L73:L88) -> 3.8 | M89: =AVERAGE(M73:M88) -> 2831.7225 | N89: =M89/L89 -> 745.19014 | O89: =L89-I89 -> 0 | P89: =N89-K89 -> -123.23092 | Q89: =N89/K89 -> 0.85809773 | S89: =S73 -> 0.25 | T89: =INDEX(T73:T88,COUNTA(T73:T88)) -> 0.44236111 | AA89: =M89-J89 -> -468.27748 | AB89: =M89/J89 -> 0.85809773
A90: GKK3600型 飯糰機 | B90: 18℃-飯糰 | C90: 一配明太子龍蝦風味沙拉飯糰 | E90: 18.18 | F90: 2203 | G90: =E90*F90 -> 40050.54 | I90: 3 | J90: 3600 | K90: =J90/I90 -> 1200 | L90: 3 | M90: =F90/V90*60 -> 3006.3685 | N90: =M90/L90 -> 1002.1228 | O90: =L90-I90 -> 0 | P90: =N90-K90 -> -197.87718 | Q90: =N90/K90 -> 0.83510235 | R90: =Q106 -> 0.83623888 | S90: 0.25002315 | T90: 0.28055556 | V90: 43.966667 | AA90: =M90-J90 -> -593.63154 | AB90: =M90/J90 -> 0.83510235 | AC90: =AB106 -> 0.83623888
B91: 18℃-飯糰 | C91: 一配蔬食鮪魚飯糰 | E91: 18.18 | F91: 2061 | G91: =E91*F91 -> 37468.98 | I91: 3 | J91: 3600 | K91: =J91/I91 -> 1200 | L91: 3 | M91: =F91/V91*60 -> 3002.671 | N91: =M91/L91 -> 1000.8903 | O91: =L91-I91 -> 0 | P91: =N91-K91 -> -199.10967 | Q91: =N91/K91 -> 0.83407527 | S91: 0.29236111 | T91: 0.32096065 | U91: 17 | V91: 41.183333 | AA91: =M91-J91 -> -597.32902 | AB91: =M91/J91 -> 0.83407527
B92: 18℃-飯糰 | C92: 一配鮪魚飯糰 | E92: 14.28 | F92: 4735 | G92: =E92*F92 -> 67615.8 | I92: 3 | J92: 3600 | K92: =J92/I92 -> 1200 | L92: 3 | M92: =F92/V92*60 -> 3022.3404 | N92: =M92/L92 -> 1007.4468 | O92: =L92-I92 -> 0 | P92: =N92-K92 -> -192.55319 | Q92: =N92/K92 -> 0.83953901 | S92: 0.33194444 | T92: 0.39722222 | U92: 15.816667 | V92: 94 | AA92: =M92-J92 -> -577.65957 | AB92: =M92/J92 -> 0.83953901
B106: 平均 | I106: =AVERAGE(I90:I105) -> 3 | J106: =AVERAGE(J90:J105) -> 3600 | K106: =J106/I106 -> 1200 | L106: =AVERAGE(L90:L105) -> 3 | M106: =AVERAGE(M90:M105) -> 3010.46 | N106: =M106/L106 -> 1003.4867 | O106: =L106-I106 -> 0 | P106: =N106-K106 -> -196.51335 | Q106: =N106/K106 -> 0.83623888 | S106: =S90 -> 0.25002315 | T106: =INDEX(T90:T105,COUNTA(T90:T105)) -> 0.39722222 | AA106: =M106-J106 -> -589.54004 | AB106: =M106/J106 -> 0.83623888
A107: GKK3600型 飯糰機2 | B107: 18℃-飯糰 | C107: 一配熟成紅鮭飯糰 | E107: 25.03 | F107: 1541 | G107: =E107*F107 -> 38571.23 | I107: 4 | J107: 3300 | K107: =J107/I107 -> 825 | L107: 4 | M107: =F107/V107*60 -> 2818.9024 | N107: =M107/L107 -> 704.72561 | O107: =L107-I107 -> 0 | P107: =N107-K107 -> -120.27439 | Q107: =N107/K107 -> 0.85421286 | R107: =Q123 -> 0.85603173 | S107: 0.25013889 | T107: 0.27291667 | V107: 32.8 | AA107: =M107-J107 -> -481.09756 | AB107: =M107/J107 -> 0.85421286 | AC107: =AB123 -> 0.85603173
B108: 18℃-飯糰 | C108: 一配北海道秋鮭親子飯糰 | E108: 24.83 | F108: 1860 | G108: =E108*F108 -> 46183.8 | I108: 4 | J108: 3300 | K108: =J108/I108 -> 825 | L108: 4 | M108: =F108/V108*60 -> 2824.1248 | N108: =M108/L108 -> 706.03121 | O108: =L108-I108 -> 0 | P108: =N108-K108 -> -118.96879 | Q108: =N108/K108 -> 0.85579541 | S108: 0.28505787 | T108: 0.3125 | U108: 17.483333 | V108: 39.516667 | AA108: =M108-J108 -> -475.87516 | AB108: =M108/J108 -> 0.85579541
B109: 18℃-飯糰 | C109: 一配海老天婦羅飯糰 | E109: 27.91 | F109: 707 | G109: =E109*F109 -> 19732.37 | I109: 4 | J109: 3000 | K109: =J109/I109 -> 750 | L109: 4 | M109: =F109/V109*60 -> 2557.9899 | N109: =M109/L109 -> 639.49749 | O109: =L109-I109 -> 0 | P109: =N109-K109 -> -110.50251 | Q109: =N109/K109 -> 0.85266332 | S109: 0.32321759 | T109: 0.3347338 | U109: 15.433333 | V109: 16.583333 | AA109: =M109-J109 -> -442.01005 | AB109: =M109/J109 -> 0.85266332
B110: 18℃-飯糰 | C110: 一配贅沢鮭魚肚飯糰 | E110: 30 | F110: 2888 | G110: =E110*F110 -> 86640 | I110: 3 | J110: 3000 | K110: =J110/I110 -> 1000 | L110: 3 | M110: =F110/V110*60 -> 2584.9826 | N110: =M110/L110 -> 861.66087 | O110: =L110-I110 -> 0 | P110: =N110-K110 -> -138.33913 | Q110: =N110/K110 -> 0.86166087 | S110: 0.34791667 | T110: 0.39446759 | U110: 18.983333 | V110: 67.033333 | AA110: =M110-J110 -> -415.0174 | AB110: =M110/J110 -> 0.86166087
B123: 平均 | I123: =AVERAGE(I107:I122) -> 3.75 | J123: =AVERAGE(J107:J122) -> 3150 | K123: =J123/I123 -> 840 | L123: =AVERAGE(L107:L122) -> 3.75 | M123: =AVERAGE(M107:M122) -> 2696.5 | N123: =M123/L123 -> 719.06666 | O123: =L123-I123 -> 0 | P123: =N123-K123 -> -120.93334 | Q123: =N123/K123 -> 0.85603173 | S123: =S107 -> 0.25013889 | T123: =INDEX(T107:T122,COUNTA(T107:T122)) -> 0.39446759 | AA123: =M123-J123 -> -453.50004 | AB123: =M123/J123 -> 0.85603173
A124: 自動包裝機 (二配) | B124: 18℃-壽司手卷 | C124: 二配雙饗雙手卷 | E124: 29.52 | F124: 2023 | G124: =E124*F124 -> 59718.96 | I124: 17 | J124: 3273 | K124: =J124/I124 -> 192.52941 | L124: 17 | M124: =F124/V124*60 -> 2802.1547 | N124: =M124/L124 -> 164.83263 | O124: =L124-I124 -> 0 | P124: =N124-K124 -> -27.696784 | Q124: =N124/K124 -> 0.85614258 | R124: =Q140 -> 0.85394352 | S124: 0.70833333 | T124: 0.73841435 | V124: 43.316667 | AA124: =M124-J124 -> -470.84533 | AB124: =M124/J124 -> 0.85614258 | AC124: =AB140 -> 0.85394352
B125: 18℃-壽司手卷 | C125: 二配海饌雙手卷 | E125: 29.85 | F125: 2031 | G125: =E125*F125 -> 60625.35 | I125: 17 | J125: 3273 | K125: =J125/I125 -> 192.52941 | L125: 17 | M125: =F125/V125*60 -> 2802.453 | N125: =M125/L125 -> 164.85018 | O125: =L125-I125 -> 0 | P125: =N125-K125 -> -27.679233 | Q125: =N125/K125 -> 0.85623374 | S125: 0.74236111 | T125: 0.77255787 | U125: 5.6833333 | V125: 43.483333 | AA125: =M125-J125 -> -470.54695 | AB125: =M125/J125 -> 0.85623374
B126: 18℃-飯糰 | C126: 二配兩粒飯糰(鮪魚&培根蛋沙拉) | E126: 28.57 | F126: 1738 | G126: =E126*F126 -> 49654.66 | I126: 13 | J126: 3600 | K126: =J126/I126 -> 276.92308 | L126: 13 | M126: =F126/V126*60 -> 3052.0976 | N126: =M126/L126 -> 234.77674 | O126: =L126-I126 -> 0 | P126: =N126-K126 -> -42.146341 | Q126: =N126/K126 -> 0.84780488 | S126: 0.77777778 | T126: 0.80150463 | U126: 7.5166667 | V126: 34.166667 | AA126: =M126-J126 -> -547.90244 | AB126: =M126/J126 -> 0.84780488
B127: 18℃-壽司手卷 | C127: 二配長野稻荷壽司 | E127: 25.64 | F127: 2009 | G127: =E127*F127 -> 51510.76 | I127: 11 | J127: 3000 | K127: =J127/I127 -> 272.72727 | L127: 11 | M127: =F127/V127*60 -> 2569.2362 | N127: =M127/L127 -> 233.56693 | O127: =L127-I127 -> 0 | P127: =N127-K127 -> -39.160342 | Q127: =N127/K127 -> 0.85641208 | S127: 0.80561343 | T127: 0.83819444 | U127: 5.9166667 | V127: 46.916667 | AA127: =M127-J127 -> -430.76377 | AB127: =M127/J127 -> 0.85641208
B140: 平均 | I140: =AVERAGE(I124:I139) -> 14.5 | J140: =AVERAGE(J124:J139) -> 3286.5 | K140: =J140/I140 -> 226.65517 | L140: =AVERAGE(L124:L139) -> 14.5 | M140: =AVERAGE(M124:M139) -> 2806.4854 | N140: =M140/L140 -> 193.55072 | O140: =L140-I140 -> 0 | P140: =N140-K140 -> -33.104457 | Q140: =N140/K140 -> 0.85394352 | S140: =S124 -> 0.70833333 | T140: =INDEX(T124:T139,COUNTA(T124:T139)) -> 0.83819444 | AA140: =M140-J140 -> -480.01462 | AB140: =M140/J140 -> 0.85394352
A141: 味付飯糰線B (二配) | B141: 18℃-飯糰 | C141: 二配經典肉鬆飯糰 | E141: 14.03 | F141: 9119 | G141: =E141*F141 -> 127939.57 | I141: 4 | J141: 2700 | K141: =J141/I141 -> 675 | L141: 4 | M141: =F141/V141*60 -> 2403.2504 | N141: =M141/L141 -> 600.81259 | O141: =L141-I141 -> 0 | P141: =N141-K141 -> -74.187408 | Q141: =N141/K141 -> 0.89009273 | R141: =Q157 -> 0.89009273 | S141: 0.70856481 | T141: 0.86666667 | V141: 227.66667 | AA141: =M141-J141 -> -296.74963 | AB141: =M141/J141 -> 0.89009273 | AC141: =AB157 -> 0.89009273
B157: 平均 | I157: =AVERAGE(I141:I156) -> 4 | J157: =AVERAGE(J141:J156) -> 2700 | K157: =J157/I157 -> 675 | L157: =AVERAGE(L141:L156) -> 4 | M157: =AVERAGE(M141:M156) -> 2403.2504 | N157: =M157/L157 -> 600.81259 | O157: =L157-I157 -> 0 | P157: =N157-K157 -> -74.187408 | Q157: =N157/K157 -> 0.89009273 | S157: =S141 -> 0.70856481 | T157: =INDEX(T141:T156,COUNTA(T141:T156)) -> 0.86666667 | AA157: =M157-J157 -> -296.74963 | AB157: =M157/J157 -> 0.89009273
