Workbook

Sheet 0731
B1: 屏榮 大溪廠組合室生產人時性分析
B3: 日期 | C3: 114.07.31星期四 | E3: 訂單量 | F3: ='0731(18度C)'!D1+'0731(4度C)'!D1 -> 221423 | H3: 營業額 | I3: ='0731(18度C)'!F1+'0731(4度C)'!F1 -> 7185631
B4: 人時性 | C4: 項目 | E4: ➀ | G4: ➁ | I4: ➂ | K4: ④ | M4: ⑤
C5: 組合室 | E5: 全溫層 | G5: 4度C-各編組展開(一配) | I5: 4度C-各編組展開(二配) | K5: 18度C-各編組展開(一配) | M5: 18度C-各編組展開(二配)
C6: 排關平均 | E6: =AVERAGE(D13:O13,D27:X27) -> 496.0075 | F6: =AVERAGE(#REF!,D13:K13) -> #REF! | G6: =AVERAGE(D13:K13) -> 176.06474 | I6: =AVERAGE(L13:O13) -> 89.572193 | K6: =AVERAGE(D27:O27) -> 688.59363 | M6: =AVERAGE(P27:X27) -> 747.971
C7: 實績平均 | E7: =AVERAGE(D14:O14,D28:X28) -> 418.09716 | F7: =AVERAGE(#REF!,D14:K14) -> #REF! | G7: =AVERAGE(D14:K14) -> 148.28978 | I7: =AVERAGE(L14:O14) -> 76.511202 | K7: =AVERAGE(D28:O28) -> 580.23624 | M7: =AVERAGE(P28:X28) -> 630.54901
C8: 達成率平均 | E8: =AVERAGE(D15:O15,D29:X29) -> 0.84591724 | F8: =AVERAGE(D15:K15,#REF!) -> #REF! | G8: =AVERAGE(D15:K15) -> 0.84560984 | I8: =AVERAGE(L15:O15) -> 0.85417343 | K8: =AVERAGE(D29:O29) -> 0.84418743 | M8: =AVERAGE(P29:X29) -> 0.84583024 | O8: ※現行日本鮮食廠以達成率80%為基本(即為現行KPI)
B10: 溫層 | D10: ➁4度C-各編組展開 | L10: ➂4度C-各編組展開
B11: 編組 | D11: 1 | E11: 2 | F11: 3 | G11: 4 | H11: 5 | I11: 6 | J11: 7 | K11: 8 | L11: 1 | M11: 2 | N11: 3 | O11: 4
D12: 便當一線 | E12: 便當二線 | F12: 涼麵一線 | G12: 涼麵二線 | H12: 涼麵三線 | I12: 自動包裝機 | J12: 自動包裝機2 | K12: 自動包裝機3 | L12: 便當一線 | M12: 便當二線 | N12: 涼麵一線 | O12: 涼麵二線
B13: 人時性 | C13: 排關 | D13: 113.26531 | E13: 78.431373 | F13: 92.45283 | G13: 88.050314 | H13: 176 | I13: 250.92 | J13: - | K13: 433.33333 | L13: - | M13: - | N13: 90.909091 | O13: 88.235294
C14: 實績 | D14: 96.882571 | E14: 65.963684 | F14: 78.694721 | G14: 74.046649 | H14: 149.5397 | I14: 213.98442 | J14: - | K14: 358.9167 | L14: - | M14: - | N14: 77.721126 | O14: 75.301278
C15: 達成率 | D15: =D14/D13 -> 0.85535964 | E15: =E14/E13 -> 0.84103697 | F15: =F14/F13 -> 0.8511878 | G15: =G14/G13 -> 0.84095837 | H15: =H14/H13 -> 0.84965737 | I15: =I14/I13 -> 0.8527994 | J15: - | K15: =K14/K13 -> 0.82826931 | L15: - | M15: - | N15: =N14/N13 -> 0.85493238 | O15: =O14/O13 -> 0.85341448
B16: 作業 時間 | C16: 開始 | D16: 0.25002315 | E16: 0.16666667 | F16: 0.25008102 | G16: 0.25023148 | H16: 0.16680556 | I16: 0.25 | J16: - | K16: 0.33194444 | L16: - | M16: - | N16: 0.70854167 | O16: 0.70833333
C17: 結束 | D17: 0.60416667 | E17: 0.68888889 | F17: 0.5669213 | G17: 0.65219907 | H17: 0.68894676 | I17: 0.49537037 | J17: - | K17: 0.4125 | L17: - | M17: - | N17: 0.83289352 | O17: 0.83055556
B18: 配置人數 | D18: 16.333333 | E18: 25.5 | F18: 21.2 | G18: 22.714286 | H18: 20.454545 | I18: 12.5 | J18: - | K18: 6 | L18: - | M18: - | N18: 22 | O18: 22.666667
B19: 主要應用設備 | D19: L型封口機 | E19: ET-55 | F19: ET-55 | G19: ET-55 | H19: ET-600 | I19: 伺服包裝機 | J19: 伺服包裝機 | K19: 伺服包裝機 | L19: L型封口機 | M19: ET-55 | N19: ET-55 | O19: ET-55
B20: 次要應用設備 | D20: 伺服包裝機 | H20: 伺服包裝機
B21: 備註 | H21: 涼麵+烤飯糰 | I21: 大口飯糰線 | K21: 烤飯糰+手卷
B24: 溫層 | D24: ➃18度C-各編組展開 (一配) | P24: ⑤18度C-各編組展開 (二配)
B25: 編組 | D25: 1 | E25: 2 | F25: 3 | G25: 4 | H25: 5 | I25: 6 | J25: 7 | K25: 8 | L25: 9 | M25: 10 | N25: 11 | O25: 12 | P25: 1 | Q25: 2 | R25: 3 | S25: 4 | T25: 5 | U25: 6 | V25: 7 | W25: 8 | X25: 9
D26: 便當一線 | E26: 涼麵一線 | F26: 涼麵三線 | G26: 自動包裝機 | H26: 自動包裝機2 | I26: 自動包裝機3 | J26: 味付飯糰線B | K26: (舊) 3300型飯糰線 | L26: 3000型飯糰線 | M26: (新) 3300型飯糰機 | N26: GKK3600型 飯糰機 | O26: GKK3600型 飯糰機2 | P26: 自動包裝機 | Q26: 自動包裝機2 | R26: 自動包裝機3 | S26: 味付飯糰線B | T26: (舊) 3300型飯糰線 | U26: 3000型飯糰線 | V26: (新) 3300型飯糰機 | W26: GKK3600型 飯糰機 | X26: GKK3600型 飯糰機2
B27: 人時性 | C27: 排關 | D27: 226.15 | E27: - | F27: - | G27: 272.72727 | H27: 433.33333 | I27: - | J27: 675 | K27: 1100 | L27: - | M27: 761.53846 | N27: 1200 | O27: 840 | P27: 226.65517 | Q27: - | R27: - | S27: 675 | T27: 768.75 | U27: - | V27: 761.53846 | W27: 1050 | X27: 1005.8824
C28: 實績 | D28: 192.83551 | E28: - | F28: - | G28: 232.70394 | H28: 355.86529 | I28: - | J28: 589.41685 | K28: 934.97177 | L28: - | M28: 640.46999 | N28: 998.12488 | O28: 697.50166 | P28: 192.07618 | Q28: - | R28: - | S28: 599.20703 | T28: 642.22889 | U28: - | V28: 642.22818 | W28: 873.52937 | X28: 834.02441
C29: 達成率 | D29: =D28/D27 -> 0.85268853 | E29: - | F29: - | G29: =G28/G27 -> 0.85324779 | H29: =H28/H27 -> 0.82122759 | I29: - | J29: =J28/J27 -> 0.87321014 | K29: =K28/K27 -> 0.84997434 | L29: - | M29: =M28/M27 -> 0.8410212 | N29: =N28/N27 -> 0.83177073 | O29: =O28/O27 -> 0.83035911 | P29: =P28/P27 -> 0.84743787 | Q29: - | R29: - | S29: =S28/S27 -> 0.88771412 | T29: =T28/T27 -> 0.8354197 | U29: - | V29: =V28/V27 -> 0.84332993 | W29: =W28/W27 -> 0.83193274 | X29: =X28/X27 -> 0.82914707
B30: 作業 時間 | C30: 開始 | D30: 0.38564815 | E30: - | F30: - | G30: 0.31458333 | H30: 0.25003472 | I30: - | J30: 0.33340278 | K30: 0.43333333 | L30: - | M30: 0.29166667 | N30: 0.25 | O30: 0.25 | P30: 0.70833333 | Q30: - | R30: - | S30: 0.70833333 | T30: 0.70833333 | U30: - | V30: 0.70833333 | W30: 0.70837963 | X30: 0.70833333
C31: 結束 | D31: 0.49375 | E31: - | F31: - | G31: 0.35788194 | H31: 0.31180556 | I31: - | J31: 0.42986111 | K31: 0.46818287 | L31: - | M31: 0.44861111 | N31: 0.46140046 | O31: 0.45428241 | P31: 0.85436343 | Q31: - | R31: - | S31: 0.85721065 | T31: 0.85902778 | U31: - | V31: 0.89539352 | W31: 0.95208333 | X31: 0.95555556
B32: 配置人數 | D32: 13.333333 | E32: - | F32: - | G32: 11 | H32: 6 | I32: - | J32: 4 | K32: 3 | L32: - | M32: 4.3333333 | N32: 3 | O32: 3.75 | P32: 14.5 | Q32: - | R32: - | S32: 4 | T32: 4 | U32: - | V32: 4.3333333 | W32: 3.3333333 | X32: 3.4
B33: 主要應用設備 | D33: 伺服包裝機 | E33: ET-55 | F33: ET-600 | G33: 夾心型 | H33: 伺服包裝機 | I33: 伺服包裝機 | J33: 夾心型 | K33: 3300型 | L33: 3300型 | M33: 3300型 | N33: GKK | O33: GKK | P33: 夾心型 | Q33: 伺服包裝機 | R33: 伺服包裝機 | S33: 夾心型 | T33: 3300型 | U33: 3300型 | V33: 3300型 | W33: GKK | X33: GKK
B34: 次要應用設備
B35: 備註

Sheet 0731(18度C)
A1: 大溪廠日報分析 | C1: 總生產量 | D1: =SUM(F5:F242) -> 114228 | E1: 營業額 | F1: =SUM(G5:G242) -> 2265682.9 | G1: 出勤人數 | H1: =L21+L38+L55+L72+L89+L106+L123+L140+L157+L174+L191+L208+L225+L242 -> 81.983333 | I1: 產線配置圖 | L1: 生產實績 | O1: 人時性差異分析 | S1: 日報登錄 | Y1: 分析說明 | AA1: 產能差異分析
A2: 45869 | C2: 人時性 | D2: =AVERAGE(N21,,N38,N55,N72,N89,N106,N123,N140,N157,N174,N191,N208,N225,N242) -> 561.67893 | E2: 平均廠價 | F2: =F1/D1 -> 19.834742 | G2: 多次生產數 | H2: =COUNT(H5:H242) -> 2
A3: 線別 | B3: 品類 | C3: 品名 | E3: 廠價 | F3: 生產量 | G3: 營收 | H3: 多次 生產 | I3: 人數 | J3: 產能/時 | K3: 人時性 | L3: 人數 | M3: 產能/時 | N3: 人時性 | O3: 人數 | P3: 人時性 | Q3: 達成率 | R3: 達成率 平均 | S3: 生產時間 | U3: 換線、休息/分 | V3: 稼動時間/分 | W3: 休息時間 | Y3: (屏榮回填) | AA3: 產能/時 | AB3: 達成率 | AC3: 達成率平均
S4: 開始 | T4: 結束 | W4: 開始 | X4: 結束
A5: 便當一線 | B5: 壽司手卷 | C5: 一配海饌雙手卷 | E5: 29.85 | F5: 2124 | G5: =E5*F5 -> 63401.4 | I5: 17 | J5: 3273 | K5: =J5/I5 -> 192.52941 | L5: 17 | M5: =F5/V5*60 -> 2790.6569 | N5: =M5/L5 -> 164.15629 | O5: =L5-I5 -> 0 | P5: =N5-K5 -> -28.373122 | Q5: =N5/K5 -> 0.85262968 | R5: =Q21 -> 0.85268853 | S5: 0.38564815 | T5: 0.41736111 | U5: 5.3333333 | V5: 45.666667 | AA5: =M5-J5 -> -482.34307 | AB5: =M5/J5 -> 0.85262968 | AC5: =AB21 -> 0.85268853
B6: 壽司手卷 | C6: 一配雙饗雙手卷 | E6: 29.52 | F6: 2174 | G6: =E6*F6 -> 64176.48 | I6: 17 | J6: 3273 | K6: =J6/I6 -> 192.52941 | L6: 17 | M6: =F6/V6*60 -> 2792.1513 | N6: =M6/L6 -> 164.24419 | O6: =L6-I6 -> 0 | P6: =N6-K6 -> -28.28522 | Q6: =N6/K6 -> 0.85308624 | S6: 0.42241898 | T6: 0.45486111 | U6: 7.2833333 | V6: 46.716667 | AA6: =M6-J6 -> -480.84873 | AB6: =M6/J6 -> 0.85308624
B7: 壽司手卷 | C7: 一配日式厚蛋脆卷 | E7: 21.61 | F7: 1740 | G7: =E7*F7 -> 37601.4 | I7: 6 | J7: 2500 | K7: =J7/I7 -> 416.66667 | L7: 6 | M7: =F7/V7*60 -> 2130.6122 | N7: =M7/L7 -> 355.10204 | O7: =L7-I7 -> 0 | P7: =N7-K7 -> -61.564626 | Q7: =N7/K7 -> 0.8522449 | S7: 0.45972222 | T7: 0.49375 | U7: 7 | V7: 49 | W7: 0.49375 | X7: 0.53402778 | AA7: =M7-J7 -> -369.38776 | AB7: =M7/J7 -> 0.8522449
B21: 平均 | I21: =AVERAGE(I5:I20) -> 13.333333 | J21: =AVERAGE(J5:J20) -> 3015.3333 | K21: =J21/I21 -> 226.15 | L21: =AVERAGE(L5:L20) -> 13.333333 | M21: =AVERAGE(M5:M20) -> 2571.1401 | N21: =M21/L21 -> 192.83551 | O21: =L21-I21 -> 0 | P21: =N21-K21 -> -33.314489 | Q21: =N21/K21 -> 0.85268853 | S21: =S5 -> 0.38564815 | T21: =INDEX(T5:T20,COUNTA(T5:T20)) -> 0.49375 | AA21: =M21-J21 -> -444.19318 | AB21: =M21/J21 -> 0.85268853
A22: 自動包裝機 | B22: 壽司手卷 | C22: 一配長野稻荷壽司 | E22: 25.64 | F22: 2660 | G22: =E22*F22 -> 68202.4 | I22: 11 | J22: 3000 | K22: =J22/I22 -> 272.72727 | L22: 11 | M22: =F22/V22*60 -> 2559.7434 | N22: =M22/L22 -> 232.70394 | O22: =L22-I22 -> 0 | P22: =N22-K22 -> -40.023329 | Q22: =N22/K22 -> 0.85324779 | R22: =Q38 -> 0.85324779 | S22: 0.31458333 | T22: 0.35788194 | U22: 6 | V22: 62.35 | AA22: =M22-J22 -> -440.25662 | AB22: =M22/J22 -> 0.85324779 | AC22: =AB38 -> 0.85324779
B38: 平均 | I38: =AVERAGE(I22:I37) -> 11 | J38: =AVERAGE(J22:J37) -> 3000 | K38: =J38/I38 -> 272.72727 | L38: =AVERAGE(L22:L37) -> 11 | M38: =AVERAGE(M22:M37) -> 2559.7434 | N38: =M38/L38 -> 232.70394 | O38: =L38-I38 -> 0 | P38: =N38-K38 -> -40.023329 | Q38: =N38/K38 -> 0.85324779 | S38: =S22 -> 0.31458333 | T38: =INDEX(T22:T37,COUNTA(T22:T37)) -> 0.35788194 | AA38: =M38-J38 -> -440.25662 | AB38: =M38/J38 -> 0.85324779
A39: 自動包裝機2 | B39: 壽司手卷 | C39: 一配芝麻海苔香鬆細卷 | E39: 14.06 | F39: 1019 | G39: =E39*F39 -> 14327.14 | I39: 6 | J39: 2600 | K39: =J39/I39 -> 433.33333 | L39: 6 | M39: =F39/V39*60 -> 2150.2931 | N39: =M39/L39 -> 358.38218 | O39: =L39-I39 -> 0 | P39: =N39-K39 -> -74.951153 | Q39: =N39/K39 -> 0.8270358 | R39: =Q55 -> 0.82122759 | S39: 0.25003472 | T39: 0.26978009 | V39: 28.433333 | AA39: =M39-J39 -> -449.70692 | AB39: =M39/J39 -> 0.8270358 | AC39: =AB55 -> 0.82122759
B40: 壽司手卷 | C40: 一配鮪魚沙拉細卷 | E40: 14.81 | F40: 1153 | G40: =E40*F40 -> 17075.93 | I40: 6 | J40: 2600 | K40: =J40/I40 -> 433.33333 | L40: 6 | M40: =F40/V40*60 -> 2164.1293 | N40: =M40/L40 -> 360.68822 | O40: =L40-I40 -> 0 | P40: =N40-K40 -> -72.645116 | Q40: =N40/K40 -> 0.83235742 | S40: 0.27363426 | T40: 0.29583333 | U40: 5.55 | V40: 31.966667 | AA40: =M40-J40 -> -435.8707 | AB40: =M40/J40 -> 0.83235742
B41: 壽司手卷 | C41: 一配炙烤焦糖鮭魚細卷 | E41: 17.87 | F41: 650 | G41: =E41*F41 -> 11615.5 | I41: 6 | J41: 2600 | K41: =J41/I41 -> 433.33333 | L41: 6 | M41: =F41/V41*60 -> 2091.1528 | N41: =M41/L41 -> 348.52547 | O41: =L41-I41 -> 0 | P41: =N41-K41 -> -84.807864 | Q41: =N41/K41 -> 0.80428954 | S41: 0.29885417 | T41: 0.31180556 | U41: 4.35 | V41: 18.65 | AA41: =M41-J41 -> -508.84718 | AB41: =M41/J41 -> 0.80428954
B55: 平均 | I55: =AVERAGE(I39:I54) -> 6 | J55: =AVERAGE(J39:J54) -> 2600 | K55: =J55/I55 -> 433.33333 | L55: =AVERAGE(L39:L54) -> 6 | M55: =AVERAGE(M39:M54) -> 2135.1917 | N55: =M55/L55 -> 355.86529 | O55: =L55-I55 -> 0 | P55: =N55-K55 -> -77.468044 | Q55: =N55/K55 -> 0.82122759 | S55: =S39 -> 0.25003472 | T55: =INDEX(T39:T54,COUNTA(T39:T54)) -> 0.31180556 | AA55: =M55-J55 -> -464.80827 | AB55: =M55/J55 -> 0.82122759
A56: 味付飯糰線B | B56: 飯糰 | C56: 一配經典肉鬆飯糰 | E56: 14.03 | F56: 5458 | G56: =E56*F56 -> 76575.74 | I56: 4 | J56: 2700 | K56: =J56/I56 -> 675 | L56: 4 | M56: =F56/V56*60 -> 2357.6674 | N56: =M56/L56 -> 589.41685 | O56: =L56-I56 -> 0 | P56: =N56-K56 -> -85.583153 | Q56: =N56/K56 -> 0.87321014 | R56: =Q72 -> 0.87321014 | S56: 0.33340278 | T56: 0.42986111 | V56: 138.9 | AA56: =M56-J56 -> -342.33261 | AB56: =M56/J56 -> 0.87321014 | AC56: =AB72 -> 0.87321014
B72: 平均 | I72: =AVERAGE(I56:I71) -> 4 | J72: =AVERAGE(J56:J71) -> 2700 | K72: =J72/I72 -> 675 | L72: =AVERAGE(L56:L71) -> 4 | M72: =AVERAGE(M56:M71) -> 2357.6674 | N72: =M72/L72 -> 589.41685 | O72: =L72-I72 -> 0 | P72: =N72-K72 -> -85.583153 | Q72: =N72/K72 -> 0.87321014 | S72: =S56 -> 0.33340278 | T72: =INDEX(T56:T71,COUNTA(T56:T71)) -> 0.42986111 | AA72: =M72-J72 -> -342.33261 | AB72: =M72/J72 -> 0.87321014
A73: (舊) 3300型飯糰線 | B73: 飯糰 | C73: 一配三杯辣海瓜子飯糰 | E73: 21.45 | F73: 2346 | G73: =E73*F73 -> 50321.7 | I73: 3 | J73: 3300 | K73: =J73/I73 -> 1100 | L73: 3 | M73: =F73/V73*60 -> 2804.9153 | N73: =M73/L73 -> 934.97177 | O73: =L73-I73 -> 0 | P73: =N73-K73 -> -165.02823 | Q73: =N73/K73 -> 0.84997434 | R73: =Q89 -> 0.84997434 | S73: 0.43333333 | T73: 0.46818287 | V73: 50.183333 | AA73: =M73-J73 -> -495.08469 | AB73: =M73/J73 -> 0.84997434 | AC73: =AB89 -> 0.84997434
B89: 平均 | I89: =AVERAGE(I73:I88) -> 3 | J89: =AVERAGE(J73:J88) -> 3300 | K89: =J89/I89 -> 1100 | L89: =AVERAGE(L73:L88) -> 3 | M89: =AVERAGE(M73:M88) -> 2804.9153 | N89: =M89/L89 -> 934.97177 | O89: =L89-I89 -> 0 | P89: =N89-K89 -> -165.02823 | Q89: =N89/K89 -> 0.84997434 | S89: =S73 -> 0.43333333 | T89: =INDEX(T73:T88,COUNTA(T73:T88)) -> 0.46818287 | AA89: =M89-J89 -> -495.08469 | AB89: =M89/J89 -> 0.84997434
A90: (新) 3300型飯糰機 | B90: 飯糰 | C90: 一配壹號醬炙烤牛飯糰 | E90: 22.28 | F90: 1465 | G90: =E90*F90 -> 32640.2 | I90: 5 | J90: 3300 | K90: =J90/I90 -> 660 | L90: 5 | M90: =F90/V90*60 -> 2735.4772 | N90: =M90/L90 -> 547.09544 | O90: =L90-I90 -> 0 | P90: =N90-K90 -> -112.90456 | Q90: =N90/K90 -> 0.82893248 | R90: =Q106 -> 0.8410212 | S90: 0.29166667 | T90: 0.31398148 | V90: 32.133333 | AA90: =M90-J90 -> -564.52282 | AB90: =M90/J90 -> 0.82893248 | AC90: =AB106 -> 0.8410212
B91: 飯糰 | C91: 一配鹽蔥燒肉飯糰 | E91: 17.89 | F91: 3197 | G91: =E91*F91 -> 57194.33 | I91: 4 | J91: 3300 | K91: =J91/I91 -> 825 | L91: 4 | M91: =F91/V91*60 -> 2771.2979 | N91: =M91/L91 -> 692.82446 | O91: =L91-I91 -> 0 | P91: =N91-K91 -> -132.17554 | Q91: =N91/K91 -> 0.83978723 | S91: 0.31877315 | T91: 0.36684028 | U91: 6.9 | V91: 69.216667 | AA91: =M91-J91 -> -528.70214 | AB91: =M91/J91 -> 0.83978723
B92: 飯糰 | C92: 一配雞肉飯飯糰 | E92: 16.66 | F92: 5298 | G92: =E92*F92 -> 88264.68 | I92: 4 | J92: 3300 | K92: =J92/I92 -> 825 | L92: 4 | M92: =F92/V92*60 -> 2819.3348 | N92: =M92/L92 -> 704.8337 | O92: =L92-I92 -> 0 | P92: =N92-K92 -> -120.1663 | Q92: =N92/K92 -> 0.85434388 | S92: 0.3703125 | T92: 0.44861111 | U92: 5 | V92: 112.75 | AA92: =M92-J92 -> -480.66519 | AB92: =M92/J92 -> 0.85434388
B106: 平均 | I106: =AVERAGE(I90:I105) -> 4.3333333 | J106: =AVERAGE(J90:J105) -> 3300 | K106: =J106/I106 -> 761.53846 | L106: =AVERAGE(L90:L105) -> 4.3333333 | M106: =AVERAGE(M90:M105) -> 2775.3699 | N106: =M106/L106 -> 640.46999 | O106: =L106-I106 -> 0 | P106: =N106-K106 -> -121.06847 | Q106: =N106/K106 -> 0.8410212 | S106: =S90 -> 0.29166667 | T106: =INDEX(T90:T105,COUNTA(T90:T105)) -> 0.44861111 | AA106: =M106-J106 -> -524.63005 | AB106: =M106/J106 -> 0.8410212
A107: GKK3600型 飯糰機 | B107: 飯糰 | C107: 一配明太子龍蝦風味沙拉飯糰 | E107: 18.18 | F107: 2894 | G107: =E107*F107 -> 52612.92 | I107: 3 | J107: 3600 | K107: =J107/I107 -> 1200 | L107: 3 | M107: =F107/V107*60 -> 2991.2145 | N107: =M107/L107 -> 997.07149 | O107: =L107-I107 -> 0 | P107: =N107-K107 -> -202.92851 | Q107: =N107/K107 -> 0.83089291 | R107: =Q123 -> 0.83177073 | S107: 0.25 | T107: 0.2903125 | V107: 58.05 | AA107: =M107-J107 -> -608.78553 | AB107: =M107/J107 -> 0.83089291 | AC107: =AB123 -> 0.83177073
B108: 飯糰 | C108: 一配蔬食鮪魚飯糰 | E108: 18.18 | F108: 3681 | G108: =E108*F108 -> 66920.58 | I108: 3 | J108: 3600 | K108: =J108/I108 -> 1200 | L108: 3 | M108: =F108/V108*60 -> 2994.0352 | N108: =M108/L108 -> 998.01175 | O108: =L108-I108 -> 0 | P108: =N108-K108 -> -201.98825 | Q108: =N108/K108 -> 0.83167646 | S108: 0.30363426 | T108: 0.35486111 | U108: 19.183333 | V108: 73.766667 | AA108: =M108-J108 -> -605.96475 | AB108: =M108/J108 -> 0.83167646
B109: 飯糰 | C109: 鮪魚飯糰 | E109: 14.28 | F109: 6816 | G109: =E109*F109 -> 97332.48 | I109: 3 | J109: 3600 | K109: =J109/I109 -> 1200 | L109: 3 | M109: =F109/V109*60 -> 2997.8742 | N109: =M109/L109 -> 999.29139 | O109: =L109-I109 -> 0 | P109: =N109-K109 -> -200.70861 | Q109: =N109/K109 -> 0.83274282 | S109: 0.36666667 | T109: 0.46140046 | U109: 17 | V109: 136.41667 | AA109: =M109-J109 -> -602.12584 | AB109: =M109/J109 -> 0.83274282
B123: 平均 | I123: =AVERAGE(I107:I122) -> 3 | J123: =AVERAGE(J107:J122) -> 3600 | K123: =J123/I123 -> 1200 | L123: =AVERAGE(L107:L122) -> 3 | M123: =AVERAGE(M107:M122) -> 2994.3746 | N123: =M123/L123 -> 998.12488 | O123: =L123-I123 -> 0 | P123: =N123-K123 -> -201.87512 | Q123: =N123/K123 -> 0.83177073 | S123: =S107 -> 0.25 | T123: =INDEX(T107:T122,COUNTA(T107:T122)) -> 0.46140046 | AA123: =M123-J123 -> -605.62537 | AB123: =M123/J123 -> 0.83177073
A124: GKK3600型 飯糰機2 | B124: 飯糰 | C124: 一配北海道秋鮭親子飯糰 | E124: 24.83 | F124: 2380 | G124: =E124*F124 -> 59095.4 | I124: 4 | J124: 3300 | K124: =J124/I124 -> 825 | L124: 4 | M124: =F124/V124*60 -> 2737.3802 | N124: =M124/L124 -> 684.34505 | O124: =L124-I124 -> 0 | P124: =N124-K124 -> -140.65495 | Q124: =N124/K124 -> 0.82950915 | R124: =Q140 -> 0.83035911 | S124: 0.25 | T124: 0.28622685 | V124: 52.166667 | AA124: =M124-J124 -> -562.61981 | AB124: =M124/J124 -> 0.82950915 | AC124: =AB140 -> 0.83035911
B125: 飯糰 | C125: 一配熟成紅鮭飯糰 | E125: 25.03 | F125: 1974 | G125: =E125*F125 -> 49409.22 | I125: 4 | J125: 3300 | K125: =J125/I125 -> 825 | L125: 4 | M125: =F125/V125*60 -> 2732.1799 | N125: =M125/L125 -> 683.04498 | O125: =L125-I125 -> 0 | P125: =N125-K125 -> -141.95502 | Q125: =N125/K125 -> 0.82793331 | S125: 0.29861111 | T125: 0.32871528 | U125: 17.833333 | V125: 43.35 | AA125: =M125-J125 -> -567.82007 | AB125: =M125/J125 -> 0.82793331
B126: 飯糰 | C126: 一配贅沢鮭魚肚飯糰 | E126: 30 | F126: 4012 | G126: =E126*F126 -> 120360 | I126: 3 | J126: 3000 | K126: =J126/I126 -> 1000 | L126: 3 | M126: =F126/V126*60 -> 2496.6638 | N126: =M126/L126 -> 832.22126 | O126: =L126-I126 -> 0 | P126: =N126-K126 -> -167.77874 | Q126: =N126/K126 -> 0.83222126 | S126: 0.34027778 | T126: 0.4072338 | U126: 16.65 | V126: 96.416667 | AA126: =M126-J126 -> -503.33621 | AB126: =M126/J126 -> 0.83222126
B127: 飯糰 | C127: 一配海老天婦羅飯糰 | E127: 27.91 | F127: 2212 | G127: =E127*F127 -> 61736.92 | I127: 4 | J127: 3000 | K127: =J127/I127 -> 750 | L127: 4 | M127: =F127/V127*60 -> 2496.3009 | N127: =M127/L127 -> 624.07524 | O127: =L127-I127 -> 0 | P127: =N127-K127 -> -125.92476 | Q127: =N127/K127 -> 0.83210031 | S127: 0.41736111 | T127: 0.45428241 | U127: 14.583333 | V127: 53.166667 | AA127: =M127-J127 -> -503.69906 | AB127: =M127/J127 -> 0.83210031
B140: 平均 | I140: =AVERAGE(I124:I139) -> 3.75 | J140: =AVERAGE(J124:J139) -> 3150 | K140: =J140/I140 -> 840 | L140: =AVERAGE(L124:L139) -> 3.75 | M140: =AVERAGE(M124:M139) -> 2615.6312 | N140: =M140/L140 -> 697.50166 | O140: =L140-I140 -> 0 | P140: =N140-K140 -> -142.49834 | Q140: =N140/K140 -> 0.83035911 | S140: =S124 -> 0.25 | T140: =INDEX(T124:T139,COUNTA(T124:T139)) -> 0.45428241 | AA140: =M140-J140 -> -534.36879 | AB140: =M140/J140 -> 0.83035911
A141: 自動包裝機 (二配) | B141: 壽司 | C141: 二配長野稻荷壽司 | E141: 25.64 | F141: 2480 | G141: =E141*F141 -> 63587.2 | I141: 11 | J141: 3000 | K141: =J141/I141 -> 272.72727 | L141: 11 | M141: =F141/V141*60 -> 2559.633 | N141: =M141/L141 -> 232.69391 | O141: =L141-I141 -> 0 | P141: =N141-K141 -> -40.033361 | Q141: =N141/K141 -> 0.85321101 | R141: =Q157 -> 0.84743787 | S141: 0.70833333 | T141: 0.7487037 | V141: 58.133333 | AA141: =M141-J141 -> -440.36697 | AB141: =M141/J141 -> 0.85321101 | AC141: =AB157 -> 0.84743787
B142: 壽司 | C142: 二配雙饗雙手卷 | E142: 29.52 | F142: 2139 | G142: =E142*F142 -> 63143.28 | I142: 17 | J142: 3273 | K142: =J142/I142 -> 192.52941 | L142: 17 | M142: =F142/V142*60 -> 2791.0112 | N142: =M142/L142 -> 164.17713 | O142: =L142-I142 -> 0 | P142: =N142-K142 -> -28.35228 | Q142: =N142/K142 -> 0.85273793 | S142: 0.7534838 | T142: 0.78541667 | U142: 6.8833333 | V142: 45.983333 | AA142: =M142-J142 -> -481.98876 | AB142: =M142/J142 -> 0.85273793
B143: 壽司 | C143: 二配海饌雙手卷 | E143: 29.85 | F143: 2181 | G143: =E143*F143 -> 65102.85 | I143: 17 | J143: 3273 | K143: =J143/I143 -> 192.52941 | L143: 17 | M143: =F143/V143*60 -> 2793.1697 | N143: =M143/L143 -> 164.3041 | O143: =L143-I143 -> 0 | P143: =N143-K143 -> -28.225312 | Q143: =N143/K143 -> 0.8533974 | S143: 0.79039352 | T143: 0.82292824 | U143: 7.1666667 | V143: 46.85 | AA143: =M143-J143 -> -479.83031 | AB143: =M143/J143 -> 0.8533974
B144: 飯糰 | C144: 二配兩粒飯糰(鮪魚&培根蛋沙拉) | E144: 28.57 | F144: 1912 | G144: =E144*F144 -> 54625.84 | I144: 13 | J144: 3600 | K144: =J144/I144 -> 276.92308 | L144: 13 | M144: =F144/V144*60 -> 2996.6043 | N144: =M144/L144 -> 230.50802 | O144: =L144-I144 -> 0 | P144: =N144-K144 -> -46.415056 | Q144: =N144/K144 -> 0.83239007 | S144: 0.82777778 | T144: 0.85436343 | U144: 6.9833333 | V144: 38.283333 | AA144: =M144-J144 -> -603.39573 | AB144: =M144/J144 -> 0.83239007
B157: 平均 | I157: =AVERAGE(I141:I156) -> 14.5 | J157: =AVERAGE(J141:J156) -> 3286.5 | K157: =J157/I157 -> 226.65517 | L157: =AVERAGE(L141:L156) -> 14.5 | M157: =AVERAGE(M141:M156) -> 2785.1046 | N157: =M157/L157 -> 192.07618 | O157: =L157-I157 -> 0 | P157: =N157-K157 -> -34.578996 | Q157: =N157/K157 -> 0.84743787 | S157: =S141 -> 0.70833333 | T157: =INDEX(T141:T156,COUNTA(T141:T156)) -> 0.85436343 | AA157: =M157-J157 -> -501.39544 | AB157: =M157/J157 -> 0.84743787
A158: 味付飯糰線B (二配) | B158: 飯糰 | C158: 二配經典肉鬆飯糰 | E158: 14.03 | F158: 8564 | G158: =E158*F158 -> 120152.92 | I158: 4 | J158: 2700 | K158: =J158/I158 -> 675 | L158: 4 | M158: =F158/V158*60 -> 2396.8281 | N158: =M158/L158 -> 599.20703 | O158: =L158-I158 -> 0 | P158: =N158-K158 -> -75.792972 | Q158: =N158/K158 -> 0.88771412 | R158: =Q174 -> 0.88771412 | S158: 0.70833333 | T158: 0.85721065 | V158: 214.38333 | AA158: =M158-J158 -> -303.17189 | AB158: =M158/J158 -> 0.88771412 | AC158: =AB174 -> 0.88771412
B174: 平均 | I174: =AVERAGE(I158:I173) -> 4 | J174: =AVERAGE(J158:J173) -> 2700 | K174: =J174/I174 -> 675 | L174: =AVERAGE(L158:L173) -> 4 | M174: =AVERAGE(M158:M173) -> 2396.8281 | N174: =M174/L174 -> 599.20703 | O174: =L174-I174 -> 0 | P174: =N174-K174 -> -75.792972 | Q174: =N174/K174 -> 0.88771412 | S174: =S158 -> 0.70833333 | T174: =INDEX(T158:T173,COUNTA(T158:T173)) -> 0.85721065 | AA174: =M174-J174 -> -303.17189 | AB174: =M174/J174 -> 0.88771412
A175: (舊) 3300型飯糰線 (二配) | B175: 飯糰 | C175: 二配大飯糰椒香鮪魚 | E175: 24.15 | F175: 1006 | G175: =E175*F175 -> 24294.9 | I175: 4 | J175: 3000 | K175: =J175/I175 -> 750 | L175: 4 | M175: =F175/V175*60 -> 2482.2481 | N175: =M175/L175 -> 620.56203 | O175: =L175-I175 -> 0 | P175: =N175-K175 -> -129.43797 | Q175: =N175/K175 -> 0.82741604 | R175: =Q191 -> 0.8354197 | S175: 0.70833333 | T175: 0.72521991 | V175: 24.316667 | AA175: =M175-J175 -> -517.75188 | AB175: =M175/J175 -> 0.82741604 | AC175: =AB191 -> 0.8354197
B176: 飯糰 | C176: 二配大飯糰春川風味辣炒雞 | E176: 24.15 | F176: 1273 | G176: =E176*F176 -> 30742.95 | I176: 4 | J176: 3000 | K176: =J176/I176 -> 750 | L176: 4 | M176: =F176/V176*60 -> 2496.0784 | N176: =M176/L176 -> 624.01961 | O176: =L176-I176 -> 0 | P176: =N176-K176 -> -125.98039 | Q176: =N176/K176 -> 0.83202614 | S176: 0.72950231 | T176: 0.75075231 | U176: 6.1666667 | V176: 30.6 | AA176: =M176-J176 -> -503.92157 | AB176: =M176/J176 -> 0.83202614
...

Sheet 0731(4度C)
A1: 大溪廠日報分析 | C1: 總生產量 | D1: =SUM(F5:F157) -> 107195 | E1: 營業額 | F1: =SUM(G5:G157) -> 4919948.2 | G1: 出勤人數 | H1: =L21+L38+L55+L72+L89+L106+L123+L140+L157 -> 169.36883 | I1: 產線配置圖 | L1: 生產實績 | O1: 人時性差異分析 | S1: 日報登錄 | Y1: 分析說明 | AA1: 產能差異分析
A2: 45869 | C2: 人時性 | D2: =AVERAGE(N21,N38,N55,N72,N89,N106,N123,N140,N157) -> 132.33898 | E2: 平均廠價 | F2: =F1/D1 -> 45.89718 | G2: 多次生產數 | H2: =COUNT(H5:H157) -> 2
A3: 線別 | B3: 品類 | C3: 品名 | E3: 廠價 | F3: 生產量 | G3: 營收 | H3: 多次 生產 | I3: 人數 | J3: 產能/時 | K3: 人時性 | L3: 人數 | M3: 產能/時 | N3: 人時性 | O3: 人數 | P3: 人時性 | Q3: 達成率 | R3: 達成率 平均 | S3: 生產時間 | U3: 換線、休息/分 | V3: 稼動時間/分 | W3: 休息時間 | Y3: (屏榮回填) | AA3: 產能/時 | AB3: 達成率 | AC3: 達成率平均
S4: 開始 | T4: 結束 | W4: 開始 | X4: 結束
A5: 便當一線 | B5: 小菜、微波 | C5: 日式茶碗蒸 | E5: 19.7 | F5: 3348 | G5: =E5*F5 -> 65955.6 | I5: 13 | J5: 1200 | K5: =J5/I5 -> 92.307692 | L5: 13 | M5: =F5/V5*60 -> 1057.4487 | N5: =M5/L5 -> 81.342206 | O5: =L5-I5 -> 0 | P5: =N5-K5 -> -10.965487 | Q5: =N5/K5 -> 0.88120723 | R5: =Q21 -> 0.85535964 | S5: 0.25002315 | T5: 0.38194444 | V5: 189.96667 | AA5: =M5-J5 -> -142.55132 | AB5: =M5/J5 -> 0.88120723 | AC5: =AB21 -> 0.85535964
B6: 壽司手卷 | C6: (冷藏)鮪魚蛋蛋稻荷壽司組 | E6: 30.55 | F6: 893 | G6: =E6*F6 -> 27281.15 | I6: 16 | J6: 1750 | K6: =J6/I6 -> 109.375 | L6: 16 | M6: =F6/V6*60 -> 1445.5036 | N6: =M6/L6 -> 90.343975 | O6: =L6-I6 -> 0 | P6: =N6-K6 -> -19.031025 | Q6: =N6/K6 -> 0.82600206 | S6: 0.53402778 | T6: 0.55976852 | U6: 58 | V6: 37.066667 | AA6: =M6-J6 -> -304.4964 | AB6: =M6/J6 -> 0.82600206
B7: 飯糰 | C7: 麻油雞飯糰 | E7: 29.97 | F7: 2114 | G7: =E7*F7 -> 63356.58 | I7: 20 | J7: 2600 | K7: =J7/I7 -> 130 | L7: 20 | M7: =F7/V7*60 -> 2244.2937 | N7: =M7/L7 -> 112.21469 | O7: =L7-I7 -> 0 | P7: =N7-K7 -> -17.785314 | Q7: =N7/K7 -> 0.86318989 | S7: 0.56491898 | T7: 0.60416667 | U7: 7.4166667 | V7: 56.516667 | AA7: =M7-J7 -> -355.70628 | AB7: =M7/J7 -> 0.86318989
B21: 平均 | I21: =AVERAGE(I5:I20) -> 16.333333 | J21: =AVERAGE(J5:J20) -> 1850 | K21: =J21/I21 -> 113.26531 | L21: =AVERAGE(L5:L20) -> 16.333333 | M21: =AVERAGE(M5:M20) -> 1582.4153 | N21: =M21/L21 -> 96.882571 | O21: =L21-I21 -> 0 | P21: =N21-K21 -> -16.382735 | Q21: =N21/K21 -> 0.85535964 | S21: =S5 -> 0.25002315 | T21: =INDEX(T5:T20,COUNTA(T5:T20)) -> 0.60416667 | AA21: =M21-J21 -> -267.58467 | AB21: =M21/J21 -> 0.85535964
A22: 便當二線 | B22: 微波主食 | C22: 壹號醬醬燒蔥鹽雞豚飯 | E22: 56.43 | F22: 2225 | G22: =E22*F22 -> 125556.75 | I22: 24 | J22: 2000 | K22: =J22/I22 -> 83.333333 | L22: 24 | M22: =F22/V22*60 -> 1688.8046 | N22: =M22/L22 -> 70.366856 | O22: =L22-I22 -> 0 | P22: =N22-K22 -> -12.966477 | Q22: =N22/K22 -> 0.84440228 | R22: =Q38 -> 0.84103697 | S22: 0.16666667 | T22: 0.2215625 | V22: 79.05 | AA22: =M22-J22 -> -311.19545 | AB22: =M22/J22 -> 0.84440228 | AC22: =AB38 -> 0.84103697
B23: 微波主食 | C23: 蒜蒜燒豚飯 | E23: 51.86 | F23: 1404 | G23: =E23*F23 -> 72811.44 | I23: 26 | J23: 2000 | K23: =J23/I23 -> 76.923077 | L23: 26 | M23: =F23/V23*60 -> 1642.1053 | N23: =M23/L23 -> 63.157895 | O23: =L23-I23 -> 0 | P23: =N23-K23 -> -13.765182 | Q23: =N23/K23 -> 0.82105263 | S23: 0.22569444 | T23: 0.26131944 | U23: 5.95 | V23: 51.3 | AA23: =M23-J23 -> -357.89474 | AB23: =M23/J23 -> 0.82105263
B24: 微波主食 | C24: 糖燻野郎三十天熟成牛飯 | E24: 56.77 | F24: 4711 | G24: =E24*F24 -> 267443.47 | I24: 26 | J24: 2000 | K24: =J24/I24 -> 76.923077 | L24: 26 | M24: =F24/V24*60 -> 1731.4548 | N24: =M24/L24 -> 66.594416 | O24: =L24-I24 -> 0 | P24: =N24-K24 -> -10.328661 | Q24: =N24/K24 -> 0.86572741 | S24: 0.26458333 | T24: 0.37795139 | U24: 4.7 | V24: 163.25 | AA24: =M24-J24 -> -268.54518 | AB24: =M24/J24 -> 0.86572741
B25: 便當 | C25: 鰻牛雙饗匠食盒 | E25: 68.73 | F25: 2923 | G25: =E25*F25 -> 200897.79 | H25: 2 | I25: 26 | J25: 2000 | K25: =J25/I25 -> 76.923077 | L25: 26 | M25: =F25/V25*60 -> 1648.0501 | N25: =M25/L25 -> 63.386543 | O25: =L25-I25 -> 0 | P25: =N25-K25 -> -13.536534 | Q25: =N25/K25 -> 0.82402506 | S25: 0.38125 | T25: 0.45515046 | U25: 4.75 | V25: 106.41667 | W25: 0.45515046 | X25: 0.49444444 | AA25: =M25-J25 -> -351.94988 | AB25: =M25/J25 -> 0.82402506
B26: 便當 | C26: 健身G肉餐盒 | E26: 59.52 | F26: 5486 | G26: =E26*F26 -> 326526.72 | I26: 25 | J26: 2000 | K26: =J26/I26 -> 80 | L26: 25 | M26: =F26/V26*60 -> 1737.4505 | N26: =M26/L26 -> 69.498021 | O26: =L26-I26 -> 0 | P26: =N26-K26 -> -10.501979 | Q26: =N26/K26 -> 0.86872526 | S26: 0.49444444 | T26: 0.62600694 | U26: 56.583333 | V26: 189.45 | AA26: =M26-J26 -> -262.54949 | AB26: =M26/J26 -> 0.86872526
B27: 便當 | C27: 鰻牛雙饗匠食盒 | E27: 68.73 | F27: 2275 | G27: =E27*F27 -> 156360.75 | I27: 26 | J27: 2000 | K27: =J27/I27 -> 76.923077 | L27: 26 | M27: =F27/V27*60 -> 1644.5783 | N27: =M27/L27 -> 63.253012 | O27: =L27-I27 -> 0 | P27: =N27-K27 -> -13.670065 | Q27: =N27/K27 -> 0.82228916 | S27: 0.63125 | T27: 0.68888889 | U27: 7.55 | V27: 83 | AA27: =M27-J27 -> -355.42169 | AB27: =M27/J27 -> 0.82228916
AQ29: =AI8 -> 0
B38: 平均 | I38: =AVERAGE(I22:I37) -> 25.5 | J38: =AVERAGE(J22:J37) -> 2000 | K38: =J38/I38 -> 78.431373 | L38: =AVERAGE(L22:L37) -> 25.5 | M38: =AVERAGE(M22:M37) -> 1682.0739 | N38: =M38/L38 -> 65.963684 | O38: =L38-I38 -> 0 | P38: =N38-K38 -> -12.467689 | Q38: =N38/K38 -> 0.84103697 | S38: =S22 -> 0.16666667 | T38: =INDEX(T22:T37,COUNTA(T22:T37)) -> 0.68888889 | AA38: =M38-J38 -> -317.92607 | AB38: =M38/J38 -> 0.84103697
A39: 涼麵一線 | B39: 熱食義麵 | C39: 金沙豆腐細扁麵 | E39: 49.52 | F39: 3185 | G39: =E39*F39 -> 157721.2 | I39: 24 | J39: 2000 | K39: =J39/I39 -> 83.333333 | L39: 24 | M39: =F39/V39*60 -> 1708.0292 | N39: =M39/L39 -> 71.167883 | O39: =L39-I39 -> 0 | P39: =N39-K39 -> -12.16545 | Q39: =N39/K39 -> 0.8540146 | R39: =Q55 -> 0.8511878 | S39: 0.25008102 | T39: 0.32777778 | V39: 111.88333 | AA39: =M39-J39 -> -291.9708 | AB39: =M39/J39 -> 0.8540146 | AC39: =AB55 -> 0.8511878
B40: 便當 | C40: 悟家厚切排骨便當 | E40: 59.8 | F40: 854 | G40: =E40*F40 -> 51069.2 | I40: 14 | J40: 2000 | K40: =J40/I40 -> 142.85714 | L40: 14 | M40: =F40/V40*60 -> 1655.5735 | N40: =M40/L40 -> 118.25525 | O40: =L40-I40 -> 0 | P40: =N40-K40 -> -24.601892 | Q40: =N40/K40 -> 0.82778675 | S40: 0.33128472 | T40: 0.35277778 | U40: 5.05 | V40: 30.95 | AA40: =M40-J40 -> -344.42649 | AB40: =M40/J40 -> 0.82778675
B41: 小菜、微波 | C41: 越式牛肉寬粉 | E41: 51.82 | F41: 2742 | G41: =E41*F41 -> 142090.44 | I41: 23 | J41: 1800 | K41: =J41/I41 -> 78.26087 | L41: 23 | M41: =F41/V41*60 -> 1530.6559 | N41: =M41/L41 -> 66.550257 | O41: =L41-I41 -> 0 | P41: =N41-K41 -> -11.710612 | Q41: =N41/K41 -> 0.8503644 | S41: 0.35555556 | T41: 0.43019676 | U41: 4 | V41: 107.48333 | AA41: =M41-J41 -> -269.34408 | AB41: =M41/J41 -> 0.8503644
B42: 便當 | C42: 美式雞丁餐盒 | E42: 59.34 | F42: 2201 | G42: =E42*F42 -> 130607.34 | I42: 24 | J42: 2000 | K42: =J42/I42 -> 83.333333 | L42: 24 | M42: =F42/V42*60 -> 1692.3537 | N42: =M42/L42 -> 70.514737 | O42: =L42-I42 -> 0 | P42: =N42-K42 -> -12.818596 | Q42: =N42/K42 -> 0.84617685 | S42: 0.43541667 | T42: 0.48960648 | U42: 7.5166667 | V42: 78.033333 | W42: 0.48960648 | X42: 0.52986111 | AA42: =M42-J42 -> -307.6463 | AB42: =M42/J42 -> 0.84617685
B43: 季節調理麵 | C43: 日式胡麻雞絲冷麵 | E43: 46.93 | F43: 1561 | G43: =E43*F43 -> 73257.73 | I43: 21 | J43: 2000 | K43: =J43/I43 -> 95.238095 | L43: 21 | M43: =F43/V43*60 -> 1755.0281 | N43: =M43/L43 -> 83.572767 | O43: =L43-I43 -> 0 | P43: =N43-K43 -> -11.665328 | Q43: =N43/K43 -> 0.87751405 | S43: 0.52986111 | T43: 0.5669213 | U43: 57.966667 | V43: 53.366667 | AA43: =M43-J43 -> -244.97189 | AB43: =M43/J43 -> 0.87751405
B55: 平均 | I55: =AVERAGE(I39:I54) -> 21.2 | J55: =AVERAGE(J39:J54) -> 1960 | K55: =J55/I55 -> 92.45283 | L55: =AVERAGE(L39:L54) -> 21.2 | M55: =AVERAGE(M39:M54) -> 1668.3281 | N55: =M55/L55 -> 78.694721 | O55: =L55-I55 -> 0 | P55: =N55-K55 -> -13.758109 | Q55: =N55/K55 -> 0.8511878 | S55: =S39 -> 0.25008102 | T55: =INDEX(T39:T54,COUNTA(T39:T54)) -> 0.5669213 | AA55: =M55-J55 -> -291.67192 | AB55: =M55/J55 -> 0.8511878
A56: 涼麵二線 | B56: 便當 | C56: 韓味豬肉時蔬拌拌餐盒 | E56: 59.36 | F56: 1689 | G56: =E56*F56 -> 100259.04 | I56: 23 | J56: 2000 | K56: =J56/I56 -> 86.956522 | L56: 23 | M56: =F56/V56*60 -> 1698.4358 | N56: =M56/L56 -> 73.845033 | O56: =L56-I56 -> 0 | P56: =N56-K56 -> -13.111489 | Q56: =N56/K56 -> 0.84921788 | R56: =Q72 -> 0.84095837 | S56: 0.25023148 | T56: 0.29166667 | V56: 59.666667 | AA56: =M56-J56 -> -301.56425 | AB56: =M56/J56 -> 0.84921788 | AC56: =AB72 -> 0.84095837
B57: 便當 | C57: 蒲燒玉子鰻飯 | E57: 102.83 | F57: 1491 | G57: =E57*F57 -> 153319.53 | I57: 19 | J57: 2000 | K57: =J57/I57 -> 105.26316 | L57: 19 | M57: =F57/V57*60 -> 1693.2492 | N57: =M57/L57 -> 89.11838 | O57: =L57-I57 -> 0 | P57: =N57-K57 -> -16.144778 | Q57: =N57/K57 -> 0.84662461 | S57: 0.29456019 | T57: 0.33125 | U57: 4.1666667 | V57: 52.833333 | AA57: =M57-J57 -> -306.75079 | AB57: =M57/J57 -> 0.84662461
B58: 微波主食 | C58: 日式中濃醬炭火漢堡排飯 | E58: 56.85 | F58: 886 | G58: =E58*F58 -> 50369.1 | I58: 21 | J58: 2000 | K58: =J58/I58 -> 95.238095 | L58: 21 | M58: =F58/V58*60 -> 1631.509 | N58: =M58/L58 -> 77.690902 | O58: =L58-I58 -> 0 | P58: =N58-K58 -> -17.547193 | Q58: =N58/K58 -> 0.81575448 | S58: 0.33501157 | T58: 0.35763889 | U58: 5.4166667 | V58: 32.583333 | AA58: =M58-J58 -> -368.49105 | AB58: =M58/J58 -> 0.81575448
B59: 便當 | C59: 經典滷肉飯 | E59: 47.37 | F59: 1775 | G59: =E59*F59 -> 84081.75 | I59: 21 | J59: 2000 | K59: =J59/I59 -> 95.238095 | L59: 21 | M59: =F59/V59*60 -> 1670.5882 | N59: =M59/L59 -> 79.551821 | O59: =L59-I59 -> 0 | P59: =N59-K59 -> -15.686275 | Q59: =N59/K59 -> 0.83529412 | S59: 0.36197917 | T59: 0.40625 | U59: 6.25 | V59: 63.75 | AA59: =M59-J59 -> -329.41176 | AB59: =M59/J59 -> 0.83529412
B60: 便當 | C60: 嫩烤香料雞胸排蔬滿盒 | E60: 77.34 | F60: 2716 | G60: =E60*F60 -> 210055.44 | I60: 25 | J60: 2000 | K60: =J60/I60 -> 80 | L60: 25 | M60: =F60/V60*60 -> 1674.2466 | N60: =M60/L60 -> 66.969863 | O60: =L60-I60 -> 0 | P60: =N60-K60 -> -13.030137 | Q60: =N60/K60 -> 0.83712329 | S60: 0.41111111 | T60: 0.4787037 | U60: 7 | V60: 97.333333 | W60: 0.4787037 | X60: 0.51694444 | AA60: =M60-J60 -> -325.75342 | AB60: =M60/J60 -> 0.83712329
B61: 便當 | C61: 一口滷魂便當 | E61: 53.37 | F61: 1282 | G61: =E61*F61 -> 68420.34 | I61: 25 | J61: 2000 | K61: =J61/I61 -> 80 | L61: 25 | M61: =F61/V61*60 -> 1686.8421 | N61: =M61/L61 -> 67.473684 | O61: =L61-I61 -> 0 | P61: =N61-K61 -> -12.526316 | Q61: =N61/K61 -> 0.84342105 | S61: 0.51694444 | T61: 0.54861111 | U61: 55.066667 | V61: 45.6 | AA61: =M61-J61 -> -313.15789 | AB61: =M61/J61 -> 0.84342105
B62: 便當 | C62: 烤蛋白餐盒 | E62: 58.67 | F62: 4072 | G62: =E62*F62 -> 238904.24 | I62: 25 | J62: 2000 | K62: =J62/I62 -> 80 | L62: 25 | M62: =F62/V62*60 -> 1718.5463 | N62: =M62/L62 -> 68.741852 | O62: =L62-I62 -> 0 | P62: =N62-K62 -> -11.258148 | Q62: =N62/K62 -> 0.85927315 | S62: 0.55347222 | T62: 0.65219907 | U62: 7 | V62: 142.16667 | AA62: =M62-J62 -> -281.45369 | AB62: =M62/J62 -> 0.85927315
B72: 平均 | I72: =AVERAGE(I56:I71) -> 22.714286 | J72: =AVERAGE(J56:J71) -> 2000 | K72: =J72/I72 -> 88.050314 | L72: =AVERAGE(L56:L71) -> 22.714286 | M72: =AVERAGE(M56:M71) -> 1681.9167 | N72: =M72/L72 -> 74.046649 | O72: =L72-I72 -> 0 | P72: =N72-K72 -> -14.003666 | Q72: =N72/K72 -> 0.84095837 | S72: =S56 -> 0.25023148 | T72: =INDEX(T56:T71,COUNTA(T56:T71)) -> 0.65219907 | AA72: =M72-J72 -> -318.08327 | AB72: =M72/J72 -> 0.84095837
A73: 涼麵三線 | B73: 季節調理麵 | C73: 椒麻香蔥雞涼拌麵 | E73: 37.94 | F73: 4241 | G73: =E73*F73 -> 160903.54 | I73: 21 | J73: 3600 | K73: =J73/I73 -> 171.42857 | L73: 21 | M73: =F73/V73*60 -> 3000.7075 | N73: =M73/L73 -> 142.89084 | O73: =L73-I73 -> 0 | P73: =N73-K73 -> -28.537736 | Q73: =N73/K73 -> 0.83352987 | R73: =Q89 -> 0.84965737 | S73: 0.16680556 | T73: 0.22569444 | V73: 84.8 | AA73: =M73-J73 -> -599.29245 | AB73: =M73/J73 -> 0.83352987 | AC73: =AB89 -> 0.84965737
B74: 季節調理麵 | C74: 柚香海藻冷麵 | E74: 38.1 | F74: 338 | G74: =E74*F74 -> 12877.8 | I74: 21 | J74: 3600 | K74: =J74/I74 -> 171.42857 | L74: 21 | M74: =F74/V74*60 -> 2883.4123 | N74: =M74/L74 -> 137.30535 | O74: =L74-I74 -> 0 | P74: =N74-K74 -> -34.123223 | Q74: =N74/K74 -> 0.80094787 | S74: 0.23125 | T74: 0.23613426 | U74: 8 | V74: 7.0333333 | AA74: =M74-J74 -> -716.58768 | AB74: =M74/J74 -> 0.80094787
B75: 季節調理麵 | C75: 酸辣麻醬細冷麵 | E75: 32.06 | F75: 3848 | G75: =E75*F75 -> 123366.88 | I75: 21 | J75: 3600 | K75: =J75/I75 -> 171.42857 | L75: 21 | M75: =F75/V75*60 -> 2990.6736 | N75: =M75/L75 -> 142.41303 | O75: =L75-I75 -> 0 | P75: =N75-K75 -> -29.015544 | Q75: =N75/K75 -> 0.83074266 | S75: 0.24097222 | T75: 0.29458333 | U75: 6.9666667 | V75: 77.2 | AA75: =M75-J75 -> -609.32642 | AB75: =M75/J75 -> 0.83074266
B76: 季節調理麵 | C76: 和風涓絲冷麵 | E76: 28.29 | F76: 3666 | G76: =E76*F76 -> 103711.14 | I76: 19 | J76: 3600 | K76: =J76/I76 -> 189.47368 | L76: 19 | M76: =F76/V76*60 -> 2993.3318 | N76: =M76/L76 -> 157.54378 | O76: =L76-I76 -> 0 | P76: =N76-K76 -> -31.929904 | Q76: =N76/K76 -> 0.83148106 | S76: 0.3 | T76: 0.35103009 | U76: 7.8 | V76: 73.483333 | AA76: =M76-J76 -> -606.66818 | AB76: =M76/J76 -> 0.83148106
B77: 季節調理麵 | C77: 芝麻鰹魚烏龍冷麵 | E77: 38.99 | F77: 2169 | G77: =E77*F77 -> 84569.31 | I77: 19 | J77: 3600 | K77: =J77/I77 -> 189.47368 | L77: 19 | M77: =F77/V77*60 -> 2968.9734 | N77: =M77/L77 -> 156.26176 | O77: =L77-I77 -> 0 | P77: =N77-K77 -> -33.211927 | Q77: =N77/K77 -> 0.82471483 | S77: 0.3556713 | T77: 0.38611111 | U77: 6.6833333 | V77: 43.833333 | AA77: =M77-J77 -> -631.02662 | AB77: =M77/J77 -> 0.82471483
B78: 季節調理麵 | C78: 台式麻醬涼麵 | E78: 31.27 | F78: 2953 | G78: =E78*F78 -> 92340.31 | I78: 19 | J78: 3600 | K78: =J78/I78 -> 189.47368 | L78: 19 | M78: =F78/V78*60 -> 2994.5915 | N78: =M78/L78 -> 157.61008 | O78: =L78-I78 -> 0 | P78: =N78-K78 -> -31.863603 | Q78: =N78/K78 -> 0.83183099 | S78: 0.39166667 | T78: 0.43275463 | U78: 8 | V78: 59.166667 | AA78: =M78-J78 -> -605.40845 | AB78: =M78/J78 -> 0.83183099
B79: 季節調理麵 | C79: 日式蕎麥沾麵 | E79: 36.86 | F79: 2972 | G79: =E79*F79 -> 109547.92 | I79: 21 | J79: 3600 | K79: =J79/I79 -> 171.42857 | L79: 21 | M79: =F79/V79*60 -> 3184.2857 | N79: =M79/L79 -> 151.63265 | O79: =L79-I79 -> 0 | P79: =N79-K79 -> -19.795918 | Q79: =N79/K79 -> 0.88452381 | S79: 0.43819444 | T79: 0.47708333 | U79: 7.8333333 | V79: 56 | W79: 0.47708333 | X79: 0.51805556 | AA79: =M79-J79 -> -415.71429 | AB79: =M79/J79 -> 0.88452381
B80: 季節調理麵 | C80: 日式擔擔冷麵 | E80: 43.61 | F80: 1253 | G80: =E80*F80 -> 54643.33 | I80: 22 | J80: 3600 | K80: =J80/I80 -> 163.63636 | L80: 22 | M80: =F80/V80*60 -> 3132.5 | N80: =M80/L80 -> 142.38636 | O80: =L80-I80 -> 0 | P80: =N80-K80 -> -21.25 | Q80: =N80/K80 -> 0.87013889 | S80: 0.51805556 | T80: 0.53472222 | U80: 59 | V80: 24 | AA80: =M80-J80 -> -467.5 | AB80: =M80/J80 -> 0.87013889
B81: 季節調理麵 | C81: 大滿足麻醬涼麵 | E81: 38 | F81: 1767 | G81: =E81*F81 -> 67146 | H81: 2 | I81: 21 | J81: 3600 | K81: =J81/I81 -> 171.42857 | L81: 21 | M81: =F81/V81*60 -> 3153.7928 | N81: =M81/L81 -> 150.18061 | O81: =L81-I81 -> 0 | P81: =N81-K81 -> -21.247964 | Q81: =N81/K81 -> 0.87605354 | S81: 0.53915509 | T81: 0.5625 | U81: 6.3833333 | V81: 33.616667 | AA81: =M81-J81 -> -446.20724 | AB81: =M81/J81 -> 0.87605354
B82: 季節調理麵 | C82: 大滿足香辣涼麵 | E82: 38.63 | F82: 4285 | G82: =E82*F82 -> 165529.55 | I82: 20 | J82: 3600 | K82: =J82/I82 -> 180 | L82: 20 | M82: =F82/V82*60 -> 3174.0741 | N82: =M82/L82 -> 158.7037 | O82: =L82-I82 -> 0 | P82: =N82-K82 -> -21.296296 | Q82: =N82/K82 -> 0.88168724 | S82: 0.56666667 | T82: 0.62291667 | U82: 6 | V82: 81 | AA82: =M82-J82 -> -425.92593 | AB82: =M82/J82 -> 0.88168724
...

Sheet 0730
B1: 屏榮 大溪廠組合室生產人時性分析
B3: 日期 | C3: 114.07.30星期三 | E3: 訂單量 | F3: ='0730(18度C)'!D1+'0730(4度C)'!D1 -> 238326 | H3: 營業額 | I3: ='0730(18度C)'!F1+'0730(4度C)'!F1 -> 7772637.8
B4: 人時性 | C4: 項目 | E4: ➀ | G4: ➁ | I4: ➂ | K4: ④ | M4: ⑤
C5: 組合室 | E5: 全溫層 | G5: 4度C-各編組展開(一配) | I5: 4度C-各編組展開(二配) | K5: 18度C-各編組展開(一配) | M5: 18度C-各編組展開(二配)
C6: 排關平均 | E6: =AVERAGE(D13:O13,D27:X27) -> 499.78255 | F6: =AVERAGE(#REF!,D13:K13) -> #REF! | G6: =AVERAGE(D13:K13) -> 175.27087 | I6: =AVERAGE(L13:O13) -> 89.572193 | K6: =AVERAGE(D27:O27) -> 688.59363 | M6: =AVERAGE(P27:X27) -> 763.36818
C7: 實績平均 | E7: =AVERAGE(D14:O14,D28:X28) -> 421.08299 | F7: =AVERAGE(#REF!,D14:K14) -> #REF! | G7: =AVERAGE(D14:K14) -> 147.65526 | I7: =AVERAGE(L14:O14) -> 76.507808 | K7: =AVERAGE(D28:O28) -> 580.0661 | M7: =AVERAGE(P28:X28) -> 642.96292
C8: 達成率平均 | E8: =AVERAGE(D15:O15,D29:X29) -> 0.84551512 | F8: =AVERAGE(D15:K15,#REF!) -> #REF! | G8: =AVERAGE(D15:K15) -> 0.84495769 | I8: =AVERAGE(L15:O15) -> 0.85413741 | K8: =AVERAGE(D29:O29) -> 0.84405679 | M8: =AVERAGE(P29:X29) -> 0.84523579 | O8: ※現行日本鮮食廠以達成率80%為基本(即為現行KPI)
B10: 溫層 | D10: ➁4度C-各編組展開 | L10: ➂4度C-各編組展開
B11: 編組 | D11: 1 | E11: 2 | F11: 3 | G11: 4 | H11: 5 | I11: 6 | J11: 7 | K11: 8 | L11: 1 | M11: 2 | N11: 3 | O11: 4
D12: 便當一線 | E12: 便當二線 | F12: 涼麵一線 | G12: 涼麵二線 | H12: 涼麵三線 | I12: 自動包裝機 | J12: 自動包裝機2 | K12: 自動包裝機3 | L12: 便當一線 | M12: 便當二線 | N12: 涼麵一線 | O12: 涼麵二線
B13: 人時性 | C13: 排關 | D13: 113.26531 | E13: 78.431373 | F13: 89.090909 | G13: 89.74359 | H13: 172.11155 | I13: 250.92 | J13: - | K13: 433.33333 | L13: - | M13: - | N13: 90.909091 | O13: 88.235294
C14: 實績 | D14: 96.870717 | E14: 65.398037 | F14: 75.53284 | G14: 75.69987 | H14: 146.68198 | I14: 213.87484 | J14: - | K14: 359.52857 | L14: - | M14: - | N14: 77.70652 | O14: 75.309096
C15: 達成率 | D15: =D14/D13 -> 0.85525498 | E15: =E14/E13 -> 0.83382497 | F15: =F14/F13 -> 0.84781759 | G15: =G14/G13 -> 0.84351284 | H15: =H14/H13 -> 0.85224947 | I15: =I14/I13 -> 0.85236268 | J15: - | K15: =K14/K13 -> 0.82968131 | L15: - | M15: - | N15: =N14/N13 -> 0.85477172 | O15: =O14/O13 -> 0.85350309
B16: 作業 時間 | C16: 開始 | D16: 0.25010417 | E16: 0.16695602 | F16: 0.25 | G16: 0.16699074 | H16: 0.16666667 | I16: 0.2502662 | J16: - | K16: 0.33417824 | L16: - | M16: - | N16: 0.70844907 | O16: 0.70833333
C17: 結束 | D17: 0.61327546 | E17: 0.66075231 | F17: 0.65347222 | G17: 0.58335648 | H17: 0.71144676 | I17: 0.53902778 | J17: - | K17: 0.44733796 | L17: - | M17: - | N17: 0.85081019 | O17: 0.84616898
B18: 配置人數 | D18: 16.333333 | E18: 25.5 | F18: 22 | G18: 22.285714 | H18: 20.916667 | I18: 12.5 | J18: - | K18: 6 | L18: - | M18: - | N18: 22 | O18: 22.666667
B19: 主要應用設備 | D19: L型封口機 | E19: ET-55 | F19: ET-55 | G19: ET-55 | H19: ET-600 | I19: 伺服包裝機 | J19: 伺服包裝機 | K19: 伺服包裝機 | L19: L型封口機 | M19: ET-55 | N19: ET-55 | O19: ET-55
B20: 次要應用設備 | D20: 伺服包裝機 | H20: 伺服包裝機
B21: 備註 | H21: 涼麵+烤飯糰 | I21: 大口飯糰線 | K21: 烤飯糰+手卷
B24: 溫層 | D24: ➃18度C-各編組展開 (一配) | P24: ⑤18度C-各編組展開 (二配)
B25: 編組 | D25: 1 | E25: 2 | F25: 3 | G25: 4 | H25: 5 | I25: 6 | J25: 7 | K25: 8 | L25: 9 | M25: 10 | N25: 11 | O25: 12 | P25: 1 | Q25: 2 | R25: 3 | S25: 4 | T25: 5 | U25: 6 | V25: 7 | W25: 8 | X25: 9
D26: 便當一線 | E26: 涼麵一線 | F26: 涼麵三線 | G26: 自動包裝機 | H26: 自動包裝機2 | I26: 自動包裝機3 | J26: 味付飯糰線B | K26: (舊) 3300型飯糰線 | L26: 3000型飯糰線 | M26: (新) 3300型飯糰機 | N26: GKK3600型 飯糰機 | O26: GKK3600型 飯糰機2 | P26: 自動包裝機 | Q26: 自動包裝機2 | R26: 自動包裝機3 | S26: 味付飯糰線B | T26: (舊) 3300型飯糰線 | U26: 3000型飯糰線 | V26: (新) 3300型飯糰機 | W26: GKK3600型 飯糰機 | X26: GKK3600型 飯糰機2
B27: 人時性 | C27: 排關 | D27: 226.15 | E27: - | F27: - | G27: 272.72727 | H27: 433.33333 | I27: - | J27: 675 | K27: 1100 | L27: - | M27: 761.53846 | N27: 1200 | O27: 840 | P27: 226.65517 | Q27: - | R27: - | S27: 675 | T27: 768.75 | U27: - | V27: 776.47059 | W27: 1200 | X27: 933.33333
C28: 實績 | D28: 192.91093 | E28: - | F28: - | G28: 232.76841 | H28: 355.96724 | I28: - | J28: 589.36096 | K28: 934.73684 | L28: - | M28: 639.92063 | N28: 997.91353 | O28: 696.9503 | P28: 192.05591 | Q28: - | R28: - | S28: 599.12568 | T28: 642.12055 | U28: - | V28: 653.47415 | W28: 999.19216 | X28: 771.80906
C29: 達成率 | D29: =D28/D27 -> 0.853022 | E29: - | F29: - | G29: =G28/G27 -> 0.85348419 | H29: =H28/H27 -> 0.82146287 | I29: - | J29: =J28/J27 -> 0.87312734 | K29: =K28/K27 -> 0.84976077 | L29: - | M29: =M28/M27 -> 0.84029981 | N29: =N28/N27 -> 0.83159461 | O29: =O28/O27 -> 0.82970274 | P29: =P28/P27 -> 0.84734846 | Q29: - | R29: - | S29: =S28/S27 -> 0.88759359 | T29: =T28/T27 -> 0.83527876 | U29: - | V29: =V28/V27 -> 0.84159549 | W29: =W28/W27 -> 0.83266013 | X29: =X28/X27 -> 0.82693828
B30: 作業 時間 | C30: 開始 | D30: 0.39166667 | E30: - | F30: - | G30: 0.31681713 | H30: 0.25 | I30: - | J30: 0.25 | K30: 0.35277778 | L30: - | M30: 0.25023148 | N30: 0.25033565 | O30: 0.25016204 | P30: 0.70833333 | Q30: - | R30: - | S30: 0.70833333 | T30: 0.70833333 | U30: - | V30: 0.70856481 | W30: 0.70856481 | X30: 0.70849537
C31: 結束 | D31: 0.50277778 | E31: - | F31: - | G31: 0.3618287 | H31: 0.31461806 | I31: - | J31: 0.34888889 | K31: 0.3890625 | L31: - | M31: 0.4125463 | N31: 0.46875 | O31: 0.45981481 | P31: 0.85788194 | Q31: - | R31: - | S31: 0.87115741 | T31: 0.87361111 | U31: - | V31: 0.95417824 | W31: 0.96527778 | X31: 0.97868056
B32: 配置人數 | D32: 13.333333 | E32: - | F32: - | G32: 11 | H32: 6 | I32: - | J32: 4 | K32: 3 | L32: - | M32: 4.3333333 | N32: 3 | O32: 3.75 | P32: 14.5 | Q32: - | R32: - | S32: 4 | T32: 4 | U32: - | V32: 4.25 | W32: 3 | X32: 3.6
B33: 主要應用設備 | D33: 伺服包裝機 | E33: ET-55 | F33: ET-600 | G33: 夾心型 | H33: 伺服包裝機 | I33: 伺服包裝機 | J33: 夾心型 | K33: 3300型 | L33: 3300型 | M33: 3300型 | N33: GKK | O33: GKK | P33: 夾心型 | Q33: 伺服包裝機 | R33: 伺服包裝機 | S33: 夾心型 | T33: 3300型 | U33: 3300型 | V33: 3300型 | W33: GKK | X33: GKK
B34: 次要應用設備
B35: 備註

Sheet 0730(18度C)
A1: 大溪廠日報分析 | C1: 總生產量 | D1: =SUM(F5:F242) -> 122220 | E1: 營業額 | F1: =SUM(G5:G242) -> 2417453 | G1: 出勤人數 | H1: =L21+L38+L55+L72+L89+L106+L123+L140+L157+L174+L191+L208+L225+L242 -> 81.766667 | I1: 產線配置圖 | L1: 生產實績 | O1: 人時性差異分析 | S1: 日報登錄 | Y1: 分析說明 | AA1: 產能差異分析
A2: 45868 | C2: 人時性 | D2: =AVERAGE(N21,N38,N55,N72,N89,N106,N123,N140,N157,N174,N191,N208,N225,N242) -> 607.02188 | E2: 平均廠價 | F2: =F1/D1 -> 19.779521 | G2: 多次生產數 | H2: =COUNT(H5:H242) -> 3
A3: 線別 | B3: 品類 | C3: 品名 | E3: 廠價 | F3: 生產量 | G3: 營收 | H3: 多次 生產 | I3: 人數 | J3: 產能/時 | K3: 人時性 | L3: 人數 | M3: 產能/時 | N3: 人時性 | O3: 人數 | P3: 人時性 | Q3: 達成率 | R3: 達成率 平均 | S3: 生產時間 | U3: 換線、休息/分 | V3: 稼動時間/分 | W3: 休息時間 | Y3: (屏榮回填) | AA3: 產能/時 | AB3: 達成率 | AC3: 達成率平均
S4: 開始 | T4: 結束 | W4: 開始 | X4: 結束
A5: 便當一線 | B5: 壽司手卷 | C5: 一配海饌雙手卷 | E5: 29.85 | F5: 2161 | G5: =E5*F5 -> 64505.85 | I5: 17 | J5: 3273 | K5: =J5/I5 -> 192.52941 | L5: 17 | M5: =F5/V5*60 -> 2791.3886 | N5: =M5/L5 -> 164.19933 | O5: =L5-I5 -> 0 | P5: =N5-K5 -> -28.330083 | Q5: =N5/K5 -> 0.85285322 | R5: =Q21 -> 0.853022 | S5: 0.39166667 | T5: 0.42392361 | U5: 4 | V5: 46.45 | AA5: =M5-J5 -> -481.61141 | AB5: =M5/J5 -> 0.85285322 | AC5: =AB21 -> 0.853022
B6: 壽司手卷 | C6: 一配雙饗雙手卷 | E6: 29.52 | F6: 2231 | G6: =E6*F6 -> 65859.12 | I6: 17 | J6: 3273 | K6: =J6/I6 -> 192.52941 | L6: 17 | M6: =F6/V6*60 -> 2792.6287 | N6: =M6/L6 -> 164.27227 | O6: =L6-I6 -> 0 | P6: =N6-K6 -> -28.257138 | Q6: =N6/K6 -> 0.8532321 | S6: 0.42712963 | T6: 0.46041667 | U6: 4.6166667 | V6: 47.933333 | AA6: =M6-J6 -> -480.37135 | AB6: =M6/J6 -> 0.8532321
B7: 壽司手卷 | C7: 一配日式厚蛋脆卷 | E7: 21.61 | F7: 1902 | G7: =E7*F7 -> 41102.22 | I7: 6 | J7: 2500 | K7: =J7/I7 -> 416.66667 | L7: 6 | M7: =F7/V7*60 -> 2132.4198 | N7: =M7/L7 -> 355.4033 | O7: =L7-I7 -> 0 | P7: =N7-K7 -> -61.263366 | Q7: =N7/K7 -> 0.85296792 | S7: 0.46561343 | T7: 0.50277778 | U7: 7.4833333 | V7: 53.516667 | W7: 0.50277778 | X7: 0.54027778 | AA7: =M7-J7 -> -367.58019 | AB7: =M7/J7 -> 0.85296792
B21: 平均 | I21: =AVERAGE(I5:I20) -> 13.333333 | J21: =AVERAGE(J5:J20) -> 3015.3333 | K21: =J21/I21 -> 226.15 | L21: =AVERAGE(L5:L20) -> 13.333333 | M21: =AVERAGE(M5:M20) -> 2572.1457 | N21: =M21/L21 -> 192.91093 | O21: =L21-I21 -> 0 | P21: =N21-K21 -> -33.239074 | Q21: =N21/K21 -> 0.853022 | S21: =S5 -> 0.39166667 | T21: =INDEX(T5:T20,COUNTA(T5:T20)) -> 0.50277778 | AA21: =M21-J21 -> -443.18765 | AB21: =M21/J21 -> 0.853022
A22: 自動包裝機 | B22: 壽司手卷 | C22: 一配長野稻荷壽司 | E22: 25.64 | F22: 2766 | G22: =E22*F22 -> 70920.24 | I22: 11 | J22: 3000 | K22: =J22/I22 -> 272.72727 | L22: 11 | M22: =F22/V22*60 -> 2560.4526 | N22: =M22/L22 -> 232.76841 | O22: =L22-I22 -> 0 | P22: =N22-K22 -> -39.958858 | Q22: =N22/K22 -> 0.85348419 | R22: =Q38 -> 0.85348419 | S22: 0.31681713 | T22: 0.3618287 | U22: 4.75 | V22: 64.816667 | AA22: =M22-J22 -> -439.54744 | AB22: =M22/J22 -> 0.85348419 | AC22: =AB38 -> 0.85348419
B38: 平均 | I38: =AVERAGE(I22:I37) -> 11 | J38: =AVERAGE(J22:J37) -> 3000 | K38: =J38/I38 -> 272.72727 | L38: =AVERAGE(L22:L37) -> 11 | M38: =AVERAGE(M22:M37) -> 2560.4526 | N38: =M38/L38 -> 232.76841 | O38: =L38-I38 -> 0 | P38: =N38-K38 -> -39.958858 | Q38: =N38/K38 -> 0.85348419 | S38: =S22 -> 0.31681713 | T38: =INDEX(T22:T37,COUNTA(T22:T37)) -> 0.3618287 | AA38: =M38-J38 -> -439.54744 | AB38: =M38/J38 -> 0.85348419
A39: 自動包裝機2 | B39: 壽司手卷 | C39: 一配芝麻海苔香鬆細卷 | E39: 14.06 | F39: 1049 | G39: =E39*F39 -> 14748.94 | I39: 6 | J39: 2600 | K39: =J39/I39 -> 433.33333 | L39: 6 | M39: =F39/V39*60 -> 2149.3455 | N39: =M39/L39 -> 358.22425 | O39: =L39-I39 -> 0 | P39: =N39-K39 -> -75.109087 | Q39: =N39/K39 -> 0.82667134 | R39: =Q55 -> 0.82146287 | S39: 0.25 | T39: 0.27033565 | V39: 29.283333 | AA39: =M39-J39 -> -450.65452 | AB39: =M39/J39 -> 0.82667134 | AC39: =AB55 -> 0.82146287
B40: 壽司手卷 | C40: 一配鮪魚沙拉細卷 | E40: 14.81 | F40: 1239 | G40: =E40*F40 -> 18349.59 | I40: 6 | J40: 2600 | K40: =J40/I40 -> 433.33333 | L40: 6 | M40: =F40/V40*60 -> 2166.2943 | N40: =M40/L40 -> 361.04905 | O40: =L40-I40 -> 0 | P40: =N40-K40 -> -72.28428 | Q40: =N40/K40 -> 0.83319012 | S40: 0.27361111 | T40: 0.29744213 | U40: 4.7166667 | V40: 34.316667 | AA40: =M40-J40 -> -433.70568 | AB40: =M40/J40 -> 0.83319012
B41: 壽司手卷 | C41: 一配炙烤焦糖鮭魚細卷 | E41: 17.87 | F41: 699 | G41: =E41*F41 -> 12491.13 | I41: 6 | J41: 2600 | K41: =J41/I41 -> 433.33333 | L41: 6 | M41: =F41/V41*60 -> 2091.7706 | N41: =M41/L41 -> 348.62843 | O41: =L41-I41 -> 0 | P41: =N41-K41 -> -84.704904 | Q41: =N41/K41 -> 0.80452714 | S41: 0.30069444 | T41: 0.31461806 | U41: 4.6833333 | V41: 20.05 | AA41: =M41-J41 -> -508.22943 | AB41: =M41/J41 -> 0.80452714
B55: 平均 | I55: =AVERAGE(I39:I54) -> 6 | J55: =AVERAGE(J39:J54) -> 2600 | K55: =J55/I55 -> 433.33333 | L55: =AVERAGE(L39:L54) -> 6 | M55: =AVERAGE(M39:M54) -> 2135.8035 | N55: =M55/L55 -> 355.96724 | O55: =L55-I55 -> 0 | P55: =N55-K55 -> -77.366091 | Q55: =N55/K55 -> 0.82146287 | S55: =S39 -> 0.25 | T55: =INDEX(T39:T54,COUNTA(T39:T54)) -> 0.31461806 | AA55: =M55-J55 -> -464.19654 | AB55: =M55/J55 -> 0.82146287
A56: 味付飯糰線B | B56: 飯糰 | C56: 一配經典肉鬆飯糰 | E56: 14.03 | F56: 5595 | G56: =E56*F56 -> 78497.85 | I56: 4 | J56: 2700 | K56: =J56/I56 -> 675 | L56: 4 | M56: =F56/V56*60 -> 2357.4438 | N56: =M56/L56 -> 589.36096 | O56: =L56-I56 -> 0 | P56: =N56-K56 -> -85.639045 | Q56: =N56/K56 -> 0.87312734 | R56: =Q72 -> 0.87312734 | S56: 0.25 | T56: 0.34888889 | V56: 142.4 | AA56: =M56-J56 -> -342.55618 | AB56: =M56/J56 -> 0.87312734 | AC56: =AB72 -> 0.87312734
B72: 平均 | I72: =AVERAGE(I56:I71) -> 4 | J72: =AVERAGE(J56:J71) -> 2700 | K72: =J72/I72 -> 675 | L72: =AVERAGE(L56:L71) -> 4 | M72: =AVERAGE(M56:M71) -> 2357.4438 | N72: =M72/L72 -> 589.36096 | O72: =L72-I72 -> 0 | P72: =N72-K72 -> -85.639045 | Q72: =N72/K72 -> 0.87312734 | S72: =S56 -> 0.25 | T72: =INDEX(T56:T71,COUNTA(T56:T71)) -> 0.34888889 | AA72: =M72-J72 -> -342.55618 | AB72: =M72/J72 -> 0.87312734
A73: (舊) 3300型飯糰線 | B73: 飯糰 | C73: 一配三杯辣海瓜子飯糰 | E73: 21.45 | F73: 2442 | G73: =E73*F73 -> 52380.9 | I73: 3 | J73: 3300 | K73: =J73/I73 -> 1100 | L73: 3 | M73: =F73/V73*60 -> 2804.2105 | N73: =M73/L73 -> 934.73684 | O73: =L73-I73 -> 0 | P73: =N73-K73 -> -165.26316 | Q73: =N73/K73 -> 0.84976077 | R73: =Q89 -> 0.84976077 | S73: 0.35277778 | T73: 0.3890625 | V73: 52.25 | AA73: =M73-J73 -> -495.78947 | AB73: =M73/J73 -> 0.84976077 | AC73: =AB89 -> 0.84976077
B89: 平均 | I89: =AVERAGE(I73:I88) -> 3 | J89: =AVERAGE(J73:J88) -> 3300 | K89: =J89/I89 -> 1100 | L89: =AVERAGE(L73:L88) -> 3 | M89: =AVERAGE(M73:M88) -> 2804.2105 | N89: =M89/L89 -> 934.73684 | O89: =L89-I89 -> 0 | P89: =N89-K89 -> -165.26316 | Q89: =N89/K89 -> 0.84976077 | S89: =S73 -> 0.35277778 | T89: =INDEX(T73:T88,COUNTA(T73:T88)) -> 0.3890625 | AA89: =M89-J89 -> -495.78947 | AB89: =M89/J89 -> 0.84976077
A90: (新) 3300型飯糰機 | B90: 飯糰 | C90: 一配壹號醬炙烤牛飯糰 | E90: 22.28 | F90: 1487 | G90: =E90*F90 -> 33130.36 | I90: 5 | J90: 3300 | K90: =J90/I90 -> 660 | L90: 5 | M90: =F90/V90*60 -> 2731.2245 | N90: =M90/L90 -> 546.2449 | O90: =L90-I90 -> 0 | P90: =N90-K90 -> -113.7551 | Q90: =N90/K90 -> 0.82764378 | R90: =Q106 -> 0.84029981 | S90: 0.25023148 | T90: 0.27291667 | V90: 32.666667 | AA90: =M90-J90 -> -568.77551 | AB90: =M90/J90 -> 0.82764378 | AC90: =AB106 -> 0.84029981
B91: 飯糰 | C91: 一配鹽蔥燒肉飯糰 | E91: 17.89 | F91: 3280 | G91: =E91*F91 -> 58679.2 | I91: 4 | J91: 3300 | K91: =J91/I91 -> 825 | L91: 4 | M91: =F91/V91*60 -> 2769.8804 | N91: =M91/L91 -> 692.47009 | O91: =L91-I91 -> 0 | P91: =N91-K91 -> -132.52991 | Q91: =N91/K91 -> 0.83935769 | S91: 0.27777778 | T91: 0.32711806 | U91: 7 | V91: 71.05 | AA91: =M91-J91 -> -530.11963 | AB91: =M91/J91 -> 0.83935769
B92: 飯糰 | C92: 一配雞肉飯飯糰 | E92: 16.66 | F92: 5451 | G92: =E92*F92 -> 90813.66 | I92: 4 | J92: 3300 | K92: =J92/I92 -> 825 | L92: 4 | M92: =F92/V92*60 -> 2817.8633 | N92: =M92/L92 -> 704.46582 | O92: =L92-I92 -> 0 | P92: =N92-K92 -> -120.53418 | Q92: =N92/K92 -> 0.85389797 | S92: 0.33194444 | T92: 0.4125463 | U92: 6.95 | V92: 116.06667 | AA92: =M92-J92 -> -482.1367 | AB92: =M92/J92 -> 0.85389797
B106: 平均 | I106: =AVERAGE(I90:I105) -> 4.3333333 | J106: =AVERAGE(J90:J105) -> 3300 | K106: =J106/I106 -> 761.53846 | L106: =AVERAGE(L90:L105) -> 4.3333333 | M106: =AVERAGE(M90:M105) -> 2772.9894 | N106: =M106/L106 -> 639.92063 | O106: =L106-I106 -> 0 | P106: =N106-K106 -> -121.61783 | Q106: =N106/K106 -> 0.84029981 | S106: =S90 -> 0.25023148 | T106: =INDEX(T90:T105,COUNTA(T90:T105)) -> 0.4125463 | AA106: =M106-J106 -> -527.01062 | AB106: =M106/J106 -> 0.84029981
A107: GKK3600型 飯糰機 | B107: 飯糰 | C107: 一配明太子龍蝦風味沙拉飯糰 | E107: 18.18 | F107: 2969 | G107: =E107*F107 -> 53976.42 | I107: 3 | J107: 3600 | K107: =J107/I107 -> 1200 | L107: 3 | M107: =F107/V107*60 -> 2991.4358 | N107: =M107/L107 -> 997.14526 | O107: =L107-I107 -> 0 | P107: =N107-K107 -> -202.85474 | Q107: =N107/K107 -> 0.83095438 | R107: =Q123 -> 0.83159461 | S107: 0.25033565 | T107: 0.29168981 | V107: 59.55 | AA107: =M107-J107 -> -608.56423 | AB107: =M107/J107 -> 0.83095438 | AC107: =AB123 -> 0.83159461
B108: 飯糰 | C108: 一配蔬食鮪魚飯糰 | E108: 18.18 | F108: 3953 | G108: =E108*F108 -> 71865.54 | I108: 3 | J108: 3600 | K108: =J108/I108 -> 1200 | L108: 3 | M108: =F108/V108*60 -> 2992.8076 | N108: =M108/L108 -> 997.60252 | O108: =L108-I108 -> 0 | P108: =N108-K108 -> -202.39748 | Q108: =N108/K108 -> 0.83133544 | S108: 0.30277778 | T108: 0.3578125 | U108: 15.966667 | V108: 79.25 | AA108: =M108-J108 -> -607.19243 | AB108: =M108/J108 -> 0.83133544
B109: 飯糰 | C109: 鮪魚飯糰 | E109: 14.28 | F109: 6943 | G109: =E109*F109 -> 99146.04 | I109: 3 | J109: 3600 | K109: =J109/I109 -> 1200 | L109: 3 | M109: =F109/V109*60 -> 2996.9784 | N109: =M109/L109 -> 998.99281 | O109: =L109-I109 -> 0 | P109: =N109-K109 -> -201.00719 | Q109: =N109/K109 -> 0.832494 | S109: 0.37222222 | T109: 0.46875 | U109: 20.75 | V109: 139 | AA109: =M109-J109 -> -603.02158 | AB109: =M109/J109 -> 0.832494
B123: 平均 | I123: =AVERAGE(I107:I122) -> 3 | J123: =AVERAGE(J107:J122) -> 3600 | K123: =J123/I123 -> 1200 | L123: =AVERAGE(L107:L122) -> 3 | M123: =AVERAGE(M107:M122) -> 2993.7406 | N123: =M123/L123 -> 997.91353 | O123: =L123-I123 -> 0 | P123: =N123-K123 -> -202.08647 | Q123: =N123/K123 -> 0.83159461 | S123: =S107 -> 0.25033565 | T123: =INDEX(T107:T122,COUNTA(T107:T122)) -> 0.46875 | AA123: =M123-J123 -> -606.25941 | AB123: =M123/J123 -> 0.83159461
A124: GKK3600型 飯糰機2 | B124: 飯糰 | C124: 一配北海道秋鮭親子飯糰 | E124: 24.83 | F124: 2407 | G124: =E124*F124 -> 59765.81 | I124: 4 | J124: 3300 | K124: =J124/I124 -> 825 | L124: 4 | M124: =F124/V124*60 -> 2736.9551 | N124: =M124/L124 -> 684.23879 | O124: =L124-I124 -> 0 | P124: =N124-K124 -> -140.76121 | Q124: =N124/K124 -> 0.82938035 | R124: =Q140 -> 0.82970274 | S124: 0.25016204 | T124: 0.28680556 | V124: 52.766667 | AA124: =M124-J124 -> -563.04485 | AB124: =M124/J124 -> 0.82938035 | AC124: =AB140 -> 0.82970274
B125: 飯糰 | C125: 一配熟成紅鮭飯糰 | E125: 25.03 | F125: 2033 | G125: =E125*F125 -> 50885.99 | I125: 4 | J125: 3300 | K125: =J125/I125 -> 825 | L125: 4 | M125: =F125/V125*60 -> 2730.8955 | N125: =M125/L125 -> 682.72388 | O125: =L125-I125 -> 0 | P125: =N125-K125 -> -142.27612 | Q125: =N125/K125 -> 0.8275441 | S125: 0.29884259 | T125: 0.32986111 | U125: 17.333333 | V125: 44.666667 | AA125: =M125-J125 -> -569.10448 | AB125: =M125/J125 -> 0.8275441
B126: 飯糰 | C126: 一配贅沢鮭魚肚飯糰 | E126: 30 | F126: 4107 | G126: =E126*F126 -> 123210 | I126: 3 | J126: 3000 | K126: =J126/I126 -> 1000 | L126: 3 | M126: =F126/V126*60 -> 2493.2884 | N126: =M126/L126 -> 831.09612 | O126: =L126-I126 -> 0 | P126: =N126-K126 -> -168.90388 | Q126: =N126/K126 -> 0.83109612 | S126: 0.34108796 | T126: 0.40972222 | U126: 16.166667 | V126: 98.833333 | AA126: =M126-J126 -> -506.71164 | AB126: =M126/J126 -> 0.83109612
B127: 飯糰 | C127: 一配海老天婦羅飯糰 | E127: 27.91 | F127: 2374 | G127: =E127*F127 -> 66258.34 | I127: 4 | J127: 3000 | K127: =J127/I127 -> 750 | L127: 4 | M127: =F127/V127*60 -> 2493.1155 | N127: =M127/L127 -> 623.27888 | O127: =L127-I127 -> 0 | P127: =N127-K127 -> -126.72112 | Q127: =N127/K127 -> 0.83103851 | S127: 0.42013889 | T127: 0.45981481 | U127: 15 | V127: 57.133333 | AA127: =M127-J127 -> -506.88448 | AB127: =M127/J127 -> 0.83103851
B140: 平均 | I140: =AVERAGE(I124:I139) -> 3.75 | J140: =AVERAGE(J124:J139) -> 3150 | K140: =J140/I140 -> 840 | L140: =AVERAGE(L124:L139) -> 3.75 | M140: =AVERAGE(M124:M139) -> 2613.5636 | N140: =M140/L140 -> 696.9503 | O140: =L140-I140 -> 0 | P140: =N140-K140 -> -143.0497 | Q140: =N140/K140 -> 0.82970274 | S140: =S124 -> 0.25016204 | T140: =INDEX(T124:T139,COUNTA(T124:T139)) -> 0.45981481 | AA140: =M140-J140 -> -536.43636 | AB140: =M140/J140 -> 0.82970274
A141: 自動包裝機 (二配) | B141: 壽司 | C141: 二配長野稻荷壽司 | E141: 25.64 | F141: 2620 | G141: =E141*F141 -> 67176.8 | I141: 11 | J141: 3000 | K141: =J141/I141 -> 272.72727 | L141: 11 | M141: =F141/V141*60 -> 2559.5658 | N141: =M141/L141 -> 232.6878 | O141: =L141-I141 -> 0 | P141: =N141-K141 -> -40.039472 | Q141: =N141/K141 -> 0.8531886 | R141: =Q157 -> 0.84734846 | S141: 0.70833333 | T141: 0.7509838 | V141: 61.416667 | AA141: =M141-J141 -> -440.43419 | AB141: =M141/J141 -> 0.8531886 | AC141: =AB157 -> 0.84734846
B142: 壽司 | C142: 二配雙饗雙手卷 | E142: 29.52 | F142: 2196 | G142: =E142*F142 -> 64825.92 | I142: 17 | J142: 3273 | K142: =J142/I142 -> 192.52941 | L142: 17 | M142: =F142/V142*60 -> 2790.5401 | N142: =M142/L142 -> 164.14942 | O142: =L142-I142 -> 0 | P142: =N142-K142 -> -28.379996 | Q142: =N142/K142 -> 0.85259397 | S142: 0.75416667 | T142: 0.78695602 | U142: 4.5833333 | V142: 47.216667 | AA142: =M142-J142 -> -482.45994 | AB142: =M142/J142 -> 0.85259397
B143: 壽司 | C143: 二配海饌雙手卷 | E143: 29.85 | F143: 2273 | G143: =E143*F143 -> 67849.05 | I143: 17 | J143: 3273 | K143: =J143/I143 -> 192.52941 | L143: 17 | M143: =F143/V143*60 -> 2792.7645 | N143: =M143/L143 -> 164.28027 | O143: =L143-I143 -> 0 | P143: =N143-K143 -> -28.249147 | Q143: =N143/K143 -> 0.8532736 | S143: 0.79178241 | T143: 0.82569444 | U143: 6.95 | V143: 48.833333 | AA143: =M143-J143 -> -480.23549 | AB143: =M143/J143 -> 0.8532736
B144: 飯糰 | C144: 二配兩粒飯糰(鮪魚&培根蛋沙拉) | E144: 28.57 | F144: 2065 | G144: =E144*F144 -> 58997.05 | I144: 13 | J144: 3600 | K144: =J144/I144 -> 276.92308 | L144: 13 | M144: =F144/V144*60 -> 2996.3724 | N144: =M144/L144 -> 230.49019 | O144: =L144-I144 -> 0 | P144: =N144-K144 -> -46.43289 | Q144: =N144/K144 -> 0.83232568 | S144: 0.82916667 | T144: 0.85788194 | U144: 5 | V144: 41.35 | AA144: =M144-J144 -> -603.62757 | AB144: =M144/J144 -> 0.83232568
B157: 平均 | I157: =AVERAGE(I141:I156) -> 14.5 | J157: =AVERAGE(J141:J156) -> 3286.5 | K157: =J157/I157 -> 226.65517 | L157: =AVERAGE(L141:L156) -> 14.5 | M157: =AVERAGE(M141:M156) -> 2784.8107 | N157: =M157/L157 -> 192.05591 | O157: =L157-I157 -> 0 | P157: =N157-K157 -> -34.599262 | Q157: =N157/K157 -> 0.84734846 | S157: =S141 -> 0.70833333 | T157: =INDEX(T141:T156,COUNTA(T141:T156)) -> 0.85788194 | AA157: =M157-J157 -> -501.6893 | AB157: =M157/J157 -> 0.84734846
A158: 味付飯糰線B (二配) | B158: 飯糰 | C158: 二配經典肉鬆飯糰 | E158: 14.03 | F158: 9365 | G158: =E158*F158 -> 131390.95 | I158: 4 | J158: 2700 | K158: =J158/I158 -> 675 | L158: 4 | M158: =F158/V158*60 -> 2396.5027 | N158: =M158/L158 -> 599.12568 | O158: =L158-I158 -> 0 | P158: =N158-K158 -> -75.874325 | Q158: =N158/K158 -> 0.88759359 | R158: =Q174 -> 0.88759359 | S158: 0.70833333 | T158: 0.87115741 | V158: 234.46667 | AA158: =M158-J158 -> -303.4973 | AB158: =M158/J158 -> 0.88759359 | AC158: =AB174 -> 0.88759359
B174: 平均 | I174: =AVERAGE(I158:I173) -> 4 | J174: =AVERAGE(J158:J173) -> 2700 | K174: =J174/I174 -> 675 | L174: =AVERAGE(L158:L173) -> 4 | M174: =AVERAGE(M158:M173) -> 2396.5027 | N174: =M174/L174 -> 599.12568 | O174: =L174-I174 -> 0 | P174: =N174-K174 -> -75.874325 | Q174: =N174/K174 -> 0.88759359 | S174: =S158 -> 0.70833333 | T174: =INDEX(T158:T173,COUNTA(T158:T173)) -> 0.87115741 | AA174: =M174-J174 -> -303.4973 | AB174: =M174/J174 -> 0.88759359
A175: (舊) 3300型飯糰線 (二配) | B175: 飯糰 | C175: 二配大飯糰椒香鮪魚 | E175: 24.15 | F175: 1133 | G175: =E175*F175 -> 27361.95 | I175: 4 | J175: 3000 | K175: =J175/I175 -> 750 | L175: 4 | M175: =F175/V175*60 -> 2482.532 | N175: =M175/L175 -> 620.63299 | O175: =L175-I175 -> 0 | P175: =N175-K175 -> -129.36701 | Q175: =N175/K175 -> 0.82751065 | R175: =Q191 -> 0.83527876 | S175: 0.70833333 | T175: 0.72734954 | V175: 27.383333 | AA175: =M175-J175 -> -517.46805 | AB175: =M175/J175 -> 0.82751065 | AC175: =AB191 -> 0.83527876
