Workbook

Sheet 1130
B1: 屏榮 大溪廠組合室生產人時性分析
B3: 日期 | C3: 114.11.30星期日 | E3: 訂單量 | F3: ='1130(18度C)'!D1+'1130(4度C)'!D1 -> 237755 | H3: 營業額 | I3: ='1130(18度C)'!F1+'1130(4度C)'!F1 -> 8105674
B4: 人時性 | C4: 項目 | E4: ➀ | G4: ➁ | I4: ➂ | K4: ④ | M4: ⑤
C5: 組合室 | E5: 全溫層 | G5: 4度C-各編組展開(一配) | I5: 4度C-各編組展開(二配) | K5: 18度C-各編組展開(一配) | M5: 18度C-各編組展開(二配)
C6: 排關平均 | E6: =AVERAGE(D13:O13,D27:X27) -> 454.74092 | F6: =AVERAGE(#REF!,D13:K13) -> #REF! | G6: =AVERAGE(D13:K13) -> 181.84724 | I6: =AVERAGE(L13:O13) -> 95.202399 | K6: =AVERAGE(D27:O27) -> 594.4684 | M6: =AVERAGE(P27:X27) -> 784.98901
C7: 實績平均 | E7: =AVERAGE(D14:O14,D28:X28) -> 401.34972 | F7: =AVERAGE(#REF!,D14:K14) -> #REF! | G7: =AVERAGE(D14:K14) -> 161.4328 | I7: =AVERAGE(L14:O14) -> 84.189588 | K7: =AVERAGE(D28:O28) -> 523.95256 | M7: =AVERAGE(P28:X28) -> 692.45348
C8: 達成率平均 | E8: =AVERAGE(D15:O15,D29:X29) -> 0.88306846 | F8: =AVERAGE(D15:K15,#REF!) -> #REF! | G8: =AVERAGE(D15:K15) -> 0.88642017 | I8: =AVERAGE(L15:O15) -> 0.88434298 | K8: =AVERAGE(D29:O29) -> 0.88050751 | M8: =AVERAGE(P29:X29) -> 0.88145158 | O8: ※現行日本鮮食廠以達成率80%為基本(即為現行KPI)
B10: 溫層 | D10: ➁4度C-各編組展開 | L10: ➂4度C-各編組展開
B11: 編組 | D11: 1 | E11: 2 | F11: 3 | G11: 4 | H11: 5 | I11: 6 | J11: 7 | K11: 8 | L11: 1 | M11: 2 | N11: 3 | O11: 4
D12: 便當一線 | E12: 便當二線 | F12: 涼麵一線 | G12: 涼麵二線 | H12: 涼麵三線 | I12: 自動包裝機 | J12: 自動包裝機2 | K12: 自動包裝機3 | L12: 便當一線 | M12: 便當二線 | N12: 涼麵一線 | O12: 涼麵二線
B13: 人時性 | C13: 排關 | D13: 120.75472 | E13: 81.300813 | F13: 90.076336 | G13: 92.307692 | H13: 136.36364 | I13: 232.33333 | J13: - | K13: 519.79412 | L13: - | M13: - | N13: 103.44828 | O13: 86.956522
C14: 實績 | D14: 107.27997 | E14: 72.143622 | F14: 79.709674 | G14: 81.605636 | H14: 121.12728 | I14: 204.37716 | J14: - | K14: 463.78628 | L14: - | M14: - | N14: 91.458858 | O14: 76.920318
C15: 達成率 | D15: =D14/D13 -> 0.88841225 | E15: =E14/E13 -> 0.88736655 | F15: =F14/F13 -> 0.88491248 | G15: =G14/G13 -> 0.88406106 | H15: =H14/H13 -> 0.8882667 | I15: =I14/I13 -> 0.87967215 | J15: - | K15: =K14/K13 -> 0.89224996 | L15: - | M15: - | N15: =N14/N13 -> 0.8841023 | O15: =O14/O13 -> 0.88458366
B16: 作業 時間 | C16: 開始 | D16: 0.25 | E16: 0.16666667 | F16: 0.16666667 | G16: 0.16693287 | H16: 0.16666667 | I16: 0.32380787 | J16: - | K16: 0.25 | L16: - | M16: - | N16: 0.70833333 | O16: 0.70833333
C17: 結束 | D17: 0.57777778 | E17: 0.63851852 | F17: 0.63435185 | G17: 0.58476852 | H17: 0.67104167 | I17: 0.57569444 | J17: - | K17: 0.40902778 | L17: - | M17: - | N17: 0.81597222 | O17: 0.85347222
B18: 配置人數 | D18: 17.666667 | E18: 24.6 | F18: 21.833333 | G18: 21.666667 | H18: 19.8 | I18: 13.5 | J18: - | K18: 6.8 | L18: - | M18: - | N18: 19.333333 | O18: 23
B19: 主要應用設備 | D19: L型封口機 | E19: ET-55 | F19: ET-55 | G19: ET-55 | H19: ET-600 | I19: 伺服包裝機 | J19: 伺服包裝機 | K19: 伺服包裝機 | L19: L型封口機 | M19: ET-55 | N19: ET-55 | O19: ET-55
B20: 次要應用設備 | D20: 伺服包裝機 | H20: 伺服包裝機
B21: 備註 | H21: 涼麵+烤飯糰 | I21: 大口飯糰線 | K21: 烤飯糰+手卷
B24: 溫層 | D24: ➃18度C-各編組展開 (一配) | P24: ⑤18度C-各編組展開 (二配)
B25: 編組 | D25: 1 | E25: 2 | F25: 3 | G25: 4 | H25: 5 | I25: 6 | J25: 7 | K25: 8 | L25: 9 | M25: 10 | N25: 11 | O25: 12 | P25: 1 | Q25: 2 | R25: 3 | S25: 4 | T25: 5 | U25: 6 | V25: 7 | W25: 8 | X25: 9
D26: 便當一線 | E26: 涼麵一線 | F26: 涼麵三線 | G26: 自動包裝機 | H26: 自動包裝機2 | I26: 自動包裝機3 | J26: 味付飯糰線B | K26: (舊) 3300型飯糰線 | L26: 3000型飯糰線 | M26: (新) 3300型飯糰機 | N26: GKK3600型 飯糰機 | O26: GKK3600型 飯糰機2 | P26: 自動包裝機 | Q26: 自動包裝機2 | R26: 自動包裝機3 | S26: 味付飯糰線B | T26: (舊) 3300型飯糰線 | U26: 3000型飯糰線 | V26: (新) 3300型飯糰機 | W26: GKK3600型 飯糰機 | X26: GKK3600型 飯糰機2
B27: 人時性 | C27: 排關 | D27: 211.76471 | E27: - | F27: - | G27: 313.04348 | H27: 433.33333 | I27: 416.66667 | J27: - | K27: - | L27: - | M27: 776.47059 | N27: 1150 | O27: 860 | P27: 285.71429 | Q27: - | R27: - | S27: - | T27: 795 | U27: - | V27: 825 | W27: 969.23077 | X27: 1050
C28: 實績 | D28: 183.32756 | E28: - | F28: - | G28: 271.80238 | H28: 384.74488 | I28: 372 | J28: - | K28: - | L28: - | M28: 693.25744 | N28: 1000.537 | O28: 761.99868 | P28: 249.25944 | Q28: - | R28: - | S28: - | T28: 706.75395 | U28: - | V28: 734.92773 | W28: 857.45836 | X28: 913.86794
C29: 達成率 | D29: =D28/D27 -> 0.86571348 | E29: - | F29: - | G29: =G28/G27 -> 0.86825761 | H29: =H28/H27 -> 0.88787279 | I29: =I28/I27 -> 0.8928 | J29: - | K29: - | L29: - | M29: =M28/M27 -> 0.89283155 | N29: =N28/N27 -> 0.87003215 | O29: =O28/O27 -> 0.88604498 | P29: =P28/P27 -> 0.87240804 | Q29: - | R29: - | S29: - | T29: =T28/T27 -> 0.88899868 | U29: - | V29: =V28/V27 -> 0.89082149 | W29: =W28/W27 -> 0.88467926 | X29: =X28/X27 -> 0.87035042
B30: 作業 時間 | C30: 開始 | D30: 0.37322917 | E30: - | F30: - | G30: 0.25 | H30: 0.25 | I30: 0.4125 | J30: - | K30: - | L30: - | M30: 0.25 | N30: 0.16666667 | O30: 0.25028935 | P30: 0.70841435 | Q30: - | R30: - | S30: - | T30: 0.70837963 | U30: - | V30: 0.70833333 | W30: 0.70833333 | X30: 0.70862269
C31: 結束 | D31: 0.44126157 | E31: - | F31: - | G31: 0.32013889 | H31: 0.33556713 | I31: 0.43622685 | J31: - | K31: - | L31: - | M31: 0.45208333 | N31: 0.43780093 | O31: 0.41319444 | P31: 0.83707176 | Q31: - | R31: - | S31: - | T31: 0.89097222 | U31: - | V31: 0.92152778 | W31: 1.0270833 | X31: 1.0263889
B32: 配置人數 | D32: 17 | E32: - | F32: - | G32: 11.5 | H32: 6 | I32: 6 | J32: - | K32: - | L32: - | M32: 4.25 | N32: 3 | O32: 3.75 | P32: 12.6 | Q32: - | R32: - | S32: - | T32: 4 | U32: - | V32: 4 | W32: 3.25 | X32: 3.3333333
B33: 主要應用設備 | D33: 伺服包裝機 | E33: ET-55 | F33: ET-600 | G33: 夾心型 | H33: 伺服包裝機 | I33: 伺服包裝機 | J33: 夾心型 | K33: 3300型 | L33: 3300型 | M33: 3300型 | N33: GKK | O33: GKK | P33: 夾心型 | Q33: 伺服包裝機 | R33: 伺服包裝機 | S33: 夾心型 | T33: 3300型 | U33: 3300型 | V33: 3300型 | W33: GKK | X33: GKK
B34: 次要應用設備
B35: 備註

Sheet 1130(18度C)
A1: 大溪廠日報分析 | C1: 總生產量 | D1: =SUM(F5:F208) -> 122280 | E1: 營業額 | F1: =SUM(G5:G208) -> 2410274.9 | G1: 出勤人數 | H1: =L21+L38+L55+L72+L89+L106+L123+L140+L157+L174+L191+L208 -> 78.683333 | I1: 產線配置圖 | L1: 生產實績 | O1: 人時性差異分析 | S1: 日報登錄 | Y1: 分析說明 | AA1: 產能差異分析
A2: 45991 | C2: 人時性 | D2: =AVERAGE(N21,N38,N55,N72,N89,N106,N123,N140,N157,N174,N191,N208) -> 594.16128 | E2: 平均廠價 | F2: =F1/D1 -> 19.711113 | G2: 多次生產數 | H2: =COUNT(H5:H208) -> 3
A3: 線別 | B3: 品類 | C3: 品名 | E3: 廠價 | F3: 生產量 | G3: 營收 | H3: 多次 生產 | I3: 人數 | J3: 產能/時 | K3: 人時性 | L3: 人數 | M3: 產能/時 | N3: 人時性 | O3: 人數 | P3: 人時性 | Q3: 達成率 | R3: 達成率 平均 | S3: 生產時間 | U3: 換線、休息/分 | V3: 稼動時間/分 | W3: 休息時間 | Y3: (屏榮回填) | AA3: 產能/時 | AB3: 達成率 | AC3: 達成率平均
S4: 開始 | T4: 結束 | W4: 開始 | X4: 結束
A5: 便當一線 | B5: 18℃-壽司手卷 | C5: 一配海饌雙手卷 | E5: 29.85 | F5: 2471 | G5: =E5*F5 -> 73759.35 | I5: 17 | J5: 3600 | K5: =J5/I5 -> 211.76471 | L5: 17 | M5: =F5/V5*60 -> 3117.9811 | N5: =M5/L5 -> 183.41065 | O5: =L5-I5 -> 0 | P5: =N5-K5 -> -28.354055 | Q5: =N5/K5 -> 0.86610585 | R5: =Q21 -> 0.86571348 | S5: 0.37322917 | T5: 0.40625 | U5: 5.1 | V5: 47.55 | AA5: =M5-J5 -> -482.01893 | AB5: =M5/J5 -> 0.86610585 | AC5: =AB21 -> 0.86571348
B6: 18℃-壽司手卷 | C6: 一配雙饗雙手卷 | E6: 29.52 | F6: 2358 | G6: =E6*F6 -> 69608.16 | I6: 17 | J6: 3600 | K6: =J6/I6 -> 211.76471 | L6: 17 | M6: =F6/V6*60 -> 3115.156 | N6: =M6/L6 -> 183.24447 | O6: =L6-I6 -> 0 | P6: =N6-K6 -> -28.520237 | Q6: =N6/K6 -> 0.8653211 | S6: 0.40972222 | T6: 0.44126157 | U6: 5 | V6: 45.416667 | AA6: =M6-J6 -> -484.84404 | AB6: =M6/J6 -> 0.8653211
B21: 平均 | I21: =AVERAGE(I5:I20) -> 17 | J21: =AVERAGE(J5:J20) -> 3600 | K21: =J21/I21 -> 211.76471 | L21: =AVERAGE(L5:L20) -> 17 | M21: =AVERAGE(M5:M20) -> 3116.5685 | N21: =M21/L21 -> 183.32756 | O21: =L21-I21 -> 0 | P21: =N21-K21 -> -28.437146 | Q21: =N21/K21 -> 0.86571348 | S21: =S5 -> 0.37322917 | T21: =INDEX(T5:T20,COUNTA(T5:T20)) -> 0.44126157 | AA21: =M21-J21 -> -483.43148 | AB21: =M21/J21 -> 0.86571348
A22: 自動包裝機 | B22: 18℃-壽司手卷 | C22: 一配長野稻荷壽司 | E22: 25.64 | F22: 1527 | G22: =E22*F22 -> 39152.28 | I22: 11 | J22: 3600 | K22: =J22/I22 -> 327.27273 | L22: 11 | M22: =F22/V22*60 -> 3144.8513 | N22: =M22/L22 -> 285.89557 | O22: =L22-I22 -> 0 | P22: =N22-K22 -> -41.377158 | Q22: =N22/K22 -> 0.87356979 | R22: =Q38 -> 0.86825761 | S22: 0.25 | T22: 0.27023148 | V22: 29.133333 | AA22: =M22-J22 -> -455.14874 | AB22: =M22/J22 -> 0.87356979 | AC22: =AB38 -> 0.86825761
B23: 18℃-飯糰 | C23: 一配兩粒飯糰(鮪魚.焦糖鮭魚) | E23: 28.57 | F23: 3463 | G23: =E23*F23 -> 98937.91 | I23: 12 | J23: 3600 | K23: =J23/I23 -> 300 | L23: 12 | M23: =F23/V23*60 -> 3106.6035 | N23: =M23/L23 -> 258.88363 | O23: =L23-I23 -> 0 | P23: =N23-K23 -> -41.116372 | Q23: =N23/K23 -> 0.86294543 | S23: 0.27369213 | T23: 0.32013889 | U23: 4.9833333 | V23: 66.883333 | AA23: =M23-J23 -> -493.39646 | AB23: =M23/J23 -> 0.86294543
B38: 平均 | I38: =AVERAGE(I22:I37) -> 11.5 | J38: =AVERAGE(J22:J37) -> 3600 | K38: =J38/I38 -> 313.04348 | L38: =AVERAGE(L22:L37) -> 11.5 | M38: =AVERAGE(M22:M37) -> 3125.7274 | N38: =M38/L38 -> 271.80238 | O38: =L38-I38 -> 0 | P38: =N38-K38 -> -41.241096 | Q38: =N38/K38 -> 0.86825761 | S38: =S22 -> 0.25 | T38: =INDEX(T22:T37,COUNTA(T22:T37)) -> 0.32013889 | AA38: =M38-J38 -> -474.2726 | AB38: =M38/J38 -> 0.86825761
A39: 自動包裝機2 | B39: 18℃-壽司手卷 | C39: 一配雙鬆細卷 | E39: 14.03 | F39: 1541 | G39: =E39*F39 -> 21620.23 | I39: 6 | J39: 2600 | K39: =J39/I39 -> 433.33333 | L39: 6 | M39: =F39/V39*60 -> 2309.5754 | N39: =M39/L39 -> 384.92923 | O39: =L39-I39 -> 0 | P39: =N39-K39 -> -48.404108 | Q39: =N39/K39 -> 0.88829821 | R39: =Q55 -> 0.88787279 | S39: 0.25 | T39: 0.27780093 | V39: 40.033333 | AA39: =M39-J39 -> -290.42465 | AB39: =M39/J39 -> 0.88829821 | AC39: =AB55 -> 0.88787279
B40: 18℃-壽司手卷 | C40: 一配香濃起司蟹風味棒細卷 | E40: 17.73 | F40: 1252 | G40: =E40*F40 -> 22197.96 | I40: 6 | J40: 2600 | K40: =J40/I40 -> 433.33333 | L40: 6 | M40: =F40/V40*60 -> 2307.8341 | N40: =M40/L40 -> 384.63902 | O40: =L40-I40 -> 0 | P40: =N40-K40 -> -48.694316 | Q40: =N40/K40 -> 0.8876285 | S40: 0.2815625 | T40: 0.30416667 | U40: 5.4166667 | V40: 32.55 | AA40: =M40-J40 -> -292.1659 | AB40: =M40/J40 -> 0.8876285
B41: 18℃-壽司手卷 | C41: 一配經典鮪魚沙拉細卷 | E41: 14.49 | F41: 1547 | G41: =E41*F41 -> 22416.03 | I41: 6 | J41: 2600 | K41: =J41/I41 -> 433.33333 | L41: 6 | M41: =F41/V41*60 -> 2307.9983 | N41: =M41/L41 -> 384.66639 | O41: =L41-I41 -> 0 | P41: =N41-K41 -> -48.666943 | Q41: =N41/K41 -> 0.88769167 | S41: 0.30763889 | T41: 0.33556713 | U41: 5 | V41: 40.216667 | AA41: =M41-J41 -> -292.00166 | AB41: =M41/J41 -> 0.88769167
B55: 平均 | I55: =AVERAGE(I39:I54) -> 6 | J55: =AVERAGE(J39:J54) -> 2600 | K55: =J55/I55 -> 433.33333 | L55: =AVERAGE(L39:L54) -> 6 | M55: =AVERAGE(M39:M54) -> 2308.4693 | N55: =M55/L55 -> 384.74488 | O55: =L55-I55 -> 0 | P55: =N55-K55 -> -48.588456 | Q55: =N55/K55 -> 0.88787279 | S55: =S39 -> 0.25 | T55: =INDEX(T39:T54,COUNTA(T39:T54)) -> 0.33556713 | AA55: =M55-J55 -> -291.53073 | AB55: =M55/J55 -> 0.88787279
A56: 自動包裝機3 | B56: 18℃-壽司手卷 | C56: 一配明太子玉子脆卷 | E56: 19.7 | F56: 1271 | G56: =E56*F56 -> 25038.7 | I56: 6 | J56: 2500 | K56: =J56/I56 -> 416.66667 | L56: 6 | M56: =F56/V56*60 -> 2232 | N56: =M56/L56 -> 372 | O56: =L56-I56 -> 0 | P56: =N56-K56 -> -44.666667 | Q56: =N56/K56 -> 0.8928 | R56: =Q72 -> 0.8928 | S56: 0.4125 | T56: 0.43622685 | U56: 5 | V56: 34.166667 | AA56: =M56-J56 -> -268 | AB56: =M56/J56 -> 0.8928 | AC56: =AB72 -> 0.8928
B72: 平均 | I72: =AVERAGE(I56:I71) -> 6 | J72: =AVERAGE(J56:J71) -> 2500 | K72: =J72/I72 -> 416.66667 | L72: =AVERAGE(L56:L71) -> 6 | M72: =AVERAGE(M56:M71) -> 2232 | N72: =M72/L72 -> 372 | O72: =L72-I72 -> 0 | P72: =N72-K72 -> -44.666667 | Q72: =N72/K72 -> 0.8928 | S72: =S56 -> 0.4125 | T72: =INDEX(T56:T71,COUNTA(T56:T71)) -> 0.43622685 | AA72: =M72-J72 -> -268 | AB72: =M72/J72 -> 0.8928
A73: (新) 3300型飯糰機 | B73: 18℃-飯糰 | C73: 一配照燒雞肉飯糰 | E73: 21.45 | F73: 2660 | G73: =E73*F73 -> 57057 | I73: 4 | J73: 3300 | K73: =J73/I73 -> 825 | L73: 4 | M73: =F73/V73*60 -> 2950.0924 | N73: =M73/L73 -> 737.52311 | O73: =L73-I73 -> 0 | P73: =N73-K73 -> -87.476895 | Q73: =N73/K73 -> 0.8939674 | R73: =Q89 -> 0.89283155 | S73: 0.25 | T73: 0.28756944 | V73: 54.1 | AA73: =M73-J73 -> -349.90758 | AB73: =M73/J73 -> 0.8939674 | AC73: =AB89 -> 0.89283155
B74: 18℃-飯糰 | C74: 一配壹號醬炙烤牛飯糰 | E74: 22.28 | F74: 1367 | G74: =E74*F74 -> 30456.76 | I74: 5 | J74: 3300 | K74: =J74/I74 -> 660 | L74: 5 | M74: =F74/V74*60 -> 2948.592 | N74: =M74/L74 -> 589.71839 | O74: =L74-I74 -> 0 | P74: =N74-K74 -> -70.281606 | Q74: =N74/K74 -> 0.89351272 | S74: 0.29109954 | T74: 0.31041667 | U74: 5.0833333 | V74: 27.816667 | AA74: =M74-J74 -> -351.40803 | AB74: =M74/J74 -> 0.89351272
B75: 18℃-飯糰 | C75: 一配鹽蔥燒肉飯糰 | E75: 17.89 | F75: 3827 | G75: =E75*F75 -> 68465.03 | I75: 4 | J75: 3300 | K75: =J75/I75 -> 825 | L75: 4 | M75: =F75/V75*60 -> 2946.3644 | N75: =M75/L75 -> 736.5911 | O75: =L75-I75 -> 0 | P75: =N75-K75 -> -88.408896 | Q75: =N75/K75 -> 0.8928377 | S75: 0.31393519 | T75: 0.36805556 | U75: 5.0666667 | V75: 77.933333 | AA75: =M75-J75 -> -353.63559 | AB75: =M75/J75 -> 0.8928377
B76: 18℃-飯糰 | C76: 一配雞肉飯飯糰 | E76: 16.66 | F76: 5683 | G76: =E76*F76 -> 94678.78 | I76: 4 | J76: 3300 | K76: =J76/I76 -> 825 | L76: 4 | M76: =F76/V76*60 -> 2940.3277 | N76: =M76/L76 -> 735.08192 | O76: =L76-I76 -> 0 | P76: =N76-K76 -> -89.91808 | Q76: =N76/K76 -> 0.89100839 | S76: 0.37155093 | T76: 0.45208333 | U76: 5.0333333 | V76: 115.96667 | AA76: =M76-J76 -> -359.67232 | AB76: =M76/J76 -> 0.89100839
B89: 平均 | I89: =AVERAGE(I73:I88) -> 4.25 | J89: =AVERAGE(J73:J88) -> 3300 | K89: =J89/I89 -> 776.47059 | L89: =AVERAGE(L73:L88) -> 4.25 | M89: =AVERAGE(M73:M88) -> 2946.3441 | N89: =M89/L89 -> 693.25744 | O89: =L89-I89 -> 0 | P89: =N89-K89 -> -83.213148 | Q89: =N89/K89 -> 0.89283155 | S89: =S73 -> 0.25 | T89: =INDEX(T73:T88,COUNTA(T73:T88)) -> 0.45208333 | AA89: =M89-J89 -> -353.65588 | AB89: =M89/J89 -> 0.89283155
A90: GKK3600型 飯糰機 | B90: 18℃-飯糰 | C90: 一配蔬食鮪魚飯糰 | E90: 18.18 | F90: 1766 | G90: =E90*F90 -> 32105.88 | I90: 3 | J90: 3600 | K90: =J90/I90 -> 1200 | L90: 3 | M90: =F90/V90*60 -> 3110.3718 | N90: =M90/L90 -> 1036.7906 | O90: =L90-I90 -> 0 | P90: =N90-K90 -> -163.20939 | Q90: =N90/K90 -> 0.86399217 | R90: =Q106 -> 0.87003215 | S90: 0.16666667 | T90: 0.19032407 | V90: 34.066667 | AA90: =M90-J90 -> -489.62818 | AB90: =M90/J90 -> 0.86399217 | AC90: =AB106 -> 0.87003215
B91: 18℃-飯糰 | C91: 一配經典肉鬆飯糰 | E91: 14.03 | F91: 5619 | G91: =E91*F91 -> 78834.57 | I91: 3 | J91: 3000 | K91: =J91/I91 -> 1000 | L91: 3 | M91: =F91/V91*60 -> 2675.0066 | N91: =M91/L91 -> 891.66887 | O91: =L91-I91 -> 0 | P91: =N91-K91 -> -108.33113 | Q91: =N91/K91 -> 0.89166887 | S91: 0.20069444 | T91: 0.28821759 | U91: 14.933333 | V91: 126.03333 | AA91: =M91-J91 -> -324.99339 | AB91: =M91/J91 -> 0.89166887
B92: 18℃-飯糰 | C92: 一配明太子龍蝦風味沙拉飯糰 | E92: 18.18 | F92: 2693 | G92: =E92*F92 -> 48958.74 | I92: 3 | J92: 3600 | K92: =J92/I92 -> 1200 | L92: 3 | M92: =F92/V92*60 -> 3110.2984 | N92: =M92/L92 -> 1036.7661 | O92: =L92-I92 -> 0 | P92: =N92-K92 -> -163.23388 | Q92: =N92/K92 -> 0.86397177 | S92: 0.29864583 | T92: 0.33472222 | U92: 15.016667 | V92: 51.95 | AA92: =M92-J92 -> -489.70164 | AB92: =M92/J92 -> 0.86397177
B93: 18℃-飯糰 | C93: 一配鮪魚飯糰 | E93: 14.28 | F93: 6918 | G93: =E93*F93 -> 98789.04 | I93: 3 | J93: 3600 | K93: =J93/I93 -> 1200 | L93: 3 | M93: =F93/V93*60 -> 3110.7669 | N93: =M93/L93 -> 1036.9223 | O93: =L93-I93 -> 0 | P93: =N93-K93 -> -163.07769 | Q93: =N93/K93 -> 0.86410192 | S93: 0.34513889 | T93: 0.43780093 | U93: 15 | V93: 133.43333 | AA93: =M93-J93 -> -489.23308 | AB93: =M93/J93 -> 0.86410192
B106: 平均 | I106: =AVERAGE(I90:I105) -> 3 | J106: =AVERAGE(J90:J105) -> 3450 | K106: =J106/I106 -> 1150 | L106: =AVERAGE(L90:L105) -> 3 | M106: =AVERAGE(M90:M105) -> 3001.6109 | N106: =M106/L106 -> 1000.537 | O106: =L106-I106 -> 0 | P106: =N106-K106 -> -149.46302 | Q106: =N106/K106 -> 0.87003215 | S106: =S90 -> 0.16666667 | T106: =INDEX(T90:T105,COUNTA(T90:T105)) -> 0.43780093 | AA106: =M106-J106 -> -448.38907 | AB106: =M106/J106 -> 0.87003215
A107: GKK3600型 飯糰機2 | B107: 18℃-飯糰 | C107: 一配博多明太子奶油飯糰 | E107: 25.45 | F107: 1242 | G107: =E107*F107 -> 31608.9 | I107: 4 | J107: 3300 | K107: =J107/I107 -> 825 | L107: 4 | M107: =F107/V107*60 -> 2912.8339 | N107: =M107/L107 -> 728.20847 | O107: =L107-I107 -> 0 | P107: =N107-K107 -> -96.791531 | Q107: =N107/K107 -> 0.88267693 | R107: =Q123 -> 0.88604498 | S107: 0.25028935 | T107: 0.26805556 | V107: 25.583333 | AA107: =M107-J107 -> -387.16612 | AB107: =M107/J107 -> 0.88267693 | AC107: =AB123 -> 0.88604498
B108: 18℃-飯糰 | C108: 一配熟成紅鮭飯糰 | E108: 25.03 | F108: 1871 | G108: =E108*F108 -> 46831.13 | I108: 4 | J108: 3300 | K108: =J108/I108 -> 825 | L108: 4 | M108: =F108/V108*60 -> 2913.3218 | N108: =M108/L108 -> 728.33045 | O108: =L108-I108 -> 0 | P108: =N108-K108 -> -96.66955 | Q108: =N108/K108 -> 0.88282479 | S108: 0.2787963 | T108: 0.30555556 | U108: 15.466667 | V108: 38.533333 | AA108: =M108-J108 -> -386.6782 | AB108: =M108/J108 -> 0.88282479
B109: 18℃-飯糰 | C109: 一配北海道秋鮭親子飯糰 | E109: 24.82 | F109: 2074 | G109: =E109*F109 -> 51476.68 | I109: 4 | J109: 3300 | K109: =J109/I109 -> 825 | L109: 4 | M109: =F109/V109*60 -> 2918.8428 | N109: =M109/L109 -> 729.71071 | O109: =L109-I109 -> 0 | P109: =N109-K109 -> -95.289289 | Q109: =N109/K109 -> 0.88449783 | S109: 0.31622685 | T109: 0.34583333 | U109: 15.366667 | V109: 42.633333 | AA109: =M109-J109 -> -381.15715 | AB109: =M109/J109 -> 0.88449783
B110: 18℃-飯糰 | C110: 一配贅沢鮭魚肚飯糰 | E110: 30 | F110: 3665 | G110: =E110*F110 -> 109950 | I110: 3 | J110: 3000 | K110: =J110/I110 -> 1000 | L110: 3 | M110: =F110/V110*60 -> 2684.9817 | N110: =M110/L110 -> 894.99389 | O110: =L110-I110 -> 0 | P110: =N110-K110 -> -105.00611 | Q110: =N110/K110 -> 0.89499389 | S110: 0.35631944 | T110: 0.41319444 | U110: 15.1 | V110: 81.9 | AA110: =M110-J110 -> -315.01832 | AB110: =M110/J110 -> 0.89499389
B123: 平均 | I123: =AVERAGE(I107:I122) -> 3.75 | J123: =AVERAGE(J107:J122) -> 3225 | K123: =J123/I123 -> 860 | L123: =AVERAGE(L107:L122) -> 3.75 | M123: =AVERAGE(M107:M122) -> 2857.4951 | N123: =M123/L123 -> 761.99868 | O123: =L123-I123 -> 0 | P123: =N123-K123 -> -98.00132 | Q123: =N123/K123 -> 0.88604498 | S123: =S107 -> 0.25028935 | T123: =INDEX(T107:T122,COUNTA(T107:T122)) -> 0.41319444 | AA123: =M123-J123 -> -367.50495 | AB123: =M123/J123 -> 0.88604498
A124: 自動包裝機 (二配) | B124: 18℃-飯糰 | C124: 二配兔兔昆布飯糰 | E124: 13.42 | F124: 155 | G124: =E124*F124 -> 2080.1 | I124: 6 | J124: 3600 | K124: =J124/I124 -> 600 | L124: 6 | M124: =F124/V124*60 -> 3225.4335 | N124: =M124/L124 -> 537.57225 | O124: =L124-I124 -> 0 | P124: =N124-K124 -> -62.427746 | Q124: =N124/K124 -> 0.89595376 | R124: =Q140 -> 0.87240804 | S124: 0.70841435 | T124: 0.71041667 | V124: 2.8833333 | AA124: =M124-J124 -> -374.56647 | AB124: =M124/J124 -> 0.89595376 | AC124: =AB140 -> 0.87240804
B125: 18℃-壽司手卷 | C125: 二配長野稻荷壽司 | E125: 25.64 | F125: 1656 | G125: =E125*F125 -> 42459.84 | I125: 11 | J125: 3600 | K125: =J125/I125 -> 327.27273 | L125: 11 | M125: =F125/V125*60 -> 3142.6463 | N125: =M125/L125 -> 285.69512 | O125: =L125-I125 -> 0 | P125: =N125-K125 -> -41.577611 | Q125: =N125/K125 -> 0.8729573 | S125: 0.71415509 | T125: 0.73611111 | U125: 5.3833333 | V125: 31.616667 | AA125: =M125-J125 -> -457.35372 | AB125: =M125/J125 -> 0.8729573
B126: 18℃-壽司手卷 | C126: 二配雙饗雙手卷 | E126: 29.52 | F126: 2075 | G126: =E126*F126 -> 61254 | I126: 17 | J126: 3600 | K126: =J126/I126 -> 211.76471 | L126: 17 | M126: =F126/V126*60 -> 3113.7974 | N126: =M126/L126 -> 183.16455 | O126: =L126-I126 -> 0 | P126: =N126-K126 -> -28.600152 | Q126: =N126/K126 -> 0.86494373 | S126: 0.73959491 | T126: 0.76736111 | U126: 5.0166667 | V126: 39.983333 | AA126: =M126-J126 -> -486.20258 | AB126: =M126/J126 -> 0.86494373
B127: 18℃-壽司手卷 | C127: 二配海饌雙手卷 | E127: 29.85 | F127: 2171 | G127: =E127*F127 -> 64804.35 | I127: 17 | J127: 3600 | K127: =J127/I127 -> 211.76471 | L127: 17 | M127: =F127/V127*60 -> 3115.0259 | N127: =M127/L127 -> 183.23682 | O127: =L127-I127 -> 0 | P127: =N127-K127 -> -28.527888 | Q127: =N127/K127 -> 0.86528497 | S127: 0.77096065 | T127: 0.8 | U127: 5.1833333 | V127: 41.816667 | AA127: =M127-J127 -> -484.97409 | AB127: =M127/J127 -> 0.86528497
B128: 18℃-飯糰 | C128: 二配兩粒飯糰(鮪魚.焦糖鮭魚) | E128: 28.57 | F128: 2505 | G128: =E128*F128 -> 71567.85 | I128: 12 | J128: 3600 | K128: =J128/I128 -> 300 | L128: 12 | M128: =F128/V128*60 -> 3106.4416 | N128: =M128/L128 -> 258.87013 | O128: =L128-I128 -> 0 | P128: =N128-K128 -> -41.129866 | Q128: =N128/K128 -> 0.86290045 | S128: 0.80347222 | T128: 0.83707176 | U128: 5 | V128: 48.383333 | AA128: =M128-J128 -> -493.55839 | AB128: =M128/J128 -> 0.86290045
B140: 平均 | I140: =AVERAGE(I124:I139) -> 12.6 | J140: =AVERAGE(J124:J139) -> 3600 | K140: =J140/I140 -> 285.71429 | L140: =AVERAGE(L124:L139) -> 12.6 | M140: =AVERAGE(M124:M139) -> 3140.6689 | N140: =M140/L140 -> 249.25944 | O140: =L140-I140 -> 0 | P140: =N140-K140 -> -36.454845 | Q140: =N140/K140 -> 0.87240804 | S140: =S124 -> 0.70841435 | T140: =INDEX(T124:T139,COUNTA(T124:T139)) -> 0.83707176 | AA140: =M140-J140 -> -459.33105 | AB140: =M140/J140 -> 0.87240804
A141: (舊) 3300型飯糰線 (二配) | B141: 18℃-飯糰 | C141: 二配三杯醬爆菇菇飯糰 | E141: 16.7 | F141: 2789 | G141: =E141*F141 -> 46576.3 | I141: 3 | J141: 3300 | K141: =J141/I141 -> 1100 | L141: 3 | M141: =F141/V141*60 -> 2939.2272 | N141: =M141/L141 -> 979.74239 | O141: =L141-I141 -> 0 | P141: =N141-K141 -> -120.25761 | Q141: =N141/K141 -> 0.8906749 | R141: =Q157 -> 0.88899868 | S141: 0.70837963 | T141: 0.74791667 | V141: 56.933333 | AA141: =M141-J141 -> -360.77283 | AB141: =M141/J141 -> 0.8906749 | AC141: =AB157 -> 0.88899868
B142: 18℃-飯糰 | C142: 二配油蔥G絲飯糰 | E142: 18.18 | F142: 1177 | G142: =E142*F142 -> 21397.86 | I142: 4 | J142: 3300 | K142: =J142/I142 -> 825 | L142: 4 | M142: =F142/V142*60 -> 2946.5925 | N142: =M142/L142 -> 736.64812 | O142: =L142-I142 -> 0 | P142: =N142-K142 -> -88.351878 | Q142: =N142/K142 -> 0.89290682 | S142: 0.75141204 | T142: 0.76805556 | U142: 5.0333333 | V142: 23.966667 | AA142: =M142-J142 -> -353.40751 | AB142: =M142/J142 -> 0.89290682
B143: 18℃-飯糰 | C143: 二配壹號醬炙烤牛飯糰 | E143: 22.28 | F143: 1875 | G143: =E143*F143 -> 41775 | I143: 5 | J143: 3300 | K143: =J143/I143 -> 660 | L143: 5 | M143: =F143/V143*60 -> 2941.1765 | N143: =M143/L143 -> 588.23529 | O143: =L143-I143 -> 0 | P143: =N143-K143 -> -71.764706 | Q143: =N143/K143 -> 0.8912656 | S143: 0.77152778 | T143: 0.79809028 | U143: 5 | V143: 38.25 | AA143: =M143-J143 -> -358.82353 | AB143: =M143/J143 -> 0.8912656
...

Sheet 1130(4度C)
A1: 大溪廠日報分析 | C1: 總生產量 | D1: =SUM(F5:F157) -> 115475 | E1: 營業額 | F1: =SUM(G5:G157) -> 5695399.1 | G1: 出勤人數 | H1: =L21+L38+L55+L72+L89+L106+L123+L140+L157 -> 168.2 | I1: 產線配置圖 | L1: 生產實績 | O1: 人時性差異分析 | S1: 日報登錄 | Y1: 分析說明 | AA1: 產能差異分析
A2: 45991 | C2: 人時性 | D2: =AVERAGE(N21,N38,N55,N72,N89,N106,N123,N140,N157) -> 144.26764 | E2: 平均廠價 | F2: =F1/D1 -> 49.32149 | G2: 多次生產數 | H2: =COUNT(H5:H157) -> 0
A3: 線別 | B3: 品類 | C3: 品名 | E3: 廠價 | F3: 生產量 | G3: 營收 | H3: 多次 生產 | I3: 人數 | J3: 產能/時 | K3: 人時性 | L3: 人數 | M3: 產能/時 | N3: 人時性 | O3: 人數 | P3: 人時性 | Q3: 達成率 | R3: 達成率 平均 | S3: 生產時間 | U3: 換線、休息/分 | V3: 稼動時間/分 | W3: 休息時間 | Y3: (屏榮回填) | AA3: 產能/時 | AB3: 達成率 | AC3: 達成率平均
S4: 開始 | T4: 結束 | W4: 開始 | X4: 結束
A5: 便當一線 | B5: 微波小吃 | C5: 日式茶碗蒸 | E5: 19.7 | F5: 3096 | G5: =E5*F5 -> 60991.2 | I5: 13 | J5: 1200 | K5: =J5/I5 -> 92.307692 | L5: 13 | M5: =F5/V5*60 -> 1077.8068 | N5: =M5/L5 -> 82.908215 | O5: =L5-I5 -> 0 | P5: =N5-K5 -> -9.3994778 | Q5: =N5/K5 -> 0.89817232 | R5: =Q21 -> 0.88841225 | S5: 0.25 | T5: 0.3696875 | V5: 172.35 | AA5: =M5-J5 -> -122.19321 | AB5: =M5/J5 -> 0.89817232 | AC5: =AB21 -> 0.88841225
B6: 4℃-飯糰 | C6: 韓素燒若飯糰 | E6: 24.07 | F6: 2377 | G6: =E6*F6 -> 57214.39 | I6: 20 | J6: 2600 | K6: =J6/I6 -> 130 | L6: 20 | M6: =F6/V6*60 -> 2304.6593 | N6: =M6/L6 -> 115.23297 | O6: =L6-I6 -> 0 | P6: =N6-K6 -> -14.767035 | Q6: =N6/K6 -> 0.88640743 | S6: 0.44452546 | T6: 0.4875 | U6: 4.7 | V6: 61.883333 | W6: 0.4875 | X6: 0.52732639 | AA6: =M6-J6 -> -295.34069 | AB6: =M6/J6 -> 0.88640743
B7: 4℃-飯糰 | C7: 麻油雞飯糰 | E7: 29.97 | F7: 2789 | G7: =E7*F7 -> 83586.33 | I7: 20 | J7: 2600 | K7: =J7/I7 -> 130 | L7: 20 | M7: =F7/V7*60 -> 2303.3723 | N7: =M7/L7 -> 115.16862 | O7: =L7-I7 -> 0 | P7: =N7-K7 -> -14.831383 | Q7: =N7/K7 -> 0.88591244 | S7: 0.52732639 | T7: 0.57777778 | U7: 57.35 | V7: 72.65 | AA7: =M7-J7 -> -296.62767 | AB7: =M7/J7 -> 0.88591244
B21: 平均 | I21: =AVERAGE(I5:I20) -> 17.666667 | J21: =AVERAGE(J5:J20) -> 2133.3333 | K21: =J21/I21 -> 120.75472 | L21: =AVERAGE(L5:L20) -> 17.666667 | M21: =AVERAGE(M5:M20) -> 1895.2795 | N21: =M21/L21 -> 107.27997 | O21: =L21-I21 -> 0 | P21: =N21-K21 -> -13.474747 | Q21: =N21/K21 -> 0.88841225 | S21: =S5 -> 0.25 | T21: =INDEX(T5:T20,COUNTA(T5:T20)) -> 0.57777778 | AA21: =M21-J21 -> -238.05386 | AB21: =M21/J21 -> 0.88841225
A22: 便當二線 | B22: 微波主食 | C22: 糖燻野郎三十天熟成牛飯 | E22: 56.77 | F22: 4325 | G22: =E22*F22 -> 245530.25 | I22: 25 | J22: 2000 | K22: =J22/I22 -> 80 | L22: 25 | M22: =F22/V22*60 -> 1774.1568 | N22: =M22/L22 -> 70.966272 | O22: =L22-I22 -> 0 | P22: =N22-K22 -> -9.0337284 | Q22: =N22/K22 -> 0.8870784 | R22: =Q38 -> 0.88736655 | S22: 0.16666667 | T22: 0.26824074 | V22: 146.26667 | AA22: =M22-J22 -> -225.84321 | AB22: =M22/J22 -> 0.8870784 | AC22: =AB38 -> 0.88736655
B23: 微波主食 | C23: 蒜蒜燒豚飯 | E23: 51.86 | F23: 1408 | G23: =E23*F23 -> 73018.88 | I23: 25 | J23: 2000 | K23: =J23/I23 -> 80 | L23: 25 | M23: =F23/V23*60 -> 1768.5973 | N23: =M23/L23 -> 70.743894 | O23: =L23-I23 -> 0 | P23: =N23-K23 -> -9.2561061 | Q23: =N23/K23 -> 0.88429867 | S23: 0.27238426 | T23: 0.30555556 | U23: 5.9666667 | V23: 47.766667 | AA23: =M23-J23 -> -231.40265 | AB23: =M23/J23 -> 0.88429867
B24: 便當 | C24: 嫩烤香料雞胸排蔬滿盒 | E24: 77.34 | F24: 2675 | G24: =E24*F24 -> 206884.5 | I24: 25 | J24: 2000 | K24: =J24/I24 -> 80 | L24: 25 | M24: =F24/V24*60 -> 1775.1152 | N24: =M24/L24 -> 71.004608 | O24: =L24-I24 -> 0 | P24: =N24-K24 -> -8.9953917 | Q24: =N24/K24 -> 0.8875576 | S24: 0.30902778 | T24: 0.37181713 | U24: 5 | V24: 90.416667 | AA24: =M24-J24 -> -224.88479 | AB24: =M24/J24 -> 0.8875576
B25: 便當 | C25: 烤蛋白餐盒 | E25: 58.67 | F25: 3982 | G25: =E25*F25 -> 233623.94 | I25: 23 | J25: 2000 | K25: =J25/I25 -> 86.956522 | L25: 23 | M25: =F25/V25*60 -> 1773.7194 | N25: =M25/L25 -> 77.118234 | O25: =L25-I25 -> 0 | P25: =N25-K25 -> -9.838288 | Q25: =N25/K25 -> 0.88685969 | S25: 0.37520833 | T25: 0.46875 | U25: 4.8833333 | V25: 134.7 | W25: 0.46875 | X25: 0.50833333 | AA25: =M25-J25 -> -226.28062 | AB25: =M25/J25 -> 0.88685969
B26: 便當 | C26: 健身G肉餐盒 | E26: 59.52 | F26: 5568 | G26: =E26*F26 -> 331407.36 | I26: 25 | J26: 2000 | K26: =J26/I26 -> 80 | L26: 25 | M26: =F26/V26*60 -> 1782.0768 | N26: =M26/L26 -> 71.283073 | O26: =L26-I26 -> 0 | P26: =N26-K26 -> -8.7169275 | Q26: =N26/K26 -> 0.89103841 | S26: 0.50833333 | T26: 0.63851852 | U26: 57 | V26: 187.46667 | AA26: =M26-J26 -> -217.92319 | AB26: =M26/J26 -> 0.89103841
B38: 平均 | I38: =AVERAGE(I22:I37) -> 24.6 | J38: =AVERAGE(J22:J37) -> 2000 | K38: =J38/I38 -> 81.300813 | L38: =AVERAGE(L22:L37) -> 24.6 | M38: =AVERAGE(M22:M37) -> 1774.7331 | N38: =M38/L38 -> 72.143622 | O38: =L38-I38 -> 0 | P38: =N38-K38 -> -9.1571908 | Q38: =N38/K38 -> 0.88736655 | S38: =S22 -> 0.16666667 | T38: =INDEX(T22:T37,COUNTA(T22:T37)) -> 0.63851852 | AA38: =M38-J38 -> -225.26689 | AB38: =M38/J38 -> 0.88736655
A39: 涼麵一線 | B39: 熱食義麵 | C39: 焗烤蕃茄起司四方麵 | E39: 57.3 | F39: 3350 | G39: =E39*F39 -> 191955 | I39: 22 | J39: 1800 | K39: =J39/I39 -> 81.818182 | L39: 22 | M39: =F39/V39*60 -> 1592.4997 | N39: =M39/L39 -> 72.386349 | O39: =L39-I39 -> 0 | P39: =N39-K39 -> -9.4318332 | Q39: =N39/K39 -> 0.88472204 | R39: =Q55 -> 0.88491248 | S39: 0.16666667 | T39: 0.25431713 | V39: 126.21667 | AA39: =M39-J39 -> -207.50033 | AB39: =M39/J39 -> 0.88472204 | AC39: =AB55 -> 0.88491248
B40: 微波主食 | C40: 壹號醬雞豚雙拼 | E40: 56.43 | F40: 2591 | G40: =E40*F40 -> 146210.13 | I40: 22 | J40: 2000 | K40: =J40/I40 -> 90.909091 | L40: 22 | M40: =F40/V40*60 -> 1768.9361 | N40: =M40/L40 -> 80.406186 | O40: =L40-I40 -> 0 | P40: =N40-K40 -> -10.502905 | Q40: =N40/K40 -> 0.88446804 | S40: 0.25771991 | T40: 0.31875 | U40: 4.9 | V40: 87.883333 | AA40: =M40-J40 -> -231.06391 | AB40: =M40/J40 -> 0.88446804
B41: 便當 | C41: 香烤藍尾鱈魚五行餐盒 | E41: 64.97 | F41: 2058 | G41: =E41*F41 -> 133708.26 | I41: 21 | J41: 2000 | K41: =J41/I41 -> 95.238095 | L41: 21 | M41: =F41/V41*60 -> 1771.169 | N41: =M41/L41 -> 84.341382 | O41: =L41-I41 -> 0 | P41: =N41-K41 -> -10.896713 | Q41: =N41/K41 -> 0.88558451 | S41: 0.32311343 | T41: 0.37152778 | U41: 6.2833333 | V41: 69.716667 | AA41: =M41-J41 -> -228.83098 | AB41: =M41/J41 -> 0.88558451
B42: 便當 | C42: 香腸腿排雙拼便當 | E42: 53.76 | F42: 3865 | G42: =E42*F42 -> 207782.4 | I42: 21 | J42: 2000 | K42: =J42/I42 -> 95.238095 | L42: 21 | M42: =F42/V42*60 -> 1769.3286 | N42: =M42/L42 -> 84.253742 | O42: =L42-I42 -> 0 | P42: =N42-K42 -> -10.984353 | Q42: =N42/K42 -> 0.88466429 | S42: 0.375 | T42: 0.46601852 | U42: 5 | V42: 131.06667 | W42: 0.46601852 | X42: 0.50570602 | AA42: =M42-J42 -> -230.67141 | AB42: =M42/J42 -> 0.88466429
B43: 便當 | C43: 美式雞丁餐盒 | E43: 59.34 | F43: 1822 | G43: =E43*F43 -> 108117.48 | I43: 24 | J43: 2000 | K43: =J43/I43 -> 83.333333 | L43: 24 | M43: =F43/V43*60 -> 1769.4092 | N43: =M43/L43 -> 73.725384 | O43: =L43-I43 -> 0 | P43: =N43-K43 -> -9.6079489 | Q43: =N43/K43 -> 0.88470461 | S43: 0.50570602 | T43: 0.54861111 | U43: 57.15 | V43: 61.783333 | AA43: =M43-J43 -> -230.59077 | AB43: =M43/J43 -> 0.88470461
B44: 熱食義麵 | C44: 明太子雞叉燒拌麵 | E44: 57.3 | F44: 3496 | G44: =E44*F44 -> 200320.8 | I44: 21 | J44: 2000 | K44: =J44/I44 -> 95.238095 | L44: 21 | M44: =F44/V44*60 -> 1770.6246 | N44: =M44/L44 -> 84.315459 | O44: =L44-I44 -> 0 | P44: =N44-K44 -> -10.922636 | Q44: =N44/K44 -> 0.88531232 | S44: 0.55208333 | T44: 0.63435185 | U44: 5 | V44: 118.46667 | AA44: =M44-J44 -> -229.37535 | AB44: =M44/J44 -> 0.88531232
B55: 平均 | I55: =AVERAGE(I39:I54) -> 21.833333 | J55: =AVERAGE(J39:J54) -> 1966.6667 | K55: =J55/I55 -> 90.076336 | L55: =AVERAGE(L39:L54) -> 21.833333 | M55: =AVERAGE(M39:M54) -> 1740.3279 | N55: =M55/L55 -> 79.709674 | O55: =L55-I55 -> 0 | P55: =N55-K55 -> -10.366662 | Q55: =N55/K55 -> 0.88491248 | S55: =S39 -> 0.16666667 | T55: =INDEX(T39:T54,COUNTA(T39:T54)) -> 0.63435185 | AA55: =M55-J55 -> -226.33879 | AB55: =M55/J55 -> 0.88491248
A56: 涼麵二線 | B56: 便當 | C56: 經典滷肉飯 | E56: 47.37 | F56: 1700 | G56: =E56*F56 -> 80529 | I56: 21 | J56: 2000 | K56: =J56/I56 -> 95.238095 | L56: 21 | M56: =F56/V56*60 -> 1770.3211 | N56: =M56/L56 -> 84.301004 | O56: =L56-I56 -> 0 | P56: =N56-K56 -> -10.937091 | Q56: =N56/K56 -> 0.88516054 | R56: =Q72 -> 0.88406106 | S56: 0.16693287 | T56: 0.20694444 | V56: 57.616667 | AA56: =M56-J56 -> -229.67891 | AB56: =M56/J56 -> 0.88516054 | AC56: =AB72 -> 0.88406106
B57: 微波主食 | C57: 妮妮家漢堡排 | E57: 57.3 | F57: 346 | G57: =E57*F57 -> 19825.8 | I57: 20 | J57: 2000 | K57: =J57/I57 -> 100 | L57: 20 | M57: =F57/V57*60 -> 1761.8105 | N57: =M57/L57 -> 88.090523 | O57: =L57-I57 -> 0 | P57: =N57-K57 -> -11.909477 | Q57: =N57/K57 -> 0.88090523 | S57: 0.21056713 | T57: 0.21875 | U57: 5.2166667 | V57: 11.783333 | AA57: =M57-J57 -> -238.18953 | AB57: =M57/J57 -> 0.88090523
B58: 便當 | C58: 海陸雙拼肉肉餐盒 | E58: 59.54 | F58: 3807 | G58: =E58*F58 -> 226668.78 | I58: 23 | J58: 2000 | K58: =J58/I58 -> 86.956522 | L58: 23 | M58: =F58/V58*60 -> 1768.1848 | N58: =M58/L58 -> 76.877598 | O58: =L58-I58 -> 0 | P58: =N58-K58 -> -10.078924 | Q58: =N58/K58 -> 0.88409238 | S58: 0.22222222 | T58: 0.31193287 | U58: 5 | V58: 129.18333 | AA58: =M58-J58 -> -231.81525 | AB58: =M58/J58 -> 0.88409238
B59: 便當 | C59: 蒜味奶燉豬紅米營養餐 | E59: 59.14 | F59: 5655 | G59: =E59*F59 -> 334436.7 | I59: 23 | J59: 2000 | K59: =J59/I59 -> 86.956522 | L59: 23 | M59: =F59/V59*60 -> 1769.4915 | N59: =M59/L59 -> 76.934414 | O59: =L59-I59 -> 0 | P59: =N59-K59 -> -10.022108 | Q59: =N59/K59 -> 0.88474576 | S59: 0.31545139 | T59: 0.44861111 | U59: 5.0666667 | V59: 191.75 | AA59: =M59-J59 -> -230.50847 | AB59: =M59/J59 -> 0.88474576
B60: 便當 | C60: 照燒豬排纖食餐盒 | E60: 59.36 | F60: 1223 | G60: =E60*F60 -> 72597.28 | I60: 20 | J60: 2000 | K60: =J60/I60 -> 100 | L60: 20 | M60: =F60/V60*60 -> 1768.9032 | N60: =M60/L60 -> 88.445159 | O60: =L60-I60 -> 0 | P60: =N60-K60 -> -11.554841 | Q60: =N60/K60 -> 0.88445159 | S60: 0.45277778 | T60: 0.48158565 | U60: 6 | V60: 41.483333 | W60: 0.48158565 | X60: 0.52083333 | AA60: =M60-J60 -> -231.09683 | AB60: =M60/J60 -> 0.88445159
B61: 便當 | C61: 蔬活腿排補力餐盒 | E61: 71.55 | F61: 2716 | G61: =E61*F61 -> 194329.8 | I61: 23 | J61: 2000 | K61: =J61/I61 -> 86.956522 | L61: 23 | M61: =F61/V61*60 -> 1770.0217 | N61: =M61/L61 -> 76.957466 | O61: =L61-I61 -> 0 | P61: =N61-K61 -> -9.9990555 | Q61: =N61/K61 -> 0.88501086 | S61: 0.52083333 | T61: 0.58476852 | U61: 56.516667 | V61: 92.066667 | AA61: =M61-J61 -> -229.97828 | AB61: =M61/J61 -> 0.88501086
B72: 平均 | I72: =AVERAGE(I56:I71) -> 21.666667 | J72: =AVERAGE(J56:J71) -> 2000 | K72: =J72/I72 -> 92.307692 | L72: =AVERAGE(L56:L71) -> 21.666667 | M72: =AVERAGE(M56:M71) -> 1768.1221 | N72: =M72/L72 -> 81.605636 | O72: =L72-I72 -> 0 | P72: =N72-K72 -> -10.702056 | Q72: =N72/K72 -> 0.88406106 | S72: =S56 -> 0.16693287 | T72: =INDEX(T56:T71,COUNTA(T56:T71)) -> 0.58476852 | AA72: =M72-J72 -> -231.87788 | AB72: =M72/J72 -> 0.88406106
A73: 涼麵三線 | B73: 季節調理麵 | C73: 大滿足香辣涼麵 | E73: 38.63 | F73: 1870 | G73: =E73*F73 -> 72238.1 | I73: 20 | J73: 3600 | K73: =J73/I73 -> 180 | L73: 20 | M73: =F73/V73*60 -> 3253.7458 | N73: =M73/L73 -> 162.68729 | O73: =L73-I73 -> 0 | P73: =N73-K73 -> -17.312711 | Q73: =N73/K73 -> 0.90381827 | R73: =Q89 -> 0.8882667 | S73: 0.16666667 | T73: 0.19061343 | V73: 34.483333 | AA73: =M73-J73 -> -346.25423 | AB73: =M73/J73 -> 0.90381827 | AC73: =AB89 -> 0.8882667
B74: 季節調理麵 | C74: 大滿足麻醬涼麵 | E74: 38 | F74: 2570 | G74: =E74*F74 -> 97660 | I74: 21 | J74: 3600 | K74: =J74/I74 -> 171.42857 | L74: 21 | M74: =F74/V74*60 -> 3255.4539 | N74: =M74/L74 -> 155.02161 | O74: =L74-I74 -> 0 | P74: =N74-K74 -> -16.406957 | Q74: =N74/K74 -> 0.90429275 | S74: 0.19375 | T74: 0.22664352 | U74: 4.5166667 | V74: 47.366667 | AA74: =M74-J74 -> -344.54609 | AB74: =M74/J74 -> 0.90429275
B75: 季節調理麵 | C75: 台式麻醬涼麵 | E75: 31.27 | F75: 1219 | G75: =E75*F75 -> 38118.13 | I75: 19 | J75: 3600 | K75: =J75/I75 -> 189.47368 | L75: 19 | M75: =F75/V75*60 -> 3168.5199 | N75: =M75/L75 -> 166.7642 | O75: =L75-I75 -> 0 | P75: =N75-K75 -> -22.709481 | Q75: =N75/K75 -> 0.8801444 | S75: 0.22986111 | T75: 0.2458912 | U75: 4.6333333 | V75: 23.083333 | AA75: =M75-J75 -> -431.48014 | AB75: =M75/J75 -> 0.8801444
B76: 季節調理麵 | C76: 椒麻香蔥雞涼拌麵 | E76: 37.94 | F76: 2774 | G76: =E76*F76 -> 105245.56 | I76: 21 | J76: 3600 | K76: =J76/I76 -> 171.42857 | L76: 21 | M76: =F76/V76*60 -> 3169.2796 | N76: =M76/L76 -> 150.91808 | O76: =L76-I76 -> 0 | P76: =N76-K76 -> -20.510496 | Q76: =N76/K76 -> 0.88035544 | S76: 0.2496412 | T76: 0.28611111 | U76: 5.4 | V76: 52.516667 | AA76: =M76-J76 -> -430.72041 | AB76: =M76/J76 -> 0.88035544
B77: 季節調理麵 | C77: 和風匠製胡麻涼麵 | E77: 32.06 | F77: 1115 | G77: =E77*F77 -> 35746.9 | I77: 19 | J77: 3600 | K77: =J77/I77 -> 189.47368 | L77: 19 | M77: =F77/V77*60 -> 3168.1137 | N77: =M77/L77 -> 166.74282 | O77: =L77-I77 -> 0 | P77: =N77-K77 -> -22.73086 | Q77: =N77/K77 -> 0.88003157 | S77: 0.28958333 | T77: 0.30424769 | U77: 5 | V77: 21.116667 | AA77: =M77-J77 -> -431.88635 | AB77: =M77/J77 -> 0.88003157
B78: 微波小吃 | C78: 韓式部隊鍋 | E78: 57.73 | F78: 1464 | G78: =E78*F78 -> 84516.72 | I78: 22 | J78: 1800 | K78: =J78/I78 -> 81.818182 | L78: 22 | M78: =F78/V78*60 -> 1593.7103 | N78: =M78/L78 -> 72.441378 | O78: =L78-I78 -> 0 | P78: =N78-K78 -> -9.376804 | Q78: =N78/K78 -> 0.88539462 | S78: 0.30763889 | T78: 0.34591435 | U78: 4.8833333 | V78: 55.116667 | AA78: =M78-J78 -> -206.28969 | AB78: =M78/J78 -> 0.88539462
B79: 微波小吃 | C79: 日式壽喜燒 | E79: 57.73 | F79: 1643 | G79: =E79*F79 -> 94850.39 | I79: 22 | J79: 1800 | K79: =J79/I79 -> 81.818182 | L79: 22 | M79: =F79/V79*60 -> 1593.4267 | N79: =M79/L79 -> 72.428487 | O79: =L79-I79 -> 0 | P79: =N79-K79 -> -9.3896944 | Q79: =N79/K79 -> 0.88523707 | S79: 0.34939815 | T79: 0.39236111 | U79: 5.0166667 | V79: 61.866667 | AA79: =M79-J79 -> -206.57328 | AB79: =M79/J79 -> 0.88523707
B80: 季節調理麵 | C80: 東京豚骨風味拉麵 | E80: 71.84 | F80: 1947 | G80: =E80*F80 -> 139872.48 | I80: 19 | J80: 1800 | K80: =J80/I80 -> 94.736842 | L80: 19 | M80: =F80/V80*60 -> 1594.0869 | N80: =M80/L80 -> 83.899309 | O80: =L80-I80 -> 0 | P80: =N80-K80 -> -10.837533 | Q80: =N80/K80 -> 0.88560382 | S80: 0.39583333 | T80: 0.44672454 | U80: 5 | V80: 73.283333 | W80: 0.44672454 | X80: 0.48611111 | AA80: =M80-J80 -> -205.91312 | AB80: =M80/J80 -> 0.88560382
B81: 季節調理麵 | C81: 醬油叉燒拉麵 | E81: 72.4 | F81: 2906 | G81: =E81*F81 -> 210394.4 | I81: 18 | J81: 1800 | K81: =J81/I81 -> 100 | L81: 18 | M81: =F81/V81*60 -> 1593.2988 | N81: =M81/L81 -> 88.516601 | O81: =L81-I81 -> 0 | P81: =N81-K81 -> -11.483399 | Q81: =N81/K81 -> 0.88516601 | S81: 0.48611111 | T81: 0.56210648 | U81: 56.716667 | V81: 109.43333 | AA81: =M81-J81 -> -206.70119 | AB81: =M81/J81 -> 0.88516601
B82: 季節調理麵 | C82: 濃厚豚骨拉麵 | E82: 79.19 | F82: 4045 | G82: =E82*F82 -> 320323.55 | I82: 17 | J82: 1800 | K82: =J82/I82 -> 105.88235 | L82: 17 | M82: =F82/V82*60 -> 1593.5653 | N82: =M82/L82 -> 93.739137 | O82: =L82-I82 -> 0 | P82: =N82-K82 -> -12.143216 | Q82: =N82/K82 -> 0.88531407 | S82: 0.56527778 | T82: 0.67104167 | U82: 4.5666667 | V82: 152.3 | AA82: =M82-J82 -> -206.43467 | AB82: =M82/J82 -> 0.88531407
B89: 平均 | I89: =AVERAGE(I73:I88) -> 19.8 | J89: =AVERAGE(J73:J88) -> 2700 | K89: =J89/I89 -> 136.36364 | L89: =AVERAGE(L73:L88) -> 19.8 | M89: =AVERAGE(M73:M88) -> 2398.3201 | N89: =M89/L89 -> 121.12728 | O89: =L89-I89 -> 0 | P89: =N89-K89 -> -15.236359 | Q89: =N89/K89 -> 0.8882667 | S89: =S73 -> 0.16666667 | T89: =INDEX(T73:T88,COUNTA(T73:T88)) -> 0.67104167 | AA89: =M89-J89 -> -301.67992 | AB89: =M89/J89 -> 0.8882667
A90: 自動包裝機 | B90: 4℃-壽司手卷 | C90: 鮮蝦稻荷壽司組 | E90: 30.84 | F90: 1297 | G90: =E90*F90 -> 39999.48 | I90: 15 | J90: 3000 | K90: =J90/I90 -> 200 | L90: 15 | M90: =F90/V90*60 -> 2618.7325 | N90: =M90/L90 -> 174.58216 | O90: =L90-I90 -> 0 | P90: =N90-K90 -> -25.417835 | Q90: =N90/K90 -> 0.87291082 | R90: =Q106 -> 0.87967215 | S90: 0.32380787 | T90: 0.34444444 | U90: 5.2833333 | V90: 29.716667 | AA90: =M90-J90 -> -381.26753 | AB90: =M90/J90 -> 0.87291082 | AC90: =AB106 -> 0.87967215
...

Sheet 1129
B1: 屏榮 大溪廠組合室生產人時性分析
B3: 日期 | C3: 114.11.29星期六 | E3: 訂單量 | F3: ='1129(18度C)'!D1+'1129(4度C)'!D1 -> 178370 | H3: 營業額 | I3: ='1129(18度C)'!F1+'1129(4度C)'!F1 -> 5795325.3
B4: 人時性 | C4: 項目 | E4: ➀ | G4: ➁ | I4: ➂ | K4: ④ | M4: ⑤
C5: 組合室 | E5: 全溫層 | G5: 4度C-各編組展開(一配) | I5: 4度C-各編組展開(二配) | K5: 18度C-各編組展開(一配) | M5: 18度C-各編組展開(二配)
C6: 排關平均 | E6: =AVERAGE(D13:O13,D27:X27) -> 454.7448 | F6: =AVERAGE(#REF!,D13:K13) -> #REF! | G6: =AVERAGE(D13:K13) -> 181.85889 | I6: =AVERAGE(L13:O13) -> 95.202399 | K6: =AVERAGE(D27:O27) -> 594.4684 | M6: =AVERAGE(P27:X27) -> 784.98901
C7: 實績平均 | E7: =AVERAGE(D14:O14,D28:X28) -> 401.30422 | F7: =AVERAGE(#REF!,D14:K14) -> #REF! | G7: =AVERAGE(D14:K14) -> 161.38623 | I7: =AVERAGE(L14:O14) -> 84.180752 | K7: =AVERAGE(D28:O28) -> 523.92564 | M7: =AVERAGE(P28:X28) -> 692.36883
C8: 達成率平均 | E8: =AVERAGE(D15:O15,D29:X29) -> 0.882846 | F8: =AVERAGE(D15:K15,#REF!) -> #REF! | G8: =AVERAGE(D15:K15) -> 0.88591442 | I8: =AVERAGE(L15:O15) -> 0.88425181 | K8: =AVERAGE(D29:O29) -> 0.88047641 | M8: =AVERAGE(P29:X29) -> 0.8813053 | O8: ※現行日本鮮食廠以達成率80%為基本(即為現行KPI)
B10: 溫層 | D10: ➁4度C-各編組展開 | L10: ➂4度C-各編組展開
B11: 編組 | D11: 1 | E11: 2 | F11: 3 | G11: 4 | H11: 5 | I11: 6 | J11: 7 | K11: 8 | L11: 1 | M11: 2 | N11: 3 | O11: 4
D12: 便當一線 | E12: 便當二線 | F12: 涼麵一線 | G12: 涼麵二線 | H12: 涼麵三線 | I12: 自動包裝機 | J12: 自動包裝機2 | K12: 自動包裝機3 | L12: 便當一線 | M12: 便當二線 | N12: 涼麵一線 | O12: 涼麵二線
B13: 人時性 | C13: 排關 | D13: 120.75472 | E13: 81.300813 | F13: 92.913386 | G13: 89.552239 | H13: 136.36364 | I13: 232.33333 | J13: - | K13: 519.79412 | L13: - | M13: - | N13: 103.44828 | O13: 86.956522
C14: 實績 | D14: 107.27134 | E14: 72.141354 | F14: 82.061549 | G14: 79.033549 | H14: 121.12211 | I14: 204.37596 | J14: - | K14: 463.69775 | L14: - | M14: - | N14: 91.447464 | O14: 76.91404
C15: 達成率 | D15: =D14/D13 -> 0.88834077 | E15: =E14/E13 -> 0.88733866 | F15: =F14/F13 -> 0.8832048 | G15: =G14/G13 -> 0.8825413 | H15: =H14/H13 -> 0.8882288 | I15: =I14/I13 -> 0.87966698 | J15: - | K15: =K14/K13 -> 0.89207965 | L15: - | M15: - | N15: =N14/N13 -> 0.88399215 | O15: =O14/O13 -> 0.88451146
B16: 作業 時間 | C16: 開始 | D16: 0.25 | E16: 0.25 | F16: 0.25015046 | G16: 0.25 | H16: 0.25019676 | I16: 0.30375 | J16: - | K16: 0.31280093 | L16: - | M16: - | N16: 0.70847222 | O16: 0.70833333
C17: 結束 | D17: 0.52927083 | E17: 0.58125 | F17: 0.57047454 | G17: 0.54408565 | H17: 0.60289352 | I17: 0.50069444 | J17: - | K17: 0.43077546 | L17: - | M17: - | N17: 0.79875 | O17: 0.8341088
B18: 配置人數 | D18: 17.666667 | E18: 24.6 | F18: 21.166667 | G18: 22.333333 | H18: 19.8 | I18: 13.5 | J18: - | K18: 6.8 | L18: - | M18: - | N18: 19.333333 | O18: 23
B19: 主要應用設備 | D19: L型封口機 | E19: ET-55 | F19: ET-55 | G19: ET-55 | H19: ET-600 | I19: 伺服包裝機 | J19: 伺服包裝機 | K19: 伺服包裝機 | L19: L型封口機 | M19: ET-55 | N19: ET-55 | O19: ET-55
B20: 次要應用設備 | D20: 伺服包裝機 | H20: 伺服包裝機
B21: 備註 | H21: 涼麵+烤飯糰 | I21: 大口飯糰線 | K21: 烤飯糰+手卷
B24: 溫層 | D24: ➃18度C-各編組展開 (一配) | P24: ⑤18度C-各編組展開 (二配)
B25: 編組 | D25: 1 | E25: 2 | F25: 3 | G25: 4 | H25: 5 | I25: 6 | J25: 7 | K25: 8 | L25: 9 | M25: 10 | N25: 11 | O25: 12 | P25: 1 | Q25: 2 | R25: 3 | S25: 4 | T25: 5 | U25: 6 | V25: 7 | W25: 8 | X25: 9
D26: 便當一線 | E26: 涼麵一線 | F26: 涼麵三線 | G26: 自動包裝機 | H26: 自動包裝機2 | I26: 自動包裝機3 | J26: 味付飯糰線B | K26: (舊) 3300型飯糰線 | L26: 3000型飯糰線 | M26: (新) 3300型飯糰機 | N26: GKK3600型 飯糰機 | O26: GKK3600型 飯糰機2 | P26: 自動包裝機 | Q26: 自動包裝機2 | R26: 自動包裝機3 | S26: 味付飯糰線B | T26: (舊) 3300型飯糰線 | U26: 3000型飯糰線 | V26: (新) 3300型飯糰機 | W26: GKK3600型 飯糰機 | X26: GKK3600型 飯糰機2
B27: 人時性 | C27: 排關 | D27: 211.76471 | E27: - | F27: - | G27: 313.04348 | H27: 433.33333 | I27: 416.66667 | J27: - | K27: - | L27: - | M27: 776.47059 | N27: 1150 | O27: 860 | P27: 285.71429 | Q27: - | R27: - | S27: - | T27: 795 | U27: - | V27: 825 | W27: 969.23077 | X27: 1050
C28: 實績 | D28: 183.32564 | E28: - | F28: - | G28: 271.82047 | H28: 384.72802 | I28: 372 | J28: - | K28: - | L28: - | M28: 693.20225 | N28: 1000.5447 | O28: 761.85836 | P28: 249.16518 | Q28: - | R28: - | S28: - | T28: 706.46376 | U28: - | V28: 734.91879 | W28: 857.49444 | X28: 913.80196
C29: 達成率 | D29: =D28/D27 -> 0.86570443 | E29: - | F29: - | G29: =G28/G27 -> 0.86831539 | H29: =H28/H27 -> 0.88783389 | I29: =I28/I27 -> 0.8928 | J29: - | K29: - | L29: - | M29: =M28/M27 -> 0.89276047 | N29: =N28/N27 -> 0.8700389 | O29: =O28/O27 -> 0.88588181 | P29: =P28/P27 -> 0.87207814 | Q29: - | R29: - | S29: - | T29: =T28/T27 -> 0.88863366 | U29: - | V29: =V28/V27 -> 0.89081065 | W29: =W28/W27 -> 0.88471648 | X29: =X28/X27 -> 0.87028758
B30: 作業 時間 | C30: 開始 | D30: 0.36736111 | E30: - | F30: - | G30: 0.25 | H30: 0.25 | I30: 0.43402778 | J30: - | K30: - | L30: - | M30: 0.25012731 | N30: 0.25 | O30: 0.25 | P30: 0.70833333 | Q30: - | R30: - | S30: - | T30: 0.70849537 | U30: - | V30: 0.70833333 | W30: 0.70833333 | X30: 0.70853009
C31: 結束 | D31: 0.41333333 | E31: - | F31: - | G31: 0.30010417 | H31: 0.30763889 | I31: 0.44733796 | J31: - | K31: - | L31: - | M31: 0.38416667 | N31: 0.43825231 | O31: 0.36875 | P31: 0.81957176 | Q31: - | R31: - | S31: - | T31: 0.87916667 | U31: - | V31: 0.89930556 | W31: 1.0050347 | X31: 1.0050463
B32: 配置人數 | D32: 17 | E32: - | F32: - | G32: 11.5 | H32: 6 | I32: 6 | J32: - | K32: - | L32: - | M32: 4.25 | N32: 3 | O32: 3.75 | P32: 12.6 | Q32: - | R32: - | S32: - | T32: 4 | U32: - | V32: 4 | W32: 3.25 | X32: 3.3333333
B33: 主要應用設備 | D33: 伺服包裝機 | E33: ET-55 | F33: ET-600 | G33: 夾心型 | H33: 伺服包裝機 | I33: 伺服包裝機 | J33: 夾心型 | K33: 3300型 | L33: 3300型 | M33: 3300型 | N33: GKK | O33: GKK | P33: 夾心型 | Q33: 伺服包裝機 | R33: 伺服包裝機 | S33: 夾心型 | T33: 3300型 | U33: 3300型 | V33: 3300型 | W33: GKK | X33: GKK
B34: 次要應用設備
B35: 備註

Sheet 1129(18度C)
A1: 大溪廠日報分析 | C1: 總生產量 | D1: =SUM(F5:F208) -> 96693 | E1: 營業額 | F1: =SUM(G5:G208) -> 1899866 | G1: 出勤人數 | H1: =L21+L38+L55+L72+L89+L106+L123+L140+L157+L174+L191+L208 -> 78.683333 | I1: 產線配置圖 | L1: 生產實績 | O1: 人時性差異分析 | S1: 日報登錄 | Y1: 分析說明 | AA1: 產能差異分析
A2: 45990 | C2: 人時性 | D2: =AVERAGE(N21,N38,N55,N72,N89,N106,N123,N140,N157,N174,N191,N208) -> 594.1103 | E2: 平均廠價 | F2: =F1/D1 -> 19.648433 | G2: 多次生產數 | H2: =COUNT(H5:H208) -> 3
A3: 線別 | B3: 品類 | C3: 品名 | E3: 廠價 | F3: 生產量 | G3: 營收 | H3: 多次 生產 | I3: 人數 | J3: 產能/時 | K3: 人時性 | L3: 人數 | M3: 產能/時 | N3: 人時性 | O3: 人數 | P3: 人時性 | Q3: 達成率 | R3: 達成率 平均 | S3: 生產時間 | U3: 換線、休息/分 | V3: 稼動時間/分 | W3: 休息時間 | Y3: (屏榮回填) | AA3: 產能/時 | AB3: 達成率 | AC3: 達成率平均
S4: 開始 | T4: 結束 | W4: 開始 | X4: 結束
A5: 便當一線 | B5: 18℃-壽司手卷 | C5: 一配海饌雙手卷 | E5: 29.85 | F5: 1636 | G5: =E5*F5 -> 48834.6 | I5: 17 | J5: 3600 | K5: =J5/I5 -> 211.76471 | L5: 17 | M5: =F5/V5*60 -> 3117.8401 | N5: =M5/L5 -> 183.40236 | O5: =L5-I5 -> 0 | P5: =N5-K5 -> -28.362345 | Q5: =N5/K5 -> 0.8660667 | R5: =Q21 -> 0.86570443 | S5: 0.36736111 | T5: 0.38922454 | U5: 4.8333333 | V5: 31.483333 | AA5: =M5-J5 -> -482.15987 | AB5: =M5/J5 -> 0.8660667 | AC5: =AB21 -> 0.86570443
B6: 18℃-壽司手卷 | C6: 一配雙饗雙手卷 | E6: 29.52 | F6: 1568 | G6: =E6*F6 -> 46287.36 | I6: 17 | J6: 3600 | K6: =J6/I6 -> 211.76471 | L6: 17 | M6: =F6/V6*60 -> 3115.2318 | N6: =M6/L6 -> 183.24893 | O6: =L6-I6 -> 0 | P6: =N6-K6 -> -28.515777 | Q6: =N6/K6 -> 0.86534216 | S6: 0.39236111 | T6: 0.41333333 | U6: 4.5166667 | V6: 30.2 | AA6: =M6-J6 -> -484.76821 | AB6: =M6/J6 -> 0.86534216
B21: 平均 | I21: =AVERAGE(I5:I20) -> 17 | J21: =AVERAGE(J5:J20) -> 3600 | K21: =J21/I21 -> 211.76471 | L21: =AVERAGE(L5:L20) -> 17 | M21: =AVERAGE(M5:M20) -> 3116.536 | N21: =M21/L21 -> 183.32564 | O21: =L21-I21 -> 0 | P21: =N21-K21 -> -28.439061 | Q21: =N21/K21 -> 0.86570443 | S21: =S5 -> 0.36736111 | T21: =INDEX(T5:T20,COUNTA(T5:T20)) -> 0.41333333 | AA21: =M21-J21 -> -483.46404 | AB21: =M21/J21 -> 0.86570443
A22: 自動包裝機 | B22: 18℃-壽司手卷 | C22: 一配長野稻荷壽司 | E22: 25.64 | F22: 1010 | G22: =E22*F22 -> 25896.4 | I22: 11 | J22: 3600 | K22: =J22/I22 -> 327.27273 | L22: 11 | M22: =F22/V22*60 -> 3145.3287 | N22: =M22/L22 -> 285.93897 | O22: =L22-I22 -> 0 | P22: =N22-K22 -> -41.333753 | Q22: =N22/K22 -> 0.87370242 | R22: =Q38 -> 0.86831539 | S22: 0.25 | T22: 0.26337963 | V22: 19.266667 | AA22: =M22-J22 -> -454.67128 | AB22: =M22/J22 -> 0.87370242 | AC22: =AB38 -> 0.86831539
B23: 18℃-飯糰 | C23: 一配兩粒飯糰(鮪魚.焦糖鮭魚) | E23: 28.57 | F23: 2493 | G23: =E23*F23 -> 71225.01 | I23: 12 | J23: 3600 | K23: =J23/I23 -> 300 | L23: 12 | M23: =F23/V23*60 -> 3106.5421 | N23: =M23/L23 -> 258.8785 | O23: =L23-I23 -> 0 | P23: =N23-K23 -> -41.121495 | Q23: =N23/K23 -> 0.86292835 | S23: 0.26666667 | T23: 0.30010417 | U23: 4.7333333 | V23: 48.15 | AA23: =M23-J23 -> -493.45794 | AB23: =M23/J23 -> 0.86292835
B38: 平均 | I38: =AVERAGE(I22:I37) -> 11.5 | J38: =AVERAGE(J22:J37) -> 3600 | K38: =J38/I38 -> 313.04348 | L38: =AVERAGE(L22:L37) -> 11.5 | M38: =AVERAGE(M22:M37) -> 3125.9354 | N38: =M38/L38 -> 271.82047 | O38: =L38-I38 -> 0 | P38: =N38-K38 -> -41.22301 | Q38: =N38/K38 -> 0.86831539 | S38: =S22 -> 0.25 | T38: =INDEX(T22:T37,COUNTA(T22:T37)) -> 0.30010417 | AA38: =M38-J38 -> -474.06461 | AB38: =M38/J38 -> 0.86831539
A39: 自動包裝機2 | B39: 18℃-壽司手卷 | C39: 一配雙鬆細卷 | E39: 14.03 | F39: 1008 | G39: =E39*F39 -> 14142.24 | I39: 6 | J39: 2600 | K39: =J39/I39 -> 433.33333 | L39: 6 | M39: =F39/V39*60 -> 2309.8663 | N39: =M39/L39 -> 384.97772 | O39: =L39-I39 -> 0 | P39: =N39-K39 -> -48.355612 | Q39: =N39/K39 -> 0.88841013 | R39: =Q55 -> 0.88783389 | S39: 0.25 | T39: 0.26818287 | V39: 26.183333 | AA39: =M39-J39 -> -290.13367 | AB39: =M39/J39 -> 0.88841013 | AC39: =AB55 -> 0.88783389
B40: 18℃-壽司手卷 | C40: 一配香濃起司蟹風味棒細卷 | E40: 17.73 | F40: 807 | G40: =E40*F40 -> 14308.11 | I40: 6 | J40: 2600 | K40: =J40/I40 -> 433.33333 | L40: 6 | M40: =F40/V40*60 -> 2307.5457 | N40: =M40/L40 -> 384.59095 | O40: =L40-I40 -> 0 | P40: =N40-K40 -> -48.742388 | Q40: =N40/K40 -> 0.88751757 | S40: 0.27153935 | T40: 0.28611111 | U40: 4.8333333 | V40: 20.983333 | AA40: =M40-J40 -> -292.45433 | AB40: =M40/J40 -> 0.88751757
B41: 18℃-壽司手卷 | C41: 一配經典鮪魚沙拉細卷 | E41: 14.49 | F41: 1000 | G41: =E41*F41 -> 14490 | I41: 6 | J41: 2600 | K41: =J41/I41 -> 433.33333 | L41: 6 | M41: =F41/V41*60 -> 2307.6923 | N41: =M41/L41 -> 384.61538 | O41: =L41-I41 -> 0 | P41: =N41-K41 -> -48.717949 | Q41: =N41/K41 -> 0.88757396 | S41: 0.28958333 | T41: 0.30763889 | U41: 5 | V41: 26 | AA41: =M41-J41 -> -292.30769 | AB41: =M41/J41 -> 0.88757396
B55: 平均 | I55: =AVERAGE(I39:I54) -> 6 | J55: =AVERAGE(J39:J54) -> 2600 | K55: =J55/I55 -> 433.33333 | L55: =AVERAGE(L39:L54) -> 6 | M55: =AVERAGE(M39:M54) -> 2308.3681 | N55: =M55/L55 -> 384.72802 | O55: =L55-I55 -> 0 | P55: =N55-K55 -> -48.605316 | Q55: =N55/K55 -> 0.88783389 | S55: =S39 -> 0.25 | T55: =INDEX(T39:T54,COUNTA(T39:T54)) -> 0.30763889 | AA55: =M55-J55 -> -291.6319 | AB55: =M55/J55 -> 0.88783389
A56: 自動包裝機3 | B56: 18℃-壽司手卷 | C56: 一配明太子玉子脆卷 | E56: 19.7 | F56: 713 | G56: =E56*F56 -> 14046.1 | I56: 6 | J56: 2500 | K56: =J56/I56 -> 416.66667 | L56: 6 | M56: =F56/V56*60 -> 2232 | N56: =M56/L56 -> 372 | O56: =L56-I56 -> 0 | P56: =N56-K56 -> -44.666667 | Q56: =N56/K56 -> 0.8928 | R56: =Q72 -> 0.8928 | S56: 0.43402778 | T56: 0.44733796 | U56: 4.6833333 | V56: 19.166667 | AA56: =M56-J56 -> -268 | AB56: =M56/J56 -> 0.8928 | AC56: =AB72 -> 0.8928
B72: 平均 | I72: =AVERAGE(I56:I71) -> 6 | J72: =AVERAGE(J56:J71) -> 2500 | K72: =J72/I72 -> 416.66667 | L72: =AVERAGE(L56:L71) -> 6 | M72: =AVERAGE(M56:M71) -> 2232 | N72: =M72/L72 -> 372 | O72: =L72-I72 -> 0 | P72: =N72-K72 -> -44.666667 | Q72: =N72/K72 -> 0.8928 | S72: =S56 -> 0.43402778 | T72: =INDEX(T56:T71,COUNTA(T56:T71)) -> 0.44733796 | AA72: =M72-J72 -> -268 | AB72: =M72/J72 -> 0.8928
A73: (新) 3300型飯糰機 | B73: 18℃-飯糰 | C73: 一配照燒雞肉飯糰 | E73: 21.45 | F73: 1810 | G73: =E73*F73 -> 38824.5 | I73: 4 | J73: 3300 | K73: =J73/I73 -> 825 | L73: 4 | M73: =F73/V73*60 -> 2949.751 | N73: =M73/L73 -> 737.43775 | O73: =L73-I73 -> 0 | P73: =N73-K73 -> -87.562245 | Q73: =N73/K73 -> 0.89386395 | R73: =Q89 -> 0.89276047 | S73: 0.25012731 | T73: 0.27569444 | V73: 36.816667 | AA73: =M73-J73 -> -350.24898 | AB73: =M73/J73 -> 0.89386395 | AC73: =AB89 -> 0.89276047
B74: 18℃-飯糰 | C74: 一配壹號醬炙烤牛飯糰 | E74: 22.28 | F74: 937 | G74: =E74*F74 -> 20876.36 | I74: 5 | J74: 3300 | K74: =J74/I74 -> 660 | L74: 5 | M74: =F74/V74*60 -> 2948.6014 | N74: =M74/L74 -> 589.72028 | O74: =L74-I74 -> 0 | P74: =N74-K74 -> -70.27972 | Q74: =N74/K74 -> 0.89351558 | S74: 0.27916667 | T74: 0.29240741 | U74: 5 | V74: 19.066667 | AA74: =M74-J74 -> -351.3986 | AB74: =M74/J74 -> 0.89351558
B75: 18℃-飯糰 | C75: 一配鹽蔥燒肉飯糰 | E75: 17.89 | F75: 2261 | G75: =E75*F75 -> 40449.29 | I75: 4 | J75: 3300 | K75: =J75/I75 -> 825 | L75: 4 | M75: =F75/V75*60 -> 2945.9283 | N75: =M75/L75 -> 736.48208 | O75: =L75-I75 -> 0 | P75: =N75-K75 -> -88.517915 | Q75: =N75/K75 -> 0.89270556 | S75: 0.29583333 | T75: 0.3278125 | U75: 4.9333333 | V75: 46.05 | AA75: =M75-J75 -> -354.07166 | AB75: =M75/J75 -> 0.89270556
B76: 18℃-飯糰 | C76: 一配雞肉飯飯糰 | E76: 16.66 | F76: 3734 | G76: =E76*F76 -> 62208.44 | I76: 4 | J76: 3300 | K76: =J76/I76 -> 825 | L76: 4 | M76: =F76/V76*60 -> 2940.1575 | N76: =M76/L76 -> 735.03937 | O76: =L76-I76 -> 0 | P76: =N76-K76 -> -89.96063 | Q76: =N76/K76 -> 0.89095681 | S76: 0.33125 | T76: 0.38416667 | U76: 4.95 | V76: 76.2 | AA76: =M76-J76 -> -359.84252 | AB76: =M76/J76 -> 0.89095681
B89: 平均 | I89: =AVERAGE(I73:I88) -> 4.25 | J89: =AVERAGE(J73:J88) -> 3300 | K89: =J89/I89 -> 776.47059 | L89: =AVERAGE(L73:L88) -> 4.25 | M89: =AVERAGE(M73:M88) -> 2946.1096 | N89: =M89/L89 -> 693.20225 | O89: =L89-I89 -> 0 | P89: =N89-K89 -> -83.268339 | Q89: =N89/K89 -> 0.89276047 | S89: =S73 -> 0.25012731 | T89: =INDEX(T73:T88,COUNTA(T73:T88)) -> 0.38416667 | AA89: =M89-J89 -> -353.89044 | AB89: =M89/J89 -> 0.89276047
A90: GKK3600型 飯糰機 | B90: 18℃-飯糰 | C90: 一配蔬食鮪魚飯糰 | E90: 18.18 | F90: 1113 | G90: =E90*F90 -> 20234.34 | I90: 3 | J90: 3600 | K90: =J90/I90 -> 1200 | L90: 3 | M90: =F90/V90*60 -> 3110.8696 | N90: =M90/L90 -> 1036.9565 | O90: =L90-I90 -> 0 | P90: =N90-K90 -> -163.04348 | Q90: =N90/K90 -> 0.86413043 | R90: =Q106 -> 0.8700389 | S90: 0.25 | T90: 0.26490741 | V90: 21.466667 | AA90: =M90-J90 -> -489.13043 | AB90: =M90/J90 -> 0.86413043 | AC90: =AB106 -> 0.8700389
B91: 18℃-飯糰 | C91: 一配經典肉鬆飯糰 | E91: 14.03 | F91: 3677 | G91: =E91*F91 -> 51588.31 | I91: 3 | J91: 3000 | K91: =J91/I91 -> 1000 | L91: 3 | M91: =F91/V91*60 -> 2674.7222 | N91: =M91/L91 -> 891.57406 | O91: =L91-I91 -> 0 | P91: =N91-K91 -> -108.42594 | Q91: =N91/K91 -> 0.89157406 | S91: 0.275 | T91: 0.33228009 | U91: 14.533333 | V91: 82.483333 | AA91: =M91-J91 -> -325.27783 | AB91: =M91/J91 -> 0.89157406
B92: 18℃-飯糰 | C92: 一配明太子龍蝦風味沙拉飯糰 | E92: 18.18 | F92: 1848 | G92: =E92*F92 -> 33596.64 | I92: 3 | J92: 3600 | K92: =J92/I92 -> 1200 | L92: 3 | M92: =F92/V92*60 -> 3110.2384 | N92: =M92/L92 -> 1036.7461 | O92: =L92-I92 -> 0 | P92: =N92-K92 -> -163.25386 | Q92: =N92/K92 -> 0.86395512 | S92: 0.34260417 | T92: 0.36736111 | U92: 14.866667 | V92: 35.65 | AA92: =M92-J92 -> -489.76157 | AB92: =M92/J92 -> 0.86395512
B93: 18℃-飯糰 | C93: 一配鮪魚飯糰 | E93: 14.28 | F93: 4463 | G93: =E93*F93 -> 63731.64 | I93: 3 | J93: 3600 | K93: =J93/I93 -> 1200 | L93: 3 | M93: =F93/V93*60 -> 3110.7067 | N93: =M93/L93 -> 1036.9022 | O93: =L93-I93 -> 0 | P93: =N93-K93 -> -163.09777 | Q93: =N93/K93 -> 0.86408519 | S93: 0.37847222 | T93: 0.43825231 | U93: 16 | V93: 86.083333 | AA93: =M93-J93 -> -489.29332 | AB93: =M93/J93 -> 0.86408519
B106: 平均 | I106: =AVERAGE(I90:I105) -> 3 | J106: =AVERAGE(J90:J105) -> 3450 | K106: =J106/I106 -> 1150 | L106: =AVERAGE(L90:L105) -> 3 | M106: =AVERAGE(M90:M105) -> 3001.6342 | N106: =M106/L106 -> 1000.5447 | O106: =L106-I106 -> 0 | P106: =N106-K106 -> -149.45526 | Q106: =N106/K106 -> 0.8700389 | S106: =S90 -> 0.25 | T106: =INDEX(T90:T105,COUNTA(T90:T105)) -> 0.43825231 | AA106: =M106-J106 -> -448.36579 | AB106: =M106/J106 -> 0.8700389
A107: GKK3600型 飯糰機2 | B107: 18℃-飯糰 | C107: 一配博多明太子奶油飯糰 | E107: 25.45 | F107: 779 | G107: =E107*F107 -> 19825.55 | I107: 4 | J107: 3300 | K107: =J107/I107 -> 825 | L107: 4 | M107: =F107/V107*60 -> 2912.1495 | N107: =M107/L107 -> 728.03738 | O107: =L107-I107 -> 0 | P107: =N107-K107 -> -96.962617 | Q107: =N107/K107 -> 0.88246956 | R107: =Q123 -> 0.88588181 | S107: 0.25 | T107: 0.26114583 | V107: 16.05 | AA107: =M107-J107 -> -387.85047 | AB107: =M107/J107 -> 0.88246956 | AC107: =AB123 -> 0.88588181
B108: 18℃-飯糰 | C108: 一配熟成紅鮭飯糰 | E108: 25.03 | F108: 1204 | G108: =E108*F108 -> 30136.12 | I108: 4 | J108: 3300 | K108: =J108/I108 -> 825 | L108: 4 | M108: =F108/V108*60 -> 2912.9032 | N108: =M108/L108 -> 728.22581 | O108: =L108-I108 -> 0 | P108: =N108-K108 -> -96.774194 | Q108: =N108/K108 -> 0.88269795 | S108: 0.27166667 | T108: 0.28888889 | U108: 15.15 | V108: 24.8 | AA108: =M108-J108 -> -387.09677 | AB108: =M108/J108 -> 0.88269795
B109: 18℃-飯糰 | C109: 一配北海道秋鮭親子飯糰 | E109: 24.82 | F109: 1438 | G109: =E109*F109 -> 35691.16 | I109: 4 | J109: 3300 | K109: =J109/I109 -> 825 | L109: 4 | M109: =F109/V109*60 -> 2918.1511 | N109: =M109/L109 -> 729.53777 | O109: =L109-I109 -> 0 | P109: =N109-K109 -> -95.462232 | Q109: =N109/K109 -> 0.8842882 | S109: 0.29960648 | T109: 0.32013889 | U109: 15.433333 | V109: 29.566667 | AA109: =M109-J109 -> -381.84893 | AB109: =M109/J109 -> 0.8842882
B110: 18℃-飯糰 | C110: 一配贅沢鮭魚肚飯糰 | E110: 30 | F110: 2452 | G110: =E110*F110 -> 73560 | I110: 3 | J110: 3000 | K110: =J110/I110 -> 1000 | L110: 3 | M110: =F110/V110*60 -> 2684.6715 | N110: =M110/L110 -> 894.89051 | O110: =L110-I110 -> 0 | P110: =N110-K110 -> -105.10949 | Q110: =N110/K110 -> 0.89489051 | S110: 0.33069444 | T110: 0.36875 | U110: 15.2 | V110: 54.8 | AA110: =M110-J110 -> -315.32847 | AB110: =M110/J110 -> 0.89489051
B123: 平均 | I123: =AVERAGE(I107:I122) -> 3.75 | J123: =AVERAGE(J107:J122) -> 3225 | K123: =J123/I123 -> 860 | L123: =AVERAGE(L107:L122) -> 3.75 | M123: =AVERAGE(M107:M122) -> 2856.9688 | N123: =M123/L123 -> 761.85836 | O123: =L123-I123 -> 0 | P123: =N123-K123 -> -98.141643 | Q123: =N123/K123 -> 0.88588181 | S123: =S107 -> 0.25 | T123: =INDEX(T107:T122,COUNTA(T107:T122)) -> 0.36875 | AA123: =M123-J123 -> -368.03116 | AB123: =M123/J123 -> 0.88588181
A124: 自動包裝機 (二配) | B124: 18℃-飯糰 | C124: 二配兔兔昆布飯糰 | E124: 13.42 | F124: 161 | G124: =E124*F124 -> 2160.62 | I124: 6 | J124: 3600 | K124: =J124/I124 -> 600 | L124: 6 | M124: =F124/V124*60 -> 3220 | N124: =M124/L124 -> 536.66667 | O124: =L124-I124 -> 0 | P124: =N124-K124 -> -63.333333 | Q124: =N124/K124 -> 0.89444444 | R124: =Q140 -> 0.87207814 | S124: 0.70833333 | T124: 0.71041667 | V124: 3 | AA124: =M124-J124 -> -380 | AB124: =M124/J124 -> 0.89444444 | AC124: =AB140 -> 0.87207814
B125: 18℃-壽司手卷 | C125: 二配長野稻荷壽司 | E125: 25.64 | F125: 1332 | G125: =E125*F125 -> 34152.48 | I125: 11 | J125: 3600 | K125: =J125/I125 -> 327.27273 | L125: 11 | M125: =F125/V125*60 -> 3142.3329 | N125: =M125/L125 -> 285.66663 | O125: =L125-I125 -> 0 | P125: =N125-K125 -> -41.6061 | Q125: =N125/K125 -> 0.87287025 | S125: 0.71388889 | T125: 0.73155093 | U125: 5 | V125: 25.433333 | AA125: =M125-J125 -> -457.6671 | AB125: =M125/J125 -> 0.87287025
B126: 18℃-壽司手卷 | C126: 二配雙饗雙手卷 | E126: 29.52 | F126: 1673 | G126: =E126*F126 -> 49386.96 | I126: 17 | J126: 3600 | K126: =J126/I126 -> 211.76471 | L126: 17 | M126: =F126/V126*60 -> 3114.1675 | N126: =M126/L126 -> 183.18633 | O126: =L126-I126 -> 0 | P126: =N126-K126 -> -28.578381 | Q126: =N126/K126 -> 0.86504654 | S126: 0.73472222 | T126: 0.75710648 | U126: 4.5666667 | V126: 32.233333 | AA126: =M126-J126 -> -485.83247 | AB126: =M126/J126 -> 0.86504654
B127: 18℃-壽司手卷 | C127: 二配海饌雙手卷 | E127: 29.85 | F127: 1830 | G127: =E127*F127 -> 54625.5 | I127: 17 | J127: 3600 | K127: =J127/I127 -> 211.76471 | L127: 17 | M127: =F127/V127*60 -> 3114.8936 | N127: =M127/L127 -> 183.22904 | O127: =L127-I127 -> 0 | P127: =N127-K127 -> -28.53567 | Q127: =N127/K127 -> 0.86524823 | S127: 0.76041667 | T127: 0.78489583 | U127: 4.7666667 | V127: 35.25 | AA127: =M127-J127 -> -485.10638 | AB127: =M127/J127 -> 0.86524823
B128: 18℃-飯糰 | C128: 二配兩粒飯糰(鮪魚.焦糖鮭魚) | E128: 28.57 | F128: 2339 | G128: =E128*F128 -> 66825.23 | I128: 12 | J128: 3600 | K128: =J128/I128 -> 300 | L128: 12 | M128: =F128/V128*60 -> 3106.0125 | N128: =M128/L128 -> 258.83438 | O128: =L128-I128 -> 0 | P128: =N128-K128 -> -41.165622 | Q128: =N128/K128 -> 0.86278126 | S128: 0.78819444 | T128: 0.81957176 | U128: 4.75 | V128: 45.183333 | AA128: =M128-J128 -> -493.98746 | AB128: =M128/J128 -> 0.86278126
B140: 平均 | I140: =AVERAGE(I124:I139) -> 12.6 | J140: =AVERAGE(J124:J139) -> 3600 | K140: =J140/I140 -> 285.71429 | L140: =AVERAGE(L124:L139) -> 12.6 | M140: =AVERAGE(M124:M139) -> 3139.4813 | N140: =M140/L140 -> 249.16518 | O140: =L140-I140 -> 0 | P140: =N140-K140 -> -36.549102 | Q140: =N140/K140 -> 0.87207814 | S140: =S124 -> 0.70833333 | T140: =INDEX(T124:T139,COUNTA(T124:T139)) -> 0.81957176 | AA140: =M140-J140 -> -460.51868 | AB140: =M140/J140 -> 0.87207814
A141: (舊) 3300型飯糰線 (二配) | B141: 18℃-飯糰 | C141: 二配三杯醬爆菇菇飯糰 | E141: 16.7 | F141: 2536 | G141: =E141*F141 -> 42351.2 | I141: 3 | J141: 3300 | K141: =J141/I141 -> 1100 | L141: 3 | M141: =F141/V141*60 -> 2939.3432 | N141: =M141/L141 -> 979.78107 | O141: =L141-I141 -> 0 | P141: =N141-K141 -> -120.21893 | Q141: =N141/K141 -> 0.89071006 | R141: =Q157 -> 0.88863366 | S141: 0.70849537 | T141: 0.74444444 | V141: 51.766667 | AA141: =M141-J141 -> -360.65679 | AB141: =M141/J141 -> 0.89071006 | AC141: =AB157 -> 0.88863366
B142: 18℃-飯糰 | C142: 二配油蔥G絲飯糰 | E142: 18.18 | F142: 1071 | G142: =E142*F142 -> 19470.78 | I142: 4 | J142: 3300 | K142: =J142/I142 -> 825 | L142: 4 | M142: =F142/V142*60 -> 2945.4545 | N142: =M142/L142 -> 736.36364 | O142: =L142-I142 -> 0 | P142: =N142-K142 -> -88.636364 | Q142: =N142/K142 -> 0.89256198 | S142: 0.74873843 | T142: 0.76388889 | U142: 6.1833333 | V142: 21.816667 | AA142: =M142-J142 -> -354.54545 | AB142: =M142/J142 -> 0.89256198
B143: 18℃-飯糰 | C143: 二配壹號醬炙烤牛飯糰 | E143: 22.28 | F143: 1750 | G143: =E143*F143 -> 38990 | I143: 5 | J143: 3300 | K143: =J143/I143 -> 660 | L143: 5 | M143: =F143/V143*60 -> 2941.1765 | N143: =M143/L143 -> 588.23529 | O143: =L143-I143 -> 0 | P143: =N143-K143 -> -71.764706 | Q143: =N143/K143 -> 0.8912656 | S143: 0.76756944 | T143: 0.79236111 | U143: 5.3 | V143: 35.7 | AA143: =M143-J143 -> -358.82353 | AB143: =M143/J143 -> 0.8912656
...

Sheet 1129(4度C)
