Workbook

Sheet 1008
B1: 屏榮 大溪廠組合室生產人時性分析
B3: 日期 | C3: 115.10.08星期四 | E3: 訂單量 | F3: ='1008(18度C)'!D1+'1008(4度C)'!D1 -> 111063 | H3: 營業額 | I3: ='1008(18度C)'!F1+'1008(4度C)'!F1 -> 3399634.9
B4: 人時性 | C4: 項目 | E4: ➀ | G4: ➁ | I4: ➂ | K4: ④ | M4: ⑤ | O4: 異常停線 | Q4: 短暫停線
C5: 組合室 | E5: 全溫層 | G5: 4度C-各編組展開(一配) | I5: 4度C-各編組展開(二配) | K5: 18度C-各編組展開(一配) | M5: 18度C-各編組展開(二配) | O5: 合計次數 | P5: 時間 | Q5: 合計次數 | R5: 設備次數
C6: 排關平均 | E6: =AVERAGE(D14:O14,D32:X32) -> 496.38205 | F6: =AVERAGE(#REF!,D14:K14) -> #REF! | G6: =AVERAGE(D14:K14) -> 302.80046 | I6: =AVERAGE(L14:O14) -> 94.325718 | K6: =AVERAGE(D32:O32) -> 717.5 | M6: =AVERAGE(P32:X32) -> 718.26923 | O6: ='1008(4度C)'!Y2 -> 0 | P6: ='1008(4度C)'!Z2 -> 0 | Q6: ='1008(4度C)'!AC2 -> 0 | R6: ='1008(4度C)'!AD2 -> 0
C7: 實績平均 | E7: =AVERAGE(D15:O15,D33:X33) -> 453.17195 | F7: =AVERAGE(#REF!,D15:K15) -> #REF! | G7: =AVERAGE(D15:K15) -> 272.47761 | I7: =AVERAGE(L15:O15) -> 87.622615 | K7: =AVERAGE(D33:O33) -> 657.60962 | M7: =AVERAGE(P33:X33) -> 657.37688
C8: 達成率平均 | E8: =AVERAGE(D16:O16,D34:X34) -> 0.90849086 | F8: =AVERAGE(D16:K16,#REF!) -> #REF! | G8: =AVERAGE(D16:K16) -> 0.89954123 | I8: =AVERAGE(L16:O16) -> 0.92704103 | K8: =AVERAGE(D34:O34) -> 0.91103199 | M8: =AVERAGE(P34:X34) -> 0.90786169
O9: ※現行日本鮮食廠以達成率80%為基本(即為現行KPI)
B11: 溫層 | D11: ➁4度C-各編組展開 | L11: ➂4度C-各編組展開
B12: 編組 | D12: 1 | E12: 2 | F12: 3 | G12: 4 | H12: 5 | I12: 6 | J12: 7 | K12: 8 | L12: 1 | M12: 2 | N12: 3 | O12: 4
D13: 便當一線 | E13: 便當二線 | F13: 涼麵一線 | G13: 涼麵二線 | H13: 涼麵三線 | I13: 自動包裝機 | J13: 自動包裝機2 | K13: 自動包裝機3 | L13: 便當一線 | M13: 便當二線 | N13: 涼麵一線 | O13: 涼麵二線
B14: 人時性 | C14: 排關 | D14: - | E14: 85.245902 | F14: 138.52113 | G14: 88.235294 | H14: - | I14: 502 | J14: 700 | K14: - | L14: - | M14: 101.69492 | N14: 86.956522 | O14: -
C15: 實績 | D15: - | E15: 76.955939 | F15: 123.84347 | G15: 79.672196 | H15: - | I15: 447.88783 | J15: 634.0286 | K15: - | L15: - | M15: 96.742857 | N15: 78.502374 | O15: -
C16: 達成率 | D16: - | E16: =E15/E14 -> 0.90275237 | F16: =F15/F14 -> 0.89404027 | G16: =G15/G14 -> 0.90295155 | H16: - | I16: =I15/I14 -> 0.89220684 | J16: =J15/J14 -> 0.90575514 | K16: - | L16: - | M16: =M15/M14 -> 0.95130476 | N16: =N15/N14 -> 0.9027773 | O16: -
B17: 作業 時間 | C17: 開始 | D17: - | E17: 0.25 | F17: 0.25 | G17: 0.25 | H17: - | I17: 0.25 | J17: 0.25 | K17: - | L17: - | M17: 0.70833333 | N17: 0.70833333 | O17: -
C18: 結束 | D18: - | E18: 0.59618056 | F18: 0.53636574 | G18: 0.55162037 | H18: - | I18: 0.47592593 | J18: 0.29010417 | K18: - | L18: - | M18: 0.77712963 | N18: 0.82528935 | O18: -
B19: 產線異常 (5分鐘以上) | C19: 次數
C20: 時間/分
B21: 短暫停線 (5分鐘以下) | C21: 次數
C22: 設備次數
B23: 配置人數 | D23: - | E23: 20.333333 | F23: 20.714286 | G23: 22.666667 | H23: - | I23: 5.75 | J23: 6 | K23: - | L23: - | M23: 18.666667 | N23: 23 | O23: -
B24: 主要應用設備 | D24: L型封口機 | E24: ET-55 | F24: ET-55 | G24: ET-55 | H24: ET-600 | I24: 伺服包裝機 | J24: 伺服包裝機 | K24: 伺服包裝機 | L24: L型封口機 | M24: ET-55 | N24: ET-55 | O24: ET-55
B25: 次要應用設備 | D25: 伺服包裝機 | H25: 伺服包裝機
B26: 備註 | H26: 涼麵+烤飯糰 | I26: 大口飯糰線 | K26: 烤飯糰+手卷
B29: 溫層 | D29: ➃18度C-各編組展開 (一配) | P29: ⑤18度C-各編組展開 (二配)
B30: 編組 | D30: 1 | E30: 2 | F30: 3 | G30: 4 | H30: 5 | I30: 6 | J30: 7 | K30: 8 | L30: 9 | M30: 10 | N30: 11 | O30: 12 | P30: 1 | Q30: 2 | R30: 3 | S30: 4 | T30: 5 | U30: 6 | V30: 7 | W30: 8 | X30: 9
D31: 便當一線 | E31: 涼麵一線 | F31: 涼麵三線 | G31: 自動包裝機 | H31: 自動包裝機2 | I31: 自動包裝機3 | J31: 味付飯糰線B | K31: (舊) 3300型飯糰線 | L31: 3000型飯糰線 | M31: (新) 3300型飯糰機 | N31: GKK3600型 飯糰機 | O31: GKK3600型 飯糰機2 | P31: 自動包裝機 | Q31: 自動包裝機2 | R31: 自動包裝機3 | S31: 味付飯糰線B | T31: (舊) 3300型飯糰線 | U31: 3000型飯糰線 | V31: (新) 3300型飯糰機 | W31: GKK3600型 飯糰機 | X31: GKK3600型 飯糰機2
B32: 人時性 | C32: 排關 | D32: - | E32: - | F32: - | G32: 327.27273 | H32: - | I32: - | J32: - | K32: - | L32: - | M32: 750 | N32: 920 | O32: 872.72727 | P32: 300 | Q32: - | R32: - | S32: - | T32: - | U32: - | V32: 750 | W32: 923.07692 | X32: 900
C33: 實績 | D33: - | E33: - | F33: - | G33: 287.37698 | H33: - | I33: - | J33: - | K33: - | L33: - | M33: 699.37202 | N33: 846.82886 | O33: 796.86061 | P33: 260.01177 | Q33: - | R33: - | S33: - | T33: - | U33: - | V33: 699.84376 | W33: 847.90871 | X33: 821.74326
C34: 達成率 | D34: - | E34: - | F34: - | G34: =G33/G32 -> 0.87809633 | H34: - | I34: - | J34: - | K34: - | L34: - | M34: =M33/M32 -> 0.93249602 | N34: =N33/N32 -> 0.92046616 | O34: =O33/O32 -> 0.91306945 | P34: =P33/P32 -> 0.86670591 | Q34: - | R34: - | S34: - | T34: - | U34: - | V34: =V33/V32 -> 0.93312502 | W34: =W33/W32 -> 0.91856777 | X34: =X33/X32 -> 0.91304807
B35: 作業 時間 | C35: 開始 | D35: - | E35: - | F35: - | G35: 0.25 | H35: - | I35: - | J35: - | K35: - | L35: - | M35: 0.30833333 | N35: 0.25 | O35: 0.25 | P35: 0.73541667 | Q35: - | R35: - | S35: - | T35: - | U35: - | V35: 0.70833333 | W35: 0.73055556 | X35: 0.72986111
C36: 結束 | D36: - | E36: - | F36: - | G36: 0.47592593 | H36: - | I36: - | J36: - | K36: - | L36: - | M36: 0.36627315 | N36: 0.42565972 | O36: 0.41710648 | P36: 0.74684028 | Q36: - | R36: - | S36: - | T36: - | U36: - | V36: 0.7183912 | W36: 1.0542014 | X36: 1.0447685
B37: 配置人數 | D37: - | E37: - | F37: - | G37: 11 | H37: - | I37: - | J37: - | K37: - | L37: - | M37: 4 | N37: 3.75 | O37: 4.125 | P37: 12 | Q37: - | R37: - | S37: - | T37: - | U37: - | V37: 4 | W37: 3.7142857 | X37: 4
B38: 主要應用設備 | D38: 伺服包裝機 | E38: ET-55 | F38: ET-600 | G38: 夾心型 | H38: 伺服包裝機 | I38: 伺服包裝機 | J38: 夾心型 | K38: 3300型 | L38: 3300型 | M38: 3300型 | N38: GKK | O38: GKK | P38: 夾心型 | Q38: 伺服包裝機 | R38: 伺服包裝機 | S38: 夾心型 | T38: 3300型 | U38: 3300型 | V38: 3300型 | W38: GKK | X38: GKK
B39: 次要應用設備
B40: 備註

Sheet 1008(18度C)
A1: 大溪廠日報分析 | C1: 總生產量 | D1: =SUM(F5:F140) -> 58711 | E1: 營業額 | F1: =SUM(G5:G140) -> 1160231.6 | G1: 出勤人數 | H1: =L21+L38+L55+L72+L89+L106+L123+L140 -> 46.589286 | I1: 產線配置圖 | L1: 生產實績 | O1: 人時性差異分析 | S1: 日報登錄 | Y1: 分析說明 | AA1: 產能差異分析
A2: 46303 | C2: 人時性 | D2: =AVERAGE(N21,N38,N55,N72,N89,N106,N123,N140) -> 657.49325 | E2: 平均廠價 | F2: =F1/D1 -> 19.761742 | G2: 多次生產數 | H2: =COUNT(H5:H140) -> 14
A3: 線別 | B3: 品類 | C3: 品名 | E3: 廠價 | F3: 生產量 | G3: 營收 | H3: 多次 生產 | I3: 人數 | J3: 產能/時 | K3: 人時性 | L3: 人數 | M3: 產能/時 | N3: 人時性 | O3: 人數 | P3: 人時性 | Q3: 達成率 | R3: 達成率 平均 | S3: 生產時間 | U3: 換線、休息/分 | V3: 稼動時間/分 | W3: 休息時間 | Y3: (屏榮回填) | AA3: 產能/時 | AB3: 達成率 | AC3: 達成率平均
S4: 開始 | T4: 結束 | W4: 開始 | X4: 結束
A5: 自動包裝機 | B5: 18℃-壽司手卷 | C5: 一配長野稻荷壽司 | E5: 25.64 | F5: 808 | G5: =E5*F5 -> 20717.12 | I5: 10 | J5: 3600 | K5: =J5/I5 -> 360 | L5: 10 | M5: =F5/V5*60 -> 3216.5296 | N5: =M5/L5 -> 321.65296 | O5: =L5-I5 -> 0 | P5: =N5-K5 -> -38.347045 | Q5: =N5/K5 -> 0.89348043 | R5: =Q21 -> 0.87809633 | S5: 0.25 | T5: 0.26046296 | V5: 15.072145 | AA5: =M5-J5 -> -383.47045 | AB5: =M5/J5 -> 0.89348043 | AC5: =AB21 -> 0.87809633
B6: 18℃-壽司手卷 | C6: 一配經典人氣雙手卷 | E6: 29.52 | F6: 1455 | G6: =E6*F6 -> 42951.6 | I6: 11 | J6: 3600 | K6: =J6/I6 -> 327.27273 | L6: 11 | M6: =F6/V6*60 -> 3158.0118 | N6: =M6/L6 -> 287.09199 | O6: =L6-I6 -> 0 | P6: =N6-K6 -> -40.180741 | Q6: =N6/K6 -> 0.87722551 | S6: 0.26458333 | T6: 0.28377315 | U6: 5.9333333 | V6: 27.643975 | AA6: =M6-J6 -> -441.98815 | AB6: =M6/J6 -> 0.87722551
B7: 18℃-壽司手卷 | C7: 一配鮭鮪海饌雙手卷 | E7: 29.85 | F7: 1735 | G7: =E7*F7 -> 51789.75 | I7: 11 | J7: 3600 | K7: =J7/I7 -> 327.27273 | L7: 11 | M7: =F7/V7*60 -> 3155.4476 | N7: =M7/L7 -> 286.85888 | O7: =L7-I7 -> 0 | P7: =N7-K7 -> -40.41385 | Q7: =N7/K7 -> 0.87651324 | S7: 0.28680556 | T7: 0.30971065 | U7: 5 | V7: 32.990565 | AA7: =M7-J7 -> -444.55235 | AB7: =M7/J7 -> 0.87651324
B8: 18℃-壽司手卷 | C8: 一配青木瓜雞絲泰泰雙手卷 | E8: 30 | F8: 110 | G8: =E8*F8 -> 3300 | I8: 11 | J8: 3600 | K8: =J8/I8 -> 327.27273 | L8: 11 | M8: =F8/V8*60 -> 3157.7073 | N8: =M8/L8 -> 287.0643 | O8: =L8-I8 -> 0 | P8: =N8-K8 -> -40.208428 | Q8: =N8/K8 -> 0.87714091 | S8: 0.31319444 | T8: 0.3146412 | U8: 5.0166667 | V8: 2.0901241 | AA8: =M8-J8 -> -442.29271 | AB8: =M8/J8 -> 0.87714091
B9: 18℃-壽司手卷 | C9: 一配陽光蔬彩雙手卷 | E9: 30.95 | F9: 1764 | G9: =E9*F9 -> 54595.8 | I9: 11 | J9: 3600 | K9: =J9/I9 -> 327.27273 | L9: 11 | M9: =F9/V9*60 -> 3156.729 | N9: =M9/L9 -> 286.97536 | O9: =L9-I9 -> 0 | P9: =N9-K9 -> -40.297363 | Q9: =N9/K9 -> 0.87686917 | S9: 0.31875 | T9: 0.34202546 | U9: 5.9166667 | V9: 33.528377 | AA9: =M9-J9 -> -443.27099 | AB9: =M9/J9 -> 0.87686917
B10: 18℃-飯糰 | C10: 一配兩粒飯糰(鮪魚.焦糖鮭魚) | E10: 28.57 | F10: 523 | G10: =E10*F10 -> 14942.11 | I10: 12 | J10: 3600 | K10: =J10/I10 -> 300 | L10: 12 | M10: =F10/V10*60 -> 3122.4554 | N10: =M10/L10 -> 260.20461 | O10: =L10-I10 -> 0 | P10: =N10-K10 -> -39.795386 | Q10: =N10/K10 -> 0.86734871 | S10: 0.34583333 | T10: 0.35280093 | U10: 5.4833333 | V10: 10.049783 | AA10: =M10-J10 -> -477.54463 | AB10: =M10/J10 -> 0.86734871
B21: 平均 | I21: =AVERAGE(I5:I20) -> 11 | J21: =AVERAGE(J5:J20) -> 3600 | K21: =J21/I21 -> 327.27273 | L21: =AVERAGE(L5:L20) -> 11 | M21: =AVERAGE(M5:M20) -> 3161.1468 | N21: =M21/L21 -> 287.37698 | O21: =L21-I21 -> 0 | P21: =N21-K21 -> -39.895747 | Q21: =N21/K21 -> 0.87809633 | S21: 0.25 | T21: 0.47592593 | AA21: =M21-J21 -> -438.85321 | AB21: =M21/J21 -> 0.87809633
A22: (新) 3300型飯糰機 | B22: 18℃-飯糰 | C22: 一配鮭魚奶油醬油飯糰 | E22: 18.53 | F22: 1043 | G22: =E22*F22 -> 19326.79 | I22: 3 | J22: 3300 | K22: =J22/I22 -> 1100 | L22: 3 | M22: =F22/V22*60 -> 3078.9014 | N22: =M22/L22 -> 1026.3005 | O22: =L22-I22 -> 0 | P22: =N22-K22 -> -73.699532 | Q22: =N22/K22 -> 0.93300043 | R22: =Q38 -> 0.93249602 | S22: 0.30833333 | T22: 0.32244213 | V22: 20.325432 | AA22: =M22-J22 -> -221.0986 | AB22: =M22/J22 -> 0.93300043 | AC22: =AB38 -> 0.93249602
B23: 18℃-飯糰 | C23: 一配熊本麥味噌雞肉飯糰 | E23: 22.95 | F23: 2409 | G23: =E23*F23 -> 55286.55 | I23: 5 | J23: 2700 | K23: =J23/I23 -> 540 | L23: 5 | M23: =F23/V23*60 -> 2516.0747 | N23: =M23/L23 -> 503.21495 | O23: =L23-I23 -> 0 | P23: =N23-K23 -> -36.785055 | Q23: =N23/K23 -> 0.93187953 | S23: 0.32638889 | T23: 0.36627315 | U23: 5.6833333 | V23: 57.446624 | AA23: =M23-J23 -> -183.92527 | AB23: =M23/J23 -> 0.93187953
B38: 平均 | I38: =AVERAGE(I22:I37) -> 4 | J38: =AVERAGE(J22:J37) -> 3000 | K38: =J38/I38 -> 750 | L38: =AVERAGE(L22:L37) -> 4 | M38: =AVERAGE(M22:M37) -> 2797.4881 | N38: =M38/L38 -> 699.37202 | O38: =L38-I38 -> 0 | P38: =N38-K38 -> -50.627984 | Q38: =N38/K38 -> 0.93249602 | S38: 0.30833333 | T38: 0.36627315 | AA38: =M38-J38 -> -202.51194 | AB38: =M38/J38 -> 0.93249602
A39: GKK3600型 飯糰機 | B39: 18℃-飯糰 | C39: 一配北海道秋鮭親子飯糰 | E39: 24.82 | F39: 479 | G39: =E39*F39 -> 11888.78 | I39: 5 | J39: 3600 | K39: =J39/I39 -> 720 | L39: 5 | M39: =F39/V39*60 -> 3287.6011 | N39: =M39/L39 -> 657.52022 | O39: =L39-I39 -> 0 | P39: =N39-K39 -> -62.479778 | Q39: =N39/K39 -> 0.91322253 | R39: =Q55 -> 0.92046616 | S39: 0.25 | T39: 0.25606481 | V39: 8.7419365 | AA39: =M39-J39 -> -312.39889 | AB39: =M39/J39 -> 0.91322253 | AC39: =AB55 -> 0.92046616
B40: 18℃-飯糰 | C40: 一配熟成紅鮭飯糰 | E40: 25.03 | F40: 330 | G40: =E40*F40 -> 8259.9 | I40: 5 | J40: 3600 | K40: =J40/I40 -> 720 | L40: 5 | M40: =F40/V40*60 -> 3287.4026 | N40: =M40/L40 -> 657.48052 | O40: =L40-I40 -> 0 | P40: =N40-K40 -> -62.519483 | Q40: =N40/K40 -> 0.91316738 | S40: 0.26527778 | T40: 0.26945602 | U40: 13.266667 | V40: 6.0229922 | AA40: =M40-J40 -> -312.59742 | AB40: =M40/J40 -> 0.91316738
B41: 18℃-飯糰 | C41: 一配生鱈魚子鮭魚飯糰 | E41: 23.8 | F41: 259 | G41: =E41*F41 -> 6164.2 | I41: 4 | J41: 3600 | K41: =J41/I41 -> 900 | L41: 4 | M41: =F41/V41*60 -> 3285.4104 | N41: =M41/L41 -> 821.3526 | O41: =L41-I41 -> 0 | P41: =N41-K41 -> -78.647399 | Q41: =N41/K41 -> 0.912614 | S41: 0.27916667 | T41: 0.28244213 | U41: 13.983333 | V41: 4.7300027 | AA41: =M41-J41 -> -314.5896 | AB41: =M41/J41 -> 0.912614
B42: 18℃-飯糰 | C42: 一配筋子銀鮭飯糰 | E42: 30 | F42: 339 | G42: =E42*F42 -> 10170 | I42: 4 | J42: 3300 | K42: =J42/I42 -> 825 | L42: 4 | M42: =F42/V42*60 -> 3083.9903 | N42: =M42/L42 -> 770.99758 | O42: =L42-I42 -> 0 | P42: =N42-K42 -> -54.002416 | Q42: =N42/K42 -> 0.93454253 | S42: 0.29166667 | T42: 0.29623843 | U42: 13.283333 | V42: 6.5953514 | AA42: =M42-J42 -> -216.00966 | AB42: =M42/J42 -> 0.93454253
B43: 18℃-飯糰 | C43: 一配蔬食鮪魚飯糰 | E43: 18.18 | F43: 589 | G43: =E43*F43 -> 10708.02 | I43: 3 | J43: 3600 | K43: =J43/I43 -> 1200 | L43: 3 | M43: =F43/V43*60 -> 3285.2877 | N43: =M43/L43 -> 1095.0959 | O43: =L43-I43 -> 0 | P43: =N43-K43 -> -104.90411 | Q43: =N43/K43 -> 0.91257991 | S43: 0.30486111 | T43: 0.31232639 | U43: 12.416667 | V43: 10.757049 | AA43: =M43-J43 -> -314.71234 | AB43: =M43/J43 -> 0.91257991
B44: 18℃-飯糰 | C44: 一配黑胡椒洋蔥豬飯糰 | E44: 17.07 | F44: 842 | G44: =E44*F44 -> 14372.94 | I44: 3 | J44: 3300 | K44: =J44/I44 -> 1100 | L44: 3 | M44: =F44/V44*60 -> 3084.0661 | N44: =M44/L44 -> 1028.022 | O44: =L44-I44 -> 0 | P44: =N44-K44 -> -71.977952 | Q44: =N44/K44 -> 0.9345655 | S44: 0.32152778 | T44: 0.33289352 | U44: 13.25 | V44: 16.380972 | AA44: =M44-J44 -> -215.93386 | AB44: =M44/J44 -> 0.9345655
B45: 18℃-飯糰 | C45: 一配經典肉鬆飯糰 | E45: 14.03 | F45: 2333 | G45: =E45*F45 -> 32731.99 | I45: 3 | J45: 3000 | K45: =J45/I45 -> 1000 | L45: 3 | M45: =F45/V45*60 -> 2803.1556 | N45: =M45/L45 -> 934.3852 | O45: =L45-I45 -> 0 | P45: =N45-K45 -> -65.614804 | Q45: =N45/K45 -> 0.9343852 | S45: 0.34166667 | T45: 0.37634259 | U45: 12.633333 | V45: 49.936579 | AA45: =M45-J45 -> -196.84441 | AB45: =M45/J45 -> 0.9343852
B46: 18℃-飯糰 | C46: 一配鮪魚飯糰 | E46: 14.28 | F46: 3176 | G46: =E46*F46 -> 45353.28 | I46: 3 | J46: 3600 | K46: =J46/I46 -> 1200 | L46: 3 | M46: =F46/V46*60 -> 3287.9521 | N46: =M46/L46 -> 1095.984 | O46: =L46-I46 -> 0 | P46: =N46-K46 -> -104.01598 | Q46: =N46/K46 -> 0.91332002 | S46: 0.38541667 | T46: 0.42565972 | U46: 13.066667 | V46: 57.957049 | AA46: =M46-J46 -> -312.04794 | AB46: =M46/J46 -> 0.91332002
B55: 平均 | I55: =AVERAGE(I39:I54) -> 3.75 | J55: =AVERAGE(J39:J54) -> 3450 | K55: =J55/I55 -> 920 | L55: =AVERAGE(L39:L54) -> 3.75 | M55: =AVERAGE(M39:M54) -> 3175.6082 | N55: =M55/L55 -> 846.82886 | O55: =L55-I55 -> 0 | P55: =N55-K55 -> -73.171137 | Q55: =N55/K55 -> 0.92046616 | S55: 0.25 | T55: 0.42565972 | AA55: =M55-J55 -> -274.39176 | AB55: =M55/J55 -> 0.92046616
A56: GKK3600型 飯糰機2 | B56: 18℃-飯糰 | C56: 一配明太子龍蝦風味沙拉飯糰 | E56: 18.18 | F56: 978 | G56: =E56*F56 -> 17780.04 | I56: 3 | J56: 3600 | K56: =J56/I56 -> 1200 | L56: 3 | M56: =F56/V56*60 -> 3285.4599 | N56: =M56/L56 -> 1095.1533 | O56: =L56-I56 -> 0 | P56: =N56-K56 -> -104.84669 | Q56: =N56/K56 -> 0.91262776 | R56: =Q72 -> 0.91306945 | S56: 0.25 | T56: 0.26239583 | V56: 17.860513 | AA56: =M56-J56 -> -314.54008 | AB56: =M56/J56 -> 0.91262776 | AC56: =AB72 -> 0.91306945
B57: 18℃-飯糰 | C57: 一配椒鹽檸檬鯖魚飯糰 | E57: 20.72 | F57: 422 | G57: =E57*F57 -> 8743.84 | I57: 3 | J57: 3600 | K57: =J57/I57 -> 1200 | L57: 3 | M57: =F57/V57*60 -> 3288.7074 | N57: =M57/L57 -> 1096.2358 | O57: =L57-I57 -> 0 | P57: =N57-K57 -> -103.76421 | Q57: =N57/K57 -> 0.91352983 | S57: 0.27152778 | T57: 0.27686343 | U57: 13.15 | V57: 7.6990735 | AA57: =M57-J57 -> -311.29262 | AB57: =M57/J57 -> 0.91352983
B58: 18℃-飯糰 | C58: 一配贅沢鮭魚肚飯糰 | E58: 30 | F58: 617 | G58: =E58*F58 -> 18510 | I58: 4 | J58: 3600 | K58: =J58/I58 -> 900 | L58: 4 | M58: =F58/V58*60 -> 3290.3419 | N58: =M58/L58 -> 822.58547 | O58: =L58-I58 -> 0 | P58: =N58-K58 -> -77.414534 | Q58: =N58/K58 -> 0.91398385 | S58: 0.28541667 | T58: 0.29322917 | U58: 12.316667 | V58: 11.251111 | AA58: =M58-J58 -> -309.65814 | AB58: =M58/J58 -> 0.91398385
B59: 18℃-飯糰 | C59: 一配卵黃牛挽肉飯糰 | E59: 24.76 | F59: 531 | G59: =E59*F59 -> 13147.56 | I59: 4 | J59: 3600 | K59: =J59/I59 -> 900 | L59: 4 | M59: =F59/V59*60 -> 3285.1034 | N59: =M59/L59 -> 821.27585 | O59: =L59-I59 -> 0 | P59: =N59-K59 -> -78.724155 | Q59: =N59/K59 -> 0.91252872 | S59: 0.30277778 | T59: 0.30950231 | U59: 13.75 | V59: 9.6983249 | AA59: =M59-J59 -> -314.89662 | AB59: =M59/J59 -> 0.91252872
B60: 18℃-飯糰 | C60: 一配鹽蔥燒肉飯糰 | E60: 17.89 | F60: 1413 | G60: =E60*F60 -> 25278.57 | I60: 4 | J60: 3600 | K60: =J60/I60 -> 900 | L60: 4 | M60: =F60/V60*60 -> 3287.3766 | N60: =M60/L60 -> 821.84414 | O60: =L60-I60 -> 0 | P60: =N60-K60 -> -78.155857 | Q60: =N60/K60 -> 0.91316016 | S60: 0.31805556 | T60: 0.33596065 | U60: 12.316667 | V60: 25.789561 | AA60: =M60-J60 -> -312.62343 | AB60: =M60/J60 -> 0.91316016
B61: 18℃-飯糰 | C61: 一配醬燒炙烤牛飯糰 | E61: 22.32 | F61: 1037 | G61: =E61*F61 -> 23145.84 | I61: 5 | J61: 3600 | K61: =J61/I61 -> 720 | L61: 5 | M61: =F61/V61*60 -> 3285.0572 | N61: =M61/L61 -> 657.01144 | O61: =L61-I61 -> 0 | P61: =N61-K61 -> -62.98856 | Q61: =N61/K61 -> 0.91251589 | S61: 0.34444444 | T61: 0.35759259 | U61: 12.216667 | V61: 18.940309 | AA61: =M61-J61 -> -314.9428 | AB61: =M61/J61 -> 0.91251589
B62: 18℃-飯糰 | C62: 一配鹽蔥生鮭飯糰 | E62: 27.48 | F62: 736 | G62: =E62*F62 -> 20225.28 | I62: 5 | J62: 3600 | K62: =J62/I62 -> 720 | L62: 5 | M62: =F62/V62*60 -> 3286.8701 | N62: =M62/L62 -> 657.37401 | O62: =L62-I62 -> 0 | P62: =N62-K62 -> -62.625986 | Q62: =N62/K62 -> 0.91301946 | S62: 0.36666667 | T62: 0.37599537 | U62: 13.066667 | V62: 13.435274 | AA62: =M62-J62 -> -313.12993 | AB62: =M62/J62 -> 0.91301946
B63: 18℃-飯糰 | C63: 一配雞肉飯飯糰 | E63: 16.66 | F63: 2556 | G63: =E63*F63 -> 42582.96 | I63: 5 | J63: 3600 | K63: =J63/I63 -> 720 | L63: 5 | M63: =F63/V63*60 -> 3287.4837 | N63: =M63/L63 -> 657.49675 | O63: =L63-I63 -> 0 | P63: =N63-K63 -> -62.503251 | Q63: =N63/K63 -> 0.91318993 | S63: 0.38472222 | T63: 0.41710648 | U63: 12.566667 | V63: 46.64966 | AA63: =M63-J63 -> -312.51625 | AB63: =M63/J63 -> 0.91318993
B72: 平均 | I72: =AVERAGE(I56:I71) -> 4.125 | J72: =AVERAGE(J56:J71) -> 3600 | K72: =J72/I72 -> 872.72727 | L72: =AVERAGE(L56:L71) -> 4.125 | M72: =AVERAGE(M56:M71) -> 3287.05 | N72: =M72/L72 -> 796.86061 | O72: =L72-I72 -> 0 | P72: =N72-K72 -> -75.866663 | Q72: =N72/K72 -> 0.91306945 | S72: 0.25 | T72: 0.41710648 | AA72: =M72-J72 -> -312.94998 | AB72: =M72/J72 -> 0.91306945
A73: 自動包裝機 (二配) | B73: 18℃-飯糰 | C73: 二配兩粒飯糰(鮪魚.焦糖鮭魚) | E73: 28.57 | F73: 856 | G73: =E73*F73 -> 24455.92 | I73: 12 | J73: 3600 | K73: =J73/I73 -> 300 | L73: 12 | M73: =F73/V73*60 -> 3120.1413 | N73: =M73/L73 -> 260.01177 | O73: =L73-I73 -> 0 | P73: =N73-K73 -> -39.988228 | Q73: =N73/K73 -> 0.86670591 | R73: =Q89 -> 0.86670591 | S73: 0.73541667 | T73: 0.74684028 | V73: 16.460793 | AA73: =M73-J73 -> -479.85874 | AB73: =M73/J73 -> 0.86670591 | AC73: =AB89 -> 0.86670591
B89: 平均 | I89: =AVERAGE(I73:I88) -> 12 | J89: =AVERAGE(J73:J88) -> 3600 | K89: =J89/I89 -> 300 | L89: =AVERAGE(L73:L88) -> 12 | M89: =AVERAGE(M73:M88) -> 3120.1413 | N89: =M89/L89 -> 260.01177 | O89: =L89-I89 -> 0 | P89: =N89-K89 -> -39.988228 | Q89: =N89/K89 -> 0.86670591 | S89: 0.73541667 | T89: 0.74684028 | AA89: =M89-J89 -> -479.85874 | AB89: =M89/J89 -> 0.86670591
A90: (新) 3300型飯糰機 (二配) | B90: 18℃-飯糰 | C90: 二配大飯糰韓式蒜烤豬五花 | E90: 24.54 | F90: 676 | G90: =E90*F90 -> 16589.04 | I90: 4 | J90: 3000 | K90: =J90/I90 -> 750 | L90: 4 | M90: =F90/V90*60 -> 2799.3751 | N90: =M90/L90 -> 699.84376 | O90: =L90-I90 -> 0 | P90: =N90-K90 -> -50.156235 | Q90: =N90/K90 -> 0.93312502 | R90: =Q106 -> 0.93312502 | S90: 0.70833333 | T90: 0.7183912 | V90: 14.488948 | AA90: =M90-J90 -> -200.62494 | AB90: =M90/J90 -> 0.93312502 | AC90: =AB106 -> 0.93312502
B106: 平均 | I106: =AVERAGE(I90:I105) -> 4 | J106: =AVERAGE(J90:J105) -> 3000 | K106: =J106/I106 -> 750 | L106: =AVERAGE(L90:L105) -> 4 | M106: =AVERAGE(M90:M105) -> 2799.3751 | N106: =M106/L106 -> 699.84376 | O106: =L106-I106 -> 0 | P106: =N106-K106 -> -50.156235 | Q106: =N106/K106 -> 0.93312502 | S106: 0.70833333 | T106: 0.7183912 | AA106: =M106-J106 -> -200.62494 | AB106: =M106/J106 -> 0.93312502
A107: GKK3600型 飯糰機 (二配) | B107: 18℃-飯糰 | C107: 二配芝麻香鬆飯糰 | E107: 18.18 | F107: 511 | G107: =E107*F107 -> 9289.98 | H107: 2 | I107: 3 | J107: 3000 | K107: =J107/I107 -> 1000 | L107: 3 | M107: =F107/V107*60 -> 2801.1874 | N107: =M107/L107 -> 933.72914 | O107: =L107-I107 -> 0 | P107: =N107-K107 -> -66.270861 | Q107: =N107/K107 -> 0.93372914 | R107: =Q123 -> 0.91856777 | S107: 0.73055556 | T107: 0.73814815 | V107: 10.945358 | AA107: =M107-J107 -> -198.81258 | AB107: =M107/J107 -> 0.93372914 | AC107: =AB123 -> 0.91856777
B108: 18℃-飯糰 | C108: 二配蔬食鮪魚飯糰 | E108: 18.18 | F108: 295 | G108: =E108*F108 -> 5363.1 | H108: 2 | I108: 3 | J108: 3600 | K108: =J108/I108 -> 1200 | L108: 3 | M108: =F108/V108*60 -> 3287.8653 | N108: =M108/L108 -> 1095.9551 | O108: =L108-I108 -> 0 | P108: =N108-K108 -> -104.04488 | Q108: =N108/K108 -> 0.91329593 | S108: 0.74652778 | T108: 0.7502662 | U108: 12.066667 | V108: 5.3834321 | AA108: =M108-J108 -> -312.13465 | AB108: =M108/J108 -> 0.91329593
B109: 18℃-飯糰 | C109: 二配三杯醬爆菇菇飯糰 | E109: 16.7 | F109: 705 | G109: =E109*F109 -> 11773.5 | H109: 2 | I109: 3 | J109: 3600 | K109: =J109/I109 -> 1200 | L109: 3 | M109: =F109/V109*60 -> 3287.232 | N109: =M109/L109 -> 1095.744 | O109: =L109-I109 -> 0 | P109: =N109-K109 -> -104.25599 | Q109: =N109/K109 -> 0.91312001 | S109: 0.75902778 | T109: 0.76796296 | U109: 12.616667 | V109: 12.867969 | AA109: =M109-J109 -> -312.76797 | AB109: =M109/J109 -> 0.91312001
B110: 18℃-飯糰 | C110: 二配贅沢鮭魚肚飯糰 | E110: 30 | F110: 550 | G110: =E110*F110 -> 16500 | H110: 2 | I110: 4 | J110: 3600 | K110: =J110/I110 -> 900 | L110: 4 | M110: =F110/V110*60 -> 3288.7538 | N110: =M110/L110 -> 822.18844 | O110: =L110-I110 -> 0 | P110: =N110-K110 -> -77.811555 | Q110: =N110/K110 -> 0.91354272 | S110: 0.77708333 | T110: 0.78405093 | U110: 13.133333 | V110: 10.034196 | AA110: =M110-J110 -> -311.24622 | AB110: =M110/J110 -> 0.91354272
...

Sheet 1008(4度C)
A1: 大溪廠日報分析 | C1: 總生產量 | D1: =SUM(F5:F123) -> 52352 | E1: 營業額 | F1: =SUM(G5:G123) -> 2239403.2 | G1: 出勤人數 | H1: =L21+L38+L55+L72+L89+L106+L123 -> 117.13095 | I1: 產線配置圖 | L1: 生產實績 | O1: 人時性差異分析 | S1: 日報登錄 | Y1: 合計次數 | Z1: 合計(時間/分) | AA1: 產線異常 分析說明(5分鐘以上) | AC1: 合計次數 | AD1: 合計(時間/分) | AE1: 產能差異分析
A2: 46303 | C2: 人時性 | D2: =AVERAGE(N21,N38,N55,N72,N89,N106,N123) -> 219.66189 | E2: 平均廠價 | F2: =F1/D1 -> 42.775887 | G2: 多次生產數 | H2: =COUNT(H5:H123) -> 0 | Y2: =SUM(Y21,Y38,Y55,Y72,Y89,Y106,Y123) -> 0 | Z2: =SUM(Z21,Z38,Z55,Z72,Z89,Z106,Z123) -> 0 | AC2: =SUM(AC21,AC38,AC55,AC72,AC89,AC106,AC123) -> 0 | AD2: =SUM(AD21,AD38,AD55,AD72,AD89,AD106,AD123) -> 0
A3: 線別 | B3: 品類 | C3: 品名 | E3: 廠價 | F3: 生產量 | G3: 營收 | H3: 多次 生產 | I3: 人數 | J3: 產能/時 | K3: 人時性 | L3: 人數 | M3: 產能/時 | N3: 人時性 | O3: 人數 | P3: 人時性 | Q3: 達成率 | R3: 達成率 平均 | S3: 生產時間 | U3: 換線、休息/分 | V3: 稼動時間/分 | W3: 休息時間 | Y3: 產線異常統計(5分鐘以上) | AA3: (屏榮回填) | AC3: 短暫停線統計(5分鐘以下) | AE3: 產能/時 | AF3: 達成率 | AG3: 達成率平均
S4: 開始 | T4: 結束 | W4: 開始 | X4: 結束 | Y4: 次數 | Z4: 時間/分 | AC4: 總次數 | AD4: 設備因素(次數)
A5: 便當二線 | B5: 微波小吃 | C5: 日式茶碗蒸 | E5: 19.7 | F5: 4302 | G5: =E5*F5 -> 84749.4 | I5: 13 | J5: 1200 | K5: =J5/I5 -> 92.307692 | L5: 13 | M5: =F5/V5*60 -> 1085.1273 | N5: =M5/L5 -> 83.47133 | O5: =L5-I5 -> 0 | P5: =N5-K5 -> -8.8363624 | Q5: =N5/K5 -> 0.90427274 | R5: =Q21 -> 0.90275237 | S5: 0.25 | T5: 0.41518519 | V5: 237.87071 | AE5: =M5-J5 -> -114.87271 | AF5: =M5/J5 -> 0.90427274 | AG5: =AF21 -> 0.90275237
B6: 微波主食 | C6: 糖燻野郎三十天熟成牛飯 | E6: 56.43 | F6: 2796 | G6: =E6*F6 -> 157778.28 | I6: 24 | J6: 2000 | K6: =J6/I6 -> 83.333333 | L6: 24 | M6: =F6/V6*60 -> 1801.5548 | N6: =M6/L6 -> 75.064784 | O6: =L6-I6 -> 0 | P6: =N6-K6 -> -8.2685491 | Q6: =N6/K6 -> 0.90077741 | S6: 0.41875 | T6: 0.48341435 | U6: 5.1333333 | V6: 93.119564 | W6: 0.48341435 | X6: 0.52222222 | AE6: =M6-J6 -> -198.44518 | AF6: =M6/J6 -> 0.90077741
B7: 便當 | C7: 健身G肉餐盒 | E7: 59.52 | F7: 3209 | G7: =E7*F7 -> 190999.68 | I7: 24 | J7: 2000 | K7: =J7/I7 -> 83.333333 | L7: 24 | M7: =F7/V7*60 -> 1807.6302 | N7: =M7/L7 -> 75.317925 | O7: =L7-I7 -> 0 | P7: =N7-K7 -> -8.0154088 | Q7: =N7/K7 -> 0.90381509 | S7: 0.52222222 | T7: 0.59618056 | U7: 55.883333 | V7: 106.51515 | AE7: =M7-J7 -> -192.36981 | AF7: =M7/J7 -> 0.90381509
B21: 平均 | I21: =AVERAGE(I5:I20) -> 20.333333 | J21: =AVERAGE(J5:J20) -> 1733.3333 | K21: =J21/I21 -> 85.245902 | L21: =AVERAGE(L5:L20) -> 20.333333 | M21: =AVERAGE(M5:M20) -> 1564.7708 | N21: =M21/L21 -> 76.955939 | O21: =L21-I21 -> 0 | P21: =N21-K21 -> -8.2899623 | Q21: =N21/K21 -> 0.90275237 | S21: 0.25 | T21: 0.59618056 | Y21: =SUM(Y5:Y20) -> 0 | Z21: =SUM(Z5:Z20) -> 0 | AC21: =SUM(AC5:AC20) -> 0 | AD21: =SUM(AD5:AD20) -> 0 | AE21: =M21-J21 -> -168.56257 | AF21: =M21/J21 -> 0.90275237
A22: 涼麵一線 | B22: 季節調理麵 | C22: 和風涓絲冷麵 | E22: 28.86 | F22: 1232 | G22: =E22*F22 -> 35555.52 | I22: 18 | J22: 3600 | K22: =J22/I22 -> 200 | L22: 18 | M22: =F22/V22*60 -> 3191.7477 | N22: =M22/L22 -> 177.31932 | O22: =L22-I22 -> 0 | P22: =N22-K22 -> -22.680682 | Q22: =N22/K22 -> 0.88659659 | R22: =Q38 -> 0.89404027 | S22: 0.25 | T22: 0.26607639 | V22: 23.159725 | AE22: =M22-J22 -> -408.25228 | AF22: =M22/J22 -> 0.88659659 | AG22: =AF38 -> 0.91292844
B23: 季節調理麵 | C23: 韓式泡菜冷麵 | E23: 36.73 | F23: 1457 | G23: =E23*F23 -> 53515.61 | I23: 21 | J23: 3600 | K23: =J23/I23 -> 171.42857 | L23: 21 | M23: =F23/V23*60 -> 3194.0782 | N23: =M23/L23 -> 152.09896 | O23: =L23-I23 -> 0 | P23: =N23-K23 -> -19.329612 | Q23: =N23/K23 -> 0.88724393 | S23: 0.26944444 | T23: 0.28844907 | U23: 4.85 | V23: 27.369399 | AE23: =M23-J23 -> -405.92185 | AF23: =M23/J23 -> 0.88724393
B24: 4℃-壽司手卷 | C24: 海陸雙拼壽司 | E24: 36.45 | F24: 1628 | G24: =E24*F24 -> 59340.6 | I24: 20 | J24: 2100 | K24: =J24/I24 -> 105 | L24: 20 | M24: =F24/V24*60 -> 1890.1283 | N24: =M24/L24 -> 94.506417 | O24: =L24-I24 -> 0 | P24: =N24-K24 -> -10.493583 | Q24: =N24/K24 -> 0.90006112 | S24: 0.29166667 | T24: 0.3275463 | U24: 4.6333333 | V24: 51.67903 | AE24: =M24-J24 -> -209.87166 | AF24: =M24/J24 -> 0.90006112
B25: 4℃-飯糰 | C25: 經典傳統飯糰 | E25: 24.35 | F25: 1902 | G25: =E25*F25 -> 46313.7 | I25: 21 | J25: 2790 | K25: =J25/I25 -> 132.85714 | L25: 22 | M25: =F25/V25*60 -> 2626.6346 | N25: =M25/L25 -> 119.39248 | O25: =L25-I25 -> 1 | P25: =N25-K25 -> -13.46466 | Q25: =N25/K25 -> 0.89865309 | S25: 0.33125 | T25: 0.36141204 | U25: 5.3333333 | V25: 43.447231 | AE25: =M25-J25 -> -163.36538 | AF25: =M25/J25 -> 0.9414461
B26: 4℃-飯糰 | C26: 里肌肉蛋紫米飯糰 | E26: 29.87 | F26: 2930 | G26: =E26*F26 -> 87519.1 | I26: 21 | J26: 2790 | K26: =J26/I26 -> 132.85714 | L26: 22 | M26: =F26/V26*60 -> 2626.6346 | N26: =M26/L26 -> 119.39248 | O26: =L26-I26 -> 1 | P26: =N26-K26 -> -13.46466 | Q26: =N26/K26 -> 0.89865309 | S26: 0.36527778 | T26: 0.41174769 | U26: 5.5666667 | V26: 66.929751 | AE26: =M26-J26 -> -163.36538 | AF26: =M26/J26 -> 0.9414461
B27: 4℃-飯糰 | C27: 麻油雞飯糰 | E27: 29.97 | F27: 2141 | G27: =E27*F27 -> 64165.77 | I27: 21 | J27: 2790 | K27: =J27/I27 -> 132.85714 | L27: 22 | M27: =F27/V27*60 -> 2626.6346 | N27: =M27/L27 -> 119.39248 | O27: =L27-I27 -> 1 | P27: =N27-K27 -> -13.46466 | Q27: =N27/K27 -> 0.89865309 | S27: 0.41458333 | T27: 0.44854167 | U27: 5 | V27: 48.906688 | W27: 0.44854167 | X27: 0.4875 | AE27: =M27-J27 -> -163.36538 | AF27: =M27/J27 -> 0.9414461
B28: 便當 | C28: 香腸腿排雙拼便當 | E28: 53.76 | F28: 2113 | G28: =E28*F28 -> 113594.88 | I28: 20 | J28: 2000 | K28: =J28/I28 -> 100 | L28: 20 | M28: =F28/V28*60 -> 1801.4444 | N28: =M28/L28 -> 90.072219 | O28: =L28-I28 -> 0 | P28: =N28-K28 -> -9.9277806 | Q28: =N28/K28 -> 0.90072219 | S28: 0.4875 | T28: 0.53636574 | U28: 56.1 | V28: 70.37686 | AE28: =M28-J28 -> -198.55561 | AF28: =M28/J28 -> 0.90072219
B38: 平均 | I38: =AVERAGE(I22:I37) -> 20.285714 | J38: =AVERAGE(J22:J37) -> 2810 | K38: =J38/I38 -> 138.52113 | L38: =AVERAGE(L22:L37) -> 20.714286 | M38: =AVERAGE(M22:M37) -> 2565.3289 | N38: =M38/L38 -> 123.84347 | O38: =L38-I38 -> 0.42857143 | P38: =N38-K38 -> -14.677662 | Q38: =N38/K38 -> 0.89404027 | S38: 0.25 | T38: 0.53636574 | Y38: =SUM(Y22:Y37) -> 0 | Z38: =SUM(Z22:Z37) -> 0 | AC38: =SUM(AC22:AC37) -> 0 | AD38: =SUM(AD22:AD37) -> 0 | AE38: =M38-J38 -> -244.67108 | AF38: =M38/J38 -> 0.91292844
A39: 涼麵二線 | B39: 便當 | C39: 蔬活腿排補力餐盒 | E39: 71.55 | F39: 2505 | G39: =E39*F39 -> 179232.75 | I39: 22 | J39: 2000 | K39: =J39/I39 -> 90.909091 | L39: 22 | M39: =F39/V39*60 -> 1808.4186 | N39: =M39/L39 -> 82.200845 | O39: =L39-I39 -> 0 | P39: =N39-K39 -> -8.7082458 | Q39: =N39/K39 -> 0.9042093 | R39: =Q55 -> 0.90295155 | S39: 0.25 | T39: 0.30770833 | V39: 83.111289 | AE39: =M39-J39 -> -191.58141 | AF39: =M39/J39 -> 0.9042093 | AG39: =AF55 -> 0.90295155
B40: 便當 | C40: 海陸雙拼肉肉餐盒 | E40: 59.54 | F40: 1834 | G40: =E40*F40 -> 109196.36 | I40: 23 | J40: 2000 | K40: =J40/I40 -> 86.956522 | L40: 23 | M40: =F40/V40*60 -> 1806.6274 | N40: =M40/L40 -> 78.549017 | O40: =L40-I40 -> 0 | P40: =N40-K40 -> -8.4075048 | Q40: =N40/K40 -> 0.90331369 | S40: 0.31180556 | T40: 0.35409722 | U40: 5.9 | V40: 60.909073 | AE40: =M40-J40 -> -193.37261 | AF40: =M40/J40 -> 0.90331369
B41: 便當 | C41: 烤蛋白餐盒 | E41: 58.67 | F41: 2612 | G41: =E41*F41 -> 153246.04 | I41: 23 | J41: 2000 | K41: =J41/I41 -> 86.956522 | L41: 23 | M41: =F41/V41*60 -> 1802.3094 | N41: =M41/L41 -> 78.361277 | O41: =L41-I41 -> 0 | P41: =N41-K41 -> -8.5952451 | Q41: =N41/K41 -> 0.90115468 | S41: 0.35694444 | T41: 0.41732639 | U41: 5 | V41: 86.955105 | AE41: =M41-J41 -> -197.69064 | AF41: =M41/J41 -> 0.90115468
B42: 便當 | C42: 香烤鱈魚輕蔬餐盒 | E42: 69.26 | F42: 455 | G42: =E42*F42 -> 31513.3 | I42: 24 | J42: 2000 | K42: =J42/I42 -> 83.333333 | L42: 24 | M42: =F42/V42*60 -> 1802.7152 | N42: =M42/L42 -> 75.113133 | O42: =L42-I42 -> 0 | P42: =N42-K42 -> -8.2202003 | Q42: =N42/K42 -> 0.9013576 | S42: 0.42013889 | T42: 0.43064815 | U42: 5 | V42: 15.143823 | AE42: =M42-J42 -> -197.28481 | AF42: =M42/J42 -> 0.9013576
B43: 便當 | C43: 地中海布格麥烤魚餐盒 | E43: 63.92 | F43: 1445 | G43: =E43*F43 -> 92364.4 | I43: 24 | J43: 2000 | K43: =J43/I43 -> 83.333333 | L43: 24 | M43: =F43/V43*60 -> 1809.9054 | N43: =M43/L43 -> 75.412727 | O43: =L43-I43 -> 0 | P43: =N43-K43 -> -7.9206067 | Q43: =N43/K43 -> 0.90495272 | S43: 0.43472222 | T43: 0.46798611 | U43: 5.8666667 | V43: 47.903055 | W43: 0.46798611 | X43: 0.50694444 | AE43: =M43-J43 -> -190.09456 | AF43: =M43/J43 -> 0.90495272
B44: 便當 | C44: 懷舊滷雙拼便當 | E44: 61.09 | F44: 1936 | G44: =E44*F44 -> 118270.24 | I44: 20 | J44: 2000 | K44: =J44/I44 -> 100 | L44: 20 | M44: =F44/V44*60 -> 1805.4427 | N44: =M44/L44 -> 90.272133 | O44: =L44-I44 -> 0 | P44: =N44-K44 -> -9.7278669 | Q44: =N44/K44 -> 0.90272133 | S44: 0.50694444 | T44: 0.55162037 | U44: 56.1 | V44: 64.338792 | AE44: =M44-J44 -> -194.55734 | AF44: =M44/J44 -> 0.90272133
B55: 平均 | I55: =AVERAGE(I39:I54) -> 22.666667 | J55: =AVERAGE(J39:J54) -> 2000 | K55: =J55/I55 -> 88.235294 | L55: =AVERAGE(L39:L54) -> 22.666667 | M55: =AVERAGE(M39:M54) -> 1805.9031 | N55: =M55/L55 -> 79.672196 | O55: =L55-I55 -> 0 | P55: =N55-K55 -> -8.5630983 | Q55: =N55/K55 -> 0.90295155 | S55: 0.25 | T55: 0.55162037 | Y55: =SUM(Y39:Y54) -> 0 | Z55: =SUM(Z39:Z54) -> 0 | AC55: =SUM(AC39:AC54) -> 0 | AD55: =SUM(AD39:AD54) -> 0 | AE55: =M55-J55 -> -194.09689 | AF55: =M55/J55 -> 0.90295155
A56: 自動包裝機 | B56: 4℃-壽司手卷 | C56: 生菜鮮蝦脆卷 | E56: 22.83 | F56: 985 | G56: =E56*F56 -> 22487.55 | I56: 6 | J56: 2500 | K56: =J56/I56 -> 416.66667 | L56: 6 | M56: =F56/V56*60 -> 2265.0449 | N56: =M56/L56 -> 377.50749 | O56: =L56-I56 -> 0 | P56: =N56-K56 -> -39.159179 | Q56: =N56/K56 -> 0.90601797 | R56: =Q72 -> 0.89220684 | S56: 0.35625 | T56: 0.37436343 | U56: 4.9666667 | V56: 26.092198 | AE56: =M56-J56 -> -234.95508 | AF56: =M56/J56 -> 0.90601797 | AG56: =AF72 -> 0.89220684
B57: 4℃-壽司手卷 | C57: 蔥花生鮪魚脆卷 | E57: 23.19 | F57: 499 | G57: =E57*F57 -> 11571.81 | I57: 6 | J57: 2500 | K57: =J57/I57 -> 416.66667 | L57: 6 | M57: =F57/V57*60 -> 2265.8385 | N57: =M57/L57 -> 377.63975 | O57: =L57-I57 -> 0 | P57: =N57-K57 -> -39.026912 | Q57: =N57/K57 -> 0.90633541 | S57: 0.37847222 | T57: 0.38763889 | U57: 5.9166667 | V57: 13.213651 | AE57: =M57-J57 -> -234.16147 | AF57: =M57/J57 -> 0.90633541
B58: 4℃-壽司手卷 | C58: 香濃明太子嫩雞飯卷 | E58: 35.89 | F58: 1348 | G58: =E58*F58 -> 48379.72 | I58: 5 | J58: 3273 | K58: =J58/I58 -> 654.6 | L58: 5 | M58: =F58/V58*60 -> 2958.5963 | N58: =M58/L58 -> 591.71927 | O58: =L58-I58 -> 0 | P58: =N58-K58 -> -62.880732 | Q58: =N58/K58 -> 0.90394022 | S58: 0.39097222 | T58: 0.4099537 | U58: 4.8 | V58: 27.337288 | AE58: =M58-J58 -> -314.40366 | AF58: =M58/J58 -> 0.90394022
B59: 4℃-壽司手卷 | C59: 小黃瓜壽司卷 | E59: 30.84 | F59: 4187 | G59: =E59*F59 -> 129127.08 | I59: 6 | J59: 3273 | K59: =J59/I59 -> 545.5 | L59: 6 | M59: =F59/V59*60 -> 2811.9403 | N59: =M59/L59 -> 468.65672 | O59: =L59-I59 -> 0 | P59: =N59-K59 -> -76.843277 | Q59: =N59/K59 -> 0.8591324 | S59: 0.41388889 | T59: 0.47592593 | U59: 5.6666667 | V59: 89.340445 | AE59: =M59-J59 -> -461.05966 | AF59: =M59/J59 -> 0.8591324
B72: 平均 | I72: =AVERAGE(I56:I71) -> 5.75 | J72: =AVERAGE(J56:J71) -> 2886.5 | K72: =J72/I72 -> 502 | L72: =AVERAGE(L56:L71) -> 5.75 | M72: =AVERAGE(M56:M71) -> 2575.355 | N72: =M72/L72 -> 447.88783 | O72: =L72-I72 -> 0 | P72: =N72-K72 -> -54.112168 | Q72: =N72/K72 -> 0.89220684 | S72: 0.25 | T72: 0.47592593 | Y72: =SUM(Y56:Y71) -> 0 | Z72: =SUM(Z56:Z71) -> 0 | AC72: =SUM(AC56:AC71) -> 0 | AD72: =SUM(AD56:AD71) -> 0 | AE72: =M72-J72 -> -311.14497 | AF72: =M72/J72 -> 0.89220684
A73: 自動包裝機2 | B73: 4℃-壽司手卷 | C73: 鮪魚昆布細卷 | E73: 15.51 | F73: 1610 | G73: =E73*F73 -> 24971.1 | I73: 6 | J73: 4200 | K73: =J73/I73 -> 700 | L73: 6 | M73: =F73/V73*60 -> 3803.1177 | N73: =M73/L73 -> 633.85295 | O73: =L73-I73 -> 0 | P73: =N73-K73 -> -66.147052 | Q73: =N73/K73 -> 0.90550421 | R73: =Q89 -> 0.90575514 | S73: 0.25 | T73: 0.26763889 | V73: 25.400213 | AE73: =M73-J73 -> -396.88231 | AF73: =M73/J73 -> 0.90550421 | AG73: =AF89 -> 0.90575514
B74: 4℃-壽司手卷 | C74: 肉鬆火腿細卷 | E74: 15.01 | F74: 1760 | G74: =E74*F74 -> 26417.6 | I74: 6 | J74: 4200 | K74: =J74/I74 -> 700 | L74: 6 | M74: =F74/V74*60 -> 3805.2255 | N74: =M74/L74 -> 634.20425 | O74: =L74-I74 -> 0 | P74: =N74-K74 -> -65.795751 | Q74: =N74/K74 -> 0.90600607 | S74: 0.27083333 | T74: 0.29010417 | U74: 4.6 | V74: 27.751312 | AE74: =M74-J74 -> -394.77451 | AF74: =M74/J74 -> 0.90600607
B89: 平均 | I89: =AVERAGE(I73:I88) -> 6 | J89: =AVERAGE(J73:J88) -> 4200 | K89: =J89/I89 -> 700 | L89: =AVERAGE(L73:L88) -> 6 | M89: =AVERAGE(M73:M88) -> 3804.1716 | N89: =M89/L89 -> 634.0286 | O89: =L89-I89 -> 0 | P89: =N89-K89 -> -65.971402 | Q89: =N89/K89 -> 0.90575514 | S89: 0.25 | T89: 0.29010417 | Y89: =SUM(Y73:Y88) -> 0 | Z89: =SUM(Z73:Z88) -> 0 | AC89: =SUM(AC73:AC88) -> 0 | AD89: =SUM(AD73:AD88) -> 0 | AE89: =M89-J89 -> -395.82841 | AF89: =M89/J89 -> 0.90575514
A90: 便當二線 (二配) | B90: 微波主食 | C90: 二配香烤魚排青醬燉飯 | E90: 58.17 | F90: 373 | G90: =E90*F90 -> 21697.41 | I90: 18 | J90: 2000 | K90: =J90/I90 -> 111.11111 | L90: 17 | M90: =F90/V90*60 -> 1805.4 | N90: =M90/L90 -> 106.2 | O90: =L90-I90 -> -1 | P90: =N90-K90 -> -4.9111111 | Q90: =N90/K90 -> 0.9558 | R90: =Q106 -> 0.95130476 | S90: 0.70833333 | T90: 0.71693287 | V90: 12.396145 | AE90: =M90-J90 -> -194.6 | AF90: =M90/J90 -> 0.9027 | AG90: =AF106 -> 0.90293333
B91: 微波主食 | C91: 二配濃起司燻腸紅醬焗烤飯 | E91: 50.67 | F91: 1374 | G91: =E91*F91 -> 69620.58 | I91: 20 | J91: 2000 | K91: =J91/I91 -> 100 | L91: 19 | M91: =F91/V91*60 -> 1805.4 | N91: =M91/L91 -> 95.021053 | O91: =L91-I91 -> -1 | P91: =N91-K91 -> -4.9789474 | Q91: =N91/K91 -> 0.95021053 | S91: 0.72083333 | T91: 0.75253472 | U91: 5.6166667 | V91: 45.663011 | AE91: =M91-J91 -> -194.6 | AF91: =M91/J91 -> 0.9027
B92: 微波主食 | C92: 二配西班牙風味海鮮燉飯 | E92: 57.3 | F92: 936 | G92: =E92*F92 -> 53632.8 | I92: 21 | J92: 2000 | K92: =J92/I92 -> 95.238095 | L92: 20 | M92: =F92/V92*60 -> 1806.8 | N92: =M92/L92 -> 90.34 | O92: =L92-I92 -> -1 | P92: =N92-K92 -> -4.8980952 | Q92: =N92/K92 -> 0.94857 | S92: 0.75555556 | T92: 0.77712963 | U92: 5 | V92: 31.082577 | AE92: =M92-J92 -> -193.2 | AF92: =M92/J92 -> 0.9034
B106: 平均 | I106: =AVERAGE(I90:I105) -> 19.666667 | J106: =AVERAGE(J90:J105) -> 2000 | K106: =J106/I106 -> 101.69492 | L106: =AVERAGE(L90:L105) -> 18.666667 | M106: =AVERAGE(M90:M105) -> 1805.8667 | N106: =M106/L106 -> 96.742857 | O106: =L106-I106 -> -1 | P106: =N106-K106 -> -4.9520581 | Q106: =N106/K106 -> 0.95130476 | S106: 0.70833333 | T106: 0.77712963 | Y106: =SUM(Y90:Y105) -> 0 | Z106: =SUM(Z90:Z105) -> 0 | AC106: =SUM(AC90:AC105) -> 0 | AD106: =SUM(AD90:AD105) -> 0 | AE106: =M106-J106 -> -194.13333 | AF106: =M106/J106 -> 0.90293333
A107: 涼麵一線 (二配) | B107: 微波主食 | C107: 二配黃金雞排蘑菇白醬歐姆蛋飯 | E107: 56.87 | F107: 1198 | G107: =E107*F107 -> 68130.26 | I107: 23 | J107: 2000 | K107: =J107/I107 -> 86.956522 | L107: 23 | M107: =F107/V107*60 -> 1806.0186 | N107: =M107/L107 -> 78.522546 | O107: =L107-I107 -> 0 | P107: =N107-K107 -> -8.4339755 | Q107: =N107/K107 -> 0.90300928 | R107: =Q123 -> 0.9027773 | S107: 0.70833333 | T107: 0.73597222 | V107: 39.800255 | AE107: =M107-J107 -> -193.98144 | AF107: =M107/J107 -> 0.90300928 | AG107: =AF123 -> 0.9027773
B108: 微波主食 | C108: 二配里肌豬排可可咖哩歐姆蛋飯 | E108: 56.79 | F108: 1672 | G108: =E108*F108 -> 94952.88 | I108: 23 | J108: 2000 | K108: =J108/I108 -> 86.956522 | L108: 23 | M108: =F108/V108*60 -> 1800.9667 | N108: =M108/L108 -> 78.302901 | O108: =L108-I108 -> 0 | P108: =N108-K108 -> -8.6536209 | Q108: =N108/K108 -> 0.90048336 | S108: 0.73958333 | T108: 0.77826389 | U108: 5.2 | V108: 55.703417 | AE108: =M108-J108 -> -199.03328 | AF108: =M108/J108 -> 0.90048336
B109: 微波主食 | C109: 二配起司棉被海陸白醬焗烤飯 | E109: 47.6 | F109: 1913 | G109: =E109*F109 -> 91058.8 | I109: 23 | J109: 2000 | K109: =J109/I109 -> 86.956522 | L109: 23 | M109: =F109/V109*60 -> 1809.6785 | N109: =M109/L109 -> 78.681674 | O109: =L109-I109 -> 0 | P109: =N109-K109 -> -8.2748476 | Q109: =N109/K109 -> 0.90483925 | S109: 0.78125 | T109: 0.82528935 | U109: 5 | V109: 63.42563 | AE109: =M109-J109 -> -190.32149 | AF109: =M109/J109 -> 0.90483925
B123: 平均 | I123: =AVERAGE(I107:I122) -> 23 | J123: =AVERAGE(J107:J122) -> 2000 | K123: =J123/I123 -> 86.956522 | L123: =AVERAGE(L107:L122) -> 23 | M123: =AVERAGE(M107:M122) -> 1805.5546 | N123: =M123/L123 -> 78.502374 | O123: =L123-I123 -> 0 | P123: =N123-K123 -> -8.454148 | Q123: =N123/K123 -> 0.9027773 | S123: 0.70833333 | T123: 0.82528935 | Y123: =SUM(Y107:Y122) -> 0 | Z123: =SUM(Z107:Z122) -> 0 | AC123: =SUM(AC107:AC122) -> 0 | AD123: =SUM(AD107:AD122) -> 0 | AE123: =M123-J123 -> -194.4454 | AF123: =M123/J123 -> 0.9027773
AA125: 原因回覆
...

Sheet 1007
B1: 屏榮 大溪廠組合室生產人時性分析
B3: 日期 | C3: 115.10.07星期三 | E3: 訂單量 | F3: ='1007(18度C)'!D1+'1007(4度C)'!D1 -> 145554 | H3: 營業額 | I3: ='1007(18度C)'!F1+'1007(4度C)'!F1 -> 4554575.8
B4: 人時性 | C4: 項目 | E4: ➀ | G4: ➁ | I4: ➂ | K4: ④ | M4: ⑤ | O4: 異常停線 | Q4: 短暫停線
C5: 組合室 | E5: 全溫層 | G5: 4度C-各編組展開(一配) | I5: 4度C-各編組展開(二配) | K5: 18度C-各編組展開(一配) | M5: 18度C-各編組展開(二配) | O5: 合計次數 | P5: 時間 | Q5: 合計次數 | R5: 設備次數
C6: 排關平均 | E6: =AVERAGE(D14:O14,D32:X32) -> 474.58296 | F6: =AVERAGE(#REF!,D14:K14) -> #REF! | G6: =AVERAGE(D14:K14) -> 276.93316 | I6: =AVERAGE(L14:O14) -> 94.325718 | K6: =AVERAGE(D32:O32) -> 717.5 | M6: =AVERAGE(P32:X32) -> 718.26923 | O6: ='1007(4度C)'!Y2 -> 0 | P6: ='1007(4度C)'!Z2 -> 0 | Q6: ='1007(4度C)'!AC2 -> 0 | R6: ='1007(4度C)'!AD2 -> 0
C7: 實績平均 | E7: =AVERAGE(D15:O15,D33:X33) -> 432.91276 | F7: =AVERAGE(#REF!,D15:K15) -> #REF! | G7: =AVERAGE(D15:K15) -> 248.82977 | I7: =AVERAGE(L15:O15) -> 87.611461 | K7: =AVERAGE(D33:O33) -> 657.38478 | M7: =AVERAGE(P33:X33) -> 657.21587
C8: 達成率平均 | E8: =AVERAGE(D16:O16,D34:X34) -> 0.90784972 | F8: =AVERAGE(D16:K16,#REF!) -> #REF! | G8: =AVERAGE(D16:K16) -> 0.89959837 | I8: =AVERAGE(L16:O16) -> 0.92692168 | K8: =AVERAGE(D34:O34) -> 0.91078059 | M8: =AVERAGE(P34:X34) -> 0.90775988
O9: ※現行日本鮮食廠以達成率80%為基本(即為現行KPI)
B11: 溫層 | D11: ➁4度C-各編組展開 | L11: ➂4度C-各編組展開
B12: 編組 | D12: 1 | E12: 2 | F12: 3 | G12: 4 | H12: 5 | I12: 6 | J12: 7 | K12: 8 | L12: 1 | M12: 2 | N12: 3 | O12: 4
D13: 便當一線 | E13: 便當二線 | F13: 涼麵一線 | G13: 涼麵二線 | H13: 涼麵三線 | I13: 自動包裝機 | J13: 自動包裝機2 | K13: 自動包裝機3 | L13: 便當一線 | M13: 便當二線 | N13: 涼麵一線 | O13: 涼麵二線
B14: 人時性 | C14: 排關 | D14: - | E14: 85.245902 | F14: 114.5098 | G14: 86.206897 | H14: 173.63636 | I14: 502 | J14: 700 | K14: - | L14: - | M14: 101.69492 | N14: 86.956522 | O14: -
C15: 實績 | D15: - | E15: 76.960529 | F15: 103.38553 | G15: 77.860138 | H15: 155.61671 | I15: 445.24945 | J15: 633.90628 | K15: - | L15: - | M15: 96.732143 | N15: 78.49078 | O15: -
C16: 達成率 | D16: - | E16: =E15/E14 -> 0.90280621 | F16: =F15/F14 -> 0.90285305 | G16: =G15/G14 -> 0.9031776 | H16: =H15/H14 -> 0.89622188 | I16: =I15/I14 -> 0.88695109 | J16: =J15/J14 -> 0.9055804 | K16: - | L16: - | M16: =M15/M14 -> 0.9511994 | N16: =N15/N14 -> 0.90264397 | O16: -
B17: 作業 時間 | C17: 開始 | D17: - | E17: 0.20833333 | F17: 0.20833333 | G17: 0.20833333 | H17: 0.25 | I17: 0.20833333 | J17: 0.25 | K17: - | L17: - | M17: 0.70833333 | N17: 0.70833333 | O17: -
C18: 結束 | D18: - | E18: 0.61229167 | F18: 0.55396991 | G18: 0.4971875 | H18: 0.41515046 | I18: 0.48258102 | J18: 0.29642361 | K18: - | L18: - | M18: 0.80793981 | N18: 0.83930556 | O18: -
B19: 產線異常 (5分鐘以上) | C19: 次數
C20: 時間/分
B21: 短暫停線 (5分鐘以下) | C21: 次數
C22: 設備次數
B23: 配置人數 | D23: - | E23: 20.333333 | F23: 20.8 | G23: 23.2 | H23: 19.8 | I23: 5.75 | J23: 6 | K23: - | L23: - | M23: 18.666667 | N23: 23 | O23: -
B24: 主要應用設備 | D24: L型封口機 | E24: ET-55 | F24: ET-55 | G24: ET-55 | H24: ET-600 | I24: 伺服包裝機 | J24: 伺服包裝機 | K24: 伺服包裝機 | L24: L型封口機 | M24: ET-55 | N24: ET-55 | O24: ET-55
B25: 次要應用設備 | D25: 伺服包裝機 | H25: 伺服包裝機
B26: 備註 | H26: 涼麵+烤飯糰 | I26: 大口飯糰線 | K26: 烤飯糰+手卷
B29: 溫層 | D29: ➃18度C-各編組展開 (一配) | P29: ⑤18度C-各編組展開 (二配)
B30: 編組 | D30: 1 | E30: 2 | F30: 3 | G30: 4 | H30: 5 | I30: 6 | J30: 7 | K30: 8 | L30: 9 | M30: 10 | N30: 11 | O30: 12 | P30: 1 | Q30: 2 | R30: 3 | S30: 4 | T30: 5 | U30: 6 | V30: 7 | W30: 8 | X30: 9
D31: 便當一線 | E31: 涼麵一線 | F31: 涼麵三線 | G31: 自動包裝機 | H31: 自動包裝機2 | I31: 自動包裝機3 | J31: 味付飯糰線B | K31: (舊) 3300型飯糰線 | L31: 3000型飯糰線 | M31: (新) 3300型飯糰機 | N31: GKK3600型 飯糰機 | O31: GKK3600型 飯糰機2 | P31: 自動包裝機 | Q31: 自動包裝機2 | R31: 自動包裝機3 | S31: 味付飯糰線B | T31: (舊) 3300型飯糰線 | U31: 3000型飯糰線 | V31: (新) 3300型飯糰機 | W31: GKK3600型 飯糰機 | X31: GKK3600型 飯糰機2
B32: 人時性 | C32: 排關 | D32: - | E32: - | F32: - | G32: 327.27273 | H32: - | I32: - | J32: - | K32: - | L32: - | M32: 750 | N32: 920 | O32: 872.72727 | P32: 300 | Q32: - | R32: - | S32: - | T32: - | U32: - | V32: 750 | W32: 923.07692 | X32: 900
C33: 實績 | D33: - | E33: - | F33: - | G33: 287.39079 | H33: - | I33: - | J33: - | K33: - | L33: - | M33: 699.22952 | N33: 846.40045 | O33: 796.51838 | P33: 260.16177 | Q33: - | R33: - | S33: - | T33: - | U33: - | V33: 699.69376 | W33: 847.60871 | X33: 821.39924
C34: 達成率 | D34: - | E34: - | F34: - | G34: =G33/G32 -> 0.87813853 | H34: - | I34: - | J34: - | K34: - | L34: - | M34: =M33/M32 -> 0.93230602 | N34: =N33/N32 -> 0.92000049 | O34: =O33/O32 -> 0.91267731 | P34: =P33/P32 -> 0.86720591 | Q34: - | R34: - | S34: - | T34: - | U34: - | V34: =V33/V32 -> 0.93292502 | W34: =W33/W32 -> 0.91824277 | X34: =X33/X32 -> 0.91266582
B35: 作業 時間 | C35: 開始 | D35: - | E35: - | F35: - | G35: 0.20833333 | H35: - | I35: - | J35: - | K35: - | L35: - | M35: 0.31458333 | N35: 0.25 | O35: 0.25 | P35: 0.73680556 | Q35: - | R35: - | S35: - | T35: - | U35: - | V35: 0.70833333 | W35: 0.73125 | X35: 0.73055556
C36: 結束 | D36: - | E36: - | F36: - | G36: 0.48258102 | H36: - | I36: - | J36: - | K36: - | L36: - | M36: 0.38748843 | N36: 0.4805787 | O36: 0.46979167 | P36: 0.74888889 | Q36: - | R36: - | S36: - | T36: - | U36: - | V36: 0.71978009 | W36: 1.0816204 | X36: 1.0689468
B37: 配置人數 | D37: - | E37: - | F37: - | G37: 11 | H37: - | I37: - | J37: - | K37: - | L37: - | M37: 4 | N37: 3.75 | O37: 4.125 | P37: 12 | Q37: - | R37: - | S37: - | T37: - | U37: - | V37: 4 | W37: 3.7142857 | X37: 4
B38: 主要應用設備 | D38: 伺服包裝機 | E38: ET-55 | F38: ET-600 | G38: 夾心型 | H38: 伺服包裝機 | I38: 伺服包裝機 | J38: 夾心型 | K38: 3300型 | L38: 3300型 | M38: 3300型 | N38: GKK | O38: GKK | P38: 夾心型 | Q38: 伺服包裝機 | R38: 伺服包裝機 | S38: 夾心型 | T38: 3300型 | U38: 3300型 | V38: 3300型 | W38: GKK | X38: GKK
B39: 次要應用設備
B40: 備註

Sheet 1007(18度C)
A1: 大溪廠日報分析 | C1: 總生產量 | D1: =SUM(F5:F140) -> 74069 | E1: 營業額 | F1: =SUM(G5:G140) -> 1470612.4 | G1: 出勤人數 | H1: =L21+L38+L55+L72+L89+L106+L123+L140 -> 46.589286 | I1: 產線配置圖 | L1: 生產實績 | O1: 人時性差異分析 | S1: 日報登錄 | Y1: 分析說明 | AA1: 產能差異分析
A2: 46302 | C2: 人時性 | D2: =AVERAGE(N21,N38,N55,N72,N89,N106,N123,N140) -> 657.30033 | E2: 平均廠價 | F2: =F1/D1 -> 19.854627 | G2: 多次生產數 | H2: =COUNT(H5:H140) -> 14
A3: 線別 | B3: 品類 | C3: 品名 | E3: 廠價 | F3: 生產量 | G3: 營收 | H3: 多次 生產 | I3: 人數 | J3: 產能/時 | K3: 人時性 | L3: 人數 | M3: 產能/時 | N3: 人時性 | O3: 人數 | P3: 人時性 | Q3: 達成率 | R3: 達成率 平均 | S3: 生產時間 | U3: 換線、休息/分 | V3: 稼動時間/分 | W3: 休息時間 | Y3: (屏榮回填) | AA3: 產能/時 | AB3: 達成率 | AC3: 達成率平均
S4: 開始 | T4: 結束 | W4: 開始 | X4: 結束
A5: 自動包裝機 | B5: 18℃-壽司手卷 | C5: 一配長野稻荷壽司 | E5: 25.64 | F5: 1110 | G5: =E5*F5 -> 28460.4 | I5: 10 | J5: 3600 | K5: =J5/I5 -> 360 | L5: 10 | M5: =F5/V5*60 -> 3216.5296 | N5: =M5/L5 -> 321.65296 | O5: =L5-I5 -> 0 | P5: =N5-K5 -> -38.347045 | Q5: =N5/K5 -> 0.89348043 | R5: =Q21 -> 0.87813853 | S5: 0.20833333 | T5: 0.22270833 | V5: 20.705546 | AA5: =M5-J5 -> -383.47045 | AB5: =M5/J5 -> 0.89348043 | AC5: =AB21 -> 0.87813853
B6: 18℃-壽司手卷 | C6: 一配經典人氣雙手卷 | E6: 29.52 | F6: 1970 | G6: =E6*F6 -> 58154.4 | I6: 11 | J6: 3600 | K6: =J6/I6 -> 327.27273 | L6: 11 | M6: =F6/V6*60 -> 3156.9318 | N6: =M6/L6 -> 286.9938 | O6: =L6-I6 -> 0 | P6: =N6-K6 -> -40.278923 | Q6: =N6/K6 -> 0.87692551 | S6: 0.22569444 | T6: 0.25168981 | U6: 5 | V6: 37.441416 | AA6: =M6-J6 -> -443.06815 | AB6: =M6/J6 -> 0.87692551
B7: 18℃-壽司手卷 | C7: 一配鮭鮪海饌雙手卷 | E7: 29.85 | F7: 2320 | G7: =E7*F7 -> 69252 | I7: 11 | J7: 3600 | K7: =J7/I7 -> 327.27273 | L7: 11 | M7: =F7/V7*60 -> 3156.1959 | N7: =M7/L7 -> 286.9269 | O7: =L7-I7 -> 0 | P7: =N7-K7 -> -40.345829 | Q7: =N7/K7 -> 0.87672108 | S7: 0.25555556 | T7: 0.28618056 | U7: 5.5666667 | V7: 44.103727 | AA7: =M7-J7 -> -443.80412 | AB7: =M7/J7 -> 0.87672108
B8: 18℃-壽司手卷 | C8: 一配青木瓜雞絲泰泰雙手卷 | E8: 30 | F8: 132 | G8: =E8*F8 -> 3960 | I8: 11 | J8: 3600 | K8: =J8/I8 -> 327.27273 | L8: 11 | M8: =F8/V8*60 -> 3157.3473 | N8: =M8/L8 -> 287.03157 | O8: =L8-I8 -> 0 | P8: =N8-K8 -> -40.241155 | Q8: =N8/K8 -> 0.87704091 | S8: 0.28958333 | T8: 0.29131944 | U8: 4.9 | V8: 2.5084349 | AA8: =M8-J8 -> -442.65271 | AB8: =M8/J8 -> 0.87704091
B9: 18℃-壽司手卷 | C9: 一配陽光蔬彩雙手卷 | E9: 30.95 | F9: 2107 | G9: =E9*F9 -> 65211.65 | I9: 11 | J9: 3600 | K9: =J9/I9 -> 327.27273 | L9: 11 | M9: =F9/V9*60 -> 3157.809 | N9: =M9/L9 -> 287.07355 | O9: =L9-I9 -> 0 | P9: =N9-K9 -> -40.199181 | Q9: =N9/K9 -> 0.87716917 | S9: 0.29444444 | T9: 0.32224537 | U9: 5 | V9: 40.034087 | AA9: =M9-J9 -> -442.19099 | AB9: =M9/J9 -> 0.87716917
B10: 18℃-飯糰 | C10: 一配兩粒飯糰(鮪魚.焦糖鮭魚) | E10: 28.57 | F10: 740 | G10: =E10*F10 -> 21141.8 | I10: 12 | J10: 3600 | K10: =J10/I10 -> 300 | L10: 12 | M10: =F10/V10*60 -> 3122.9787 | N10: =M10/L10 -> 260.24822 | O10: =L10-I10 -> 0 | P10: =N10-K10 -> -39.751778 | Q10: =N10/K10 -> 0.86749407 | S10: 0.32638889 | T10: 0.33626157 | U10: 5.9666667 | V10: 14.217196 | AA10: =M10-J10 -> -477.02134 | AB10: =M10/J10 -> 0.86749407
B21: 平均 | I21: =AVERAGE(I5:I20) -> 11 | J21: =AVERAGE(J5:J20) -> 3600 | K21: =J21/I21 -> 327.27273 | L21: =AVERAGE(L5:L20) -> 11 | M21: =AVERAGE(M5:M20) -> 3161.2987 | N21: =M21/L21 -> 287.39079 | O21: =L21-I21 -> 0 | P21: =N21-K21 -> -39.881936 | Q21: =N21/K21 -> 0.87813853 | S21: 0.20833333 | T21: 0.48258102 | AA21: =M21-J21 -> -438.70129 | AB21: =M21/J21 -> 0.87813853
A22: (新) 3300型飯糰機 | B22: 18℃-飯糰 | C22: 一配鮭魚奶油醬油飯糰 | E22: 18.53 | F22: 1498 | G22: =E22*F22 -> 27757.94 | I22: 3 | J22: 3300 | K22: =J22/I22 -> 1100 | L22: 3 | M22: =F22/V22*60 -> 3078.5714 | N22: =M22/L22 -> 1026.1905 | O22: =L22-I22 -> 0 | P22: =N22-K22 -> -73.809532 | Q22: =N22/K22 -> 0.93290043 | R22: =Q38 -> 0.93230602 | S22: 0.31458333 | T22: 0.33484954 | V22: 29.19536 | AA22: =M22-J22 -> -221.4286 | AB22: =M22/J22 -> 0.93290043 | AC22: =AB38 -> 0.93230602
B23: 18℃-飯糰 | C23: 一配熊本麥味噌雞肉飯糰 | E23: 22.95 | F23: 2934 | G23: =E23*F23 -> 67335.3 | I23: 5 | J23: 2700 | K23: =J23/I23 -> 540 | L23: 5 | M23: =F23/V23*60 -> 2515.2647 | N23: =M23/L23 -> 503.05295 | O23: =L23-I23 -> 0 | P23: =N23-K23 -> -36.947055 | Q23: =N23/K23 -> 0.93157953 | S23: 0.33888889 | T23: 0.38748843 | U23: 5.8166667 | V23: 69.988657 | AA23: =M23-J23 -> -184.73527 | AB23: =M23/J23 -> 0.93157953
B38: 平均 | I38: =AVERAGE(I22:I37) -> 4 | J38: =AVERAGE(J22:J37) -> 3000 | K38: =J38/I38 -> 750 | L38: =AVERAGE(L22:L37) -> 4 | M38: =AVERAGE(M22:M37) -> 2796.9181 | N38: =M38/L38 -> 699.22952 | O38: =L38-I38 -> 0 | P38: =N38-K38 -> -50.770484 | Q38: =N38/K38 -> 0.93230602 | S38: 0.31458333 | T38: 0.38748843 | AA38: =M38-J38 -> -203.08194 | AB38: =M38/J38 -> 0.93230602
A39: GKK3600型 飯糰機 | B39: 18℃-飯糰 | C39: 一配北海道秋鮭親子飯糰 | E39: 24.82 | F39: 722 | G39: =E39*F39 -> 17920.04 | I39: 5 | J39: 3600 | K39: =J39/I39 -> 720 | L39: 5 | M39: =F39/V39*60 -> 3286.8811 | N39: =M39/L39 -> 657.37622 | O39: =L39-I39 -> 0 | P39: =N39-K39 -> -62.623778 | Q39: =N39/K39 -> 0.91302253 | R39: =Q55 -> 0.92000049 | S39: 0.25 | T39: 0.25914352 | V39: 13.179667 | AA39: =M39-J39 -> -313.11889 | AB39: =M39/J39 -> 0.91302253 | AC39: =AB55 -> 0.92000049
B40: 18℃-飯糰 | C40: 一配熟成紅鮭飯糰 | E40: 25.03 | F40: 629 | G40: =E40*F40 -> 15743.87 | I40: 5 | J40: 3600 | K40: =J40/I40 -> 720 | L40: 5 | M40: =F40/V40*60 -> 3285.9626 | N40: =M40/L40 -> 657.19252 | O40: =L40-I40 -> 0 | P40: =N40-K40 -> -62.807483 | Q40: =N40/K40 -> 0.91276738 | S40: 0.26875 | T40: 0.27672454 | U40: 13.833333 | V40: 11.485219 | AA40: =M40-J40 -> -314.03742 | AB40: =M40/J40 -> 0.91276738
B41: 18℃-飯糰 | C41: 一配生鱈魚子鮭魚飯糰 | E41: 23.8 | F41: 490 | G41: =E41*F41 -> 11662 | I41: 4 | J41: 3600 | K41: =J41/I41 -> 900 | L41: 4 | M41: =F41/V41*60 -> 3282.7737 | N41: =M41/L41 -> 820.69343 | O41: =L41-I41 -> 0 | P41: =N41-K41 -> -79.306568 | Q41: =N41/K41 -> 0.91188159 | S41: 0.28541667 | T41: 0.29163194 | U41: 12.516667 | V41: 8.9558411 | AA41: =M41-J41 -> -317.22627 | AB41: =M41/J41 -> 0.91188159
B42: 18℃-飯糰 | C42: 一配筋子銀鮭飯糰 | E42: 30 | F42: 607 | G42: =E42*F42 -> 18210 | I42: 4 | J42: 3300 | K42: =J42/I42 -> 825 | L42: 4 | M42: =F42/V42*60 -> 3082.5882 | N42: =M42/L42 -> 770.64704 | O42: =L42-I42 -> 0 | P42: =N42-K42 -> -54.352957 | Q42: =N42/K42 -> 0.93411763 | S42: 0.30069444 | T42: 0.30888889 | U42: 13.05 | V42: 11.814747 | AA42: =M42-J42 -> -217.41183 | AB42: =M42/J42 -> 0.93411763
B43: 18℃-飯糰 | C43: 一配蔬食鮪魚飯糰 | E43: 18.18 | F43: 839 | G43: =E43*F43 -> 15253.02 | I43: 3 | J43: 3600 | K43: =J43/I43 -> 1200 | L43: 3 | M43: =F43/V43*60 -> 3283.1277 | N43: =M43/L43 -> 1094.3759 | O43: =L43-I43 -> 0 | P43: =N43-K43 -> -105.62411 | Q43: =N43/K43 -> 0.91197991 | S43: 0.31805556 | T43: 0.32869213 | U43: 13.2 | V43: 15.33294 | AA43: =M43-J43 -> -316.87234 | AB43: =M43/J43 -> 0.91197991
B44: 18℃-飯糰 | C44: 一配黑胡椒洋蔥豬飯糰 | E44: 17.07 | F44: 1139 | G44: =E44*F44 -> 19442.73 | I44: 3 | J44: 3300 | K44: =J44/I44 -> 1100 | L44: 3 | M44: =F44/V44*60 -> 3080.7726 | N44: =M44/L44 -> 1026.9242 | O44: =L44-I44 -> 0 | P44: =N44-K44 -> -73.075801 | Q44: =N44/K44 -> 0.93356745 | S44: 0.33819444 | T44: 0.35358796 | U44: 13.683333 | V44: 22.182747 | AA44: =M44-J44 -> -219.2274 | AB44: =M44/J44 -> 0.93356745
B45: 18℃-飯糰 | C45: 一配經典肉鬆飯糰 | E45: 14.03 | F45: 3239 | G45: =E45*F45 -> 45443.17 | I45: 3 | J45: 3000 | K45: =J45/I45 -> 1000 | L45: 3 | M45: =F45/V45*60 -> 2801.9556 | N45: =M45/L45 -> 933.9852 | O45: =L45-I45 -> 0 | P45: =N45-K45 -> -66.014804 | Q45: =N45/K45 -> 0.9339852 | S45: 0.3625 | T45: 0.41065972 | U45: 12.833333 | V45: 69.358701 | AA45: =M45-J45 -> -198.04441 | AB45: =M45/J45 -> 0.9339852
B46: 18℃-飯糰 | C46: 一配鮪魚飯糰 | E46: 14.28 | F46: 4825 | G46: =E46*F46 -> 68901 | I46: 3 | J46: 3600 | K46: =J46/I46 -> 1200 | L46: 3 | M46: =F46/V46*60 -> 3287.9521 | N46: =M46/L46 -> 1095.984 | O46: =L46-I46 -> 0 | P46: =N46-K46 -> -104.01598 | Q46: =N46/K46 -> 0.91332002 | S46: 0.41944444 | T46: 0.4805787 | U46: 12.65 | V46: 88.048729 | AA46: =M46-J46 -> -312.04794 | AB46: =M46/J46 -> 0.91332002
B55: 平均 | I55: =AVERAGE(I39:I54) -> 3.75 | J55: =AVERAGE(J39:J54) -> 3450 | K55: =J55/I55 -> 920 | L55: =AVERAGE(L39:L54) -> 3.75 | M55: =AVERAGE(M39:M54) -> 3174.0017 | N55: =M55/L55 -> 846.40045 | O55: =L55-I55 -> 0 | P55: =N55-K55 -> -73.59955 | Q55: =N55/K55 -> 0.92000049 | S55: 0.25 | T55: 0.4805787 | AA55: =M55-J55 -> -275.99831 | AB55: =M55/J55 -> 0.92000049
A56: GKK3600型 飯糰機2 | B56: 18℃-飯糰 | C56: 一配明太子龍蝦風味沙拉飯糰 | E56: 18.18 | F56: 1333 | G56: =E56*F56 -> 24233.94 | I56: 3 | J56: 3600 | K56: =J56/I56 -> 1200 | L56: 3 | M56: =F56/V56*60 -> 3283.6599 | N56: =M56/L56 -> 1094.5533 | O56: =L56-I56 -> 0 | P56: =N56-K56 -> -105.44669 | Q56: =N56/K56 -> 0.91212776 | R56: =Q72 -> 0.91267731 | S56: 0.25 | T56: 0.26690972 | V56: 24.356968 | AA56: =M56-J56 -> -316.34008 | AB56: =M56/J56 -> 0.91212776 | AC56: =AB72 -> 0.91267731
B57: 18℃-飯糰 | C57: 一配椒鹽檸檬鯖魚飯糰 | E57: 20.72 | F57: 686 | G57: =E57*F57 -> 14213.92 | I57: 3 | J57: 3600 | K57: =J57/I57 -> 1200 | L57: 3 | M57: =F57/V57*60 -> 3287.9874 | N57: =M57/L57 -> 1095.9958 | O57: =L57-I57 -> 0 | P57: =N57-K57 -> -104.00421 | Q57: =N57/K57 -> 0.91332983 | S57: 0.27569444 | T57: 0.28438657 | U57: 12.65 | V57: 12.518296 | AA57: =M57-J57 -> -312.01262 | AB57: =M57/J57 -> 0.91332983
B58: 18℃-飯糰 | C58: 一配贅沢鮭魚肚飯糰 | E58: 30 | F58: 983 | G58: =E58*F58 -> 29490 | I58: 4 | J58: 3600 | K58: =J58/I58 -> 900 | L58: 4 | M58: =F58/V58*60 -> 3288.5419 | N58: =M58/L58 -> 822.13547 | O58: =L58-I58 -> 0 | P58: =N58-K58 -> -77.864534 | Q58: =N58/K58 -> 0.91348385 | S58: 0.29375 | T58: 0.3062037 | U58: 13.483333 | V58: 17.935001 | AA58: =M58-J58 -> -311.45814 | AB58: =M58/J58 -> 0.91348385
B59: 18℃-飯糰 | C59: 一配卵黃牛挽肉飯糰 | E59: 24.76 | F59: 902 | G59: =E59*F59 -> 22333.52 | I59: 4 | J59: 3600 | K59: =J59/I59 -> 900 | L59: 4 | M59: =F59/V59*60 -> 3283.3034 | N59: =M59/L59 -> 820.82585 | O59: =L59-I59 -> 0 | P59: =N59-K59 -> -79.174155 | Q59: =N59/K59 -> 0.91202872 | S59: 0.31458333 | T59: 0.32603009 | U59: 12.066667 | V59: 16.483399 | AA59: =M59-J59 -> -316.69662 | AB59: =M59/J59 -> 0.91202872
B60: 18℃-飯糰 | C60: 一配鹽蔥燒肉飯糰 | E60: 17.89 | F60: 1999 | G60: =E60*F60 -> 35762.11 | I60: 4 | J60: 3600 | K60: =J60/I60 -> 900 | L60: 4 | M60: =F60/V60*60 -> 3285.2166 | N60: =M60/L60 -> 821.30414 | O60: =L60-I60 -> 0 | P60: =N60-K60 -> -78.695857 | Q60: =N60/K60 -> 0.91256016 | S60: 0.33541667 | T60: 0.36076389 | U60: 13.516667 | V60: 36.509009 | AA60: =M60-J60 -> -314.78343 | AB60: =M60/J60 -> 0.91256016
B61: 18℃-飯糰 | C61: 一配醬燒炙烤牛飯糰 | E61: 22.32 | F61: 1438 | G61: =E61*F61 -> 32096.16 | I61: 5 | J61: 3600 | K61: =J61/I61 -> 720 | L61: 5 | M61: =F61/V61*60 -> 3283.4835 | N61: =M61/L61 -> 656.69671 | O61: =L61-I61 -> 0 | P61: =N61-K61 -> -63.30329 | Q61: =N61/K61 -> 0.91207876 | S61: 0.36944444 | T61: 0.38768519 | U61: 12.5 | V61: 26.27697 | AA61: =M61-J61 -> -316.51645 | AB61: =M61/J61 -> 0.91207876
B62: 18℃-飯糰 | C62: 一配鹽蔥生鮭飯糰 | E62: 27.48 | F62: 1145 | G62: =E62*F62 -> 31464.6 | I62: 5 | J62: 3600 | K62: =J62/I62 -> 720 | L62: 5 | M62: =F62/V62*60 -> 3286.1501 | N62: =M62/L62 -> 657.23001 | O62: =L62-I62 -> 0 | P62: =N62-K62 -> -62.769986 | Q62: =N62/K62 -> 0.91281946 | S62: 0.39722222 | T62: 0.41173611 | U62: 13.733333 | V62: 20.905923 | AA62: =M62-J62 -> -313.84993 | AB62: =M62/J62 -> 0.91281946
B63: 18℃-飯糰 | C63: 一配雞肉飯飯糰 | E63: 16.66 | F63: 3917 | G63: =E63*F63 -> 65257.22 | I63: 5 | J63: 3600 | K63: =J63/I63 -> 720 | L63: 5 | M63: =F63/V63*60 -> 3286.7637 | N63: =M63/L63 -> 657.35275 | O63: =L63-I63 -> 0 | P63: =N63-K63 -> -62.647251 | Q63: =N63/K63 -> 0.91298993 | S63: 0.42013889 | T63: 0.46979167 | U63: 12.1 | V63: 71.504987 | AA63: =M63-J63 -> -313.23625 | AB63: =M63/J63 -> 0.91298993
B72: 平均 | I72: =AVERAGE(I56:I71) -> 4.125 | J72: =AVERAGE(J56:J71) -> 3600 | K72: =J72/I72 -> 872.72727 | L72: =AVERAGE(L56:L71) -> 4.125 | M72: =AVERAGE(M56:M71) -> 3285.6383 | N72: =M72/L72 -> 796.51838 | O72: =L72-I72 -> 0 | P72: =N72-K72 -> -76.208895 | Q72: =N72/K72 -> 0.91267731 | S72: 0.25 | T72: 0.46979167 | AA72: =M72-J72 -> -314.36169 | AB72: =M72/J72 -> 0.91267731
A73: 自動包裝機 (二配) | B73: 18℃-飯糰 | C73: 二配兩粒飯糰(鮪魚.焦糖鮭魚) | E73: 28.57 | F73: 906 | G73: =E73*F73 -> 25884.42 | I73: 12 | J73: 3600 | K73: =J73/I73 -> 300 | L73: 12 | M73: =F73/V73*60 -> 3121.9413 | N73: =M73/L73 -> 260.16177 | O73: =L73-I73 -> 0 | P73: =N73-K73 -> -39.838228 | Q73: =N73/K73 -> 0.86720591 | R73: =Q89 -> 0.86720591 | S73: 0.73680556 | T73: 0.74888889 | V73: 17.412243 | AA73: =M73-J73 -> -478.05874 | AB73: =M73/J73 -> 0.86720591 | AC73: =AB89 -> 0.86720591
B89: 平均 | I89: =AVERAGE(I73:I88) -> 12 | J89: =AVERAGE(J73:J88) -> 3600 | K89: =J89/I89 -> 300 | L89: =AVERAGE(L73:L88) -> 12 | M89: =AVERAGE(M73:M88) -> 3121.9413 | N89: =M89/L89 -> 260.16177 | O89: =L89-I89 -> 0 | P89: =N89-K89 -> -39.838228 | Q89: =N89/K89 -> 0.86720591 | S89: 0.73680556 | T89: 0.74888889 | AA89: =M89-J89 -> -478.05874 | AB89: =M89/J89 -> 0.86720591
A90: (新) 3300型飯糰機 (二配) | B90: 18℃-飯糰 | C90: 二配大飯糰韓式蒜烤豬五花 | E90: 24.54 | F90: 769 | G90: =E90*F90 -> 18871.26 | I90: 4 | J90: 3000 | K90: =J90/I90 -> 750 | L90: 4 | M90: =F90/V90*60 -> 2798.7751 | N90: =M90/L90 -> 699.69376 | O90: =L90-I90 -> 0 | P90: =N90-K90 -> -50.306235 | Q90: =N90/K90 -> 0.93292502 | R90: =Q106 -> 0.93292502 | S90: 0.70833333 | T90: 0.71978009 | V90: 16.485784 | AA90: =M90-J90 -> -201.22494 | AB90: =M90/J90 -> 0.93292502 | AC90: =AB106 -> 0.93292502
B106: 平均 | I106: =AVERAGE(I90:I105) -> 4 | J106: =AVERAGE(J90:J105) -> 3000 | K106: =J106/I106 -> 750 | L106: =AVERAGE(L90:L105) -> 4 | M106: =AVERAGE(M90:M105) -> 2798.7751 | N106: =M106/L106 -> 699.69376 | O106: =L106-I106 -> 0 | P106: =N106-K106 -> -50.306235 | Q106: =N106/K106 -> 0.93292502 | S106: 0.70833333 | T106: 0.71978009 | AA106: =M106-J106 -> -201.22494 | AB106: =M106/J106 -> 0.93292502
A107: GKK3600型 飯糰機 (二配) | B107: 18℃-飯糰 | C107: 二配經典肉鬆飯糰 | E107: 14.03 | F107: 293 | G107: =E107*F107 -> 4110.79 | H107: 2 | I107: 3 | J107: 3000 | K107: =J107/I107 -> 1000 | L107: 3 | M107: =F107/V107*60 -> 2804.5383 | N107: =M107/L107 -> 934.84609 | O107: =L107-I107 -> 0 | P107: =N107-K107 -> -65.153906 | Q107: =N107/K107 -> 0.93484609 | R107: =Q123 -> 0.91824277 | S107: 0.73125 | T107: 0.73560185 | V107: 6.2684115 | AA107: =M107-J107 -> -195.46172 | AB107: =M107/J107 -> 0.93484609 | AC107: =AB123 -> 0.91824277
B108: 18℃-飯糰 | C108: 二配芝麻香鬆飯糰 | E108: 18.18 | F108: 539 | G108: =E108*F108 -> 9799.02 | H108: 2 | I108: 3 | J108: 3000 | K108: =J108/I108 -> 1000 | L108: 3 | M108: =F108/V108*60 -> 2799.3874 | N108: =M108/L108 -> 933.12914 | O108: =L108-I108 -> 0 | P108: =N108-K108 -> -66.870861 | Q108: =N108/K108 -> 0.93312914 | S108: 0.74444444 | T108: 0.75246528 | U108: 12.733333 | V108: 11.552527 | AA108: =M108-J108 -> -200.61258 | AB108: =M108/J108 -> 0.93312914
B109: 18℃-飯糰 | C109: 二配蔬食鮪魚飯糰 | E109: 18.18 | F109: 340 | G109: =E109*F109 -> 6181.2 | H109: 2 | I109: 3 | J109: 3600 | K109: =J109/I109 -> 1200 | L109: 3 | M109: =F109/V109*60 -> 3287.8653 | N109: =M109/L109 -> 1095.9551 | O109: =L109-I109 -> 0 | P109: =N109-K109 -> -104.04488 | Q109: =N109/K109 -> 0.91329593 | S109: 0.76180556 | T109: 0.76611111 | U109: 13.45 | V109: 6.2046337 | AA109: =M109-J109 -> -312.13465 | AB109: =M109/J109 -> 0.91329593
B110: 18℃-飯糰 | C110: 二配三杯醬爆菇菇飯糰 | E110: 16.7 | F110: 938 | G110: =E110*F110 -> 15664.6 | H110: 2 | I110: 3 | J110: 3600 | K110: =J110/I110 -> 1200 | L110: 3 | M110: =F110/V110*60 -> 3286.872 | N110: =M110/L110 -> 1095.624 | O110: =L110-I110 -> 0 | P110: =N110-K110 -> -104.37599 | Q110: =N110/K110 -> 0.91302001 | S110: 0.77569444 | T110: 0.78758102 | U110: 13.8 | V110: 17.122662 | AA110: =M110-J110 -> -313.12797 | AB110: =M110/J110 -> 0.91302001
...

Sheet 1007(4度C)
A1: 大溪廠日報分析 | C1: 總生產量 | D1: =SUM(F5:F140) -> 71485 | E1: 營業額 | F1: =SUM(G5:G140) -> 3083963.4 | G1: 出勤人數 | H1: =L21+L38+L55+L72+L89+L106+L123+L140 -> 137.55 | I1: 產線配置圖 | L1: 生產實績 | O1: 人時性差異分析 | S1: 日報登錄 | Y1: 合計次數 | Z1: 合計(時間/分) | AA1: 產線異常 分析說明(5分鐘以上) | AC1: 合計次數 | AD1: 合計(時間/分) | AE1: 產能差異分析
A2: 46302 | C2: 人時性 | D2: =AVERAGE(N21,N38,N55,N72,N89,N106,N123,N140) -> 208.52519 | E2: 平均廠價 | F2: =F1/D1 -> 43.141406 | G2: 多次生產數 | H2: =COUNT(H5:H140) -> 0 | Y2: =SUM(Y21,Y38,Y55,Y72,Y89,Y106,Y123,Y140) -> 0 | Z2: =SUM(Z21,Z38,Z55,Z72,Z89,Z106,Z123,Z140) -> 0 | AC2: =SUM(AC21,AC38,AC55,AC72,AC89,AC106,AC123,AC140) -> 0 | AD2: =SUM(AD21,AD38,AD55,AD72,AD89,AD106,AD123,AD140) -> 0
A3: 線別 | B3: 品類 | C3: 品名 | E3: 廠價 | F3: 生產量 | G3: 營收 | H3: 多次 生產 | I3: 人數 | J3: 產能/時 | K3: 人時性 | L3: 人數 | M3: 產能/時 | N3: 人時性 | O3: 人數 | P3: 人時性 | Q3: 達成率 | R3: 達成率 平均 | S3: 生產時間 | U3: 換線、休息/分 | V3: 稼動時間/分 | W3: 休息時間 | Y3: 產線異常統計(5分鐘以上) | AA3: (屏榮回填) | AC3: 短暫停線統計(5分鐘以下) | AE3: 產能/時 | AF3: 達成率 | AG3: 達成率平均
S4: 開始 | T4: 結束 | W4: 開始 | X4: 結束 | Y4: 次數 | Z4: 時間/分 | AC4: 總次數 | AD4: 設備因素(次數)
