Workbook

Sheet 0531
B1: 屏榮 大溪廠組合室生產人時性分析
B3: 日期 | C3: 115.05.31星期日 | E3: 訂單量 | F3: ='0531(18度C)'!D1+'0531(4度C)'!D1 -> 243554 | H3: 營業額 | I3: ='0531(18度C)'!F1+'0531(4度C)'!F1 -> 7473420.7
B4: 人時性 | C4: 項目 | E4: ➀ | G4: ➁ | I4: ➂ | K4: ④ | M4: ⑤ | O4: 異常停線 | Q4: 短暫停線
C5: 組合室 | E5: 全溫層 | G5: 4度C-各編組展開(一配) | I5: 4度C-各編組展開(二配) | K5: 18度C-各編組展開(一配) | M5: 18度C-各編組展開(二配) | O5: 合計次數 | P5: 時間 | Q5: 合計次數 | R5: 設備次數
C6: 排關平均 | E6: =AVERAGE(D14:O14,D32:X32) -> 483.3671 | F6: =AVERAGE(#REF!,D14:K14) -> #REF! | G6: =AVERAGE(D14:K14) -> 231.40882 | I6: =AVERAGE(L14:O14) -> 92.630803 | K6: =AVERAGE(D32:O32) -> 820.88068 | M6: =AVERAGE(P32:X32) -> 719.15909 | O6: ='0531(4度C)'!Y2 -> 0 | P6: ='0531(4度C)'!Z2 -> 0 | Q6: ='0531(4度C)'!AC2 -> 0 | R6: ='0531(4度C)'!AD2 -> 0
C7: 實績平均 | E7: =AVERAGE(D15:O15,D33:X33) -> 432.62004 | F7: =AVERAGE(#REF!,D15:K15) -> #REF! | G7: =AVERAGE(D15:K15) -> 208.10492 | I7: =AVERAGE(L15:O15) -> 84.386889 | K7: =AVERAGE(D33:O33) -> 733.45537 | M7: =AVERAGE(P33:X33) -> 642.67395
C8: 達成率平均 | E8: =AVERAGE(D16:O16,D34:X34) -> 0.89519368 | F8: =AVERAGE(D16:K16,#REF!) -> #REF! | G8: =AVERAGE(D16:K16) -> 0.89534984 | I8: =AVERAGE(L16:O16) -> 0.9100553 | K8: =AVERAGE(D34:O34) -> 0.8901601 | M8: =AVERAGE(P34:X34) -> 0.89256222
O9: ※現行日本鮮食廠以達成率80%為基本(即為現行KPI)
B11: 溫層 | D11: ➁4度C-各編組展開 | L11: ➂4度C-各編組展開
B12: 編組 | D12: 1 | E12: 2 | F12: 3 | G12: 4 | H12: 5 | I12: 6 | J12: 7 | K12: 8 | L12: 1 | M12: 2 | N12: 3 | O12: 4
D13: 便當一線 | E13: 便當二線 | F13: 涼麵一線 | G13: 涼麵二線 | H13: 涼麵三線 | I13: 自動包裝機 | J13: 自動包裝機2 | K13: 自動包裝機3 | L13: 便當一線 | M13: 便當二線 | N13: 涼麵一線 | O13: 涼麵二線
B14: 人時性 | C14: 排關 | D14: - | E14: 95.543478 | F14: 111.81102 | G14: 88.659794 | H14: 178.02198 | I14: 481.08333 | J14: 433.33333 | K14: - | L14: - | M14: 98.305085 | N14: 86.956522 | O14: -
C15: 實績 | D15: - | E15: 86.872645 | F15: 96.766323 | G15: 79.33844 | H15: 159.40901 | I15: 434.9168 | J15: 391.32629 | K15: - | L15: - | M15: 90.983041 | N15: 77.790736 | O15: -
C16: 達成率 | D16: - | E16: =E15/E14 -> 0.90924725 | F16: =F15/F14 -> 0.86544528 | G16: =G15/G14 -> 0.8948638 | H16: =H15/H14 -> 0.8954457 | I16: =I15/I14 -> 0.90403631 | J16: =J15/J14 -> 0.90306068 | K16: - | L16: - | M16: =M15/M14 -> 0.92551714 | N16: =N15/N14 -> 0.89459346 | O16: -
B17: 作業 時間 | C17: 開始 | D17: - | E17: 0.20833333 | F17: 0.16666667 | G17: 0.16666667 | H17: 0.16666667 | I17: 0.25 | J17: 0.25 | K17: - | L17: - | M17: 0.70833333 | N17: 0.70833333 | O17: -
C18: 結束 | D18: - | E18: 0.60186343 | F18: 0.7009375 | G18: 0.72422454 | H18: 0.67072917 | I18: 0.46684028 | J18: 0.37260417 | K18: - | L18: - | M18: 0.85929398 | N18: 0.85038194 | O18: -
B19: 產線異常 (5分鐘以上) | C19: 次數
C20: 時間/分
B21: 短暫停線 (5分鐘以下) | C21: 次數
C22: 設備次數
B23: 配置人數 | D23: - | E23: 24 | F23: 18.142857 | G23: 21.555556 | H23: 20.222222 | I23: 6 | J23: 6 | K23: - | L23: - | M23: 19 | N23: 23 | O23: -
B24: 主要應用設備 | D24: L型封口機 | E24: ET-55 | F24: ET-55 | G24: ET-55 | H24: ET-600 | I24: 伺服包裝機 | J24: 伺服包裝機 | K24: 伺服包裝機 | L24: L型封口機 | M24: ET-55 | N24: ET-55 | O24: ET-55
B25: 次要應用設備 | D25: 伺服包裝機 | H25: 伺服包裝機
B26: 備註 | H26: 涼麵+烤飯糰 | I26: 大口飯糰線 | K26: 烤飯糰+手卷
B29: 溫層 | D29: ➃18度C-各編組展開 (一配) | P29: ⑤18度C-各編組展開 (二配)
B30: 編組 | D30: 1 | E30: 2 | F30: 3 | G30: 4 | H30: 5 | I30: 6 | J30: 7 | K30: 8 | L30: 9 | M30: 10 | N30: 11 | O30: 12 | P30: 1 | Q30: 2 | R30: 3 | S30: 4 | T30: 5 | U30: 6 | V30: 7 | W30: 8 | X30: 9
D31: 便當一線 | E31: 涼麵一線 | F31: 涼麵三線 | G31: 自動包裝機 | H31: 自動包裝機2 | I31: 自動包裝機3 | J31: 味付飯糰線B | K31: (舊) 3300型飯糰線 | L31: 3000型飯糰線 | M31: (新) 3300型飯糰機 | N31: GKK3600型 飯糰機 | O31: GKK3600型 飯糰機2 | P31: 自動包裝機 | Q31: 自動包裝機2 | R31: 自動包裝機3 | S31: 味付飯糰線B | T31: (舊) 3300型飯糰線 | U31: 3000型飯糰線 | V31: (新) 3300型飯糰機 | W31: GKK3600型 飯糰機 | X31: GKK3600型 飯糰機2
B32: 人時性 | C32: 排關 | D32: - | E32: - | F32: - | G32: 327.27273 | H32: - | I32: - | J32: - | K32: - | L32: - | M32: 1100 | N32: 956.25 | O32: 900 | P32: 288 | Q32: - | R32: - | S32: - | T32: - | U32: - | V32: 775 | W32: 913.63636 | X32: 900
C33: 實績 | D33: - | E33: - | F33: - | G33: 286.88729 | H33: - | I33: - | J33: - | K33: - | L33: - | M33: 995.86476 | N33: 853.93607 | O33: 797.13334 | P33: 254.93707 | Q33: - | R33: - | S33: - | T33: - | U33: - | V33: 700.48873 | W33: 817.07364 | X33: 798.19638
C34: 達成率 | D34: - | E34: - | F34: - | G34: =G33/G32 -> 0.87660005 | H34: - | I34: - | J34: - | K34: - | L34: - | M34: =M33/M32 -> 0.9053316 | N34: =N33/N32 -> 0.89300504 | O34: =O33/O32 -> 0.88570371 | P34: =P33/P32 -> 0.88519815 | Q34: - | R34: - | S34: - | T34: - | U34: - | V34: =V33/V32 -> 0.90385642 | W34: =W33/W32 -> 0.89430945 | X34: =X33/X32 -> 0.88688487
B35: 作業 時間 | C35: 開始 | D35: - | E35: - | F35: - | G35: 0.25 | H35: - | I35: - | J35: - | K35: - | L35: - | M35: 0.375 | N35: 0.25 | O35: 0.25 | P35: 0.70833333 | Q35: - | R35: - | S35: - | T35: - | U35: - | V35: 0.70833333 | W35: 0.70833333 | X35: 0.70833333
C36: 結束 | D36: - | E36: - | F36: - | G36: 0.46684028 | H36: - | I36: - | J36: - | K36: - | L36: - | M36: 0.42011574 | N36: 0.66674769 | O36: 0.66922454 | P36: 0.75134259 | Q36: - | R36: - | S36: - | T36: - | U36: - | V36: 0.79664352 | W36: 1.2352894 | X36: 1.2122685
B37: 配置人數 | D37: - | E37: - | F37: - | G37: 11 | H37: - | I37: - | J37: - | K37: - | L37: - | M37: 3 | N37: 3.5555556 | O37: 4 | P37: 12.5 | Q37: - | R37: - | S37: - | T37: - | U37: - | V37: 4 | W37: 3.6666667 | X37: 4
B38: 主要應用設備 | D38: 伺服包裝機 | E38: ET-55 | F38: ET-600 | G38: 夾心型 | H38: 伺服包裝機 | I38: 伺服包裝機 | J38: 夾心型 | K38: 3300型 | L38: 3300型 | M38: 3300型 | N38: GKK | O38: GKK | P38: 夾心型 | Q38: 伺服包裝機 | R38: 伺服包裝機 | S38: 夾心型 | T38: 3300型 | U38: 3300型 | V38: 3300型 | W38: GKK | X38: GKK
B39: 次要應用設備
B40: 備註

Sheet 0531(18度C)
A1: 大溪廠日報分析 | C1: 總生產量 | D1: =SUM(F5:F140) -> 132668 | E1: 營業額 | F1: =SUM(G5:G140) -> 2595395.5 | G1: 出勤人數 | H1: =L21+L38+L55+L72+L89+L106+L123+L140 -> 45.722222 | I1: 產線配置圖 | L1: 生產實績 | O1: 人時性差異分析 | S1: 日報登錄 | Y1: 分析說明 | AA1: 產能差異分析
A2: 46173 | C2: 人時性 | D2: =AVERAGE(N21,N38,N55,N72,N89,N106,N123,N140) -> 688.06466 | E2: 平均廠價 | F2: =F1/D1 -> 19.563086 | G2: 多次生產數 | H2: =COUNT(H5:H140) -> 17
A3: 線別 | B3: 品類 | C3: 品名 | E3: 廠價 | F3: 生產量 | G3: 營收 | H3: 多次 生產 | I3: 人數 | J3: 產能/時 | K3: 人時性 | L3: 人數 | M3: 產能/時 | N3: 人時性 | O3: 人數 | P3: 人時性 | Q3: 達成率 | R3: 達成率 平均 | S3: 生產時間 | U3: 換線、休息/分 | V3: 稼動時間/分 | W3: 休息時間 | Y3: (屏榮回填) | AA3: 產能/時 | AB3: 達成率 | AC3: 達成率平均
S4: 開始 | T4: 結束 | W4: 開始 | X4: 結束
A5: 自動包裝機 | B5: 18℃-壽司手卷 | C5: 一配長野稻荷壽司 | E5: 25.64 | F5: 1915 | G5: =E5*F5 -> 49100.6 | I5: 10 | J5: 3600 | K5: =J5/I5 -> 360 | L5: 10 | M5: =F5/V5*60 -> 3209.1356 | N5: =M5/L5 -> 320.91356 | O5: =L5-I5 -> 0 | P5: =N5-K5 -> -39.086441 | Q5: =N5/K5 -> 0.89142655 | R5: =Q21 -> 0.87660005 | S5: 0.25 | T5: 0.27486111 | V5: 35.804034 | AA5: =M5-J5 -> -390.86441 | AB5: =M5/J5 -> 0.89142655 | AC5: =AB21 -> 0.87660005
B6: 18℃-壽司手卷 | C6: 一配經典人氣雙手卷 | E6: 29.52 | F6: 3642 | G6: =E6*F6 -> 107511.84 | I6: 11 | J6: 3600 | K6: =J6/I6 -> 327.27273 | L6: 11 | M6: =F6/V6*60 -> 3150.318 | N6: =M6/L6 -> 286.39254 | O6: =L6-I6 -> 0 | P6: =N6-K6 -> -40.880183 | Q6: =N6/K6 -> 0.87508833 | S6: 0.27847222 | T6: 0.32663194 | U6: 5.2 | V6: 69.364426 | AA6: =M6-J6 -> -449.68201 | AB6: =M6/J6 -> 0.87508833
B7: 18℃-壽司手卷 | C7: 一配鮭鮪海饌雙手卷 | E7: 29.85 | F7: 3820 | G7: =E7*F7 -> 114027 | I7: 11 | J7: 3600 | K7: =J7/I7 -> 327.27273 | L7: 11 | M7: =F7/V7*60 -> 3148.9036 | N7: =M7/L7 -> 286.26396 | O7: =L7-I7 -> 0 | P7: =N7-K7 -> -41.008764 | Q7: =N7/K7 -> 0.87469544 | S7: 0.32986111 | T7: 0.38040509 | U7: 4.65 | V7: 72.787239 | AA7: =M7-J7 -> -451.0964 | AB7: =M7/J7 -> 0.87469544
B8: 18℃-飯糰 | C8: 一配兩粒飯糰(鮪魚.焦糖鮭魚) | E8: 28.57 | F8: 2253 | G8: =E8*F8 -> 64368.21 | I8: 12 | J8: 3600 | K8: =J8/I8 -> 300 | L8: 12 | M8: =F8/V8*60 -> 3114.6835 | N8: =M8/L8 -> 259.55696 | O8: =L8-I8 -> 0 | P8: =N8-K8 -> -40.443044 | Q8: =N8/K8 -> 0.86518985 | S8: 0.38402778 | T8: 0.41416667 | U8: 5.2166667 | V8: 43.400879 | AA8: =M8-J8 -> -485.31652 | AB8: =M8/J8 -> 0.86518985
B21: 平均 | I21: =AVERAGE(I5:I20) -> 11 | J21: =AVERAGE(J5:J20) -> 3600 | K21: =J21/I21 -> 327.27273 | L21: =AVERAGE(L5:L20) -> 11 | M21: =AVERAGE(M5:M20) -> 3155.7602 | N21: =M21/L21 -> 286.88729 | O21: =L21-I21 -> 0 | P21: =N21-K21 -> -40.38544 | Q21: =N21/K21 -> 0.87660005 | S21: 0.25 | T21: 0.46684028 | AA21: =M21-J21 -> -444.23984 | AB21: =M21/J21 -> 0.87660005
A22: (新) 3300型飯糰機 | B22: 18℃-飯糰 | C22: 一配鮭魚奶油醬油飯糰 | E22: 18.53 | F22: 3235 | G22: =E22*F22 -> 59944.55 | I22: 3 | J22: 3300 | K22: =J22/I22 -> 1100 | L22: 3 | M22: =F22/V22*60 -> 2987.5943 | N22: =M22/L22 -> 995.86476 | O22: =L22-I22 -> 0 | P22: =N22-K22 -> -104.13524 | Q22: =N22/K22 -> 0.9053316 | R22: =Q38 -> 0.9053316 | S22: 0.375 | T22: 0.42011574 | V22: 64.968661 | AA22: =M22-J22 -> -312.40572 | AB22: =M22/J22 -> 0.9053316 | AC22: =AB38 -> 0.9053316
B38: 平均 | I38: =AVERAGE(I22:I37) -> 3 | J38: =AVERAGE(J22:J37) -> 3300 | K38: =J38/I38 -> 1100 | L38: =AVERAGE(L22:L37) -> 3 | M38: =AVERAGE(M22:M37) -> 2987.5943 | N38: =M38/L38 -> 995.86476 | O38: =L38-I38 -> 0 | P38: =N38-K38 -> -104.13524 | Q38: =N38/K38 -> 0.9053316 | S38: 0.375 | T38: 0.42011574 | AA38: =M38-J38 -> -312.40572 | AB38: =M38/J38 -> 0.9053316
A39: GKK3600型 飯糰機 | B39: 18℃-飯糰 | C39: 一配經典肉鬆飯糰 | E39: 14.03 | F39: 1633 | G39: =E39*F39 -> 22910.99 | H39: 2 | I39: 3 | J39: 3000 | K39: =J39/I39 -> 1000 | L39: 3 | M39: =F39/V39*60 -> 2714.51 | N39: =M39/L39 -> 904.83668 | O39: =L39-I39 -> 0 | P39: =N39-K39 -> -95.163322 | Q39: =N39/K39 -> 0.90483668 | R39: =Q55 -> 0.89300504 | S39: 0.25 | T39: 0.27505787 | V39: 36.094912 | AA39: =M39-J39 -> -285.48997 | AB39: =M39/J39 -> 0.90483668 | AC39: =AB55 -> 0.89300504
B40: 18℃-飯糰 | C40: 一配鮪魚飯糰 | E40: 14.28 | F40: 2388 | G40: =E40*F40 -> 34100.64 | H40: 2 | I40: 3 | J40: 3600 | K40: =J40/I40 -> 1200 | L40: 3 | M40: =F40/V40*60 -> 3186.1241 | N40: =M40/L40 -> 1062.0414 | O40: =L40-I40 -> 0 | P40: =N40-K40 -> -137.95864 | Q40: =N40/K40 -> 0.88503447 | S40: 0.28541667 | T40: 0.31664352 | U40: 14.916667 | V40: 44.97 | AA40: =M40-J40 -> -413.87591 | AB40: =M40/J40 -> 0.88503447
B41: 18℃-飯糰 | C41: 一配贅沢鮭魚肚飯糰 | E41: 30 | F41: 2919 | G41: =E41*F41 -> 87570 | I41: 4 | J41: 3600 | K41: =J41/I41 -> 900 | L41: 4 | M41: =F41/V41*60 -> 3189.96 | N41: =M41/L41 -> 797.49 | O41: =L41-I41 -> 0 | P41: =N41-K41 -> -102.51 | Q41: =N41/K41 -> 0.8861 | S41: 0.32638889 | T41: 0.36451389 | U41: 15 | V41: 54.90351 | AA41: =M41-J41 -> -410.04 | AB41: =M41/J41 -> 0.8861
B42: 18℃-飯糰 | C42: 一配熟成紅鮭飯糰 | E42: 25.03 | F42: 1692 | G42: =E42*F42 -> 42350.76 | I42: 5 | J42: 3600 | K42: =J42/I42 -> 720 | L42: 5 | M42: =F42/V42*60 -> 3185.622 | N42: =M42/L42 -> 637.1244 | O42: =L42-I42 -> 0 | P42: =N42-K42 -> -82.875597 | Q42: =N42/K42 -> 0.884895 | S42: 0.37430556 | T42: 0.39643519 | U42: 15 | V42: 31.868188 | AA42: =M42-J42 -> -414.37799 | AB42: =M42/J42 -> 0.884895
B43: 18℃-飯糰 | C43: 一配壹號醬炙烤牛飯糰 | E43: 22.28 | F43: 1224 | G43: =E43*F43 -> 27270.72 | I43: 5 | J43: 3300 | K43: =J43/I43 -> 660 | L43: 5 | M43: =F43/V43*60 -> 2979.7551 | N43: =M43/L43 -> 595.95102 | O43: =L43-I43 -> 0 | P43: =N43-K43 -> -64.048982 | Q43: =N43/K43 -> 0.90295609 | S43: 0.40625 | T43: 0.42335648 | U43: 15 | V43: 24.646321 | AA43: =M43-J43 -> -320.24491 | AB43: =M43/J43 -> 0.90295609
B44: 18℃-飯糰 | C44: 一配蔬食鮪魚飯糰 | E44: 18.18 | F44: 1403 | G44: =E44*F44 -> 25506.54 | I44: 3 | J44: 3600 | K44: =J44/I44 -> 1200 | L44: 3 | M44: =F44/V44*60 -> 3193.1059 | N44: =M44/L44 -> 1064.3686 | O44: =L44-I44 -> 0 | P44: =N44-K44 -> -135.63136 | Q44: =N44/K44 -> 0.88697386 | S44: 0.43333333 | T44: 0.45163194 | U44: 15 | V44: 26.363047 | AA44: =M44-J44 -> -406.89409 | AB44: =M44/J44 -> 0.88697386
B45: 18℃-飯糰 | C45: 一配黑胡椒洋蔥豬飯糰 | E45: 17.07 | F45: 4345 | G45: =E45*F45 -> 74169.15 | I45: 3 | J45: 3300 | K45: =J45/I45 -> 1100 | L45: 3 | M45: =F45/V45*60 -> 2976.2431 | N45: =M45/L45 -> 992.08104 | O45: =L45-I45 -> 0 | P45: =N45-K45 -> -107.91896 | Q45: =N45/K45 -> 0.90189185 | S45: 0.46180556 | T45: 0.52262731 | U45: 14.65 | V45: 87.593651 | AA45: =M45-J45 -> -323.75689 | AB45: =M45/J45 -> 0.90189185
B46: 18℃-飯糰 | C46: 一配經典肉鬆飯糰 | E46: 14.03 | F46: 3554 | G46: =E46*F46 -> 49862.62 | I46: 3 | J46: 3000 | K46: =J46/I46 -> 1000 | L46: 3 | M46: =F46/V46*60 -> 2714.51 | N46: =M46/L46 -> 904.83668 | O46: =L46-I46 -> 0 | P46: =N46-K46 -> -95.163322 | Q46: =N46/K46 -> 0.90483668 | S46: 0.53263889 | T46: 0.5871875 | U46: 15 | V46: 78.555613 | AA46: =M46-J46 -> -285.48997 | AB46: =M46/J46 -> 0.90483668
B47: 18℃-飯糰 | C47: 一配鮪魚飯糰 | E47: 14.28 | F47: 5317 | G47: =E47*F47 -> 75926.76 | I47: 3 | J47: 3600 | K47: =J47/I47 -> 1200 | L47: 3 | M47: =F47/V47*60 -> 3186.1241 | N47: =M47/L47 -> 1062.0414 | O47: =L47-I47 -> 0 | P47: =N47-K47 -> -137.95864 | Q47: =N47/K47 -> 0.88503447 | S47: 0.59722222 | T47: 0.66674769 | U47: 15 | V47: 100.12793 | AA47: =M47-J47 -> -413.87591 | AB47: =M47/J47 -> 0.88503447
B55: 平均 | I55: =AVERAGE(I39:I54) -> 3.5555556 | J55: =AVERAGE(J39:J54) -> 3400 | K55: =J55/I55 -> 956.25 | L55: =AVERAGE(L39:L54) -> 3.5555556 | M55: =AVERAGE(M39:M54) -> 3036.2172 | N55: =M55/L55 -> 853.93607 | O55: =L55-I55 -> 0 | P55: =N55-K55 -> -102.31393 | Q55: =N55/K55 -> 0.89300504 | S55: 0.25 | T55: 0.66674769 | AA55: =M55-J55 -> -363.78285 | AB55: =M55/J55 -> 0.89300504
A56: GKK3600型 飯糰機2 | B56: 18℃-飯糰 | C56: 一配椒鹽檸檬鯖魚飯糰 | E56: 20.72 | F56: 1447 | G56: =E56*F56 -> 29981.84 | H56: 2 | I56: 3 | J56: 3600 | K56: =J56/I56 -> 1200 | L56: 3 | M56: =F56/V56*60 -> 3190.358 | N56: =M56/L56 -> 1063.4527 | O56: =L56-I56 -> 0 | P56: =N56-K56 -> -136.54734 | Q56: =N56/K56 -> 0.88621055 | R56: =Q72 -> 0.88570371 | S56: 0.25 | T56: 0.26888889 | V56: 27.213247 | AA56: =M56-J56 -> -409.64202 | AB56: =M56/J56 -> 0.88621055 | AC56: =AB72 -> 0.88570371
B57: 18℃-飯糰 | C57: 一配雞肉飯飯糰 | E57: 16.66 | F57: 2058 | G57: =E57*F57 -> 34286.28 | H57: 2 | I57: 5 | J57: 3600 | K57: =J57/I57 -> 720 | L57: 5 | M57: =F57/V57*60 -> 3193.6958 | N57: =M57/L57 -> 638.73917 | O57: =L57-I57 -> 0 | P57: =N57-K57 -> -81.260834 | Q57: =N57/K57 -> 0.88713773 | S57: 0.27916667 | T57: 0.30600694 | U57: 14.8 | V57: 38.66367 | AA57: =M57-J57 -> -406.30417 | AB57: =M57/J57 -> 0.88713773
B58: 18℃-飯糰 | C58: 一配鹽蔥燒肉飯糰 | E58: 17.89 | F58: 1073 | G58: =E58*F58 -> 19195.97 | H58: 2 | I58: 4 | J58: 3600 | K58: =J58/I58 -> 900 | L58: 4 | M58: =F58/V58*60 -> 3186.4787 | N58: =M58/L58 -> 796.61967 | O58: =L58-I58 -> 0 | P58: =N58-K58 -> -103.38033 | Q58: =N58/K58 -> 0.88513296 | S58: 0.31597222 | T58: 0.33 | U58: 15 | V58: 20.204121 | AA58: =M58-J58 -> -413.52133 | AB58: =M58/J58 -> 0.88513296
B59: 18℃-飯糰 | C59: 一配北海道秋鮭親子飯糰 | E59: 24.82 | F59: 2091 | G59: =E59*F59 -> 51898.62 | I59: 5 | J59: 3600 | K59: =J59/I59 -> 720 | L59: 5 | M59: =F59/V59*60 -> 3185.6633 | N59: =M59/L59 -> 637.13267 | O59: =L59-I59 -> 0 | P59: =N59-K59 -> -82.867334 | Q59: =N59/K59 -> 0.88490648 | S59: 0.34027778 | T59: 0.36761574 | U59: 14.8 | V59: 39.382693 | AA59: =M59-J59 -> -414.33667 | AB59: =M59/J59 -> 0.88490648
B60: 18℃-飯糰 | C60: 一配明太子龍蝦風味沙拉飯糰 | E60: 18.18 | F60: 2521 | G60: =E60*F60 -> 45831.78 | I60: 3 | J60: 3600 | K60: =J60/I60 -> 1200 | L60: 3 | M60: =F60/V60*60 -> 3189.1183 | N60: =M60/L60 -> 1063.0394 | O60: =L60-I60 -> 0 | P60: =N60-K60 -> -136.96057 | Q60: =N60/K60 -> 0.88586619 | S60: 0.37777778 | T60: 0.41070602 | U60: 14.633333 | V60: 47.430038 | AA60: =M60-J60 -> -410.88171 | AB60: =M60/J60 -> 0.88586619
B61: 18℃-飯糰 | C61: 一配柚檸海灣貝飯糰 | E61: 23.72 | F61: 2464 | G61: =E61*F61 -> 58446.08 | I61: 5 | J61: 3600 | K61: =J61/I61 -> 720 | L61: 5 | M61: =F61/V61*60 -> 3184.3247 | N61: =M61/L61 -> 636.86494 | O61: =L61-I61 -> 0 | P61: =N61-K61 -> -83.135057 | Q61: =N61/K61 -> 0.88453464 | S61: 0.42083333 | T61: 0.45306713 | U61: 14.583333 | V61: 46.427426 | AA61: =M61-J61 -> -415.67528 | AB61: =M61/J61 -> 0.88453464
B62: 18℃-飯糰 | C62: 一配山葵章魚飯糰 | E62: 25.2 | F62: 2437 | G62: =E62*F62 -> 61412.4 | I62: 3 | J62: 3600 | K62: =J62/I62 -> 1200 | L62: 3 | M62: =F62/V62*60 -> 3185.1624 | N62: =M62/L62 -> 1061.7208 | O62: =L62-I62 -> 0 | P62: =N62-K62 -> -138.2792 | Q62: =N62/K62 -> 0.88476733 | S62: 0.46319444 | T62: 0.49506944 | U62: 14.583333 | V62: 45.906607 | AA62: =M62-J62 -> -414.8376 | AB62: =M62/J62 -> 0.88476733
B63: 18℃-飯糰 | C63: 一配鹽蔥燒肉飯糰 | E63: 17.89 | F63: 2943 | G63: =E63*F63 -> 52650.27 | I63: 4 | J63: 3600 | K63: =J63/I63 -> 900 | L63: 4 | M63: =F63/V63*60 -> 3186.4787 | N63: =M63/L63 -> 796.61967 | O63: =L63-I63 -> 0 | P63: =N63-K63 -> -103.38033 | Q63: =N63/K63 -> 0.88513296 | S63: 0.50486111 | T63: 0.54333333 | U63: 15 | V63: 55.415403 | AA63: =M63-J63 -> -413.52133 | AB63: =M63/J63 -> 0.88513296
B64: 18℃-飯糰 | C64: 一配椒鹽檸檬鯖魚飯糰 | E64: 20.72 | F64: 3640 | G64: =E64*F64 -> 75420.8 | I64: 3 | J64: 3600 | K64: =J64/I64 -> 1200 | L64: 3 | M64: =F64/V64*60 -> 3190.358 | N64: =M64/L64 -> 1063.4527 | O64: =L64-I64 -> 0 | P64: =N64-K64 -> -136.54734 | Q64: =N64/K64 -> 0.88621055 | S64: 0.55347222 | T64: 0.60100694 | U64: 14.6 | V64: 68.456268 | AA64: =M64-J64 -> -409.64202 | AB64: =M64/J64 -> 0.88621055
B65: 18℃-飯糰 | C65: 一配雞肉飯飯糰 | E65: 16.66 | F65: 4455 | G65: =E65*F65 -> 74220.3 | I65: 5 | J65: 3600 | K65: =J65/I65 -> 720 | L65: 5 | M65: =F65/V65*60 -> 3193.6958 | N65: =M65/L65 -> 638.73917 | O65: =L65-I65 -> 0 | P65: =N65-K65 -> -81.260834 | Q65: =N65/K65 -> 0.88713773 | S65: 0.61111111 | T65: 0.66922454 | U65: 14.55 | V65: 83.696136 | AA65: =M65-J65 -> -406.30417 | AB65: =M65/J65 -> 0.88713773
B72: 平均 | I72: =AVERAGE(I56:I71) -> 4 | J72: =AVERAGE(J56:J71) -> 3600 | K72: =J72/I72 -> 900 | L72: =AVERAGE(L56:L71) -> 4 | M72: =AVERAGE(M56:M71) -> 3188.5334 | N72: =M72/L72 -> 797.13334 | O72: =L72-I72 -> 0 | P72: =N72-K72 -> -102.86666 | Q72: =N72/K72 -> 0.88570371 | S72: 0.25 | T72: 0.66922454 | AA72: =M72-J72 -> -411.46663 | AB72: =M72/J72 -> 0.88570371
A73: 自動包裝機 (二配) | B73: 18℃-飯糰 | C73: 二配兩粒飯糰(鮪魚.焦糖鮭魚) | E73: 28.57 | F73: 1990 | G73: =E73*F73 -> 56854.3 | I73: 12 | J73: 3600 | K73: =J73/I73 -> 300 | L73: 12 | M73: =F73/V73*60 -> 3114.2829 | N73: =M73/L73 -> 259.52358 | O73: =L73-I73 -> 0 | P73: =N73-K73 -> -40.476423 | Q73: =N73/K73 -> 0.86507859 | R73: =Q89 -> 0.88519815 | S73: 0.70833333 | T73: 0.7349537 | V73: 38.339484 | AA73: =M73-J73 -> -485.71707 | AB73: =M73/J73 -> 0.86507859 | AC73: =AB89 -> 0.88519815
B74: 18℃-飯糰 | C74: 二配溏心蛋五目飯糰 | E74: 20.42 | F74: 1029 | G74: =E74*F74 -> 21012.18 | I74: 13 | J74: 3600 | K74: =J74/I74 -> 276.92308 | L74: 13 | M74: =F74/V74*60 -> 3259.1438 | N74: =M74/L74 -> 250.70337 | O74: =L74-I74 -> 0 | P74: =N74-K74 -> -26.21971 | Q74: =N74/K74 -> 0.90531771 | S74: 0.73819444 | T74: 0.75134259 | U74: 4.6666667 | V74: 18.943626 | AA74: =M74-J74 -> -340.85623 | AB74: =M74/J74 -> 0.90531771
B89: 平均 | I89: =AVERAGE(I73:I88) -> 12.5 | J89: =AVERAGE(J73:J88) -> 3600 | K89: =J89/I89 -> 288 | L89: =AVERAGE(L73:L88) -> 12.5 | M89: =AVERAGE(M73:M88) -> 3186.7133 | N89: =M89/L89 -> 254.93707 | O89: =L89-I89 -> 0 | P89: =N89-K89 -> -33.062932 | Q89: =N89/K89 -> 0.88519815 | S89: 0.70833333 | T89: 0.75134259 | AA89: =M89-J89 -> -413.28665 | AB89: =M89/J89 -> 0.88519815
A90: (新) 3300型飯糰機 (二配) | B90: 18℃-飯糰 | C90: 二配鹽水G絲飯糰 | E90: 17.22 | F90: 1807 | G90: =E90*F90 -> 31116.54 | I90: 3 | J90: 3300 | K90: =J90/I90 -> 1100 | L90: 3 | M90: =F90/V90*60 -> 2988.0988 | N90: =M90/L90 -> 996.03294 | O90: =L90-I90 -> 0 | P90: =N90-K90 -> -103.96706 | Q90: =N90/K90 -> 0.90548449 | R90: =Q106 -> 0.90385642 | S90: 0.70833333 | T90: 0.73353009 | V90: 36.28394 | AA90: =M90-J90 -> -311.90117 | AB90: =M90/J90 -> 0.90548449 | AC90: =AB106 -> 0.90385642
B91: 18℃-飯糰 | C91: 二配大飯糰韓式蒜烤豬五花 | E91: 24.54 | F91: 1952 | G91: =E91*F91 -> 47902.08 | I91: 4 | J91: 3000 | K91: =J91/I91 -> 750 | L91: 4 | M91: =F91/V91*60 -> 2709.1175 | N91: =M91/L91 -> 677.27938 | O91: =L91-I91 -> 0 | P91: =N91-K91 -> -72.720624 | Q91: =N91/K91 -> 0.90303917 | S91: 0.7375 | T91: 0.76751157 | U91: 5.7166667 | V91: 43.23179 | AA91: =M91-J91 -> -290.8825 | AB91: =M91/J91 -> 0.90303917
B92: 18℃-飯糰 | C92: 二配大飯糰乾燒風味鮮蝦 | E92: 23.27 | F92: 1678 | G92: =E92*F92 -> 39047.06 | I92: 5 | J92: 3000 | K92: =J92/I92 -> 600 | L92: 5 | M92: =F92/V92*60 -> 2708.6484 | N92: =M92/L92 -> 541.72968 | O92: =L92-I92 -> 0 | P92: =N92-K92 -> -58.270318 | Q92: =N92/K92 -> 0.9028828 | S92: 0.77083333 | T92: 0.79664352 | U92: 4.7833333 | V92: 37.16983 | AA92: =M92-J92 -> -291.35159 | AB92: =M92/J92 -> 0.9028828
B106: 平均 | I106: =AVERAGE(I90:I105) -> 4 | J106: =AVERAGE(J90:J105) -> 3100 | K106: =J106/I106 -> 775 | L106: =AVERAGE(L90:L105) -> 4 | M106: =AVERAGE(M90:M105) -> 2801.9549 | N106: =M106/L106 -> 700.48873 | O106: =L106-I106 -> 0 | P106: =N106-K106 -> -74.511272 | Q106: =N106/K106 -> 0.90385642 | S106: 0.70833333 | T106: 0.79664352 | AA106: =M106-J106 -> -298.04509 | AB106: =M106/J106 -> 0.90385642
A107: GKK3600型 飯糰機 (二配) | B107: 18℃-飯糰 | C107: 二配壹號醬炙烤牛飯糰 | E107: 22.28 | F107: 558 | G107: =E107*F107 -> 12432.24 | H107: 2 | I107: 5 | J107: 3300 | K107: =J107/I107 -> 660 | L107: 5 | M107: =F107/V107*60 -> 2978.9766 | N107: =M107/L107 -> 595.79532 | O107: =L107-I107 -> 0 | P107: =N107-K107 -> -64.204681 | Q107: =N107/K107 -> 0.90272018 | R107: =Q123 -> 0.89430945 | S107: 0.70833333 | T107: 0.71613426 | V107: 11.238759 | AA107: =M107-J107 -> -321.02341 | AB107: =M107/J107 -> 0.90272018 | AC107: =AB123 -> 0.89430945
...

Sheet 0531(4度C)
A1: 大溪廠日報分析 | C1: 總生產量 | D1: =SUM(F5:F140) -> 110886 | E1: 營業額 | F1: =SUM(G5:G140) -> 4878025.2 | G1: 出勤人數 | H1: =L21+L38+L55+L72+L89+L106+L123+L140 -> 137.92063 | I1: 產線配置圖 | L1: 生產實績 | O1: 人時性差異分析 | S1: 日報登錄 | Y1: 合計次數 | Z1: 合計(時間/分) | AA1: 產線異常 分析說明(5分鐘以上) | AC1: 合計次數 | AD1: 合計(時間/分) | AE1: 產能差異分析
A2: 46173 | C2: 人時性 | D2: =AVERAGE(N21,N38,N55,N72,N89,N106,N123,N140) -> 177.17541 | E2: 平均廠價 | F2: =F1/D1 -> 43.991353 | G2: 多次生產數 | H2: =COUNT(H5:H140) -> 6 | Y2: =SUM(Y21,Y38,Y55,Y72,Y89,Y106,Y123,Y140) -> 0 | Z2: =SUM(Z21,Z38,Z55,Z72,Z89,Z106,Z123,Z140) -> 0 | AC2: =SUM(AC21,AC38,AC55,AC72,AC89,AC106,AC123,AC140) -> 0 | AD2: =SUM(AD21,AD38,AD55,AD72,AD89,AD106,AD123,AD140) -> 0
A3: 線別 | B3: 品類 | C3: 品名 | E3: 廠價 | F3: 生產量 | G3: 營收 | H3: 多次 生產 | I3: 人數 | J3: 產能/時 | K3: 人時性 | L3: 人數 | M3: 產能/時 | N3: 人時性 | O3: 人數 | P3: 人時性 | Q3: 達成率 | R3: 達成率 平均 | S3: 生產時間 | U3: 換線、休息/分 | V3: 稼動時間/分 | W3: 休息時間 | Y3: 產線異常統計(5分鐘以上) | AA3: (屏榮回填) | AC3: 短暫停線統計(5分鐘以下) | AE3: 產能/時 | AF3: 達成率 | AG3: 達成率平均
S4: 開始 | T4: 結束 | W4: 開始 | X4: 結束 | Y4: 次數 | Z4: 時間/分 | AC4: 總次數 | AD4: 設備因素(次數)
A5: 便當二線 | B5: 4℃-飯糰 | C5: 麻油雞飯糰 | E5: 29.97 | F5: 2756 | G5: =E5*F5 -> 82597.32 | I5: 21 | J5: 2790 | K5: =J5/I5 -> 132.85714 | L5: 25 | M5: =F5/V5*60 -> 2964.9808 | N5: =M5/L5 -> 118.59923 | O5: =L5-I5 -> 4 | P5: =N5-K5 -> -14.257912 | Q5: =N5/K5 -> 0.89268238 | R5: =Q21 -> 0.90924725 | S5: 0.20833333 | T5: 0.24706019 | V5: 55.771019 | AE5: =M5-J5 -> 174.98077 | AF5: =M5/J5 -> 1.0627171 | AG5: =AF21 -> 0.94877974
B6: 微波主食 | C6: 糖燻野郎三十天熟成牛飯 | E6: 56.77 | F6: 3849 | G6: =E6*F6 -> 218507.73 | I6: 24 | J6: 2000 | K6: =J6/I6 -> 83.333333 | L6: 24 | M6: =F6/V6*60 -> 1789.7623 | N6: =M6/L6 -> 74.573427 | O6: =L6-I6 -> 0 | P6: =N6-K6 -> -8.7599059 | Q6: =N6/K6 -> 0.89488113 | S6: 0.25069444 | T6: 0.34030093 | U6: 5.2333333 | V6: 129.0339 | AE6: =M6-J6 -> -210.23774 | AF6: =M6/J6 -> 0.89488113
B7: 便當 | C7: 健身G肉餐盒 | E7: 59.52 | F7: 6249 | G7: =E7*F7 -> 371940.48 | I7: 24 | J7: 2000 | K7: =J7/I7 -> 83.333333 | L7: 24 | M7: =F7/V7*60 -> 1794.8117 | N7: =M7/L7 -> 74.78382 | O7: =L7-I7 -> 0 | P7: =N7-K7 -> -8.5495136 | Q7: =N7/K7 -> 0.89740584 | S7: 0.34375 | T7: 0.48881944 | U7: 4.9666667 | V7: 208.90214 | W7: 0.48881944 | X7: 0.52638889 | AE7: =M7-J7 -> -205.18833 | AF7: =M7/J7 -> 0.89740584
B8: 便當 | C8: 嫩烤香料雞胸排蔬滿盒 | E8: 77.34 | F8: 3243 | G8: =E8*F8 -> 250813.62 | I8: 23 | J8: 2000 | K8: =J8/I8 -> 86.956522 | L8: 23 | M8: =F8/V8*60 -> 1790.2192 | N8: =M8/L8 -> 77.835619 | O8: =L8-I8 -> 0 | P8: =N8-K8 -> -9.1209031 | Q8: =N8/K8 -> 0.89510961 | S8: 0.52638889 | T8: 0.60186343 | U8: 55 | V8: 108.6906 | AE8: =M8-J8 -> -209.78077 | AF8: =M8/J8 -> 0.89510961
B21: 平均 | I21: =AVERAGE(I5:I20) -> 23 | J21: =AVERAGE(J5:J20) -> 2197.5 | K21: =J21/I21 -> 95.543478 | L21: =AVERAGE(L5:L20) -> 24 | M21: =AVERAGE(M5:M20) -> 2084.9435 | N21: =M21/L21 -> 86.872645 | O21: =L21-I21 -> 1 | P21: =N21-K21 -> -8.6708332 | Q21: =N21/K21 -> 0.90924725 | S21: 0.20833333 | T21: 0.60186343 | Y21: =SUM(Y5:Y20) -> 0 | Z21: =SUM(Z5:Z20) -> 0 | AC21: =SUM(AC5:AC20) -> 0 | AD21: =SUM(AD5:AD20) -> 0 | AE21: =M21-J21 -> -112.55652 | AF21: =M21/J21 -> 0.94877974
A22: 涼麵一線 | B22: 4℃-壽司手卷 | C22: 海陸雙拼壽司 | E22: 36.45 | F22: 3714 | G22: =E22*F22 -> 135375.3 | H22: 2 | I22: 20 | J22: 2100 | K22: =J22/I22 -> 105 | L22: 20 | M22: =F22/V22*60 -> 1896.1659 | N22: =M22/L22 -> 94.808294 | O22: =L22-I22 -> 0 | P22: =N22-K22 -> -10.191706 | Q22: =N22/K22 -> 0.90293613 | R22: =Q38 -> 0.86544528 | S22: 0.16666667 | T22: 0.24827546 | V22: 117.52136 | AE22: =M22-J22 -> -203.83413 | AF22: =M22/J22 -> 0.90293613 | AG22: =AF38 -> 0.86544528
B23: 微波小吃 | C23: 蒸蛋湯 | E23: 33.2 | F23: 3482 | G23: =E23*F23 -> 115602.4 | I23: 11 | J23: 2000 | K23: =J23/I23 -> 181.81818 | L23: 11 | M23: =F23/V23*60 -> 1642.8173 | N23: =M23/L23 -> 149.34703 | O23: =L23-I23 -> 0 | P23: =N23-K23 -> -32.471154 | Q23: =N23/K23 -> 0.82140865 | S23: 0.25138889 | T23: 0.33969907 | U23: 5 | V23: 127.17178 | AE23: =M23-J23 -> -357.18269 | AF23: =M23/J23 -> 0.82140865
B24: 微波小吃 | C24: 馬鈴薯玉米濃湯 | E24: 31.72 | F24: 1971 | G24: =E24*F24 -> 62520.12 | I24: 22 | J24: 2000 | K24: =J24/I24 -> 90.909091 | L24: 22 | M24: =F24/V24*60 -> 1630 | N24: =M24/L24 -> 74.090909 | O24: =L24-I24 -> 0 | P24: =N24-K24 -> -16.818182 | Q24: =N24/K24 -> 0.815 | S24: 0.34375 | T24: 0.39413194 | U24: 5.8333333 | V24: 72.552147 | AE24: =M24-J24 -> -370 | AF24: =M24/J24 -> 0.815
B25: 微波小吃 | C25: 三合一味噌湯 | E25: 34.79 | F25: 2020 | G25: =E25*F25 -> 70275.8 | I25: 11 | J25: 2000 | K25: =J25/I25 -> 181.81818 | L25: 11 | M25: =F25/V25*60 -> 1642.1467 | N25: =M25/L25 -> 149.28607 | O25: =L25-I25 -> 0 | P25: =N25-K25 -> -32.532115 | Q25: =N25/K25 -> 0.82107337 | S25: 0.39722222 | T25: 0.44847222 | U25: 5 | V25: 73.805828 | W25: 0.44847222 | X25: 0.48819444 | AE25: =M25-J25 -> -357.85326 | AF25: =M25/J25 -> 0.82107337
B26: 便當 | C26: 懷舊滷雙拼便當 | E26: 61.09 | F26: 3520 | G26: =E26*F26 -> 215036.8 | I26: 20 | J26: 2000 | K26: =J26/I26 -> 100 | L26: 20 | M26: =F26/V26*60 -> 1789.3456 | N26: =M26/L26 -> 89.467279 | O26: =L26-I26 -> 0 | P26: =N26-K26 -> -10.532721 | Q26: =N26/K26 -> 0.89467279 | S26: 0.48819444 | T26: 0.57015046 | U26: 57.2 | V26: 118.03198 | AE26: =M26-J26 -> -210.65441 | AF26: =M26/J26 -> 0.89467279
B27: 4℃-壽司手卷 | C27: 海陸雙拼壽司 | E27: 36.45 | F27: 2876 | G27: =E27*F27 -> 104830.2 | I27: 20 | J27: 2100 | K27: =J27/I27 -> 105 | L27: 20 | M27: =F27/V27*60 -> 1896.1659 | N27: =M27/L27 -> 94.808294 | O27: =L27-I27 -> 0 | P27: =N27-K27 -> -10.191706 | Q27: =N27/K27 -> 0.90293613 | S27: 0.57361111 | T27: 0.63680556 | U27: 4.9833333 | V27: 91.004697 | AE27: =M27-J27 -> -203.83413 | AF27: =M27/J27 -> 0.90293613
B28: 便當 | C28: 海陸雙拼肉肉餐盒 | E28: 59.54 | F28: 2580 | G28: =E28*F28 -> 153613.2 | I28: 23 | J28: 2000 | K28: =J28/I28 -> 86.956522 | L28: 23 | M28: =F28/V28*60 -> 1792.6816 | N28: =M28/L28 -> 77.942678 | O28: =L28-I28 -> 0 | P28: =N28-K28 -> -9.0138436 | Q28: =N28/K28 -> 0.8963408 | S28: 0.64097222 | T28: 0.7009375 | U28: 6 | V28: 86.351084 | AE28: =M28-J28 -> -207.3184 | AF28: =M28/J28 -> 0.8963408
B38: 平均 | I38: =AVERAGE(I22:I37) -> 18.142857 | J38: =AVERAGE(J22:J37) -> 2028.5714 | K38: =J38/I38 -> 111.81102 | L38: =AVERAGE(L22:L37) -> 18.142857 | M38: =AVERAGE(M22:M37) -> 1755.6176 | N38: =M38/L38 -> 96.766323 | O38: =L38-I38 -> 0 | P38: =N38-K38 -> -15.044701 | Q38: =N38/K38 -> 0.86544528 | S38: 0.16666667 | T38: 0.7009375 | Y38: =SUM(Y22:Y37) -> 0 | Z38: =SUM(Z22:Z37) -> 0 | AC38: =SUM(AC22:AC37) -> 0 | AD38: =SUM(AD22:AD37) -> 0 | AE38: =M38-J38 -> -272.95386 | AF38: =M38/J38 -> 0.86544528
A39: 涼麵二線 | B39: 微波小吃 | C39: 日式茶碗蒸 | E39: 19.7 | F39: 3471 | G39: =E39*F39 -> 68378.7 | I39: 13 | J39: 1200 | K39: =J39/I39 -> 92.307692 | L39: 13 | M39: =F39/V39*60 -> 1079.2077 | N39: =M39/L39 -> 83.015977 | O39: =L39-I39 -> 0 | P39: =N39-K39 -> -9.2917151 | Q39: =N39/K39 -> 0.89933975 | R39: =Q55 -> 0.8948638 | S39: 0.16666667 | T39: 0.3006713 | V39: 192.9749 | AE39: =M39-J39 -> -120.7923 | AF39: =M39/J39 -> 0.89933975 | AG39: =AF55 -> 0.8948638
B40: 便當 | C40: 香檸奶油魚排蔬滿盒 | E40: 77.35 | F40: 1572 | G40: =E40*F40 -> 121594.2 | I40: 26 | J40: 2000 | K40: =J40/I40 -> 76.923077 | L40: 26 | M40: =F40/V40*60 -> 1793.3662 | N40: =M40/L40 -> 68.975623 | O40: =L40-I40 -> 0 | P40: =N40-K40 -> -7.9474537 | Q40: =N40/K40 -> 0.8966831 | S40: 0.30347222 | T40: 0.33998843 | U40: 5 | V40: 52.593832 | AE40: =M40-J40 -> -206.6338 | AF40: =M40/J40 -> 0.8966831
B41: 便當 | C41: 美式雞丁餐盒 | E41: 59.34 | F41: 1680 | G41: =E41*F41 -> 99691.2 | I41: 24 | J41: 2000 | K41: =J41/I41 -> 83.333333 | L41: 24 | M41: =F41/V41*60 -> 1788.4082 | N41: =M41/L41 -> 74.51701 | O41: =L41-I41 -> 0 | P41: =N41-K41 -> -8.8163237 | Q41: =N41/K41 -> 0.89420412 | S41: 0.34305556 | T41: 0.3821875 | U41: 5 | V41: 56.36297 | AE41: =M41-J41 -> -211.59177 | AF41: =M41/J41 -> 0.89420412
B42: 便當 | C42: 烤蛋白餐盒 | E42: 58.67 | F42: 1412 | G42: =E42*F42 -> 82842.04 | H42: 2 | I42: 23 | J42: 2000 | K42: =J42/I42 -> 86.956522 | L42: 23 | M42: =F42/V42*60 -> 1791.327 | N42: =M42/L42 -> 77.883783 | O42: =L42-I42 -> 0 | P42: =N42-K42 -> -9.0727389 | Q42: =N42/K42 -> 0.8956635 | S42: 0.38611111 | T42: 0.41894676 | U42: 5.65 | V42: 47.294547 | AE42: =M42-J42 -> -208.67299 | AF42: =M42/J42 -> 0.8956635
B43: 便當 | C43: 海陸雙拼肉肉餐盒 | E43: 59.54 | F43: 1062 | G43: =E43*F43 -> 63231.48 | H43: 2 | I43: 23 | J43: 2000 | K43: =J43/I43 -> 86.956522 | L43: 23 | M43: =F43/V43*60 -> 1792.6816 | N43: =M43/L43 -> 77.942678 | O43: =L43-I43 -> 0 | P43: =N43-K43 -> -9.0138436 | Q43: =N43/K43 -> 0.8963408 | S43: 0.42222222 | T43: 0.44689815 | U43: 4.7166667 | V43: 35.544516 | AE43: =M43-J43 -> -207.3184 | AF43: =M43/J43 -> 0.8963408
B44: 便當 | C44: 香腸腿排雙拼便當 | E44: 53.76 | F44: 900 | G44: =E44*F44 -> 48384 | H44: 2 | I44: 20 | J44: 2000 | K44: =J44/I44 -> 100 | L44: 20 | M44: =F44/V44*60 -> 1784.5467 | N44: =M44/L44 -> 89.227333 | O44: =L44-I44 -> 0 | P44: =N44-K44 -> -10.772667 | Q44: =N44/K44 -> 0.89227333 | S44: 0.45 | T44: 0.47100694 | U44: 5 | V44: 30.259786 | W44: 0.47100694 | X44: 0.50972222 | AE44: =M44-J44 -> -215.45334 | AF44: =M44/J44 -> 0.89227333
B45: 便當 | C45: 蔬活腿排補力餐盒 | E45: 71.55 | F45: 2734 | G45: =E45*F45 -> 195617.7 | I45: 22 | J45: 2000 | K45: =J45/I45 -> 90.909091 | L45: 22 | M45: =F45/V45*60 -> 1786.2462 | N45: =M45/L45 -> 81.19301 | O45: =L45-I45 -> 0 | P45: =N45-K45 -> -9.7160814 | Q45: =N45/K45 -> 0.89312311 | S45: 0.50972222 | T45: 0.57349537 | U45: 55.75 | V45: 91.835044 | AE45: =M45-J45 -> -213.75379 | AF45: =M45/J45 -> 0.89312311
B46: 便當 | C46: 香腸腿排雙拼便當 | E46: 53.76 | F46: 2730 | G46: =E46*F46 -> 146764.8 | I46: 20 | J46: 2000 | K46: =J46/I46 -> 100 | L46: 20 | M46: =F46/V46*60 -> 1784.5467 | N46: =M46/L46 -> 89.227333 | O46: =L46-I46 -> 0 | P46: =N46-K46 -> -10.772667 | Q46: =N46/K46 -> 0.89227333 | S46: 0.57708333 | T46: 0.64082176 | U46: 5.1666667 | V46: 91.788017 | AE46: =M46-J46 -> -215.45334 | AF46: =M46/J46 -> 0.89227333
B47: 便當 | C47: 烤蛋白餐盒 | E47: 58.67 | F47: 3430 | G47: =E47*F47 -> 201238.1 | I47: 23 | J47: 2000 | K47: =J47/I47 -> 86.956522 | L47: 23 | M47: =F47/V47*60 -> 1791.327 | N47: =M47/L47 -> 77.883783 | O47: =L47-I47 -> 0 | P47: =N47-K47 -> -9.0727389 | Q47: =N47/K47 -> 0.8956635 | S47: 0.64444444 | T47: 0.72422454 | U47: 5.2166667 | V47: 114.8869 | AE47: =M47-J47 -> -208.67299 | AF47: =M47/J47 -> 0.8956635
B55: 平均 | I55: =AVERAGE(I39:I54) -> 21.555556 | J55: =AVERAGE(J39:J54) -> 1911.1111 | K55: =J55/I55 -> 88.659794 | L55: =AVERAGE(L39:L54) -> 21.555556 | M55: =AVERAGE(M39:M54) -> 1710.1841 | N55: =M55/L55 -> 79.33844 | O55: =L55-I55 -> 0 | P55: =N55-K55 -> -9.3213542 | Q55: =N55/K55 -> 0.8948638 | S55: 0.16666667 | T55: 0.72422454 | Y55: =SUM(Y39:Y54) -> 0 | Z55: =SUM(Z39:Z54) -> 0 | AC55: =SUM(AC39:AC54) -> 0 | AD55: =SUM(AD39:AD54) -> 0 | AE55: =M55-J55 -> -200.92697 | AF55: =M55/J55 -> 0.8948638
A56: 涼麵三線 | B56: 季節調理麵 | C56: 和風涓絲冷麵 | E56: 28.86 | F56: 3238 | G56: =E56*F56 -> 93448.68 | I56: 19 | J56: 3600 | K56: =J56/I56 -> 189.47368 | L56: 19 | M56: =F56/V56*60 -> 3181.5656 | N56: =M56/L56 -> 167.45082 | O56: =L56-I56 -> 0 | P56: =N56-K56 -> -22.022864 | Q56: =N56/K56 -> 0.88376822 | R56: =Q72 -> 0.8954457 | S56: 0.16666667 | T56: 0.2090625 | V56: 61.064276 | AE56: =M56-J56 -> -418.43441 | AF56: =M56/J56 -> 0.88376822 | AG56: =AF72 -> 0.8954457
B57: 季節調理麵 | C57: 台式麻醬涼麵 | E57: 31.11 | F57: 4546 | G57: =E57*F57 -> 141426.06 | I57: 19 | J57: 3600 | K57: =J57/I57 -> 189.47368 | L57: 19 | M57: =F57/V57*60 -> 3182.6771 | N57: =M57/L57 -> 167.50932 | O57: =L57-I57 -> 0 | P57: =N57-K57 -> -21.964364 | Q57: =N57/K57 -> 0.88407697 | S57: 0.21319444 | T57: 0.27270833 | U57: 5.95 | V57: 85.701437 | AE57: =M57-J57 -> -417.32291 | AF57: =M57/J57 -> 0.88407697
B58: 季節調理麵 | C58: 鰹魚烏龍冷麵 | E58: 38.99 | F58: 2555 | G58: =E58*F58 -> 99619.45 | I58: 19 | J58: 3600 | K58: =J58/I58 -> 189.47368 | L58: 19 | M58: =F58/V58*60 -> 3183.3553 | N58: =M58/L58 -> 167.54502 | O58: =L58-I58 -> 0 | P58: =N58-K58 -> -21.928668 | Q58: =N58/K58 -> 0.88426536 | S58: 0.27638889 | T58: 0.30982639 | U58: 5.3 | V58: 48.156736 | AE58: =M58-J58 -> -416.6447 | AF58: =M58/J58 -> 0.88426536
B59: 季節調理麵 | C59: 嘉義崇文白醋涼麵 | E59: 35.89 | F59: 3900 | G59: =E59*F59 -> 139971 | I59: 19 | J59: 3600 | K59: =J59/I59 -> 189.47368 | L59: 19 | M59: =F59/V59*60 -> 3182.8371 | N59: =M59/L59 -> 167.51774 | O59: =L59-I59 -> 0 | P59: =N59-K59 -> -21.955941 | Q59: =N59/K59 -> 0.88412142 | S59: 0.31388889 | T59: 0.36494213 | U59: 5.85 | V59: 73.519313 | AE59: =M59-J59 -> -417.16287 | AF59: =M59/J59 -> 0.88412142
B60: 季節調理麵 | C60: 日式胡麻雞絲冷麵 | E60: 46.93 | F60: 3714 | G60: =E60*F60 -> 174298.02 | I60: 24 | J60: 3600 | K60: =J60/I60 -> 150 | L60: 24 | M60: =F60/V60*60 -> 3257.238 | N60: =M60/L60 -> 135.71825 | O60: =L60-I60 -> 0 | P60: =N60-K60 -> -14.281751 | Q60: =N60/K60 -> 0.90478833 | S60: 0.36805556 | T60: 0.41555556 | U60: 5 | V60: 68.413792 | AE60: =M60-J60 -> -342.76203 | AF60: =M60/J60 -> 0.90478833
B61: 季節調理麵 | C61: 大滿足香辣涼麵 | E61: 38.48 | F61: 2011 | G61: =E61*F61 -> 77383.28 | H61: 2 | I61: 20 | J61: 3600 | K61: =J61/I61 -> 180 | L61: 20 | M61: =F61/V61*60 -> 3256.7714 | N61: =M61/L61 -> 162.83857 | O61: =L61-I61 -> 0 | P61: =N61-K61 -> -17.161429 | Q61: =N61/K61 -> 0.90465873 | S61: 0.41875 | T61: 0.44446759 | U61: 4.6 | V61: 37.048962 | AE61: =M61-J61 -> -343.22857 | AF61: =M61/J61 -> 0.90465873
B62: 季節調理麵 | C62: 大滿足麻醬涼麵 | E62: 37.8 | F62: 2619 | G62: =E62*F62 -> 98998.2 | H62: 2 | I62: 21 | J62: 3600 | K62: =J62/I62 -> 171.42857 | L62: 21 | M62: =F62/V62*60 -> 3255.6124 | N62: =M62/L62 -> 155.02916 | O62: =L62-I62 -> 0 | P62: =N62-K62 -> -16.399411 | Q62: =N62/K62 -> 0.90433677 | S62: 0.44861111 | T62: 0.48212963 | U62: 5.9666667 | V62: 48.267417 | W62: 0.48212963 | X62: 0.52013889 | AE62: =M62-J62 -> -344.38762 | AF62: =M62/J62 -> 0.90433677
B63: 季節調理麵 | C63: 大滿足香辣涼麵 | E63: 38.48 | F63: 4897 | G63: =E63*F63 -> 188436.56 | I63: 20 | J63: 3600 | K63: =J63/I63 -> 180 | L63: 20 | M63: =F63/V63*60 -> 3256.7714 | N63: =M63/L63 -> 162.83857 | O63: =L63-I63 -> 0 | P63: =N63-K63 -> -17.161429 | Q63: =N63/K63 -> 0.90465873 | S63: 0.52013889 | T63: 0.58278935 | U63: 54.733333 | V63: 90.218183 | AE63: =M63-J63 -> -343.22857 | AF63: =M63/J63 -> 0.90465873
B64: 季節調理麵 | C64: 大滿足麻醬涼麵 | E64: 37.8 | F64: 6558 | G64: =E64*F64 -> 247892.4 | I64: 21 | J64: 3600 | K64: =J64/I64 -> 171.42857 | L64: 21 | M64: =F64/V64*60 -> 3255.6124 | N64: =M64/L64 -> 155.02916 | O64: =L64-I64 -> 0 | P64: =N64-K64 -> -16.399411 | Q64: =N64/K64 -> 0.90433677 | S64: 0.58680556 | T64: 0.67072917 | U64: 5.7833333 | V64: 120.86205 | AE64: =M64-J64 -> -344.38762 | AF64: =M64/J64 -> 0.90433677
B72: 平均 | I72: =AVERAGE(I56:I71) -> 20.222222 | J72: =AVERAGE(J56:J71) -> 3600 | K72: =J72/I72 -> 178.02198 | L72: =AVERAGE(L56:L71) -> 20.222222 | M72: =AVERAGE(M56:M71) -> 3223.6045 | N72: =M72/L72 -> 159.40901 | O72: =L72-I72 -> 0 | P72: =N72-K72 -> -18.612963 | Q72: =N72/K72 -> 0.8954457 | S72: 0.16666667 | T72: 0.67072917 | Y72: =SUM(Y56:Y71) -> 0 | Z72: =SUM(Z56:Z71) -> 0 | AC72: =SUM(AC56:AC71) -> 0 | AD72: =SUM(AD56:AD71) -> 0 | AE72: =M72-J72 -> -376.39548 | AF72: =M72/J72 -> 0.8954457
A73: 自動包裝機 | B73: 4℃-壽司手卷 | C73: 山葵生鮪魚泥脆卷 | E73: 23.19 | F73: 450 | G73: =E73*F73 -> 10435.5 | I73: 6 | J73: 2500 | K73: =J73/I73 -> 416.66667 | L73: 6 | M73: =F73/V73*60 -> 2262.9238 | N73: =M73/L73 -> 377.15397 | O73: =L73-I73 -> 0 | P73: =N73-K73 -> -39.512692 | Q73: =N73/K73 -> 0.90516954 | R73: =Q89 -> 0.90403631 | S73: 0.41736111 | T73: 0.42563657 | U73: 4.6 | V73: 11.931466 | AE73: =M73-J73 -> -237.07615 | AF73: =M73/J73 -> 0.90516954 | AG73: =AF89 -> 0.90403631
B74: 4℃-壽司手卷 | C74: 韓式辣炒豬肉飯卷 | E74: 27.05 | F74: 2673 | G74: =E74*F74 -> 72304.65 | I74: 6 | J74: 3273 | K74: =J74/I74 -> 545.5 | L74: 6 | M74: =F74/V74*60 -> 2956.0778 | N74: =M74/L74 -> 492.67963 | O74: =L74-I74 -> 0 | P74: =N74-K74 -> -52.82037 | Q74: =N74/K74 -> 0.90317072 | S74: 0.42916667 | T74: 0.46684028 | U74: 5.0833333 | V74: 54.254323 | AE74: =M74-J74 -> -316.92222 | AF74: =M74/J74 -> 0.90317072
B89: 平均 | I89: =AVERAGE(I73:I88) -> 6 | J89: =AVERAGE(J73:J88) -> 2886.5 | K89: =J89/I89 -> 481.08333 | L89: =AVERAGE(L73:L88) -> 6 | M89: =AVERAGE(M73:M88) -> 2609.5008 | N89: =M89/L89 -> 434.9168 | O89: =L89-I89 -> 0 | P89: =N89-K89 -> -46.166531 | Q89: =N89/K89 -> 0.90403631 | S89: 0.25 | T89: 0.46684028 | Y89: =SUM(Y73:Y88) -> 0 | Z89: =SUM(Z73:Z88) -> 0 | AC89: =SUM(AC73:AC88) -> 0 | AD89: =SUM(AD73:AD88) -> 0 | AE89: =M89-J89 -> -276.99919 | AF89: =M89/J89 -> 0.90403631
...

Sheet 0530
B1: 屏榮 大溪廠組合室生產人時性分析
B3: 日期 | C3: 115.05.30星期六 | E3: 訂單量 | F3: ='0530(18度C)'!D1+'0530(4度C)'!D1 -> 190453 | H3: 營業額 | I3: ='0530(18度C)'!F1+'0530(4度C)'!F1 -> 5706651.9
B4: 人時性 | C4: 項目 | E4: ➀ | G4: ➁ | I4: ➂ | K4: ④ | M4: ⑤ | O4: 異常停線 | Q4: 短暫停線
C5: 組合室 | E5: 全溫層 | G5: 4度C-各編組展開(一配) | I5: 4度C-各編組展開(二配) | K5: 18度C-各編組展開(一配) | M5: 18度C-各編組展開(二配) | O5: 合計次數 | P5: 時間 | Q5: 合計次數 | R5: 設備次數
C6: 排關平均 | E6: =AVERAGE(D14:O14,D32:X32) -> 480.21337 | F6: =AVERAGE(#REF!,D14:K14) -> #REF! | G6: =AVERAGE(D14:K14) -> 228.52771 | I6: =AVERAGE(L14:O14) -> 92.630803 | K6: =AVERAGE(D32:O32) -> 812.58741 | M6: =AVERAGE(P32:X32) -> 719.15909 | O6: ='0530(4度C)'!Y2 -> 0 | P6: ='0530(4度C)'!Z2 -> 0 | Q6: ='0530(4度C)'!AC2 -> 0 | R6: ='0530(4度C)'!AD2 -> 0
C7: 實績平均 | E7: =AVERAGE(D15:O15,D33:X33) -> 429.99426 | F7: =AVERAGE(#REF!,D15:K15) -> #REF! | G7: =AVERAGE(D15:K15) -> 206.1266 | I7: =AVERAGE(L15:O15) -> 84.385439 | K7: =AVERAGE(D33:O33) -> 725.94278 | M7: =AVERAGE(P33:X33) -> 642.65166
C8: 達成率平均 | E8: =AVERAGE(D16:O16,D34:X34) -> 0.89694523 | F8: =AVERAGE(D16:K16,#REF!) -> #REF! | G8: =AVERAGE(D16:K16) -> 0.90007203 | I8: =AVERAGE(L16:O16) -> 0.91003864 | K8: =AVERAGE(D34:O34) -> 0.88999393 | M8: =AVERAGE(P34:X34) -> 0.89265962
O9: ※現行日本鮮食廠以達成率80%為基本(即為現行KPI)
B11: 溫層 | D11: ➁4度C-各編組展開 | L11: ➂4度C-各編組展開
B12: 編組 | D12: 1 | E12: 2 | F12: 3 | G12: 4 | H12: 5 | I12: 6 | J12: 7 | K12: 8 | L12: 1 | M12: 2 | N12: 3 | O12: 4
D13: 便當一線 | E13: 便當二線 | F13: 涼麵一線 | G13: 涼麵二線 | H13: 涼麵三線 | I13: 自動包裝機 | J13: 自動包裝機2 | K13: 自動包裝機3 | L13: 便當一線 | M13: 便當二線 | N13: 涼麵一線 | O13: 涼麵二線
B14: 人時性 | C14: 排關 | D14: - | E14: 95.543478 | F14: 98.780488 | G14: 84.40367 | H14: 178.02198 | I14: 481.08333 | J14: 433.33333 | K14: - | L14: - | M14: 98.305085 | N14: 86.956522 | O14: -
C15: 實績 | D15: - | E15: 86.874728 | F15: 88.072739 | G15: 75.630741 | H15: 159.36659 | I15: 435.44519 | J15: 391.36963 | K15: - | L15: - | M15: 90.983041 | N15: 77.787837 | O15: -
C16: 達成率 | D16: - | E16: =E15/E14 -> 0.90926906 | F16: =F15/F14 -> 0.89160057 | G16: =G15/G14 -> 0.89605986 | H16: =H15/H14 -> 0.89520738 | I16: =I15/I14 -> 0.90513464 | J16: =J15/J14 -> 0.90316068 | K16: - | L16: - | M16: =M15/M14 -> 0.92551714 | N16: =N15/N14 -> 0.89456013 | O16: -
B17: 作業 時間 | C17: 開始 | D17: - | E17: 0.25 | F17: 0.20833333 | G17: 0.20833333 | H17: 0.16666667 | I17: 0.25 | J17: 0.25 | K17: - | L17: - | M17: 0.70833333 | N17: 0.70833333 | O17: -
C18: 結束 | D18: - | E18: 0.53590278 | F18: 0.56354167 | G18: 0.55762731 | H18: 0.6205787 | I18: 0.42475694 | J18: 0.35850694 | K18: - | L18: - | M18: 0.84310185 | N18: 0.82780093 | O18: -
B19: 產線異常 (5分鐘以上) | C19: 次數
C20: 時間/分
B21: 短暫停線 (5分鐘以下) | C21: 次數
C22: 設備次數
B23: 配置人數 | D23: - | E23: 24 | F23: 20.5 | G23: 21.8 | H23: 20.222222 | I23: 6 | J23: 6 | K23: - | L23: - | M23: 19 | N23: 23 | O23: -
B24: 主要應用設備 | D24: L型封口機 | E24: ET-55 | F24: ET-55 | G24: ET-55 | H24: ET-600 | I24: 伺服包裝機 | J24: 伺服包裝機 | K24: 伺服包裝機 | L24: L型封口機 | M24: ET-55 | N24: ET-55 | O24: ET-55
B25: 次要應用設備 | D25: 伺服包裝機 | H25: 伺服包裝機
B26: 備註 | H26: 涼麵+烤飯糰 | I26: 大口飯糰線 | K26: 烤飯糰+手卷
B29: 溫層 | D29: ➃18度C-各編組展開 (一配) | P29: ⑤18度C-各編組展開 (二配)
B30: 編組 | D30: 1 | E30: 2 | F30: 3 | G30: 4 | H30: 5 | I30: 6 | J30: 7 | K30: 8 | L30: 9 | M30: 10 | N30: 11 | O30: 12 | P30: 1 | Q30: 2 | R30: 3 | S30: 4 | T30: 5 | U30: 6 | V30: 7 | W30: 8 | X30: 9
D31: 便當一線 | E31: 涼麵一線 | F31: 涼麵三線 | G31: 自動包裝機 | H31: 自動包裝機2 | I31: 自動包裝機3 | J31: 味付飯糰線B | K31: (舊) 3300型飯糰線 | L31: 3000型飯糰線 | M31: (新) 3300型飯糰機 | N31: GKK3600型 飯糰機 | O31: GKK3600型 飯糰機2 | P31: 自動包裝機 | Q31: 自動包裝機2 | R31: 自動包裝機3 | S31: 味付飯糰線B | T31: (舊) 3300型飯糰線 | U31: 3000型飯糰線 | V31: (新) 3300型飯糰機 | W31: GKK3600型 飯糰機 | X31: GKK3600型 飯糰機2
B32: 人時性 | C32: 排關 | D32: - | E32: - | F32: - | G32: 327.27273 | H32: - | I32: - | J32: - | K32: - | L32: - | M32: 1100 | N32: 923.07692 | O32: 900 | P32: 288 | Q32: - | R32: - | S32: - | T32: - | U32: - | V32: 775 | W32: 913.63636 | X32: 900
C33: 實績 | D33: - | E33: - | F33: - | G33: 286.81861 | H33: - | I33: - | J33: - | K33: - | L33: - | M33: 996.19476 | N33: 823.9677 | O33: 796.79004 | P33: 255.14385 | Q33: - | R33: - | S33: - | T33: - | U33: - | V33: 700.47734 | W33: 816.92406 | X33: 798.06138
C34: 達成率 | D34: - | E34: - | F34: - | G34: =G33/G32 -> 0.87639019 | H34: - | I34: - | J34: - | K34: - | L34: - | M34: =M33/M32 -> 0.9056316 | N34: =N33/N32 -> 0.89263168 | O34: =O33/O32 -> 0.88532227 | P34: =P33/P32 -> 0.88591614 | Q34: - | R34: - | S34: - | T34: - | U34: - | V34: =V33/V32 -> 0.90384173 | W34: =W33/W32 -> 0.89414574 | X34: =X33/X32 -> 0.88673487
B35: 作業 時間 | C35: 開始 | D35: - | E35: - | F35: - | G35: 0.25 | H35: - | I35: - | J35: - | K35: - | L35: - | M35: 0.375 | N35: 0.25 | O35: 0.25 | P35: 0.70833333 | Q35: - | R35: - | S35: - | T35: - | U35: - | V35: 0.70833333 | W35: 0.70833333 | X35: 0.70833333
C36: 結束 | D36: - | E36: - | F36: - | G36: 0.42475694 | H36: - | I36: - | J36: - | K36: - | L36: - | M36: 0.40711806 | N36: 0.54569444 | O36: 0.54077546 | P36: 0.74695602 | Q36: - | R36: - | S36: - | T36: - | U36: - | V36: 0.7859838 | W36: 1.1875694 | X36: 1.1636921
B37: 配置人數 | D37: - | E37: - | F37: - | G37: 11 | H37: - | I37: - | J37: - | K37: - | L37: - | M37: 3 | N37: 3.7142857 | O37: 4 | P37: 12.5 | Q37: - | R37: - | S37: - | T37: - | U37: - | V37: 4 | W37: 3.6666667 | X37: 4
B38: 主要應用設備 | D38: 伺服包裝機 | E38: ET-55 | F38: ET-600 | G38: 夾心型 | H38: 伺服包裝機 | I38: 伺服包裝機 | J38: 夾心型 | K38: 3300型 | L38: 3300型 | M38: 3300型 | N38: GKK | O38: GKK | P38: 夾心型 | Q38: 伺服包裝機 | R38: 伺服包裝機 | S38: 夾心型 | T38: 3300型 | U38: 3300型 | V38: 3300型 | W38: GKK | X38: GKK
B39: 次要應用設備
B40: 備註

Sheet 0530(18度C)
A1: 大溪廠日報分析 | C1: 總生產量 | D1: =SUM(F5:F140) -> 105671 | E1: 營業額 | F1: =SUM(G5:G140) -> 2060605.4 | G1: 出勤人數 | H1: =L21+L38+L55+L72+L89+L106+L123+L140 -> 45.880952 | I1: 產線配置圖 | L1: 生產實績 | O1: 人時性差異分析 | S1: 日報登錄 | Y1: 分析說明 | AA1: 產能差異分析
A2: 46172 | C2: 人時性 | D2: =AVERAGE(N21,N38,N55,N72,N89,N106,N123,N140) -> 684.29722 | E2: 平均廠價 | F2: =F1/D1 -> 19.500198 | G2: 多次生產數 | H2: =COUNT(H5:H140) -> 12
A3: 線別 | B3: 品類 | C3: 品名 | E3: 廠價 | F3: 生產量 | G3: 營收 | H3: 多次 生產 | I3: 人數 | J3: 產能/時 | K3: 人時性 | L3: 人數 | M3: 產能/時 | N3: 人時性 | O3: 人數 | P3: 人時性 | Q3: 達成率 | R3: 達成率 平均 | S3: 生產時間 | U3: 換線、休息/分 | V3: 稼動時間/分 | W3: 休息時間 | Y3: (屏榮回填) | AA3: 產能/時 | AB3: 達成率 | AC3: 達成率平均
S4: 開始 | T4: 結束 | W4: 開始 | X4: 結束
A5: 自動包裝機 | B5: 18℃-壽司手卷 | C5: 一配長野稻荷壽司 | E5: 25.64 | F5: 1377 | G5: =E5*F5 -> 35306.28 | I5: 10 | J5: 3600 | K5: =J5/I5 -> 360 | L5: 10 | M5: =F5/V5*60 -> 3203.5937 | N5: =M5/L5 -> 320.35937 | O5: =L5-I5 -> 0 | P5: =N5-K5 -> -39.640631 | Q5: =N5/K5 -> 0.88988714 | R5: =Q21 -> 0.87639019 | S5: 0.25 | T5: 0.26790509 | V5: 25.789787 | AA5: =M5-J5 -> -396.40631 | AB5: =M5/J5 -> 0.88988714 | AC5: =AB21 -> 0.87639019
B6: 18℃-壽司手卷 | C6: 一配經典人氣雙手卷 | E6: 29.52 | F6: 2528 | G6: =E6*F6 -> 74626.56 | I6: 11 | J6: 3600 | K6: =J6/I6 -> 327.27273 | L6: 11 | M6: =F6/V6*60 -> 3151.038 | N6: =M6/L6 -> 286.458 | O6: =L6-I6 -> 0 | P6: =N6-K6 -> -40.814728 | Q6: =N6/K6 -> 0.87528833 | S6: 0.27152778 | T6: 0.3049537 | U6: 5.2166667 | V6: 48.136519 | AA6: =M6-J6 -> -448.96201 | AB6: =M6/J6 -> 0.87528833
B7: 18℃-壽司手卷 | C7: 一配鮭鮪海饌雙手卷 | E7: 29.85 | F7: 2911 | G7: =E7*F7 -> 86893.35 | I7: 11 | J7: 3600 | K7: =J7/I7 -> 327.27273 | L7: 11 | M7: =F7/V7*60 -> 3150.3436 | N7: =M7/L7 -> 286.39487 | O7: =L7-I7 -> 0 | P7: =N7-K7 -> -40.877855 | Q7: =N7/K7 -> 0.87509544 | S7: 0.30902778 | T7: 0.34752315 | U7: 5.8666667 | V7: 55.441572 | AA7: =M7-J7 -> -449.6564 | AB7: =M7/J7 -> 0.87509544
B8: 18℃-飯糰 | C8: 一配兩粒飯糰(鮪魚.焦糖鮭魚) | E8: 28.57 | F8: 1669 | G8: =E8*F8 -> 47683.33 | I8: 12 | J8: 3600 | K8: =J8/I8 -> 300 | L8: 12 | M8: =F8/V8*60 -> 3115.0435 | N8: =M8/L8 -> 259.58696 | O8: =L8-I8 -> 0 | P8: =N8-K8 -> -40.413044 | Q8: =N8/K8 -> 0.86528985 | S8: 0.35138889 | T8: 0.3737037 | U8: 5.5666667 | V8: 32.147224 | AA8: =M8-J8 -> -484.95652 | AB8: =M8/J8 -> 0.86528985
B21: 平均 | I21: =AVERAGE(I5:I20) -> 11 | J21: =AVERAGE(J5:J20) -> 3600 | K21: =J21/I21 -> 327.27273 | L21: =AVERAGE(L5:L20) -> 11 | M21: =AVERAGE(M5:M20) -> 3155.0047 | N21: =M21/L21 -> 286.81861 | O21: =L21-I21 -> 0 | P21: =N21-K21 -> -40.454119 | Q21: =N21/K21 -> 0.87639019 | S21: 0.25 | T21: 0.42475694 | AA21: =M21-J21 -> -444.99531 | AB21: =M21/J21 -> 0.87639019
A22: (新) 3300型飯糰機 | B22: 18℃-飯糰 | C22: 一配鮭魚奶油醬油飯糰 | E22: 18.53 | F22: 2304 | G22: =E22*F22 -> 42693.12 | I22: 3 | J22: 3300 | K22: =J22/I22 -> 1100 | L22: 3 | M22: =F22/V22*60 -> 2988.5843 | N22: =M22/L22 -> 996.19476 | O22: =L22-I22 -> 0 | P22: =N22-K22 -> -103.80524 | Q22: =N22/K22 -> 0.9056316 | R22: =Q38 -> 0.9056316 | S22: 0.375 | T22: 0.40711806 | V22: 46.256015 | AA22: =M22-J22 -> -311.41572 | AB22: =M22/J22 -> 0.9056316 | AC22: =AB38 -> 0.9056316
B38: 平均 | I38: =AVERAGE(I22:I37) -> 3 | J38: =AVERAGE(J22:J37) -> 3300 | K38: =J38/I38 -> 1100 | L38: =AVERAGE(L22:L37) -> 3 | M38: =AVERAGE(M22:M37) -> 2988.5843 | N38: =M38/L38 -> 996.19476 | O38: =L38-I38 -> 0 | P38: =N38-K38 -> -103.80524 | Q38: =N38/K38 -> 0.9056316 | S38: 0.375 | T38: 0.40711806 | AA38: =M38-J38 -> -311.41572 | AB38: =M38/J38 -> 0.9056316
A39: GKK3600型 飯糰機 | B39: 18℃-飯糰 | C39: 一配贅沢鮭魚肚飯糰 | E39: 30 | F39: 1992 | G39: =E39*F39 -> 59760 | I39: 4 | J39: 3600 | K39: =J39/I39 -> 900 | L39: 4 | M39: =F39/V39*60 -> 3189.24 | N39: =M39/L39 -> 797.31 | O39: =L39-I39 -> 0 | P39: =N39-K39 -> -102.69 | Q39: =N39/K39 -> 0.8859 | R39: =Q55 -> 0.89263168 | S39: 0.25 | T39: 0.27601852 | V39: 37.476013 | AA39: =M39-J39 -> -410.76 | AB39: =M39/J39 -> 0.8859 | AC39: =AB55 -> 0.89263168
B40: 18℃-飯糰 | C40: 一配熟成紅鮭飯糰 | E40: 25.03 | F40: 1099 | G40: =E40*F40 -> 27507.97 | I40: 5 | J40: 3600 | K40: =J40/I40 -> 720 | L40: 5 | M40: =F40/V40*60 -> 3185.262 | N40: =M40/L40 -> 637.0524 | O40: =L40-I40 -> 0 | P40: =N40-K40 -> -82.947597 | Q40: =N40/K40 -> 0.884795 | S40: 0.28611111 | T40: 0.30048611 | U40: 14.533333 | V40: 20.701594 | AA40: =M40-J40 -> -414.73799 | AB40: =M40/J40 -> 0.884795
B41: 18℃-飯糰 | C41: 一配壹號醬炙烤牛飯糰 | E41: 22.28 | F41: 886 | G41: =E41*F41 -> 19740.08 | I41: 5 | J41: 3300 | K41: =J41/I41 -> 660 | L41: 5 | M41: =F41/V41*60 -> 2978.7651 | N41: =M41/L41 -> 595.75302 | O41: =L41-I41 -> 0 | P41: =N41-K41 -> -64.246982 | Q41: =N41/K41 -> 0.90265609 | S41: 0.31041667 | T41: 0.32280093 | U41: 15 | V41: 17.846322 | AA41: =M41-J41 -> -321.23491 | AB41: =M41/J41 -> 0.90265609
B42: 18℃-飯糰 | C42: 一配蔬食鮪魚飯糰 | E42: 18.18 | F42: 931 | G42: =E42*F42 -> 16925.58 | I42: 3 | J42: 3600 | K42: =J42/I42 -> 1200 | L42: 3 | M42: =F42/V42*60 -> 3192.0259 | N42: =M42/L42 -> 1064.0086 | O42: =L42-I42 -> 0 | P42: =N42-K42 -> -135.99136 | Q42: =N42/K42 -> 0.88667386 | S42: 0.33263889 | T42: 0.34478009 | U42: 15 | V42: 17.499858 | AA42: =M42-J42 -> -407.97409 | AB42: =M42/J42 -> 0.88667386
B43: 18℃-飯糰 | C43: 一配黑胡椒洋蔥豬飯糰 | E43: 17.07 | F43: 3319 | G43: =E43*F43 -> 56655.33 | I43: 3 | J43: 3300 | K43: =J43/I43 -> 1100 | L43: 3 | M43: =F43/V43*60 -> 2977.2331 | N43: =M43/L43 -> 992.41104 | O43: =L43-I43 -> 0 | P43: =N43-K43 -> -107.58896 | Q43: =N43/K43 -> 0.90219185 | S43: 0.35486111 | T43: 0.40130787 | U43: 14.516667 | V43: 66.887608 | AA43: =M43-J43 -> -322.76689 | AB43: =M43/J43 -> 0.90219185
B44: 18℃-飯糰 | C44: 一配經典肉鬆飯糰 | E44: 14.03 | F44: 3750 | G44: =E44*F44 -> 52612.5 | I44: 3 | J44: 3000 | K44: =J44/I44 -> 1000 | L44: 3 | M44: =F44/V44*60 -> 2714.51 | N44: =M44/L44 -> 904.83668 | O44: =L44-I44 -> 0 | P44: =N44-K44 -> -95.163322 | Q44: =N44/K44 -> 0.90483668 | S44: 0.41111111 | T44: 0.46866898 | U44: 15 | V44: 82.887887 | AA44: =M44-J44 -> -285.48997 | AB44: =M44/J44 -> 0.90483668
B45: 18℃-飯糰 | C45: 一配鮪魚飯糰 | E45: 14.28 | F45: 5141 | G45: =E45*F45 -> 73413.48 | I45: 3 | J45: 3600 | K45: =J45/I45 -> 1200 | L45: 3 | M45: =F45/V45*60 -> 3186.1241 | N45: =M45/L45 -> 1062.0414 | O45: =L45-I45 -> 0 | P45: =N45-K45 -> -137.95864 | Q45: =N45/K45 -> 0.88503447 | S45: 0.47847222 | T45: 0.54569444 | U45: 15 | V45: 96.813555 | AA45: =M45-J45 -> -413.87591 | AB45: =M45/J45 -> 0.88503447
B55: 平均 | I55: =AVERAGE(I39:I54) -> 3.7142857 | J55: =AVERAGE(J39:J54) -> 3428.5714 | K55: =J55/I55 -> 923.07692 | L55: =AVERAGE(L39:L54) -> 3.7142857 | M55: =AVERAGE(M39:M54) -> 3060.4515 | N55: =M55/L55 -> 823.9677 | O55: =L55-I55 -> 0 | P55: =N55-K55 -> -99.109221 | Q55: =N55/K55 -> 0.89263168 | S55: 0.25 | T55: 0.54569444 | AA55: =M55-J55 -> -368.11996 | AB55: =M55/J55 -> 0.89263168
A56: GKK3600型 飯糰機2 | B56: 18℃-飯糰 | C56: 一配鹽蔥燒肉飯糰 | E56: 17.89 | F56: 2560 | G56: =E56*F56 -> 45798.4 | I56: 4 | J56: 3600 | K56: =J56/I56 -> 900 | L56: 4 | M56: =F56/V56*60 -> 3185.3987 | N56: =M56/L56 -> 796.34967 | O56: =L56-I56 -> 0 | P56: =N56-K56 -> -103.65033 | Q56: =N56/K56 -> 0.88483296 | R56: =Q72 -> 0.88532227 | S56: 0.25 | T56: 0.2834838 | V56: 48.220024 | AA56: =M56-J56 -> -414.60133 | AB56: =M56/J56 -> 0.88483296 | AC56: =AB72 -> 0.88532227
B57: 18℃-飯糰 | C57: 一配北海道秋鮭親子飯糰 | E57: 24.82 | F57: 1509 | G57: =E57*F57 -> 37453.38 | I57: 5 | J57: 3600 | K57: =J57/I57 -> 720 | L57: 5 | M57: =F57/V57*60 -> 3184.9433 | N57: =M57/L57 -> 636.98867 | O57: =L57-I57 -> 0 | P57: =N57-K57 -> -83.011334 | Q57: =N57/K57 -> 0.88470648 | S57: 0.29375 | T57: 0.3134838 | U57: 14.783333 | V57: 28.427507 | AA57: =M57-J57 -> -415.05667 | AB57: =M57/J57 -> 0.88470648
B58: 18℃-飯糰 | C58: 一配明太子龍蝦風味沙拉飯糰 | E58: 18.18 | F58: 1795 | G58: =E58*F58 -> 32633.1 | I58: 3 | J58: 3600 | K58: =J58/I58 -> 1200 | L58: 3 | M58: =F58/V58*60 -> 3189.1183 | N58: =M58/L58 -> 1063.0394 | O58: =L58-I58 -> 0 | P58: =N58-K58 -> -136.96057 | Q58: =N58/K58 -> 0.88586619 | S58: 0.32361111 | T58: 0.34706019 | U58: 14.583333 | V58: 33.77109 | AA58: =M58-J58 -> -410.88171 | AB58: =M58/J58 -> 0.88586619
B59: 18℃-飯糰 | C59: 一配柚檸海灣貝飯糰 | E59: 23.72 | F59: 1705 | G59: =E59*F59 -> 40442.6 | I59: 5 | J59: 3600 | K59: =J59/I59 -> 720 | L59: 5 | M59: =F59/V59*60 -> 3182.8847 | N59: =M59/L59 -> 636.57694 | O59: =L59-I59 -> 0 | P59: =N59-K59 -> -83.423057 | Q59: =N59/K59 -> 0.88413464 | S59: 0.35694444 | T59: 0.37925926 | U59: 15 | V59: 32.140655 | W59: 0.37925926 | X59: 0.38958333 | AA59: =M59-J59 -> -417.11528 | AB59: =M59/J59 -> 0.88413464
B60: 18℃-飯糰 | C60: 一配山葵章魚飯糰 | E60: 25.2 | F60: 1697 | G60: =E60*F60 -> 42764.4 | I60: 3 | J60: 3600 | K60: =J60/I60 -> 1200 | L60: 3 | M60: =F60/V60*60 -> 3184.4424 | N60: =M60/L60 -> 1061.4808 | O60: =L60-I60 -> 0 | P60: =N60-K60 -> -138.5192 | Q60: =N60/K60 -> 0.88456733 | S60: 0.38958333 | T60: 0.41178241 | U60: 14.866667 | V60: 31.974201 | AA60: =M60-J60 -> -415.5576 | AB60: =M60/J60 -> 0.88456733
B61: 18℃-飯糰 | C61: 一配椒鹽檸檬鯖魚飯糰 | E61: 20.72 | F61: 3945 | G61: =E61*F61 -> 81740.4 | I61: 3 | J61: 3600 | K61: =J61/I61 -> 1200 | L61: 3 | M61: =F61/V61*60 -> 3190.358 | N61: =M61/L61 -> 1063.4527 | O61: =L61-I61 -> 0 | P61: =N61-K61 -> -136.54734 | Q61: =N61/K61 -> 0.88621055 | S61: 0.42152778 | T61: 0.47304398 | U61: 15 | V61: 74.192301 | AA61: =M61-J61 -> -409.64202 | AB61: =M61/J61 -> 0.88621055
B62: 18℃-飯糰 | C62: 一配雞肉飯飯糰 | E62: 16.66 | F62: 4402 | G62: =E62*F62 -> 73337.32 | I62: 5 | J62: 3600 | K62: =J62/I62 -> 720 | L62: 5 | M62: =F62/V62*60 -> 3192.9758 | N62: =M62/L62 -> 638.59517 | O62: =L62-I62 -> 0 | P62: =N62-K62 -> -81.404834 | Q62: =N62/K62 -> 0.88693773 | S62: 0.48333333 | T62: 0.54077546 | U62: 14.816667 | V62: 82.719073 | AA62: =M62-J62 -> -407.02417 | AB62: =M62/J62 -> 0.88693773
B72: 平均 | I72: =AVERAGE(I56:I71) -> 4 | J72: =AVERAGE(J56:J71) -> 3600 | K72: =J72/I72 -> 900 | L72: =AVERAGE(L56:L71) -> 4 | M72: =AVERAGE(M56:M71) -> 3187.1602 | N72: =M72/L72 -> 796.79004 | O72: =L72-I72 -> 0 | P72: =N72-K72 -> -103.20996 | Q72: =N72/K72 -> 0.88532227 | S72: 0.25 | T72: 0.54077546 | AA72: =M72-J72 -> -412.83983 | AB72: =M72/J72 -> 0.88532227
A73: 自動包裝機 (二配) | B73: 18℃-飯糰 | C73: 二配兩粒飯糰(鮪魚.焦糖鮭魚) | E73: 28.57 | F73: 1812 | G73: =E73*F73 -> 51768.84 | I73: 12 | J73: 3600 | K73: =J73/I73 -> 300 | L73: 12 | M73: =F73/V73*60 -> 3115.0029 | N73: =M73/L73 -> 259.58358 | O73: =L73-I73 -> 0 | P73: =N73-K73 -> -40.416423 | Q73: =N73/K73 -> 0.86527859 | R73: =Q89 -> 0.88591614 | S73: 0.70833333 | T73: 0.73256944 | V73: 34.902054 | AA73: =M73-J73 -> -484.99707 | AB73: =M73/J73 -> 0.86527859 | AC73: =AB89 -> 0.88591614
B74: 18℃-飯糰 | C74: 二配溏心蛋五目飯糰 | E74: 20.42 | F74: 904 | G74: =E74*F74 -> 18459.68 | I74: 13 | J74: 3600 | K74: =J74/I74 -> 276.92308 | L74: 13 | M74: =F74/V74*60 -> 3263.5933 | N74: =M74/L74 -> 251.04564 | O74: =L74-I74 -> 0 | P74: =N74-K74 -> -25.87744 | Q74: =N74/K74 -> 0.90655369 | S74: 0.73541667 | T74: 0.74695602 | U74: 5 | V74: 16.619718 | AA74: =M74-J74 -> -336.40671 | AB74: =M74/J74 -> 0.90655369
B89: 平均 | I89: =AVERAGE(I73:I88) -> 12.5 | J89: =AVERAGE(J73:J88) -> 3600 | K89: =J89/I89 -> 288 | L89: =AVERAGE(L73:L88) -> 12.5 | M89: =AVERAGE(M73:M88) -> 3189.2981 | N89: =M89/L89 -> 255.14385 | O89: =L89-I89 -> 0 | P89: =N89-K89 -> -32.856151 | Q89: =N89/K89 -> 0.88591614 | S89: 0.70833333 | T89: 0.74695602 | AA89: =M89-J89 -> -410.70189 | AB89: =M89/J89 -> 0.88591614
A90: (新) 3300型飯糰機 (二配) | B90: 18℃-飯糰 | C90: 二配鹽水G絲飯糰 | E90: 17.22 | F90: 1540 | G90: =E90*F90 -> 26518.8 | I90: 3 | J90: 3300 | K90: =J90/I90 -> 1100 | L90: 3 | M90: =F90/V90*60 -> 2989.4188 | N90: =M90/L90 -> 996.47294 | O90: =L90-I90 -> 0 | P90: =N90-K90 -> -103.52706 | Q90: =N90/K90 -> 0.90588449 | R90: =Q106 -> 0.90384173 | S90: 0.70833333 | T90: 0.72979167 | V90: 30.909018 | AA90: =M90-J90 -> -310.58117 | AB90: =M90/J90 -> 0.90588449 | AC90: =AB106 -> 0.90384173
B91: 18℃-飯糰 | C91: 二配大飯糰韓式蒜烤豬五花 | E91: 24.54 | F91: 1748 | G91: =E91*F91 -> 42895.92 | I91: 4 | J91: 3000 | K91: =J91/I91 -> 750 | L91: 4 | M91: =F91/V91*60 -> 2707.9175 | N91: =M91/L91 -> 676.97938 | O91: =L91-I91 -> 0 | P91: =N91-K91 -> -73.020624 | Q91: =N91/K91 -> 0.90263917 | S91: 0.73333333 | T91: 0.76021991 | U91: 5.1 | V91: 38.73087 | AA91: =M91-J91 -> -292.0825 | AB91: =M91/J91 -> 0.90263917
B92: 18℃-飯糰 | C92: 二配大飯糰乾燒風味鮮蝦 | E92: 23.27 | F92: 1482 | G92: =E92*F92 -> 34486.14 | I92: 5 | J92: 3000 | K92: =J92/I92 -> 600 | L92: 5 | M92: =F92/V92*60 -> 2708.3917 | N92: =M92/L92 -> 541.67835 | O92: =L92-I92 -> 0 | P92: =N92-K92 -> -58.32165 | Q92: =N92/K92 -> 0.90279725 | S92: 0.76319444 | T92: 0.7859838 | U92: 5 | V92: 32.831292 | AA92: =M92-J92 -> -291.60825 | AB92: =M92/J92 -> 0.90279725
B106: 平均 | I106: =AVERAGE(I90:I105) -> 4 | J106: =AVERAGE(J90:J105) -> 3100 | K106: =J106/I106 -> 775 | L106: =AVERAGE(L90:L105) -> 4 | M106: =AVERAGE(M90:M105) -> 2801.9094 | N106: =M106/L106 -> 700.47734 | O106: =L106-I106 -> 0 | P106: =N106-K106 -> -74.52266 | Q106: =N106/K106 -> 0.90384173 | S106: 0.70833333 | T106: 0.7859838 | AA106: =M106-J106 -> -298.09064 | AB106: =M106/J106 -> 0.90384173
A107: GKK3600型 飯糰機 (二配) | B107: 18℃-飯糰 | C107: 二配壹號醬炙烤牛飯糰 | E107: 22.28 | F107: 516 | G107: =E107*F107 -> 11496.48 | H107: 2 | I107: 5 | J107: 3300 | K107: =J107/I107 -> 660 | L107: 5 | M107: =F107/V107*60 -> 2975.0048 | N107: =M107/L107 -> 595.00095 | O107: =L107-I107 -> 0 | P107: =N107-K107 -> -64.999049 | Q107: =N107/K107 -> 0.90151659 | R107: =Q123 -> 0.89414574 | S107: 0.70833333 | T107: 0.71555556 | V107: 10.406706 | AA107: =M107-J107 -> -324.99525 | AB107: =M107/J107 -> 0.90151659 | AC107: =AB123 -> 0.89414574
B108: 18℃-飯糰 | C108: 二配熟成紅鮭飯糰 | E108: 25.03 | F108: 693 | G108: =E108*F108 -> 17345.79 | H108: 2 | I108: 5 | J108: 3600 | K108: =J108/I108 -> 720 | L108: 5 | M108: =F108/V108*60 -> 3196.6175 | N108: =M108/L108 -> 639.3235 | O108: =L108-I108 -> 0 | P108: =N108-K108 -> -80.676502 | Q108: =N108/K108 -> 0.8879493 | S108: 0.72569444 | T108: 0.73472222 | U108: 14.6 | V108: 13.007499 | AA108: =M108-J108 -> -403.38251 | AB108: =M108/J108 -> 0.8879493
B109: 18℃-飯糰 | C109: 二配蔬食鮪魚飯糰 | E109: 18.18 | F109: 412 | G109: =E109*F109 -> 7490.16 | H109: 2 | I109: 3 | J109: 3600 | K109: =J109/I109 -> 1200 | L109: 3 | M109: =F109/V109*60 -> 3194.1561 | N109: =M109/L109 -> 1064.7187 | O109: =L109-I109 -> 0 | P109: =N109-K109 -> -135.28131 | Q109: =N109/K109 -> 0.88726557 | S109: 0.74513889 | T109: 0.75050926 | U109: 15 | V109: 7.7391334 | AA109: =M109-J109 -> -405.84394 | AB109: =M109/J109 -> 0.88726557
B110: 18℃-飯糰 | C110: 二配芝麻香鬆飯糰 | E110: 18.18 | F110: 622 | G110: =E110*F110 -> 11307.96 | H110: 2 | I110: 3 | J110: 3000 | K110: =J110/I110 -> 1000 | L110: 3 | M110: =F110/V110*60 -> 2712.4607 | N110: =M110/L110 -> 904.15355 | O110: =L110-I110 -> 0 | P110: =N110-K110 -> -95.846449 | Q110: =N110/K110 -> 0.90415355 | S110: 0.76041667 | T110: 0.76996528 | U110: 15 | V110: 13.758725 | AA110: =M110-J110 -> -287.53935 | AB110: =M110/J110 -> 0.90415355
B111: 18℃-飯糰 | C111: 二配經典肉鬆飯糰 | E111: 14.03 | F111: 2360 | G111: =E111*F111 -> 33110.8 | H111: 2 | I111: 3 | J111: 3000 | K111: =J111/I111 -> 1000 | L111: 3 | M111: =F111/V111*60 -> 2712.925 | N111: =M111/L111 -> 904.30835 | O111: =L111-I111 -> 0 | P111: =N111-K111 -> -95.691655 | Q111: =N111/K111 -> 0.90430835 | S111: 0.77986111 | T111: 0.81609954 | U111: 15 | V111: 52.194586 | AA111: =M111-J111 -> -287.07496 | AB111: =M111/J111 -> 0.90430835
B112: 18℃-飯糰 | C112: 二配鮪魚飯糰 | E112: 14.28 | F112: 2954 | G112: =E112*F112 -> 42183.12 | H112: 2 | I112: 3 | J112: 3600 | K112: =J112/I112 -> 1200 | L112: 3 | M112: =F112/V112*60 -> 3180.0845 | N112: =M112/L112 -> 1060.0282 | O112: =L112-I112 -> 0 | P112: =N112-K112 -> -139.97184 | Q112: =N112/K112 -> 0.8833568 | S112: 0.82638889 | T112: 0.86509259 | U112: 14.816667 | V112: 55.734368 | AA112: =M112-J112 -> -419.91552 | AB112: =M112/J112 -> 0.8833568
...

Sheet 0530(4度C)
A1: 大溪廠日報分析 | C1: 總生產量 | D1: =SUM(F5:F140) -> 84782 | E1: 營業額 | F1: =SUM(G5:G140) -> 3646046.4 | G1: 出勤人數 | H1: =L21+L38+L55+L72+L89+L106+L123+L140 -> 140.52222 | I1: 產線配置圖 | L1: 生產實績 | O1: 人時性差異分析 | S1: 日報登錄 | Y1: 合計次數 | Z1: 合計(時間/分) | AA1: 產線異常 分析說明(5分鐘以上) | AC1: 合計次數 | AD1: 合計(時間/分) | AE1: 產能差異分析
A2: 46172 | C2: 人時性 | D2: =AVERAGE(N21,N38,N55,N72,N89,N106,N123,N140) -> 175.69131 | E2: 平均廠價 | F2: =F1/D1 -> 43.004959 | G2: 多次生產數 | H2: =COUNT(H5:H140) -> 2 | Y2: =SUM(Y21,Y38,Y55,Y72,Y89,Y106,Y123,Y140) -> 0 | Z2: =SUM(Z21,Z38,Z55,Z72,Z89,Z106,Z123,Z140) -> 0 | AC2: =SUM(AC21,AC38,AC55,AC72,AC89,AC106,AC123,AC140) -> 0 | AD2: =SUM(AD21,AD38,AD55,AD72,AD89,AD106,AD123,AD140) -> 0
A3: 線別 | B3: 品類 | C3: 品名 | E3: 廠價 | F3: 生產量 | G3: 營收 | H3: 多次 生產 | I3: 人數 | J3: 產能/時 | K3: 人時性 | L3: 人數 | M3: 產能/時 | N3: 人時性 | O3: 人數 | P3: 人時性 | Q3: 達成率 | R3: 達成率 平均 | S3: 生產時間 | U3: 換線、休息/分 | V3: 稼動時間/分 | W3: 休息時間 | Y3: 產線異常統計(5分鐘以上) | AA3: (屏榮回填) | AC3: 短暫停線統計(5分鐘以下) | AE3: 產能/時 | AF3: 達成率 | AG3: 達成率平均
S4: 開始 | T4: 結束 | W4: 開始 | X4: 結束 | Y4: 次數 | Z4: 時間/分 | AC4: 總次數 | AD4: 設備因素(次數)
