Workbook

Sheet 0810
B1: 屏榮 大溪廠組合室生產人時性分析
B3: 日期 | C3: 115.08.10星期一 | E3: 訂單量 | F3: ='0810(18度C)'!D1+'0810(4度C)'!D1 -> 203928 | H3: 營業額 | I3: ='0810(18度C)'!F1+'0810(4度C)'!F1 -> 6334097.6
B4: 人時性 | C4: 項目 | E4: ➀ | G4: ➁ | I4: ➂ | K4: ④ | M4: ⑤ | O4: 異常停線 | Q4: 短暫停線
C5: 組合室 | E5: 全溫層 | G5: 4度C-各編組展開(一配) | I5: 4度C-各編組展開(二配) | K5: 18度C-各編組展開(一配) | M5: 18度C-各編組展開(二配) | O5: 合計次數 | P5: 時間 | Q5: 合計次數 | R5: 設備次數
C6: 排關平均 | E6: =AVERAGE(D14:O14,D32:X32) -> 497.21851 | F6: =AVERAGE(#REF!,D14:K14) -> #REF! | G6: =AVERAGE(D14:K14) -> 270.36048 | I6: =AVERAGE(L14:O14) -> 94.325718 | K6: =AVERAGE(D32:O32) -> 745.17045 | M6: =AVERAGE(P32:X32) -> 791 | O6: ='0810(4度C)'!Y2 -> 0 | P6: ='0810(4度C)'!Z2 -> 0 | Q6: ='0810(4度C)'!AC2 -> 0 | R6: ='0810(4度C)'!AD2 -> 0
C7: 實績平均 | E7: =AVERAGE(D15:O15,D33:X33) -> 446.9071 | F7: =AVERAGE(#REF!,D15:K15) -> #REF! | G7: =AVERAGE(D15:K15) -> 239.11906 | I7: =AVERAGE(L15:O15) -> 87.501787 | K7: =AVERAGE(D33:O33) -> 671.59199 | M7: =AVERAGE(P33:X33) -> 713.60693
C8: 達成率平均 | E8: =AVERAGE(D16:O16,D34:X34) -> 0.90062994 | F8: =AVERAGE(D16:K16,#REF!) -> #REF! | G8: =AVERAGE(D16:K16) -> 0.89344112 | I8: =AVERAGE(L16:O16) -> 0.92580032 | K8: =AVERAGE(D34:O34) -> 0.89786111 | M8: =AVERAGE(P34:X34) -> 0.90159679
O9: ※現行日本鮮食廠以達成率80%為基本(即為現行KPI)
B11: 溫層 | D11: ➁4度C-各編組展開 | L11: ➂4度C-各編組展開
B12: 編組 | D12: 1 | E12: 2 | F12: 3 | G12: 4 | H12: 5 | I12: 6 | J12: 7 | K12: 8 | L12: 1 | M12: 2 | N12: 3 | O12: 4
D13: 便當一線 | E13: 便當二線 | F13: 涼麵一線 | G13: 涼麵二線 | H13: 涼麵三線 | I13: 自動包裝機 | J13: 自動包裝機2 | K13: 自動包裝機3 | L13: 便當一線 | M13: 便當二線 | N13: 涼麵一線 | O13: 涼麵二線
B14: 人時性 | C14: 排關 | D14: - | E14: 83.72093 | F14: 111.31579 | G14: 90.322581 | H14: 171.42857 | I14: 565.375 | J14: 600 | K14: - | L14: - | M14: 101.69492 | N14: 86.956522 | O14: -
C15: 實績 | D15: - | E15: 75.531327 | F15: 100.52621 | G15: 81.425878 | H15: 154.24812 | I15: 481.44777 | J15: 541.53503 | K15: - | L15: - | M15: 96.564286 | N15: 78.439289 | O15: -
C16: 達成率 | D16: - | E16: =E15/E14 -> 0.90217973 | F16: =F15/F14 -> 0.90307235 | G16: =G15/G14 -> 0.90150079 | H16: =H15/H14 -> 0.89978071 | I16: =I15/I14 -> 0.85155475 | J16: =J15/J14 -> 0.90255839 | K16: - | L16: - | M16: =M15/M14 -> 0.94954881 | N16: =N15/N14 -> 0.90205182 | O16: -
B17: 作業 時間 | C17: 開始 | D17: - | E17: 0.20833333 | F17: 0.20833333 | G17: 0.16666667 | H17: 0.16666667 | I17: 0.20833333 | J17: 0.25 | K17: - | L17: - | M17: 0.70833333 | N17: 0.70833333 | O17: -
C18: 結束 | D18: - | E18: 0.64444444 | F18: 0.55238426 | G18: 0.66355324 | H18: 0.5650463 | I18: 0.46320602 | J18: 0.31898148 | K18: - | L18: - | M18: 0.82371528 | N18: 0.84960648 | O18: -
B19: 產線異常 (5分鐘以上) | C19: 次數
C20: 時間/分
B21: 短暫停線 (5分鐘以下) | C21: 次數
C22: 設備次數
B23: 配置人數 | D23: - | E23: 21.5 | F23: 19.166667 | G23: 22.142857 | H23: 21 | I23: 5.6666667 | J23: 6 | K23: - | L23: - | M23: 18.666667 | N23: 23 | O23: -
B24: 主要應用設備 | D24: L型封口機 | E24: ET-55 | F24: ET-55 | G24: ET-55 | H24: ET-600 | I24: 伺服包裝機 | J24: 伺服包裝機 | K24: 伺服包裝機 | L24: L型封口機 | M24: ET-55 | N24: ET-55 | O24: ET-55
B25: 次要應用設備 | D25: 伺服包裝機 | H25: 伺服包裝機
B26: 備註 | H26: 涼麵+烤飯糰 | I26: 大口飯糰線 | K26: 烤飯糰+手卷
B29: 溫層 | D29: ➃18度C-各編組展開 (一配) | P29: ⑤18度C-各編組展開 (二配)
B30: 編組 | D30: 1 | E30: 2 | F30: 3 | G30: 4 | H30: 5 | I30: 6 | J30: 7 | K30: 8 | L30: 9 | M30: 10 | N30: 11 | O30: 12 | P30: 1 | Q30: 2 | R30: 3 | S30: 4 | T30: 5 | U30: 6 | V30: 7 | W30: 8 | X30: 9
D31: 便當一線 | E31: 涼麵一線 | F31: 涼麵三線 | G31: 自動包裝機 | H31: 自動包裝機2 | I31: 自動包裝機3 | J31: 味付飯糰線B | K31: (舊) 3300型飯糰線 | L31: 3000型飯糰線 | M31: (新) 3300型飯糰機 | N31: GKK3600型 飯糰機 | O31: GKK3600型 飯糰機2 | P31: 自動包裝機 | Q31: 自動包裝機2 | R31: 自動包裝機3 | S31: 味付飯糰線B | T31: (舊) 3300型飯糰線 | U31: 3000型飯糰線 | V31: (新) 3300型飯糰機 | W31: GKK3600型 飯糰機 | X31: GKK3600型 飯糰機2
B32: 人時性 | C32: 排關 | D32: - | E32: - | F32: - | G32: 327.27273 | H32: - | I32: - | J32: - | K32: - | L32: - | M32: 825 | N32: 940.90909 | O32: 887.5 | P32: 490.90909 | Q32: - | R32: - | S32: - | T32: - | U32: - | V32: 709.09091 | W32: 1100 | X32: 864
C33: 實績 | D33: - | E33: - | F33: - | G33: 287.42851 | H33: - | I33: - | J33: - | K33: - | L33: - | M33: 754.29135 | N33: 847.83687 | O33: 796.81123 | P33: 438.60095 | Q33: - | R33: - | S33: - | T33: - | U33: - | V33: 648.09035 | W33: 994.79493 | X33: 772.94148
C34: 達成率 | D34: - | E34: - | F34: - | G34: =G33/G32 -> 0.87825377 | H34: - | I34: - | J34: - | K34: - | L34: - | M34: =M33/M32 -> 0.91429255 | N34: =N33/N32 -> 0.90108267 | O34: =O33/O32 -> 0.89781547 | P34: =P33/P32 -> 0.89344638 | Q34: - | R34: - | S34: - | T34: - | U34: - | V34: =V33/V32 -> 0.91397357 | W34: =W33/W32 -> 0.90435903 | X34: =X33/X32 -> 0.8946082
B35: 作業 時間 | C35: 開始 | D35: - | E35: - | F35: - | G35: 0.20833333 | H35: - | I35: - | J35: - | K35: - | L35: - | M35: 0.33680556 | N35: 0.25 | O35: 0.25 | P35: 0.70833333 | Q35: - | R35: - | S35: - | T35: - | U35: - | V35: 0.70833333 | W35: 0.73125 | X35: 0.74027778
C36: 結束 | D36: - | E36: - | F36: - | G36: 0.46320602 | H36: - | I36: - | J36: - | K36: - | L36: - | M36: 0.43195602 | N36: 0.53586806 | O36: 0.51173611 | P36: 0.76032407 | Q36: - | R36: - | S36: - | T36: - | U36: - | V36: 0.88039352 | W36: 1.1289815 | X36: 1.1228935
B37: 配置人數 | D37: - | E37: - | F37: - | G37: 11 | H37: - | I37: - | J37: - | K37: - | L37: - | M37: 4 | N37: 3.6666667 | O37: 4 | P37: 7.3333333 | Q37: - | R37: - | S37: - | T37: - | U37: - | V37: 4.4 | W37: 3 | X37: 4.1666667
B38: 主要應用設備 | D38: 伺服包裝機 | E38: ET-55 | F38: ET-600 | G38: 夾心型 | H38: 伺服包裝機 | I38: 伺服包裝機 | J38: 夾心型 | K38: 3300型 | L38: 3300型 | M38: 3300型 | N38: GKK | O38: GKK | P38: 夾心型 | Q38: 伺服包裝機 | R38: 伺服包裝機 | S38: 夾心型 | T38: 3300型 | U38: 3300型 | V38: 3300型 | W38: GKK | X38: GKK
B39: 次要應用設備
B40: 備註

Sheet 0810(18度C)
A1: 大溪廠日報分析 | C1: 總生產量 | D1: =SUM(F5:F140) -> 110952 | E1: 營業額 | F1: =SUM(G5:G140) -> 2193328.7 | G1: 出勤人數 | H1: =L21+L38+L55+L72+L89+L106+L123+L140 -> 41.566667 | I1: 產線配置圖 | L1: 生產實績 | O1: 人時性差異分析 | S1: 日報登錄 | Y1: 分析說明 | AA1: 產能差異分析
A2: 46244 | C2: 人時性 | D2: =AVERAGE(N21,N38,N55,N72,N89,N106,N123,N140) -> 692.59946 | E2: 平均廠價 | F2: =F1/D1 -> 19.768266 | G2: 多次生產數 | H2: =COUNT(H5:H140) -> 10
A3: 線別 | B3: 品類 | C3: 品名 | E3: 廠價 | F3: 生產量 | G3: 營收 | H3: 多次 生產 | I3: 人數 | J3: 產能/時 | K3: 人時性 | L3: 人數 | M3: 產能/時 | N3: 人時性 | O3: 人數 | P3: 人時性 | Q3: 達成率 | R3: 達成率 平均 | S3: 生產時間 | U3: 換線、休息/分 | V3: 稼動時間/分 | W3: 休息時間 | Y3: (屏榮回填) | AA3: 產能/時 | AB3: 達成率 | AC3: 達成率平均
S4: 開始 | T4: 結束 | W4: 開始 | X4: 結束
A5: 自動包裝機 | B5: 18℃-壽司手卷 | C5: 一配長野稻荷壽司 | E5: 25.64 | F5: 1887 | G5: =E5*F5 -> 48382.68 | I5: 10 | J5: 3600 | K5: =J5/I5 -> 360 | L5: 10 | M5: =F5/V5*60 -> 3216.5296 | N5: =M5/L5 -> 321.65296 | O5: =L5-I5 -> 0 | P5: =N5-K5 -> -38.347045 | Q5: =N5/K5 -> 0.89348043 | R5: =Q21 -> 0.87825377 | S5: 0.20833333 | T5: 0.2327662 | V5: 35.199428 | AA5: =M5-J5 -> -383.47045 | AB5: =M5/J5 -> 0.89348043 | AC5: =AB21 -> 0.87825377
B6: 18℃-壽司手卷 | C6: 一配經典人氣雙手卷 | E6: 29.52 | F6: 2887 | G6: =E6*F6 -> 85224.24 | I6: 11 | J6: 3600 | K6: =J6/I6 -> 327.27273 | L6: 11 | M6: =F6/V6*60 -> 3156.8233 | N6: =M6/L6 -> 286.98394 | O6: =L6-I6 -> 0 | P6: =N6-K6 -> -40.288787 | Q6: =N6/K6 -> 0.87689537 | S6: 0.23680556 | T6: 0.27490741 | U6: 5.8166667 | V6: 54.871617 | AA6: =M6-J6 -> -443.17666 | AB6: =M6/J6 -> 0.87689537
B7: 18℃-壽司手卷 | C7: 一配鮭鮪海饌雙手卷 | E7: 29.85 | F7: 3340 | G7: =E7*F7 -> 99699 | I7: 11 | J7: 3600 | K7: =J7/I7 -> 327.27273 | L7: 11 | M7: =F7/V7*60 -> 3158.3719 | N7: =M7/L7 -> 287.12472 | O7: =L7-I7 -> 0 | P7: =N7-K7 -> -40.148009 | Q7: =N7/K7 -> 0.87732553 | S7: 0.27777778 | T7: 0.32184028 | U7: 5 | V7: 63.450412 | AA7: =M7-J7 -> -441.62809 | AB7: =M7/J7 -> 0.87732553
B8: 18℃-壽司手卷 | C8: 一配青木瓜雞絲泰泰雙手卷 | E8: 30 | F8: 2650 | G8: =E8*F8 -> 79500 | I8: 11 | J8: 3600 | K8: =J8/I8 -> 327.27273 | L8: 11 | M8: =F8/V8*60 -> 3156.3952 | N8: =M8/L8 -> 286.94501 | O8: =L8-I8 -> 0 | P8: =N8-K8 -> -40.327713 | Q8: =N8/K8 -> 0.87677643 | S8: 0.325 | T8: 0.35997685 | U8: 4.55 | V8: 50.373921 | AA8: =M8-J8 -> -443.60484 | AB8: =M8/J8 -> 0.87677643
B9: 18℃-飯糰 | C9: 一配兩粒飯糰(鮪魚.焦糖鮭魚) | E9: 28.57 | F9: 1416 | G9: =E9*F9 -> 40455.12 | I9: 12 | J9: 3600 | K9: =J9/I9 -> 300 | L9: 12 | M9: =F9/V9*60 -> 3120.448 | N9: =M9/L9 -> 260.03733 | O9: =L9-I9 -> 0 | P9: =N9-K9 -> -39.962668 | Q9: =N9/K9 -> 0.86679111 | S9: 0.36319444 | T9: 0.38209491 | U9: 4.6333333 | V9: 27.22686 | AA9: =M9-J9 -> -479.55202 | AB9: =M9/J9 -> 0.86679111
B21: 平均 | I21: =AVERAGE(I5:I20) -> 11 | J21: =AVERAGE(J5:J20) -> 3600 | K21: =J21/I21 -> 327.27273 | L21: =AVERAGE(L5:L20) -> 11 | M21: =AVERAGE(M5:M20) -> 3161.7136 | N21: =M21/L21 -> 287.42851 | O21: =L21-I21 -> 0 | P21: =N21-K21 -> -39.844219 | Q21: =N21/K21 -> 0.87825377 | S21: 0.20833333 | T21: 0.46320602 | AA21: =M21-J21 -> -438.28641 | AB21: =M21/J21 -> 0.87825377
A22: (新) 3300型飯糰機 | B22: 18℃-飯糰 | C22: 一配鮭魚奶油醬油飯糰 | E22: 18.53 | F22: 2482 | G22: =E22*F22 -> 45991.46 | I22: 3 | J22: 3300 | K22: =J22/I22 -> 1100 | L22: 3 | M22: =F22/V22*60 -> 3015.7334 | N22: =M22/L22 -> 1005.2445 | O22: =L22-I22 -> 0 | P22: =N22-K22 -> -94.75552 | Q22: =N22/K22 -> 0.91385862 | R22: =Q38 -> 0.91429255 | S22: 0.33680556 | T22: 0.37108796 | V22: 49.381022 | AA22: =M22-J22 -> -284.26656 | AB22: =M22/J22 -> 0.91385862 | AC22: =AB38 -> 0.91429255
B23: 18℃-飯糰 | C23: 一配壹號醬炙烤牛飯糰 | E23: 22.28 | F23: 766 | G23: =E23*F23 -> 17066.48 | I23: 5 | J23: 3300 | K23: =J23/I23 -> 660 | L23: 5 | M23: =F23/V23*60 -> 3019.0098 | N23: =M23/L23 -> 603.80196 | O23: =L23-I23 -> 0 | P23: =N23-K23 -> -56.198039 | Q23: =N23/K23 -> 0.91485146 | S23: 0.375 | T23: 0.38556713 | U23: 5.6333333 | V23: 15.223535 | AA23: =M23-J23 -> -280.99019 | AB23: =M23/J23 -> 0.91485146
B24: 18℃-飯糰 | C24: 一配鹽蔥燒肉飯糰 | E24: 17.89 | F24: 3068 | G24: =E24*F24 -> 54886.52 | I24: 4 | J24: 3300 | K24: =J24/I24 -> 825 | L24: 4 | M24: =F24/V24*60 -> 3016.753 | N24: =M24/L24 -> 754.18824 | O24: =L24-I24 -> 0 | P24: =N24-K24 -> -70.811761 | Q24: =N24/K24 -> 0.91416756 | S24: 0.38958333 | T24: 0.43195602 | U24: 5.7833333 | V24: 61.019249 | AA24: =M24-J24 -> -283.24704 | AB24: =M24/J24 -> 0.91416756
B38: 平均 | I38: =AVERAGE(I22:I37) -> 4 | J38: =AVERAGE(J22:J37) -> 3300 | K38: =J38/I38 -> 825 | L38: =AVERAGE(L22:L37) -> 4 | M38: =AVERAGE(M22:M37) -> 3017.1654 | N38: =M38/L38 -> 754.29135 | O38: =L38-I38 -> 0 | P38: =N38-K38 -> -70.70865 | Q38: =N38/K38 -> 0.91429255 | S38: 0.33680556 | T38: 0.43195602 | AA38: =M38-J38 -> -282.8346 | AB38: =M38/J38 -> 0.91429255
A39: GKK3600型 飯糰機 | B39: 18℃-飯糰 | C39: 一配熟成紅鮭飯糰 | E39: 25.03 | F39: 971 | G39: =E39*F39 -> 24304.13 | I39: 5 | J39: 3600 | K39: =J39/I39 -> 720 | L39: 5 | M39: =F39/V39*60 -> 3221.3896 | N39: =M39/L39 -> 644.27791 | O39: =L39-I39 -> 0 | P39: =N39-K39 -> -75.72209 | Q39: =N39/K39 -> 0.89483043 | R39: =Q55 -> 0.90108267 | S39: 0.25 | T39: 0.26255787 | V39: 18.085363 | AA39: =M39-J39 -> -378.61045 | AB39: =M39/J39 -> 0.89483043 | AC39: =AB55 -> 0.90108267
B40: 18℃-飯糰 | C40: 一配蔬食鮪魚飯糰 | E40: 18.18 | F40: 1229 | G40: =E40*F40 -> 22343.22 | I40: 3 | J40: 3600 | K40: =J40/I40 -> 1200 | L40: 3 | M40: =F40/V40*60 -> 3218.8818 | N40: =M40/L40 -> 1072.9606 | O40: =L40-I40 -> 0 | P40: =N40-K40 -> -127.0394 | Q40: =N40/K40 -> 0.89413384 | S40: 0.27291667 | T40: 0.28881944 | U40: 14.916667 | V40: 22.908576 | AA40: =M40-J40 -> -381.11819 | AB40: =M40/J40 -> 0.89413384
B41: 18℃-飯糰 | C41: 一配北海道秋鮭親子飯糰 | E41: 24.82 | F41: 1284 | G41: =E41*F41 -> 31868.88 | I41: 5 | J41: 3600 | K41: =J41/I41 -> 720 | L41: 5 | M41: =F41/V41*60 -> 3222.1602 | N41: =M41/L41 -> 644.43203 | O41: =L41-I41 -> 0 | P41: =N41-K41 -> -75.567968 | Q41: =N41/K41 -> 0.89504449 | S41: 0.29861111 | T41: 0.31520833 | U41: 15 | V41: 23.909426 | AA41: =M41-J41 -> -377.83984 | AB41: =M41/J41 -> 0.89504449
B42: 18℃-飯糰 | C42: 一配黑胡椒洋蔥豬飯糰 | E42: 17.07 | F42: 2135 | G42: =E42*F42 -> 36444.45 | I42: 3 | J42: 3300 | K42: =J42/I42 -> 1100 | L42: 3 | M42: =F42/V42*60 -> 3022.7384 | N42: =M42/L42 -> 1007.5795 | O42: =L42-I42 -> 0 | P42: =N42-K42 -> -92.420545 | Q42: =N42/K42 -> 0.91598132 | S42: 0.325 | T42: 0.3544213 | U42: 15 | V42: 42.378792 | AA42: =M42-J42 -> -277.26164 | AB42: =M42/J42 -> 0.91598132
B43: 18℃-飯糰 | C43: 一配經典肉鬆飯糰 | E43: 14.03 | F43: 4837 | G43: =E43*F43 -> 67863.11 | I43: 3 | J43: 3000 | K43: =J43/I43 -> 1000 | L43: 3 | M43: =F43/V43*60 -> 2746.4161 | N43: =M43/L43 -> 915.47204 | O43: =L43-I43 -> 0 | P43: =N43-K43 -> -84.527962 | Q43: =N43/K43 -> 0.91547204 | S43: 0.36458333 | T43: 0.43796296 | U43: 14.633333 | V43: 105.67226 | AA43: =M43-J43 -> -253.58389 | AB43: =M43/J43 -> 0.91547204
B44: 18℃-飯糰 | C44: 一配鮪魚飯糰 | E44: 14.28 | F44: 6799 | G44: =E44*F44 -> 97089.72 | I44: 3 | J44: 3600 | K44: =J44/I44 -> 1200 | L44: 3 | M44: =F44/V44*60 -> 3220.8252 | N44: =M44/L44 -> 1073.6084 | O44: =L44-I44 -> 0 | P44: =N44-K44 -> -126.39159 | Q44: =N44/K44 -> 0.89467368 | S44: 0.44791667 | T44: 0.53586806 | U44: 15 | V44: 126.65698 | AA44: =M44-J44 -> -379.17476 | AB44: =M44/J44 -> 0.89467368
B55: 平均 | I55: =AVERAGE(I39:I54) -> 3.6666667 | J55: =AVERAGE(J39:J54) -> 3450 | K55: =J55/I55 -> 940.90909 | L55: =AVERAGE(L39:L54) -> 3.6666667 | M55: =AVERAGE(M39:M54) -> 3108.7352 | N55: =M55/L55 -> 847.83687 | O55: =L55-I55 -> 0 | P55: =N55-K55 -> -93.072217 | Q55: =N55/K55 -> 0.90108267 | S55: 0.25 | T55: 0.53586806 | AA55: =M55-J55 -> -341.26479 | AB55: =M55/J55 -> 0.90108267
A56: GKK3600型 飯糰機2 | B56: 18℃-飯糰 | C56: 一配椒鹽檸檬鯖魚飯糰 | E56: 20.72 | F56: 1589 | G56: =E56*F56 -> 32924.08 | I56: 3 | J56: 3600 | K56: =J56/I56 -> 1200 | L56: 3 | M56: =F56/V56*60 -> 3221.2384 | N56: =M56/L56 -> 1073.7461 | O56: =L56-I56 -> 0 | P56: =N56-K56 -> -126.25388 | Q56: =N56/K56 -> 0.89478843 | R56: =Q72 -> 0.89781547 | S56: 0.25 | T56: 0.27054398 | V56: 29.597313 | AA56: =M56-J56 -> -378.76164 | AB56: =M56/J56 -> 0.89478843 | AC56: =AB72 -> 0.89781547
B57: 18℃-飯糰 | C57: 一配贅沢鮭魚肚飯糰 | E57: 30 | F57: 1927 | G57: =E57*F57 -> 57810 | I57: 4 | J57: 3600 | K57: =J57/I57 -> 900 | L57: 4 | M57: =F57/V57*60 -> 3223.2307 | N57: =M57/L57 -> 805.80767 | O57: =L57-I57 -> 0 | P57: =N57-K57 -> -94.192331 | Q57: =N57/K57 -> 0.89534185 | S57: 0.28055556 | T57: 0.30546296 | U57: 15 | V57: 35.870843 | AA57: =M57-J57 -> -376.76933 | AB57: =M57/J57 -> 0.89534185
B58: 18℃-飯糰 | C58: 一配筋子銀鮭飯糰 | E58: 30 | F58: 1996 | G58: =E58*F58 -> 59880 | I58: 4 | J58: 3300 | K58: =J58/I58 -> 825 | L58: 4 | M58: =F58/V58*60 -> 3023.0409 | N58: =M58/L58 -> 755.76023 | O58: =L58-I58 -> 0 | P58: =N58-K58 -> -69.239775 | Q58: =N58/K58 -> 0.916073 | S58: 0.31527778 | T58: 0.34277778 | U58: 15 | V58: 39.615739 | AA58: =M58-J58 -> -276.9591 | AB58: =M58/J58 -> 0.916073
B59: 18℃-飯糰 | C59: 一配鹽蔥生鮭飯糰 | E59: 27.48 | F59: 2907 | G59: =E59*F59 -> 79884.36 | I59: 5 | J59: 3600 | K59: =J59/I59 -> 720 | L59: 5 | M59: =F59/V59*60 -> 3222.0059 | N59: =M59/L59 -> 644.40118 | O59: =L59-I59 -> 0 | P59: =N59-K59 -> -75.598825 | Q59: =N59/K59 -> 0.89500163 | S59: 0.35277778 | T59: 0.39037037 | U59: 15 | V59: 54.133979 | AA59: =M59-J59 -> -377.99412 | AB59: =M59/J59 -> 0.89500163
B60: 18℃-飯糰 | C60: 一配明太子龍蝦風味沙拉飯糰 | E60: 18.18 | F60: 2167 | G60: =E60*F60 -> 39396.06 | I60: 3 | J60: 3600 | K60: =J60/I60 -> 1200 | L60: 3 | M60: =F60/V60*60 -> 3216.6063 | N60: =M60/L60 -> 1072.2021 | O60: =L60-I60 -> 0 | P60: =N60-K60 -> -127.79791 | Q60: =N60/K60 -> 0.89350174 | S60: 0.40069444 | T60: 0.42876157 | U60: 14.866667 | V60: 40.421484 | AA60: =M60-J60 -> -383.39372 | AB60: =M60/J60 -> 0.89350174
B61: 18℃-飯糰 | C61: 一配雞肉飯飯糰 | E61: 16.66 | F61: 5625 | G61: =E61*F61 -> 93712.5 | I61: 5 | J61: 3600 | K61: =J61/I61 -> 720 | L61: 5 | M61: =F61/V61*60 -> 3217.3474 | N61: =M61/L61 -> 643.46947 | O61: =L61-I61 -> 0 | P61: =N61-K61 -> -76.530527 | Q61: =N61/K61 -> 0.8937076 | S61: 0.43888889 | T61: 0.51173611 | U61: 14.583333 | V61: 104.90008 | AA61: =M61-J61 -> -382.65263 | AB61: =M61/J61 -> 0.8937076
B72: 平均 | I72: =AVERAGE(I56:I71) -> 4 | J72: =AVERAGE(J56:J71) -> 3550 | K72: =J72/I72 -> 887.5 | L72: =AVERAGE(L56:L71) -> 4 | M72: =AVERAGE(M56:M71) -> 3187.2449 | N72: =M72/L72 -> 796.81123 | O72: =L72-I72 -> 0 | P72: =N72-K72 -> -90.688773 | Q72: =N72/K72 -> 0.89781547 | S72: 0.25 | T72: 0.51173611 | AA72: =M72-J72 -> -362.75509 | AB72: =M72/J72 -> 0.89781547
A73: 自動包裝機 (二配) | B73: 18℃-飯糰 | C73: 二配兩粒飯糰(鮪魚.焦糖鮭魚) | E73: 28.57 | F73: 1572 | G73: =E73*F73 -> 44912.04 | I73: 12 | J73: 3600 | K73: =J73/I73 -> 300 | L73: 12 | M73: =F73/V73*60 -> 3120.179 | N73: =M73/L73 -> 260.01492 | O73: =L73-I73 -> 0 | P73: =N73-K73 -> -39.985083 | Q73: =N73/K73 -> 0.86671639 | R73: =Q89 -> 0.89344638 | S73: 0.70833333 | T73: 0.72931713 | V73: 30.229035 | AA73: =M73-J73 -> -479.821 | AB73: =M73/J73 -> 0.86671639 | AC73: =AB89 -> 0.89344638
B74: 18℃-飯糰 | C74: 二配柚香雞胸五穀飯糰 | E74: 17.71 | F74: 612 | G74: =E74*F74 -> 10838.52 | I74: 5 | J74: 3600 | K74: =J74/I74 -> 720 | L74: 5 | M74: =F74/V74*60 -> 3264.6273 | N74: =M74/L74 -> 652.92546 | O74: =L74-I74 -> 0 | P74: =N74-K74 -> -67.074544 | Q74: =N74/K74 -> 0.90684091 | S74: 0.73263889 | T74: 0.74043981 | U74: 4.7833333 | V74: 11.247838 | AA74: =M74-J74 -> -335.37272 | AB74: =M74/J74 -> 0.90684091
B75: 18℃-飯糰 | C75: 二配鮭魚毛豆炊飯飯糰 | E75: 18.92 | F75: 1245 | G75: =E75*F75 -> 23555.4 | I75: 5 | J75: 3600 | K75: =J75/I75 -> 720 | L75: 5 | M75: =F75/V75*60 -> 3264.4147 | N75: =M75/L75 -> 652.88293 | O75: =L75-I75 -> 0 | P75: =N75-K75 -> -67.117068 | Q75: =N75/K75 -> 0.90678185 | S75: 0.74444444 | T75: 0.76032407 | U75: 5.7666667 | V75: 22.883122 | AA75: =M75-J75 -> -335.58534 | AB75: =M75/J75 -> 0.90678185
B89: 平均 | I89: =AVERAGE(I73:I88) -> 7.3333333 | J89: =AVERAGE(J73:J88) -> 3600 | K89: =J89/I89 -> 490.90909 | L89: =AVERAGE(L73:L88) -> 7.3333333 | M89: =AVERAGE(M73:M88) -> 3216.407 | N89: =M89/L89 -> 438.60095 | O89: =L89-I89 -> 0 | P89: =N89-K89 -> -52.308139 | Q89: =N89/K89 -> 0.89344638 | S89: 0.70833333 | T89: 0.76032407 | AA89: =M89-J89 -> -383.59302 | AB89: =M89/J89 -> 0.89344638
A90: (新) 3300型飯糰機 (二配) | B90: 18℃-飯糰 | C90: 二配大飯糰乾燒風味鮮蝦 | E90: 23.27 | F90: 570 | G90: =E90*F90 -> 13263.9 | I90: 5 | J90: 3000 | K90: =J90/I90 -> 600 | L90: 5 | M90: =F90/V90*60 -> 2742.0771 | N90: =M90/L90 -> 548.41543 | O90: =L90-I90 -> 0 | P90: =N90-K90 -> -51.584572 | Q90: =N90/K90 -> 0.91402571 | R90: =Q106 -> 0.91397357 | S90: 0.70833333 | T90: 0.71699074 | V90: 12.472297 | AA90: =M90-J90 -> -257.92286 | AB90: =M90/J90 -> 0.91402571 | AC90: =AB106 -> 0.91397357
B91: 18℃-飯糰 | C91: 二配大飯糰韓式蒜烤豬五花 | E91: 24.54 | F91: 1495 | G91: =E91*F91 -> 36687.3 | I91: 4 | J91: 3000 | K91: =J91/I91 -> 750 | L91: 4 | M91: =F91/V91*60 -> 2742.9099 | N91: =M91/L91 -> 685.72748 | O91: =L91-I91 -> 0 | P91: =N91-K91 -> -64.272523 | Q91: =N91/K91 -> 0.9143033 | S91: 0.72013889 | T91: 0.74284722 | U91: 4.5333333 | V91: 32.702496 | AA91: =M91-J91 -> -257.09009 | AB91: =M91/J91 -> 0.9143033
B92: 18℃-飯糰 | C92: 二配大飯糰泡菜鮪魚 | E92: 24.33 | F92: 1478 | G92: =E92*F92 -> 35959.74 | I92: 4 | J92: 3000 | K92: =J92/I92 -> 750 | L92: 4 | M92: =F92/V92*60 -> 2742.2238 | N92: =M92/L92 -> 685.55594 | O92: =L92-I92 -> 0 | P92: =N92-K92 -> -64.444061 | Q92: =N92/K92 -> 0.91407459 | S92: 0.74652778 | T92: 0.76898148 | U92: 5.3 | V92: 32.338718 | AA92: =M92-J92 -> -257.77624 | AB92: =M92/J92 -> 0.91407459
B93: 18℃-飯糰 | C93: 二配壹號醬炙烤牛飯糰 | E93: 22.28 | F93: 1693 | G93: =E93*F93 -> 37720.04 | I93: 5 | J93: 3300 | K93: =J93/I93 -> 660 | L93: 5 | M93: =F93/V93*60 -> 3014.2588 | N93: =M93/L93 -> 602.85175 | O93: =L93-I93 -> 0 | P93: =N93-K93 -> -57.148245 | Q93: =N93/K93 -> 0.91341175 | S93: 0.77222222 | T93: 0.79561343 | U93: 4.6666667 | V93: 33.699827 | AA93: =M93-J93 -> -285.74123 | AB93: =M93/J93 -> 0.91341175
B94: 18℃-飯糰 | C94: 二配鹽蔥燒肉飯糰 | E94: 17.89 | F94: 5921 | G94: =E94*F94 -> 105926.69 | I94: 4 | J94: 3300 | K94: =J94/I94 -> 825 | L94: 4 | M94: =F94/V94*60 -> 3016.5181 | N94: =M94/L94 -> 754.12952 | O94: =L94-I94 -> 0 | P94: =N94-K94 -> -70.870481 | Q94: =N94/K94 -> 0.91409639 | S94: 0.79861111 | T94: 0.88039352 | U94: 5 | V94: 117.77155 | AA94: =M94-J94 -> -283.48192 | AB94: =M94/J94 -> 0.91409639
B106: 平均 | I106: =AVERAGE(I90:I105) -> 4.4 | J106: =AVERAGE(J90:J105) -> 3120 | K106: =J106/I106 -> 709.09091 | L106: =AVERAGE(L90:L105) -> 4.4 | M106: =AVERAGE(M90:M105) -> 2851.5975 | N106: =M106/L106 -> 648.09035 | O106: =L106-I106 -> 0 | P106: =N106-K106 -> -61.000561 | Q106: =N106/K106 -> 0.91397357 | S106: 0.70833333 | T106: 0.88039352 | AA106: =M106-J106 -> -268.40247 | AB106: =M106/J106 -> 0.91397357
A107: GKK3600型 飯糰機 (二配) | B107: 18℃-飯糰 | C107: 二配芝麻香鬆飯糰 | E107: 18.18 | F107: 690 | G107: =E107*F107 -> 12544.2 | H107: 2 | I107: 3 | J107: 3000 | K107: =J107/I107 -> 1000 | L107: 3 | M107: =F107/V107*60 -> 2744.8541 | N107: =M107/L107 -> 914.95137 | O107: =L107-I107 -> 0 | P107: =N107-K107 -> -85.048628 | Q107: =N107/K107 -> 0.91495137 | R107: =Q123 -> 0.90435903 | S107: 0.73125 | T107: 0.74171296 | V107: 15.082769 | AA107: =M107-J107 -> -255.14588 | AB107: =M107/J107 -> 0.91495137 | AC107: =AB123 -> 0.90435903
B108: 18℃-飯糰 | C108: 二配蔬食鮪魚飯糰 | E108: 18.18 | F108: 432 | G108: =E108*F108 -> 7853.76 | H108: 2 | I108: 3 | J108: 3600 | K108: =J108/I108 -> 1200 | L108: 3 | M108: =F108/V108*60 -> 3221.2046 | N108: =M108/L108 -> 1073.7349 | O108: =L108-I108 -> 0 | P108: =N108-K108 -> -126.26513 | Q108: =N108/K108 -> 0.89477906 | S108: 0.75208333 | T108: 0.75766204 | U108: 14.933333 | V108: 8.0466791 | AA108: =M108-J108 -> -378.79538 | AB108: =M108/J108 -> 0.89477906
...

Sheet 0810(4度C)
A1: 大溪廠日報分析 | C1: 總生產量 | D1: =SUM(F5:F140) -> 92976 | E1: 營業額 | F1: =SUM(G5:G140) -> 4140768.9 | G1: 出勤人數 | H1: =L21+L38+L55+L72+L89+L106+L123+L140 -> 137.14286 | I1: 產線配置圖 | L1: 生產實績 | O1: 人時性差異分析 | S1: 日報登錄 | Y1: 合計次數 | Z1: 合計(時間/分) | AA1: 產線異常 分析說明(5分鐘以上) | AC1: 合計次數 | AD1: 合計(時間/分) | AE1: 產能差異分析
A2: 46244 | C2: 人時性 | D2: =AVERAGE(N21,N38,N55,N72,N89,N106,N123,N140) -> 201.21474 | E2: 平均廠價 | F2: =F1/D1 -> 44.53589 | G2: 多次生產數 | H2: =COUNT(H5:H140) -> 1 | Y2: =SUM(Y21,Y38,Y55,Y72,Y89,Y106,Y123,Y140) -> 0 | Z2: =SUM(Z21,Z38,Z55,Z72,Z89,Z106,Z123,Z140) -> 0 | AC2: =SUM(AC21,AC38,AC55,AC72,AC89,AC106,AC123,AC140) -> 0 | AD2: =SUM(AD21,AD38,AD55,AD72,AD89,AD106,AD123,AD140) -> 0
A3: 線別 | B3: 品類 | C3: 品名 | E3: 廠價 | F3: 生產量 | G3: 營收 | H3: 多次 生產 | I3: 人數 | J3: 產能/時 | K3: 人時性 | L3: 人數 | M3: 產能/時 | N3: 人時性 | O3: 人數 | P3: 人時性 | Q3: 達成率 | R3: 達成率 平均 | S3: 生產時間 | U3: 換線、休息/分 | V3: 稼動時間/分 | W3: 休息時間 | Y3: 產線異常統計(5分鐘以上) | AA3: (屏榮回填) | AC3: 短暫停線統計(5分鐘以下) | AE3: 產能/時 | AF3: 達成率 | AG3: 達成率平均
S4: 開始 | T4: 結束 | W4: 開始 | X4: 結束 | Y4: 次數 | Z4: 時間/分 | AC4: 總次數 | AD4: 設備因素(次數)
A5: 便當二線 | B5: 微波小吃 | C5: 日式茶碗蒸 | E5: 19.7 | F5: 3603 | G5: =E5*F5 -> 70979.1 | I5: 13 | J5: 1200 | K5: =J5/I5 -> 92.307692 | L5: 13 | M5: =F5/V5*60 -> 1083.2073 | N5: =M5/L5 -> 83.323638 | O5: =L5-I5 -> 0 | P5: =N5-K5 -> -8.9840548 | Q5: =N5/K5 -> 0.90267274 | R5: =Q21 -> 0.90217973 | S5: 0.20833333 | T5: 0.3469213 | V5: 199.57399 | AE5: =M5-J5 -> -116.79271 | AF5: =M5/J5 -> 0.90267274 | AG5: =AF21 -> 0.90217973
B6: 微波主食 | C6: 糖燻野郎三十天熟成牛飯 | E6: 56.43 | F6: 4649 | G6: =E6*F6 -> 262343.07 | I6: 24 | J6: 2000 | K6: =J6/I6 -> 83.333333 | L6: 24 | M6: =F6/V6*60 -> 1804.9548 | N6: =M6/L6 -> 75.206451 | O6: =L6-I6 -> 0 | P6: =N6-K6 -> -8.1268824 | Q6: =N6/K6 -> 0.90247741 | S6: 0.35069444 | T6: 0.45800926 | U6: 5.4333333 | V6: 154.54126 | AE6: =M6-J6 -> -195.04518 | AF6: =M6/J6 -> 0.90247741
B7: 便當 | C7: 香檸奶油魚排蔬滿盒 | E7: 77.35 | F7: 1047 | G7: =E7*F7 -> 80985.45 | I7: 25 | J7: 2000 | K7: =J7/I7 -> 80 | L7: 25 | M7: =F7/V7*60 -> 1803.4216 | N7: =M7/L7 -> 72.136864 | O7: =L7-I7 -> 0 | P7: =N7-K7 -> -7.8631358 | Q7: =N7/K7 -> 0.9017108 | S7: 0.46111111 | T7: 0.48530093 | U7: 5 | V7: 34.833785 | W7: 0.48530093 | X7: 0.52361111 | AE7: =M7-J7 -> -196.5784 | AF7: =M7/J7 -> 0.9017108
B8: 便當 | C8: 健身G肉餐盒 | E8: 59.52 | F8: 5232 | G8: =E8*F8 -> 311408.64 | I8: 24 | J8: 2000 | K8: =J8/I8 -> 83.333333 | L8: 24 | M8: =F8/V8*60 -> 1804.1104 | N8: =M8/L8 -> 75.171265 | O8: =L8-I8 -> 0 | P8: =N8-K8 -> -8.1620679 | Q8: =N8/K8 -> 0.90205519 | S8: 0.52361111 | T8: 0.64444444 | U8: 55.166667 | V8: 174.00266 | AE8: =M8-J8 -> -195.88963 | AF8: =M8/J8 -> 0.90205519
B21: 平均 | I21: =AVERAGE(I5:I20) -> 21.5 | J21: =AVERAGE(J5:J20) -> 1800 | K21: =J21/I21 -> 83.72093 | L21: =AVERAGE(L5:L20) -> 21.5 | M21: =AVERAGE(M5:M20) -> 1623.9235 | N21: =M21/L21 -> 75.531327 | O21: =L21-I21 -> 0 | P21: =N21-K21 -> -8.1896037 | Q21: =N21/K21 -> 0.90217973 | S21: 0.20833333 | T21: 0.64444444 | Y21: =SUM(Y5:Y20) -> 0 | Z21: =SUM(Z5:Z20) -> 0 | AC21: =SUM(AC5:AC20) -> 0 | AD21: =SUM(AD5:AD20) -> 0 | AE21: =M21-J21 -> -176.07648 | AF21: =M21/J21 -> 0.90217973
A22: 涼麵一線 | B22: 4℃-壽司手卷 | C22: 海陸雙拼壽司 | E22: 36.45 | F22: 2647 | G22: =E22*F22 -> 96483.15 | I22: 20 | J22: 2100 | K22: =J22/I22 -> 105 | L22: 20 | M22: =F22/V22*60 -> 1892.2283 | N22: =M22/L22 -> 94.611417 | O22: =L22-I22 -> 0 | P22: =N22-K22 -> -10.388583 | Q22: =N22/K22 -> 0.90106112 | R22: =Q38 -> 0.90307235 | S22: 0.20833333 | T22: 0.2666088 | V22: 83.932788 | AE22: =M22-J22 -> -207.77166 | AF22: =M22/J22 -> 0.90106112 | AG22: =AF38 -> 0.91099404
B23: 微波小吃 | C23: 馬鈴薯玉米濃湯 | E23: 31.72 | F23: 1771 | G23: =E23*F23 -> 56176.12 | I23: 22 | J23: 2000 | K23: =J23/I23 -> 90.909091 | L23: 22 | M23: =F23/V23*60 -> 1804.8275 | N23: =M23/L23 -> 82.037614 | O23: =L23-I23 -> 0 | P23: =N23-K23 -> -8.8714766 | Q23: =N23/K23 -> 0.90241376 | S23: 0.26944444 | T23: 0.31032407 | U23: 5 | V23: 58.875432 | AE23: =M23-J23 -> -195.17249 | AF23: =M23/J23 -> 0.90241376
B24: 微波小吃 | C24: 三合一味噌湯 | E24: 34.79 | F24: 1946 | G24: =E24*F24 -> 67701.34 | I24: 11 | J24: 2000 | K24: =J24/I24 -> 181.81818 | L24: 11 | M24: =F24/V24*60 -> 1808.128 | N24: =M24/L24 -> 164.37527 | O24: =L24-I24 -> 0 | P24: =N24-K24 -> -17.44291 | Q24: =N24/K24 -> 0.904064 | S24: 0.31388889 | T24: 0.35872685 | U24: 5.1333333 | V24: 64.575074 | AE24: =M24-J24 -> -191.872 | AF24: =M24/J24 -> 0.904064
B25: 微波小吃 | C25: 越式牛肉寬粉 | E25: 51.44 | F25: 1833 | G25: =E25*F25 -> 94289.52 | I25: 19 | J25: 2000 | K25: =J25/I25 -> 105.26316 | L25: 19 | M25: =F25/V25*60 -> 1805.1709 | N25: =M25/L25 -> 95.008996 | O25: =L25-I25 -> 0 | P25: =N25-K25 -> -10.254162 | Q25: =N25/K25 -> 0.90258546 | S25: 0.3625 | T25: 0.40480324 | U25: 5.4333333 | V25: 60.924979 | AE25: =M25-J25 -> -194.82908 | AF25: =M25/J25 -> 0.90258546
B26: 微波主食 | C26: 日式鮭魚茶泡烤飯 | E26: 43.28 | F26: 2626 | G26: =E26*F26 -> 113653.28 | I26: 21 | J26: 1800 | K26: =J26/I26 -> 85.714286 | L26: 21 | M26: =F26/V26*60 -> 1623.5249 | N26: =M26/L26 -> 77.310711 | O26: =L26-I26 -> 0 | P26: =N26-K26 -> -8.403575 | Q26: =N26/K26 -> 0.90195829 | S26: 0.40833333 | T26: 0.47571759 | U26: 5.0833333 | V26: 97.048094 | W26: 0.47571759 | X26: 0.51458333 | AE26: =M26-J26 -> -176.47508 | AF26: =M26/J26 -> 0.90195829
B27: 4℃-飯糰 | C27: 麻油雞飯糰 | E27: 29.97 | F27: 2383 | G27: =E27*F27 -> 71418.51 | I27: 21 | J27: 2790 | K27: =J27/I27 -> 132.85714 | L27: 22 | M27: =F27/V27*60 -> 2626.6346 | N27: =M27/L27 -> 119.39248 | O27: =L27-I27 -> 1 | P27: =N27-K27 -> -13.46466 | Q27: =N27/K27 -> 0.89865309 | S27: 0.51458333 | T27: 0.55238426 | U27: 55.966667 | V27: 54.434674 | AE27: =M27-J27 -> -163.36538 | AF27: =M27/J27 -> 0.9414461
B38: 平均 | I38: =AVERAGE(I22:I37) -> 19 | J38: =AVERAGE(J22:J37) -> 2115 | K38: =J38/I38 -> 111.31579 | L38: =AVERAGE(L22:L37) -> 19.166667 | M38: =AVERAGE(M22:M37) -> 1926.7524 | N38: =M38/L38 -> 100.52621 | O38: =L38-I38 -> 0.16666667 | P38: =N38-K38 -> -10.789578 | Q38: =N38/K38 -> 0.90307235 | S38: 0.20833333 | T38: 0.55238426 | Y38: =SUM(Y22:Y37) -> 0 | Z38: =SUM(Z22:Z37) -> 0 | AC38: =SUM(AC22:AC37) -> 0 | AD38: =SUM(AD22:AD37) -> 0 | AE38: =M38-J38 -> -188.24762 | AF38: =M38/J38 -> 0.91099404
A39: 涼麵二線 | B39: 便當 | C39: 香腸腿排雙拼便當 | E39: 53.76 | F39: 3151 | G39: =E39*F39 -> 169397.76 | I39: 20 | J39: 2000 | K39: =J39/I39 -> 100 | L39: 20 | M39: =F39/V39*60 -> 1802.7482 | N39: =M39/L39 -> 90.137411 | O39: =L39-I39 -> 0 | P39: =N39-K39 -> -9.8625893 | Q39: =N39/K39 -> 0.90137411 | R39: =Q55 -> 0.90150079 | S39: 0.16666667 | T39: 0.23949074 | V39: 104.87321 | AE39: =M39-J39 -> -197.25179 | AF39: =M39/J39 -> 0.90137411 | AG39: =AF55 -> 0.90150079
B40: 便當 | C40: 蔬活腿排補力餐盒 | E40: 71.55 | F40: 3197 | G40: =E40*F40 -> 228745.35 | I40: 22 | J40: 2000 | K40: =J40/I40 -> 90.909091 | L40: 22 | M40: =F40/V40*60 -> 1802.8138 | N40: =M40/L40 -> 81.946082 | O40: =L40-I40 -> 0 | P40: =N40-K40 -> -8.9630088 | Q40: =N40/K40 -> 0.9014069 | S40: 0.24305556 | T40: 0.31694444 | U40: 5.1333333 | V40: 106.40034 | AE40: =M40-J40 -> -197.18619 | AF40: =M40/J40 -> 0.9014069
B41: 便當 | C41: 地中海布格麥烤魚餐盒 | E41: 63.92 | F41: 2540 | G41: =E41*F41 -> 162356.8 | I41: 24 | J41: 2000 | K41: =J41/I41 -> 83.333333 | L41: 24 | M41: =F41/V41*60 -> 1804.5666 | N41: =M41/L41 -> 75.190274 | O41: =L41-I41 -> 0 | P41: =N41-K41 -> -8.1430594 | Q41: =N41/K41 -> 0.90228329 | S41: 0.32083333 | T41: 0.37947917 | U41: 5.6 | V41: 84.452412 | AE41: =M41-J41 -> -195.43343 | AF41: =M41/J41 -> 0.90228329
B42: 便當 | C42: 烤蛋白餐盒 | E42: 58.67 | F42: 1083 | G42: =E42*F42 -> 63539.61 | H42: 2 | I42: 23 | J42: 2000 | K42: =J42/I42 -> 86.956522 | L42: 23 | M42: =F42/V42*60 -> 1802.6616 | N42: =M42/L42 -> 78.37659 | O42: =L42-I42 -> 0 | P42: =N42-K42 -> -8.5799313 | Q42: =N42/K42 -> 0.90133079 | S42: 0.38263889 | T42: 0.40766204 | U42: 4.55 | V42: 36.046699 | AE42: =M42-J42 -> -197.33842 | AF42: =M42/J42 -> 0.90133079
B43: 便當 | C43: 海陸雙拼肉肉餐盒 | E43: 59.54 | F43: 3117 | G43: =E43*F43 -> 185586.18 | I43: 23 | J43: 2000 | K43: =J43/I43 -> 86.956522 | L43: 23 | M43: =F43/V43*60 -> 1802.7797 | N43: =M43/L43 -> 78.381725 | O43: =L43-I43 -> 0 | P43: =N43-K43 -> -8.5747967 | Q43: =N43/K43 -> 0.90138984 | S43: 0.41111111 | T43: 0.48314815 | U43: 4.9666667 | V43: 103.7398 | W43: 0.48314815 | X43: 0.52222222 | AE43: =M43-J43 -> -197.22032 | AF43: =M43/J43 -> 0.90138984
B44: 便當 | C44: 懷舊滷雙拼便當 | E44: 61.09 | F44: 3178 | G44: =E44*F44 -> 194144.02 | I44: 20 | J44: 2000 | K44: =J44/I44 -> 100 | L44: 20 | M44: =F44/V44*60 -> 1802.7797 | N44: =M44/L44 -> 90.138985 | O44: =L44-I44 -> 0 | P44: =N44-K44 -> -9.8610153 | Q44: =N44/K44 -> 0.90138985 | S44: 0.52222222 | T44: 0.5956713 | U44: 56.266667 | V44: 105.77 | AE44: =M44-J44 -> -197.22031 | AF44: =M44/J44 -> 0.90138985
B45: 便當 | C45: 烤蛋白餐盒 | E45: 58.67 | F45: 2780 | G45: =E45*F45 -> 163102.6 | I45: 23 | J45: 2000 | K45: =J45/I45 -> 86.956522 | L45: 23 | M45: =F45/V45*60 -> 1802.6616 | N45: =M45/L45 -> 78.37659 | O45: =L45-I45 -> 0 | P45: =N45-K45 -> -8.5799313 | Q45: =N45/K45 -> 0.90133079 | S45: 0.59930556 | T45: 0.66355324 | U45: 5.2333333 | V45: 92.529847 | AE45: =M45-J45 -> -197.33842 | AF45: =M45/J45 -> 0.90133079
B55: 平均 | I55: =AVERAGE(I39:I54) -> 22.142857 | J55: =AVERAGE(J39:J54) -> 2000 | K55: =J55/I55 -> 90.322581 | L55: =AVERAGE(L39:L54) -> 22.142857 | M55: =AVERAGE(M39:M54) -> 1803.0016 | N55: =M55/L55 -> 81.425878 | O55: =L55-I55 -> 0 | P55: =N55-K55 -> -8.8967024 | Q55: =N55/K55 -> 0.90150079 | S55: 0.16666667 | T55: 0.66355324 | Y55: =SUM(Y39:Y54) -> 0 | Z55: =SUM(Z39:Z54) -> 0 | AC55: =SUM(AC39:AC54) -> 0 | AD55: =SUM(AD39:AD54) -> 0 | AE55: =M55-J55 -> -196.99841 | AF55: =M55/J55 -> 0.90150079
A56: 涼麵三線 | B56: 季節調理麵 | C56: 和風涓絲冷麵 | E56: 28.86 | F56: 2240 | G56: =E56*F56 -> 64646.4 | I56: 19 | J56: 3600 | K56: =J56/I56 -> 189.47368 | L56: 19 | M56: =F56/V56*60 -> 3193.4287 | N56: =M56/L56 -> 168.0752 | O56: =L56-I56 -> 0 | P56: =N56-K56 -> -21.398487 | Q56: =N56/K56 -> 0.88706354 | R56: =Q72 -> 0.89978071 | S56: 0.16666667 | T56: 0.1958912 | V56: 42.086425 | AE56: =M56-J56 -> -406.57126 | AF56: =M56/J56 -> 0.88706354 | AG56: =AF72 -> 0.89978071
B57: 季節調理麵 | C57: 嘉義崇文白醋涼麵 | E57: 35.89 | F57: 2851 | G57: =E57*F57 -> 102322.39 | I57: 19 | J57: 3600 | K57: =J57/I57 -> 189.47368 | L57: 19 | M57: =F57/V57*60 -> 3192.271 | N57: =M57/L57 -> 168.01426 | O57: =L57-I57 -> 0 | P57: =N57-K57 -> -21.459422 | Q57: =N57/K57 -> 0.88674194 | S57: 0.19930556 | T57: 0.2365162 | U57: 4.9166667 | V57: 53.585676 | AE57: =M57-J57 -> -407.72902 | AF57: =M57/J57 -> 0.88674194
B58: 季節調理麵 | C58: 韓式泡菜冷麵 | E58: 36.73 | F58: 2206 | G58: =E58*F58 -> 81026.38 | I58: 21 | J58: 3600 | K58: =J58/I58 -> 171.42857 | L58: 21 | M58: =F58/V58*60 -> 3194.4505 | N58: =M58/L58 -> 152.11669 | O58: =L58-I58 -> 0 | P58: =N58-K58 -> -19.311883 | Q58: =N58/K58 -> 0.88734735 | S58: 0.24027778 | T58: 0.26905093 | U58: 5.4166667 | V58: 41.434357 | AE58: =M58-J58 -> -405.54954 | AF58: =M58/J58 -> 0.88734735
B59: 季節調理麵 | C59: 招牌雞絲胡麻涼麵 | E59: 43.96 | F59: 1721 | G59: =E59*F59 -> 75655.16 | I59: 24 | J59: 3600 | K59: =J59/I59 -> 150 | L59: 24 | M59: =F59/V59*60 -> 3269.157 | N59: =M59/L59 -> 136.21488 | O59: =L59-I59 -> 0 | P59: =N59-K59 -> -13.785125 | Q59: =N59/K59 -> 0.90809917 | S59: 0.27291667 | T59: 0.29484954 | U59: 5.5666667 | V59: 31.586124 | AE59: =M59-J59 -> -330.843 | AF59: =M59/J59 -> 0.90809917
B60: 季節調理麵 | C60: 日式胡麻雞絲冷麵 | E60: 46.93 | F60: 1364 | G60: =E60*F60 -> 64012.52 | I60: 24 | J60: 3600 | K60: =J60/I60 -> 150 | L60: 24 | M60: =F60/V60*60 -> 3267.0243 | N60: =M60/L60 -> 136.12601 | O60: =L60-I60 -> 0 | P60: =N60-K60 -> -13.873988 | Q60: =N60/K60 -> 0.90750675 | S60: 0.29861111 | T60: 0.31600694 | U60: 5.4166667 | V60: 25.050319 | AE60: =M60-J60 -> -332.97571 | AF60: =M60/J60 -> 0.90750675
B61: 季節調理麵 | C61: 日式蕎麥沾麵 | E61: 36.73 | F61: 3615 | G61: =E61*F61 -> 132778.95 | I61: 20 | J61: 3600 | K61: =J61/I61 -> 180 | L61: 20 | M61: =F61/V61*60 -> 3261.8967 | N61: =M61/L61 -> 163.09484 | O61: =L61-I61 -> 0 | P61: =N61-K61 -> -16.905164 | Q61: =N61/K61 -> 0.90608242 | S61: 0.32013889 | T61: 0.36630787 | U61: 5.95 | V61: 66.495055 | AE61: =M61-J61 -> -338.10329 | AF61: =M61/J61 -> 0.90608242
B62: 季節調理麵 | C62: 大滿足麻醬涼麵 | E62: 37.8 | F62: 6652 | G62: =E62*F62 -> 251445.6 | I62: 21 | J62: 3600 | K62: =J62/I62 -> 171.42857 | L62: 21 | M62: =F62/V62*60 -> 3267.132 | N62: =M62/L62 -> 155.57772 | O62: =L62-I62 -> 0 | P62: =N62-K62 -> -15.850855 | Q62: =N62/K62 -> 0.90753668 | S62: 0.36944444 | T62: 0.45427083 | U62: 4.5166667 | V62: 122.16219 | W62: 0.45427083 | X62: 0.49305556 | AE62: =M62-J62 -> -332.86796 | AF62: =M62/J62 -> 0.90753668
B63: 季節調理麵 | C63: 大滿足香辣涼麵 | E63: 38.48 | F63: 5647 | G63: =E63*F63 -> 217296.56 | I63: 20 | J63: 3600 | K63: =J63/I63 -> 180 | L63: 20 | M63: =F63/V63*60 -> 3268.3241 | N63: =M63/L63 -> 163.41621 | O63: =L63-I63 -> 0 | P63: =N63-K63 -> -16.583794 | Q63: =N63/K63 -> 0.90786781 | S63: 0.49305556 | T63: 0.5650463 | U63: 55.85 | V63: 103.66781 | AE63: =M63-J63 -> -331.67588 | AF63: =M63/J63 -> 0.90786781
B72: 平均 | I72: =AVERAGE(I56:I71) -> 21 | J72: =AVERAGE(J56:J71) -> 3600 | K72: =J72/I72 -> 171.42857 | L72: =AVERAGE(L56:L71) -> 21 | M72: =AVERAGE(M56:M71) -> 3239.2105 | N72: =M72/L72 -> 154.24812 | O72: =L72-I72 -> 0 | P72: =N72-K72 -> -17.18045 | Q72: =N72/K72 -> 0.89978071 | S72: 0.16666667 | T72: 0.5650463 | Y72: =SUM(Y56:Y71) -> 0 | Z72: =SUM(Z56:Z71) -> 0 | AC72: =SUM(AC56:AC71) -> 0 | AD72: =SUM(AD56:AD71) -> 0 | AE72: =M72-J72 -> -360.78946 | AF72: =M72/J72 -> 0.89978071
A73: 自動包裝機 | B73: 4℃-壽司手卷 | C73: 醬油生鮭脆卷 | E73: 23.55 | F73: 2304 | G73: =E73*F73 -> 54259.2 | I73: 6 | J73: 2500 | K73: =J73/I73 -> 416.66667 | L73: 6 | M73: =F73/V73*60 -> 2257.0793 | N73: =M73/L73 -> 376.17989 | O73: =L73-I73 -> 0 | P73: =N73-K73 -> -40.486778 | Q73: =N73/K73 -> 0.90283173 | R73: =Q89 -> 0.85155475 | S73: 0.38611111 | T73: 0.42863426 | U73: 5.7833333 | V73: 61.247293 | AE73: =M73-J73 -> -242.92067 | AF73: =M73/J73 -> 0.90283173 | AG73: =AF89 -> 0.90477692
B74: 4℃-壽司手卷 | C74: 韓式辣炒豬肉飯卷 | E74: 27.05 | F74: 887 | G74: =E74*F74 -> 23993.35 | I74: 5 | J74: 3273 | K74: =J74/I74 -> 654.6 | L74: 6 | M74: =F74/V74*60 -> 2961.3146 | N74: =M74/L74 -> 493.55243 | O74: =L74-I74 -> 1 | P74: =N74-K74 -> -161.04757 | Q74: =N74/K74 -> 0.7539756 | S74: 0.43194444 | T74: 0.4444213 | U74: 4.7666667 | V74: 17.971748 | AE74: =M74-J74 -> -311.68542 | AF74: =M74/J74 -> 0.90477072
B75: 4℃-壽司手卷 | C75: 厚香料優格咖哩烤雞飯卷 | E75: 27.05 | F75: 1089 | G75: =E75*F75 -> 29457.45 | I75: 5 | J75: 3273 | K75: =J75/I75 -> 654.6 | L75: 5 | M75: =F75/V75*60 -> 2966.2181 | N75: =M75/L75 -> 593.24362 | O75: =L75-I75 -> 0 | P75: =N75-K75 -> -61.356377 | Q75: =N75/K75 -> 0.9062689 | S75: 0.44791667 | T75: 0.46320602 | U75: 5.0333333 | V75: 22.02805 | AE75: =M75-J75 -> -306.78189 | AF75: =M75/J75 -> 0.9062689
B89: 平均 | I89: =AVERAGE(I73:I88) -> 5.3333333 | J89: =AVERAGE(J73:J88) -> 3015.3333 | K89: =J89/I89 -> 565.375 | L89: =AVERAGE(L73:L88) -> 5.6666667 | M89: =AVERAGE(M73:M88) -> 2728.204 | N89: =M89/L89 -> 481.44777 | O89: =L89-I89 -> 0.33333333 | P89: =N89-K89 -> -83.927234 | Q89: =N89/K89 -> 0.85155475 | S89: 0.20833333 | T89: 0.46320602 | Y89: =SUM(Y73:Y88) -> 0 | Z89: =SUM(Z73:Z88) -> 0 | AC89: =SUM(AC73:AC88) -> 0 | AD89: =SUM(AD73:AD88) -> 0 | AE89: =M89-J89 -> -287.12933 | AF89: =M89/J89 -> 0.90477692
A90: 自動包裝機2 | B90: 4℃-壽司手卷 | C90: 鮪魚昆布細卷 | E90: 15.51 | F90: 2471 | G90: =E90*F90 -> 38325.21 | I90: 6 | J90: 3600 | K90: =J90/I90 -> 600 | L90: 6 | M90: =F90/V90*60 -> 3247.7931 | N90: =M90/L90 -> 541.29885 | O90: =L90-I90 -> 0 | P90: =N90-K90 -> -58.701149 | Q90: =N90/K90 -> 0.90216475 | R90: =Q106 -> 0.90255839 | S90: 0.25 | T90: 0.28168981 | V90: 45.64946 | AE90: =M90-J90 -> -352.20689 | AF90: =M90/J90 -> 0.90216475 | AG90: =AF106 -> 0.90255839
B91: 4℃-壽司手卷 | C91: 肉鬆火腿細卷 | E91: 15.01 | F91: 2619 | G91: =E91*F91 -> 39311.19 | I91: 6 | J91: 3600 | K91: =J91/I91 -> 600 | L91: 6 | M91: =F91/V91*60 -> 3250.6273 | N91: =M91/L91 -> 541.77121 | O91: =L91-I91 -> 0 | P91: =N91-K91 -> -58.228787 | Q91: =N91/K91 -> 0.90295202 | S91: 0.28541667 | T91: 0.31898148 | U91: 5.3666667 | V91: 48.341439 | AE91: =M91-J91 -> -349.37272 | AF91: =M91/J91 -> 0.90295202
B106: 平均 | I106: =AVERAGE(I90:I105) -> 6 | J106: =AVERAGE(J90:J105) -> 3600 | K106: =J106/I106 -> 600 | L106: =AVERAGE(L90:L105) -> 6 | M106: =AVERAGE(M90:M105) -> 3249.2102 | N106: =M106/L106 -> 541.53503 | O106: =L106-I106 -> 0 | P106: =N106-K106 -> -58.464968 | Q106: =N106/K106 -> 0.90255839 | S106: 0.25 | T106: 0.31898148 | Y106: =SUM(Y90:Y105) -> 0 | Z106: =SUM(Z90:Z105) -> 0 | AC106: =SUM(AC90:AC105) -> 0 | AD106: =SUM(AD90:AD105) -> 0 | AE106: =M106-J106 -> -350.78981 | AF106: =M106/J106 -> 0.90255839
...

Sheet 0809
B1: 屏榮 大溪廠組合室生產人時性分析
B3: 日期 | C3: 115.08.09星期日 | E3: 訂單量 | F3: ='0809(18度C)'!D1+'0809(4度C)'!D1 -> 211756 | H3: 營業額 | I3: ='0809(18度C)'!F1+'0809(4度C)'!F1 -> 6655646.1
B4: 人時性 | C4: 項目 | E4: ➀ | G4: ➁ | I4: ➂ | K4: ④ | M4: ⑤ | O4: 異常停線 | Q4: 短暫停線
C5: 組合室 | E5: 全溫層 | G5: 4度C-各編組展開(一配) | I5: 4度C-各編組展開(二配) | K5: 18度C-各編組展開(一配) | M5: 18度C-各編組展開(二配) | O5: 合計次數 | P5: 時間 | Q5: 合計次數 | R5: 設備次數
C6: 排關平均 | E6: =AVERAGE(D14:O14,D32:X32) -> 495.36277 | F6: =AVERAGE(#REF!,D14:K14) -> #REF! | G6: =AVERAGE(D14:K14) -> 270.22507 | I6: =AVERAGE(L14:O14) -> 94.325718 | K6: =AVERAGE(D32:O32) -> 737.95063 | M6: =AVERAGE(P32:X32) -> 791 | O6: ='0809(4度C)'!Y2 -> 0 | P6: ='0809(4度C)'!Z2 -> 0 | Q6: ='0809(4度C)'!AC2 -> 0 | R6: ='0809(4度C)'!AD2 -> 0
C7: 實績平均 | E7: =AVERAGE(D15:O15,D33:X33) -> 445.08293 | F7: =AVERAGE(#REF!,D15:K15) -> #REF! | G7: =AVERAGE(D15:K15) -> 238.95862 | I7: =AVERAGE(L15:O15) -> 87.498889 | K7: =AVERAGE(D33:O33) -> 664.77552 | M7: =AVERAGE(P33:X33) -> 713.36881
C8: 達成率平均 | E8: =AVERAGE(D16:O16,D34:X34) -> 0.90047856 | F8: =AVERAGE(D16:K16,#REF!) -> #REF! | G8: =AVERAGE(D16:K16) -> 0.89348295 | I8: =AVERAGE(L16:O16) -> 0.92576698 | K8: =AVERAGE(D34:O34) -> 0.89745821 | M8: =AVERAGE(P34:X34) -> 0.90134812
O9: ※現行日本鮮食廠以達成率80%為基本(即為現行KPI)
B11: 溫層 | D11: ➁4度C-各編組展開 | L11: ➂4度C-各編組展開
B12: 編組 | D12: 1 | E12: 2 | F12: 3 | G12: 4 | H12: 5 | I12: 6 | J12: 7 | K12: 8 | L12: 1 | M12: 2 | N12: 3 | O12: 4
D13: 便當一線 | E13: 便當二線 | F13: 涼麵一線 | G13: 涼麵二線 | H13: 涼麵三線 | I13: 自動包裝機 | J13: 自動包裝機2 | K13: 自動包裝機3 | L13: 便當一線 | M13: 便當二線 | N13: 涼麵一線 | O13: 涼麵二線
B14: 人時性 | C14: 排關 | D14: - | E14: 83.72093 | F14: 111.31579 | G14: 90.322581 | H14: 170.61611 | I14: 565.375 | J14: 600 | K14: - | L14: - | M14: 101.69492 | N14: 86.956522 | O14: -
C15: 實績 | D15: - | E15: 75.516908 | F15: 100.51012 | G15: 81.406523 | H15: 153.78897 | I15: 480.90415 | J15: 541.62503 | K15: - | L15: - | M15: 96.564286 | N15: 78.433492 | O15: -
C16: 達成率 | D16: - | E16: =E15/E14 -> 0.90200751 | F16: =F15/F14 -> 0.90292783 | G16: =G15/G14 -> 0.90128651 | H16: =H15/H14 -> 0.90137425 | I16: =I15/I14 -> 0.85059323 | J16: =J15/J14 -> 0.90270839 | K16: - | L16: - | M16: =M15/M14 -> 0.94954881 | N16: =N15/N14 -> 0.90198516 | O16: -
B17: 作業 時間 | C17: 開始 | D17: - | E17: 0.20833333 | F17: 0.20833333 | G17: 0.16666667 | H17: 0.16666667 | I17: 0.20833333 | J17: 0.25 | K17: - | L17: - | M17: 0.70833333 | N17: 0.70833333 | O17: -
C18: 結束 | D18: - | E18: 0.64769676 | F18: 0.52631944 | G18: 0.6771875 | H18: 0.64643519 | I18: 0.44952546 | J18: 0.31493056 | K18: - | L18: - | M18: 0.83488426 | N18: 0.85583333 | O18: -
B19: 產線異常 (5分鐘以上) | C19: 次數
C20: 時間/分
B21: 短暫停線 (5分鐘以下) | C21: 次數
C22: 設備次數
B23: 配置人數 | D23: - | E23: 21.5 | F23: 19.166667 | G23: 22.142857 | H23: 21.1 | I23: 5.6666667 | J23: 6 | K23: - | L23: - | M23: 18.666667 | N23: 23 | O23: -
B24: 主要應用設備 | D24: L型封口機 | E24: ET-55 | F24: ET-55 | G24: ET-55 | H24: ET-600 | I24: 伺服包裝機 | J24: 伺服包裝機 | K24: 伺服包裝機 | L24: L型封口機 | M24: ET-55 | N24: ET-55 | O24: ET-55
B25: 次要應用設備 | D25: 伺服包裝機 | H25: 伺服包裝機
B26: 備註 | H26: 涼麵+烤飯糰 | I26: 大口飯糰線 | K26: 烤飯糰+手卷
B29: 溫層 | D29: ➃18度C-各編組展開 (一配) | P29: ⑤18度C-各編組展開 (二配)
B30: 編組 | D30: 1 | E30: 2 | F30: 3 | G30: 4 | H30: 5 | I30: 6 | J30: 7 | K30: 8 | L30: 9 | M30: 10 | N30: 11 | O30: 12 | P30: 1 | Q30: 2 | R30: 3 | S30: 4 | T30: 5 | U30: 6 | V30: 7 | W30: 8 | X30: 9
D31: 便當一線 | E31: 涼麵一線 | F31: 涼麵三線 | G31: 自動包裝機 | H31: 自動包裝機2 | I31: 自動包裝機3 | J31: 味付飯糰線B | K31: (舊) 3300型飯糰線 | L31: 3000型飯糰線 | M31: (新) 3300型飯糰機 | N31: GKK3600型 飯糰機 | O31: GKK3600型 飯糰機2 | P31: 自動包裝機 | Q31: 自動包裝機2 | R31: 自動包裝機3 | S31: 味付飯糰線B | T31: (舊) 3300型飯糰線 | U31: 3000型飯糰線 | V31: (新) 3300型飯糰機 | W31: GKK3600型 飯糰機 | X31: GKK3600型 飯糰機2
B32: 人時性 | C32: 排關 | D32: - | E32: - | F32: - | G32: 327.27273 | H32: - | I32: - | J32: - | K32: - | L32: - | M32: 825 | N32: 940.90909 | O32: 858.62069 | P32: 490.90909 | Q32: - | R32: - | S32: - | T32: - | U32: - | V32: 709.09091 | W32: 1100 | X32: 864
C33: 實績 | D33: - | E33: - | F33: - | G33: 287.39459 | H33: - | I33: - | J33: - | K33: - | L33: - | M33: 753.90635 | N33: 847.55597 | O33: 770.24519 | P33: 438.63482 | Q33: - | R33: - | S33: - | T33: - | U33: - | V33: 647.89262 | W33: 994.27993 | X33: 772.66788
C34: 達成率 | D34: - | E34: - | F34: - | G34: =G33/G32 -> 0.87815013 | H34: - | I34: - | J34: - | K34: - | L34: - | M34: =M33/M32 -> 0.91382588 | N34: =N33/N32 -> 0.90078412 | O34: =O33/O32 -> 0.89707272 | P34: =P33/P32 -> 0.89351537 | Q34: - | R34: - | S34: - | T34: - | U34: - | V34: =V33/V32 -> 0.91369472 | W34: =W33/W32 -> 0.90389085 | X34: =X33/X32 -> 0.89429153
B35: 作業 時間 | C35: 開始 | D35: - | E35: - | F35: - | G35: 0.20833333 | H35: - | I35: - | J35: - | K35: - | L35: - | M35: 0.33263889 | N35: 0.25 | O35: 0.25 | P35: 0.70833333 | Q35: - | R35: - | S35: - | T35: - | U35: - | V35: 0.70833333 | W35: 0.73125 | X35: 0.74097222
C36: 結束 | D36: - | E36: - | F36: - | G36: 0.44952546 | H36: - | I36: - | J36: - | K36: - | L36: - | M36: 0.42873843 | N36: 0.53991898 | O36: 0.5359375 | P36: 0.76232639 | Q36: - | R36: - | S36: - | T36: - | U36: - | V36: 0.88533565 | W36: 1.1326389 | X36: 1.1299653
B37: 配置人數 | D37: - | E37: - | F37: - | G37: 11 | H37: - | I37: - | J37: - | K37: - | L37: - | M37: 4 | N37: 3.6666667 | O37: 4.1428571 | P37: 7.3333333 | Q37: - | R37: - | S37: - | T37: - | U37: - | V37: 4.4 | W37: 3 | X37: 4.1666667
B38: 主要應用設備 | D38: 伺服包裝機 | E38: ET-55 | F38: ET-600 | G38: 夾心型 | H38: 伺服包裝機 | I38: 伺服包裝機 | J38: 夾心型 | K38: 3300型 | L38: 3300型 | M38: 3300型 | N38: GKK | O38: GKK | P38: 夾心型 | Q38: 伺服包裝機 | R38: 伺服包裝機 | S38: 夾心型 | T38: 3300型 | U38: 3300型 | V38: 3300型 | W38: GKK | X38: GKK
B39: 次要應用設備
B40: 備註

Sheet 0809(18度C)
A1: 大溪廠日報分析 | C1: 總生產量 | D1: =SUM(F5:F140) -> 113185 | E1: 營業額 | F1: =SUM(G5:G140) -> 2234671.9 | G1: 出勤人數 | H1: =L21+L38+L55+L72+L89+L106+L123+L140 -> 41.709524 | I1: 產線配置圖 | L1: 生產實績 | O1: 人時性差異分析 | S1: 日報登錄 | Y1: 分析說明 | AA1: 產能差異分析
A2: 46243 | C2: 人時性 | D2: =AVERAGE(N21,N38,N55,N72,N89,N106,N123,N140) -> 689.07217 | E2: 平均廠價 | F2: =F1/D1 -> 19.743534 | G2: 多次生產數 | H2: =COUNT(H5:H140) -> 10
A3: 線別 | B3: 品類 | C3: 品名 | E3: 廠價 | F3: 生產量 | G3: 營收 | H3: 多次 生產 | I3: 人數 | J3: 產能/時 | K3: 人時性 | L3: 人數 | M3: 產能/時 | N3: 人時性 | O3: 人數 | P3: 人時性 | Q3: 達成率 | R3: 達成率 平均 | S3: 生產時間 | U3: 換線、休息/分 | V3: 稼動時間/分 | W3: 休息時間 | Y3: (屏榮回填) | AA3: 產能/時 | AB3: 達成率 | AC3: 達成率平均
S4: 開始 | T4: 結束 | W4: 開始 | X4: 結束
A5: 自動包裝機 | B5: 18℃-壽司手卷 | C5: 一配長野稻荷壽司 | E5: 25.64 | F5: 1919 | G5: =E5*F5 -> 49203.16 | I5: 10 | J5: 3600 | K5: =J5/I5 -> 360 | L5: 10 | M5: =F5/V5*60 -> 3216.1696 | N5: =M5/L5 -> 321.61696 | O5: =L5-I5 -> 0 | P5: =N5-K5 -> -38.383045 | Q5: =N5/K5 -> 0.89338043 | R5: =Q21 -> 0.87815013 | S5: 0.20833333 | T5: 0.23319444 | V5: 35.800351 | AA5: =M5-J5 -> -383.83045 | AB5: =M5/J5 -> 0.89338043 | AC5: =AB21 -> 0.87815013
B6: 18℃-壽司手卷 | C6: 一配經典人氣雙手卷 | E6: 29.52 | F6: 3031 | G6: =E6*F6 -> 89475.12 | I6: 11 | J6: 3600 | K6: =J6/I6 -> 327.27273 | L6: 11 | M6: =F6/V6*60 -> 3156.4633 | N6: =M6/L6 -> 286.95121 | O6: =L6-I6 -> 0 | P6: =N6-K6 -> -40.321514 | Q6: =N6/K6 -> 0.87679537 | S6: 0.23680556 | T6: 0.27680556 | U6: 5.2 | V6: 57.615116 | AA6: =M6-J6 -> -443.53666 | AB6: =M6/J6 -> 0.87679537
B7: 18℃-壽司手卷 | C7: 一配鮭鮪海饌雙手卷 | E7: 29.85 | F7: 3499 | G7: =E7*F7 -> 104445.15 | I7: 11 | J7: 3600 | K7: =J7/I7 -> 327.27273 | L7: 11 | M7: =F7/V7*60 -> 3157.6519 | N7: =M7/L7 -> 287.05926 | O7: =L7-I7 -> 0 | P7: =N7-K7 -> -40.213463 | Q7: =N7/K7 -> 0.87712553 | S7: 0.28055556 | T7: 0.32672454 | U7: 5.4 | V7: 66.486113 | AA7: =M7-J7 -> -442.34809 | AB7: =M7/J7 -> 0.87712553
B8: 18℃-壽司手卷 | C8: 一配青木瓜雞絲泰泰雙手卷 | E8: 30 | F8: 1877 | G8: =E8*F8 -> 56310 | I8: 11 | J8: 3600 | K8: =J8/I8 -> 327.27273 | L8: 11 | M8: =F8/V8*60 -> 3155.6752 | N8: =M8/L8 -> 286.87956 | O8: =L8-I8 -> 0 | P8: =N8-K8 -> -40.393167 | Q8: =N8/K8 -> 0.87657643 | S8: 0.33055556 | T8: 0.35533565 | U8: 5.5166667 | V8: 35.688084 | AA8: =M8-J8 -> -444.32484 | AB8: =M8/J8 -> 0.87657643
B9: 18℃-飯糰 | C9: 一配兩粒飯糰(鮪魚.焦糖鮭魚) | E9: 28.57 | F9: 1446 | G9: =E9*F9 -> 41312.22 | I9: 12 | J9: 3600 | K9: =J9/I9 -> 300 | L9: 12 | M9: =F9/V9*60 -> 3120.7423 | N9: =M9/L9 -> 260.06186 | O9: =L9-I9 -> 0 | P9: =N9-K9 -> -39.938141 | Q9: =N9/K9 -> 0.86687286 | S9: 0.35902778 | T9: 0.37833333 | U9: 5.3166667 | V9: 27.801078 | AA9: =M9-J9 -> -479.25769 | AB9: =M9/J9 -> 0.86687286
B21: 平均 | I21: =AVERAGE(I5:I20) -> 11 | J21: =AVERAGE(J5:J20) -> 3600 | K21: =J21/I21 -> 327.27273 | L21: =AVERAGE(L5:L20) -> 11 | M21: =AVERAGE(M5:M20) -> 3161.3405 | N21: =M21/L21 -> 287.39459 | O21: =L21-I21 -> 0 | P21: =N21-K21 -> -39.878141 | Q21: =N21/K21 -> 0.87815013 | S21: 0.20833333 | T21: 0.44952546 | AA21: =M21-J21 -> -438.65955 | AB21: =M21/J21 -> 0.87815013
A22: (新) 3300型飯糰機 | B22: 18℃-飯糰 | C22: 一配鮭魚奶油醬油飯糰 | E22: 18.53 | F22: 2594 | G22: =E22*F22 -> 48066.82 | I22: 3 | J22: 3300 | K22: =J22/I22 -> 1100 | L22: 3 | M22: =F22/V22*60 -> 3015.0734 | N22: =M22/L22 -> 1005.0245 | O22: =L22-I22 -> 0 | P22: =N22-K22 -> -94.97552 | Q22: =N22/K22 -> 0.91365862 | R22: =Q38 -> 0.91382588 | S22: 0.33263889 | T22: 0.3684838 | V22: 51.620633 | AA22: =M22-J22 -> -284.92656 | AB22: =M22/J22 -> 0.91365862 | AC22: =AB38 -> 0.91382588
B23: 18℃-飯糰 | C23: 一配壹號醬炙烤牛飯糰 | E23: 22.28 | F23: 773 | G23: =E23*F23 -> 17222.44 | I23: 5 | J23: 3300 | K23: =J23/I23 -> 660 | L23: 5 | M23: =F23/V23*60 -> 3017.0298 | N23: =M23/L23 -> 603.40596 | O23: =L23-I23 -> 0 | P23: =N23-K23 -> -56.594039 | Q23: =N23/K23 -> 0.91425146 | S23: 0.37222222 | T23: 0.38289352 | U23: 5.3833333 | V23: 15.372735 | AA23: =M23-J23 -> -282.97019 | AB23: =M23/J23 -> 0.91425146
B24: 18℃-飯糰 | C24: 一配鹽蔥燒肉飯糰 | E24: 17.89 | F24: 3085 | G24: =E24*F24 -> 55190.65 | I24: 4 | J24: 3300 | K24: =J24/I24 -> 825 | L24: 4 | M24: =F24/V24*60 -> 3014.773 | N24: =M24/L24 -> 753.69324 | O24: =L24-I24 -> 0 | P24: =N24-K24 -> -71.306761 | Q24: =N24/K24 -> 0.91356756 | S24: 0.38611111 | T24: 0.42873843 | U24: 4.6333333 | V24: 61.397658 | AA24: =M24-J24 -> -285.22704 | AB24: =M24/J24 -> 0.91356756
B38: 平均 | I38: =AVERAGE(I22:I37) -> 4 | J38: =AVERAGE(J22:J37) -> 3300 | K38: =J38/I38 -> 825 | L38: =AVERAGE(L22:L37) -> 4 | M38: =AVERAGE(M22:M37) -> 3015.6254 | N38: =M38/L38 -> 753.90635 | O38: =L38-I38 -> 0 | P38: =N38-K38 -> -71.09365 | Q38: =N38/K38 -> 0.91382588 | S38: 0.33263889 | T38: 0.42873843 | AA38: =M38-J38 -> -284.3746 | AB38: =M38/J38 -> 0.91382588
A39: GKK3600型 飯糰機 | B39: 18℃-飯糰 | C39: 一配熟成紅鮭飯糰 | E39: 25.03 | F39: 958 | G39: =E39*F39 -> 23978.74 | I39: 5 | J39: 3600 | K39: =J39/I39 -> 720 | L39: 5 | M39: =F39/V39*60 -> 3220.3096 | N39: =M39/L39 -> 644.06191 | O39: =L39-I39 -> 0 | P39: =N39-K39 -> -75.93809 | Q39: =N39/K39 -> 0.89453043 | R39: =Q55 -> 0.90078412 | S39: 0.25 | T39: 0.26238426 | V39: 17.849216 | AA39: =M39-J39 -> -379.69045 | AB39: =M39/J39 -> 0.89453043 | AC39: =AB55 -> 0.90078412
B40: 18℃-飯糰 | C40: 一配蔬食鮪魚飯糰 | E40: 18.18 | F40: 1281 | G40: =E40*F40 -> 23288.58 | I40: 3 | J40: 3600 | K40: =J40/I40 -> 1200 | L40: 3 | M40: =F40/V40*60 -> 3218.5218 | N40: =M40/L40 -> 1072.8406 | O40: =L40-I40 -> 0 | P40: =N40-K40 -> -127.1594 | Q40: =N40/K40 -> 0.89403384 | S40: 0.27222222 | T40: 0.2887963 | U40: 15 | V40: 23.880528 | AA40: =M40-J40 -> -381.47819 | AB40: =M40/J40 -> 0.89403384
B41: 18℃-飯糰 | C41: 一配北海道秋鮭親子飯糰 | E41: 24.82 | F41: 1269 | G41: =E41*F41 -> 31496.58 | I41: 5 | J41: 3600 | K41: =J41/I41 -> 720 | L41: 5 | M41: =F41/V41*60 -> 3221.0802 | N41: =M41/L41 -> 644.21603 | O41: =L41-I41 -> 0 | P41: =N41-K41 -> -75.783968 | Q41: =N41/K41 -> 0.89474449 | S41: 0.29861111 | T41: 0.31502315 | U41: 15 | V41: 23.638033 | AA41: =M41-J41 -> -378.91984 | AB41: =M41/J41 -> 0.89474449
B42: 18℃-飯糰 | C42: 一配黑胡椒洋蔥豬飯糰 | E42: 17.07 | F42: 2152 | G42: =E42*F42 -> 36734.64 | I42: 3 | J42: 3300 | K42: =J42/I42 -> 1100 | L42: 3 | M42: =F42/V42*60 -> 3021.4184 | N42: =M42/L42 -> 1007.1395 | O42: =L42-I42 -> 0 | P42: =N42-K42 -> -92.860545 | Q42: =N42/K42 -> 0.91558132 | S42: 0.325 | T42: 0.35467593 | U42: 15 | V42: 42.734896 | AA42: =M42-J42 -> -278.58164 | AB42: =M42/J42 -> 0.91558132
B43: 18℃-飯糰 | C43: 一配經典肉鬆飯糰 | E43: 14.03 | F43: 4928 | G43: =E43*F43 -> 69139.84 | I43: 3 | J43: 3000 | K43: =J43/I43 -> 1000 | L43: 3 | M43: =F43/V43*60 -> 2745.5161 | N43: =M43/L43 -> 915.17204 | O43: =L43-I43 -> 0 | P43: =N43-K43 -> -84.827962 | Q43: =N43/K43 -> 0.91517204 | S43: 0.36458333 | T43: 0.43936343 | U43: 15 | V43: 107.6956 | AA43: =M43-J43 -> -254.48389 | AB43: =M43/J43 -> 0.91517204
B44: 18℃-飯糰 | C44: 一配鮪魚飯糰 | E44: 14.28 | F44: 7002 | G44: =E44*F44 -> 99988.56 | I44: 3 | J44: 3600 | K44: =J44/I44 -> 1200 | L44: 3 | M44: =F44/V44*60 -> 3219.3852 | N44: =M44/L44 -> 1073.1284 | O44: =L44-I44 -> 0 | P44: =N44-K44 -> -126.87159 | Q44: =N44/K44 -> 0.89427368 | S44: 0.44930556 | T44: 0.53991898 | U44: 15 | V44: 130.49696 | AA44: =M44-J44 -> -380.61476 | AB44: =M44/J44 -> 0.89427368
B55: 平均 | I55: =AVERAGE(I39:I54) -> 3.6666667 | J55: =AVERAGE(J39:J54) -> 3450 | K55: =J55/I55 -> 940.90909 | L55: =AVERAGE(L39:L54) -> 3.6666667 | M55: =AVERAGE(M39:M54) -> 3107.7052 | N55: =M55/L55 -> 847.55597 | O55: =L55-I55 -> 0 | P55: =N55-K55 -> -93.353126 | Q55: =N55/K55 -> 0.90078412 | S55: 0.25 | T55: 0.53991898 | AA55: =M55-J55 -> -342.29479 | AB55: =M55/J55 -> 0.90078412
A56: GKK3600型 飯糰機2 | B56: 18℃-飯糰 | C56: 一配椒鹽檸檬鯖魚飯糰 | E56: 20.72 | F56: 1620 | G56: =E56*F56 -> 33566.4 | I56: 3 | J56: 3600 | K56: =J56/I56 -> 1200 | L56: 3 | M56: =F56/V56*60 -> 3219.4384 | N56: =M56/L56 -> 1073.1461 | O56: =L56-I56 -> 0 | P56: =N56-K56 -> -126.85388 | Q56: =N56/K56 -> 0.89428843 | R56: =Q72 -> 0.89707272 | S56: 0.25 | T56: 0.27096065 | V56: 30.191602 | AA56: =M56-J56 -> -380.56164 | AB56: =M56/J56 -> 0.89428843 | AC56: =AB72 -> 0.89707272
B57: 18℃-飯糰 | C57: 一配柚檸海灣貝飯糰 | E57: 23.72 | F57: 658 | G57: =E57*F57 -> 15607.76 | I57: 5 | J57: 3600 | K57: =J57/I57 -> 720 | L57: 5 | M57: =F57/V57*60 -> 3219.6711 | N57: =M57/L57 -> 643.93423 | O57: =L57-I57 -> 0 | P57: =N57-K57 -> -76.06577 | Q57: =N57/K57 -> 0.8943531 | S57: 0.28125 | T57: 0.28975694 | U57: 14.816667 | V57: 12.262122 | AA57: =M57-J57 -> -380.32885 | AB57: =M57/J57 -> 0.8943531
B58: 18℃-飯糰 | C58: 一配贅沢鮭魚肚飯糰 | E58: 30 | F58: 1964 | G58: =E58*F58 -> 58920 | I58: 4 | J58: 3600 | K58: =J58/I58 -> 900 | L58: 4 | M58: =F58/V58*60 -> 3221.7907 | N58: =M58/L58 -> 805.44767 | O58: =L58-I58 -> 0 | P58: =N58-K58 -> -94.552331 | Q58: =N58/K58 -> 0.89494185 | S58: 0.3 | T58: 0.32539352 | U58: 14.75 | V58: 36.575933 | AA58: =M58-J58 -> -378.20933 | AB58: =M58/J58 -> 0.89494185
B59: 18℃-飯糰 | C59: 一配筋子銀鮭飯糰 | E59: 30 | F59: 2038 | G59: =E59*F59 -> 61140 | I59: 4 | J59: 3300 | K59: =J59/I59 -> 825 | L59: 4 | M59: =F59/V59*60 -> 3022.0509 | N59: =M59/L59 -> 755.51273 | O59: =L59-I59 -> 0 | P59: =N59-K59 -> -69.487275 | Q59: =N59/K59 -> 0.915773 | S59: 0.33541667 | T59: 0.36350694 | U59: 15 | V59: 40.462588 | AA59: =M59-J59 -> -277.9491 | AB59: =M59/J59 -> 0.915773
B60: 18℃-飯糰 | C60: 一配鹽蔥生鮭飯糰 | E60: 27.48 | F60: 3014 | G60: =E60*F60 -> 82824.72 | I60: 5 | J60: 3600 | K60: =J60/I60 -> 720 | L60: 5 | M60: =F60/V60*60 -> 3221.6459 | N60: =M60/L60 -> 644.32918 | O60: =L60-I60 -> 0 | P60: =N60-K60 -> -75.670825 | Q60: =N60/K60 -> 0.89490163 | S60: 0.37361111 | T60: 0.41258102 | U60: 14.55 | V60: 56.132799 | AA60: =M60-J60 -> -378.35412 | AB60: =M60/J60 -> 0.89490163
B61: 18℃-飯糰 | C61: 一配明太子龍蝦風味沙拉飯糰 | E61: 18.18 | F61: 2227 | G61: =E61*F61 -> 40486.86 | I61: 3 | J61: 3600 | K61: =J61/I61 -> 1200 | L61: 3 | M61: =F61/V61*60 -> 3215.8863 | N61: =M61/L61 -> 1071.9621 | O61: =L61-I61 -> 0 | P61: =N61-K61 -> -128.03791 | Q61: =N61/K61 -> 0.89330174 | S61: 0.42291667 | T61: 0.45175926 | U61: 14.883333 | V61: 41.549977 | AA61: =M61-J61 -> -384.11372 | AB61: =M61/J61 -> 0.89330174
B62: 18℃-飯糰 | C62: 一配雞肉飯飯糰 | E62: 16.66 | F62: 5723 | G62: =E62*F62 -> 95345.18 | I62: 5 | J62: 3600 | K62: =J62/I62 -> 720 | L62: 5 | M62: =F62/V62*60 -> 3216.6274 | N62: =M62/L62 -> 643.32547 | O62: =L62-I62 -> 0 | P62: =N62-K62 -> -76.674527 | Q62: =N62/K62 -> 0.8935076 | S62: 0.46180556 | T62: 0.5359375 | U62: 15 | V62: 106.75156 | AA62: =M62-J62 -> -383.37263 | AB62: =M62/J62 -> 0.8935076
B72: 平均 | I72: =AVERAGE(I56:I71) -> 4.1428571 | J72: =AVERAGE(J56:J71) -> 3557.1429 | K72: =J72/I72 -> 858.62069 | L72: =AVERAGE(L56:L71) -> 4.1428571 | M72: =AVERAGE(M56:M71) -> 3191.0158 | N72: =M72/L72 -> 770.24519 | O72: =L72-I72 -> 0 | P72: =N72-K72 -> -88.375496 | Q72: =N72/K72 -> 0.89707272 | S72: 0.25 | T72: 0.5359375 | AA72: =M72-J72 -> -366.12706 | AB72: =M72/J72 -> 0.89707272
A73: 自動包裝機 (二配) | B73: 18℃-飯糰 | C73: 二配兩粒飯糰(鮪魚.焦糖鮭魚) | E73: 28.57 | F73: 1681 | G73: =E73*F73 -> 48026.17 | I73: 12 | J73: 3600 | K73: =J73/I73 -> 300 | L73: 12 | M73: =F73/V73*60 -> 3119.819 | N73: =M73/L73 -> 259.98492 | O73: =L73-I73 -> 0 | P73: =N73-K73 -> -40.015083 | Q73: =N73/K73 -> 0.86661639 | R73: =Q89 -> 0.89351537 | S73: 0.70833333 | T73: 0.73077546 | V73: 32.328799 | AA73: =M73-J73 -> -480.181 | AB73: =M73/J73 -> 0.86661639 | AC73: =AB89 -> 0.89351537
B74: 18℃-飯糰 | C74: 二配柚香雞胸五穀飯糰 | E74: 17.71 | F74: 638 | G74: =E74*F74 -> 11298.98 | I74: 5 | J74: 3600 | K74: =J74/I74 -> 720 | L74: 5 | M74: =F74/V74*60 -> 3265.7323 | N74: =M74/L74 -> 653.14646 | O74: =L74-I74 -> 0 | P74: =N74-K74 -> -66.853537 | Q74: =N74/K74 -> 0.90714786 | S74: 0.73402778 | T74: 0.74216435 | U74: 4.6833333 | V74: 11.72172 | AA74: =M74-J74 -> -334.26769 | AB74: =M74/J74 -> 0.90714786
B75: 18℃-飯糰 | C75: 二配鮭魚毛豆炊飯飯糰 | E75: 18.92 | F75: 1293 | G75: =E75*F75 -> 24463.56 | I75: 5 | J75: 3600 | K75: =J75/I75 -> 720 | L75: 5 | M75: =F75/V75*60 -> 3264.4147 | N75: =M75/L75 -> 652.88293 | O75: =L75-I75 -> 0 | P75: =N75-K75 -> -67.117068 | Q75: =N75/K75 -> 0.90678185 | S75: 0.74583333 | T75: 0.76232639 | U75: 5.2833333 | V75: 23.765363 | AA75: =M75-J75 -> -335.58534 | AB75: =M75/J75 -> 0.90678185
B89: 平均 | I89: =AVERAGE(I73:I88) -> 7.3333333 | J89: =AVERAGE(J73:J88) -> 3600 | K89: =J89/I89 -> 490.90909 | L89: =AVERAGE(L73:L88) -> 7.3333333 | M89: =AVERAGE(M73:M88) -> 3216.6553 | N89: =M89/L89 -> 438.63482 | O89: =L89-I89 -> 0 | P89: =N89-K89 -> -52.274274 | Q89: =N89/K89 -> 0.89351537 | S89: 0.70833333 | T89: 0.76232639 | AA89: =M89-J89 -> -383.34468 | AB89: =M89/J89 -> 0.89351537
A90: (新) 3300型飯糰機 (二配) | B90: 18℃-飯糰 | C90: 二配大飯糰乾燒風味鮮蝦 | E90: 23.27 | F90: 585 | G90: =E90*F90 -> 13612.95 | I90: 5 | J90: 3000 | K90: =J90/I90 -> 600 | L90: 5 | M90: =F90/V90*60 -> 2741.4771 | N90: =M90/L90 -> 548.29543 | O90: =L90-I90 -> 0 | P90: =N90-K90 -> -51.704572 | Q90: =N90/K90 -> 0.91382571 | R90: =Q106 -> 0.91369472 | S90: 0.70833333 | T90: 0.71722222 | V90: 12.803317 | AA90: =M90-J90 -> -258.52286 | AB90: =M90/J90 -> 0.91382571 | AC90: =AB106 -> 0.91369472
B91: 18℃-飯糰 | C91: 二配大飯糰韓式蒜烤豬五花 | E91: 24.54 | F91: 1501 | G91: =E91*F91 -> 36834.54 | I91: 4 | J91: 3000 | K91: =J91/I91 -> 750 | L91: 4 | M91: =F91/V91*60 -> 2741.7099 | N91: =M91/L91 -> 685.42748 | O91: =L91-I91 -> 0 | P91: =N91-K91 -> -64.572523 | Q91: =N91/K91 -> 0.9139033 | S91: 0.72013889 | T91: 0.74293981 | U91: 5 | V91: 32.848114 | AA91: =M91-J91 -> -258.29009 | AB91: =M91/J91 -> 0.9139033
B92: 18℃-飯糰 | C92: 二配大飯糰泡菜鮪魚 | E92: 24.33 | F92: 1555 | G92: =E92*F92 -> 37833.15 | I92: 4 | J92: 3000 | K92: =J92/I92 -> 750 | L92: 4 | M92: =F92/V92*60 -> 2741.3238 | N92: =M92/L92 -> 685.33094 | O92: =L92-I92 -> 0 | P92: =N92-K92 -> -64.669061 | Q92: =N92/K92 -> 0.91377459 | S92: 0.74652778 | T92: 0.77016204 | U92: 5.1666667 | V92: 34.034652 | AA92: =M92-J92 -> -258.67624 | AB92: =M92/J92 -> 0.91377459
B93: 18℃-飯糰 | C93: 二配壹號醬炙烤牛飯糰 | E93: 22.28 | F93: 1727 | G93: =E93*F93 -> 38477.56 | I93: 5 | J93: 3300 | K93: =J93/I93 -> 660 | L93: 5 | M93: =F93/V93*60 -> 3012.9388 | N93: =M93/L93 -> 602.58775 | O93: =L93-I93 -> 0 | P93: =N93-K93 -> -57.412245 | Q93: =N93/K93 -> 0.91301175 | S93: 0.77361111 | T93: 0.79748843 | U93: 4.9666667 | V93: 34.391671 | AA93: =M93-J93 -> -287.06123 | AB93: =M93/J93 -> 0.91301175
B94: 18℃-飯糰 | C94: 二配鹽蔥燒肉飯糰 | E94: 17.89 | F94: 6077 | G94: =E94*F94 -> 108717.53 | I94: 4 | J94: 3300 | K94: =J94/I94 -> 825 | L94: 4 | M94: =F94/V94*60 -> 3016.1881 | N94: =M94/L94 -> 754.04702 | O94: =L94-I94 -> 0 | P94: =N94-K94 -> -70.952981 | Q94: =N94/K94 -> 0.91399639 | S94: 0.80138889 | T94: 0.88533565 | U94: 5.6166667 | V94: 120.88769 | AA94: =M94-J94 -> -283.81192 | AB94: =M94/J94 -> 0.91399639
B106: 平均 | I106: =AVERAGE(I90:I105) -> 4.4 | J106: =AVERAGE(J90:J105) -> 3120 | K106: =J106/I106 -> 709.09091 | L106: =AVERAGE(L90:L105) -> 4.4 | M106: =AVERAGE(M90:M105) -> 2850.7275 | N106: =M106/L106 -> 647.89262 | O106: =L106-I106 -> 0 | P106: =N106-K106 -> -61.198288 | Q106: =N106/K106 -> 0.91369472 | S106: 0.70833333 | T106: 0.88533565 | AA106: =M106-J106 -> -269.27247 | AB106: =M106/J106 -> 0.91369472
A107: GKK3600型 飯糰機 (二配) | B107: 18℃-飯糰 | C107: 二配芝麻香鬆飯糰 | E107: 18.18 | F107: 714 | G107: =E107*F107 -> 12980.52 | H107: 2 | I107: 3 | J107: 3000 | K107: =J107/I107 -> 1000 | L107: 3 | M107: =F107/V107*60 -> 2743.3541 | N107: =M107/L107 -> 914.45137 | O107: =L107-I107 -> 0 | P107: =N107-K107 -> -85.548628 | Q107: =N107/K107 -> 0.91445137 | R107: =Q123 -> 0.90389085 | S107: 0.73125 | T107: 0.74208333 | V107: 15.615921 | AA107: =M107-J107 -> -256.64588 | AB107: =M107/J107 -> 0.91445137 | AC107: =AB123 -> 0.90389085
...

Sheet 0809(4度C)
A1: 大溪廠日報分析 | C1: 總生產量 | D1: =SUM(F5:F140) -> 98571 | E1: 營業額 | F1: =SUM(G5:G140) -> 4420974.2 | G1: 出勤人數 | H1: =L21+L38+L55+L72+L89+L106+L123+L140 -> 137.24286 | I1: 產線配置圖 | L1: 生產實績 | O1: 人時性差異分析 | S1: 日報登錄 | Y1: 合計次數 | Z1: 合計(時間/分) | AA1: 產線異常 分析說明(5分鐘以上) | AC1: 合計次數 | AD1: 合計(時間/分) | AE1: 產能差異分析
A2: 46243 | C2: 人時性 | D2: =AVERAGE(N21,N38,N55,N72,N89,N106,N123,N140) -> 201.09369 | E2: 平均廠價 | F2: =F1/D1 -> 44.850658 | G2: 多次生產數 | H2: =COUNT(H5:H140) -> 2 | Y2: =SUM(Y21,Y38,Y55,Y72,Y89,Y106,Y123,Y140) -> 0 | Z2: =SUM(Z21,Z38,Z55,Z72,Z89,Z106,Z123,Z140) -> 0 | AC2: =SUM(AC21,AC38,AC55,AC72,AC89,AC106,AC123,AC140) -> 0 | AD2: =SUM(AD21,AD38,AD55,AD72,AD89,AD106,AD123,AD140) -> 0
A3: 線別 | B3: 品類 | C3: 品名 | E3: 廠價 | F3: 生產量 | G3: 營收 | H3: 多次 生產 | I3: 人數 | J3: 產能/時 | K3: 人時性 | L3: 人數 | M3: 產能/時 | N3: 人時性 | O3: 人數 | P3: 人時性 | Q3: 達成率 | R3: 達成率 平均 | S3: 生產時間 | U3: 換線、休息/分 | V3: 稼動時間/分 | W3: 休息時間 | Y3: 產線異常統計(5分鐘以上) | AA3: (屏榮回填) | AC3: 短暫停線統計(5分鐘以下) | AE3: 產能/時 | AF3: 達成率 | AG3: 達成率平均
S4: 開始 | T4: 結束 | W4: 開始 | X4: 結束 | Y4: 次數 | Z4: 時間/分 | AC4: 總次數 | AD4: 設備因素(次數)
