Workbook

Sheet 0630
B1: 屏榮 大溪廠組合室生產人時性分析
B3: 日期 | C3: 115.06.30星期二 | E3: 訂單量 | F3: ='0630(18度C)'!D1+'0630(4度C)'!D1 -> 229980 | H3: 營業額 | I3: ='0630(18度C)'!F1+'0630(4度C)'!F1 -> 7292751.3
B4: 人時性 | C4: 項目 | E4: ➀ | G4: ➁ | I4: ➂ | K4: ④ | M4: ⑤ | O4: 異常停線 | Q4: 短暫停線
C5: 組合室 | E5: 全溫層 | G5: 4度C-各編組展開(一配) | I5: 4度C-各編組展開(二配) | K5: 18度C-各編組展開(一配) | M5: 18度C-各編組展開(二配) | O5: 合計次數 | P5: 時間 | Q5: 合計次數 | R5: 設備次數
C6: 排關平均 | E6: =AVERAGE(D14:O14,D32:X32) -> 467.18932 | F6: =AVERAGE(#REF!,D14:K14) -> #REF! | G6: =AVERAGE(D14:K14) -> 259.10779 | I6: =AVERAGE(L14:O14) -> 94.858523 | K6: =AVERAGE(D32:O32) -> 758.22628 | M6: =AVERAGE(P32:X32) -> 767.52276 | O6: ='0630(4度C)'!Y2 -> 0 | P6: ='0630(4度C)'!Z2 -> 0 | Q6: ='0630(4度C)'!AC2 -> 0 | R6: ='0630(4度C)'!AD2 -> 0
C7: 實績平均 | E7: =AVERAGE(D15:O15,D33:X33) -> 414.46182 | F7: =AVERAGE(#REF!,D15:K15) -> #REF! | G7: =AVERAGE(D15:K15) -> 224.5527 | I7: =AVERAGE(L15:O15) -> 85.517795 | K7: =AVERAGE(D33:O33) -> 676.93347 | M7: =AVERAGE(P33:X33) -> 683.56186
C8: 達成率平均 | E8: =AVERAGE(D16:O16,D34:X34) -> 0.88940871 | F8: =AVERAGE(D16:K16,#REF!) -> #REF! | G8: =AVERAGE(D16:K16) -> 0.88244287 | I8: =AVERAGE(L16:O16) -> 0.90192169 | K8: =AVERAGE(D34:O34) -> 0.89084618 | M8: =AVERAGE(P34:X34) -> 0.88903526
O9: ※現行日本鮮食廠以達成率80%為基本(即為現行KPI)
B11: 溫層 | D11: ➁4度C-各編組展開 | L11: ➂4度C-各編組展開
B12: 編組 | D12: 1 | E12: 2 | F12: 3 | G12: 4 | H12: 5 | I12: 6 | J12: 7 | K12: 8 | L12: 1 | M12: 2 | N12: 3 | O12: 4
D13: 便當一線 | E13: 便當二線 | F13: 涼麵一線 | G13: 涼麵二線 | H13: 涼麵三線 | I13: 自動包裝機 | J13: 自動包裝機2 | K13: 自動包裝機3 | L13: 便當一線 | M13: 便當二線 | N13: 涼麵一線 | O13: 涼麵二線
B14: 人時性 | C14: 排關 | D14: - | E14: 85.517241 | F14: 116.32813 | G14: 90.322581 | H14: 174.54545 | I14: 654.6 | J14: 433.33333 | K14: - | L14: - | M14: 90.47619 | N14: 86.956522 | O14: 107.14286
C15: 實績 | D15: - | E15: 76.758862 | F15: 103.58224 | G15: 79.787464 | H15: 156.30728 | I15: 538.96456 | J15: 391.91577 | K15: - | L15: - | M15: 82.877696 | N15: 77.896314 | O15: 95.779373
C16: 達成率 | D16: - | E16: =E15/E14 -> 0.89758346 | F16: =F15/F14 -> 0.89043163 | G16: =G15/G14 -> 0.8833612 | H16: =H15/H14 -> 0.89551044 | I16: =I15/I14 -> 0.82334947 | J16: =J15/J14 -> 0.90442101 | K16: - | L16: - | M16: =M15/M14 -> 0.91601664 | N16: =N15/N14 -> 0.89580761 | O16: =O15/O14 -> 0.89394082
B17: 作業 時間 | C17: 開始 | D17: - | E17: 0.16666667 | F17: 0.16666667 | G17: 0.16666667 | H17: 0.16666667 | I17: 0.25 | J17: 0.25 | K17: - | L17: - | M17: 0.73541667 | N17: 0.70833333 | O17: 0.70833333
C18: 結束 | D18: - | E18: 0.71666667 | F18: 0.65836806 | G18: 0.62726852 | H18: 0.59304398 | I18: 0.45006944 | J18: 0.33930556 | K18: - | L18: - | M18: 0.81407407 | N18: 0.83884259 | O18: 0.8558912
B19: 產線異常 (5分鐘以上) | C19: 次數
C20: 時間/分
B21: 短暫停線 (5分鐘以下) | C21: 次數
C22: 設備次數
B23: 配置人數 | D23: - | E23: 20.714286 | F23: 18.428571 | G23: 22.142857 | H23: 20.625 | I23: 5.5 | J23: 6 | K23: - | L23: - | M23: 20.5 | N23: 23 | O23: 18.666667
B24: 主要應用設備 | D24: L型封口機 | E24: ET-55 | F24: ET-55 | G24: ET-55 | H24: ET-600 | I24: 伺服包裝機 | J24: 伺服包裝機 | K24: 伺服包裝機 | L24: L型封口機 | M24: ET-55 | N24: ET-55 | O24: ET-55
B25: 次要應用設備 | D25: 伺服包裝機 | H25: 伺服包裝機
B26: 備註 | H26: 涼麵+烤飯糰 | I26: 大口飯糰線 | K26: 烤飯糰+手卷
B29: 溫層 | D29: ➃18度C-各編組展開 (一配) | P29: ⑤18度C-各編組展開 (二配)
B30: 編組 | D30: 1 | E30: 2 | F30: 3 | G30: 4 | H30: 5 | I30: 6 | J30: 7 | K30: 8 | L30: 9 | M30: 10 | N30: 11 | O30: 12 | P30: 1 | Q30: 2 | R30: 3 | S30: 4 | T30: 5 | U30: 6 | V30: 7 | W30: 8 | X30: 9
D31: 便當一線 | E31: 涼麵一線 | F31: 涼麵三線 | G31: 自動包裝機 | H31: 自動包裝機2 | I31: 自動包裝機3 | J31: 味付飯糰線B | K31: (舊) 3300型飯糰線 | L31: 3000型飯糰線 | M31: (新) 3300型飯糰機 | N31: GKK3600型 飯糰機 | O31: GKK3600型 飯糰機2 | P31: 自動包裝機 | Q31: 自動包裝機2 | R31: 自動包裝機3 | S31: 味付飯糰線B | T31: (舊) 3300型飯糰線 | U31: 3000型飯糰線 | V31: (新) 3300型飯糰機 | W31: GKK3600型 飯糰機 | X31: GKK3600型 飯糰機2
B32: 人時性 | C32: 排關 | D32: - | E32: - | F32: - | G32: 327.27273 | H32: - | I32: - | J32: - | K32: - | L32: - | M32: 825 | N32: 954.54545 | O32: 926.08696 | P32: 389.18919 | Q32: - | R32: - | S32: - | T32: - | U32: - | V32: 765.51724 | W32: 1015.3846 | X32: 900
C33: 實績 | D33: - | E33: - | F33: - | G33: 287.46981 | H33: - | I33: - | J33: - | K33: - | L33: - | M33: 747.45494 | N33: 848.6572 | O33: 824.15192 | P33: 342.16967 | Q33: - | R33: - | S33: - | T33: - | U33: - | V33: 685.42306 | W33: 908.42704 | X33: 798.22766
C34: 達成率 | D34: - | E34: - | F34: - | G34: =G33/G32 -> 0.87837996 | H34: - | I34: - | J34: - | K34: - | L34: - | M34: =M33/M32 -> 0.90600599 | N34: =N33/N32 -> 0.88906945 | O34: =O33/O32 -> 0.88992931 | P34: =P33/P32 -> 0.87918595 | Q34: - | R34: - | S34: - | T34: - | U34: - | V34: =V33/V32 -> 0.89537247 | W34: =W33/W32 -> 0.89466299 | X34: =X33/X32 -> 0.88691962
B35: 作業 時間 | C35: 開始 | D35: - | E35: - | F35: - | G35: 0.25 | H35: - | I35: - | J35: - | K35: - | L35: - | M35: 0.35694444 | N35: 0.25 | O35: 0.25 | P35: 0.70833333 | Q35: - | R35: - | S35: - | T35: - | U35: - | V35: 0.70833333 | W35: 0.78680556 | X35: 0.75763889
C36: 結束 | D36: - | E36: - | F36: - | G36: 0.45006944 | H36: - | I36: - | J36: - | K36: - | L36: - | M36: 0.46508102 | N36: 0.54493056 | O36: 0.54524306 | P36: 0.83944444 | Q36: - | R36: - | S36: - | T36: - | U36: - | V36: 0.99738426 | W36: 1.1701505 | X36: 1.1817593
B37: 配置人數 | D37: - | E37: - | F37: - | G37: 11 | H37: - | I37: - | J37: - | K37: - | L37: - | M37: 4 | N37: 3.6666667 | O37: 3.8333333 | P37: 9.25 | Q37: - | R37: - | S37: - | T37: - | U37: - | V37: 4.1428571 | W37: 3.25 | X37: 4
B38: 主要應用設備 | D38: 伺服包裝機 | E38: ET-55 | F38: ET-600 | G38: 夾心型 | H38: 伺服包裝機 | I38: 伺服包裝機 | J38: 夾心型 | K38: 3300型 | L38: 3300型 | M38: 3300型 | N38: GKK | O38: GKK | P38: 夾心型 | Q38: 伺服包裝機 | R38: 伺服包裝機 | S38: 夾心型 | T38: 3300型 | U38: 3300型 | V38: 3300型 | W38: GKK | X38: GKK
B39: 次要應用設備
B40: 備註

Sheet 0630(18度C)
A1: 大溪廠日報分析 | C1: 總生產量 | D1: =SUM(F5:F140) -> 123366 | E1: 營業額 | F1: =SUM(G5:G140) -> 2410082.5 | G1: 出勤人數 | H1: =L21+L38+L55+L72+L89+L106+L123+L140 -> 43.142857 | I1: 產線配置圖 | L1: 生產實績 | O1: 人時性差異分析 | S1: 日報登錄 | Y1: 分析說明 | AA1: 產能差異分析
A2: 46203 | C2: 人時性 | D2: =AVERAGE(N21,N38,N55,N72,N89,N106,N123,N140) -> 680.24766 | E2: 平均廠價 | F2: =F1/D1 -> 19.536035 | G2: 多次生產數 | H2: =COUNT(H5:H140) -> 11
A3: 線別 | B3: 品類 | C3: 品名 | E3: 廠價 | F3: 生產量 | G3: 營收 | H3: 多次 生產 | I3: 人數 | J3: 產能/時 | K3: 人時性 | L3: 人數 | M3: 產能/時 | N3: 人時性 | O3: 人數 | P3: 人時性 | Q3: 達成率 | R3: 達成率 平均 | S3: 生產時間 | U3: 換線、休息/分 | V3: 稼動時間/分 | W3: 休息時間 | Y3: (屏榮回填) | AA3: 產能/時 | AB3: 達成率 | AC3: 達成率平均
S4: 開始 | T4: 結束 | W4: 開始 | X4: 結束
A5: 自動包裝機 | B5: 18℃-壽司手卷 | C5: 一配長野稻荷壽司 | E5: 25.64 | F5: 1829 | G5: =E5*F5 -> 46895.56 | I5: 10 | J5: 3600 | K5: =J5/I5 -> 360 | L5: 10 | M5: =F5/V5*60 -> 3214.0096 | N5: =M5/L5 -> 321.40096 | O5: =L5-I5 -> 0 | P5: =N5-K5 -> -38.599045 | Q5: =N5/K5 -> 0.89278043 | R5: =Q21 -> 0.87837996 | S5: 0.25 | T5: 0.2737037 | V5: 34.144267 | AA5: =M5-J5 -> -385.99045 | AB5: =M5/J5 -> 0.89278043 | AC5: =AB21 -> 0.87837996
B6: 18℃-壽司手卷 | C6: 一配經典人氣雙手卷 | E6: 29.52 | F6: 3065 | G6: =E6*F6 -> 90478.8 | I6: 11 | J6: 3600 | K6: =J6/I6 -> 327.27273 | L6: 11 | M6: =F6/V6*60 -> 3159.2041 | N6: =M6/L6 -> 287.20037 | O6: =L6-I6 -> 0 | P6: =N6-K6 -> -40.072355 | Q6: =N6/K6 -> 0.87755669 | S6: 0.27708333 | T6: 0.3175 | U6: 4.8666667 | V6: 58.210864 | AA6: =M6-J6 -> -440.7959 | AB6: =M6/J6 -> 0.87755669
B7: 18℃-壽司手卷 | C7: 一配鮭鮪海饌雙手卷 | E7: 29.85 | F7: 3560 | G7: =E7*F7 -> 106266 | I7: 11 | J7: 3600 | K7: =J7/I7 -> 327.27273 | L7: 11 | M7: =F7/V7*60 -> 3161.0368 | N7: =M7/L7 -> 287.36698 | O7: =L7-I7 -> 0 | P7: =N7-K7 -> -39.905749 | Q7: =N7/K7 -> 0.87806577 | S7: 0.32083333 | T7: 0.36775463 | U7: 4.8 | V7: 67.572767 | AA7: =M7-J7 -> -438.96324 | AB7: =M7/J7 -> 0.87806577
B8: 18℃-飯糰 | C8: 一配兩粒飯糰(鮪魚.焦糖鮭魚) | E8: 28.57 | F8: 1863 | G8: =E8*F8 -> 53225.91 | I8: 12 | J8: 3600 | K8: =J8/I8 -> 300 | L8: 12 | M8: =F8/V8*60 -> 3114.4211 | N8: =M8/L8 -> 259.53509 | O8: =L8-I8 -> 0 | P8: =N8-K8 -> -40.46491 | Q8: =N8/K8 -> 0.86511697 | S8: 0.37152778 | T8: 0.39644676 | U8: 5.4333333 | V8: 35.8911 | AA8: =M8-J8 -> -485.57892 | AB8: =M8/J8 -> 0.86511697
B21: 平均 | I21: =AVERAGE(I5:I20) -> 11 | J21: =AVERAGE(J5:J20) -> 3600 | K21: =J21/I21 -> 327.27273 | L21: =AVERAGE(L5:L20) -> 11 | M21: =AVERAGE(M5:M20) -> 3162.1679 | N21: =M21/L21 -> 287.46981 | O21: =L21-I21 -> 0 | P21: =N21-K21 -> -39.802921 | Q21: =N21/K21 -> 0.87837996 | S21: 0.25 | T21: 0.45006944 | AA21: =M21-J21 -> -437.83213 | AB21: =M21/J21 -> 0.87837996
A22: (新) 3300型飯糰機 | B22: 18℃-飯糰 | C22: 一配鮭魚奶油醬油飯糰 | E22: 18.53 | F22: 2841 | G22: =E22*F22 -> 52643.73 | I22: 3 | J22: 3300 | K22: =J22/I22 -> 1100 | L22: 3 | M22: =F22/V22*60 -> 2989.8593 | N22: =M22/L22 -> 996.61977 | O22: =L22-I22 -> 0 | P22: =N22-K22 -> -103.38023 | Q22: =N22/K22 -> 0.90601797 | R22: =Q38 -> 0.90600599 | S22: 0.35694444 | T22: 0.39652778 | V22: 57.012716 | AA22: =M22-J22 -> -310.1407 | AB22: =M22/J22 -> 0.90601797 | AC22: =AB38 -> 0.90600599
B23: 18℃-飯糰 | C23: 一配壹號醬炙烤牛飯糰 | E23: 22.28 | F23: 1151 | G23: =E23*F23 -> 25644.28 | I23: 5 | J23: 3300 | K23: =J23/I23 -> 660 | L23: 5 | M23: =F23/V23*60 -> 2989.8 | N23: =M23/L23 -> 597.96 | O23: =L23-I23 -> 0 | P23: =N23-K23 -> -62.04 | Q23: =N23/K23 -> 0.906 | S23: 0.40069444 | T23: 0.41672454 | U23: 6 | V23: 23.098535 | AA23: =M23-J23 -> -310.2 | AB23: =M23/J23 -> 0.906
B24: 18℃-飯糰 | C24: 一配鹽蔥燒肉飯糰 | E24: 17.89 | F24: 3225 | G24: =E24*F24 -> 57695.25 | I24: 4 | J24: 3300 | K24: =J24/I24 -> 825 | L24: 4 | M24: =F24/V24*60 -> 2989.8 | N24: =M24/L24 -> 747.45 | O24: =L24-I24 -> 0 | P24: =N24-K24 -> -77.55 | Q24: =N24/K24 -> 0.906 | S24: 0.42013889 | T24: 0.46508102 | U24: 4.9166667 | V24: 64.720048 | AA24: =M24-J24 -> -310.2 | AB24: =M24/J24 -> 0.906
B38: 平均 | I38: =AVERAGE(I22:I37) -> 4 | J38: =AVERAGE(J22:J37) -> 3300 | K38: =J38/I38 -> 825 | L38: =AVERAGE(L22:L37) -> 4 | M38: =AVERAGE(M22:M37) -> 2989.8198 | N38: =M38/L38 -> 747.45494 | O38: =L38-I38 -> 0 | P38: =N38-K38 -> -77.545059 | Q38: =N38/K38 -> 0.90600599 | S38: 0.35694444 | T38: 0.46508102 | AA38: =M38-J38 -> -310.18023 | AB38: =M38/J38 -> 0.90600599
A39: GKK3600型 飯糰機 | B39: 18℃-飯糰 | C39: 一配山葵章魚飯糰 | E39: 25.2 | F39: 1527 | G39: =E39*F39 -> 38480.4 | I39: 3 | J39: 3600 | K39: =J39/I39 -> 1200 | L39: 3 | M39: =F39/V39*60 -> 3187.7889 | N39: =M39/L39 -> 1062.5963 | O39: =L39-I39 -> 0 | P39: =N39-K39 -> -137.4037 | Q39: =N39/K39 -> 0.88549692 | R39: =Q55 -> 0.88906945 | S39: 0.25 | T39: 0.2699537 | V39: 28.740925 | AA39: =M39-J39 -> -412.2111 | AB39: =M39/J39 -> 0.88549692 | AC39: =AB55 -> 0.88906945
B40: 18℃-飯糰 | C40: 一配熟成紅鮭飯糰 | E40: 25.03 | F40: 1485 | G40: =E40*F40 -> 37169.55 | I40: 5 | J40: 3600 | K40: =J40/I40 -> 720 | L40: 5 | M40: =F40/V40*60 -> 3193.4962 | N40: =M40/L40 -> 638.69923 | O40: =L40-I40 -> 0 | P40: =N40-K40 -> -81.300766 | Q40: =N40/K40 -> 0.88708227 | S40: 0.27986111 | T40: 0.29923611 | U40: 15 | V40: 27.900456 | AA40: =M40-J40 -> -406.50383 | AB40: =M40/J40 -> 0.88708227
B41: 18℃-飯糰 | C41: 一配蔬食鮪魚飯糰 | E41: 18.18 | F41: 1318 | G41: =E41*F41 -> 23961.24 | I41: 3 | J41: 3600 | K41: =J41/I41 -> 1200 | L41: 3 | M41: =F41/V41*60 -> 3186.2659 | N41: =M41/L41 -> 1062.0886 | O41: =L41-I41 -> 0 | P41: =N41-K41 -> -137.91136 | Q41: =N41/K41 -> 0.88507386 | S41: 0.30902778 | T41: 0.32626157 | U41: 15 | V41: 24.819021 | AA41: =M41-J41 -> -413.73409 | AB41: =M41/J41 -> 0.88507386
B42: 18℃-飯糰 | C42: 一配柚檸海灣貝飯糰 | E42: 23.72 | F42: 1542 | G42: =E42*F42 -> 36576.24 | I42: 5 | J42: 3600 | K42: =J42/I42 -> 720 | L42: 5 | M42: =F42/V42*60 -> 3194.8311 | N42: =M42/L42 -> 638.96623 | O42: =L42-I42 -> 0 | P42: =N42-K42 -> -81.03377 | Q42: =N42/K42 -> 0.8874531 | S42: 0.33611111 | T42: 0.35621528 | U42: 15 | V42: 28.959277 | AA42: =M42-J42 -> -405.16885 | AB42: =M42/J42 -> 0.8874531
B43: 18℃-飯糰 | C43: 一配鮪魚飯糰 | E43: 14.28 | F43: 7042 | G43: =E43*F43 -> 100559.76 | I43: 3 | J43: 3600 | K43: =J43/I43 -> 1200 | L43: 3 | M43: =F43/V43*60 -> 3190.0841 | N43: =M43/L43 -> 1063.3614 | O43: =L43-I43 -> 0 | P43: =N43-K43 -> -136.63864 | Q43: =N43/K43 -> 0.88613447 | S43: 0.36597222 | T43: 0.45793981 | U43: 15 | V43: 132.44792 | AA43: =M43-J43 -> -409.91591 | AB43: =M43/J43 -> 0.88613447
B44: 18℃-飯糰 | C44: 一配經典肉鬆飯糰 | E44: 14.03 | F44: 5015 | G44: =E44*F44 -> 70360.45 | I44: 3 | J44: 3000 | K44: =J44/I44 -> 1000 | L44: 3 | M44: =F44/V44*60 -> 2717.9922 | N44: =M44/L44 -> 905.99739 | O44: =L44-I44 -> 0 | P44: =N44-K44 -> -94.002611 | Q44: =N44/K44 -> 0.90599739 | S44: 0.46805556 | T44: 0.54493056 | U44: 14.566667 | V44: 110.70672 | AA44: =M44-J44 -> -282.00783 | AB44: =M44/J44 -> 0.90599739
B55: 平均 | I55: =AVERAGE(I39:I54) -> 3.6666667 | J55: =AVERAGE(J39:J54) -> 3500 | K55: =J55/I55 -> 954.54545 | L55: =AVERAGE(L39:L54) -> 3.6666667 | M55: =AVERAGE(M39:M54) -> 3111.7431 | N55: =M55/L55 -> 848.6572 | O55: =L55-I55 -> 0 | P55: =N55-K55 -> -105.88826 | Q55: =N55/K55 -> 0.88906945 | S55: 0.25 | T55: 0.54493056 | AA55: =M55-J55 -> -388.25694 | AB55: =M55/J55 -> 0.88906945
A56: GKK3600型 飯糰機2 | B56: 18℃-飯糰 | C56: 一配黑胡椒洋蔥豬飯糰 | E56: 17.07 | F56: 3029 | G56: =E56*F56 -> 51705.03 | I56: 3 | J56: 3300 | K56: =J56/I56 -> 1100 | L56: 3 | M56: =F56/V56*60 -> 2976.4588 | N56: =M56/L56 -> 992.15294 | O56: =L56-I56 -> 0 | P56: =N56-K56 -> -107.84706 | Q56: =N56/K56 -> 0.90195722 | R56: =Q72 -> 0.88992931 | S56: 0.25 | T56: 0.29239583 | V56: 61.059135 | AA56: =M56-J56 -> -323.54119 | AB56: =M56/J56 -> 0.90195722 | AC56: =AB72 -> 0.88992931
B57: 18℃-飯糰 | C57: 一配椒鹽檸檬鯖魚飯糰 | E57: 20.72 | F57: 2943 | G57: =E57*F57 -> 60978.96 | I57: 3 | J57: 3600 | K57: =J57/I57 -> 1200 | L57: 3 | M57: =F57/V57*60 -> 3197.198 | N57: =M57/L57 -> 1065.7327 | O57: =L57-I57 -> 0 | P57: =N57-K57 -> -134.26734 | Q57: =N57/K57 -> 0.88811055 | S57: 0.30277778 | T57: 0.34112269 | U57: 14.95 | V57: 55.229611 | AA57: =M57-J57 -> -402.80202 | AB57: =M57/J57 -> 0.88811055
B58: 18℃-飯糰 | C58: 一配北海道秋鮭親子飯糰 | E58: 24.82 | F58: 1829 | G58: =E58*F58 -> 45395.78 | I58: 5 | J58: 3600 | K58: =J58/I58 -> 720 | L58: 5 | M58: =F58/V58*60 -> 3200.7833 | N58: =M58/L58 -> 640.15667 | O58: =L58-I58 -> 0 | P58: =N58-K58 -> -79.843334 | Q58: =N58/K58 -> 0.88910648 | S58: 0.35138889 | T58: 0.37519676 | U58: 14.783333 | V58: 34.285357 | AA58: =M58-J58 -> -399.21667 | AB58: =M58/J58 -> 0.88910648
B59: 18℃-飯糰 | C59: 一配明太子龍蝦風味沙拉飯糰 | E59: 18.18 | F59: 2438 | G59: =E59*F59 -> 44322.84 | I59: 3 | J59: 3600 | K59: =J59/I59 -> 1200 | L59: 3 | M59: =F59/V59*60 -> 3193.4383 | N59: =M59/L59 -> 1064.4794 | O59: =L59-I59 -> 0 | P59: =N59-K59 -> -135.52057 | Q59: =N59/K59 -> 0.88706619 | S59: 0.38541667 | T59: 0.41722222 | U59: 14.716667 | V59: 45.806428 | AA59: =M59-J59 -> -406.56171 | AB59: =M59/J59 -> 0.88706619
B60: 18℃-飯糰 | C60: 一配贅沢鮭魚肚飯糰 | E60: 30 | F60: 2490 | G60: =E60*F60 -> 74700 | I60: 4 | J60: 3600 | K60: =J60/I60 -> 900 | L60: 4 | M60: =F60/V60*60 -> 3193.2 | N60: =M60/L60 -> 798.3 | O60: =L60-I60 -> 0 | P60: =N60-K60 -> -101.7 | Q60: =N60/K60 -> 0.887 | S60: 0.42708333 | T60: 0.45957176 | U60: 15 | V60: 46.786922 | AA60: =M60-J60 -> -406.8 | AB60: =M60/J60 -> 0.887
B61: 18℃-飯糰 | C61: 一配雞肉飯飯糰 | E61: 16.66 | F61: 5812 | G61: =E61*F61 -> 96827.92 | I61: 5 | J61: 3600 | K61: =J61/I61 -> 720 | L61: 5 | M61: =F61/V61*60 -> 3194.4158 | N61: =M61/L61 -> 638.88317 | O61: =L61-I61 -> 0 | P61: =N61-K61 -> -81.116834 | Q61: =N61/K61 -> 0.88733773 | S61: 0.46944444 | T61: 0.54524306 | U61: 15 | V61: 109.1655 | AA61: =M61-J61 -> -405.58417 | AB61: =M61/J61 -> 0.88733773
B72: 平均 | I72: =AVERAGE(I56:I71) -> 3.8333333 | J72: =AVERAGE(J56:J71) -> 3550 | K72: =J72/I72 -> 926.08696 | L72: =AVERAGE(L56:L71) -> 3.8333333 | M72: =AVERAGE(M56:M71) -> 3159.249 | N72: =M72/L72 -> 824.15192 | O72: =L72-I72 -> 0 | P72: =N72-K72 -> -101.93503 | Q72: =N72/K72 -> 0.88992931 | S72: 0.25 | T72: 0.54524306 | AA72: =M72-J72 -> -390.75096 | AB72: =M72/J72 -> 0.88992931
A73: 自動包裝機 (二配) | B73: 18℃-飯糰 | C73: 二配兩粒飯糰(鮪魚.焦糖鮭魚) | E73: 28.57 | F73: 1619 | G73: =E73*F73 -> 46254.83 | I73: 12 | J73: 3600 | K73: =J73/I73 -> 300 | L73: 12 | M73: =F73/V73*60 -> 3114.2226 | N73: =M73/L73 -> 259.51855 | O73: =L73-I73 -> 0 | P73: =N73-K73 -> -40.481452 | Q73: =N73/K73 -> 0.86506183 | R73: =Q89 -> 0.87918595 | S73: 0.70833333 | T73: 0.72998843 | V73: 31.192376 | AA73: =M73-J73 -> -485.77743 | AB73: =M73/J73 -> 0.86506183 | AC73: =AB89 -> 0.87918595
B74: 18℃-飯糰 | C74: 二配溏心蛋五目飯糰 | E74: 20.42 | F74: 622 | G74: =E74*F74 -> 12701.24 | I74: 13 | J74: 3600 | K74: =J74/I74 -> 276.92308 | L74: 13 | M74: =F74/V74*60 -> 3261.3038 | N74: =M74/L74 -> 250.86952 | O74: =L74-I74 -> 0 | P74: =N74-K74 -> -26.053556 | Q74: =N74/K74 -> 0.90591771 | S74: 0.73402778 | T74: 0.74196759 | U74: 5.8166667 | V74: 11.443276 | AA74: =M74-J74 -> -338.69623 | AB74: =M74/J74 -> 0.90591771
B75: 18℃-飯糰 | C75: 二配鮭魚毛豆炊飯飯糰 | E75: 18.92 | F75: 2406 | G75: =E75*F75 -> 45521.52 | I75: 6 | J75: 3600 | K75: =J75/I75 -> 600 | L75: 6 | M75: =F75/V75*60 -> 3261.3892 | N75: =M75/L75 -> 543.56487 | O75: =L75-I75 -> 0 | P75: =N75-K75 -> -56.435127 | Q75: =N75/K75 -> 0.90594146 | S75: 0.74513889 | T75: 0.77586806 | U75: 4.5666667 | V75: 44.263346 | AA75: =M75-J75 -> -338.61076 | AB75: =M75/J75 -> 0.90594146
B76: 18℃-飯糰 | C76: 二配柚香雞胸五穀飯糰 | E76: 17.71 | F76: 4374 | G76: =E76*F76 -> 77463.54 | I76: 6 | J76: 3600 | K76: =J76/I76 -> 600 | L76: 6 | M76: =F76/V76*60 -> 3023.3622 | N76: =M76/L76 -> 503.89369 | O76: =L76-I76 -> 0 | P76: =N76-K76 -> -96.106307 | Q76: =N76/K76 -> 0.83982282 | S76: 0.77916667 | T76: 0.83944444 | U76: 4.75 | V76: 86.804024 | AA76: =M76-J76 -> -576.63784 | AB76: =M76/J76 -> 0.83982282
B89: 平均 | I89: =AVERAGE(I73:I88) -> 9.25 | J89: =AVERAGE(J73:J88) -> 3600 | K89: =J89/I89 -> 389.18919 | L89: =AVERAGE(L73:L88) -> 9.25 | M89: =AVERAGE(M73:M88) -> 3165.0694 | N89: =M89/L89 -> 342.16967 | O89: =L89-I89 -> 0 | P89: =N89-K89 -> -47.01952 | Q89: =N89/K89 -> 0.87918595 | S89: 0.70833333 | T89: 0.83944444 | AA89: =M89-J89 -> -434.93056 | AB89: =M89/J89 -> 0.87918595
A90: (新) 3300型飯糰機 (二配) | B90: 18℃-飯糰 | C90: 二配鹽水G絲飯糰 | E90: 17.22 | F90: 1219 | G90: =E90*F90 -> 20991.18 | I90: 3 | J90: 3300 | K90: =J90/I90 -> 1100 | L90: 3 | M90: =F90/V90*60 -> 2989.4264 | N90: =M90/L90 -> 996.47547 | O90: =L90-I90 -> 0 | P90: =N90-K90 -> -103.52453 | Q90: =N90/K90 -> 0.90588679 | R90: =Q106 -> 0.89537247 | S90: 0.70833333 | T90: 0.7253125 | V90: 24.466232 | AA90: =M90-J90 -> -310.5736 | AB90: =M90/J90 -> 0.90588679 | AC90: =AB106 -> 0.89537247
B91: 18℃-飯糰 | C91: 二配壹號醬炙烤牛飯糰 | E91: 22.28 | F91: 1822 | G91: =E91*F91 -> 40594.16 | I91: 5 | J91: 3300 | K91: =J91/I91 -> 660 | L91: 5 | M91: =F91/V91*60 -> 2989.8 | N91: =M91/L91 -> 597.96 | O91: =L91-I91 -> 0 | P91: =N91-K91 -> -62.04 | Q91: =N91/K91 -> 0.906 | S91: 0.72847222 | T91: 0.75385417 | U91: 4.55 | V91: 36.564319 | AA91: =M91-J91 -> -310.2 | AB91: =M91/J91 -> 0.906
B92: 18℃-飯糰 | C92: 二配鹽蔥燒肉飯糰 | E92: 17.89 | F92: 1516 | G92: =E92*F92 -> 27121.24 | H92: 2 | I92: 4 | J92: 3300 | K92: =J92/I92 -> 825 | L92: 4 | M92: =F92/V92*60 -> 2989.8 | N92: =M92/L92 -> 747.45 | O92: =L92-I92 -> 0 | P92: =N92-K92 -> -77.55 | Q92: =N92/K92 -> 0.906 | S92: 0.75694444 | T92: 0.77806713 | U92: 5 | V92: 30.42344 | AA92: =M92-J92 -> -310.2 | AB92: =M92/J92 -> 0.906
B93: 18℃-飯糰 | C93: 二配大飯糰韓式蒜烤豬五花 | E93: 24.54 | F93: 1644 | G93: =E93*F93 -> 40343.76 | I93: 4 | J93: 3000 | K93: =J93/I93 -> 750 | L93: 4 | M93: =F93/V93*60 -> 2707.2757 | N93: =M93/L93 -> 676.81894 | O93: =L93-I93 -> 0 | P93: =N93-K93 -> -73.181063 | Q93: =N93/K93 -> 0.90242525 | S93: 0.78125 | T93: 0.80655093 | U93: 4.5833333 | V93: 36.435151 | AA93: =M93-J93 -> -292.72425 | AB93: =M93/J93 -> 0.90242525
B94: 18℃-飯糰 | C94: 二配大飯糰乾燒風味鮮蝦 | E94: 23.27 | F94: 1066 | G94: =E94*F94 -> 24805.82 | I94: 5 | J94: 3000 | K94: =J94/I94 -> 600 | L94: 5 | M94: =F94/V94*60 -> 2710.2287 | N94: =M94/L94 -> 542.04573 | O94: =L94-I94 -> 0 | P94: =N94-K94 -> -57.954268 | Q94: =N94/K94 -> 0.90340955 | S94: 0.80972222 | T94: 0.82609954 | U94: 4.5666667 | V94: 23.599485 | AA94: =M94-J94 -> -289.77134 | AB94: =M94/J94 -> 0.90340955
B95: 18℃-飯糰 | C95: 二配大飯糰泡菜鮪魚 | E95: 24.33 | F95: 4387 | G95: =E95*F95 -> 106735.71 | I95: 4 | J95: 3000 | K95: =J95/I95 -> 750 | L95: 4 | M95: =F95/V95*60 -> 2500.938 | N95: =M95/L95 -> 625.2345 | O95: =L95-I95 -> 0 | P95: =N95-K95 -> -124.7655 | Q95: =N95/K95 -> 0.833646 | S95: 0.82916667 | T95: 0.90224537 | U95: 5 | V95: 105.24851 | W95: 0.90224537 | X95: 0.94027778 | AA95: =M95-J95 -> -499.062 | AB95: =M95/J95 -> 0.833646
B96: 18℃-飯糰 | C96: 二配鹽蔥燒肉飯糰 | E96: 17.89 | F96: 4098 | G96: =E96*F96 -> 73313.22 | I96: 4 | J96: 3300 | K96: =J96/I96 -> 825 | L96: 4 | M96: =F96/V96*60 -> 2989.8 | N96: =M96/L96 -> 747.45 | O96: =L96-I96 -> 0 | P96: =N96-K96 -> -77.55 | Q96: =N96/K96 -> 0.906 | S96: 0.94027778 | T96: 0.99738426 | U96: 54.766667 | V96: 82.239615 | AA96: =M96-J96 -> -310.2 | AB96: =M96/J96 -> 0.906
B106: 平均 | I106: =AVERAGE(I90:I105) -> 4.1428571 | J106: =AVERAGE(J90:J105) -> 3171.4286 | K106: =J106/I106 -> 765.51724 | L106: =AVERAGE(L90:L105) -> 4.1428571 | M106: =AVERAGE(M90:M105) -> 2839.6098 | N106: =M106/L106 -> 685.42306 | O106: =L106-I106 -> 0 | P106: =N106-K106 -> -80.094179 | Q106: =N106/K106 -> 0.89537247 | S106: 0.70833333 | T106: 0.99738426 | AA106: =M106-J106 -> -331.81874 | AB106: =M106/J106 -> 0.89537247
...

Sheet 0630(4度C)
A1: 大溪廠日報分析 | C1: 總生產量 | D1: =SUM(F5:F157) -> 106614 | E1: 營業額 | F1: =SUM(G5:G157) -> 4882668.8 | G1: 出勤人數 | H1: =L21+L38+L55+L72+L89+L106+L123+L140+L157 -> 155.57738 | I1: 產線配置圖 | L1: 生產實績 | O1: 人時性差異分析 | S1: 日報登錄 | Y1: 合計次數 | Z1: 合計(時間/分) | AA1: 產線異常 分析說明(5分鐘以上) | AC1: 合計次數 | AD1: 合計(時間/分) | AE1: 產能差異分析
A2: 46203 | C2: 人時性 | D2: =AVERAGE(N21,N38,N55,N72,N89,N106,N123,N140,N157) -> 178.20773 | E2: 平均廠價 | F2: =F1/D1 -> 45.797633 | G2: 多次生產數 | H2: =COUNT(H5:H157) -> 3 | Y2: =SUM(Y21,Y38,Y55,Y72,Y89,Y106,Y123,Y140,Y157) -> 0 | Z2: =SUM(Z21,Z38,Z55,Z72,Z89,Z106,Z123,Z140,Z157) -> 0 | AC2: =SUM(AC21,AC38,AC55,AC72,AC89,AC106,AC123,AC140,AC157) -> 0 | AD2: =SUM(AD21,AD38,AD55,AD72,AD89,AD106,AD123,AD140,AD157) -> 0
A3: 線別 | B3: 品類 | C3: 品名 | E3: 廠價 | F3: 生產量 | G3: 營收 | H3: 多次 生產 | I3: 人數 | J3: 產能/時 | K3: 人時性 | L3: 人數 | M3: 產能/時 | N3: 人時性 | O3: 人數 | P3: 人時性 | Q3: 達成率 | R3: 達成率 平均 | S3: 生產時間 | U3: 換線、休息/分 | V3: 稼動時間/分 | W3: 休息時間 | Y3: 產線異常統計(5分鐘以上) | AA3: (屏榮回填) | AC3: 短暫停線統計(5分鐘以下) | AE3: 產能/時 | AF3: 達成率 | AG3: 達成率平均
S4: 開始 | T4: 結束 | W4: 開始 | X4: 結束 | Y4: 次數 | Z4: 時間/分 | AC4: 總次數 | AD4: 設備因素(次數)
A5: 便當二線 | B5: 微波小吃 | C5: 日式茶碗蒸 | E5: 19.7 | F5: 1836 | G5: =E5*F5 -> 36169.2 | H5: 2 | I5: 13 | J5: 1200 | K5: =J5/I5 -> 92.307692 | L5: 13 | M5: =F5/V5*60 -> 1083.1705 | N5: =M5/L5 -> 83.320807 | O5: =L5-I5 -> 0 | P5: =N5-K5 -> -8.9868854 | Q5: =N5/K5 -> 0.90264207 | R5: =Q21 -> 0.89758346 | S5: 0.16666667 | T5: 0.23729167 | V5: 101.70144 | AE5: =M5-J5 -> -116.82951 | AF5: =M5/J5 -> 0.90264207 | AG5: =AF21 -> 0.89758346
B6: 微波主食 | C6: 糖燻野郎三十天熟成牛飯 | E6: 56.43 | F6: 4744 | G6: =E6*F6 -> 267703.92 | I6: 24 | J6: 2000 | K6: =J6/I6 -> 83.333333 | L6: 24 | M6: =F6/V6*60 -> 1791.9403 | N6: =M6/L6 -> 74.664179 | O6: =L6-I6 -> 0 | P6: =N6-K6 -> -8.6691541 | Q6: =N6/K6 -> 0.89597015 | S6: 0.24097222 | T6: 0.35127315 | U6: 5.3 | V6: 158.84458 | AE6: =M6-J6 -> -208.0597 | AF6: =M6/J6 -> 0.89597015
B7: 便當 | C7: 香檸奶油魚排蔬滿盒 | E7: 77.35 | F7: 1039 | G7: =E7*F7 -> 80366.65 | I7: 25 | J7: 2000 | K7: =J7/I7 -> 80 | L7: 25 | M7: =F7/V7*60 -> 1787.8324 | N7: =M7/L7 -> 71.513295 | O7: =L7-I7 -> 0 | P7: =N7-K7 -> -8.4867053 | Q7: =N7/K7 -> 0.89391618 | S7: 0.35416667 | T7: 0.37837963 | U7: 5 | V7: 34.869041 | AE7: =M7-J7 -> -212.16763 | AF7: =M7/J7 -> 0.89391618
B8: 便當 | C8: 美式雞丁餐盒 | E8: 59.34 | F8: 1396 | G8: =E8*F8 -> 82838.64 | I8: 23 | J8: 2000 | K8: =J8/I8 -> 86.956522 | L8: 23 | M8: =F8/V8*60 -> 1791.0904 | N8: =M8/L8 -> 77.873495 | O8: =L8-I8 -> 0 | P8: =N8-K8 -> -9.0830267 | Q8: =N8/K8 -> 0.89554519 | S8: 0.38194444 | T8: 0.41440972 | U8: 5.1333333 | V8: 46.764809 | AE8: =M8-J8 -> -208.90961 | AF8: =M8/J8 -> 0.89554519
B9: 便當 | C9: 嫩烤香料雞胸排蔬滿盒 | E9: 77.34 | F9: 2363 | G9: =E9*F9 -> 182754.42 | I9: 23 | J9: 2000 | K9: =J9/I9 -> 86.956522 | L9: 23 | M9: =F9/V9*60 -> 1796.8192 | N9: =M9/L9 -> 78.122575 | O9: =L9-I9 -> 0 | P9: =N9-K9 -> -8.8339465 | Q9: =N9/K9 -> 0.89840961 | S9: 0.41736111 | T9: 0.47215278 | U9: 5 | V9: 78.906101 | W9: 0.47215278 | X9: 0.51111111 | AE9: =M9-J9 -> -203.18077 | AF9: =M9/J9 -> 0.89840961
B10: 便當 | C10: 健身G肉餐盒 | E10: 59.52 | F10: 5355 | G10: =E10*F10 -> 318729.6 | I10: 24 | J10: 2000 | K10: =J10/I10 -> 83.333333 | L10: 24 | M10: =F10/V10*60 -> 1796.0117 | N10: =M10/L10 -> 74.83382 | O10: =L10-I10 -> 0 | P10: =N10-K10 -> -8.4995136 | Q10: =N10/K10 -> 0.89800584 | S10: 0.51111111 | T10: 0.63533565 | U10: 56.1 | V10: 178.89639 | AE10: =M10-J10 -> -203.98833 | AF10: =M10/J10 -> 0.89800584
B11: 微波小吃 | C11: 日式茶碗蒸 | E11: 19.7 | F11: 2040 | G11: =E11*F11 -> 40188 | I11: 13 | J11: 1200 | K11: =J11/I11 -> 92.307692 | L11: 13 | M11: =F11/V11*60 -> 1083.1705 | N11: =M11/L11 -> 83.320807 | O11: =L11-I11 -> 0 | P11: =N11-K11 -> -8.9868854 | Q11: =N11/K11 -> 0.90264207 | S11: 0.63819444 | T11: 0.71666667 | U11: 5 | V11: 113.0016 | AE11: =M11-J11 -> -116.82951 | AF11: =M11/J11 -> 0.90264207
B21: 平均 | I21: =AVERAGE(I5:I20) -> 20.714286 | J21: =AVERAGE(J5:J20) -> 1771.4286 | K21: =J21/I21 -> 85.517241 | L21: =AVERAGE(L5:L20) -> 20.714286 | M21: =AVERAGE(M5:M20) -> 1590.005 | N21: =M21/L21 -> 76.758862 | O21: =L21-I21 -> 0 | P21: =N21-K21 -> -8.7583797 | Q21: =N21/K21 -> 0.89758346 | S21: 0.16666667 | T21: 0.71666667 | Y21: =SUM(Y5:Y20) -> 0 | Z21: =SUM(Z5:Z20) -> 0 | AC21: =SUM(AC5:AC20) -> 0 | AD21: =SUM(AD5:AD20) -> 0 | AE21: =M21-J21 -> -181.42358 | AF21: =M21/J21 -> 0.89758346
A22: 涼麵一線 | B22: 4℃-壽司手卷 | C22: 海陸雙拼壽司 | E22: 36.45 | F22: 2843 | G22: =E22*F22 -> 103627.35 | I22: 20 | J22: 2100 | K22: =J22/I22 -> 105 | L22: 20 | M22: =F22/V22*60 -> 1898.5283 | N22: =M22/L22 -> 94.926417 | O22: =L22-I22 -> 0 | P22: =N22-K22 -> -10.073583 | Q22: =N22/K22 -> 0.90406112 | R22: =Q38 -> 0.89043163 | S22: 0.16666667 | T22: 0.22905093 | V22: 89.84854 | AE22: =M22-J22 -> -201.47166 | AF22: =M22/J22 -> 0.90406112 | AG22: =AF38 -> 0.89738813
B23: 微波小吃 | C23: 馬鈴薯玉米濃湯 | E23: 31.72 | F23: 1876 | G23: =E23*F23 -> 59506.72 | I23: 22 | J23: 2000 | K23: =J23/I23 -> 90.909091 | L23: 22 | M23: =F23/V23*60 -> 1800.2072 | N23: =M23/L23 -> 81.827601 | O23: =L23-I23 -> 0 | P23: =N23-K23 -> -9.08149 | Q23: =N23/K23 -> 0.90010361 | S23: 0.23263889 | T23: 0.27605324 | U23: 5.1666667 | V23: 62.526135 | AE23: =M23-J23 -> -199.79278 | AF23: =M23/J23 -> 0.90010361
B24: 微波小吃 | C24: 三合一味噌湯 | E24: 34.79 | F24: 1985 | G24: =E24*F24 -> 69058.15 | I24: 11 | J24: 2000 | K24: =J24/I24 -> 181.81818 | L24: 11 | M24: =F24/V24*60 -> 1805.0362 | N24: =M24/L24 -> 164.0942 | O24: =L24-I24 -> 0 | P24: =N24-K24 -> -17.723978 | Q24: =N24/K24 -> 0.90251812 | S24: 0.27916667 | T24: 0.32497685 | U24: 5 | V24: 65.982055 | AE24: =M24-J24 -> -194.96376 | AF24: =M24/J24 -> 0.90251812
B25: 微波小吃 | C25: 蒸蛋湯 | E25: 33.2 | F25: 3274 | G25: =E25*F25 -> 108696.8 | I25: 11 | J25: 2000 | K25: =J25/I25 -> 181.81818 | L25: 11 | M25: =F25/V25*60 -> 1805.6739 | N25: =M25/L25 -> 164.15218 | O25: =L25-I25 -> 0 | P25: =N25-K25 -> -17.666006 | Q25: =N25/K25 -> 0.90283697 | S25: 0.32847222 | T25: 0.4040162 | U25: 5.0333333 | V25: 108.79041 | AE25: =M25-J25 -> -194.32607 | AF25: =M25/J25 -> 0.90283697
B26: 微波小吃 | C26: 越式牛肉寬粉 | E26: 51.44 | F26: 2913 | G26: =E26*F26 -> 149844.72 | I26: 19 | J26: 2000 | K26: =J26/I26 -> 105.26316 | L26: 19 | M26: =F26/V26*60 -> 1785.9152 | N26: =M26/L26 -> 93.995539 | O26: =L26-I26 -> 0 | P26: =N26-K26 -> -11.267619 | Q26: =N26/K26 -> 0.89295762 | S26: 0.40694444 | T26: 0.47489583 | U26: 5 | V26: 97.865786 | W26: 0.47489583 | X26: 0.51319444 | AE26: =M26-J26 -> -214.08475 | AF26: =M26/J26 -> 0.89295762
B27: 4℃-飯糰 | C27: 麻油雞飯糰 | E27: 29.97 | F27: 2567 | G27: =E27*F27 -> 76932.99 | I27: 21 | J27: 2790 | K27: =J27/I27 -> 132.85714 | L27: 22 | M27: =F27/V27*60 -> 2626.6346 | N27: =M27/L27 -> 119.39248 | O27: =L27-I27 -> 1 | P27: =N27-K27 -> -13.46466 | Q27: =N27/K27 -> 0.89865309 | S27: 0.51319444 | T27: 0.55391204 | U27: 55.15 | V27: 58.637771 | AE27: =M27-J27 -> -163.36538 | AF27: =M27/J27 -> 0.9414461
B28: 便當 | C28: 地中海布格麥烤魚餐盒 | E28: 63.92 | F28: 3965 | G28: =E28*F28 -> 253442.8 | I28: 24 | J28: 2000 | K28: =J28/I28 -> 83.333333 | L28: 24 | M28: =F28/V28*60 -> 1640.1137 | N28: =M28/L28 -> 68.33807 | O28: =L28-I28 -> 0 | P28: =N28-K28 -> -14.995263 | Q28: =N28/K28 -> 0.82005684 | S28: 0.55763889 | T28: 0.65836806 | U28: 5.3666667 | V28: 145.05092 | AE28: =M28-J28 -> -359.88631 | AF28: =M28/J28 -> 0.82005684
B38: 平均 | I38: =AVERAGE(I22:I37) -> 18.285714 | J38: =AVERAGE(J22:J37) -> 2127.1429 | K38: =J38/I38 -> 116.32813 | L38: =AVERAGE(L22:L37) -> 18.428571 | M38: =AVERAGE(M22:M37) -> 1908.8728 | N38: =M38/L38 -> 103.58224 | O38: =L38-I38 -> 0.14285714 | P38: =N38-K38 -> -12.745882 | Q38: =N38/K38 -> 0.89043163 | S38: 0.16666667 | T38: 0.65836806 | Y38: =SUM(Y22:Y37) -> 0 | Z38: =SUM(Z22:Z37) -> 0 | AC38: =SUM(AC22:AC37) -> 0 | AD38: =SUM(AD22:AD37) -> 0 | AE38: =M38-J38 -> -218.2701 | AF38: =M38/J38 -> 0.89738813
A39: 涼麵二線 | B39: 便當 | C39: 香腸腿排雙拼便當 | E39: 53.76 | F39: 2996 | G39: =E39*F39 -> 161064.96 | I39: 20 | J39: 2000 | K39: =J39/I39 -> 100 | L39: 20 | M39: =F39/V39*60 -> 1788.1673 | N39: =M39/L39 -> 89.408363 | O39: =L39-I39 -> 0 | P39: =N39-K39 -> -10.591637 | Q39: =N39/K39 -> 0.89408363 | R39: =Q55 -> 0.8833612 | S39: 0.16666667 | T39: 0.23646991 | V39: 100.52751 | AE39: =M39-J39 -> -211.83275 | AF39: =M39/J39 -> 0.89408363 | AG39: =AF55 -> 0.8833612
B40: 便當 | C40: 蔬活腿排補力餐盒 | E40: 71.55 | F40: 2366 | G40: =E40*F40 -> 169287.3 | I40: 22 | J40: 2000 | K40: =J40/I40 -> 90.909091 | L40: 22 | M40: =F40/V40*60 -> 1786.7377 | N40: =M40/L40 -> 81.215351 | O40: =L40-I40 -> 0 | P40: =N40-K40 -> -9.69374 | Q40: =N40/K40 -> 0.89336886 | S40: 0.23958333 | T40: 0.29475694 | U40: 5 | V40: 79.452064 | AE40: =M40-J40 -> -213.26228 | AF40: =M40/J40 -> 0.89336886
B41: 便當 | C41: 地中海布格麥烤魚餐盒 | E41: 63.92 | F41: 1525 | G41: =E41*F41 -> 97478 | H41: 2 | I41: 24 | J41: 2000 | K41: =J41/I41 -> 83.333333 | L41: 24 | M41: =F41/V41*60 -> 1630 | N41: =M41/L41 -> 67.916667 | O41: =L41-I41 -> 0 | P41: =N41-K41 -> -15.416667 | Q41: =N41/K41 -> 0.815 | S41: 0.29861111 | T41: 0.33759259 | U41: 5.55 | V41: 56.134969 | AE41: =M41-J41 -> -370 | AF41: =M41/J41 -> 0.815
B42: 便當 | C42: 烤蛋白餐盒 | E42: 58.67 | F42: 1174 | G42: =E42*F42 -> 68878.58 | H42: 2 | I42: 23 | J42: 2000 | K42: =J42/I42 -> 86.956522 | L42: 23 | M42: =F42/V42*60 -> 1787.1744 | N42: =M42/L42 -> 77.703233 | O42: =L42-I42 -> 0 | P42: =N42-K42 -> -9.2532891 | Q42: =N42/K42 -> 0.89358718 | S42: 0.34097222 | T42: 0.36833333 | U42: 4.8666667 | V42: 39.414174 | AE42: =M42-J42 -> -212.82565 | AF42: =M42/J42 -> 0.89358718
B43: 便當 | C43: 海陸雙拼肉肉餐盒 | E43: 59.54 | F43: 2978 | G43: =E43*F43 -> 177310.12 | I43: 23 | J43: 2000 | K43: =J43/I43 -> 86.956522 | L43: 23 | M43: =F43/V43*60 -> 1794.6576 | N43: =M43/L43 -> 78.028591 | O43: =L43-I43 -> 0 | P43: =N43-K43 -> -8.9279303 | Q43: =N43/K43 -> 0.8973288 | S43: 0.37152778 | T43: 0.44065972 | U43: 4.6 | V43: 99.562167 | W43: 0.44065972 | X43: 0.47916667 | AE43: =M43-J43 -> -205.3424 | AF43: =M43/J43 -> 0.8973288
B44: 便當 | C44: 懷舊滷雙拼便當 | E44: 61.09 | F44: 3279 | G44: =E44*F44 -> 200314.11 | I44: 20 | J44: 2000 | K44: =J44/I44 -> 100 | L44: 20 | M44: =F44/V44*60 -> 1793.1456 | N44: =M44/L44 -> 89.657279 | O44: =L44-I44 -> 0 | P44: =N44-K44 -> -10.342721 | Q44: =N44/K44 -> 0.89657279 | S44: 0.47916667 | T44: 0.5553588 | U44: 55.45 | V44: 109.71781 | AE44: =M44-J44 -> -206.85441 | AF44: =M44/J44 -> 0.89657279
B45: 便當 | C45: 烤蛋白餐盒 | E45: 58.67 | F45: 2927 | G45: =E45*F45 -> 171727.09 | I45: 23 | J45: 2000 | K45: =J45/I45 -> 86.956522 | L45: 23 | M45: =F45/V45*60 -> 1787.1744 | N45: =M45/L45 -> 77.703233 | O45: =L45-I45 -> 0 | P45: =N45-K45 -> -9.2532891 | Q45: =N45/K45 -> 0.89358718 | S45: 0.55902778 | T45: 0.62726852 | U45: 5.2833333 | V45: 98.266853 | AE45: =M45-J45 -> -212.82565 | AF45: =M45/J45 -> 0.89358718
B55: 平均 | I55: =AVERAGE(I39:I54) -> 22.142857 | J55: =AVERAGE(J39:J54) -> 2000 | K55: =J55/I55 -> 90.322581 | L55: =AVERAGE(L39:L54) -> 22.142857 | M55: =AVERAGE(M39:M54) -> 1766.7224 | N55: =M55/L55 -> 79.787464 | O55: =L55-I55 -> 0 | P55: =N55-K55 -> -10.535117 | Q55: =N55/K55 -> 0.8833612 | S55: 0.16666667 | T55: 0.62726852 | Y55: =SUM(Y39:Y54) -> 0 | Z55: =SUM(Z39:Z54) -> 0 | AC55: =SUM(AC39:AC54) -> 0 | AD55: =SUM(AD39:AD54) -> 0 | AE55: =M55-J55 -> -233.27759 | AF55: =M55/J55 -> 0.8833612
A56: 涼麵三線 | B56: 季節調理麵 | C56: 和風涓絲冷麵 | E56: 28.86 | F56: 2595 | G56: =E56*F56 -> 74891.7 | I56: 19 | J56: 3600 | K56: =J56/I56 -> 189.47368 | L56: 19 | M56: =F56/V56*60 -> 3191.1179 | N56: =M56/L56 -> 167.95358 | O56: =L56-I56 -> 0 | P56: =N56-K56 -> -21.520108 | Q56: =N56/K56 -> 0.88642165 | R56: =Q72 -> 0.89551044 | S56: 0.16666667 | T56: 0.20054398 | V56: 48.791678 | AE56: =M56-J56 -> -408.88206 | AF56: =M56/J56 -> 0.88642165 | AG56: =AF72 -> 0.89551044
B57: 季節調理麵 | C57: 台式麻醬涼麵 | E57: 31.11 | F57: 3506 | G57: =E57*F57 -> 109071.66 | I57: 19 | J57: 3600 | K57: =J57/I57 -> 189.47368 | L57: 19 | M57: =F57/V57*60 -> 3186.7559 | N57: =M57/L57 -> 167.72399 | O57: =L57-I57 -> 0 | P57: =N57-K57 -> -21.749691 | Q57: =N57/K57 -> 0.88520996 | S57: 0.20347222 | T57: 0.24930556 | U57: 5 | V57: 66.010705 | AE57: =M57-J57 -> -413.24413 | AF57: =M57/J57 -> 0.88520996
B58: 季節調理麵 | C58: 鰹魚烏龍冷麵 | E58: 38.99 | F58: 1509 | G58: =E58*F58 -> 58835.91 | I58: 19 | J58: 3600 | K58: =J58/I58 -> 189.47368 | L58: 19 | M58: =F58/V58*60 -> 3186.8034 | N58: =M58/L58 -> 167.7265 | O58: =L58-I58 -> 0 | P58: =N58-K58 -> -21.747188 | Q58: =N58/K58 -> 0.88522318 | S58: 0.25347222 | T58: 0.27319444 | U58: 6 | V58: 28.410915 | AE58: =M58-J58 -> -413.19656 | AF58: =M58/J58 -> 0.88522318
B59: 季節調理麵 | C59: 嘉義崇文白醋涼麵 | E59: 35.89 | F59: 5125 | G59: =E59*F59 -> 183936.25 | I59: 19 | J59: 3600 | K59: =J59/I59 -> 189.47368 | L59: 19 | M59: =F59/V59*60 -> 3184.8062 | N59: =M59/L59 -> 167.62138 | O59: =L59-I59 -> 0 | P59: =N59-K59 -> -21.852304 | Q59: =N59/K59 -> 0.8846684 | S59: 0.27638889 | T59: 0.3434375 | U59: 4.6 | V59: 96.552185 | AE59: =M59-J59 -> -415.19378 | AF59: =M59/J59 -> 0.8846684
B60: 季節調理麵 | C60: 招牌雞絲胡麻涼麵 | E60: 43.96 | F60: 2007 | G60: =E60*F60 -> 88227.72 | I60: 24 | J60: 3600 | K60: =J60/I60 -> 150 | L60: 24 | M60: =F60/V60*60 -> 3261.3448 | N60: =M60/L60 -> 135.88937 | O60: =L60-I60 -> 0 | P60: =N60-K60 -> -14.110633 | Q60: =N60/K60 -> 0.90592911 | S60: 0.34722222 | T60: 0.3728588 | U60: 5.45 | V60: 36.923419 | AE60: =M60-J60 -> -338.65519 | AF60: =M60/J60 -> 0.90592911
B61: 季節調理麵 | C61: 日式胡麻雞絲冷麵 | E61: 46.93 | F61: 1744 | G61: =E61*F61 -> 81845.92 | I61: 24 | J61: 3600 | K61: =J61/I61 -> 150 | L61: 24 | M61: =F61/V61*60 -> 3258.7809 | N61: =M61/L61 -> 135.78254 | O61: =L61-I61 -> 0 | P61: =N61-K61 -> -14.217463 | Q61: =N61/K61 -> 0.90521692 | S61: 0.37638889 | T61: 0.39868056 | U61: 5.0833333 | V61: 32.110167 | AE61: =M61-J61 -> -341.21911 | AF61: =M61/J61 -> 0.90521692
B62: 季節調理麵 | C62: 大滿足香辣涼麵 | E62: 38.48 | F62: 5268 | G62: =E62*F62 -> 202712.64 | I62: 20 | J62: 3600 | K62: =J62/I62 -> 180 | L62: 20 | M62: =F62/V62*60 -> 3263.0765 | N62: =M62/L62 -> 163.15383 | O62: =L62-I62 -> 0 | P62: =N62-K62 -> -16.846174 | Q62: =N62/K62 -> 0.90641015 | S62: 0.40277778 | T62: 0.47003472 | U62: 5.9 | V62: 96.865641 | W62: 0.47003472 | X62: 0.50833333 | AE62: =M62-J62 -> -336.92348 | AF62: =M62/J62 -> 0.90641015
B63: 季節調理麵 | C63: 大滿足麻醬涼麵 | E63: 37.8 | F63: 6624 | G63: =E63*F63 -> 250387.2 | I63: 21 | J63: 3600 | K63: =J63/I63 -> 171.42857 | L63: 21 | M63: =F63/V63*60 -> 3258.0149 | N63: =M63/L63 -> 155.14357 | O63: =L63-I63 -> 0 | P63: =N63-K63 -> -16.285003 | Q63: =N63/K63 -> 0.90500415 | S63: 0.50833333 | T63: 0.59304398 | U63: 55.15 | V63: 121.98839 | AE63: =M63-J63 -> -341.98506 | AF63: =M63/J63 -> 0.90500415
B72: 平均 | I72: =AVERAGE(I56:I71) -> 20.625 | J72: =AVERAGE(J56:J71) -> 3600 | K72: =J72/I72 -> 174.54545 | L72: =AVERAGE(L56:L71) -> 20.625 | M72: =AVERAGE(M56:M71) -> 3223.8376 | N72: =M72/L72 -> 156.30728 | O72: =L72-I72 -> 0 | P72: =N72-K72 -> -18.238178 | Q72: =N72/K72 -> 0.89551044 | S72: 0.16666667 | T72: 0.59304398 | Y72: =SUM(Y56:Y71) -> 0 | Z72: =SUM(Z56:Z71) -> 0 | AC72: =SUM(AC56:AC71) -> 0 | AD72: =SUM(AD56:AD71) -> 0 | AE72: =M72-J72 -> -376.16242 | AF72: =M72/J72 -> 0.89551044
A73: 自動包裝機 | B73: 4℃-壽司手卷 | C73: 韓式辣炒豬肉飯卷 | E73: 27.05 | F73: 1267 | G73: =E73*F73 -> 34272.35 | I73: 5 | J73: 3273 | K73: =J73/I73 -> 654.6 | L73: 6 | M73: =F73/V73*60 -> 2961.6419 | N73: =M73/L73 -> 493.60698 | O73: =L73-I73 -> 1 | P73: =N73-K73 -> -160.99302 | Q73: =N73/K73 -> 0.75405894 | R73: =Q89 -> 0.82334947 | S73: 0.39930556 | T73: 0.41712963 | U73: 5 | V73: 25.668195 | AE73: =M73-J73 -> -311.35812 | AF73: =M73/J73 -> 0.90487072 | AG73: =AF89 -> 0.90568442
B74: 4℃-壽司手卷 | C74: 厚香料優格咖哩烤雞飯卷 | E74: 27.05 | F74: 2132 | G74: =E74*F74 -> 57670.6 | I74: 5 | J74: 3273 | K74: =J74/I74 -> 654.6 | L74: 5 | M74: =F74/V74*60 -> 2966.9683 | N74: =M74/L74 -> 593.39366 | O74: =L74-I74 -> 0 | P74: =N74-K74 -> -61.206335 | Q74: =N74/K74 -> 0.90649811 | S74: 0.42013889 | T74: 0.45006944 | U74: 5 | V74: 43.114717 | AE74: =M74-J74 -> -306.03168 | AF74: =M74/J74 -> 0.90649811
B89: 平均 | I89: =AVERAGE(I73:I88) -> 5 | J89: =AVERAGE(J73:J88) -> 3273 | K89: =J89/I89 -> 654.6 | L89: =AVERAGE(L73:L88) -> 5.5 | M89: =AVERAGE(M73:M88) -> 2964.3051 | N89: =M89/L89 -> 538.96456 | O89: =L89-I89 -> 0.5 | P89: =N89-K89 -> -115.63544 | Q89: =N89/K89 -> 0.82334947 | S89: 0.25 | T89: 0.45006944 | Y89: =SUM(Y73:Y88) -> 0 | Z89: =SUM(Z73:Z88) -> 0 | AC89: =SUM(AC73:AC88) -> 0 | AD89: =SUM(AD73:AD88) -> 0 | AE89: =M89-J89 -> -308.6949 | AF89: =M89/J89 -> 0.90568442
...

Sheet 0629
B1: 屏榮 大溪廠組合室生產人時性分析
B3: 日期 | C3: 115.06.29星期一 | E3: 訂單量 | F3: ='0629(18度C)'!D1+'0629(4度C)'!D1 -> 234628 | H3: 營業額 | I3: ='0629(18度C)'!F1+'0629(4度C)'!F1 -> 7280769.8
B4: 人時性 | C4: 項目 | E4: ➀ | G4: ➁ | I4: ➂ | K4: ④ | M4: ⑤ | O4: 異常停線 | Q4: 短暫停線
C5: 組合室 | E5: 全溫層 | G5: 4度C-各編組展開(一配) | I5: 4度C-各編組展開(二配) | K5: 18度C-各編組展開(一配) | M5: 18度C-各編組展開(二配) | O5: 合計次數 | P5: 時間 | Q5: 合計次數 | R5: 設備次數
C6: 排關平均 | E6: =AVERAGE(D14:O14,D32:X32) -> 466.95569 | F6: =AVERAGE(#REF!,D14:K14) -> #REF! | G6: =AVERAGE(D14:K14) -> 260.16997 | I6: =AVERAGE(L14:O14) -> 94.858523 | K6: =AVERAGE(D32:O32) -> 758.22628 | M6: =AVERAGE(P32:X32) -> 764.93655 | O6: ='0629(4度C)'!Y2 -> 0 | P6: ='0629(4度C)'!Z2 -> 0 | Q6: ='0629(4度C)'!AC2 -> 0 | R6: ='0629(4度C)'!AD2 -> 0
C7: 實績平均 | E7: =AVERAGE(D15:O15,D33:X33) -> 413.70392 | F7: =AVERAGE(#REF!,D15:K15) -> #REF! | G7: =AVERAGE(D15:K15) -> 226.07692 | I7: =AVERAGE(L15:O15) -> 85.550767 | K7: =AVERAGE(D33:O33) -> 676.79445 | M7: =AVERAGE(P33:X33) -> 678.16875
C8: 達成率平均 | E8: =AVERAGE(D16:O16,D34:X34) -> 0.8902702 | F8: =AVERAGE(D16:K16,#REF!) -> #REF! | G8: =AVERAGE(D16:K16) -> 0.88791885 | I8: =AVERAGE(L16:O16) -> 0.90226923 | K8: =AVERAGE(D34:O34) -> 0.89066189 | M8: =AVERAGE(P34:X34) -> 0.88440627
O9: ※現行日本鮮食廠以達成率80%為基本(即為現行KPI)
B11: 溫層 | D11: ➁4度C-各編組展開 | L11: ➂4度C-各編組展開
B12: 編組 | D12: 1 | E12: 2 | F12: 3 | G12: 4 | H12: 5 | I12: 6 | J12: 7 | K12: 8 | L12: 1 | M12: 2 | N12: 3 | O12: 4
D13: 便當一線 | E13: 便當二線 | F13: 涼麵一線 | G13: 涼麵二線 | H13: 涼麵三線 | I13: 自動包裝機 | J13: 自動包裝機2 | K13: 自動包裝機3 | L13: 便當一線 | M13: 便當二線 | N13: 涼麵一線 | O13: 涼麵二線
B14: 人時性 | C14: 排關 | D14: - | E14: 91.357143 | F14: 115.51724 | G14: 91.666667 | H14: 174.54545 | I14: 654.6 | J14: 433.33333 | K14: - | L14: - | M14: 90.47619 | N14: 86.956522 | O14: 107.14286
C15: 實績 | D15: - | E15: 82.842186 | F15: 104.11396 | G15: 82.118412 | H15: 156.31382 | I15: 539.179 | J15: 391.8941 | K15: - | L15: - | M15: 82.899647 | N15: 77.933995 | O15: 95.818659
C16: 達成率 | D16: - | E16: =E15/E14 -> 0.90679484 | F16: =F15/F14 -> 0.90128506 | G16: =G15/G14 -> 0.89583722 | H16: =H15/H14 -> 0.89554794 | I16: =I15/I14 -> 0.82367706 | J16: =J15/J14 -> 0.90437101 | K16: - | L16: - | M16: =M15/M14 -> 0.91625926 | N16: =N15/N14 -> 0.89624095 | O16: =O15/O14 -> 0.89430749
B17: 作業 時間 | C17: 開始 | D17: - | E17: 0.16666667 | F17: 0.16666667 | G17: 0.16666667 | H17: 0.16666667 | I17: 0.40138889 | J17: 0.25 | K17: - | L17: - | M17: 0.70833333 | N17: 0.70833333 | O17: 0.70833333
C18: 結束 | D18: - | E18: 0.61135417 | F18: 0.61002315 | G18: 0.67137731 | H18: 0.62148148 | I18: 0.45396991 | J18: 0.35236111 | K18: - | L18: - | M18: 0.80288194 | N18: 0.85136574 | O18: 0.8558912
B19: 產線異常 (5分鐘以上) | C19: 次數
C20: 時間/分
B21: 短暫停線 (5分鐘以下) | C21: 次數
C22: 設備次數
B23: 配置人數 | D23: - | E23: 24 | F23: 16.571429 | G23: 20.571429 | H23: 20.625 | I23: 5.5 | J23: 6 | K23: - | L23: - | M23: 20.5 | N23: 23 | O23: 18.666667
B24: 主要應用設備 | D24: L型封口機 | E24: ET-55 | F24: ET-55 | G24: ET-55 | H24: ET-600 | I24: 伺服包裝機 | J24: 伺服包裝機 | K24: 伺服包裝機 | L24: L型封口機 | M24: ET-55 | N24: ET-55 | O24: ET-55
B25: 次要應用設備 | D25: 伺服包裝機 | H25: 伺服包裝機
B26: 備註 | H26: 涼麵+烤飯糰 | I26: 大口飯糰線 | K26: 烤飯糰+手卷
B29: 溫層 | D29: ➃18度C-各編組展開 (一配) | P29: ⑤18度C-各編組展開 (二配)
B30: 編組 | D30: 1 | E30: 2 | F30: 3 | G30: 4 | H30: 5 | I30: 6 | J30: 7 | K30: 8 | L30: 9 | M30: 10 | N30: 11 | O30: 12 | P30: 1 | Q30: 2 | R30: 3 | S30: 4 | T30: 5 | U30: 6 | V30: 7 | W30: 8 | X30: 9
D31: 便當一線 | E31: 涼麵一線 | F31: 涼麵三線 | G31: 自動包裝機 | H31: 自動包裝機2 | I31: 自動包裝機3 | J31: 味付飯糰線B | K31: (舊) 3300型飯糰線 | L31: 3000型飯糰線 | M31: (新) 3300型飯糰機 | N31: GKK3600型 飯糰機 | O31: GKK3600型 飯糰機2 | P31: 自動包裝機 | Q31: 自動包裝機2 | R31: 自動包裝機3 | S31: 味付飯糰線B | T31: (舊) 3300型飯糰線 | U31: 3000型飯糰線 | V31: (新) 3300型飯糰機 | W31: GKK3600型 飯糰機 | X31: GKK3600型 飯糰機2
B32: 人時性 | C32: 排關 | D32: - | E32: - | F32: - | G32: 327.27273 | H32: - | I32: - | J32: - | K32: - | L32: - | M32: 825 | N32: 954.54545 | O32: 926.08696 | P32: 389.18919 | Q32: - | R32: - | S32: - | T32: - | U32: - | V32: 755.17241 | W32: 1015.3846 | X32: 900
C33: 實績 | D33: - | E33: - | F33: - | G33: 287.42072 | H33: - | I33: - | J33: - | K33: - | L33: - | M33: 747.12869 | N33: 848.55084 | O33: 824.07758 | P33: 340.43988 | Q33: - | R33: - | S33: - | T33: - | U33: - | V33: 665.43867 | W33: 908.67165 | X33: 798.1248
C34: 達成率 | D34: - | E34: - | F34: - | G34: =G33/G32 -> 0.87822996 | H34: - | I34: - | J34: - | K34: - | L34: - | M34: =M33/M32 -> 0.90561053 | N34: =N33/N32 -> 0.88895802 | O34: =O33/O32 -> 0.88984903 | P34: =P33/P32 -> 0.87474136 | Q34: - | R34: - | S34: - | T34: - | U34: - | V34: =V33/V32 -> 0.88117449 | W34: =W33/W32 -> 0.8949039 | X34: =X33/X32 -> 0.88680534
B35: 作業 時間 | C35: 開始 | D35: - | E35: - | F35: - | G35: 0.25 | H35: - | I35: - | J35: - | K35: - | L35: - | M35: 0.37013889 | N35: 0.25 | O35: 0.25 | P35: 0.70833333 | Q35: - | R35: - | S35: - | T35: - | U35: - | V35: 0.70833333 | W35: 0.79861111 | X35: 0.75972222
C36: 結束 | D36: - | E36: - | F36: - | G36: 0.39818287 | H36: - | I36: - | J36: - | K36: - | L36: - | M36: 0.48037037 | N36: 0.5499537 | O36: 0.54914352 | P36: 0.8559838 | Q36: - | R36: - | S36: - | T36: - | U36: - | V36: 1.0225694 | W36: 1.1878704 | X36: 1.1919213
B37: 配置人數 | D37: - | E37: - | F37: - | G37: 11 | H37: - | I37: - | J37: - | K37: - | L37: - | M37: 4 | N37: 3.6666667 | O37: 3.8333333 | P37: 9.25 | Q37: - | R37: - | S37: - | T37: - | U37: - | V37: 4.1428571 | W37: 3.25 | X37: 4
B38: 主要應用設備 | D38: 伺服包裝機 | E38: ET-55 | F38: ET-600 | G38: 夾心型 | H38: 伺服包裝機 | I38: 伺服包裝機 | J38: 夾心型 | K38: 3300型 | L38: 3300型 | M38: 3300型 | N38: GKK | O38: GKK | P38: 夾心型 | Q38: 伺服包裝機 | R38: 伺服包裝機 | S38: 夾心型 | T38: 3300型 | U38: 3300型 | V38: 3300型 | W38: GKK | X38: GKK
B39: 次要應用設備
B40: 備註

Sheet 0629(18度C)
A1: 大溪廠日報分析 | C1: 總生產量 | D1: =SUM(F5:F140) -> 127625 | E1: 營業額 | F1: =SUM(G5:G140) -> 2496786.8 | G1: 出勤人數 | H1: =L21+L38+L55+L72+L89+L106+L123+L140 -> 43.142857 | I1: 產線配置圖 | L1: 生產實績 | O1: 人時性差異分析 | S1: 日報登錄 | Y1: 分析說明 | AA1: 產能差異分析
A2: 46202 | C2: 人時性 | D2: =AVERAGE(N21,N38,N55,N72,N89,N106,N123,N140) -> 677.4816 | E2: 平均廠價 | F2: =F1/D1 -> 19.563461 | G2: 多次生產數 | H2: =COUNT(H5:H140) -> 11
A3: 線別 | B3: 品類 | C3: 品名 | E3: 廠價 | F3: 生產量 | G3: 營收 | H3: 多次 生產 | I3: 人數 | J3: 產能/時 | K3: 人時性 | L3: 人數 | M3: 產能/時 | N3: 人時性 | O3: 人數 | P3: 人時性 | Q3: 達成率 | R3: 達成率 平均 | S3: 生產時間 | U3: 換線、休息/分 | V3: 稼動時間/分 | W3: 休息時間 | Y3: (屏榮回填) | AA3: 產能/時 | AB3: 達成率 | AC3: 達成率平均
S4: 開始 | T4: 結束 | W4: 開始 | X4: 結束
A5: 自動包裝機 | B5: 18℃-壽司手卷 | C5: 一配長野稻荷壽司 | E5: 25.64 | F5: 1860 | G5: =E5*F5 -> 47690.4 | I5: 10 | J5: 3600 | K5: =J5/I5 -> 360 | L5: 10 | M5: =F5/V5*60 -> 3212.2096 | N5: =M5/L5 -> 321.22096 | O5: =L5-I5 -> 0 | P5: =N5-K5 -> -38.779045 | Q5: =N5/K5 -> 0.89228043 | R5: =Q21 -> 0.87822996 | S5: 0.25 | T5: 0.27412037 | V5: 34.742441 | AA5: =M5-J5 -> -387.79045 | AB5: =M5/J5 -> 0.89228043 | AC5: =AB21 -> 0.87822996
B6: 18℃-壽司手卷 | C6: 一配經典人氣雙手卷 | E6: 29.52 | F6: 3120 | G6: =E6*F6 -> 92102.4 | I6: 11 | J6: 3600 | K6: =J6/I6 -> 327.27273 | L6: 11 | M6: =F6/V6*60 -> 3160.2841 | N6: =M6/L6 -> 287.29855 | O6: =L6-I6 -> 0 | P6: =N6-K6 -> -39.974173 | Q6: =N6/K6 -> 0.87785669 | S6: 0.27708333 | T6: 0.31821759 | U6: 5 | V6: 59.235181 | AA6: =M6-J6 -> -439.7159 | AB6: =M6/J6 -> 0.87785669
B7: 18℃-壽司手卷 | C7: 一配鮭鮪海饌雙手卷 | E7: 29.85 | F7: 3544 | G7: =E7*F7 -> 105788.4 | I7: 11 | J7: 3600 | K7: =J7/I7 -> 327.27273 | L7: 11 | M7: =F7/V7*60 -> 3159.9568 | N7: =M7/L7 -> 287.2688 | O7: =L7-I7 -> 0 | P7: =N7-K7 -> -40.003931 | Q7: =N7/K7 -> 0.87776577 | S7: 0.32222222 | T7: 0.36894676 | U7: 5.7666667 | V7: 67.29206 | AA7: =M7-J7 -> -440.04324 | AB7: =M7/J7 -> 0.87776577
B8: 18℃-飯糰 | C8: 一配兩粒飯糰(鮪魚.焦糖鮭魚) | E8: 28.57 | F8: 1889 | G8: =E8*F8 -> 53968.73 | I8: 12 | J8: 3600 | K8: =J8/I8 -> 300 | L8: 12 | M8: =F8/V8*60 -> 3114.0611 | N8: =M8/L8 -> 259.50509 | O8: =L8-I8 -> 0 | P8: =N8-K8 -> -40.49491 | Q8: =N8/K8 -> 0.86501697 | S8: 0.37291667 | T8: 0.39818287 | U8: 5.7166667 | V8: 36.396203 | AA8: =M8-J8 -> -485.93892 | AB8: =M8/J8 -> 0.86501697
B21: 平均 | I21: =AVERAGE(I5:I20) -> 11 | J21: =AVERAGE(J5:J20) -> 3600 | K21: =J21/I21 -> 327.27273 | L21: =AVERAGE(L5:L20) -> 11 | M21: =AVERAGE(M5:M20) -> 3161.6279 | N21: =M21/L21 -> 287.42072 | O21: =L21-I21 -> 0 | P21: =N21-K21 -> -39.852011 | Q21: =N21/K21 -> 0.87822996 | S21: =S5 -> 0.25 | T21: =INDEX(T5:T20,COUNTA(T5:T20)) -> 0.39818287 | AA21: =M21-J21 -> -438.37213 | AB21: =M21/J21 -> 0.87822996
A22: (新) 3300型飯糰機 | B22: 18℃-飯糰 | C22: 一配鮭魚奶油醬油飯糰 | E22: 18.53 | F22: 2924 | G22: =E22*F22 -> 54181.72 | I22: 3 | J22: 3300 | K22: =J22/I22 -> 1100 | L22: 3 | M22: =F22/V22*60 -> 2985.9443 | N22: =M22/L22 -> 995.31476 | O22: =L22-I22 -> 0 | P22: =N22-K22 -> -104.68524 | Q22: =N22/K22 -> 0.9048316 | R22: =Q38 -> 0.90561053 | S22: 0.37013889 | T22: 0.4109375 | V22: 58.755283 | AA22: =M22-J22 -> -314.05572 | AB22: =M22/J22 -> 0.9048316 | AC22: =AB38 -> 0.90561053
B23: 18℃-飯糰 | C23: 一配壹號醬炙烤牛飯糰 | E23: 22.28 | F23: 1206 | G23: =E23*F23 -> 26869.68 | I23: 5 | J23: 3300 | K23: =J23/I23 -> 660 | L23: 5 | M23: =F23/V23*60 -> 2989.8 | N23: =M23/L23 -> 597.96 | O23: =L23-I23 -> 0 | P23: =N23-K23 -> -62.04 | Q23: =N23/K23 -> 0.906 | S23: 0.41388889 | T23: 0.43069444 | U23: 5 | V23: 24.202288 | AA23: =M23-J23 -> -310.2 | AB23: =M23/J23 -> 0.906
B24: 18℃-飯糰 | C24: 一配鹽蔥燒肉飯糰 | E24: 17.89 | F24: 3276 | G24: =E24*F24 -> 58607.64 | I24: 4 | J24: 3300 | K24: =J24/I24 -> 825 | L24: 4 | M24: =F24/V24*60 -> 2989.8 | N24: =M24/L24 -> 747.45 | O24: =L24-I24 -> 0 | P24: =N24-K24 -> -77.55 | Q24: =N24/K24 -> 0.906 | S24: 0.43472222 | T24: 0.48037037 | U24: 5.8 | V24: 65.743528 | AA24: =M24-J24 -> -310.2 | AB24: =M24/J24 -> 0.906
B38: 平均 | I38: =AVERAGE(I22:I37) -> 4 | J38: =AVERAGE(J22:J37) -> 3300 | K38: =J38/I38 -> 825 | L38: =AVERAGE(L22:L37) -> 4 | M38: =AVERAGE(M22:M37) -> 2988.5148 | N38: =M38/L38 -> 747.12869 | O38: =L38-I38 -> 0 | P38: =N38-K38 -> -77.87131 | Q38: =N38/K38 -> 0.90561053 | S38: =S22 -> 0.37013889 | T38: =INDEX(T22:T37,COUNTA(T22:T37)) -> 0.48037037 | AA38: =M38-J38 -> -311.48524 | AB38: =M38/J38 -> 0.90561053
A39: GKK3600型 飯糰機 | B39: 18℃-飯糰 | C39: 一配山葵章魚飯糰 | E39: 25.2 | F39: 1608 | G39: =E39*F39 -> 40521.6 | I39: 3 | J39: 3600 | K39: =J39/I39 -> 1200 | L39: 3 | M39: =F39/V39*60 -> 3187.4289 | N39: =M39/L39 -> 1062.4763 | O39: =L39-I39 -> 0 | P39: =N39-K39 -> -137.5237 | Q39: =N39/K39 -> 0.88539692 | R39: =Q55 -> 0.88895802 | S39: 0.25 | T39: 0.27101852 | V39: 30.268911 | AA39: =M39-J39 -> -412.5711 | AB39: =M39/J39 -> 0.88539692 | AC39: =AB55 -> 0.88895802
B40: 18℃-飯糰 | C40: 一配熟成紅鮭飯糰 | E40: 25.03 | F40: 1524 | G40: =E40*F40 -> 38145.72 | I40: 5 | J40: 3600 | K40: =J40/I40 -> 720 | L40: 5 | M40: =F40/V40*60 -> 3193.4962 | N40: =M40/L40 -> 638.69923 | O40: =L40-I40 -> 0 | P40: =N40-K40 -> -81.300766 | Q40: =N40/K40 -> 0.88708227 | S40: 0.28125 | T40: 0.30112269 | U40: 14.733333 | V40: 28.633195 | AA40: =M40-J40 -> -406.50383 | AB40: =M40/J40 -> 0.88708227
B41: 18℃-飯糰 | C41: 一配蔬食鮪魚飯糰 | E41: 18.18 | F41: 1326 | G41: =E41*F41 -> 24106.68 | I41: 3 | J41: 3600 | K41: =J41/I41 -> 1200 | L41: 3 | M41: =F41/V41*60 -> 3185.9059 | N41: =M41/L41 -> 1061.9686 | O41: =L41-I41 -> 0 | P41: =N41-K41 -> -138.03136 | Q41: =N41/K41 -> 0.88497386 | S41: 0.31111111 | T41: 0.32844907 | U41: 15 | V41: 24.972489 | AA41: =M41-J41 -> -414.09409 | AB41: =M41/J41 -> 0.88497386
B42: 18℃-飯糰 | C42: 一配柚檸海灣貝飯糰 | E42: 23.72 | F42: 1598 | G42: =E42*F42 -> 37904.56 | I42: 5 | J42: 3600 | K42: =J42/I42 -> 720 | L42: 5 | M42: =F42/V42*60 -> 3193.3911 | N42: =M42/L42 -> 638.67823 | O42: =L42-I42 -> 0 | P42: =N42-K42 -> -81.32177 | Q42: =N42/K42 -> 0.8870531 | S42: 0.33819444 | T42: 0.35903935 | U42: 15 | V42: 30.024509 | AA42: =M42-J42 -> -406.60885 | AB42: =M42/J42 -> 0.8870531
B43: 18℃-飯糰 | C43: 一配鮪魚飯糰 | E43: 14.28 | F43: 7146 | G43: =E43*F43 -> 102044.88 | I43: 3 | J43: 3600 | K43: =J43/I43 -> 1200 | L43: 3 | M43: =F43/V43*60 -> 3190.8041 | N43: =M43/L43 -> 1063.6014 | O43: =L43-I43 -> 0 | P43: =N43-K43 -> -136.39864 | Q43: =N43/K43 -> 0.88633447 | S43: 0.36944444 | T43: 0.46275463 | U43: 14.983333 | V43: 134.37365 | AA43: =M43-J43 -> -409.19591 | AB43: =M43/J43 -> 0.88633447
B44: 18℃-飯糰 | C44: 一配經典肉鬆飯糰 | E44: 14.03 | F44: 5024 | G44: =E44*F44 -> 70486.72 | I44: 3 | J44: 3000 | K44: =J44/I44 -> 1000 | L44: 3 | M44: =F44/V44*60 -> 2717.0922 | N44: =M44/L44 -> 905.69739 | O44: =L44-I44 -> 0 | P44: =N44-K44 -> -94.302611 | Q44: =N44/K44 -> 0.90569739 | S44: 0.47291667 | T44: 0.5499537 | U44: 14.633333 | V44: 110.94213 | AA44: =M44-J44 -> -282.90783 | AB44: =M44/J44 -> 0.90569739
B55: 平均 | I55: =AVERAGE(I39:I54) -> 3.6666667 | J55: =AVERAGE(J39:J54) -> 3500 | K55: =J55/I55 -> 954.54545 | L55: =AVERAGE(L39:L54) -> 3.6666667 | M55: =AVERAGE(M39:M54) -> 3111.3531 | N55: =M55/L55 -> 848.55084 | O55: =L55-I55 -> 0 | P55: =N55-K55 -> -105.99462 | Q55: =N55/K55 -> 0.88895802 | S55: =S39 -> 0.25 | T55: =INDEX(T39:T54,COUNTA(T39:T54)) -> 0.5499537 | AA55: =M55-J55 -> -388.64694 | AB55: =M55/J55 -> 0.88895802
A56: GKK3600型 飯糰機2 | B56: 18℃-飯糰 | C56: 一配黑胡椒洋蔥豬飯糰 | E56: 17.07 | F56: 3105 | G56: =E56*F56 -> 53002.35 | I56: 3 | J56: 3300 | K56: =J56/I56 -> 1100 | L56: 3 | M56: =F56/V56*60 -> 2975.4688 | N56: =M56/L56 -> 991.82294 | O56: =L56-I56 -> 0 | P56: =N56-K56 -> -108.17706 | Q56: =N56/K56 -> 0.90165722 | R56: =Q72 -> 0.88984903 | S56: 0.25 | T56: 0.29347222 | V56: 62.611982 | AA56: =M56-J56 -> -324.53119 | AB56: =M56/J56 -> 0.90165722 | AC56: =AB72 -> 0.88984903
B57: 18℃-飯糰 | C57: 一配椒鹽檸檬鯖魚飯糰 | E57: 20.72 | F57: 3017 | G57: =E57*F57 -> 62512.24 | I57: 3 | J57: 3600 | K57: =J57/I57 -> 1200 | L57: 3 | M57: =F57/V57*60 -> 3198.638 | N57: =M57/L57 -> 1066.2127 | O57: =L57-I57 -> 0 | P57: =N57-K57 -> -133.78734 | Q57: =N57/K57 -> 0.88851055 | S57: 0.30347222 | T57: 0.3427662 | U57: 15 | V57: 56.592838 | AA57: =M57-J57 -> -401.36202 | AB57: =M57/J57 -> 0.88851055
B58: 18℃-飯糰 | C58: 一配北海道秋鮭親子飯糰 | E58: 24.82 | F58: 1839 | G58: =E58*F58 -> 45643.98 | I58: 5 | J58: 3600 | K58: =J58/I58 -> 720 | L58: 5 | M58: =F58/V58*60 -> 3199.3433 | N58: =M58/L58 -> 639.86867 | O58: =L58-I58 -> 0 | P58: =N58-K58 -> -80.131334 | Q58: =N58/K58 -> 0.88870648 | S58: 0.35277778 | T58: 0.37672454 | U58: 15 | V58: 34.488327 | AA58: =M58-J58 -> -400.65667 | AB58: =M58/J58 -> 0.88870648
B59: 18℃-飯糰 | C59: 一配明太子龍蝦風味沙拉飯糰 | E59: 18.18 | F59: 2458 | G59: =E59*F59 -> 44686.44 | I59: 3 | J59: 3600 | K59: =J59/I59 -> 1200 | L59: 3 | M59: =F59/V59*60 -> 3193.7983 | N59: =M59/L59 -> 1064.5994 | O59: =L59-I59 -> 0 | P59: =N59-K59 -> -135.40057 | Q59: =N59/K59 -> 0.88716619 | S59: 0.38680556 | T59: 0.41886574 | U59: 14.516667 | V59: 46.176993 | AA59: =M59-J59 -> -406.20171 | AB59: =M59/J59 -> 0.88716619
B60: 18℃-飯糰 | C60: 一配贅沢鮭魚肚飯糰 | E60: 30 | F60: 2542 | G60: =E60*F60 -> 76260 | I60: 4 | J60: 3600 | K60: =J60/I60 -> 900 | L60: 4 | M60: =F60/V60*60 -> 3192.48 | N60: =M60/L60 -> 798.12 | O60: =L60-I60 -> 0 | P60: =N60-K60 -> -101.88 | Q60: =N60/K60 -> 0.8868 | S60: 0.42916667 | T60: 0.46233796 | U60: 14.833333 | V60: 47.774771 | AA60: =M60-J60 -> -407.52 | AB60: =M60/J60 -> 0.8868
B61: 18℃-飯糰 | C61: 一配雞肉飯飯糰 | E61: 16.66 | F61: 5897 | G61: =E61*F61 -> 98244.02 | I61: 5 | J61: 3600 | K61: =J61/I61 -> 720 | L61: 5 | M61: =F61/V61*60 -> 3194.0558 | N61: =M61/L61 -> 638.81117 | O61: =L61-I61 -> 0 | P61: =N61-K61 -> -81.188834 | Q61: =N61/K61 -> 0.88723773 | S61: 0.47222222 | T61: 0.54914352 | U61: 15 | V61: 110.77452 | AA61: =M61-J61 -> -405.94417 | AB61: =M61/J61 -> 0.88723773
B72: 平均 | I72: =AVERAGE(I56:I71) -> 3.8333333 | J72: =AVERAGE(J56:J71) -> 3550 | K72: =J72/I72 -> 926.08696 | L72: =AVERAGE(L56:L71) -> 3.8333333 | M72: =AVERAGE(M56:M71) -> 3158.964 | N72: =M72/L72 -> 824.07758 | O72: =L72-I72 -> 0 | P72: =N72-K72 -> -102.00938 | Q72: =N72/K72 -> 0.88984903 | S72: =S56 -> 0.25 | T72: =INDEX(T56:T71,COUNTA(T56:T71)) -> 0.54914352 | AA72: =M72-J72 -> -391.03596 | AB72: =M72/J72 -> 0.88984903
A73: 自動包裝機 (二配) | B73: 18℃-飯糰 | C73: 二配兩粒飯糰(鮪魚.焦糖鮭魚) | E73: 28.57 | F73: 1632 | G73: =E73*F73 -> 46626.24 | I73: 12 | J73: 3600 | K73: =J73/I73 -> 300 | L73: 12 | M73: =F73/V73*60 -> 3114.9426 | N73: =M73/L73 -> 259.57855 | O73: =L73-I73 -> 0 | P73: =N73-K73 -> -40.421452 | Q73: =N73/K73 -> 0.86526183 | R73: =Q89 -> 0.87474136 | S73: 0.70833333 | T73: 0.73016204 | V73: 31.435571 | AA73: =M73-J73 -> -485.05743 | AB73: =M73/J73 -> 0.86526183 | AC73: =AB89 -> 0.87474136
B74: 18℃-飯糰 | C74: 二配溏心蛋五目飯糰 | E74: 20.42 | F74: 654 | G74: =E74*F74 -> 13354.68 | I74: 13 | J74: 3600 | K74: =J74/I74 -> 276.92308 | L74: 13 | M74: =F74/V74*60 -> 3262.3838 | N74: =M74/L74 -> 250.9526 | O74: =L74-I74 -> 0 | P74: =N74-K74 -> -25.970479 | Q74: =N74/K74 -> 0.90621771 | S74: 0.73402778 | T74: 0.74237269 | U74: 5.5666667 | V74: 12.028015 | AA74: =M74-J74 -> -337.61623 | AB74: =M74/J74 -> 0.90621771
B75: 18℃-飯糰 | C75: 二配鮭魚毛豆炊飯飯糰 | E75: 18.92 | F75: 2516 | G75: =E75*F75 -> 47602.72 | I75: 6 | J75: 3600 | K75: =J75/I75 -> 600 | L75: 6 | M75: =F75/V75*60 -> 3259.9492 | N75: =M75/L75 -> 543.32487 | O75: =L75-I75 -> 0 | P75: =N75-K75 -> -56.675127 | Q75: =N75/K75 -> 0.90554146 | S75: 0.74583333 | T75: 0.77798611 | U75: 4.9833333 | V75: 46.30747 | AA75: =M75-J75 -> -340.05076 | AB75: =M75/J75 -> 0.90554146
B76: 18℃-飯糰 | C76: 二配柚香雞胸五穀飯糰 | E76: 17.71 | F76: 5308 | G76: =E76*F76 -> 94004.68 | I76: 6 | J76: 3600 | K76: =J76/I76 -> 600 | L76: 6 | M76: =F76/V76*60 -> 2959 | N76: =M76/L76 -> 493.16667 | O76: =L76-I76 -> 0 | P76: =N76-K76 -> -106.83333 | Q76: =N76/K76 -> 0.82194444 | S76: 0.78125 | T76: 0.8559838 | U76: 4.7 | V76: 107.63096 | AA76: =M76-J76 -> -641 | AB76: =M76/J76 -> 0.82194444
B89: 平均 | I89: =AVERAGE(I73:I88) -> 9.25 | J89: =AVERAGE(J73:J88) -> 3600 | K89: =J89/I89 -> 389.18919 | L89: =AVERAGE(L73:L88) -> 9.25 | M89: =AVERAGE(M73:M88) -> 3149.0689 | N89: =M89/L89 -> 340.43988 | O89: =L89-I89 -> 0 | P89: =N89-K89 -> -48.749309 | Q89: =N89/K89 -> 0.87474136 | S89: =S73 -> 0.70833333 | T89: =INDEX(T73:T88,COUNTA(T73:T88)) -> 0.8559838 | AA89: =M89-J89 -> -450.9311 | AB89: =M89/J89 -> 0.87474136
A90: (新) 3300型飯糰機 (二配) | B90: 18℃-飯糰 | C90: 二配大飯糰韓式蒜烤豬五花 | E90: 24.54 | F90: 1729 | G90: =E90*F90 -> 42429.66 | I90: 4 | J90: 3000 | K90: =J90/I90 -> 750 | L90: 4 | M90: =F90/V90*60 -> 2707.5757 | N90: =M90/L90 -> 676.89394 | O90: =L90-I90 -> 0 | P90: =N90-K90 -> -73.106063 | Q90: =N90/K90 -> 0.90252525 | R90: =Q106 -> 0.88117449 | S90: 0.70833333 | T90: 0.73493056 | V90: 38.314718 | AA90: =M90-J90 -> -292.42425 | AB90: =M90/J90 -> 0.90252525 | AC90: =AB106 -> 0.88117449
B91: 18℃-飯糰 | C91: 二配大飯糰乾燒風味鮮蝦 | E91: 23.27 | F91: 1106 | G91: =E91*F91 -> 25736.62 | I91: 5 | J91: 3000 | K91: =J91/I91 -> 600 | L91: 5 | M91: =F91/V91*60 -> 2711.1287 | N91: =M91/L91 -> 542.22573 | O91: =L91-I91 -> 0 | P91: =N91-K91 -> -57.774268 | Q91: =N91/K91 -> 0.90370955 | S91: 0.73888889 | T91: 0.75587963 | U91: 5.7 | V91: 24.476891 | AA91: =M91-J91 -> -288.87134 | AB91: =M91/J91 -> 0.90370955
B92: 18℃-飯糰 | C92: 二配大飯糰泡菜鮪魚 | E92: 24.33 | F92: 1531 | G92: =E92*F92 -> 37249.23 | H92: 2 | I92: 4 | J92: 3000 | K92: =J92/I92 -> 750 | L92: 4 | M92: =F92/V92*60 -> 2451 | N92: =M92/L92 -> 612.75 | O92: =L92-I92 -> 0 | P92: =N92-K92 -> -137.25 | Q92: =N92/K92 -> 0.817 | S92: 0.75902778 | T92: 0.7850463 | U92: 4.5333333 | V92: 37.47858 | AA92: =M92-J92 -> -549 | AB92: =M92/J92 -> 0.817
B93: 18℃-飯糰 | C93: 二配鹽水G絲飯糰 | E93: 17.22 | F93: 1273 | G93: =E93*F93 -> 21921.06 | I93: 3 | J93: 3300 | K93: =J93/I93 -> 1100 | L93: 3 | M93: =F93/V93*60 -> 2988.7664 | N93: =M93/L93 -> 996.25547 | O93: =L93-I93 -> 0 | P93: =N93-K93 -> -103.74453 | Q93: =N93/K93 -> 0.90568679 | S93: 0.78888889 | T93: 0.80663194 | U93: 5.5333333 | V93: 25.555694 | AA93: =M93-J93 -> -311.2336 | AB93: =M93/J93 -> 0.90568679
B94: 18℃-飯糰 | C94: 二配壹號醬炙烤牛飯糰 | E94: 22.28 | F94: 1890 | G94: =E94*F94 -> 42109.2 | I94: 5 | J94: 3300 | K94: =J94/I94 -> 660 | L94: 5 | M94: =F94/V94*60 -> 2989.8 | N94: =M94/L94 -> 597.96 | O94: =L94-I94 -> 0 | P94: =N94-K94 -> -62.04 | Q94: =N94/K94 -> 0.906 | S94: 0.80972222 | T94: 0.83605324 | U94: 5 | V94: 37.928958 | AA94: =M94-J94 -> -310.2 | AB94: =M94/J94 -> 0.906
B95: 18℃-飯糰 | C95: 二配鹽蔥燒肉飯糰 | E95: 17.89 | F95: 5681 | G95: =E95*F95 -> 101633.09 | I95: 4 | J95: 3300 | K95: =J95/I95 -> 825 | L95: 4 | M95: =F95/V95*60 -> 2989.8 | N95: =M95/L95 -> 747.45 | O95: =L95-I95 -> 0 | P95: =N95-K95 -> -77.55 | Q95: =N95/K95 -> 0.906 | S95: 0.83958333 | T95: 0.91875 | U95: 5.0833333 | V95: 114.00763 | W95: 0.91875 | X95: 0.95763889 | AA95: =M95-J95 -> -310.2 | AB95: =M95/J95 -> 0.906
B96: 18℃-飯糰 | C96: 二配大飯糰泡菜鮪魚 | E96: 24.33 | F96: 3833 | G96: =E96*F96 -> 93256.89 | I96: 4 | J96: 3000 | K96: =J96/I96 -> 750 | L96: 4 | M96: =F96/V96*60 -> 2459.6505 | N96: =M96/L96 -> 614.91262 | O96: =L96-I96 -> 0 | P96: =N96-K96 -> -135.08738 | Q96: =N96/K96 -> 0.8198835 | S96: 0.95763889 | T96: 1.0225694 | U96: 56 | V96: 93.501089 | AA96: =M96-J96 -> -540.34951 | AB96: =M96/J96 -> 0.8198835
B106: 平均 | I106: =AVERAGE(I90:I105) -> 4.1428571 | J106: =AVERAGE(J90:J105) -> 3128.5714 | K106: =J106/I106 -> 755.17241 | L106: =AVERAGE(L90:L105) -> 4.1428571 | M106: =AVERAGE(M90:M105) -> 2756.8173 | N106: =M106/L106 -> 665.43867 | O106: =L106-I106 -> 0 | P106: =N106-K106 -> -89.733748 | Q106: =N106/K106 -> 0.88117449 | S106: =S90 -> 0.70833333 | T106: =INDEX(T90:T105,COUNTA(T90:T105)) -> 1.0225694 | AA106: =M106-J106 -> -371.7541 | AB106: =M106/J106 -> 0.88117449
...

Sheet 0629(4度C)
A1: 大溪廠日報分析 | C1: 總生產量 | D1: =SUM(F5:F157) -> 107003 | E1: 營業額 | F1: =SUM(G5:G157) -> 4783983.1 | G1: 出勤人數 | H1: =L21+L38+L55+L72+L89+L106+L123+L140+L157 -> 155.43452 | I1: 產線配置圖 | L1: 生產實績 | O1: 人時性差異分析 | S1: 日報登錄 | Y1: 合計次數 | Z1: 合計(時間/分) | AA1: 產線異常 分析說明(5分鐘以上) | AC1: 合計次數 | AD1: 合計(時間/分) | AE1: 產能差異分析
A2: 46202 | C2: 人時性 | D2: =AVERAGE(N21,N38,N55,N72,N89,N106,N123,N140,N157) -> 179.23487 | E2: 平均廠價 | F2: =F1/D1 -> 44.708869 | G2: 多次生產數 | H2: =COUNT(H5:H157) -> 3 | Y2: =SUM(Y21,Y38,Y55,Y72,Y89,Y106,Y123,Y140,Y157) -> 0 | Z2: =SUM(Z21,Z38,Z55,Z72,Z89,Z106,Z123,Z140,Z157) -> 0 | AC2: =SUM(AC21,AC38,AC55,AC72,AC89,AC106,AC123,AC140,AC157) -> 0 | AD2: =SUM(AD21,AD38,AD55,AD72,AD89,AD106,AD123,AD140,AD157) -> 0
A3: 線別 | B3: 品類 | C3: 品名 | E3: 廠價 | F3: 生產量 | G3: 營收 | H3: 多次 生產 | I3: 人數 | J3: 產能/時 | K3: 人時性 | L3: 人數 | M3: 產能/時 | N3: 人時性 | O3: 人數 | P3: 人時性 | Q3: 達成率 | R3: 達成率 平均 | S3: 生產時間 | U3: 換線、休息/分 | V3: 稼動時間/分 | W3: 休息時間 | Y3: 產線異常統計(5分鐘以上) | AA3: (屏榮回填) | AC3: 短暫停線統計(5分鐘以下) | AE3: 產能/時 | AF3: 達成率 | AG3: 達成率平均
S4: 開始 | T4: 結束 | W4: 開始 | X4: 結束 | Y4: 次數 | Z4: 時間/分 | AC4: 總次數 | AD4: 設備因素(次數)
