Workbook

Sheet 0228
B1: 屏榮 大溪廠組合室生產人時性分析
B3: 日期 | C3: 115.02.28星期六 | E3: 訂單量 | F3: ='0228(18度C)'!D1+'0228(4度C)'!D1 -> 131697 | H3: 營業額 | I3: ='0228(18度C)'!F1+'0228(4度C)'!F1 -> 3915929.6
B4: 人時性 | C4: 項目 | E4: ➀ | G4: ➁ | I4: ➂ | K4: ④ | M4: ⑤ | O4: 異常停線 | Q4: 短暫停線
C5: 組合室 | E5: 全溫層 | G5: 4度C-各編組展開(一配) | I5: 4度C-各編組展開(二配) | K5: 18度C-各編組展開(一配) | M5: 18度C-各編組展開(二配) | O5: 合計次數 | P5: 時間 | Q5: 合計次數 | R5: 設備次數
C6: 排關平均 | E6: =AVERAGE(D14:O14,D32:X32) -> 550.03519 | F6: =AVERAGE(#REF!,D14:K14) -> #REF! | G6: =AVERAGE(D14:K14) -> 209.01033 | I6: =AVERAGE(L14:O14) -> 92.630803 | K6: =AVERAGE(D32:O32) -> 733.74087 | M6: =AVERAGE(P32:X32) -> 785.37 | O6: ='0228(4度C)'!Y2 -> 0 | P6: ='0228(4度C)'!Z2 -> 0 | Q6: ='0228(4度C)'!AC2 -> 0 | R6: ='0228(4度C)'!AD2 -> 0
C7: 實績平均 | E7: =AVERAGE(D15:O15,D33:X33) -> 489.05639 | F7: =AVERAGE(#REF!,D15:K15) -> #REF! | G7: =AVERAGE(D15:K15) -> 185.45097 | I7: =AVERAGE(L15:O15) -> 82.595783 | K7: =AVERAGE(D33:O33) -> 653.0331 | M7: =AVERAGE(P33:X33) -> 697.7529
C8: 達成率平均 | E8: =AVERAGE(D16:O16,D34:X34) -> 0.88971142 | F8: =AVERAGE(D16:K16,#REF!) -> #REF! | G8: =AVERAGE(D16:K16) -> 0.89160684 | I8: =AVERAGE(L16:O16) -> 0.89164615 | K8: =AVERAGE(D34:O34) -> 0.88988962 | M8: =AVERAGE(P34:X34) -> 0.88720734
O9: ※現行日本鮮食廠以達成率80%為基本(即為現行KPI)
B11: 溫層 | D11: ➁4度C-各編組展開 | L11: ➂4度C-各編組展開
B12: 編組 | D12: 1 | E12: 2 | F12: 3 | G12: 4 | H12: 5 | I12: 6 | J12: 7 | K12: 8 | L12: 1 | M12: 2 | N12: 3 | O12: 4
D13: 便當一線 | E13: 便當二線 | F13: 涼麵一線 | G13: 涼麵二線 | H13: 涼麵三線 | I13: 自動包裝機 | J13: 自動包裝機2 | K13: 自動包裝機3 | L13: 便當一線 | M13: 便當二線 | N13: 涼麵一線 | O13: 涼麵二線
B14: 人時性 | C14: 排關 | D14: - | E14: - | F14: 100.84112 | G14: 82.644628 | H14: 88.888889 | I14: 563.66667 | J14: - | K14: - | L14: - | M14: - | N14: 86.956522 | O14: 98.305085
C15: 實績 | D15: - | E15: - | F15: 90.372876 | G15: 73.698516 | H15: 79.520713 | I15: 498.21178 | J15: - | K15: - | L15: - | M15: - | N15: 77.505574 | O15: 87.685992
C16: 達成率 | D16: - | E16: - | F16: =F15/F14 -> 0.89619071 | G16: =G15/G14 -> 0.89175204 | H16: =H15/H14 -> 0.89460802 | I16: =I15/I14 -> 0.8838766 | J16: - | K16: - | L16: - | M16: - | N16: =N15/N14 -> 0.8913141 | O16: =O15/O14 -> 0.8919782
B17: 作業 時間 | C17: 開始 | D17: - | E17: - | F17: 0.25 | G17: 0.25025463 | H17: 0.25 | I17: 0.40295139 | J17: - | K17: - | L17: - | M17: - | N17: 0.70849537 | O17: 0.70833333
C18: 結束 | D18: - | E18: - | F18: 0.53222222 | G18: 0.59305556 | H18: 0.44728009 | I18: 0.47855324 | J18: - | K18: - | L18: - | M18: - | N18: 0.83888889 | O18: 0.82916667
B19: 產線異常 (5分鐘以上) | C19: 次數
C20: 時間/分
B21: 短暫停線 (5分鐘以下) | C21: 次數
C22: 設備次數
B23: 配置人數 | D23: - | E23: - | F23: 21.6 | G23: 24.2 | H23: 18 | I23: 6 | J23: - | K23: - | L23: - | M23: - | N23: 23 | O23: 19.666667
B24: 主要應用設備 | D24: L型封口機 | E24: ET-55 | F24: ET-55 | G24: ET-55 | H24: ET-600 | I24: 伺服包裝機 | J24: 伺服包裝機 | K24: 伺服包裝機 | L24: L型封口機 | M24: ET-55 | N24: ET-55 | O24: ET-55
B25: 次要應用設備 | D25: 伺服包裝機 | H25: 伺服包裝機
B26: 備註 | H26: 涼麵+烤飯糰 | I26: 大口飯糰線 | K26: 烤飯糰+手卷
B29: 溫層 | D29: ➃18度C-各編組展開 (一配) | P29: ⑤18度C-各編組展開 (二配)
B30: 編組 | D30: 1 | E30: 2 | F30: 3 | G30: 4 | H30: 5 | I30: 6 | J30: 7 | K30: 8 | L30: 9 | M30: 10 | N30: 11 | O30: 12 | P30: 1 | Q30: 2 | R30: 3 | S30: 4 | T30: 5 | U30: 6 | V30: 7 | W30: 8 | X30: 9
D31: 便當一線 | E31: 涼麵一線 | F31: 涼麵三線 | G31: 自動包裝機 | H31: 自動包裝機2 | I31: 自動包裝機3 | J31: 味付飯糰線B | K31: (舊) 3300型飯糰線 | L31: 3000型飯糰線 | M31: (新) 3300型飯糰機 | N31: GKK3600型 飯糰機 | O31: GKK3600型 飯糰機2 | P31: 自動包裝機 | Q31: 自動包裝機2 | R31: 自動包裝機3 | S31: 味付飯糰線B | T31: (舊) 3300型飯糰線 | U31: 3000型飯糰線 | V31: (新) 3300型飯糰機 | W31: GKK3600型 飯糰機 | X31: GKK3600型 飯糰機2
B32: 人時性 | C32: 排關 | D32: - | E32: - | F32: - | G32: 306.38298 | H32: 433.33333 | I32: - | J32: - | K32: 761.53846 | L32: - | M32: 825 | N32: 1133.3333 | O32: 942.85714 | P32: 306.38298 | Q32: - | R32: - | S32: - | T32: 787.5 | U32: - | V32: 761.53846 | W32: 1100 | X32: 971.42857
C33: 實績 | D33: - | E33: - | F33: - | G33: 267.78764 | H33: 390.09236 | I33: - | J33: - | K33: 684.71318 | L33: - | M33: 740.8564 | N33: 998.44809 | O33: 836.30091 | P33: 267.70227 | Q33: - | R33: - | S33: - | T33: 705.07886 | U33: - | V33: 684.38721 | W33: 974.13666 | X33: 857.45953
C34: 達成率 | D34: - | E34: - | F34: - | G34: =G33/G32 -> 0.87402912 | H34: =H33/H32 -> 0.90021313 | I34: - | J34: - | K34: =K33/K32 -> 0.89911832 | L34: - | M34: =M33/M32 -> 0.89800776 | N34: =N33/N32 -> 0.88098361 | O34: =O33/O32 -> 0.88698581 | P34: =P33/P32 -> 0.87375048 | Q34: - | R34: - | S34: - | T34: =T33/T32 -> 0.89533823 | U34: - | V34: =V33/V32 -> 0.89869027 | W34: =W33/W32 -> 0.88557878 | X34: =X33/X32 -> 0.88267892
B35: 作業 時間 | C35: 開始 | D35: - | E35: - | F35: - | G35: 0.30347222 | H35: 0.25025463 | I35: - | J35: - | K35: 0.39583333 | L35: - | M35: 0.29166667 | N35: 0.29195602 | O35: 0.29177083 | P35: 0.7084375 | Q35: - | R35: - | S35: - | T35: 0.70833333 | U35: - | V35: 0.70856481 | W35: 0.70842593 | X35: 0.70846065
C36: 結束 | D36: - | E36: - | F36: - | G36: 0.39877315 | H36: 0.28571759 | I36: - | J36: - | K36: 0.47712963 | L36: - | M36: 0.3821412 | N36: 0.43263889 | O36: 0.41111111 | P36: 0.80208333 | Q36: - | R36: - | S36: - | T36: 0.86070602 | U36: - | V36: 0.85561343 | W36: 0.98680556 | X36: 0.99457176
B37: 配置人數 | D37: - | E37: - | F37: - | G37: 11.75 | H37: 6 | I37: - | J37: - | K37: 4.3333333 | L37: - | M37: 4 | N37: 3 | O37: 3.5 | P37: 11.75 | Q37: - | R37: - | S37: - | T37: 4 | U37: - | V37: 4.3333333 | W37: 3 | X37: 3.5
B38: 主要應用設備 | D38: 伺服包裝機 | E38: ET-55 | F38: ET-600 | G38: 夾心型 | H38: 伺服包裝機 | I38: 伺服包裝機 | J38: 夾心型 | K38: 3300型 | L38: 3300型 | M38: 3300型 | N38: GKK | O38: GKK | P38: 夾心型 | Q38: 伺服包裝機 | R38: 伺服包裝機 | S38: 夾心型 | T38: 3300型 | U38: 3300型 | V38: 3300型 | W38: GKK | X38: GKK
B39: 次要應用設備
B40: 備註

Sheet 0228(18度C)
A1: 大溪廠日報分析 | C1: 總生產量 | D1: =SUM(F5:F191) -> 87934 | E1: 營業額 | F1: =SUM(G5:G191) -> 1718979.1 | G1: 出勤人數 | H1: =L21+L38+L55+L72+L89+L106+L123+L140+L157+L174+L191 -> 59.166667 | I1: 產線配置圖 | L1: 生產實績 | O1: 人時性差異分析 | S1: 日報登錄 | Y1: 分析說明 | AA1: 產能差異分析
A2: 46081 | C2: 人時性 | D2: =AVERAGE(N21,N38,N55,N72,N89,N106,N123,N140,N157,N174,N191) -> 673.36028 | E2: 平均廠價 | F2: =F1/D1 -> 19.548515 | G2: 多次生產數 | H2: =COUNT(H5:H191) -> 3
A3: 線別 | B3: 品類 | C3: 品名 | E3: 廠價 | F3: 生產量 | G3: 營收 | H3: 多次 生產 | I3: 人數 | J3: 產能/時 | K3: 人時性 | L3: 人數 | M3: 產能/時 | N3: 人時性 | O3: 人數 | P3: 人時性 | Q3: 達成率 | R3: 達成率 平均 | S3: 生產時間 | U3: 換線、休息/分 | V3: 稼動時間/分 | W3: 休息時間 | Y3: (屏榮回填) | AA3: 產能/時 | AB3: 達成率 | AC3: 達成率平均
S4: 開始 | T4: 結束 | W4: 開始 | X4: 結束
A5: 自動包裝機 | B5: 18℃-飯糰 | C5: 一配兩粒飯糰(鮪魚.焦糖鮭魚) | E5: 28.57 | F5: 1485 | G5: =E5*F5 -> 42426.45 | I5: 12 | J5: 3600 | K5: =J5/I5 -> 300 | L5: 12 | M5: =F5/V5*60 -> 3128.1451 | N5: =M5/L5 -> 260.67876 | O5: =L5-I5 -> 0 | P5: =N5-K5 -> -39.32124 | Q5: =N5/K5 -> 0.8689292 | R5: =Q21 -> 0.87402912 | S5: 0.30347222 | T5: 0.32325231 | V5: 28.483333 | AA5: =M5-J5 -> -471.85489 | AB5: =M5/J5 -> 0.8689292 | AC5: =AB21 -> 0.87402912
B6: 18℃-壽司手卷 | C6: 一配海饌雙手卷 | E6: 29.85 | F6: 1784 | G6: =E6*F6 -> 53252.4 | I6: 12 | J6: 3600 | K6: =J6/I6 -> 300 | L6: 12 | M6: =F6/V6*60 -> 3140.5379 | N6: =M6/L6 -> 261.71149 | O6: =L6-I6 -> 0 | P6: =N6-K6 -> -38.288509 | Q6: =N6/K6 -> 0.87237164 | S6: 0.32638889 | T6: 0.35005787 | U6: 4.5166667 | V6: 34.083333 | AA6: =M6-J6 -> -459.4621 | AB6: =M6/J6 -> 0.87237164
B7: 18℃-壽司手卷 | C7: 一配雙饗雙手卷 | E7: 29.52 | F7: 1708 | G7: =E7*F7 -> 50420.16 | I7: 12 | J7: 3600 | K7: =J7/I7 -> 300 | L7: 12 | M7: =F7/V7*60 -> 3140.3473 | N7: =M7/L7 -> 261.69561 | O7: =L7-I7 -> 0 | P7: =N7-K7 -> -38.304392 | Q7: =N7/K7 -> 0.87231869 | S7: 0.35372685 | T7: 0.37638889 | U7: 5.2833333 | V7: 32.633333 | AA7: =M7-J7 -> -459.65271 | AB7: =M7/J7 -> 0.87231869
B8: 18℃-壽司手卷 | C8: 一配長野稻荷壽司 | E8: 25.64 | F8: 1442 | G8: =E8*F8 -> 36972.88 | I8: 11 | J8: 3600 | K8: =J8/I8 -> 327.27273 | L8: 11 | M8: =F8/V8*60 -> 3176.989 | N8: =M8/L8 -> 288.81718 | O8: =L8-I8 -> 0 | P8: =N8-K8 -> -38.455547 | Q8: =N8/K8 -> 0.88249694 | S8: 0.37986111 | T8: 0.39877315 | U8: 5 | V8: 27.233333 | AA8: =M8-J8 -> -423.01102 | AB8: =M8/J8 -> 0.88249694
B21: 平均 | I21: =AVERAGE(I5:I20) -> 11.75 | J21: =AVERAGE(J5:J20) -> 3600 | K21: =J21/I21 -> 306.38298 | L21: =AVERAGE(L5:L20) -> 11.75 | M21: =AVERAGE(M5:M20) -> 3146.5048 | N21: =M21/L21 -> 267.78764 | O21: =L21-I21 -> 0 | P21: =N21-K21 -> -38.595334 | Q21: =N21/K21 -> 0.87402912 | S21: =S5 -> 0.30347222 | T21: =INDEX(T5:T20,COUNTA(T5:T20)) -> 0.39877315 | AA21: =M21-J21 -> -453.49518 | AB21: =M21/J21 -> 0.87402912
A22: 自動包裝機2 | B22: 18℃-壽司手卷 | C22: 一配雙鬆細卷 | E22: 14.03 | F22: 805 | G22: =E22*F22 -> 11294.15 | I22: 6 | J22: 2600 | K22: =J22/I22 -> 433.33333 | L22: 6 | M22: =F22/V22*60 -> 2340.8724 | N22: =M22/L22 -> 390.1454 | O22: =L22-I22 -> 0 | P22: =N22-K22 -> -43.187938 | Q22: =N22/K22 -> 0.90033553 | R22: =Q38 -> 0.90021313 | S22: 0.25025463 | T22: 0.26458333 | V22: 20.633333 | AA22: =M22-J22 -> -259.12763 | AB22: =M22/J22 -> 0.90033553 | AC22: =AB38 -> 0.90021313
B23: 18℃-壽司手卷 | C23: 一配經典鮪魚沙拉細卷 | E23: 14.49 | F23: 992 | G23: =E23*F23 -> 14374.08 | I23: 6 | J23: 2600 | K23: =J23/I23 -> 433.33333 | L23: 6 | M23: =F23/V23*60 -> 2340.2359 | N23: =M23/L23 -> 390.03932 | O23: =L23-I23 -> 0 | P23: =N23-K23 -> -43.294015 | Q23: =N23/K23 -> 0.90009073 | S23: 0.26805556 | T23: 0.28571759 | U23: 5 | V23: 25.433333 | AA23: =M23-J23 -> -259.76409 | AB23: =M23/J23 -> 0.90009073
B38: 平均 | I38: =AVERAGE(I22:I37) -> 6 | J38: =AVERAGE(J22:J37) -> 2600 | K38: =J38/I38 -> 433.33333 | L38: =AVERAGE(L22:L37) -> 6 | M38: =AVERAGE(M22:M37) -> 2340.5541 | N38: =M38/L38 -> 390.09236 | O38: =L38-I38 -> 0 | P38: =N38-K38 -> -43.240976 | Q38: =N38/K38 -> 0.90021313 | S38: =S22 -> 0.25025463 | T38: =INDEX(T22:T37,COUNTA(T22:T37)) -> 0.28571759 | AA38: =M38-J38 -> -259.44586 | AB38: =M38/J38 -> 0.90021313
A39: (舊) 3300型飯糰線 | B39: 18℃-飯糰 | C39: 一配壹號醬炙烤牛飯糰 | E39: 22.28 | F39: 801 | G39: =E39*F39 -> 17846.28 | I39: 5 | J39: 3300 | K39: =J39/I39 -> 660 | L39: 5 | M39: =F39/V39*60 -> 2969.7219 | N39: =M39/L39 -> 593.94439 | O39: =L39-I39 -> 0 | P39: =N39-K39 -> -66.055613 | Q39: =N39/K39 -> 0.89991574 | R39: =Q55 -> 0.89911832 | S39: 0.39583333 | T39: 0.40707176 | V39: 16.183333 | AA39: =M39-J39 -> -330.27806 | AB39: =M39/J39 -> 0.89991574 | AC39: =AB55 -> 0.89911832
B40: 18℃-飯糰 | C40: 一配照燒雞肉飯糰 | E40: 21.45 | F40: 1013 | G40: =E40*F40 -> 21728.85 | I40: 4 | J40: 3300 | K40: =J40/I40 -> 825 | L40: 4 | M40: =F40/V40*60 -> 2967.2905 | N40: =M40/L40 -> 741.82262 | O40: =L40-I40 -> 0 | P40: =N40-K40 -> -83.17738 | Q40: =N40/K40 -> 0.89917893 | S40: 0.41041667 | T40: 0.4246412 | U40: 4.8166667 | V40: 20.483333 | AA40: =M40-J40 -> -332.70952 | AB40: =M40/J40 -> 0.89917893
B41: 18℃-飯糰 | C41: 一配雞肉飯飯糰 | E41: 16.66 | F41: 3511 | G41: =E41*F41 -> 58493.26 | I41: 4 | J41: 3300 | K41: =J41/I41 -> 825 | L41: 4 | M41: =F41/V41*60 -> 2964.2589 | N41: =M41/L41 -> 741.06473 | O41: =L41-I41 -> 0 | P41: =N41-K41 -> -83.935272 | Q41: =N41/K41 -> 0.89826028 | S41: 0.42777778 | T41: 0.47712963 | U41: 4.5166667 | V41: 71.066667 | AA41: =M41-J41 -> -335.74109 | AB41: =M41/J41 -> 0.89826028
B55: 平均 | I55: =AVERAGE(I39:I54) -> 4.3333333 | J55: =AVERAGE(J39:J54) -> 3300 | K55: =J55/I55 -> 761.53846 | L55: =AVERAGE(L39:L54) -> 4.3333333 | M55: =AVERAGE(M39:M54) -> 2967.0904 | N55: =M55/L55 -> 684.71318 | O55: =L55-I55 -> 0 | P55: =N55-K55 -> -76.825282 | Q55: =N55/K55 -> 0.89911832 | S55: =S39 -> 0.39583333 | T55: =INDEX(T39:T54,COUNTA(T39:T54)) -> 0.47712963 | AA55: =M55-J55 -> -332.90956 | AB55: =M55/J55 -> 0.89911832
A56: (新) 3300型飯糰機 | B56: 18℃-飯糰 | C56: 一配鹽蔥燒肉飯糰 | E56: 17.89 | F56: 2246 | G56: =E56*F56 -> 40180.94 | I56: 4 | J56: 3300 | K56: =J56/I56 -> 825 | L56: 4 | M56: =F56/V56*60 -> 2962.8435 | N56: =M56/L56 -> 740.71088 | O56: =L56-I56 -> 0 | P56: =N56-K56 -> -84.289117 | Q56: =N56/K56 -> 0.89783137 | R56: =Q72 -> 0.89800776 | S56: 0.29166667 | T56: 0.32325231 | V56: 45.483333 | AA56: =M56-J56 -> -337.15647 | AB56: =M56/J56 -> 0.89783137 | AC56: =AB72 -> 0.89800776
B57: 18℃-飯糰 | C57: 一配紅運烏魚子紹興飯糰 | E57: 27.27 | F57: 1229 | G57: =E57*F57 -> 33514.83 | I57: 5 | J57: 3300 | K57: =J57/I57 -> 660 | L57: 5 | M57: =F57/V57*60 -> 2963.4293 | N57: =M57/L57 -> 592.68587 | O57: =L57-I57 -> 0 | P57: =N57-K57 -> -67.314133 | Q57: =N57/K57 -> 0.89800889 | S57: 0.32646991 | T57: 0.34375 | U57: 4.6333333 | V57: 24.883333 | AA57: =M57-J57 -> -336.57066 | AB57: =M57/J57 -> 0.89800889
B58: 18℃-飯糰 | C58: 一配鮭魚奶油醬油飯糰 | E58: 18.53 | F58: 2484 | G58: =E58*F58 -> 46028.52 | I58: 3 | J58: 3300 | K58: =J58/I58 -> 1100 | L58: 3 | M58: =F58/V58*60 -> 2964.004 | N58: =M58/L58 -> 988.00133 | O58: =L58-I58 -> 0 | P58: =N58-K58 -> -111.99867 | Q58: =N58/K58 -> 0.89818302 | S58: 0.34722222 | T58: 0.3821412 | U58: 5 | V58: 50.283333 | AA58: =M58-J58 -> -335.99602 | AB58: =M58/J58 -> 0.89818302
B72: 平均 | I72: =AVERAGE(I56:I71) -> 4 | J72: =AVERAGE(J56:J71) -> 3300 | K72: =J72/I72 -> 825 | L72: =AVERAGE(L56:L71) -> 4 | M72: =AVERAGE(M56:M71) -> 2963.4256 | N72: =M72/L72 -> 740.8564 | O72: =L72-I72 -> 0 | P72: =N72-K72 -> -84.143596 | Q72: =N72/K72 -> 0.89800776 | S72: =S56 -> 0.29166667 | T72: =INDEX(T56:T71,COUNTA(T56:T71)) -> 0.3821412 | AA72: =M72-J72 -> -336.57438 | AB72: =M72/J72 -> 0.89800776
A73: GKK3600型 飯糰機 | B73: 18℃-飯糰 | C73: 一配蔬食鮪魚飯糰 | E73: 18.18 | F73: 817 | G73: =E73*F73 -> 14853.06 | I73: 3 | J73: 3600 | K73: =J73/I73 -> 1200 | L73: 3 | M73: =F73/V73*60 -> 3145.6684 | N73: =M73/L73 -> 1048.5561 | O73: =L73-I73 -> 0 | P73: =N73-K73 -> -151.44385 | Q73: =N73/K73 -> 0.87379679 | R73: =Q89 -> 0.88098361 | S73: 0.29195602 | T73: 0.30277778 | V73: 15.583333 | AA73: =M73-J73 -> -454.33155 | AB73: =M73/J73 -> 0.87379679 | AC73: =AB89 -> 0.88098361
B74: 18℃-飯糰 | C74: 一配經典肉鬆飯糰 | E74: 14.03 | F74: 3312 | G74: =E74*F74 -> 46467.36 | I74: 3 | J74: 3000 | K74: =J74/I74 -> 1000 | L74: 3 | M74: =F74/V74*60 -> 2693.2912 | N74: =M74/L74 -> 897.76372 | O74: =L74-I74 -> 0 | P74: =N74-K74 -> -102.23628 | Q74: =N74/K74 -> 0.89776372 | S74: 0.31403935 | T74: 0.36527778 | U74: 16.216667 | V74: 73.783333 | AA74: =M74-J74 -> -306.70883 | AB74: =M74/J74 -> 0.89776372
B75: 18℃-飯糰 | C75: 一配鮪魚飯糰 | E75: 14.28 | F75: 4301 | G75: =E75*F75 -> 61418.28 | I75: 3 | J75: 3600 | K75: =J75/I75 -> 1200 | L75: 3 | M75: =F75/V75*60 -> 3147.0732 | N75: =M75/L75 -> 1049.0244 | O75: =L75-I75 -> 0 | P75: =N75-K75 -> -150.97561 | Q75: =N75/K75 -> 0.87418699 | S75: 0.37569444 | T75: 0.43263889 | U75: 15 | V75: 82 | AA75: =M75-J75 -> -452.92683 | AB75: =M75/J75 -> 0.87418699
B89: 平均 | I89: =AVERAGE(I73:I88) -> 3 | J89: =AVERAGE(J73:J88) -> 3400 | K89: =J89/I89 -> 1133.3333 | L89: =AVERAGE(L73:L88) -> 3 | M89: =AVERAGE(M73:M88) -> 2995.3443 | N89: =M89/L89 -> 998.44809 | O89: =L89-I89 -> 0 | P89: =N89-K89 -> -134.88525 | Q89: =N89/K89 -> 0.88098361 | S89: =S73 -> 0.29195602 | T89: =INDEX(T73:T88,COUNTA(T73:T88)) -> 0.43263889 | AA89: =M89-J89 -> -404.65574 | AB89: =M89/J89 -> 0.88098361
A90: GKK3600型 飯糰機2 | B90: 18℃-飯糰 | C90: 一配熟成紅鮭飯糰 | E90: 25.03 | F90: 971 | G90: =E90*F90 -> 24304.13 | I90: 4 | J90: 3300 | K90: =J90/I90 -> 825 | L90: 4 | M90: =F90/V90*60 -> 2935.0126 | N90: =M90/L90 -> 733.75315 | O90: =L90-I90 -> 0 | P90: =N90-K90 -> -91.246851 | Q90: =N90/K90 -> 0.88939776 | R90: =Q106 -> 0.88698581 | S90: 0.29177083 | T90: 0.30555556 | V90: 19.85 | AA90: =M90-J90 -> -364.98741 | AB90: =M90/J90 -> 0.88939776 | AC90: =AB106 -> 0.88698581
B91: 18℃-飯糰 | C91: 一配北海道秋鮭親子飯糰 | E91: 24.82 | F91: 1325 | G91: =E91*F91 -> 32886.5 | I91: 4 | J91: 3300 | K91: =J91/I91 -> 825 | L91: 4 | M91: =F91/V91*60 -> 2933.5793 | N91: =M91/L91 -> 733.39483 | O91: =L91-I91 -> 0 | P91: =N91-K91 -> -91.605166 | Q91: =N91/K91 -> 0.88896344 | S91: 0.31597222 | T91: 0.33479167 | U91: 15 | V91: 27.1 | AA91: =M91-J91 -> -366.42066 | AB91: =M91/J91 -> 0.88896344
B92: 18℃-飯糰 | C92: 一配贅沢鮭魚肚飯糰 | E92: 30 | F92: 2032 | G92: =E92*F92 -> 60960 | I92: 3 | J92: 3000 | K92: =J92/I92 -> 1000 | L92: 3 | M92: =F92/V92*60 -> 2693.3726 | N92: =M92/L92 -> 897.79087 | O92: =L92-I92 -> 0 | P92: =N92-K92 -> -102.20913 | Q92: =N92/K92 -> 0.89779087 | S92: 0.34583333 | T92: 0.37726852 | U92: 15.9 | V92: 45.266667 | AA92: =M92-J92 -> -306.62739 | AB92: =M92/J92 -> 0.89779087
B93: 18℃-飯糰 | C93: 一配明太子龍蝦風味沙拉飯糰 | E93: 18.18 | F93: 1782 | G93: =E93*F93 -> 32396.76 | I93: 3 | J93: 3600 | K93: =J93/I93 -> 1200 | L93: 3 | M93: =F93/V93*60 -> 3146.2482 | N93: =M93/L93 -> 1048.7494 | O93: =L93-I93 -> 0 | P93: =N93-K93 -> -151.25061 | Q93: =N93/K93 -> 0.87395782 | S93: 0.38751157 | T93: 0.41111111 | U93: 14.75 | V93: 33.983333 | AA93: =M93-J93 -> -453.75184 | AB93: =M93/J93 -> 0.87395782
B106: 平均 | I106: =AVERAGE(I90:I105) -> 3.5 | J106: =AVERAGE(J90:J105) -> 3300 | K106: =J106/I106 -> 942.85714 | L106: =AVERAGE(L90:L105) -> 3.5 | M106: =AVERAGE(M90:M105) -> 2927.0532 | N106: =M106/L106 -> 836.30091 | O106: =L106-I106 -> 0 | P106: =N106-K106 -> -106.55624 | Q106: =N106/K106 -> 0.88698581 | S106: =S90 -> 0.29177083 | T106: =INDEX(T90:T105,COUNTA(T90:T105)) -> 0.41111111 | AA106: =M106-J106 -> -372.94683 | AB106: =M106/J106 -> 0.88698581
A107: 自動包裝機 (二配) | B107: 18℃-壽司手卷 | C107: 二配長野稻荷壽司 | E107: 25.64 | F107: 1315 | G107: =E107*F107 -> 33716.6 | I107: 11 | J107: 3600 | K107: =J107/I107 -> 327.27273 | L107: 11 | M107: =F107/V107*60 -> 3175.0503 | N107: =M107/L107 -> 288.64094 | O107: =L107-I107 -> 0 | P107: =N107-K107 -> -38.631791 | Q107: =N107/K107 -> 0.88195842 | R107: =Q123 -> 0.87375048 | S107: 0.7084375 | T107: 0.72569444 | V107: 24.85 | AA107: =M107-J107 -> -424.9497 | AB107: =M107/J107 -> 0.88195842 | AC107: =AB123 -> 0.87375048
B108: 18℃-壽司手卷 | C108: 二配雙饗雙手卷 | E108: 29.52 | F108: 1640 | G108: =E108*F108 -> 48412.8 | I108: 12 | J108: 3600 | K108: =J108/I108 -> 300 | L108: 12 | M108: =F108/V108*60 -> 3142.0969 | N108: =M108/L108 -> 261.84141 | O108: =L108-I108 -> 0 | P108: =N108-K108 -> -38.158595 | Q108: =N108/K108 -> 0.87280468 | S108: 0.72916667 | T108: 0.75091435 | U108: 5 | V108: 31.316667 | AA108: =M108-J108 -> -457.90314 | AB108: =M108/J108 -> 0.87280468
B109: 18℃-壽司手卷 | C109: 二配海饌雙手卷 | E109: 29.85 | F109: 1825 | G109: =E109*F109 -> 54476.25 | I109: 12 | J109: 3600 | K109: =J109/I109 -> 300 | L109: 12 | M109: =F109/V109*60 -> 3140.5354 | N109: =M109/L109 -> 261.71128 | O109: =L109-I109 -> 0 | P109: =N109-K109 -> -38.288719 | Q109: =N109/K109 -> 0.87237094 | S109: 0.75425926 | T109: 0.77847222 | U109: 4.8166667 | V109: 34.866667 | AA109: =M109-J109 -> -459.46463 | AB109: =M109/J109 -> 0.87237094
B110: 18℃-飯糰 | C110: 二配兩粒飯糰(鮪魚.焦糖鮭魚) | E110: 28.57 | F110: 1445 | G110: =E110*F110 -> 41283.65 | I110: 12 | J110: 3600 | K110: =J110/I110 -> 300 | L110: 12 | M110: =F110/V110*60 -> 3124.3243 | N110: =M110/L110 -> 260.36036 | O110: =L110-I110 -> 0 | P110: =N110-K110 -> -39.63964 | Q110: =N110/K110 -> 0.86786787 | S110: 0.7828125 | T110: 0.80208333 | U110: 6.25 | V110: 27.75 | AA110: =M110-J110 -> -475.67568 | AB110: =M110/J110 -> 0.86786787
B123: 平均 | I123: =AVERAGE(I107:I122) -> 11.75 | J123: =AVERAGE(J107:J122) -> 3600 | K123: =J123/I123 -> 306.38298 | L123: =AVERAGE(L107:L122) -> 11.75 | M123: =AVERAGE(M107:M122) -> 3145.5017 | N123: =M123/L123 -> 267.70227 | O123: =L123-I123 -> 0 | P123: =N123-K123 -> -38.680705 | Q123: =N123/K123 -> 0.87375048 | S123: =S107 -> 0.7084375 | T123: =INDEX(T107:T122,COUNTA(T107:T122)) -> 0.80208333 | AA123: =M123-J123 -> -454.49829 | AB123: =M123/J123 -> 0.87375048
A124: (舊) 3300型飯糰線 (二配) | B124: 18℃-飯糰 | C124: 二配大飯糰滷肉飯加蛋 | E124: 22.48 | F124: 1387 | G124: =E124*F124 -> 31179.76 | I124: 5 | J124: 3000 | K124: =J124/I124 -> 600 | L124: 5 | M124: =F124/V124*60 -> 2673.0193 | N124: =M124/L124 -> 534.60385 | O124: =L124-I124 -> 0 | P124: =N124-K124 -> -65.396146 | Q124: =N124/K124 -> 0.89100642 | R124: =Q140 -> 0.89533823 | S124: 0.70833333 | T124: 0.7299537 | V124: 31.133333 | AA124: =M124-J124 -> -326.98073 | AB124: =M124/J124 -> 0.89100642 | AC124: =AB140 -> 0.89533823
B125: 18℃-飯糰 | C125: 二配大飯糰韓式蒜烤豬五花 | E125: 24.54 | F125: 2005 | G125: =E125*F125 -> 49202.7 | I125: 4 | J125: 3000 | K125: =J125/I125 -> 750 | L125: 4 | M125: =F125/V125*60 -> 2674.3238 | N125: =M125/L125 -> 668.58096 | O125: =L125-I125 -> 0 | P125: =N125-K125 -> -81.419044 | Q125: =N125/K125 -> 0.89144127 | S125: 0.73334491 | T125: 0.76458333 | U125: 4.8833333 | V125: 44.983333 | AA125: =M125-J125 -> -325.67618 | AB125: =M125/J125 -> 0.89144127
B126: 18℃-飯糰 | C126: 二配三杯醬爆菇菇飯糰 | E126: 16.7 | F126: 1360 | G126: =E126*F126 -> 22712 | I126: 3 | J126: 3300 | K126: =J126/I126 -> 1100 | L126: 3 | M126: =F126/V126*60 -> 2969.0722 | N126: =M126/L126 -> 989.69072 | O126: =L126-I126 -> 0 | P126: =N126-K126 -> -110.30928 | Q126: =N126/K126 -> 0.89971884 | S126: 0.76875 | T126: 0.78783565 | U126: 6 | V126: 27.483333 | AA126: =M126-J126 -> -330.92784 | AB126: =M126/J126 -> 0.89971884
B127: 18℃-飯糰 | C127: 二配鹽蔥燒肉飯糰 | E127: 17.89 | F127: 4962 | G127: =E127*F127 -> 88770.18 | I127: 4 | J127: 3300 | K127: =J127/I127 -> 825 | L127: 4 | M127: =F127/V127*60 -> 2964.8465 | N127: =M127/L127 -> 741.21162 | O127: =L127-I127 -> 0 | P127: =N127-K127 -> -83.788382 | Q127: =N127/K127 -> 0.89843833 | S127: 0.79097222 | T127: 0.86070602 | U127: 4.5166667 | V127: 100.41667 | AA127: =M127-J127 -> -335.15353 | AB127: =M127/J127 -> 0.89843833
B140: 平均 | I140: =AVERAGE(I124:I139) -> 4 | J140: =AVERAGE(J124:J139) -> 3150 | K140: =J140/I140 -> 787.5 | L140: =AVERAGE(L124:L139) -> 4 | M140: =AVERAGE(M124:M139) -> 2820.3154 | N140: =M140/L140 -> 705.07886 | O140: =L140-I140 -> 0 | P140: =N140-K140 -> -82.421142 | Q140: =N140/K140 -> 0.89533823 | S140: =S124 -> 0.70833333 | T140: =INDEX(T124:T139,COUNTA(T124:T139)) -> 0.86070602 | AA140: =M140-J140 -> -329.68457 | AB140: =M140/J140 -> 0.89533823
A141: (新) 3300型飯糰機 (二配) | B141: 18℃-飯糰 | C141: 二配壹號醬炙烤牛飯糰 | E141: 22.28 | F141: 1665 | G141: =E141*F141 -> 37096.2 | I141: 5 | J141: 3300 | K141: =J141/I141 -> 660 | L141: 5 | M141: =F141/V141*60 -> 2967.3267 | N141: =M141/L141 -> 593.46535 | O141: =L141-I141 -> 0 | P141: =N141-K141 -> -66.534653 | Q141: =N141/K141 -> 0.89918992 | R141: =Q157 -> 0.89869027 | S141: 0.70856481 | T141: 0.73194444 | V141: 33.666667 | AA141: =M141-J141 -> -332.67327 | AB141: =M141/J141 -> 0.89918992 | AC141: =AB157 -> 0.89869027
...

Sheet 0228(4度C)
A1: 大溪廠日報分析 | C1: 總生產量 | D1: =SUM(F5:F106) -> 43763 | E1: 營業額 | F1: =SUM(G5:G106) -> 2196950.5 | G1: 出勤人數 | H1: =L21+L38+L55+L72+L89+L106 -> 112.46667 | I1: 產線配置圖 | L1: 生產實績 | O1: 人時性差異分析 | S1: 日報登錄 | Y1: 合計次數 | Z1: 合計(時間/分) | AA1: 產線異常 分析說明(5分鐘以上) | AC1: 合計次數 | AD1: 合計(時間/分) | AE1: 產能差異分析
A2: 46081 | C2: 人時性 | D2: =AVERAGE(N21,N38,N55,N72,N89,N106) -> 151.16591 | E2: 平均廠價 | F2: =F1/D1 -> 50.201094 | G2: 多次生產數 | H2: =COUNT(H5:H106) -> 0 | Y2: =SUM(Y21,Y38,Y55,Y72,Y89,Y106) -> 0 | Z2: =SUM(Z21,Z38,Z55,Z72,Z89,Z106) -> 0 | AC2: =SUM(AC21,AC38,AC55,AC72,AC89,AC106) -> 0 | AD2: =SUM(AD21,AD38,AD55,AD72,AD89,AD106) -> 0
A3: 線別 | B3: 品類 | C3: 品名 | E3: 廠價 | F3: 生產量 | G3: 營收 | H3: 多次 生產 | I3: 人數 | J3: 產能/時 | K3: 人時性 | L3: 人數 | M3: 產能/時 | N3: 人時性 | O3: 人數 | P3: 人時性 | Q3: 達成率 | R3: 達成率 平均 | S3: 生產時間 | U3: 換線、休息/分 | V3: 稼動時間/分 | W3: 休息時間 | Y3: 產線異常統計(5分鐘以上) | AA3: (屏榮回填) | AC3: 短暫停線統計(5分鐘以下) | AE3: 產能/時 | AF3: 達成率 | AG3: 達成率平均
S4: 開始 | T4: 結束 | W4: 開始 | X4: 結束 | Y4: 次數 | Z4: 時間/分 | AC4: 總次數 | AD4: 設備因素(次數)
A5: 涼麵一線 | B5: 便當 | C5: 經典滷肉飯 | E5: 47.37 | F5: 1966 | G5: =E5*F5 -> 93129.42 | I5: 21 | J5: 2000 | K5: =J5/I5 -> 95.238095 | L5: 21 | M5: =F5/V5*60 -> 1782.3218 | N5: =M5/L5 -> 84.872468 | O5: =L5-I5 -> 0 | P5: =N5-K5 -> -10.365627 | Q5: =N5/K5 -> 0.89116092 | R5: =Q21 -> 0.89619071 | S5: 0.25 | T5: 0.29596065 | V5: 66.183333 | AE5: =M5-J5 -> -217.67817 | AF5: =M5/J5 -> 0.89116092 | AG5: =AF21 -> 0.90456632
B6: 便當 | C6: 蔬活腿排補力餐盒 | E6: 71.55 | F6: 1871 | G6: =E6*F6 -> 133870.05 | I6: 22 | J6: 2000 | K6: =J6/I6 -> 90.909091 | L6: 22 | M6: =F6/V6*60 -> 1784.2649 | N6: =M6/L6 -> 81.10295 | O6: =L6-I6 -> 0 | P6: =N6-K6 -> -9.8061409 | Q6: =N6/K6 -> 0.89213245 | S6: 0.29936343 | T6: 0.34305556 | U6: 4.9 | V6: 62.916667 | AE6: =M6-J6 -> -215.7351 | AF6: =M6/J6 -> 0.89213245
B7: 便當 | C7: 海陸雙拼肉肉餐盒 | E7: 59.54 | F7: 2210 | G7: =E7*F7 -> 131583.4 | I7: 23 | J7: 2000 | K7: =J7/I7 -> 86.956522 | L7: 23 | M7: =F7/V7*60 -> 1782.2581 | N7: =M7/L7 -> 77.489481 | O7: =L7-I7 -> 0 | P7: =N7-K7 -> -9.4670407 | Q7: =N7/K7 -> 0.89112903 | S7: 0.34652778 | T7: 0.39819444 | U7: 5 | V7: 74.4 | AE7: =M7-J7 -> -217.74194 | AF7: =M7/J7 -> 0.89112903
B8: 便當 | C8: 香腸腿排雙拼便當 | E8: 53.76 | F8: 2486 | G8: =E8*F8 -> 133647.36 | I8: 20 | J8: 2000 | K8: =J8/I8 -> 100 | L8: 20 | M8: =F8/V8*60 -> 1784.5663 | N8: =M8/L8 -> 89.228315 | O8: =L8-I8 -> 0 | P8: =N8-K8 -> -10.771685 | Q8: =N8/K8 -> 0.89228315 | S8: 0.40237269 | T8: 0.46041667 | U8: 6.0166667 | V8: 83.583333 | W8: 0.46041667 | X8: 0.49861111 | AE8: =M8-J8 -> -215.4337 | AF8: =M8/J8 -> 0.89228315
B9: 4℃-飯糰 | C9: 麻油雞飯糰 | E9: 29.97 | F9: 2119 | G9: =E9*F9 -> 63506.43 | I9: 21 | J9: 2790 | K9: =J9/I9 -> 132.85714 | L9: 22 | M9: =F9/V9*60 -> 2626.8595 | N9: =M9/L9 -> 119.4027 | O9: =L9-I9 -> 1 | P9: =N9-K9 -> -13.454438 | Q9: =N9/K9 -> 0.89873004 | S9: 0.49861111 | T9: 0.53222222 | U9: 55 | V9: 48.4 | AE9: =M9-J9 -> -163.1405 | AF9: =M9/J9 -> 0.9415267
B21: 平均 | I21: =AVERAGE(I5:I20) -> 21.4 | J21: =AVERAGE(J5:J20) -> 2158 | K21: =J21/I21 -> 100.84112 | L21: =AVERAGE(L5:L20) -> 21.6 | M21: =AVERAGE(M5:M20) -> 1952.0541 | N21: =M21/L21 -> 90.372876 | O21: =L21-I21 -> 0.2 | P21: =N21-K21 -> -10.468246 | Q21: =N21/K21 -> 0.89619071 | S21: =S5 -> 0.25 | T21: =INDEX(T5:T20,COUNTA(T5:T20)) -> 0.53222222 | Y21: =SUM(Y5:Y20) -> 0 | Z21: =SUM(Z5:Z20) -> 0 | AC21: =SUM(AC5:AC20) -> 0 | AD21: =SUM(AD5:AD20) -> 0 | AE21: =M21-J21 -> -205.94588 | AF21: =M21/J21 -> 0.90456632
A22: 涼麵二線 | B22: 微波主食 | C22: 糖燻野郎三十天熟成牛飯 | E22: 56.77 | F22: 3911 | G22: =E22*F22 -> 222027.47 | I22: 25 | J22: 2000 | K22: =J22/I22 -> 80 | L22: 25 | M22: =F22/V22*60 -> 1782.6792 | N22: =M22/L22 -> 71.307166 | O22: =L22-I22 -> 0 | P22: =N22-K22 -> -8.6928336 | Q22: =N22/K22 -> 0.89133958 | R22: =Q38 -> 0.89175204 | S22: 0.25025463 | T22: 0.34166667 | V22: 131.63333 | AE22: =M22-J22 -> -217.32084 | AF22: =M22/J22 -> 0.89133958 | AG22: =AF38 -> 0.89175204
B23: 便當 | C23: 嫩烤香料雞胸排蔬滿盒 | E23: 77.34 | F23: 1567 | G23: =E23*F23 -> 121191.78 | I23: 24 | J23: 2000 | K23: =J23/I23 -> 83.333333 | L23: 24 | M23: =F23/V23*60 -> 1784.6251 | N23: =M23/L23 -> 74.35938 | O23: =L23-I23 -> 0 | P23: =N23-K23 -> -8.9739534 | Q23: =N23/K23 -> 0.89231256 | S23: 0.3453588 | T23: 0.38194444 | U23: 5.3166667 | V23: 52.683333 | AE23: =M23-J23 -> -215.37488 | AF23: =M23/J23 -> 0.89231256
B24: 便當 | C24: 健身G肉餐盒 | E24: 59.52 | F24: 3353 | G24: =E24*F24 -> 199570.56 | I24: 25 | J24: 2000 | K24: =J24/I24 -> 80 | L24: 25 | M24: =F24/V24*60 -> 1783.5106 | N24: =M24/L24 -> 71.340426 | O24: =L24-I24 -> 0 | P24: =N24-K24 -> -8.6595745 | Q24: =N24/K24 -> 0.89175532 | S24: 0.38625 | T24: 0.46458333 | U24: 6.2 | V24: 112.8 | W24: 0.46458333 | X24: 0.50366898 | AE24: =M24-J24 -> -216.48936 | AF24: =M24/J24 -> 0.89175532
B25: 便當 | C25: 美式雞丁餐盒 | E25: 59.34 | F25: 1122 | G25: =E25*F25 -> 66579.48 | I25: 24 | J25: 2000 | K25: =J25/I25 -> 83.333333 | L25: 24 | M25: =F25/V25*60 -> 1784.8873 | N25: =M25/L25 -> 74.370305 | O25: =L25-I25 -> 0 | P25: =N25-K25 -> -8.9630284 | Q25: =N25/K25 -> 0.89244366 | S25: 0.50366898 | T25: 0.52986111 | U25: 56.283333 | V25: 37.716667 | AE25: =M25-J25 -> -215.11268 | AF25: =M25/J25 -> 0.89244366
B26: 便當 | C26: 烤蛋白餐盒 | E26: 58.67 | F26: 2548 | G26: =E26*F26 -> 149491.16 | I26: 23 | J26: 2000 | K26: =J26/I26 -> 86.956522 | L26: 23 | M26: =F26/V26*60 -> 1781.8182 | N26: =M26/L26 -> 77.470356 | O26: =L26-I26 -> 0 | P26: =N26-K26 -> -9.486166 | Q26: =N26/K26 -> 0.89090909 | S26: 0.53347222 | T26: 0.59305556 | U26: 5.2 | V26: 85.8 | AE26: =M26-J26 -> -218.18182 | AF26: =M26/J26 -> 0.89090909
B38: 平均 | I38: =AVERAGE(I22:I37) -> 24.2 | J38: =AVERAGE(J22:J37) -> 2000 | K38: =J38/I38 -> 82.644628 | L38: =AVERAGE(L22:L37) -> 24.2 | M38: =AVERAGE(M22:M37) -> 1783.5041 | N38: =M38/L38 -> 73.698516 | O38: =L38-I38 -> 0 | P38: =N38-K38 -> -8.9461123 | Q38: =N38/K38 -> 0.89175204 | S38: =S22 -> 0.25025463 | T38: =INDEX(T22:T37,COUNTA(T22:T37)) -> 0.59305556 | Y38: =SUM(Y22:Y37) -> 0 | Z38: =SUM(Z22:Z37) -> 0 | AC38: =SUM(AC22:AC37) -> 0 | AD38: =SUM(AD22:AD37) -> 0 | AE38: =M38-J38 -> -216.49592 | AF38: =M38/J38 -> 0.89175204
A39: 涼麵三線 | B39: 微波小吃 | C39: 日式茶碗蒸 | E39: 19.7 | F39: 3405 | G39: =E39*F39 -> 67078.5 | I39: 13 | J39: 1200 | K39: =J39/I39 -> 92.307692 | L39: 13 | M39: =F39/V39*60 -> 1079.6195 | N39: =M39/L39 -> 83.047655 | O39: =L39-I39 -> 0 | P39: =N39-K39 -> -9.2600371 | Q39: =N39/K39 -> 0.89968293 | R39: =Q55 -> 0.89460802 | S39: 0.25 | T39: 0.38141204 | V39: 189.23333 | AE39: =M39-J39 -> -120.38048 | AF39: =M39/J39 -> 0.89968293 | AG39: =AF55 -> 0.89460802
B40: 季節調理麵 | C40: 東京豚骨風味拉麵 | E40: 71.84 | F40: 980 | G40: =E40*F40 -> 70403.2 | I40: 19 | J40: 1800 | K40: =J40/I40 -> 94.736842 | L40: 19 | M40: =F40/V40*60 -> 1607.2893 | N40: =M40/L40 -> 84.594173 | O40: =L40-I40 -> 0 | P40: =N40-K40 -> -10.142669 | Q40: =N40/K40 -> 0.8929385 | S40: 0.38501157 | T40: 0.41041667 | U40: 5.1833333 | V40: 36.583333 | AE40: =M40-J40 -> -192.71071 | AF40: =M40/J40 -> 0.8929385
B41: 微波小吃 | C41: 韓式部隊鍋 | E41: 57.73 | F41: 1288 | G41: =E41*F41 -> 74356.24 | I41: 22 | J41: 1800 | K41: =J41/I41 -> 81.818182 | L41: 22 | M41: =F41/V41*60 -> 1607.2097 | N41: =M41/L41 -> 73.054987 | O41: =L41-I41 -> 0 | P41: =N41-K41 -> -8.7631952 | Q41: =N41/K41 -> 0.89289428 | S41: 0.41388889 | T41: 0.44728009 | U41: 5 | V41: 48.083333 | AE41: =M41-J41 -> -192.79029 | AF41: =M41/J41 -> 0.89289428
B55: 平均 | I55: =AVERAGE(I39:I54) -> 18 | J55: =AVERAGE(J39:J54) -> 1600 | K55: =J55/I55 -> 88.888889 | L55: =AVERAGE(L39:L54) -> 18 | M55: =AVERAGE(M39:M54) -> 1431.3728 | N55: =M55/L55 -> 79.520713 | O55: =L55-I55 -> 0 | P55: =N55-K55 -> -9.3681756 | Q55: =N55/K55 -> 0.89460802 | S55: =S39 -> 0.25 | T55: =INDEX(T39:T54,COUNTA(T39:T54)) -> 0.44728009 | Y55: =SUM(Y39:Y54) -> 0 | Z55: =SUM(Z39:Z54) -> 0 | AC55: =SUM(AC39:AC54) -> 0 | AD55: =SUM(AD39:AD54) -> 0 | AE55: =M55-J55 -> -168.62716 | AF55: =M55/J55 -> 0.89460802
A56: 自動包裝機 | B56: 4℃-壽司手卷 | C56: 香料咖哩烤雞飯卷 | E56: 26.21 | F56: 1797 | G56: =E56*F56 -> 47099.37 | I56: 6 | J56: 3273 | K56: =J56/I56 -> 545.5 | L56: 6 | M56: =F56/V56*60 -> 2856.1589 | N56: =M56/L56 -> 476.02649 | O56: =L56-I56 -> 0 | P56: =N56-K56 -> -69.47351 | Q56: =N56/K56 -> 0.87264251 | R56: =Q72 -> 0.8838766 | S56: 0.40295139 | T56: 0.42916667 | U56: 6.0166667 | V56: 37.75 | AE56: =M56-J56 -> -416.84106 | AF56: =M56/J56 -> 0.87264251 | AG56: =AF72 -> 0.8838766
B57: 4℃-飯糰 | C57: 蟹味可樂餅風炸飯糰 | E57: 21.92 | F57: 2452 | G57: =E57*F57 -> 53747.84 | I57: 6 | J57: 3600 | K57: =J57/I57 -> 600 | L57: 6 | M57: =F57/V57*60 -> 3149.1973 | N57: =M57/L57 -> 524.86621 | O57: =L57-I57 -> 0 | P57: =N57-K57 -> -75.133785 | Q57: =N57/K57 -> 0.87477702 | S57: 0.43283565 | T57: 0.46527778 | U57: 5.2833333 | V57: 46.716667 | AE57: =M57-J57 -> -450.80271 | AF57: =M57/J57 -> 0.87477702
B58: 4℃-壽司手卷 | C58: 明太子泡菜牛飯卷 | E58: 27.05 | F58: 697 | G58: =E58*F58 -> 18853.85 | I58: 6 | J58: 3273 | K58: =J58/I58 -> 545.5 | L58: 6 | M58: =F58/V58*60 -> 2962.4557 | N58: =M58/L58 -> 493.74262 | O58: =L58-I58 -> 0 | P58: =N58-K58 -> -51.757379 | Q58: =N58/K58 -> 0.90511938 | S58: 0.46875 | T58: 0.47855324 | U58: 5 | V58: 14.116667 | AE58: =M58-J58 -> -310.54427 | AF58: =M58/J58 -> 0.90511938
B72: 平均 | I72: =AVERAGE(I56:I71) -> 6 | J72: =AVERAGE(J56:J71) -> 3382 | K72: =J72/I72 -> 563.66667 | L72: =AVERAGE(L56:L71) -> 6 | M72: =AVERAGE(M56:M71) -> 2989.2707 | N72: =M72/L72 -> 498.21178 | O72: =L72-I72 -> 0 | P72: =N72-K72 -> -65.454891 | Q72: =N72/K72 -> 0.8838766 | S72: =S56 -> 0.40295139 | T72: =INDEX(T56:T71,COUNTA(T56:T71)) -> 0.47855324 | Y72: =SUM(Y56:Y71) -> 0 | Z72: =SUM(Z56:Z71) -> 0 | AC72: =SUM(AC56:AC71) -> 0 | AD72: =SUM(AD56:AD71) -> 0 | AE72: =M72-J72 -> -392.72935 | AF72: =M72/J72 -> 0.8838766
A73: 涼麵一線 (二配) | B73: 微波主食 | C73: 二配里肌豬排可可咖哩歐姆蛋飯 | E73: 56.79 | F73: 1955 | G73: =E73*F73 -> 111024.45 | I73: 23 | J73: 2000 | K73: =J73/I73 -> 86.956522 | L73: 23 | M73: =F73/V73*60 -> 1783.5783 | N73: =M73/L73 -> 77.546883 | O73: =L73-I73 -> 0 | P73: =N73-K73 -> -9.4096388 | Q73: =N73/K73 -> 0.89178915 | R73: =Q89 -> 0.8913141 | S73: 0.70849537 | T73: 0.75416667 | V73: 65.766667 | AE73: =M73-J73 -> -216.42169 | AF73: =M73/J73 -> 0.89178915 | AG73: =AF89 -> 0.8913141
B74: 微波主食 | C74: 二配黃金雞排蘑菇白醬歐姆蛋飯 | E74: 56.87 | F74: 1589 | G74: =E74*F74 -> 90366.43 | I74: 23 | J74: 2000 | K74: =J74/I74 -> 86.956522 | L74: 23 | M74: =F74/V74*60 -> 1782.6114 | N74: =M74/L74 -> 77.504844 | O74: =L74-I74 -> 0 | P74: =N74-K74 -> -9.451678 | Q74: =N74/K74 -> 0.8913057 | S74: 0.75763889 | T74: 0.79478009 | U74: 5 | V74: 53.483333 | AE74: =M74-J74 -> -217.38859 | AF74: =M74/J74 -> 0.8913057
B75: 微波主食 | C75: 二配哞哞培根奶香海陸焗飯 | E75: 47.6 | F75: 1752 | G75: =E75*F75 -> 83395.2 | I75: 23 | J75: 2000 | K75: =J75/I75 -> 86.956522 | L75: 23 | M75: =F75/V75*60 -> 1781.6949 | N75: =M75/L75 -> 77.464996 | O75: =L75-I75 -> 0 | P75: =N75-K75 -> -9.4915254 | Q75: =N75/K75 -> 0.89084746 | S75: 0.79791667 | T75: 0.83888889 | U75: 4.5166667 | V75: 59 | AE75: =M75-J75 -> -218.30508 | AF75: =M75/J75 -> 0.89084746
B89: 平均 | I89: =AVERAGE(I73:I88) -> 23 | J89: =AVERAGE(J73:J88) -> 2000 | K89: =J89/I89 -> 86.956522 | L89: =AVERAGE(L73:L88) -> 23 | M89: =AVERAGE(M73:M88) -> 1782.6282 | N89: =M89/L89 -> 77.505574 | O89: =L89-I89 -> 0 | P89: =N89-K89 -> -9.4509474 | Q89: =N89/K89 -> 0.8913141 | S89: =S73 -> 0.70849537 | T89: =INDEX(T73:T88,COUNTA(T73:T88)) -> 0.83888889 | Y89: =SUM(Y73:Y88) -> 0 | Z89: =SUM(Z73:Z88) -> 0 | AC89: =SUM(AC73:AC88) -> 0 | AD89: =SUM(AD73:AD88) -> 0 | AE89: =M89-J89 -> -217.37179 | AF89: =M89/J89 -> 0.8913141
A90: 涼麵二線 (二配) | B90: 微波主食 | C90: 二配西班牙風味海鮮燉飯 | E90: 57.3 | F90: 1591 | G90: =E90*F90 -> 91164.3 | I90: 21 | J90: 2000 | K90: =J90/I90 -> 95.238095 | L90: 21 | M90: =F90/V90*60 -> 1784.8551 | N90: =M90/L90 -> 84.9931 | O90: =L90-I90 -> 0 | P90: =N90-K90 -> -10.244995 | Q90: =N90/K90 -> 0.89242755 | R90: =Q106 -> 0.8919782 | S90: 0.70833333 | T90: 0.74547454 | V90: 53.483333 | AE90: =M90-J90 -> -215.1449 | AF90: =M90/J90 -> 0.89242755 | AG90: =AF106 -> 0.8919782
B91: 微波主食 | C91: 二配失控起司薯餅焗飯 | E91: 54.09 | F91: 1396 | G91: =E91*F91 -> 75509.64 | I91: 19 | J91: 2000 | K91: =J91/I91 -> 105.26316 | L91: 19 | M91: =F91/V91*60 -> 1784.0256 | N91: =M91/L91 -> 93.896082 | O91: =L91-I91 -> 0 | P91: =N91-K91 -> -11.367076 | Q91: =N91/K91 -> 0.89201278 | S91: 0.74864583 | T91: 0.78125 | U91: 4.5666667 | V91: 46.95 | AE91: =M91-J91 -> -215.97444 | AF91: =M91/J91 -> 0.89201278
B92: 微波主食 | C92: 二配蒙古風味烤肉飯 | E92: 58.17 | F92: 1708 | G92: =E92*F92 -> 99354.36 | I92: 19 | J92: 1800 | K92: =J92/I92 -> 94.736842 | L92: 19 | M92: =F92/V92*60 -> 1604.5929 | N92: =M92/L92 -> 84.452258 | O92: =L92-I92 -> 0 | P92: =N92-K92 -> -10.284584 | Q92: =N92/K92 -> 0.8914405 | S92: 0.78481481 | T92: 0.82916667 | U92: 5.1333333 | V92: 63.866667 | AE92: =M92-J92 -> -195.4071 | AF92: =M92/J92 -> 0.8914405
B106: 平均 | I106: =AVERAGE(I90:I105) -> 19.666667 | J106: =AVERAGE(J90:J105) -> 1933.3333 | K106: =J106/I106 -> 98.305085 | L106: =AVERAGE(L90:L105) -> 19.666667 | M106: =AVERAGE(M90:M105) -> 1724.4912 | N106: =M106/L106 -> 87.685992 | O106: =L106-I106 -> 0 | P106: =N106-K106 -> -10.619092 | Q106: =N106/K106 -> 0.8919782 | S106: =S90 -> 0.70833333 | T106: =INDEX(T90:T105,COUNTA(T90:T105)) -> 0.82916667 | Y106: =SUM(Y90:Y105) -> 0 | Z106: =SUM(Z90:Z105) -> 0 | AC106: =SUM(AC90:AC105) -> 0 | AD106: =SUM(AD90:AD105) -> 0 | AE106: =M106-J106 -> -208.84215 | AF106: =M106/J106 -> 0.8919782
AA108: 原因回覆
AA109: 1.當日出勤人數較多
AA110: 2.當日出勤人數較少
AA111: 3.當日出勤熟手較多
AA112: 4.當日出勤新人較多
AA113: 5.機台夾盒
AA114: 6.封膜不順
AA115: 7.更換膠膜
...

Sheet 0227
B1: 屏榮 大溪廠組合室生產人時性分析
B3: 日期 | C3: 115.02.27星期五 | E3: 訂單量 | F3: ='0227(18度C)'!D1+'0227(4度C)'!D1 -> 120519 | H3: 營業額 | I3: ='0227(18度C)'!F1+'0227(4度C)'!F1 -> 3610052.1
B4: 人時性 | C4: 項目 | E4: ➀ | G4: ➁ | I4: ➂ | K4: ④ | M4: ⑤ | O4: 異常停線 | Q4: 短暫停線
C5: 組合室 | E5: 全溫層 | G5: 4度C-各編組展開(一配) | I5: 4度C-各編組展開(二配) | K5: 18度C-各編組展開(一配) | M5: 18度C-各編組展開(二配) | O5: 合計次數 | P5: 時間 | Q5: 合計次數 | R5: 設備次數
C6: 排關平均 | E6: =AVERAGE(D14:O14,D32:X32) -> 547.89053 | F6: =AVERAGE(#REF!,D14:K14) -> #REF! | G6: =AVERAGE(D14:K14) -> 209.41934 | I6: =AVERAGE(L14:O14) -> 92.630803 | K6: =AVERAGE(D32:O32) -> 733.74087 | M6: =AVERAGE(P32:X32) -> 777.75095 | O6: ='0227(4度C)'!Y2 -> 0 | P6: ='0227(4度C)'!Z2 -> 0 | Q6: ='0227(4度C)'!AC2 -> 0 | R6: ='0227(4度C)'!AD2 -> 0
C7: 實績平均 | E7: =AVERAGE(D15:O15,D33:X33) -> 486.84866 | F7: =AVERAGE(#REF!,D15:K15) -> #REF! | G7: =AVERAGE(D15:K15) -> 184.3156 | I7: =AVERAGE(L15:O15) -> 82.585037 | K7: =AVERAGE(D33:O33) -> 652.95164 | M7: =AVERAGE(P33:X33) -> 691.257
C8: 達成率平均 | E8: =AVERAGE(D16:O16,D34:X34) -> 0.88907453 | F8: =AVERAGE(D16:K16,#REF!) -> #REF! | G8: =AVERAGE(D16:K16) -> 0.88882476 | I8: =AVERAGE(L16:O16) -> 0.8915329 | K8: =AVERAGE(D34:O34) -> 0.88978496 | M8: =AVERAGE(P34:X34) -> 0.88743846
O9: ※現行日本鮮食廠以達成率80%為基本(即為現行KPI)
B11: 溫層 | D11: ➁4度C-各編組展開 | L11: ➂4度C-各編組展開
B12: 編組 | D12: 1 | E12: 2 | F12: 3 | G12: 4 | H12: 5 | I12: 6 | J12: 7 | K12: 8 | L12: 1 | M12: 2 | N12: 3 | O12: 4
D13: 便當一線 | E13: 便當二線 | F13: 涼麵一線 | G13: 涼麵二線 | H13: 涼麵三線 | I13: 自動包裝機 | J13: 自動包裝機2 | K13: 自動包裝機3 | L13: 便當一線 | M13: 便當二線 | N13: 涼麵一線 | O13: 涼麵二線
B14: 人時性 | C14: 排關 | D14: - | E14: - | F14: 100.84112 | G14: 82.758621 | H14: 90.410959 | I14: 563.66667 | J14: - | K14: - | L14: - | M14: - | N14: 86.956522 | O14: 98.305085
C15: 實績 | D15: - | E15: - | F15: 90.365626 | G15: 73.804502 | H15: 80.832742 | I15: 492.25952 | J15: - | K15: - | L15: - | M15: - | N15: 77.499654 | O15: 87.670419
C16: 達成率 | D16: - | E16: - | F16: =F15/F14 -> 0.89611881 | G16: =G15/G14 -> 0.8918044 | H16: =H15/H14 -> 0.89405911 | I16: =I15/I14 -> 0.87331672 | J16: - | K16: - | L16: - | M16: - | N16: =N15/N14 -> 0.89124602 | O16: =O15/O14 -> 0.89181978
B17: 作業 時間 | C17: 開始 | D17: - | E17: - | F17: 0.25 | G17: 0.25 | H17: 0.25006944 | I17: 0.40925926 | J17: - | K17: - | L17: - | M17: - | N17: 0.70861111 | O17: 0.70842593
C18: 結束 | D18: - | E18: - | F18: 0.50555556 | G18: 0.57847222 | H18: 0.45902778 | I18: 0.47640046 | J18: - | K18: - | L18: - | M18: - | N18: 0.8225 | O18: 0.81130787
B19: 產線異常 (5分鐘以上) | C19: 次數
C20: 時間/分
B21: 短暫停線 (5分鐘以下) | C21: 次數
C22: 設備次數
B23: 配置人數 | D23: - | E23: - | F23: 21.6 | G23: 24.166667 | H23: 18.25 | I23: 6 | J23: - | K23: - | L23: - | M23: - | N23: 23 | O23: 19.666667
B24: 主要應用設備 | D24: L型封口機 | E24: ET-55 | F24: ET-55 | G24: ET-55 | H24: ET-600 | I24: 伺服包裝機 | J24: 伺服包裝機 | K24: 伺服包裝機 | L24: L型封口機 | M24: ET-55 | N24: ET-55 | O24: ET-55
B25: 次要應用設備 | D25: 伺服包裝機 | H25: 伺服包裝機
B26: 備註 | H26: 涼麵+烤飯糰 | I26: 大口飯糰線 | K26: 烤飯糰+手卷
B29: 溫層 | D29: ➃18度C-各編組展開 (一配) | P29: ⑤18度C-各編組展開 (二配)
B30: 編組 | D30: 1 | E30: 2 | F30: 3 | G30: 4 | H30: 5 | I30: 6 | J30: 7 | K30: 8 | L30: 9 | M30: 10 | N30: 11 | O30: 12 | P30: 1 | Q30: 2 | R30: 3 | S30: 4 | T30: 5 | U30: 6 | V30: 7 | W30: 8 | X30: 9
D31: 便當一線 | E31: 涼麵一線 | F31: 涼麵三線 | G31: 自動包裝機 | H31: 自動包裝機2 | I31: 自動包裝機3 | J31: 味付飯糰線B | K31: (舊) 3300型飯糰線 | L31: 3000型飯糰線 | M31: (新) 3300型飯糰機 | N31: GKK3600型 飯糰機 | O31: GKK3600型 飯糰機2 | P31: 自動包裝機 | Q31: 自動包裝機2 | R31: 自動包裝機3 | S31: 味付飯糰線B | T31: (舊) 3300型飯糰線 | U31: 3000型飯糰線 | V31: (新) 3300型飯糰機 | W31: GKK3600型 飯糰機 | X31: GKK3600型 飯糰機2
B32: 人時性 | C32: 排關 | D32: - | E32: - | F32: - | G32: 306.38298 | H32: 433.33333 | I32: - | J32: - | K32: 761.53846 | L32: - | M32: 825 | N32: 1133.3333 | O32: 942.85714 | P32: 306.38298 | Q32: - | R32: - | S32: - | T32: 787.5 | U32: - | V32: 761.53846 | W32: 1100 | X32: 933.33333
C33: 實績 | D33: - | E33: - | F33: - | G33: 267.732 | H33: 390.13329 | I33: - | J33: - | K33: 684.61797 | L33: - | M33: 740.69247 | N33: 998.38735 | O33: 836.14677 | P33: 267.6914 | Q33: - | R33: - | S33: - | T33: 704.93353 | U33: - | V33: 684.27083 | W33: 974.08595 | X33: 825.30327
C34: 達成率 | D34: - | E34: - | F34: - | G34: =G33/G32 -> 0.87384748 | H34: =H33/H32 -> 0.9003076 | I34: - | J34: - | K34: =K33/K32 -> 0.89899329 | L34: - | M34: =M33/M32 -> 0.89780906 | N34: =N33/N32 -> 0.88093002 | O34: =O33/O32 -> 0.88682233 | P34: =P33/P32 -> 0.87371499 | Q34: - | R34: - | S34: - | T34: =T33/T32 -> 0.89515369 | U34: - | V34: =V33/V32 -> 0.89853745 | W34: =W33/W32 -> 0.88553268 | X34: =X33/X32 -> 0.8842535
B35: 作業 時間 | C35: 開始 | D35: - | E35: - | F35: - | G35: 0.30641204 | H35: 0.25018519 | I35: - | J35: - | K35: 0.39609954 | L35: - | M35: 0.29166667 | N35: 0.29195602 | O35: 0.29166667 | P35: 0.70849537 | Q35: - | R35: - | S35: - | T35: 0.70833333 | U35: - | V35: 0.70846065 | W35: 0.70833333 | X35: 0.70837963
C36: 結束 | D36: - | E36: - | F36: - | G36: 0.40555556 | H36: 0.28888889 | I36: - | J36: - | K36: 0.47916667 | L36: - | M36: 0.38541667 | N36: 0.43472222 | O36: 0.4125 | P36: 0.80012731 | Q36: - | R36: - | S36: - | T36: 0.83560185 | U36: - | V36: 0.8306713 | W36: 0.95138889 | X36: 0.95416667
B37: 配置人數 | D37: - | E37: - | F37: - | G37: 11.75 | H37: 6 | I37: - | J37: - | K37: 4.3333333 | L37: - | M37: 4 | N37: 3 | O37: 3.5 | P37: 11.75 | Q37: - | R37: - | S37: - | T37: 4 | U37: - | V37: 4.3333333 | W37: 3 | X37: 3.6
B38: 主要應用設備 | D38: 伺服包裝機 | E38: ET-55 | F38: ET-600 | G38: 夾心型 | H38: 伺服包裝機 | I38: 伺服包裝機 | J38: 夾心型 | K38: 3300型 | L38: 3300型 | M38: 3300型 | N38: GKK | O38: GKK | P38: 夾心型 | Q38: 伺服包裝機 | R38: 伺服包裝機 | S38: 夾心型 | T38: 3300型 | U38: 3300型 | V38: 3300型 | W38: GKK | X38: GKK
B39: 次要應用設備
B40: 備註

Sheet 0227(18度C)
A1: 大溪廠日報分析 | C1: 總生產量 | D1: =SUM(F5:F191) -> 80480 | E1: 營業額 | F1: =SUM(G5:G191) -> 1587718.5 | G1: 出勤人數 | H1: =L21+L38+L55+L72+L89+L106+L123+L140+L157+L174+L191 -> 59.266667 | I1: 產線配置圖 | L1: 生產實績 | O1: 人時性差異分析 | S1: 日報登錄 | Y1: 分析說明 | AA1: 產能差異分析
A2: 46080 | C2: 人時性 | D2: =AVERAGE(N21,N38,N55,N72,N89,N106,N123,N140,N157,N174,N191) -> 670.36317 | E2: 平均廠價 | F2: =F1/D1 -> 19.728112 | G2: 多次生產數 | H2: =COUNT(H5:H191) -> 2
A3: 線別 | B3: 品類 | C3: 品名 | E3: 廠價 | F3: 生產量 | G3: 營收 | H3: 多次 生產 | I3: 人數 | J3: 產能/時 | K3: 人時性 | L3: 人數 | M3: 產能/時 | N3: 人時性 | O3: 人數 | P3: 人時性 | Q3: 達成率 | R3: 達成率 平均 | S3: 生產時間 | U3: 換線、休息/分 | V3: 稼動時間/分 | W3: 休息時間 | Y3: (屏榮回填) | AA3: 產能/時 | AB3: 達成率 | AC3: 達成率平均
S4: 開始 | T4: 結束 | W4: 開始 | X4: 結束
A5: 自動包裝機 | B5: 18℃-飯糰 | C5: 一配兩粒飯糰(鮪魚.焦糖鮭魚) | E5: 28.57 | F5: 1499 | G5: =E5*F5 -> 42826.43 | I5: 12 | J5: 3600 | K5: =J5/I5 -> 300 | L5: 12 | M5: =F5/V5*60 -> 3126.5353 | N5: =M5/L5 -> 260.54461 | O5: =L5-I5 -> 0 | P5: =N5-K5 -> -39.455388 | Q5: =N5/K5 -> 0.86848204 | R5: =Q21 -> 0.87384748 | S5: 0.30641204 | T5: 0.32638889 | V5: 28.766667 | AA5: =M5-J5 -> -473.46466 | AB5: =M5/J5 -> 0.86848204 | AC5: =AB21 -> 0.87384748
B6: 18℃-壽司手卷 | C6: 一配海饌雙手卷 | E6: 29.85 | F6: 1856 | G6: =E6*F6 -> 55401.6 | I6: 12 | J6: 3600 | K6: =J6/I6 -> 300 | L6: 12 | M6: =F6/V6*60 -> 3139.8496 | N6: =M6/L6 -> 261.65414 | O6: =L6-I6 -> 0 | P6: =N6-K6 -> -38.345865 | Q6: =N6/K6 -> 0.87218045 | S6: 0.32986111 | T6: 0.35449074 | U6: 5 | V6: 35.466667 | AA6: =M6-J6 -> -460.15038 | AB6: =M6/J6 -> 0.87218045
B7: 18℃-壽司手卷 | C7: 一配雙饗雙手卷 | E7: 29.52 | F7: 1763 | G7: =E7*F7 -> 52043.76 | I7: 12 | J7: 3600 | K7: =J7/I7 -> 300 | L7: 12 | M7: =F7/V7*60 -> 3140.4255 | N7: =M7/L7 -> 261.70213 | O7: =L7-I7 -> 0 | P7: =N7-K7 -> -38.297872 | Q7: =N7/K7 -> 0.87234043 | S7: 0.3578588 | T7: 0.38125 | U7: 4.85 | V7: 33.683333 | AA7: =M7-J7 -> -459.57447 | AB7: =M7/J7 -> 0.87234043
B8: 18℃-壽司手卷 | C8: 一配長野稻荷壽司 | E8: 25.64 | F8: 1523 | G8: =E8*F8 -> 39049.72 | I8: 11 | J8: 3600 | K8: =J8/I8 -> 327.27273 | L8: 11 | M8: =F8/V8*60 -> 3176.5933 | N8: =M8/L8 -> 288.78121 | O8: =L8-I8 -> 0 | P8: =N8-K8 -> -38.49152 | Q8: =N8/K8 -> 0.88238702 | S8: 0.3855787 | T8: 0.40555556 | U8: 6.2333333 | V8: 28.766667 | AA8: =M8-J8 -> -423.40672 | AB8: =M8/J8 -> 0.88238702
B21: 平均 | I21: =AVERAGE(I5:I20) -> 11.75 | J21: =AVERAGE(J5:J20) -> 3600 | K21: =J21/I21 -> 306.38298 | L21: =AVERAGE(L5:L20) -> 11.75 | M21: =AVERAGE(M5:M20) -> 3145.8509 | N21: =M21/L21 -> 267.732 | O21: =L21-I21 -> 0 | P21: =N21-K21 -> -38.650983 | Q21: =N21/K21 -> 0.87384748 | S21: =S5 -> 0.30641204 | T21: =INDEX(T5:T20,COUNTA(T5:T20)) -> 0.40555556 | AA21: =M21-J21 -> -454.14906 | AB21: =M21/J21 -> 0.87384748
A22: 自動包裝機2 | B22: 18℃-壽司手卷 | C22: 一配雙鬆細卷 | E22: 14.03 | F22: 887 | G22: =E22*F22 -> 12444.61 | I22: 6 | J22: 2600 | K22: =J22/I22 -> 433.33333 | L22: 6 | M22: =F22/V22*60 -> 2341.0557 | N22: =M22/L22 -> 390.17595 | O22: =L22-I22 -> 0 | P22: =N22-K22 -> -43.15738 | Q22: =N22/K22 -> 0.90040605 | R22: =Q38 -> 0.9003076 | S22: 0.25018519 | T22: 0.26597222 | V22: 22.733333 | AA22: =M22-J22 -> -258.94428 | AB22: =M22/J22 -> 0.90040605 | AC22: =AB38 -> 0.9003076
B23: 18℃-壽司手卷 | C23: 一配經典鮪魚沙拉細卷 | E23: 14.49 | F23: 1076 | G23: =E23*F23 -> 15591.24 | I23: 6 | J23: 2600 | K23: =J23/I23 -> 433.33333 | L23: 6 | M23: =F23/V23*60 -> 2340.5438 | N23: =M23/L23 -> 390.09063 | O23: =L23-I23 -> 0 | P23: =N23-K23 -> -43.242699 | Q23: =N23/K23 -> 0.90020916 | S23: 0.2697338 | T23: 0.28888889 | U23: 5.4166667 | V23: 27.583333 | AA23: =M23-J23 -> -259.45619 | AB23: =M23/J23 -> 0.90020916
B38: 平均 | I38: =AVERAGE(I22:I37) -> 6 | J38: =AVERAGE(J22:J37) -> 2600 | K38: =J38/I38 -> 433.33333 | L38: =AVERAGE(L22:L37) -> 6 | M38: =AVERAGE(M22:M37) -> 2340.7998 | N38: =M38/L38 -> 390.13329 | O38: =L38-I38 -> 0 | P38: =N38-K38 -> -43.20004 | Q38: =N38/K38 -> 0.9003076 | S38: =S22 -> 0.25018519 | T38: =INDEX(T22:T37,COUNTA(T22:T37)) -> 0.28888889 | AA38: =M38-J38 -> -259.20024 | AB38: =M38/J38 -> 0.9003076
A39: (舊) 3300型飯糰線 | B39: 18℃-飯糰 | C39: 一配壹號醬炙烤牛飯糰 | E39: 22.28 | F39: 822 | G39: =E39*F39 -> 18314.16 | I39: 5 | J39: 3300 | K39: =J39/I39 -> 660 | L39: 5 | M39: =F39/V39*60 -> 2968.1043 | N39: =M39/L39 -> 593.62086 | O39: =L39-I39 -> 0 | P39: =N39-K39 -> -66.379137 | Q39: =N39/K39 -> 0.89942555 | R39: =Q55 -> 0.89899329 | S39: 0.39609954 | T39: 0.40763889 | V39: 16.616667 | AA39: =M39-J39 -> -331.89569 | AB39: =M39/J39 -> 0.89942555 | AC39: =AB55 -> 0.89899329
B40: 18℃-飯糰 | C40: 一配照燒雞肉飯糰 | E40: 21.45 | F40: 1028 | G40: =E40*F40 -> 22050.6 | I40: 4 | J40: 3300 | K40: =J40/I40 -> 825 | L40: 4 | M40: =F40/V40*60 -> 2967.7626 | N40: =M40/L40 -> 741.94066 | O40: =L40-I40 -> 0 | P40: =N40-K40 -> -83.059342 | Q40: =N40/K40 -> 0.89932201 | S40: 0.41126157 | T40: 0.42569444 | U40: 5.2166667 | V40: 20.783333 | AA40: =M40-J40 -> -332.23737 | AB40: =M40/J40 -> 0.89932201
B41: 18℃-飯糰 | C41: 一配雞肉飯飯糰 | E41: 16.66 | F41: 3557 | G41: =E41*F41 -> 59259.62 | I41: 4 | J41: 3300 | K41: =J41/I41 -> 825 | L41: 4 | M41: =F41/V41*60 -> 2964.1667 | N41: =M41/L41 -> 741.04167 | O41: =L41-I41 -> 0 | P41: =N41-K41 -> -83.958333 | Q41: =N41/K41 -> 0.89823232 | S41: 0.42916667 | T41: 0.47916667 | U41: 5 | V41: 72 | AA41: =M41-J41 -> -335.83333 | AB41: =M41/J41 -> 0.89823232
B55: 平均 | I55: =AVERAGE(I39:I54) -> 4.3333333 | J55: =AVERAGE(J39:J54) -> 3300 | K55: =J55/I55 -> 761.53846 | L55: =AVERAGE(L39:L54) -> 4.3333333 | M55: =AVERAGE(M39:M54) -> 2966.6779 | N55: =M55/L55 -> 684.61797 | O55: =L55-I55 -> 0 | P55: =N55-K55 -> -76.920492 | Q55: =N55/K55 -> 0.89899329 | S55: =S39 -> 0.39609954 | T55: =INDEX(T39:T54,COUNTA(T39:T54)) -> 0.47916667 | AA55: =M55-J55 -> -333.32213 | AB55: =M55/J55 -> 0.89899329
A56: (新) 3300型飯糰機 | B56: 18℃-飯糰 | C56: 一配鹽蔥燒肉飯糰 | E56: 17.89 | F56: 2271 | G56: =E56*F56 -> 40628.19 | I56: 4 | J56: 3300 | K56: =J56/I56 -> 825 | L56: 4 | M56: =F56/V56*60 -> 2962.1739 | N56: =M56/L56 -> 740.54348 | O56: =L56-I56 -> 0 | P56: =N56-K56 -> -84.456522 | Q56: =N56/K56 -> 0.89762846 | R56: =Q72 -> 0.89780906 | S56: 0.29166667 | T56: 0.32361111 | V56: 46 | AA56: =M56-J56 -> -337.82609 | AB56: =M56/J56 -> 0.89762846 | AC56: =AB72 -> 0.89780906
B57: 18℃-飯糰 | C57: 一配紅運烏魚子紹興飯糰 | E57: 27.27 | F57: 1302 | G57: =E57*F57 -> 35505.54 | I57: 5 | J57: 3300 | K57: =J57/I57 -> 660 | L57: 5 | M57: =F57/V57*60 -> 2962.8319 | N57: =M57/L57 -> 592.56637 | O57: =L57-I57 -> 0 | P57: =N57-K57 -> -67.433628 | Q57: =N57/K57 -> 0.89782784 | S57: 0.32708333 | T57: 0.34539352 | U57: 5 | V57: 26.366667 | AA57: =M57-J57 -> -337.16814 | AB57: =M57/J57 -> 0.89782784
B58: 18℃-飯糰 | C58: 一配鮭魚奶油醬油飯糰 | E58: 18.53 | F58: 2611 | G58: =E58*F58 -> 48381.83 | I58: 3 | J58: 3300 | K58: =J58/I58 -> 1100 | L58: 3 | M58: =F58/V58*60 -> 2963.3039 | N58: =M58/L58 -> 987.76797 | O58: =L58-I58 -> 0 | P58: =N58-K58 -> -112.23203 | Q58: =N58/K58 -> 0.89797088 | S58: 0.3487037 | T58: 0.38541667 | U58: 4.7666667 | V58: 52.866667 | AA58: =M58-J58 -> -336.69609 | AB58: =M58/J58 -> 0.89797088
B72: 平均 | I72: =AVERAGE(I56:I71) -> 4 | J72: =AVERAGE(J56:J71) -> 3300 | K72: =J72/I72 -> 825 | L72: =AVERAGE(L56:L71) -> 4 | M72: =AVERAGE(M56:M71) -> 2962.7699 | N72: =M72/L72 -> 740.69247 | O72: =L72-I72 -> 0 | P72: =N72-K72 -> -84.307527 | Q72: =N72/K72 -> 0.89780906 | S72: =S56 -> 0.29166667 | T72: =INDEX(T56:T71,COUNTA(T56:T71)) -> 0.38541667 | AA72: =M72-J72 -> -337.23011 | AB72: =M72/J72 -> 0.89780906
A73: GKK3600型 飯糰機 | B73: 18℃-飯糰 | C73: 一配蔬食鮪魚飯糰 | E73: 18.18 | F73: 817 | G73: =E73*F73 -> 14853.06 | I73: 3 | J73: 3600 | K73: =J73/I73 -> 1200 | L73: 3 | M73: =F73/V73*60 -> 3145.6684 | N73: =M73/L73 -> 1048.5561 | O73: =L73-I73 -> 0 | P73: =N73-K73 -> -151.44385 | Q73: =N73/K73 -> 0.87379679 | R73: =Q89 -> 0.88093002 | S73: 0.29195602 | T73: 0.30277778 | V73: 15.583333 | AA73: =M73-J73 -> -454.33155 | AB73: =M73/J73 -> 0.87379679 | AC73: =AB89 -> 0.88093002
B74: 18℃-飯糰 | C74: 一配經典肉鬆飯糰 | E74: 14.03 | F74: 3388 | G74: =E74*F74 -> 47533.64 | I74: 3 | J74: 3000 | K74: =J74/I74 -> 1000 | L74: 3 | M74: =F74/V74*60 -> 2693.0448 | N74: =M74/L74 -> 897.68161 | O74: =L74-I74 -> 0 | P74: =N74-K74 -> -102.31839 | Q74: =N74/K74 -> 0.89768161 | S74: 0.31319444 | T74: 0.36561343 | U74: 15 | V74: 75.483333 | AA74: =M74-J74 -> -306.95518 | AB74: =M74/J74 -> 0.89768161
B75: 18℃-飯糰 | C75: 一配鮪魚飯糰 | E75: 14.28 | F75: 4388 | G75: =E75*F75 -> 62660.64 | I75: 3 | J75: 3600 | K75: =J75/I75 -> 1200 | L75: 3 | M75: =F75/V75*60 -> 3146.7729 | N75: =M75/L75 -> 1048.9243 | O75: =L75-I75 -> 0 | P75: =N75-K75 -> -151.0757 | Q75: =N75/K75 -> 0.87410359 | S75: 0.37662037 | T75: 0.43472222 | U75: 15.85 | V75: 83.666667 | AA75: =M75-J75 -> -453.22709 | AB75: =M75/J75 -> 0.87410359
B89: 平均 | I89: =AVERAGE(I73:I88) -> 3 | J89: =AVERAGE(J73:J88) -> 3400 | K89: =J89/I89 -> 1133.3333 | L89: =AVERAGE(L73:L88) -> 3 | M89: =AVERAGE(M73:M88) -> 2995.1621 | N89: =M89/L89 -> 998.38735 | O89: =L89-I89 -> 0 | P89: =N89-K89 -> -134.94598 | Q89: =N89/K89 -> 0.88093002 | S89: =S73 -> 0.29195602 | T89: =INDEX(T73:T88,COUNTA(T73:T88)) -> 0.43472222 | AA89: =M89-J89 -> -404.83794 | AB89: =M89/J89 -> 0.88093002
A90: GKK3600型 飯糰機2 | B90: 18℃-飯糰 | C90: 一配熟成紅鮭飯糰 | E90: 25.03 | F90: 982 | G90: =E90*F90 -> 24579.46 | I90: 4 | J90: 3300 | K90: =J90/I90 -> 825 | L90: 4 | M90: =F90/V90*60 -> 2933.7759 | N90: =M90/L90 -> 733.44398 | O90: =L90-I90 -> 0 | P90: =N90-K90 -> -91.556017 | Q90: =N90/K90 -> 0.88902301 | R90: =Q106 -> 0.88682233 | S90: 0.29166667 | T90: 0.30561343 | V90: 20.083333 | AA90: =M90-J90 -> -366.22407 | AB90: =M90/J90 -> 0.88902301 | AC90: =AB106 -> 0.88682233
B91: 18℃-飯糰 | C91: 一配北海道秋鮭親子飯糰 | E91: 24.82 | F91: 1342 | G91: =E91*F91 -> 33308.44 | I91: 4 | J91: 3300 | K91: =J91/I91 -> 825 | L91: 4 | M91: =F91/V91*60 -> 2933.3333 | N91: =M91/L91 -> 733.33333 | O91: =L91-I91 -> 0 | P91: =N91-K91 -> -91.666667 | Q91: =N91/K91 -> 0.88888889 | S91: 0.31597222 | T91: 0.33503472 | U91: 14.916667 | V91: 27.45 | AA91: =M91-J91 -> -366.66667 | AB91: =M91/J91 -> 0.88888889
B92: 18℃-飯糰 | C92: 一配贅沢鮭魚肚飯糰 | E92: 30 | F92: 2113 | G92: =E92*F92 -> 63390 | I92: 3 | J92: 3000 | K92: =J92/I92 -> 1000 | L92: 3 | M92: =F92/V92*60 -> 2693.6261 | N92: =M92/L92 -> 897.87535 | O92: =L92-I92 -> 0 | P92: =N92-K92 -> -102.12465 | Q92: =N92/K92 -> 0.89787535 | S92: 0.34583333 | T92: 0.37851852 | U92: 15.55 | V92: 47.066667 | AA92: =M92-J92 -> -306.37394 | AB92: =M92/J92 -> 0.89787535
B93: 18℃-飯糰 | C93: 一配明太子龍蝦風味沙拉飯糰 | E93: 18.18 | F93: 1764 | G93: =E93*F93 -> 32069.52 | I93: 3 | J93: 3600 | K93: =J93/I93 -> 1200 | L93: 3 | M93: =F93/V93*60 -> 3145.3195 | N93: =M93/L93 -> 1048.4398 | O93: =L93-I93 -> 0 | P93: =N93-K93 -> -151.56018 | Q93: =N93/K93 -> 0.87369985 | S93: 0.38913194 | T93: 0.4125 | U93: 15.283333 | V93: 33.65 | AA93: =M93-J93 -> -454.68053 | AB93: =M93/J93 -> 0.87369985
B106: 平均 | I106: =AVERAGE(I90:I105) -> 3.5 | J106: =AVERAGE(J90:J105) -> 3300 | K106: =J106/I106 -> 942.85714 | L106: =AVERAGE(L90:L105) -> 3.5 | M106: =AVERAGE(M90:M105) -> 2926.5137 | N106: =M106/L106 -> 836.14677 | O106: =L106-I106 -> 0 | P106: =N106-K106 -> -106.71037 | Q106: =N106/K106 -> 0.88682233 | S106: =S90 -> 0.29166667 | T106: =INDEX(T90:T105,COUNTA(T90:T105)) -> 0.4125 | AA106: =M106-J106 -> -373.4863 | AB106: =M106/J106 -> 0.88682233
A107: 自動包裝機 (二配) | B107: 18℃-壽司手卷 | C107: 二配長野稻荷壽司 | E107: 25.64 | F107: 1364 | G107: =E107*F107 -> 34972.96 | I107: 11 | J107: 3600 | K107: =J107/I107 -> 327.27273 | L107: 11 | M107: =F107/V107*60 -> 3176.1966 | N107: =M107/L107 -> 288.74515 | O107: =L107-I107 -> 0 | P107: =N107-K107 -> -38.527579 | Q107: =N107/K107 -> 0.88227684 | R107: =Q123 -> 0.87371499 | S107: 0.70849537 | T107: 0.72638889 | V107: 25.766667 | AA107: =M107-J107 -> -423.80336 | AB107: =M107/J107 -> 0.88227684 | AC107: =AB123 -> 0.87371499
B108: 18℃-壽司手卷 | C108: 二配雙饗雙手卷 | E108: 29.52 | F108: 1655 | G108: =E108*F108 -> 48855.6 | I108: 12 | J108: 3600 | K108: =J108/I108 -> 300 | L108: 12 | M108: =F108/V108*60 -> 3140.7486 | N108: =M108/L108 -> 261.72905 | O108: =L108-I108 -> 0 | P108: =N108-K108 -> -38.270954 | Q108: =N108/K108 -> 0.87243015 | S108: 0.73012731 | T108: 0.75208333 | U108: 5.3833333 | V108: 31.616667 | AA108: =M108-J108 -> -459.25145 | AB108: =M108/J108 -> 0.87243015
B109: 18℃-壽司手卷 | C109: 二配海饌雙手卷 | E109: 29.85 | F109: 1826 | G109: =E109*F109 -> 54506.1 | I109: 12 | J109: 3600 | K109: =J109/I109 -> 300 | L109: 12 | M109: =F109/V109*60 -> 3140.7549 | N109: =M109/L109 -> 261.72957 | O109: =L109-I109 -> 0 | P109: =N109-K109 -> -38.270425 | Q109: =N109/K109 -> 0.87243192 | S109: 0.75563657 | T109: 0.77986111 | U109: 5.1166667 | V109: 34.883333 | AA109: =M109-J109 -> -459.2451 | AB109: =M109/J109 -> 0.87243192
B110: 18℃-飯糰 | C110: 二配兩粒飯糰(鮪魚.焦糖鮭魚) | E110: 28.57 | F110: 1207 | G110: =E110*F110 -> 34483.99 | I110: 12 | J110: 3600 | K110: =J110/I110 -> 300 | L110: 12 | M110: =F110/V110*60 -> 3123.7958 | N110: =M110/L110 -> 260.31632 | O110: =L110-I110 -> 0 | P110: =N110-K110 -> -39.683681 | Q110: =N110/K110 -> 0.86772106 | S110: 0.78402778 | T110: 0.80012731 | U110: 6 | V110: 23.183333 | AA110: =M110-J110 -> -476.20417 | AB110: =M110/J110 -> 0.86772106
B123: 平均 | I123: =AVERAGE(I107:I122) -> 11.75 | J123: =AVERAGE(J107:J122) -> 3600 | K123: =J123/I123 -> 306.38298 | L123: =AVERAGE(L107:L122) -> 11.75 | M123: =AVERAGE(M107:M122) -> 3145.374 | N123: =M123/L123 -> 267.6914 | O123: =L123-I123 -> 0 | P123: =N123-K123 -> -38.691576 | Q123: =N123/K123 -> 0.87371499 | S123: =S107 -> 0.70849537 | T123: =INDEX(T107:T122,COUNTA(T107:T122)) -> 0.80012731 | AA123: =M123-J123 -> -454.62602 | AB123: =M123/J123 -> 0.87371499
A124: (舊) 3300型飯糰線 (二配) | B124: 18℃-飯糰 | C124: 二配大飯糰滷肉飯加蛋 | E124: 22.48 | F124: 1075 | G124: =E124*F124 -> 24166 | I124: 5 | J124: 3000 | K124: =J124/I124 -> 600 | L124: 5 | M124: =F124/V124*60 -> 2672.6519 | N124: =M124/L124 -> 534.53039 | O124: =L124-I124 -> 0 | P124: =N124-K124 -> -65.469613 | Q124: =N124/K124 -> 0.89088398 | R124: =Q140 -> 0.89515369 | S124: 0.70833333 | T124: 0.72509259 | V124: 24.133333 | AA124: =M124-J124 -> -327.34807 | AB124: =M124/J124 -> 0.89088398 | AC124: =AB140 -> 0.89515369
B125: 18℃-飯糰 | C125: 二配大飯糰韓式蒜烤豬五花 | E125: 24.54 | F125: 1666 | G125: =E125*F125 -> 40883.64 | I125: 4 | J125: 3000 | K125: =J125/I125 -> 750 | L125: 4 | M125: =F125/V125*60 -> 2673.9189 | N125: =M125/L125 -> 668.47971 | O125: =L125-I125 -> 0 | P125: =N125-K125 -> -81.520285 | Q125: =N125/K125 -> 0.89130629 | S125: 0.72847222 | T125: 0.75443287 | U125: 4.8666667 | V125: 37.383333 | AA125: =M125-J125 -> -326.08114 | AB125: =M125/J125 -> 0.89130629
B126: 18℃-飯糰 | C126: 二配三杯醬爆菇菇飯糰 | E126: 16.7 | F126: 1065 | G126: =E126*F126 -> 17785.5 | I126: 3 | J126: 3300 | K126: =J126/I126 -> 1100 | L126: 3 | M126: =F126/V126*60 -> 2967.4923 | N126: =M126/L126 -> 989.16409 | O126: =L126-I126 -> 0 | P126: =N126-K126 -> -110.83591 | Q126: =N126/K126 -> 0.89924008 | S126: 0.75796296 | T126: 0.77291667 | U126: 5.0833333 | V126: 21.533333 | AA126: =M126-J126 -> -332.50774 | AB126: =M126/J126 -> 0.89924008
B127: 18℃-飯糰 | C127: 二配鹽蔥燒肉飯糰 | E127: 17.89 | F127: 4164 | G127: =E127*F127 -> 74493.96 | I127: 4 | J127: 3300 | K127: =J127/I127 -> 825 | L127: 4 | M127: =F127/V127*60 -> 2964.8734 | N127: =M127/L127 -> 741.21835 | O127: =L127-I127 -> 0 | P127: =N127-K127 -> -83.781646 | Q127: =N127/K127 -> 0.89844649 | S127: 0.77708333 | T127: 0.83560185 | U127: 6 | V127: 84.266667 | AA127: =M127-J127 -> -335.12658 | AB127: =M127/J127 -> 0.89844649
B140: 平均 | I140: =AVERAGE(I124:I139) -> 4 | J140: =AVERAGE(J124:J139) -> 3150 | K140: =J140/I140 -> 787.5 | L140: =AVERAGE(L124:L139) -> 4 | M140: =AVERAGE(M124:M139) -> 2819.7341 | N140: =M140/L140 -> 704.93353 | O140: =L140-I140 -> 0 | P140: =N140-K140 -> -82.566471 | Q140: =N140/K140 -> 0.89515369 | S140: =S124 -> 0.70833333 | T140: =INDEX(T124:T139,COUNTA(T124:T139)) -> 0.83560185 | AA140: =M140-J140 -> -330.26588 | AB140: =M140/J140 -> 0.89515369
A141: (新) 3300型飯糰機 (二配) | B141: 18℃-飯糰 | C141: 二配壹號醬炙烤牛飯糰 | E141: 22.28 | F141: 1425 | G141: =E141*F141 -> 31749 | I141: 5 | J141: 3300 | K141: =J141/I141 -> 660 | L141: 5 | M141: =F141/V141*60 -> 2967.033 | N141: =M141/L141 -> 593.40659 | O141: =L141-I141 -> 0 | P141: =N141-K141 -> -66.593407 | Q141: =N141/K141 -> 0.8991009 | R141: =Q157 -> 0.89853745 | S141: 0.70846065 | T141: 0.72847222 | V141: 28.816667 | AA141: =M141-J141 -> -332.96703 | AB141: =M141/J141 -> 0.8991009 | AC141: =AB157 -> 0.89853745
...

Sheet 0227(4度C)
A1: 大溪廠日報分析 | C1: 總生產量 | D1: =SUM(F5:F106) -> 40039 | E1: 營業額 | F1: =SUM(G5:G106) -> 2022333.6 | G1: 出勤人數 | H1: =L21+L38+L55+L72+L89+L106 -> 112.68333 | I1: 產線配置圖 | L1: 生產實績 | O1: 人時性差異分析 | S1: 日報登錄 | Y1: 合計次數 | Z1: 合計(時間/分) | AA1: 產線異常 分析說明(5分鐘以上) | AC1: 合計次數 | AD1: 合計(時間/分) | AE1: 產能差異分析
A2: 46080 | C2: 人時性 | D2: =AVERAGE(N21,N38,N55,N72,N89,N106) -> 150.40541 | E2: 平均廠價 | F2: =F1/D1 -> 50.509093 | G2: 多次生產數 | H2: =COUNT(H5:H106) -> 0 | Y2: =SUM(Y21,Y38,Y55,Y72,Y89,Y106) -> 0 | Z2: =SUM(Z21,Z38,Z55,Z72,Z89,Z106) -> 0 | AC2: =SUM(AC21,AC38,AC55,AC72,AC89,AC106) -> 0 | AD2: =SUM(AD21,AD38,AD55,AD72,AD89,AD106) -> 0
A3: 線別 | B3: 品類 | C3: 品名 | E3: 廠價 | F3: 生產量 | G3: 營收 | H3: 多次 生產 | I3: 人數 | J3: 產能/時 | K3: 人時性 | L3: 人數 | M3: 產能/時 | N3: 人時性 | O3: 人數 | P3: 人時性 | Q3: 達成率 | R3: 達成率 平均 | S3: 生產時間 | U3: 換線、休息/分 | V3: 稼動時間/分 | W3: 休息時間 | Y3: 產線異常統計(5分鐘以上) | AA3: (屏榮回填) | AC3: 短暫停線統計(5分鐘以下) | AE3: 產能/時 | AF3: 達成率 | AG3: 達成率平均
S4: 開始 | T4: 結束 | W4: 開始 | X4: 結束 | Y4: 次數 | Z4: 時間/分 | AC4: 總次數 | AD4: 設備因素(次數)
A5: 涼麵一線 | B5: 便當 | C5: 經典滷肉飯 | E5: 47.37 | F5: 1470 | G5: =E5*F5 -> 69633.9 | I5: 21 | J5: 2000 | K5: =J5/I5 -> 95.238095 | L5: 21 | M5: =F5/V5*60 -> 1782.4183 | N5: =M5/L5 -> 84.877063 | O5: =L5-I5 -> 0 | P5: =N5-K5 -> -10.361032 | Q5: =N5/K5 -> 0.89120916 | R5: =Q21 -> 0.89611881 | S5: 0.25 | T5: 0.28436343 | V5: 49.483333 | AE5: =M5-J5 -> -217.58168 | AF5: =M5/J5 -> 0.89120916 | AG5: =AF21 -> 0.90449376
B6: 便當 | C6: 蔬活腿排補力餐盒 | E6: 71.55 | F6: 1731 | G6: =E6*F6 -> 123853.05 | I6: 22 | J6: 2000 | K6: =J6/I6 -> 90.909091 | L6: 22 | M6: =F6/V6*60 -> 1784.0252 | N6: =M6/L6 -> 81.092054 | O6: =L6-I6 -> 0 | P6: =N6-K6 -> -9.8170367 | Q6: =N6/K6 -> 0.8920126 | S6: 0.2875 | T6: 0.32792824 | U6: 4.5166667 | V6: 58.216667 | AE6: =M6-J6 -> -215.97481 | AF6: =M6/J6 -> 0.8920126
B7: 便當 | C7: 海陸雙拼肉肉餐盒 | E7: 59.54 | F7: 2117 | G7: =E7*F7 -> 126046.18 | I7: 23 | J7: 2000 | K7: =J7/I7 -> 86.956522 | L7: 23 | M7: =F7/V7*60 -> 1782.3199 | N7: =M7/L7 -> 77.492171 | O7: =L7-I7 -> 0 | P7: =N7-K7 -> -9.4643511 | Q7: =N7/K7 -> 0.89115996 | S7: 0.33194444 | T7: 0.38143519 | U7: 5.7833333 | V7: 71.266667 | AE7: =M7-J7 -> -217.68007 | AF7: =M7/J7 -> 0.89115996
