Workbook

Sheet 0731
B1: 屏榮 大溪廠組合室生產人時性分析
B3: 日期 | C3: 115.07.31星期五 | E3: 訂單量 | F3: ='0731(18度C)'!D1+'0731(4度C)'!D1 -> 159659 | H3: 營業額 | I3: ='0731(18度C)'!F1+'0731(4度C)'!F1 -> 4936115
B4: 人時性 | C4: 項目 | E4: ➀ | G4: ➁ | I4: ➂ | K4: ④ | M4: ⑤ | O4: 異常停線 | Q4: 短暫停線
C5: 組合室 | E5: 全溫層 | G5: 4度C-各編組展開(一配) | I5: 4度C-各編組展開(二配) | K5: 18度C-各編組展開(一配) | M5: 18度C-各編組展開(二配) | O5: 合計次數 | P5: 時間 | Q5: 合計次數 | R5: 設備次數
C6: 排關平均 | E6: =AVERAGE(D14:O14,D32:X32) -> 494.17253 | F6: =AVERAGE(#REF!,D14:K14) -> #REF! | G6: =AVERAGE(D14:K14) -> 271.43699 | I6: =AVERAGE(L14:O14) -> 94.325718 | K6: =AVERAGE(D32:O32) -> 734.94318 | M6: =AVERAGE(P32:X32) -> 787.42857 | O6: ='0731(4度C)'!Y2 -> 0 | P6: ='0731(4度C)'!Z2 -> 0 | Q6: ='0731(4度C)'!AC2 -> 0 | R6: ='0731(4度C)'!AD2 -> 0
C7: 實績平均 | E7: =AVERAGE(D15:O15,D33:X33) -> 442.85545 | F7: =AVERAGE(#REF!,D15:K15) -> #REF! | G7: =AVERAGE(D15:K15) -> 239.60235 | I7: =AVERAGE(L15:O15) -> 87.223021 | K7: =AVERAGE(D33:O33) -> 659.88028 | M7: =AVERAGE(P33:X33) -> 708.5265
C8: 達成率平均 | E8: =AVERAGE(D16:O16,D34:X34) -> 0.8985302 | F8: =AVERAGE(D16:K16,#REF!) -> #REF! | G8: =AVERAGE(D16:K16) -> 0.89209377 | I8: =AVERAGE(L16:O16) -> 0.92289808 | K8: =AVERAGE(D34:O34) -> 0.89503783 | M8: =AVERAGE(P34:X34) -> 0.89949327
O9: ※現行日本鮮食廠以達成率80%為基本(即為現行KPI)
B11: 溫層 | D11: ➁4度C-各編組展開 | L11: ➂4度C-各編組展開
B12: 編組 | D12: 1 | E12: 2 | F12: 3 | G12: 4 | H12: 5 | I12: 6 | J12: 7 | K12: 8 | L12: 1 | M12: 2 | N12: 3 | O12: 4
D13: 便當一線 | E13: 便當二線 | F13: 涼麵一線 | G13: 涼麵二線 | H13: 涼麵三線 | I13: 自動包裝機 | J13: 自動包裝機2 | K13: 自動包裝機3 | L13: 便當一線 | M13: 便當二線 | N13: 涼麵一線 | O13: 涼麵二線
B14: 人時性 | C14: 排關 | D14: - | E14: 84.40367 | F14: 117.52 | G14: 90.909091 | H14: 170.4142 | I14: 565.375 | J14: 600 | K14: - | L14: - | M14: 101.69492 | N14: 86.956522 | O14: -
C15: 實績 | D15: - | E15: 75.953783 | F15: 106.04578 | G15: 81.736495 | H15: 153.73462 | I15: 478.56948 | J15: 541.57395 | K15: - | L15: - | M15: 96.2 | N15: 78.246043 | O15: -
C16: 達成率 | D16: - | E16: =E15/E14 -> 0.89988721 | F16: =F15/F14 -> 0.90236366 | G16: =G15/G14 -> 0.89910144 | H16: =H15/H14 -> 0.90212327 | I16: =I15/I14 -> 0.84646381 | J16: =J15/J14 -> 0.90262325 | K16: - | L16: - | M16: =M15/M14 -> 0.94596667 | N16: =N15/N14 -> 0.89982949 | O16: -
B17: 作業 時間 | C17: 開始 | D17: - | E17: 0.20833333 | F17: 0.20833333 | G17: 0.20833333 | H17: 0.20833333 | I17: 0.20833333 | J17: 0.25 | K17: - | L17: - | M17: 0.70833333 | N17: 0.70833333 | O17: -
C18: 結束 | D18: - | E18: 0.58033565 | F18: 0.52068287 | G18: 0.51439815 | H18: 0.59740741 | I18: 0.43421296 | J18: 0.29471065 | K18: - | L18: - | M18: 0.79233796 | N18: 0.8115625 | O18: -
B19: 產線異常 (5分鐘以上) | C19: 次數
C20: 時間/分
B21: 短暫停線 (5分鐘以下) | C21: 次數
C22: 設備次數
B23: 配置人數 | D23: - | E23: 21.8 | F23: 18 | G23: 22 | H23: 21.125 | I23: 5.6666667 | J23: 6 | K23: - | L23: - | M23: 18.666667 | N23: 23 | O23: -
B24: 主要應用設備 | D24: L型封口機 | E24: ET-55 | F24: ET-55 | G24: ET-55 | H24: ET-600 | I24: 伺服包裝機 | J24: 伺服包裝機 | K24: 伺服包裝機 | L24: L型封口機 | M24: ET-55 | N24: ET-55 | O24: ET-55
B25: 次要應用設備 | D25: 伺服包裝機 | H25: 伺服包裝機
B26: 備註 | H26: 涼麵+烤飯糰 | I26: 大口飯糰線 | K26: 烤飯糰+手卷
B29: 溫層 | D29: ➃18度C-各編組展開 (一配) | P29: ⑤18度C-各編組展開 (二配)
B30: 編組 | D30: 1 | E30: 2 | F30: 3 | G30: 4 | H30: 5 | I30: 6 | J30: 7 | K30: 8 | L30: 9 | M30: 10 | N30: 11 | O30: 12 | P30: 1 | Q30: 2 | R30: 3 | S30: 4 | T30: 5 | U30: 6 | V30: 7 | W30: 8 | X30: 9
D31: 便當一線 | E31: 涼麵一線 | F31: 涼麵三線 | G31: 自動包裝機 | H31: 自動包裝機2 | I31: 自動包裝機3 | J31: 味付飯糰線B | K31: (舊) 3300型飯糰線 | L31: 3000型飯糰線 | M31: (新) 3300型飯糰機 | N31: GKK3600型 飯糰機 | O31: GKK3600型 飯糰機2 | P31: 自動包裝機 | Q31: 自動包裝機2 | R31: 自動包裝機3 | S31: 味付飯糰線B | T31: (舊) 3300型飯糰線 | U31: 3000型飯糰線 | V31: (新) 3300型飯糰機 | W31: GKK3600型 飯糰機 | X31: GKK3600型 飯糰機2
B32: 人時性 | C32: 排關 | D32: - | E32: - | F32: - | G32: 327.27273 | H32: - | I32: - | J32: - | K32: - | L32: - | M32: 825 | N32: 900 | O32: 887.5 | P32: 490.90909 | Q32: - | R32: - | S32: - | T32: - | U32: - | V32: 709.09091 | W32: 1085.7143 | X32: 864
C33: 實績 | D33: - | E33: - | F33: - | G33: 287.50448 | H33: - | I33: - | J33: - | K33: - | L33: - | M33: 751.3376 | N33: 806.98329 | O33: 793.69575 | P33: 438.78593 | Q33: - | R33: - | S33: - | T33: - | U33: - | V33: 645.79108 | W33: 979.45528 | X33: 770.07373
C34: 達成率 | D34: - | E34: - | F34: - | G34: =G33/G32 -> 0.87848591 | H34: - | I34: - | J34: - | K34: - | L34: - | M34: =M33/M32 -> 0.91071224 | N34: =N33/N32 -> 0.89664809 | O34: =O33/O32 -> 0.89430507 | P34: =P33/P32 -> 0.89382319 | Q34: - | R34: - | S34: - | T34: - | U34: - | V34: =V33/V32 -> 0.91073101 | W34: =W33/W32 -> 0.90212986 | X34: =X33/X32 -> 0.89128904
B35: 作業 時間 | C35: 開始 | D35: - | E35: - | F35: - | G35: 0.20833333 | H35: - | I35: - | J35: - | K35: - | L35: - | M35: 0.31319444 | N35: 0.25 | O35: 0.25 | P35: 0.70833333 | Q35: - | R35: - | S35: - | T35: - | U35: - | V35: 0.70833333 | W35: 0.73125 | X35: 0.73888889
C36: 結束 | D36: - | E36: - | F36: - | G36: 0.43421296 | H36: - | I36: - | J36: - | K36: - | L36: - | M36: 0.38420139 | N36: 0.48579861 | O36: 0.47641204 | P36: 0.74927083 | Q36: - | R36: - | S36: - | T36: - | U36: - | V36: 0.8468287 | W36: 1.035 | X36: 1.0550116
B37: 配置人數 | D37: - | E37: - | F37: - | G37: 11 | H37: - | I37: - | J37: - | K37: - | L37: - | M37: 4 | N37: 3.8571429 | O37: 4 | P37: 7.3333333 | Q37: - | R37: - | S37: - | T37: - | U37: - | V37: 4.4 | W37: 3 | X37: 4.1666667
B38: 主要應用設備 | D38: 伺服包裝機 | E38: ET-55 | F38: ET-600 | G38: 夾心型 | H38: 伺服包裝機 | I38: 伺服包裝機 | J38: 夾心型 | K38: 3300型 | L38: 3300型 | M38: 3300型 | N38: GKK | O38: GKK | P38: 夾心型 | Q38: 伺服包裝機 | R38: 伺服包裝機 | S38: 夾心型 | T38: 3300型 | U38: 3300型 | V38: 3300型 | W38: GKK | X38: GKK
B39: 次要應用設備
B40: 備註

Sheet 0731(18度C)
A1: 大溪廠日報分析 | C1: 總生產量 | D1: =SUM(F5:F140) -> 85072 | E1: 營業額 | F1: =SUM(G5:G140) -> 1712058.9 | G1: 出勤人數 | H1: =L21+L38+L55+L72+L89+L106+L123+L140 -> 41.757143 | I1: 產線配置圖 | L1: 生產實績 | O1: 人時性差異分析 | S1: 日報登錄 | Y1: 分析說明 | AA1: 產能差異分析
A2: 46234 | C2: 人時性 | D2: =AVERAGE(N21,N38,N55,N72,N89,N106,N123,N140) -> 684.20339 | E2: 平均廠價 | F2: =F1/D1 -> 20.124823 | G2: 多次生產數 | H2: =COUNT(H5:H140) -> 9
A3: 線別 | B3: 品類 | C3: 品名 | E3: 廠價 | F3: 生產量 | G3: 營收 | H3: 多次 生產 | I3: 人數 | J3: 產能/時 | K3: 人時性 | L3: 人數 | M3: 產能/時 | N3: 人時性 | O3: 人數 | P3: 人時性 | Q3: 達成率 | R3: 達成率 平均 | S3: 生產時間 | U3: 換線、休息/分 | V3: 稼動時間/分 | W3: 休息時間 | Y3: (屏榮回填) | AA3: 產能/時 | AB3: 達成率 | AC3: 達成率平均
S4: 開始 | T4: 結束 | W4: 開始 | X4: 結束
A5: 自動包裝機 | B5: 18℃-壽司手卷 | C5: 一配長野稻荷壽司 | E5: 25.64 | F5: 1446 | G5: =E5*F5 -> 37075.44 | I5: 10 | J5: 3600 | K5: =J5/I5 -> 360 | L5: 10 | M5: =F5/V5*60 -> 3217.6096 | N5: =M5/L5 -> 321.76096 | O5: =L5-I5 -> 0 | P5: =N5-K5 -> -38.239045 | Q5: =N5/K5 -> 0.89378043 | R5: =Q21 -> 0.87848591 | S5: 0.20833333 | T5: 0.22704861 | V5: 26.964117 | AA5: =M5-J5 -> -382.39045 | AB5: =M5/J5 -> 0.89378043 | AC5: =AB21 -> 0.87848591
B6: 18℃-壽司手卷 | C6: 一配經典人氣雙手卷 | E6: 29.52 | F6: 2171 | G6: =E6*F6 -> 64087.92 | I6: 11 | J6: 3600 | K6: =J6/I6 -> 327.27273 | L6: 11 | M6: =F6/V6*60 -> 3157.0827 | N6: =M6/L6 -> 287.00752 | O6: =L6-I6 -> 0 | P6: =N6-K6 -> -40.265205 | Q6: =N6/K6 -> 0.87696743 | S6: 0.23055556 | T6: 0.25920139 | U6: 5.05 | V6: 41.259609 | AA6: =M6-J6 -> -442.91726 | AB6: =M6/J6 -> 0.87696743
B7: 18℃-壽司手卷 | C7: 一配鮭鮪海饌雙手卷 | E7: 29.85 | F7: 2602 | G7: =E7*F7 -> 77669.7 | I7: 11 | J7: 3600 | K7: =J7/I7 -> 327.27273 | L7: 11 | M7: =F7/V7*60 -> 3157.6519 | N7: =M7/L7 -> 287.05926 | O7: =L7-I7 -> 0 | P7: =N7-K7 -> -40.213463 | Q7: =N7/K7 -> 0.87712553 | S7: 0.2625 | T7: 0.2968287 | U7: 4.75 | V7: 49.441802 | AA7: =M7-J7 -> -442.34809 | AB7: =M7/J7 -> 0.87712553
B8: 18℃-壽司手卷 | C8: 一配青木瓜雞絲泰泰雙手卷 | E8: 30 | F8: 2474 | G8: =E8*F8 -> 74220 | I8: 11 | J8: 3600 | K8: =J8/I8 -> 327.27273 | L8: 11 | M8: =F8/V8*60 -> 3158.6313 | N8: =M8/L8 -> 287.1483 | O8: =L8-I8 -> 0 | P8: =N8-K8 -> -40.124432 | Q8: =N8/K8 -> 0.87739757 | S8: 0.3 | T8: 0.33262731 | U8: 4.5666667 | V8: 46.995039 | AA8: =M8-J8 -> -441.36875 | AB8: =M8/J8 -> 0.87739757
B9: 18℃-飯糰 | C9: 一配兩粒飯糰(鮪魚.焦糖鮭魚) | E9: 28.57 | F9: 1120 | G9: =E9*F9 -> 31998.4 | I9: 12 | J9: 3600 | K9: =J9/I9 -> 300 | L9: 12 | M9: =F9/V9*60 -> 3121.7709 | N9: =M9/L9 -> 260.14757 | O9: =L9-I9 -> 0 | P9: =N9-K9 -> -39.852429 | Q9: =N9/K9 -> 0.86715857 | S9: 0.33611111 | T9: 0.35105324 | U9: 5.0166667 | V9: 21.526244 | AA9: =M9-J9 -> -478.22915 | AB9: =M9/J9 -> 0.86715857
B21: 平均 | I21: =AVERAGE(I5:I20) -> 11 | J21: =AVERAGE(J5:J20) -> 3600 | K21: =J21/I21 -> 327.27273 | L21: =AVERAGE(L5:L20) -> 11 | M21: =AVERAGE(M5:M20) -> 3162.5493 | N21: =M21/L21 -> 287.50448 | O21: =L21-I21 -> 0 | P21: =N21-K21 -> -39.768249 | Q21: =N21/K21 -> 0.87848591 | S21: 0.20833333 | T21: 0.43421296 | AA21: =M21-J21 -> -437.45074 | AB21: =M21/J21 -> 0.87848591
A22: (新) 3300型飯糰機 | B22: 18℃-飯糰 | C22: 一配鮭魚奶油醬油飯糰 | E22: 18.53 | F22: 1880 | G22: =E22*F22 -> 34836.4 | I22: 3 | J22: 3300 | K22: =J22/I22 -> 1100 | L22: 3 | M22: =F22/V22*60 -> 3003.6757 | N22: =M22/L22 -> 1001.2252 | O22: =L22-I22 -> 0 | P22: =N22-K22 -> -98.774772 | Q22: =N22/K22 -> 0.91020475 | R22: =Q38 -> 0.91071224 | S22: 0.31319444 | T22: 0.33927083 | V22: 37.553988 | AA22: =M22-J22 -> -296.32432 | AB22: =M22/J22 -> 0.91020475 | AC22: =AB38 -> 0.91071224
B23: 18℃-飯糰 | C23: 一配壹號醬炙烤牛飯糰 | E23: 22.28 | F23: 580 | G23: =E23*F23 -> 12922.4 | I23: 5 | J23: 3300 | K23: =J23/I23 -> 660 | L23: 5 | M23: =F23/V23*60 -> 3007.1729 | N23: =M23/L23 -> 601.43458 | O23: =L23-I23 -> 0 | P23: =N23-K23 -> -58.565424 | Q23: =N23/K23 -> 0.91126451 | S23: 0.34236111 | T23: 0.35039352 | U23: 5 | V23: 11.572331 | AA23: =M23-J23 -> -292.82712 | AB23: =M23/J23 -> 0.91126451
B24: 18℃-飯糰 | C24: 一配鹽蔥燒肉飯糰 | E24: 17.89 | F24: 2167 | G24: =E24*F24 -> 38767.63 | I24: 4 | J24: 3300 | K24: =J24/I24 -> 825 | L24: 4 | M24: =F24/V24*60 -> 3005.2026 | N24: =M24/L24 -> 751.30066 | O24: =L24-I24 -> 0 | P24: =N24-K24 -> -73.699342 | Q24: =N24/K24 -> 0.91066746 | S24: 0.35416667 | T24: 0.38420139 | U24: 5.4333333 | V24: 43.264969 | AA24: =M24-J24 -> -294.79737 | AB24: =M24/J24 -> 0.91066746
B38: 平均 | I38: =AVERAGE(I22:I37) -> 4 | J38: =AVERAGE(J22:J37) -> 3300 | K38: =J38/I38 -> 825 | L38: =AVERAGE(L22:L37) -> 4 | M38: =AVERAGE(M22:M37) -> 3005.3504 | N38: =M38/L38 -> 751.3376 | O38: =L38-I38 -> 0 | P38: =N38-K38 -> -73.6624 | Q38: =N38/K38 -> 0.91071224 | S38: 0.31319444 | T38: 0.38420139 | AA38: =M38-J38 -> -294.6496 | AB38: =M38/J38 -> 0.91071224
A39: GKK3600型 飯糰機 | B39: 18℃-飯糰 | C39: 一配熟成紅鮭飯糰 | E39: 25.03 | F39: 664 | G39: =E39*F39 -> 16619.92 | I39: 5 | J39: 3600 | K39: =J39/I39 -> 720 | L39: 5 | M39: =F39/V39*60 -> 3210.5896 | N39: =M39/L39 -> 642.11791 | O39: =L39-I39 -> 0 | P39: =N39-K39 -> -77.88209 | Q39: =N39/K39 -> 0.89183043 | R39: =Q55 -> 0.89664809 | S39: 0.25 | T39: 0.25861111 | V39: 12.408936 | AA39: =M39-J39 -> -389.41045 | AB39: =M39/J39 -> 0.89183043 | AC39: =AB55 -> 0.89664809
B40: 18℃-飯糰 | C40: 一配蔬食鮪魚飯糰 | E40: 18.18 | F40: 903 | G40: =E40*F40 -> 16416.54 | I40: 3 | J40: 3600 | K40: =J40/I40 -> 1200 | L40: 3 | M40: =F40/V40*60 -> 3211.3218 | N40: =M40/L40 -> 1070.4406 | O40: =L40-I40 -> 0 | P40: =N40-K40 -> -129.5594 | Q40: =N40/K40 -> 0.89203384 | S40: 0.26875 | T40: 0.28046296 | U40: 14.6 | V40: 16.871557 | AA40: =M40-J40 -> -388.67819 | AB40: =M40/J40 -> 0.89203384
B41: 18℃-飯糰 | C41: 一配柚檸海灣貝飯糰 | E41: 23.72 | F41: 517 | G41: =E41*F41 -> 12263.24 | I41: 5 | J41: 3600 | K41: =J41/I41 -> 720 | L41: 5 | M41: =F41/V41*60 -> 3208.5111 | N41: =M41/L41 -> 641.70223 | O41: =L41-I41 -> 0 | P41: =N41-K41 -> -78.29777 | Q41: =N41/K41 -> 0.8912531 | S41: 0.29027778 | T41: 0.29699074 | U41: 15 | V41: 9.6680356 | AA41: =M41-J41 -> -391.48885 | AB41: =M41/J41 -> 0.8912531
B42: 18℃-飯糰 | C42: 一配北海道秋鮭親子飯糰 | E42: 24.82 | F42: 935 | G42: =E42*F42 -> 23206.7 | I42: 5 | J42: 3600 | K42: =J42/I42 -> 720 | L42: 5 | M42: =F42/V42*60 -> 3206.5677 | N42: =M42/L42 -> 641.31353 | O42: =L42-I42 -> 0 | P42: =N42-K42 -> -78.686468 | Q42: =N42/K42 -> 0.89071324 | S42: 0.30694444 | T42: 0.31908565 | U42: 15 | V42: 17.495343 | AA42: =M42-J42 -> -393.43234 | AB42: =M42/J42 -> 0.89071324
B43: 18℃-飯糰 | C43: 一配黑胡椒洋蔥豬飯糰 | E43: 17.07 | F43: 1586 | G43: =E43*F43 -> 27073.02 | I43: 3 | J43: 3300 | K43: =J43/I43 -> 1100 | L43: 3 | M43: =F43/V43*60 -> 3009.3972 | N43: =M43/L43 -> 1003.1324 | O43: =L43-I43 -> 0 | P43: =N43-K43 -> -96.867606 | Q43: =N43/K43 -> 0.91193854 | S43: 0.32916667 | T43: 0.35112269 | U43: 14.516667 | V43: 31.620951 | AA43: =M43-J43 -> -290.60282 | AB43: =M43/J43 -> 0.91193854
B44: 18℃-飯糰 | C44: 一配經典肉鬆飯糰 | E44: 14.03 | F44: 3468 | G44: =E44*F44 -> 48656.04 | I44: 3 | J44: 3000 | K44: =J44/I44 -> 1000 | L44: 3 | M44: =F44/V44*60 -> 2735.0161 | N44: =M44/L44 -> 911.67204 | O44: =L44-I44 -> 0 | P44: =N44-K44 -> -88.327962 | Q44: =N44/K44 -> 0.91167204 | S44: 0.36111111 | T44: 0.41393519 | U44: 15 | V44: 76.07999 | AA44: =M44-J44 -> -264.98389 | AB44: =M44/J44 -> 0.91167204
B45: 18℃-飯糰 | C45: 一配鮪魚飯糰 | E45: 14.28 | F45: 4734 | G45: =E45*F45 -> 67601.52 | I45: 3 | J45: 3600 | K45: =J45/I45 -> 1200 | L45: 3 | M45: =F45/V45*60 -> 3207.1452 | N45: =M45/L45 -> 1069.0484 | O45: =L45-I45 -> 0 | P45: =N45-K45 -> -130.95159 | Q45: =N45/K45 -> 0.89087368 | S45: 0.42430556 | T45: 0.48579861 | U45: 14.933333 | V45: 88.564745 | AA45: =M45-J45 -> -392.85476 | AB45: =M45/J45 -> 0.89087368
B55: 平均 | I55: =AVERAGE(I39:I54) -> 3.8571429 | J55: =AVERAGE(J39:J54) -> 3471.4286 | K55: =J55/I55 -> 900 | L55: =AVERAGE(L39:L54) -> 3.8571429 | M55: =AVERAGE(M39:M54) -> 3112.6498 | N55: =M55/L55 -> 806.98329 | O55: =L55-I55 -> 0 | P55: =N55-K55 -> -93.016715 | Q55: =N55/K55 -> 0.89664809 | S55: 0.25 | T55: 0.48579861 | AA55: =M55-J55 -> -358.77876 | AB55: =M55/J55 -> 0.89664809
A56: GKK3600型 飯糰機2 | B56: 18℃-飯糰 | C56: 一配椒鹽檸檬鯖魚飯糰 | E56: 20.72 | F56: 1217 | G56: =E56*F56 -> 25216.24 | I56: 3 | J56: 3600 | K56: =J56/I56 -> 1200 | L56: 3 | M56: =F56/V56*60 -> 3210.4384 | N56: =M56/L56 -> 1070.1461 | O56: =L56-I56 -> 0 | P56: =N56-K56 -> -129.85388 | Q56: =N56/K56 -> 0.89178843 | R56: =Q72 -> 0.89430507 | S56: 0.25 | T56: 0.26578704 | V56: 22.744558 | AA56: =M56-J56 -> -389.56164 | AB56: =M56/J56 -> 0.89178843 | AC56: =AB72 -> 0.89430507
B57: 18℃-飯糰 | C57: 一配贅沢鮭魚肚飯糰 | E57: 30 | F57: 1444 | G57: =E57*F57 -> 43320 | I57: 4 | J57: 3600 | K57: =J57/I57 -> 900 | L57: 4 | M57: =F57/V57*60 -> 3207.3911 | N57: =M57/L57 -> 801.84778 | O57: =L57-I57 -> 0 | P57: =N57-K57 -> -98.152224 | Q57: =N57/K57 -> 0.89094197 | S57: 0.27569444 | T57: 0.29444444 | U57: 15 | V57: 27.012608 | AA57: =M57-J57 -> -392.6089 | AB57: =M57/J57 -> 0.89094197
B58: 18℃-飯糰 | C58: 一配筋子銀鮭飯糰 | E58: 30 | F58: 2198 | G58: =E58*F58 -> 65940 | I58: 4 | J58: 3300 | K58: =J58/I58 -> 825 | L58: 4 | M58: =F58/V58*60 -> 3008.1051 | N58: =M58/L58 -> 752.02628 | O58: =L58-I58 -> 0 | P58: =N58-K58 -> -72.97372 | Q58: =N58/K58 -> 0.91154701 | S58: 0.30486111 | T58: 0.33530093 | U58: 15 | V58: 43.841553 | AA58: =M58-J58 -> -291.89488 | AB58: =M58/J58 -> 0.91154701
B59: 18℃-飯糰 | C59: 一配鹽蔥生鮭飯糰 | E59: 27.48 | F59: 3053 | G59: =E59*F59 -> 83896.44 | I59: 5 | J59: 3600 | K59: =J59/I59 -> 720 | L59: 5 | M59: =F59/V59*60 -> 3207.6059 | N59: =M59/L59 -> 641.52118 | O59: =L59-I59 -> 0 | P59: =N59-K59 -> -78.478825 | Q59: =N59/K59 -> 0.89100163 | S59: 0.34513889 | T59: 0.38479167 | U59: 15 | V59: 57.108014 | AA59: =M59-J59 -> -392.39412 | AB59: =M59/J59 -> 0.89100163
B60: 18℃-飯糰 | C60: 一配明太子龍蝦風味沙拉飯糰 | E60: 18.18 | F60: 1560 | G60: =E60*F60 -> 28360.8 | I60: 3 | J60: 3600 | K60: =J60/I60 -> 1200 | L60: 3 | M60: =F60/V60*60 -> 3208.1417 | N60: =M60/L60 -> 1069.3806 | O60: =L60-I60 -> 0 | P60: =N60-K60 -> -130.61943 | Q60: =N60/K60 -> 0.89115048 | S60: 0.39513889 | T60: 0.41539352 | U60: 14.9 | V60: 29.175768 | AA60: =M60-J60 -> -391.85828 | AB60: =M60/J60 -> 0.89115048
B61: 18℃-飯糰 | C61: 一配雞肉飯飯糰 | E61: 16.66 | F61: 3904 | G61: =E61*F61 -> 65040.64 | I61: 5 | J61: 3600 | K61: =J61/I61 -> 720 | L61: 5 | M61: =F61/V61*60 -> 3207.0158 | N61: =M61/L61 -> 641.40317 | O61: =L61-I61 -> 0 | P61: =N61-K61 -> -78.596834 | Q61: =N61/K61 -> 0.89083773 | S61: 0.42569444 | T61: 0.47641204 | U61: 14.833333 | V61: 73.039864 | AA61: =M61-J61 -> -392.98417 | AB61: =M61/J61 -> 0.89083773
B72: 平均 | I72: =AVERAGE(I56:I71) -> 4 | J72: =AVERAGE(J56:J71) -> 3550 | K72: =J72/I72 -> 887.5 | L72: =AVERAGE(L56:L71) -> 4 | M72: =AVERAGE(M56:M71) -> 3174.783 | N72: =M72/L72 -> 793.69575 | O72: =L72-I72 -> 0 | P72: =N72-K72 -> -93.80425 | Q72: =N72/K72 -> 0.89430507 | S72: 0.25 | T72: 0.47641204 | AA72: =M72-J72 -> -375.217 | AB72: =M72/J72 -> 0.89430507
A73: 自動包裝機 (二配) | B73: 18℃-飯糰 | C73: 二配兩粒飯糰(鮪魚.焦糖鮭魚) | E73: 28.57 | F73: 1189 | G73: =E73*F73 -> 33969.73 | I73: 12 | J73: 3600 | K73: =J73/I73 -> 300 | L73: 12 | M73: =F73/V73*60 -> 3122.6949 | N73: =M73/L73 -> 260.22458 | O73: =L73-I73 -> 0 | P73: =N73-K73 -> -39.775425 | Q73: =N73/K73 -> 0.86741525 | R73: =Q89 -> 0.89382319 | S73: 0.70833333 | T73: 0.72418981 | V73: 22.845652 | AA73: =M73-J73 -> -477.3051 | AB73: =M73/J73 -> 0.86741525 | AC73: =AB89 -> 0.89382319
B74: 18℃-飯糰 | C74: 二配柚香雞胸五穀飯糰 | E74: 17.71 | F74: 518 | G74: =E74*F74 -> 9173.78 | I74: 5 | J74: 3600 | K74: =J74/I74 -> 720 | L74: 5 | M74: =F74/V74*60 -> 3266.7813 | N74: =M74/L74 -> 653.35626 | O74: =L74-I74 -> 0 | P74: =N74-K74 -> -66.64374 | Q74: =N74/K74 -> 0.90743925 | S74: 0.72708333 | T74: 0.73368056 | U74: 5 | V74: 9.5139518 | AA74: =M74-J74 -> -333.2187 | AB74: =M74/J74 -> 0.90743925
B75: 18℃-飯糰 | C75: 二配鮭魚毛豆炊飯飯糰 | E75: 18.92 | F75: 977 | G75: =E75*F75 -> 18484.84 | I75: 5 | J75: 3600 | K75: =J75/I75 -> 720 | L75: 5 | M75: =F75/V75*60 -> 3263.8142 | N75: =M75/L75 -> 652.76284 | O75: =L75-I75 -> 0 | P75: =N75-K75 -> -67.23716 | Q75: =N75/K75 -> 0.90661506 | S75: 0.73680556 | T75: 0.74927083 | U75: 5 | V75: 17.960581 | AA75: =M75-J75 -> -336.1858 | AB75: =M75/J75 -> 0.90661506
B89: 平均 | I89: =AVERAGE(I73:I88) -> 7.3333333 | J89: =AVERAGE(J73:J88) -> 3600 | K89: =J89/I89 -> 490.90909 | L89: =AVERAGE(L73:L88) -> 7.3333333 | M89: =AVERAGE(M73:M88) -> 3217.7635 | N89: =M89/L89 -> 438.78593 | O89: =L89-I89 -> 0 | P89: =N89-K89 -> -52.123164 | Q89: =N89/K89 -> 0.89382319 | S89: 0.70833333 | T89: 0.74927083 | AA89: =M89-J89 -> -382.23653 | AB89: =M89/J89 -> 0.89382319
A90: (新) 3300型飯糰機 (二配) | B90: 18℃-飯糰 | C90: 二配大飯糰乾燒風味鮮蝦 | E90: 23.27 | F90: 468 | G90: =E90*F90 -> 10890.36 | I90: 5 | J90: 3000 | K90: =J90/I90 -> 600 | L90: 5 | M90: =F90/V90*60 -> 2734.0218 | N90: =M90/L90 -> 546.80437 | O90: =L90-I90 -> 0 | P90: =N90-K90 -> -53.195633 | Q90: =N90/K90 -> 0.91134061 | R90: =Q106 -> 0.91073101 | S90: 0.70833333 | T90: 0.71546296 | V90: 10.270584 | AA90: =M90-J90 -> -265.97816 | AB90: =M90/J90 -> 0.91134061 | AC90: =AB106 -> 0.91073101
B91: 18℃-飯糰 | C91: 二配大飯糰韓式蒜烤豬五花 | E91: 24.54 | F91: 1197 | G91: =E91*F91 -> 29374.38 | I91: 4 | J91: 3000 | K91: =J91/I91 -> 750 | L91: 4 | M91: =F91/V91*60 -> 2731.9787 | N91: =M91/L91 -> 682.99467 | O91: =L91-I91 -> 0 | P91: =N91-K91 -> -67.005331 | Q91: =N91/K91 -> 0.91065956 | S91: 0.71875 | T91: 0.73700231 | U91: 4.7333333 | V91: 26.288639 | AA91: =M91-J91 -> -268.02132 | AB91: =M91/J91 -> 0.91065956
B92: 18℃-飯糰 | C92: 二配大飯糰泡菜鮪魚 | E92: 24.33 | F92: 1355 | G92: =E92*F92 -> 32967.15 | I92: 4 | J92: 3000 | K92: =J92/I92 -> 750 | L92: 4 | M92: =F92/V92*60 -> 2732.1766 | N92: =M92/L92 -> 683.04416 | O92: =L92-I92 -> 0 | P92: =N92-K92 -> -66.955839 | Q92: =N92/K92 -> 0.91072555 | S92: 0.74097222 | T92: 0.76163194 | U92: 5.7166667 | V92: 29.756495 | AA92: =M92-J92 -> -267.82336 | AB92: =M92/J92 -> 0.91072555
B93: 18℃-飯糰 | C93: 二配壹號醬炙烤牛飯糰 | E93: 22.28 | F93: 1367 | G93: =E93*F93 -> 30456.76 | I93: 5 | J93: 3300 | K93: =J93/I93 -> 660 | L93: 5 | M93: =F93/V93*60 -> 3006.1962 | N93: =M93/L93 -> 601.23925 | O93: =L93-I93 -> 0 | P93: =N93-K93 -> -58.760754 | Q93: =N93/K93 -> 0.91096856 | S93: 0.76527778 | T93: 0.78422454 | U93: 5.25 | V93: 27.283648 | AA93: =M93-J93 -> -293.80377 | AB93: =M93/J93 -> 0.91096856
B94: 18℃-飯糰 | C94: 二配鹽蔥燒肉飯糰 | E94: 17.89 | F94: 4276 | G94: =E94*F94 -> 76497.64 | I94: 4 | J94: 3300 | K94: =J94/I94 -> 825 | L94: 4 | M94: =F94/V94*60 -> 3003.0303 | N94: =M94/L94 -> 750.75757 | O94: =L94-I94 -> 0 | P94: =N94-K94 -> -74.242428 | Q94: =N94/K94 -> 0.91000918 | S94: 0.7875 | T94: 0.8468287 | U94: 4.7166667 | V94: 85.433704 | AA94: =M94-J94 -> -296.96971 | AB94: =M94/J94 -> 0.91000918
B106: 平均 | I106: =AVERAGE(I90:I105) -> 4.4 | J106: =AVERAGE(J90:J105) -> 3120 | K106: =J106/I106 -> 709.09091 | L106: =AVERAGE(L90:L105) -> 4.4 | M106: =AVERAGE(M90:M105) -> 2841.4807 | N106: =M106/L106 -> 645.79108 | O106: =L106-I106 -> 0 | P106: =N106-K106 -> -63.299833 | Q106: =N106/K106 -> 0.91073101 | S106: 0.70833333 | T106: 0.8468287 | AA106: =M106-J106 -> -278.51926 | AB106: =M106/J106 -> 0.91073101
A107: GKK3600型 飯糰機 (二配) | B107: 18℃-飯糰 | C107: 二配芝麻香鬆飯糰 | E107: 18.18 | F107: 534 | G107: =E107*F107 -> 9708.12 | H107: 2 | I107: 3 | J107: 3000 | K107: =J107/I107 -> 1000 | L107: 3 | M107: =F107/V107*60 -> 2736.4541 | N107: =M107/L107 -> 912.15137 | O107: =L107-I107 -> 0 | P107: =N107-K107 -> -87.848628 | Q107: =N107/K107 -> 0.91215137 | R107: =Q123 -> 0.90212986 | S107: 0.73125 | T107: 0.739375 | V107: 11.708583 | AA107: =M107-J107 -> -263.54588 | AB107: =M107/J107 -> 0.91215137 | AC107: =AB123 -> 0.90212986
...

Sheet 0731(4度C)
A1: 大溪廠日報分析 | C1: 總生產量 | D1: =SUM(F5:F140) -> 74587 | E1: 營業額 | F1: =SUM(G5:G140) -> 3224056.1 | G1: 出勤人數 | H1: =L21+L38+L55+L72+L89+L106+L123+L140 -> 136.25833 | I1: 產線配置圖 | L1: 生產實績 | O1: 人時性差異分析 | S1: 日報登錄 | Y1: 合計次數 | Z1: 合計(時間/分) | AA1: 產線異常 分析說明(5分鐘以上) | AC1: 合計次數 | AD1: 合計(時間/分) | AE1: 產能差異分析
A2: 46234 | C2: 人時性 | D2: =AVERAGE(N21,N38,N55,N72,N89,N106,N123,N140) -> 201.50752 | E2: 平均廠價 | F2: =F1/D1 -> 43.225443 | G2: 多次生產數 | H2: =COUNT(H5:H140) -> 0 | Y2: =SUM(Y21,Y38,Y55,Y72,Y89,Y106,Y123,Y140) -> 0 | Z2: =SUM(Z21,Z38,Z55,Z72,Z89,Z106,Z123,Z140) -> 0 | AC2: =SUM(AC21,AC38,AC55,AC72,AC89,AC106,AC123,AC140) -> 0 | AD2: =SUM(AD21,AD38,AD55,AD72,AD89,AD106,AD123,AD140) -> 0
A3: 線別 | B3: 品類 | C3: 品名 | E3: 廠價 | F3: 生產量 | G3: 營收 | H3: 多次 生產 | I3: 人數 | J3: 產能/時 | K3: 人時性 | L3: 人數 | M3: 產能/時 | N3: 人時性 | O3: 人數 | P3: 人時性 | Q3: 達成率 | R3: 達成率 平均 | S3: 生產時間 | U3: 換線、休息/分 | V3: 稼動時間/分 | W3: 休息時間 | Y3: 產線異常統計(5分鐘以上) | AA3: (屏榮回填) | AC3: 短暫停線統計(5分鐘以下) | AE3: 產能/時 | AF3: 達成率 | AG3: 達成率平均
S4: 開始 | T4: 結束 | W4: 開始 | X4: 結束 | Y4: 次數 | Z4: 時間/分 | AC4: 總次數 | AD4: 設備因素(次數)
A5: 便當二線 | B5: 微波小吃 | C5: 日式茶碗蒸 | E5: 19.7 | F5: 3540 | G5: =E5*F5 -> 69738 | I5: 13 | J5: 1200 | K5: =J5/I5 -> 92.307692 | L5: 13 | M5: =F5/V5*60 -> 1083.5673 | N5: =M5/L5 -> 83.35133 | O5: =L5-I5 -> 0 | P5: =N5-K5 -> -8.9563624 | Q5: =N5/K5 -> 0.90297274 | R5: =Q21 -> 0.89988721 | S5: 0.20833333 | T5: 0.34445602 | V5: 196.01921 | AE5: =M5-J5 -> -116.43271 | AF5: =M5/J5 -> 0.90297274 | AG5: =AF21 -> 0.89988721
B6: 微波主食 | C6: 糖燻野郎三十天熟成牛飯 | E6: 56.43 | F6: 3502 | G6: =E6*F6 -> 197617.86 | I6: 24 | J6: 2000 | K6: =J6/I6 -> 83.333333 | L6: 24 | M6: =F6/V6*60 -> 1799.6827 | N6: =M6/L6 -> 74.98678 | O6: =L6-I6 -> 0 | P6: =N6-K6 -> -8.3465538 | Q6: =N6/K6 -> 0.89984135 | S6: 0.34791667 | T6: 0.42899306 | U6: 4.9833333 | V6: 116.75391 | AE6: =M6-J6 -> -200.31729 | AF6: =M6/J6 -> 0.89984135
B7: 便當 | C7: 香檸奶油魚排蔬滿盒 | E7: 77.35 | F7: 392 | G7: =E7*F7 -> 30321.2 | I7: 25 | J7: 2000 | K7: =J7/I7 -> 80 | L7: 25 | M7: =F7/V7*60 -> 1797.4925 | N7: =M7/L7 -> 71.899701 | O7: =L7-I7 -> 0 | P7: =N7-K7 -> -8.1002987 | Q7: =N7/K7 -> 0.89874627 | S7: 0.43194444 | T7: 0.44103009 | U7: 5 | V7: 13.084894 | AE7: =M7-J7 -> -202.50747 | AF7: =M7/J7 -> 0.89874627
B8: 便當 | C8: 嫩烤香料雞胸排蔬滿盒 | E8: 77.34 | F8: 1242 | G8: =E8*F8 -> 96056.28 | I8: 23 | J8: 2000 | K8: =J8/I8 -> 86.956522 | L8: 23 | M8: =F8/V8*60 -> 1798.6081 | N8: =M8/L8 -> 78.200352 | O8: =L8-I8 -> 0 | P8: =N8-K8 -> -8.7561697 | Q8: =N8/K8 -> 0.89930405 | S8: 0.44444444 | T8: 0.47320602 | U8: 4.9166667 | V8: 41.432039 | W8: 0.47320602 | X8: 0.51180556 | AE8: =M8-J8 -> -201.3919 | AF8: =M8/J8 -> 0.89930405
B9: 便當 | C9: 健身G肉餐盒 | E9: 59.52 | F9: 2960 | G9: =E9*F9 -> 176179.2 | I9: 24 | J9: 2000 | K9: =J9/I9 -> 83.333333 | L9: 24 | M9: =F9/V9*60 -> 1799.6117 | N9: =M9/L9 -> 74.98382 | O9: =L9-I9 -> 0 | P9: =N9-K9 -> -8.3495136 | Q9: =N9/K9 -> 0.89980584 | S9: 0.51180556 | T9: 0.58033565 | U9: 55.583333 | V9: 98.687957 | AE9: =M9-J9 -> -200.38833 | AF9: =M9/J9 -> 0.89980584
B21: 平均 | I21: =AVERAGE(I5:I20) -> 21.8 | J21: =AVERAGE(J5:J20) -> 1840 | K21: =J21/I21 -> 84.40367 | L21: =AVERAGE(L5:L20) -> 21.8 | M21: =AVERAGE(M5:M20) -> 1655.7925 | N21: =M21/L21 -> 75.953783 | O21: =L21-I21 -> 0 | P21: =N21-K21 -> -8.4498872 | Q21: =N21/K21 -> 0.89988721 | S21: 0.20833333 | T21: 0.58033565 | Y21: =SUM(Y5:Y20) -> 0 | Z21: =SUM(Z5:Z20) -> 0 | AC21: =SUM(AC5:AC20) -> 0 | AD21: =SUM(AD5:AD20) -> 0 | AE21: =M21-J21 -> -184.20754 | AF21: =M21/J21 -> 0.89988721
A22: 涼麵一線 | B22: 4℃-壽司手卷 | C22: 海陸雙拼壽司 | E22: 36.45 | F22: 1806 | G22: =E22*F22 -> 65828.7 | I22: 20 | J22: 2100 | K22: =J22/I22 -> 105 | L22: 20 | M22: =F22/V22*60 -> 1893.2783 | N22: =M22/L22 -> 94.663917 | O22: =L22-I22 -> 0 | P22: =N22-K22 -> -10.336083 | Q22: =N22/K22 -> 0.90156112 | R22: =Q38 -> 0.90236366 | S22: 0.20833333 | T22: 0.2480787 | V22: 57.234057 | AE22: =M22-J22 -> -206.72166 | AF22: =M22/J22 -> 0.90156112 | AG22: =AF38 -> 0.90958257
B23: 微波小吃 | C23: 馬鈴薯玉米濃湯 | E23: 31.72 | F23: 1195 | G23: =E23*F23 -> 37905.4 | I23: 22 | J23: 2000 | K23: =J23/I23 -> 90.909091 | L23: 22 | M23: =F23/V23*60 -> 1800.8275 | N23: =M23/L23 -> 81.855796 | O23: =L23-I23 -> 0 | P23: =N23-K23 -> -9.0532948 | Q23: =N23/K23 -> 0.90041376 | S23: 0.25208333 | T23: 0.27972222 | U23: 5.7666667 | V23: 39.815029 | AE23: =M23-J23 -> -199.17249 | AF23: =M23/J23 -> 0.90041376
B24: 微波小吃 | C24: 三合一味噌湯 | E24: 34.79 | F24: 1273 | G24: =E24*F24 -> 44287.67 | I24: 11 | J24: 2000 | K24: =J24/I24 -> 181.81818 | L24: 11 | M24: =F24/V24*60 -> 1809.128 | N24: =M24/L24 -> 164.46618 | O24: =L24-I24 -> 0 | P24: =N24-K24 -> -17.352 | Q24: =N24/K24 -> 0.904564 | S24: 0.28333333 | T24: 0.31265046 | U24: 5.2 | V24: 42.219235 | AE24: =M24-J24 -> -190.872 | AF24: =M24/J24 -> 0.904564
B25: 微波小吃 | C25: 蒸蛋湯 | E25: 33.2 | F25: 2207 | G25: =E25*F25 -> 73272.4 | I25: 11 | J25: 2000 | K25: =J25/I25 -> 181.81818 | L25: 11 | M25: =F25/V25*60 -> 1807.9725 | N25: =M25/L25 -> 164.36113 | O25: =L25-I25 -> 0 | P25: =N25-K25 -> -17.457049 | Q25: =N25/K25 -> 0.90398623 | S25: 0.31666667 | T25: 0.36752315 | U25: 5.7833333 | V25: 73.242266 | AE25: =M25-J25 -> -192.02754 | AF25: =M25/J25 -> 0.90398623
B26: 微波小吃 | C26: 越式牛肉寬粉 | E26: 51.44 | F26: 1239 | G26: =E26*F26 -> 63734.16 | I26: 19 | J26: 2000 | K26: =J26/I26 -> 105.26316 | L26: 19 | M26: =F26/V26*60 -> 1801.3709 | N26: =M26/L26 -> 94.808996 | O26: =L26-I26 -> 0 | P26: =N26-K26 -> -10.454162 | Q26: =N26/K26 -> 0.90068546 | S26: 0.37083333 | T26: 0.39949074 | U26: 4.7666667 | V26: 41.268569 | AE26: =M26-J26 -> -198.62908 | AF26: =M26/J26 -> 0.90068546
B27: 微波主食 | C27: 日式鮭魚茶泡烤飯 | E27: 46.34 | F27: 2131 | G27: =E27*F27 -> 98750.54 | I27: 21 | J27: 1800 | K27: =J27/I27 -> 85.714286 | L27: 21 | M27: =F27/V27*60 -> 1622.5561 | N27: =M27/L27 -> 77.264577 | O27: =L27-I27 -> 0 | P27: =N27-K27 -> -8.449709 | Q27: =N27/K27 -> 0.90142006 | S27: 0.40277778 | T27: 0.4575 | U27: 4.7333333 | V27: 78.801589 | W27: 0.4575 | X27: 0.49513889 | AE27: =M27-J27 -> -177.44389 | AF27: =M27/J27 -> 0.90142006
B28: 4℃-飯糰 | C28: 麻油雞飯糰 | E28: 29.97 | F28: 1611 | G28: =E28*F28 -> 48281.67 | I28: 21 | J28: 2790 | K28: =J28/I28 -> 132.85714 | L28: 22 | M28: =F28/V28*60 -> 2626.6346 | N28: =M28/L28 -> 119.39248 | O28: =L28-I28 -> 1 | P28: =N28-K28 -> -13.46466 | Q28: =N28/K28 -> 0.89865309 | S28: 0.49513889 | T28: 0.52068287 | U28: 55 | V28: 36.799941 | AE28: =M28-J28 -> -163.36538 | AF28: =M28/J28 -> 0.9414461
B38: 平均 | I38: =AVERAGE(I22:I37) -> 17.857143 | J38: =AVERAGE(J22:J37) -> 2098.5714 | K38: =J38/I38 -> 117.52 | L38: =AVERAGE(L22:L37) -> 18 | M38: =AVERAGE(M22:M37) -> 1908.824 | N38: =M38/L38 -> 106.04578 | O38: =L38-I38 -> 0.14285714 | P38: =N38-K38 -> -11.474223 | Q38: =N38/K38 -> 0.90236366 | S38: 0.20833333 | T38: 0.52068287 | Y38: =SUM(Y22:Y37) -> 0 | Z38: =SUM(Z22:Z37) -> 0 | AC38: =SUM(AC22:AC37) -> 0 | AD38: =SUM(AD22:AD37) -> 0 | AE38: =M38-J38 -> -189.74743 | AF38: =M38/J38 -> 0.90958257
A39: 涼麵二線 | B39: 便當 | C39: 香腸腿排雙拼便當 | E39: 53.76 | F39: 2284 | G39: =E39*F39 -> 122787.84 | I39: 20 | J39: 2000 | K39: =J39/I39 -> 100 | L39: 20 | M39: =F39/V39*60 -> 1797.1216 | N39: =M39/L39 -> 89.856082 | O39: =L39-I39 -> 0 | P39: =N39-K39 -> -10.143918 | Q39: =N39/K39 -> 0.89856082 | R39: =Q55 -> 0.89910144 | S39: 0.20833333 | T39: 0.26128472 | V39: 76.255272 | AE39: =M39-J39 -> -202.87836 | AF39: =M39/J39 -> 0.89856082 | AG39: =AF55 -> 0.89910144
B40: 便當 | C40: 蔬活腿排補力餐盒 | E40: 71.55 | F40: 1387 | G40: =E40*F40 -> 99239.85 | I40: 22 | J40: 2000 | K40: =J40/I40 -> 90.909091 | L40: 22 | M40: =F40/V40*60 -> 1797.8029 | N40: =M40/L40 -> 81.718314 | O40: =L40-I40 -> 0 | P40: =N40-K40 -> -9.1907771 | Q40: =N40/K40 -> 0.89890145 | S40: 0.26458333 | T40: 0.29672454 | U40: 4.75 | V40: 46.289835 | AE40: =M40-J40 -> -202.1971 | AF40: =M40/J40 -> 0.89890145
B41: 便當 | C41: 地中海布格麥烤魚餐盒 | E41: 63.92 | F41: 1124 | G41: =E41*F41 -> 71846.08 | I41: 24 | J41: 2000 | K41: =J41/I41 -> 83.333333 | L41: 24 | M41: =F41/V41*60 -> 1798.6273 | N41: =M41/L41 -> 74.942803 | O41: =L41-I41 -> 0 | P41: =N41-K41 -> -8.3905307 | Q41: =N41/K41 -> 0.89931363 | S41: 0.3 | T41: 0.32603009 | U41: 4.7166667 | V41: 37.495262 | AE41: =M41-J41 -> -201.37274 | AF41: =M41/J41 -> 0.89931363
B42: 便當 | C42: 烤蛋白餐盒 | E42: 58.67 | F42: 2143 | G42: =E42*F42 -> 125729.81 | I42: 23 | J42: 2000 | K42: =J42/I42 -> 86.956522 | L42: 23 | M42: =F42/V42*60 -> 1798.162 | N42: =M42/L42 -> 78.180956 | O42: =L42-I42 -> 0 | P42: =N42-K42 -> -8.7755661 | Q42: =N42/K42 -> 0.89908099 | S42: 0.32986111 | T42: 0.37951389 | U42: 5.5166667 | V42: 71.50635 | AE42: =M42-J42 -> -201.83802 | AF42: =M42/J42 -> 0.89908099
B43: 便當 | C43: 海陸雙拼肉肉餐盒 | E43: 59.54 | F43: 1767 | G43: =E43*F43 -> 105207.18 | I43: 23 | J43: 2000 | K43: =J43/I43 -> 86.956522 | L43: 23 | M43: =F43/V43*60 -> 1797.6576 | N43: =M43/L43 -> 78.159026 | O43: =L43-I43 -> 0 | P43: =N43-K43 -> -8.7974955 | Q43: =N43/K43 -> 0.8988288 | S43: 0.38263889 | T43: 0.42358796 | U43: 5 | V43: 58.976748 | W43: 0.42358796 | X43: 0.46180556 | AE43: =M43-J43 -> -202.3424 | AF43: =M43/J43 -> 0.8988288
B44: 便當 | C44: 懷舊滷雙拼便當 | E44: 61.09 | F44: 2272 | G44: =E44*F44 -> 138796.48 | I44: 20 | J44: 2000 | K44: =J44/I44 -> 100 | L44: 20 | M44: =F44/V44*60 -> 1799.8459 | N44: =M44/L44 -> 89.992295 | O44: =L44-I44 -> 0 | P44: =N44-K44 -> -10.007705 | Q44: =N44/K44 -> 0.89992295 | S44: 0.46180556 | T44: 0.51439815 | U44: 55.033333 | V44: 75.739817 | AE44: =M44-J44 -> -200.15409 | AF44: =M44/J44 -> 0.89992295
B55: 平均 | I55: =AVERAGE(I39:I54) -> 22 | J55: =AVERAGE(J39:J54) -> 2000 | K55: =J55/I55 -> 90.909091 | L55: =AVERAGE(L39:L54) -> 22 | M55: =AVERAGE(M39:M54) -> 1798.2029 | N55: =M55/L55 -> 81.736495 | O55: =L55-I55 -> 0 | P55: =N55-K55 -> -9.1725962 | Q55: =N55/K55 -> 0.89910144 | S55: 0.20833333 | T55: 0.51439815 | Y55: =SUM(Y39:Y54) -> 0 | Z55: =SUM(Z39:Z54) -> 0 | AC55: =SUM(AC39:AC54) -> 0 | AD55: =SUM(AD39:AD54) -> 0 | AE55: =M55-J55 -> -201.79712 | AF55: =M55/J55 -> 0.89910144
A56: 涼麵三線 | B56: 季節調理麵 | C56: 和風涓絲冷麵 | E56: 28.86 | F56: 2107 | G56: =E56*F56 -> 60808.02 | I56: 19 | J56: 3600 | K56: =J56/I56 -> 189.47368 | L56: 19 | M56: =F56/V56*60 -> 3191.4779 | N56: =M56/L56 -> 167.97252 | O56: =L56-I56 -> 0 | P56: =N56-K56 -> -21.501161 | Q56: =N56/K56 -> 0.88652165 | R56: =Q72 -> 0.90212327 | S56: 0.20833333 | T56: 0.23583333 | V56: 39.611742 | AE56: =M56-J56 -> -408.52206 | AF56: =M56/J56 -> 0.88652165 | AG56: =AF72 -> 0.90212327
B57: 季節調理麵 | C57: 嘉義崇文白醋涼麵 | E57: 35.89 | F57: 2856 | G57: =E57*F57 -> 102501.84 | I57: 19 | J57: 3600 | K57: =J57/I57 -> 189.47368 | L57: 19 | M57: =F57/V57*60 -> 3192.0224 | N57: =M57/L57 -> 168.00118 | O57: =L57-I57 -> 0 | P57: =N57-K57 -> -21.472508 | Q57: =N57/K57 -> 0.88667288 | S57: 0.23958333 | T57: 0.27686343 | U57: 5.4 | V57: 53.683835 | AE57: =M57-J57 -> -407.97765 | AF57: =M57/J57 -> 0.88667288
B58: 季節調理麵 | C58: 招牌雞絲胡麻涼麵 | E58: 43.96 | F58: 1526 | G58: =E58*F58 -> 67082.96 | I58: 24 | J58: 3600 | K58: =J58/I58 -> 150 | L58: 24 | M58: =F58/V58*60 -> 3269.4283 | N58: =M58/L58 -> 136.22618 | O58: =L58-I58 -> 0 | P58: =N58-K58 -> -13.77382 | Q58: =N58/K58 -> 0.90817453 | S58: 0.27986111 | T58: 0.29930556 | U58: 5 | V58: 28.004896 | AE58: =M58-J58 -> -330.57169 | AF58: =M58/J58 -> 0.90817453
B59: 季節調理麵 | C59: 日式胡麻雞絲冷麵 | E59: 46.93 | F59: 1149 | G59: =E59*F59 -> 53922.57 | I59: 24 | J59: 3600 | K59: =J59/I59 -> 150 | L59: 24 | M59: =F59/V59*60 -> 3267.6265 | N59: =M59/L59 -> 136.15111 | O59: =L59-I59 -> 0 | P59: =N59-K59 -> -13.848894 | Q59: =N59/K59 -> 0.90767404 | S59: 0.30347222 | T59: 0.31811343 | U59: 6 | V59: 21.097882 | AE59: =M59-J59 -> -332.37346 | AF59: =M59/J59 -> 0.90767404
B60: 季節調理麵 | C60: 日式蕎麥沾麵 | E60: 36.73 | F60: 3022 | G60: =E60*F60 -> 110998.06 | I60: 20 | J60: 3600 | K60: =J60/I60 -> 180 | L60: 20 | M60: =F60/V60*60 -> 3260.8167 | N60: =M60/L60 -> 163.04084 | O60: =L60-I60 -> 0 | P60: =N60-K60 -> -16.959164 | Q60: =N60/K60 -> 0.90578242 | S60: 0.32222222 | T60: 0.36083333 | U60: 5.9166667 | V60: 55.605701 | AE60: =M60-J60 -> -339.18329 | AF60: =M60/J60 -> 0.90578242
B61: 季節調理麵 | C61: 月見烏龍冷麵 | E61: 48.4 | F61: 3321 | G61: =E61*F61 -> 160736.4 | I61: 22 | J61: 3600 | K61: =J61/I61 -> 163.63636 | L61: 22 | M61: =F61/V61*60 -> 3264.4252 | N61: =M61/L61 -> 148.38296 | O61: =L61-I61 -> 0 | P61: =N61-K61 -> -15.2534 | Q61: =N61/K61 -> 0.90678478 | S61: 0.36388889 | T61: 0.40627315 | U61: 5 | V61: 61.039842 | AE61: =M61-J61 -> -335.57479 | AF61: =M61/J61 -> 0.90678478
B62: 季節調理麵 | C62: 大滿足香辣涼麵 | E62: 38.48 | F62: 4885 | G62: =E62*F62 -> 187974.8 | I62: 20 | J62: 3600 | K62: =J62/I62 -> 180 | L62: 20 | M62: =F62/V62*60 -> 3267.1412 | N62: =M62/L62 -> 163.35706 | O62: =L62-I62 -> 0 | P62: =N62-K62 -> -16.64294 | Q62: =N62/K62 -> 0.90753922 | S62: 0.40972222 | T62: 0.47201389 | U62: 4.9666667 | V62: 89.711458 | W62: 0.47201389 | X62: 0.51041667 | AE62: =M62-J62 -> -332.8588 | AF62: =M62/J62 -> 0.90753922
B63: 季節調理麵 | C63: 大滿足麻醬涼麵 | E63: 37.8 | F63: 6824 | G63: =E63*F63 -> 257947.2 | I63: 21 | J63: 3600 | K63: =J63/I63 -> 171.42857 | L63: 21 | M63: =F63/V63*60 -> 3268.212 | N63: =M63/L63 -> 155.62914 | O63: =L63-I63 -> 0 | P63: =N63-K63 -> -15.799427 | Q63: =N63/K63 -> 0.90783668 | S63: 0.51041667 | T63: 0.59740741 | U63: 55.3 | V63: 125.27951 | AE63: =M63-J63 -> -331.78796 | AF63: =M63/J63 -> 0.90783668
B72: 平均 | I72: =AVERAGE(I56:I71) -> 21.125 | J72: =AVERAGE(J56:J71) -> 3600 | K72: =J72/I72 -> 170.4142 | L72: =AVERAGE(L56:L71) -> 21.125 | M72: =AVERAGE(M56:M71) -> 3247.6438 | N72: =M72/L72 -> 153.73462 | O72: =L72-I72 -> 0 | P72: =N72-K72 -> -16.679584 | Q72: =N72/K72 -> 0.90212327 | S72: 0.20833333 | T72: 0.59740741 | Y72: =SUM(Y56:Y71) -> 0 | Z72: =SUM(Z56:Z71) -> 0 | AC72: =SUM(AC56:AC71) -> 0 | AD72: =SUM(AD56:AD71) -> 0 | AE72: =M72-J72 -> -352.35621 | AF72: =M72/J72 -> 0.90212327
A73: 自動包裝機 | B73: 4℃-壽司手卷 | C73: 醬油生鮭脆卷 | E73: 23.55 | F73: 2951 | G73: =E73*F73 -> 69496.05 | I73: 6 | J73: 2500 | K73: =J73/I73 -> 416.66667 | L73: 6 | M73: =F73/V73*60 -> 2209.362 | N73: =M73/L73 -> 368.227 | O73: =L73-I73 -> 0 | P73: =N73-K73 -> -48.439663 | Q73: =N73/K73 -> 0.88374481 | R73: =Q89 -> 0.84646381 | S73: 0.35486111 | T73: 0.41050926 | U73: 5.4833333 | V73: 80.140782 | AE73: =M73-J73 -> -290.63798 | AF73: =M73/J73 -> 0.88374481 | AG73: =AF89 -> 0.8993678
B74: 4℃-壽司手卷 | C74: 韓式辣炒豬肉飯卷 | E74: 27.05 | F74: 506 | G74: =E74*F74 -> 13687.3 | I74: 5 | J74: 3273 | K74: =J74/I74 -> 654.6 | L74: 6 | M74: =F74/V74*60 -> 2960.3327 | N74: =M74/L74 -> 493.38878 | O74: =L74-I74 -> 1 | P74: =N74-K74 -> -161.21122 | Q74: =N74/K74 -> 0.7537256 | S74: 0.41388889 | T74: 0.42100694 | U74: 4.8666667 | V74: 10.255604 | AE74: =M74-J74 -> -312.66732 | AF74: =M74/J74 -> 0.90447072
B75: 4℃-壽司手卷 | C75: 厚香料優格咖哩烤雞飯卷 | E75: 27.05 | F75: 656 | G75: =E75*F75 -> 17744.8 | I75: 5 | J75: 3273 | K75: =J75/I75 -> 654.6 | L75: 5 | M75: =F75/V75*60 -> 2965.9864 | N75: =M75/L75 -> 593.19728 | O75: =L75-I75 -> 0 | P75: =N75-K75 -> -61.402715 | Q75: =N75/K75 -> 0.90619811 | S75: 0.425 | T75: 0.43421296 | U75: 5.75 | V75: 13.270459 | AE75: =M75-J75 -> -307.01358 | AF75: =M75/J75 -> 0.90619811
B89: 平均 | I89: =AVERAGE(I73:I88) -> 5.3333333 | J89: =AVERAGE(J73:J88) -> 3015.3333 | K89: =J89/I89 -> 565.375 | L89: =AVERAGE(L73:L88) -> 5.6666667 | M89: =AVERAGE(M73:M88) -> 2711.8937 | N89: =M89/L89 -> 478.56948 | O89: =L89-I89 -> 0.33333333 | P89: =N89-K89 -> -86.805522 | Q89: =N89/K89 -> 0.84646381 | S89: 0.20833333 | T89: 0.43421296 | Y89: =SUM(Y73:Y88) -> 0 | Z89: =SUM(Z73:Z88) -> 0 | AC89: =SUM(AC73:AC88) -> 0 | AD89: =SUM(AD73:AD88) -> 0 | AE89: =M89-J89 -> -303.43962 | AF89: =M89/J89 -> 0.8993678
A90: 自動包裝機2 | B90: 4℃-壽司手卷 | C90: 鮪魚昆布細卷 | E90: 15.51 | F90: 1606 | G90: =E90*F90 -> 24909.06 | I90: 6 | J90: 3600 | K90: =J90/I90 -> 600 | L90: 6 | M90: =F90/V90*60 -> 3249.36 | N90: =M90/L90 -> 541.56 | O90: =L90-I90 -> 0 | P90: =N90-K90 -> -58.44 | Q90: =N90/K90 -> 0.9026 | R90: =Q106 -> 0.90262325 | S90: 0.25 | T90: 0.27059028 | V90: 29.655071 | AE90: =M90-J90 -> -350.64 | AF90: =M90/J90 -> 0.9026 | AG90: =AF106 -> 0.90262325
B91: 4℃-壽司手卷 | C91: 肉鬆火腿細卷 | E91: 15.01 | F91: 1646 | G91: =E91*F91 -> 24706.46 | I91: 6 | J91: 3600 | K91: =J91/I91 -> 600 | L91: 6 | M91: =F91/V91*60 -> 3249.5274 | N91: =M91/L91 -> 541.5879 | O91: =L91-I91 -> 0 | P91: =N91-K91 -> -58.412104 | Q91: =N91/K91 -> 0.90264649 | S91: 0.27361111 | T91: 0.29471065 | U91: 5 | V91: 30.392112 | AE91: =M91-J91 -> -350.47263 | AF91: =M91/J91 -> 0.90264649
...

Sheet 0730
B1: 屏榮 大溪廠組合室生產人時性分析
B3: 日期 | C3: 115.07.30星期四 | E3: 訂單量 | F3: ='0730(18度C)'!D1+'0730(4度C)'!D1 -> 187092 | H3: 營業額 | I3: ='0730(18度C)'!F1+'0730(4度C)'!F1 -> 5785963.2
B4: 人時性 | C4: 項目 | E4: ➀ | G4: ➁ | I4: ➂ | K4: ④ | M4: ⑤ | O4: 異常停線 | Q4: 短暫停線
C5: 組合室 | E5: 全溫層 | G5: 4度C-各編組展開(一配) | I5: 4度C-各編組展開(二配) | K5: 18度C-各編組展開(一配) | M5: 18度C-各編組展開(二配) | O5: 合計次數 | P5: 時間 | Q5: 合計次數 | R5: 設備次數
C6: 排關平均 | E6: =AVERAGE(D14:O14,D32:X32) -> 492.96756 | F6: =AVERAGE(#REF!,D14:K14) -> #REF! | G6: =AVERAGE(D14:K14) -> 271.43699 | I6: =AVERAGE(L14:O14) -> 94.325718 | K6: =AVERAGE(D32:O32) -> 734.94318 | M6: =AVERAGE(P32:X32) -> 782.6087 | O6: ='0730(4度C)'!Y2 -> 0 | P6: ='0730(4度C)'!Z2 -> 0 | Q6: ='0730(4度C)'!AC2 -> 0 | R6: ='0730(4度C)'!AD2 -> 0
C7: 實績平均 | E7: =AVERAGE(D15:O15,D33:X33) -> 441.47627 | F7: =AVERAGE(#REF!,D15:K15) -> #REF! | G7: =AVERAGE(D15:K15) -> 239.17437 | I7: =AVERAGE(L15:O15) -> 87.150577 | K7: =AVERAGE(D33:O33) -> 659.73262 | M7: =AVERAGE(P33:X33) -> 703.83563
C8: 達成率平均 | E8: =AVERAGE(D16:O16,D34:X34) -> 0.89801516 | F8: =AVERAGE(D16:K16,#REF!) -> #REF! | G8: =AVERAGE(D16:K16) -> 0.89120764 | I8: =AVERAGE(L16:O16) -> 0.92212588 | K8: =AVERAGE(D34:O34) -> 0.89486541 | M8: =AVERAGE(P34:X34) -> 0.89932083
O9: ※現行日本鮮食廠以達成率80%為基本(即為現行KPI)
B11: 溫層 | D11: ➁4度C-各編組展開 | L11: ➂4度C-各編組展開
B12: 編組 | D12: 1 | E12: 2 | F12: 3 | G12: 4 | H12: 5 | I12: 6 | J12: 7 | K12: 8 | L12: 1 | M12: 2 | N12: 3 | O12: 4
D13: 便當一線 | E13: 便當二線 | F13: 涼麵一線 | G13: 涼麵二線 | H13: 涼麵三線 | I13: 自動包裝機 | J13: 自動包裝機2 | K13: 自動包裝機3 | L13: 便當一線 | M13: 便當二線 | N13: 涼麵一線 | O13: 涼麵二線
B14: 人時性 | C14: 排關 | D14: - | E14: 84.40367 | F14: 117.52 | G14: 90.909091 | H14: 170.4142 | I14: 565.375 | J14: 600 | K14: - | L14: - | M14: 101.69492 | N14: 86.956522 | O14: -
C15: 實績 | D15: - | E15: 75.92012 | F15: 106.03236 | G15: 81.697971 | H15: 153.74314 | I15: 475.83868 | J15: 541.81395 | K15: - | L15: - | M15: 96.12691 | N15: 78.174245 | O15: -
C16: 達成率 | D16: - | E16: =E15/E14 -> 0.89948838 | F16: =F15/F14 -> 0.90224953 | G16: =G15/G14 -> 0.89867768 | H16: =H15/H14 -> 0.90217327 | I16: =I15/I14 -> 0.84163375 | J16: =J15/J14 -> 0.90302325 | K16: - | L16: - | M16: =M15/M14 -> 0.94524794 | N16: =N15/N14 -> 0.89900382 | O16: -
B17: 作業 時間 | C17: 開始 | D17: - | E17: 0.16666667 | F17: 0.16666667 | G17: 0.16666667 | H17: 0.16666667 | I17: 0.16666667 | J17: 0.25 | K17: - | L17: - | M17: 0.70833333 | N17: 0.70833333 | O17: -
C18: 結束 | D18: - | E18: 0.5902662 | F18: 0.54158565 | G18: 0.55518519 | H18: 0.54767361 | I18: 0.4590162 | J18: 0.31049769 | K18: - | L18: - | M18: 0.79748843 | N18: 0.81333333 | O18: -
B19: 產線異常 (5分鐘以上) | C19: 次數
C20: 時間/分
B21: 短暫停線 (5分鐘以下) | C21: 次數
C22: 設備次數
B23: 配置人數 | D23: - | E23: 21.8 | F23: 18 | G23: 22 | H23: 21.125 | I23: 5.6666667 | J23: 6 | K23: - | L23: - | M23: 18.666667 | N23: 23 | O23: -
B24: 主要應用設備 | D24: L型封口機 | E24: ET-55 | F24: ET-55 | G24: ET-55 | H24: ET-600 | I24: 伺服包裝機 | J24: 伺服包裝機 | K24: 伺服包裝機 | L24: L型封口機 | M24: ET-55 | N24: ET-55 | O24: ET-55
B25: 次要應用設備 | D25: 伺服包裝機 | H25: 伺服包裝機
B26: 備註 | H26: 涼麵+烤飯糰 | I26: 大口飯糰線 | K26: 烤飯糰+手卷
B29: 溫層 | D29: ➃18度C-各編組展開 (一配) | P29: ⑤18度C-各編組展開 (二配)
B30: 編組 | D30: 1 | E30: 2 | F30: 3 | G30: 4 | H30: 5 | I30: 6 | J30: 7 | K30: 8 | L30: 9 | M30: 10 | N30: 11 | O30: 12 | P30: 1 | Q30: 2 | R30: 3 | S30: 4 | T30: 5 | U30: 6 | V30: 7 | W30: 8 | X30: 9
D31: 便當一線 | E31: 涼麵一線 | F31: 涼麵三線 | G31: 自動包裝機 | H31: 自動包裝機2 | I31: 自動包裝機3 | J31: 味付飯糰線B | K31: (舊) 3300型飯糰線 | L31: 3000型飯糰線 | M31: (新) 3300型飯糰機 | N31: GKK3600型 飯糰機 | O31: GKK3600型 飯糰機2 | P31: 自動包裝機 | Q31: 自動包裝機2 | R31: 自動包裝機3 | S31: 味付飯糰線B | T31: (舊) 3300型飯糰線 | U31: 3000型飯糰線 | V31: (新) 3300型飯糰機 | W31: GKK3600型 飯糰機 | X31: GKK3600型 飯糰機2
B32: 人時性 | C32: 排關 | D32: - | E32: - | F32: - | G32: 327.27273 | H32: - | I32: - | J32: - | K32: - | L32: - | M32: 825 | N32: 900 | O32: 887.5 | P32: 490.90909 | Q32: - | R32: - | S32: - | T32: - | U32: - | V32: 709.09091 | W32: 991.30435 | X32: 939.13043
C33: 實績 | D33: - | E33: - | F33: - | G33: 287.49813 | H33: - | I33: - | J33: - | K33: - | L33: - | M33: 751.1451 | N33: 806.69399 | O33: 793.59325 | P33: 438.68775 | Q33: - | R33: - | S33: - | T33: - | U33: - | V33: 645.76313 | W33: 894.14654 | X33: 836.74511
C34: 達成率 | D34: - | E34: - | F34: - | G34: =G33/G32 -> 0.87846651 | H34: - | I34: - | J34: - | K34: - | L34: - | M34: =M33/M32 -> 0.91047891 | N34: =N33/N32 -> 0.89632665 | O34: =O33/O32 -> 0.89418958 | P34: =P33/P32 -> 0.89362319 | Q34: - | R34: - | S34: - | T34: - | U34: - | V34: =V33/V32 -> 0.9106916 | W34: =W33/W32 -> 0.90198993 | X34: =X33/X32 -> 0.89097859
B35: 作業 時間 | C35: 開始 | D35: - | E35: - | F35: - | G35: 0.16666667 | H35: - | I35: - | J35: - | K35: - | L35: - | M35: 0.32847222 | N35: 0.25 | O35: 0.25 | P35: 0.70833333 | Q35: - | R35: - | S35: - | T35: - | U35: - | V35: 0.70833333 | W35: 0.73055556 | X35: 0.74097222
C36: 結束 | D36: - | E36: - | F36: - | G36: 0.4590162 | H36: - | I36: - | J36: - | K36: - | L36: - | M36: 0.41778935 | N36: 0.54612269 | O36: 0.52671296 | P36: 0.75427083 | Q36: - | R36: - | S36: - | T36: - | U36: - | V36: 0.85847222 | W36: 1.059213 | X36: 1.0709954
B37: 配置人數 | D37: - | E37: - | F37: - | G37: 11 | H37: - | I37: - | J37: - | K37: - | L37: - | M37: 4 | N37: 3.8571429 | O37: 4 | P37: 7.3333333 | Q37: - | R37: - | S37: - | T37: - | U37: - | V37: 4.4 | W37: 3.2857143 | X37: 3.8333333
B38: 主要應用設備 | D38: 伺服包裝機 | E38: ET-55 | F38: ET-600 | G38: 夾心型 | H38: 伺服包裝機 | I38: 伺服包裝機 | J38: 夾心型 | K38: 3300型 | L38: 3300型 | M38: 3300型 | N38: GKK | O38: GKK | P38: 夾心型 | Q38: 伺服包裝機 | R38: 伺服包裝機 | S38: 夾心型 | T38: 3300型 | U38: 3300型 | V38: 3300型 | W38: GKK | X38: GKK
B39: 次要應用設備
B40: 備註

Sheet 0730(18度C)
A1: 大溪廠日報分析 | C1: 總生產量 | D1: =SUM(F5:F140) -> 101163 | E1: 營業額 | F1: =SUM(G5:G140) -> 2044839.5 | G1: 出勤人數 | H1: =L21+L38+L55+L72+L89+L106+L123+L140 -> 41.709524 | I1: 產線配置圖 | L1: 生產實績 | O1: 人時性差異分析 | S1: 日報登錄 | Y1: 分析說明 | AA1: 產能差異分析
A2: 46233 | C2: 人時性 | D2: =AVERAGE(N21,N38,N55,N72,N89,N106,N123,N140) -> 681.78412 | E2: 平均廠價 | F2: =F1/D1 -> 20.213314 | G2: 多次生產數 | H2: =COUNT(H5:H140) -> 9
A3: 線別 | B3: 品類 | C3: 品名 | E3: 廠價 | F3: 生產量 | G3: 營收 | H3: 多次 生產 | I3: 人數 | J3: 產能/時 | K3: 人時性 | L3: 人數 | M3: 產能/時 | N3: 人時性 | O3: 人數 | P3: 人時性 | Q3: 達成率 | R3: 達成率 平均 | S3: 生產時間 | U3: 換線、休息/分 | V3: 稼動時間/分 | W3: 休息時間 | Y3: (屏榮回填) | AA3: 產能/時 | AB3: 達成率 | AC3: 達成率平均
S4: 開始 | T4: 結束 | W4: 開始 | X4: 結束
A5: 自動包裝機 | B5: 18℃-壽司手卷 | C5: 一配長野稻荷壽司 | E5: 25.64 | F5: 1790 | G5: =E5*F5 -> 45895.6 | I5: 10 | J5: 3600 | K5: =J5/I5 -> 360 | L5: 10 | M5: =F5/V5*60 -> 3216.5296 | N5: =M5/L5 -> 321.65296 | O5: =L5-I5 -> 0 | P5: =N5-K5 -> -38.347045 | Q5: =N5/K5 -> 0.89348043 | R5: =Q21 -> 0.87846651 | S5: 0.16666667 | T5: 0.18984954 | V5: 33.390024 | AA5: =M5-J5 -> -383.47045 | AB5: =M5/J5 -> 0.89348043 | AC5: =AB21 -> 0.87846651
B6: 18℃-壽司手卷 | C6: 一配經典人氣雙手卷 | E6: 29.52 | F6: 2831 | G6: =E6*F6 -> 83571.12 | I6: 11 | J6: 3600 | K6: =J6/I6 -> 327.27273 | L6: 11 | M6: =F6/V6*60 -> 3156.0027 | N6: =M6/L6 -> 286.90934 | O6: =L6-I6 -> 0 | P6: =N6-K6 -> -40.363387 | Q6: =N6/K6 -> 0.87666743 | S6: 0.19305556 | T6: 0.23042824 | U6: 4.6166667 | V6: 53.821246 | AA6: =M6-J6 -> -443.99726 | AB6: =M6/J6 -> 0.87666743
B7: 18℃-壽司手卷 | C7: 一配鮭鮪海饌雙手卷 | E7: 29.85 | F7: 3271 | G7: =E7*F7 -> 97639.35 | I7: 11 | J7: 3600 | K7: =J7/I7 -> 327.27273 | L7: 11 | M7: =F7/V7*60 -> 3158.7319 | N7: =M7/L7 -> 287.15745 | O7: =L7-I7 -> 0 | P7: =N7-K7 -> -40.115281 | Q7: =N7/K7 -> 0.87742553 | S7: 0.23402778 | T7: 0.27716435 | U7: 5.1833333 | V7: 62.132528 | AA7: =M7-J7 -> -441.26809 | AB7: =M7/J7 -> 0.87742553
B8: 18℃-壽司手卷 | C8: 一配青木瓜雞絲泰泰雙手卷 | E8: 30 | F8: 3003 | G8: =E8*F8 -> 90090 | I8: 11 | J8: 3600 | K8: =J8/I8 -> 327.27273 | L8: 11 | M8: =F8/V8*60 -> 3157.1913 | N8: =M8/L8 -> 287.01739 | O8: =L8-I8 -> 0 | P8: =N8-K8 -> -40.255341 | Q8: =N8/K8 -> 0.87699757 | S8: 0.28055556 | T8: 0.32018519 | U8: 4.8833333 | V8: 57.069713 | AA8: =M8-J8 -> -442.80875 | AB8: =M8/J8 -> 0.87699757
B9: 18℃-飯糰 | C9: 一配兩粒飯糰(鮪魚.焦糖鮭魚) | E9: 28.57 | F9: 1407 | G9: =E9*F9 -> 40197.99 | I9: 12 | J9: 3600 | K9: =J9/I9 -> 300 | L9: 12 | M9: =F9/V9*60 -> 3123.9417 | N9: =M9/L9 -> 260.32848 | O9: =L9-I9 -> 0 | P9: =N9-K9 -> -39.671521 | Q9: =N9/K9 -> 0.8677616 | S9: 0.32430556 | T9: 0.34306713 | U9: 5.9333333 | V9: 27.023551 | AA9: =M9-J9 -> -476.05826 | AB9: =M9/J9 -> 0.8677616
B21: 平均 | I21: =AVERAGE(I5:I20) -> 11 | J21: =AVERAGE(J5:J20) -> 3600 | K21: =J21/I21 -> 327.27273 | L21: =AVERAGE(L5:L20) -> 11 | M21: =AVERAGE(M5:M20) -> 3162.4794 | N21: =M21/L21 -> 287.49813 | O21: =L21-I21 -> 0 | P21: =N21-K21 -> -39.774596 | Q21: =N21/K21 -> 0.87846651 | S21: 0.16666667 | T21: 0.4590162 | AA21: =M21-J21 -> -437.52056 | AB21: =M21/J21 -> 0.87846651
A22: (新) 3300型飯糰機 | B22: 18℃-飯糰 | C22: 一配鮭魚奶油醬油飯糰 | E22: 18.53 | F22: 2352 | G22: =E22*F22 -> 43582.56 | I22: 3 | J22: 3300 | K22: =J22/I22 -> 1100 | L22: 3 | M22: =F22/V22*60 -> 3003.0157 | N22: =M22/L22 -> 1001.0052 | O22: =L22-I22 -> 0 | P22: =N22-K22 -> -98.994772 | Q22: =N22/K22 -> 0.91000475 | R22: =Q38 -> 0.91047891 | S22: 0.32847222 | T22: 0.36109954 | V22: 46.992762 | AA22: =M22-J22 -> -296.98432 | AB22: =M22/J22 -> 0.91000475 | AC22: =AB38 -> 0.91047891
B23: 18℃-飯糰 | C23: 一配壹號醬炙烤牛飯糰 | E23: 22.28 | F23: 810 | G23: =E23*F23 -> 18046.8 | I23: 5 | J23: 3300 | K23: =J23/I23 -> 660 | L23: 5 | M23: =F23/V23*60 -> 3006.8429 | N23: =M23/L23 -> 601.36858 | O23: =L23-I23 -> 0 | P23: =N23-K23 -> -58.631424 | Q23: =N23/K23 -> 0.91116451 | S23: 0.36388889 | T23: 0.37510417 | U23: 5 | V23: 16.163133 | AA23: =M23-J23 -> -293.15712 | AB23: =M23/J23 -> 0.91116451
B24: 18℃-飯糰 | C24: 一配鹽蔥燒肉飯糰 | E24: 17.89 | F24: 2835 | G24: =E24*F24 -> 50718.15 | I24: 4 | J24: 3300 | K24: =J24/I24 -> 825 | L24: 4 | M24: =F24/V24*60 -> 3003.8826 | N24: =M24/L24 -> 750.97066 | O24: =L24-I24 -> 0 | P24: =N24-K24 -> -74.029342 | Q24: =N24/K24 -> 0.91026746 | S24: 0.37847222 | T24: 0.41778935 | U24: 4.85 | V24: 56.626713 | AA24: =M24-J24 -> -296.11737 | AB24: =M24/J24 -> 0.91026746
B38: 平均 | I38: =AVERAGE(I22:I37) -> 4 | J38: =AVERAGE(J22:J37) -> 3300 | K38: =J38/I38 -> 825 | L38: =AVERAGE(L22:L37) -> 4 | M38: =AVERAGE(M22:M37) -> 3004.5804 | N38: =M38/L38 -> 751.1451 | O38: =L38-I38 -> 0 | P38: =N38-K38 -> -73.8549 | Q38: =N38/K38 -> 0.91047891 | S38: 0.32847222 | T38: 0.41778935 | AA38: =M38-J38 -> -295.4196 | AB38: =M38/J38 -> 0.91047891
A39: GKK3600型 飯糰機 | B39: 18℃-飯糰 | C39: 一配熟成紅鮭飯糰 | E39: 25.03 | F39: 1000 | G39: =E39*F39 -> 25030 | I39: 5 | J39: 3600 | K39: =J39/I39 -> 720 | L39: 5 | M39: =F39/V39*60 -> 3210.2296 | N39: =M39/L39 -> 642.04591 | O39: =L39-I39 -> 0 | P39: =N39-K39 -> -77.95409 | Q39: =N39/K39 -> 0.89173043 | R39: =Q55 -> 0.89632665 | S39: 0.25 | T39: 0.26297454 | V39: 18.690252 | AA39: =M39-J39 -> -389.77045 | AB39: =M39/J39 -> 0.89173043 | AC39: =AB55 -> 0.89632665
B40: 18℃-飯糰 | C40: 一配蔬食鮪魚飯糰 | E40: 18.18 | F40: 1144 | G40: =E40*F40 -> 20797.92 | I40: 3 | J40: 3600 | K40: =J40/I40 -> 1200 | L40: 3 | M40: =F40/V40*60 -> 3211.3218 | N40: =M40/L40 -> 1070.4406 | O40: =L40-I40 -> 0 | P40: =N40-K40 -> -129.5594 | Q40: =N40/K40 -> 0.89203384 | S40: 0.27291667 | T40: 0.28775463 | U40: 15 | V40: 21.374376 | AA40: =M40-J40 -> -388.67819 | AB40: =M40/J40 -> 0.89203384
B41: 18℃-飯糰 | C41: 一配柚檸海灣貝飯糰 | E41: 23.72 | F41: 802 | G41: =E41*F41 -> 19023.44 | I41: 5 | J41: 3600 | K41: =J41/I41 -> 720 | L41: 5 | M41: =F41/V41*60 -> 3207.0711 | N41: =M41/L41 -> 641.41423 | O41: =L41-I41 -> 0 | P41: =N41-K41 -> -78.58577 | Q41: =N41/K41 -> 0.8908531 | S41: 0.29791667 | T41: 0.30833333 | U41: 14.633333 | V41: 15.004344 | AA41: =M41-J41 -> -392.92885 | AB41: =M41/J41 -> 0.8908531
B42: 18℃-飯糰 | C42: 一配北海道秋鮭親子飯糰 | E42: 24.82 | F42: 1330 | G42: =E42*F42 -> 33010.6 | I42: 5 | J42: 3600 | K42: =J42/I42 -> 720 | L42: 5 | M42: =F42/V42*60 -> 3206.5677 | N42: =M42/L42 -> 641.31353 | O42: =L42-I42 -> 0 | P42: =N42-K42 -> -78.686468 | Q42: =N42/K42 -> 0.89071324 | S42: 0.31875 | T42: 0.33603009 | U42: 15 | V42: 24.886423 | AA42: =M42-J42 -> -393.43234 | AB42: =M42/J42 -> 0.89071324
B43: 18℃-飯糰 | C43: 一配黑胡椒洋蔥豬飯糰 | E43: 17.07 | F43: 2133 | G43: =E43*F43 -> 36410.31 | I43: 3 | J43: 3300 | K43: =J43/I43 -> 1100 | L43: 3 | M43: =F43/V43*60 -> 3003.9861 | N43: =M43/L43 -> 1001.3287 | O43: =L43-I43 -> 0 | P43: =N43-K43 -> -98.671285 | Q43: =N43/K43 -> 0.91029883 | S43: 0.34583333 | T43: 0.37541667 | U43: 15 | V43: 42.603392 | AA43: =M43-J43 -> -296.01385 | AB43: =M43/J43 -> 0.91029883
B44: 18℃-飯糰 | C44: 一配經典肉鬆飯糰 | E44: 14.03 | F44: 4530 | G44: =E44*F44 -> 63555.9 | I44: 3 | J44: 3000 | K44: =J44/I44 -> 1000 | L44: 3 | M44: =F44/V44*60 -> 2734.4161 | N44: =M44/L44 -> 911.47204 | O44: =L44-I44 -> 0 | P44: =N44-K44 -> -88.527962 | Q44: =N44/K44 -> 0.91147204 | S44: 0.38541667 | T44: 0.45443287 | U44: 15 | V44: 99.399648 | AA44: =M44-J44 -> -265.58389 | AB44: =M44/J44 -> 0.91147204
B45: 18℃-飯糰 | C45: 一配鮪魚飯糰 | E45: 14.28 | F45: 6277 | G45: =E45*F45 -> 89635.56 | I45: 3 | J45: 3600 | K45: =J45/I45 -> 1200 | L45: 3 | M45: =F45/V45*60 -> 3207.1452 | N45: =M45/L45 -> 1069.0484 | O45: =L45-I45 -> 0 | P45: =N45-K45 -> -130.95159 | Q45: =N45/K45 -> 0.89087368 | S45: 0.46458333 | T45: 0.54612269 | U45: 14.616667 | V45: 117.43154 | AA45: =M45-J45 -> -392.85476 | AB45: =M45/J45 -> 0.89087368
B55: 平均 | I55: =AVERAGE(I39:I54) -> 3.8571429 | J55: =AVERAGE(J39:J54) -> 3471.4286 | K55: =J55/I55 -> 900 | L55: =AVERAGE(L39:L54) -> 3.8571429 | M55: =AVERAGE(M39:M54) -> 3111.534 | N55: =M55/L55 -> 806.69399 | O55: =L55-I55 -> 0 | P55: =N55-K55 -> -93.306012 | Q55: =N55/K55 -> 0.89632665 | S55: 0.25 | T55: 0.54612269 | AA55: =M55-J55 -> -359.89462 | AB55: =M55/J55 -> 0.89632665
A56: GKK3600型 飯糰機2 | B56: 18℃-飯糰 | C56: 一配椒鹽檸檬鯖魚飯糰 | E56: 20.72 | F56: 1778 | G56: =E56*F56 -> 36840.16 | I56: 3 | J56: 3600 | K56: =J56/I56 -> 1200 | L56: 3 | M56: =F56/V56*60 -> 3209.7184 | N56: =M56/L56 -> 1069.9061 | O56: =L56-I56 -> 0 | P56: =N56-K56 -> -130.09388 | Q56: =N56/K56 -> 0.89158843 | R56: =Q72 -> 0.89418958 | S56: 0.25 | T56: 0.2730787 | V56: 33.236561 | AA56: =M56-J56 -> -390.28164 | AB56: =M56/J56 -> 0.89158843 | AC56: =AB72 -> 0.89418958
B57: 18℃-飯糰 | C57: 一配贅沢鮭魚肚飯糰 | E57: 30 | F57: 1879 | G57: =E57*F57 -> 56370 | I57: 4 | J57: 3600 | K57: =J57/I57 -> 900 | L57: 4 | M57: =F57/V57*60 -> 3207.3911 | N57: =M57/L57 -> 801.84778 | O57: =L57-I57 -> 0 | P57: =N57-K57 -> -98.152224 | Q57: =N57/K57 -> 0.89094197 | S57: 0.28333333 | T57: 0.30774306 | U57: 14.766667 | V57: 35.150063 | AA57: =M57-J57 -> -392.6089 | AB57: =M57/J57 -> 0.89094197
B58: 18℃-飯糰 | C58: 一配筋子銀鮭飯糰 | E58: 30 | F58: 2723 | G58: =E58*F58 -> 81690 | I58: 4 | J58: 3300 | K58: =J58/I58 -> 825 | L58: 4 | M58: =F58/V58*60 -> 3007.4451 | N58: =M58/L58 -> 751.86128 | O58: =L58-I58 -> 0 | P58: =N58-K58 -> -73.13872 | Q58: =N58/K58 -> 0.91134701 | S58: 0.31805556 | T58: 0.35577546 | U58: 14.85 | V58: 54.325181 | AA58: =M58-J58 -> -292.55488 | AB58: =M58/J58 -> 0.91134701
B59: 18℃-飯糰 | C59: 一配鹽蔥生鮭飯糰 | E59: 27.48 | F59: 3686 | G59: =E59*F59 -> 101291.28 | I59: 5 | J59: 3600 | K59: =J59/I59 -> 720 | L59: 5 | M59: =F59/V59*60 -> 3207.6059 | N59: =M59/L59 -> 641.52118 | O59: =L59-I59 -> 0 | P59: =N59-K59 -> -78.478825 | Q59: =N59/K59 -> 0.89100163 | S59: 0.36597222 | T59: 0.41384259 | U59: 14.683333 | V59: 68.94862 | AA59: =M59-J59 -> -392.39412 | AB59: =M59/J59 -> 0.89100163
B60: 18℃-飯糰 | C60: 一配明太子龍蝦風味沙拉飯糰 | E60: 18.18 | F60: 2060 | G60: =E60*F60 -> 37450.8 | I60: 3 | J60: 3600 | K60: =J60/I60 -> 1200 | L60: 3 | M60: =F60/V60*60 -> 3207.4217 | N60: =M60/L60 -> 1069.1406 | O60: =L60-I60 -> 0 | P60: =N60-K60 -> -130.85943 | Q60: =N60/K60 -> 0.89095048 | S60: 0.42361111 | T60: 0.45037037 | U60: 15 | V60: 38.535625 | AA60: =M60-J60 -> -392.57828 | AB60: =M60/J60 -> 0.89095048
B61: 18℃-飯糰 | C61: 一配雞肉飯飯糰 | E61: 16.66 | F61: 5103 | G61: =E61*F61 -> 85015.98 | I61: 5 | J61: 3600 | K61: =J61/I61 -> 720 | L61: 5 | M61: =F61/V61*60 -> 3206.6558 | N61: =M61/L61 -> 641.33117 | O61: =L61-I61 -> 0 | P61: =N61-K61 -> -78.668834 | Q61: =N61/K61 -> 0.89073773 | S61: 0.46041667 | T61: 0.52671296 | U61: 15 | V61: 95.482651 | AA61: =M61-J61 -> -393.34417 | AB61: =M61/J61 -> 0.89073773
B72: 平均 | I72: =AVERAGE(I56:I71) -> 4 | J72: =AVERAGE(J56:J71) -> 3550 | K72: =J72/I72 -> 887.5 | L72: =AVERAGE(L56:L71) -> 4 | M72: =AVERAGE(M56:M71) -> 3174.373 | N72: =M72/L72 -> 793.59325 | O72: =L72-I72 -> 0 | P72: =N72-K72 -> -93.90675 | Q72: =N72/K72 -> 0.89418958 | S72: 0.25 | T72: 0.52671296 | AA72: =M72-J72 -> -375.627 | AB72: =M72/J72 -> 0.89418958
A73: 自動包裝機 (二配) | B73: 18℃-飯糰 | C73: 二配兩粒飯糰(鮪魚.焦糖鮭魚) | E73: 28.57 | F73: 1259 | G73: =E73*F73 -> 35969.63 | I73: 12 | J73: 3600 | K73: =J73/I73 -> 300 | L73: 12 | M73: =F73/V73*60 -> 3121.9749 | N73: =M73/L73 -> 260.16458 | O73: =L73-I73 -> 0 | P73: =N73-K73 -> -39.835425 | Q73: =N73/K73 -> 0.86721525 | R73: =Q89 -> 0.89362319 | S73: 0.70833333 | T73: 0.72512731 | V73: 24.196223 | AA73: =M73-J73 -> -478.0251 | AB73: =M73/J73 -> 0.86721525 | AC73: =AB89 -> 0.89362319
B74: 18℃-飯糰 | C74: 二配柚香雞胸五穀飯糰 | E74: 17.71 | F74: 626 | G74: =E74*F74 -> 11086.46 | I74: 5 | J74: 3600 | K74: =J74/I74 -> 720 | L74: 5 | M74: =F74/V74*60 -> 3265.7013 | N74: =M74/L74 -> 653.14026 | O74: =L74-I74 -> 0 | P74: =N74-K74 -> -66.85974 | Q74: =N74/K74 -> 0.90713925 | S74: 0.72916667 | T74: 0.73715278 | U74: 5.8166667 | V74: 11.501358 | AA74: =M74-J74 -> -334.2987 | AB74: =M74/J74 -> 0.90713925
B75: 18℃-飯糰 | C75: 二配鮭魚毛豆炊飯飯糰 | E75: 18.92 | F75: 1096 | G75: =E75*F75 -> 20736.32 | I75: 5 | J75: 3600 | K75: =J75/I75 -> 720 | L75: 5 | M75: =F75/V75*60 -> 3263.4542 | N75: =M75/L75 -> 652.69084 | O75: =L75-I75 -> 0 | P75: =N75-K75 -> -67.30916 | Q75: =N75/K75 -> 0.90651506 | S75: 0.74027778 | T75: 0.75427083 | U75: 5 | V75: 20.150428 | AA75: =M75-J75 -> -336.5458 | AB75: =M75/J75 -> 0.90651506
B89: 平均 | I89: =AVERAGE(I73:I88) -> 7.3333333 | J89: =AVERAGE(J73:J88) -> 3600 | K89: =J89/I89 -> 490.90909 | L89: =AVERAGE(L73:L88) -> 7.3333333 | M89: =AVERAGE(M73:M88) -> 3217.0435 | N89: =M89/L89 -> 438.68775 | O89: =L89-I89 -> 0 | P89: =N89-K89 -> -52.221345 | Q89: =N89/K89 -> 0.89362319 | S89: 0.70833333 | T89: 0.75427083 | AA89: =M89-J89 -> -382.95653 | AB89: =M89/J89 -> 0.89362319
A90: (新) 3300型飯糰機 (二配) | B90: 18℃-飯糰 | C90: 二配大飯糰乾燒風味鮮蝦 | E90: 23.27 | F90: 559 | G90: =E90*F90 -> 13007.93 | I90: 5 | J90: 3000 | K90: =J90/I90 -> 600 | L90: 5 | M90: =F90/V90*60 -> 2733.7218 | N90: =M90/L90 -> 546.74437 | O90: =L90-I90 -> 0 | P90: =N90-K90 -> -53.255633 | Q90: =N90/K90 -> 0.91124061 | R90: =Q106 -> 0.9106916 | S90: 0.70833333 | T90: 0.71685185 | V90: 12.268988 | AA90: =M90-J90 -> -266.27816 | AB90: =M90/J90 -> 0.91124061 | AC90: =AB106 -> 0.9106916
B91: 18℃-飯糰 | C91: 二配大飯糰韓式蒜烤豬五花 | E91: 24.54 | F91: 1301 | G91: =E91*F91 -> 31926.54 | I91: 4 | J91: 3000 | K91: =J91/I91 -> 750 | L91: 4 | M91: =F91/V91*60 -> 2731.3787 | N91: =M91/L91 -> 682.84467 | O91: =L91-I91 -> 0 | P91: =N91-K91 -> -67.155331 | Q91: =N91/K91 -> 0.91045956 | S91: 0.72083333 | T91: 0.7406713 | U91: 5.7333333 | V91: 28.578974 | AA91: =M91-J91 -> -268.62132 | AB91: =M91/J91 -> 0.91045956
B92: 18℃-飯糰 | C92: 二配大飯糰泡菜鮪魚 | E92: 24.33 | F92: 1451 | G92: =E92*F92 -> 35302.83 | I92: 4 | J92: 3000 | K92: =J92/I92 -> 750 | L92: 4 | M92: =F92/V92*60 -> 2731.5766 | N92: =M92/L92 -> 682.89416 | O92: =L92-I92 -> 0 | P92: =N92-K92 -> -67.105839 | Q92: =N92/K92 -> 0.91052555 | S92: 0.74444444 | T92: 0.76657407 | U92: 5.4333333 | V92: 31.871703 | AA92: =M92-J92 -> -268.42336 | AB92: =M92/J92 -> 0.91052555
B93: 18℃-飯糰 | C93: 二配壹號醬炙烤牛飯糰 | E93: 22.28 | F93: 1426 | G93: =E93*F93 -> 31771.28 | I93: 5 | J93: 3300 | K93: =J93/I93 -> 660 | L93: 5 | M93: =F93/V93*60 -> 3007.7415 | N93: =M93/L93 -> 601.5483 | O93: =L93-I93 -> 0 | P93: =N93-K93 -> -58.451698 | Q93: =N93/K93 -> 0.91143682 | S93: 0.77013889 | T93: 0.78988426 | U93: 5.1333333 | V93: 28.446593 | AA93: =M93-J93 -> -292.25849 | AB93: =M93/J93 -> 0.91143682
B94: 18℃-飯糰 | C94: 二配鹽蔥燒肉飯糰 | E94: 17.89 | F94: 4664 | G94: =E94*F94 -> 83438.96 | I94: 4 | J94: 3300 | K94: =J94/I94 -> 825 | L94: 4 | M94: =F94/V94*60 -> 3002.3703 | N94: =M94/L94 -> 750.59257 | O94: =L94-I94 -> 0 | P94: =N94-K94 -> -74.407428 | Q94: =N94/K94 -> 0.90980918 | S94: 0.79375 | T94: 0.85847222 | U94: 5.5666667 | V94: 93.206358 | AA94: =M94-J94 -> -297.62971 | AB94: =M94/J94 -> 0.90980918
B106: 平均 | I106: =AVERAGE(I90:I105) -> 4.4 | J106: =AVERAGE(J90:J105) -> 3120 | K106: =J106/I106 -> 709.09091 | L106: =AVERAGE(L90:L105) -> 4.4 | M106: =AVERAGE(M90:M105) -> 2841.3578 | N106: =M106/L106 -> 645.76313 | O106: =L106-I106 -> 0 | P106: =N106-K106 -> -63.327775 | Q106: =N106/K106 -> 0.9106916 | S106: 0.70833333 | T106: 0.85847222 | AA106: =M106-J106 -> -278.64221 | AB106: =M106/J106 -> 0.9106916
A107: GKK3600型 飯糰機 (二配) | B107: 18℃-飯糰 | C107: 二配芝麻香鬆飯糰 | E107: 18.18 | F107: 588 | G107: =E107*F107 -> 10689.84 | H107: 2 | I107: 3 | J107: 3000 | K107: =J107/I107 -> 1000 | L107: 3 | M107: =F107/V107*60 -> 2736.4541 | N107: =M107/L107 -> 912.15137 | O107: =L107-I107 -> 0 | P107: =N107-K107 -> -87.848628 | Q107: =N107/K107 -> 0.91215137 | R107: =Q123 -> 0.90198993 | S107: 0.73055556 | T107: 0.73950231 | V107: 12.892597 | AA107: =M107-J107 -> -263.54588 | AB107: =M107/J107 -> 0.91215137 | AC107: =AB123 -> 0.90198993
...

Sheet 0730(4度C)
A1: 大溪廠日報分析 | C1: 總生產量 | D1: =SUM(F5:F140) -> 85929 | E1: 營業額 | F1: =SUM(G5:G140) -> 3741123.7 | G1: 出勤人數 | H1: =L21+L38+L55+L72+L89+L106+L123+L140 -> 136.25833 | I1: 產線配置圖 | L1: 生產實績 | O1: 人時性差異分析 | S1: 日報登錄 | Y1: 合計次數 | Z1: 合計(時間/分) | AA1: 產線異常 分析說明(5分鐘以上) | AC1: 合計次數 | AD1: 合計(時間/分) | AE1: 產能差異分析
A2: 46233 | C2: 人時性 | D2: =AVERAGE(N21,N38,N55,N72,N89,N106,N123,N140) -> 201.16842 | E2: 平均廠價 | F2: =F1/D1 -> 43.537382 | G2: 多次生產數 | H2: =COUNT(H5:H140) -> 0 | Y2: =SUM(Y21,Y38,Y55,Y72,Y89,Y106,Y123,Y140) -> 0 | Z2: =SUM(Z21,Z38,Z55,Z72,Z89,Z106,Z123,Z140) -> 0 | AC2: =SUM(AC21,AC38,AC55,AC72,AC89,AC106,AC123,AC140) -> 0 | AD2: =SUM(AD21,AD38,AD55,AD72,AD89,AD106,AD123,AD140) -> 0
A3: 線別 | B3: 品類 | C3: 品名 | E3: 廠價 | F3: 生產量 | G3: 營收 | H3: 多次 生產 | I3: 人數 | J3: 產能/時 | K3: 人時性 | L3: 人數 | M3: 產能/時 | N3: 人時性 | O3: 人數 | P3: 人時性 | Q3: 達成率 | R3: 達成率 平均 | S3: 生產時間 | U3: 換線、休息/分 | V3: 稼動時間/分 | W3: 休息時間 | Y3: 產線異常統計(5分鐘以上) | AA3: (屏榮回填) | AC3: 短暫停線統計(5分鐘以下) | AE3: 產能/時 | AF3: 達成率 | AG3: 達成率平均
S4: 開始 | T4: 結束 | W4: 開始 | X4: 結束 | Y4: 次數 | Z4: 時間/分 | AC4: 總次數 | AD4: 設備因素(次數)
