Workbook

Sheet 0831
B1: 屏榮 大溪廠組合室生產人時性分析
B3: 日期 | C3: 115.08.31星期一 | E3: 訂單量 | F3: ='0831(18度C)'!D1+'0831(4度C)'!D1 -> 177281 | H3: 營業額 | I3: ='0831(18度C)'!F1+'0831(4度C)'!F1 -> 5898192.5
B4: 人時性 | C4: 項目 | E4: ➀ | G4: ➁ | I4: ➂ | K4: ④ | M4: ⑤ | O4: 異常停線 | Q4: 短暫停線
C5: 組合室 | E5: 全溫層 | G5: 4度C-各編組展開(一配) | I5: 4度C-各編組展開(二配) | K5: 18度C-各編組展開(一配) | M5: 18度C-各編組展開(二配) | O5: 合計次數 | P5: 時間 | Q5: 合計次數 | R5: 設備次數
C6: 排關平均 | E6: =AVERAGE(D14:O14,D32:X32) -> 496.61355 | F6: =AVERAGE(#REF!,D14:K14) -> #REF! | G6: =AVERAGE(D14:K14) -> 276.1197 | I6: =AVERAGE(L14:O14) -> 94.325718 | K6: =AVERAGE(D32:O32) -> 754.19394 | M6: =AVERAGE(P32:X32) -> 770.91785 | O6: ='0831(4度C)'!Y2 -> 0 | P6: ='0831(4度C)'!Z2 -> 0 | Q6: ='0831(4度C)'!AC2 -> 0 | R6: ='0831(4度C)'!AD2 -> 0
C7: 實績平均 | E7: =AVERAGE(D15:O15,D33:X33) -> 448.28439 | F7: =AVERAGE(#REF!,D15:K15) -> #REF! | G7: =AVERAGE(D15:K15) -> 249.43326 | I7: =AVERAGE(L15:O15) -> 87.598921 | K7: =AVERAGE(D33:O33) -> 683.89348 | M7: =AVERAGE(P33:X33) -> 691.2947
C8: 達成率平均 | E8: =AVERAGE(D16:O16,D34:X34) -> 0.90420411 | F8: =AVERAGE(D16:K16,#REF!) -> #REF! | G8: =AVERAGE(D16:K16) -> 0.9029267 | I8: =AVERAGE(L16:O16) -> 0.9267745 | K8: =AVERAGE(D34:O34) -> 0.90246043 | M8: =AVERAGE(P34:X34) -> 0.89657872
O9: ※現行日本鮮食廠以達成率80%為基本(即為現行KPI)
B11: 溫層 | D11: ➁4度C-各編組展開 | L11: ➂4度C-各編組展開
B12: 編組 | D12: 1 | E12: 2 | F12: 3 | G12: 4 | H12: 5 | I12: 6 | J12: 7 | K12: 8 | L12: 1 | M12: 2 | N12: 3 | O12: 4
D13: 便當一線 | E13: 便當二線 | F13: 涼麵一線 | G13: 涼麵二線 | H13: 涼麵三線 | I13: 自動包裝機 | J13: 自動包裝機2 | K13: 自動包裝機3 | L13: 便當一線 | M13: 便當二線 | N13: 涼麵一線 | O13: 涼麵二線
B14: 人時性 | C14: 排關 | D14: - | E14: 85.245902 | F14: 104.87603 | G14: 85.714286 | H14: 178.88199 | I14: 502 | J14: 700 | K14: - | L14: - | M14: 101.69492 | N14: 86.956522 | O14: -
C15: 實績 | D15: - | E15: 76.98086 | F15: 94.782902 | G15: 77.384913 | H15: 160.96847 | I15: 454.25368 | J15: 632.22876 | K15: - | L15: - | M15: 96.735714 | N15: 78.462128 | O15: -
C16: 達成率 | D16: - | E16: =E15/E14 -> 0.90304471 | F16: =F15/F14 -> 0.90376132 | G16: =G15/G14 -> 0.90282398 | H16: =H15/H14 -> 0.89985846 | I16: =I15/I14 -> 0.90488781 | J16: =J15/J14 -> 0.90318394 | K16: - | L16: - | M16: =M15/M14 -> 0.95123452 | N16: =N15/N14 -> 0.90231447 | O16: -
B17: 作業 時間 | C17: 開始 | D17: - | E17: 0.20833333 | F17: 0.16666667 | G17: 0.16666667 | H17: 0.20833333 | I17: 0.16666667 | J17: 0.25 | K17: - | L17: - | M17: 0.70833333 | N17: 0.70833333 | O17: -
C18: 結束 | D18: - | E18: 0.61980324 | F18: 0.54282407 | G18: 0.57949074 | H18: 0.56479167 | I18: 0.43425926 | J18: 0.30453704 | K18: - | L18: - | M18: 0.82475694 | N18: 0.86189815 | O18: -
B19: 產線異常 (5分鐘以上) | C19: 次數
C20: 時間/分
B21: 短暫停線 (5分鐘以下) | C21: 次數
C22: 設備次數
B23: 配置人數 | D23: - | E23: 20.333333 | F23: 20.333333 | G23: 23.333333 | H23: 20.125 | I23: 5.75 | J23: 6 | K23: - | L23: - | M23: 18.666667 | N23: 23 | O23: -
B24: 主要應用設備 | D24: L型封口機 | E24: ET-55 | F24: ET-55 | G24: ET-55 | H24: ET-600 | I24: 伺服包裝機 | J24: 伺服包裝機 | K24: 伺服包裝機 | L24: L型封口機 | M24: ET-55 | N24: ET-55 | O24: ET-55
B25: 次要應用設備 | D25: 伺服包裝機 | H25: 伺服包裝機
B26: 備註 | H26: 涼麵+烤飯糰 | I26: 大口飯糰線 | K26: 烤飯糰+手卷
B29: 溫層 | D29: ➃18度C-各編組展開 (一配) | P29: ⑤18度C-各編組展開 (二配)
B30: 編組 | D30: 1 | E30: 2 | F30: 3 | G30: 4 | H30: 5 | I30: 6 | J30: 7 | K30: 8 | L30: 9 | M30: 10 | N30: 11 | O30: 12 | P30: 1 | Q30: 2 | R30: 3 | S30: 4 | T30: 5 | U30: 6 | V30: 7 | W30: 8 | X30: 9
D31: 便當一線 | E31: 涼麵一線 | F31: 涼麵三線 | G31: 自動包裝機 | H31: 自動包裝機2 | I31: 自動包裝機3 | J31: 味付飯糰線B | K31: (舊) 3300型飯糰線 | L31: 3000型飯糰線 | M31: (新) 3300型飯糰機 | N31: GKK3600型 飯糰機 | O31: GKK3600型 飯糰機2 | P31: 自動包裝機 | Q31: 自動包裝機2 | R31: 自動包裝機3 | S31: 味付飯糰線B | T31: (舊) 3300型飯糰線 | U31: 3000型飯糰線 | V31: (新) 3300型飯糰機 | W31: GKK3600型 飯糰機 | X31: GKK3600型 飯糰機2
B32: 人時性 | C32: 排關 | D32: - | E32: - | F32: - | G32: 327.27273 | H32: - | I32: - | J32: - | K32: - | L32: - | M32: 825 | N32: 1005.8824 | O32: 858.62069 | P32: 423.52941 | Q32: - | R32: - | S32: - | T32: - | U32: - | V32: 741.17647 | W32: 1050 | X32: 868.96552
C33: 實績 | D33: - | E33: - | F33: - | G33: 287.45578 | H33: - | I33: - | J33: - | K33: - | L33: - | M33: 759.31811 | N33: 913.49261 | O33: 775.30744 | P33: 375.38684 | Q33: - | R33: - | S33: - | T33: - | U33: - | V33: 682.15979 | W33: 935.02965 | X33: 772.60253
C34: 達成率 | D34: - | E34: - | F34: - | G34: =G33/G32 -> 0.8783371 | H34: - | I34: - | J34: - | K34: - | L34: - | M34: =M33/M32 -> 0.92038559 | N34: =N33/N32 -> 0.90815055 | O34: =O33/O32 -> 0.9029685 | P34: =P33/P32 -> 0.88633005 | Q34: - | R34: - | S34: - | T34: - | U34: - | V34: =V33/V32 -> 0.92037432 | W34: =W33/W32 -> 0.89050443 | X34: =X33/X32 -> 0.88910609
B35: 作業 時間 | C35: 開始 | D35: - | E35: - | F35: - | G35: 0.16666667 | H35: - | I35: - | J35: - | K35: - | L35: - | M35: 0.32222222 | N35: 0.25 | O35: 0.25 | P35: 0.70833333 | Q35: - | R35: - | S35: - | T35: - | U35: - | V35: 0.70833333 | W35: 0.72638889 | X35: 0.70833333
C36: 結束 | D36: - | E36: - | F36: - | G36: 0.43425926 | H36: - | I36: - | J36: - | K36: - | L36: - | M36: 0.42141204 | N36: 0.44452546 | O36: 0.45101852 | P36: 0.72873843 | Q36: - | R36: - | S36: - | T36: - | U36: - | V36: 0.83298611 | W36: 1.1025463 | X36: 1.0927894
B37: 配置人數 | D37: - | E37: - | F37: - | G37: 11 | H37: - | I37: - | J37: - | K37: - | L37: - | M37: 4 | N37: 3.4 | O37: 4.1428571 | P37: 8.5 | Q37: - | R37: - | S37: - | T37: - | U37: - | V37: 4.25 | W37: 3.2 | X37: 4.1428571
B38: 主要應用設備 | D38: 伺服包裝機 | E38: ET-55 | F38: ET-600 | G38: 夾心型 | H38: 伺服包裝機 | I38: 伺服包裝機 | J38: 夾心型 | K38: 3300型 | L38: 3300型 | M38: 3300型 | N38: GKK | O38: GKK | P38: 夾心型 | Q38: 伺服包裝機 | R38: 伺服包裝機 | S38: 夾心型 | T38: 3300型 | U38: 3300型 | V38: 3300型 | W38: GKK | X38: GKK
B39: 次要應用設備
B40: 備註

Sheet 0831(18度C)
A1: 大溪廠日報分析 | C1: 總生產量 | D1: =SUM(F5:F140) -> 85536 | E1: 營業額 | F1: =SUM(G5:G140) -> 1720173.9 | G1: 出勤人數 | H1: =L21+L38+L55+L72+L89+L106+L123+L140 -> 42.635714 | I1: 產線配置圖 | L1: 生產實績 | O1: 人時性差異分析 | S1: 日報登錄 | Y1: 分析說明 | AA1: 產能差異分析
A2: 46265 | C2: 人時性 | D2: =AVERAGE(N21,N38,N55,N72,N89,N106,N123,N140) -> 687.59409 | E2: 平均廠價 | F2: =F1/D1 -> 20.110525 | G2: 多次生產數 | H2: =COUNT(H5:H140) -> 12
A3: 線別 | B3: 品類 | C3: 品名 | E3: 廠價 | F3: 生產量 | G3: 營收 | H3: 多次 生產 | I3: 人數 | J3: 產能/時 | K3: 人時性 | L3: 人數 | M3: 產能/時 | N3: 人時性 | O3: 人數 | P3: 人時性 | Q3: 達成率 | R3: 達成率 平均 | S3: 生產時間 | U3: 換線、休息/分 | V3: 稼動時間/分 | W3: 休息時間 | Y3: (屏榮回填) | AA3: 產能/時 | AB3: 達成率 | AC3: 達成率平均
S4: 開始 | T4: 結束 | W4: 開始 | X4: 結束
A5: 自動包裝機 | B5: 18℃-壽司手卷 | C5: 一配長野稻荷壽司 | E5: 25.64 | F5: 1280 | G5: =E5*F5 -> 32819.2 | I5: 10 | J5: 3600 | K5: =J5/I5 -> 360 | L5: 10 | M5: =F5/V5*60 -> 3217.6096 | N5: =M5/L5 -> 321.76096 | O5: =L5-I5 -> 0 | P5: =N5-K5 -> -38.239045 | Q5: =N5/K5 -> 0.89378043 | R5: =Q21 -> 0.8783371 | S5: 0.16666667 | T5: 0.18324074 | V5: 23.868651 | AA5: =M5-J5 -> -382.39045 | AB5: =M5/J5 -> 0.89378043 | AC5: =AB21 -> 0.8783371
B6: 18℃-壽司手卷 | C6: 一配經典人氣雙手卷 | E6: 29.52 | F6: 2147 | G6: =E6*F6 -> 63379.44 | I6: 11 | J6: 3600 | K6: =J6/I6 -> 327.27273 | L6: 11 | M6: =F6/V6*60 -> 3156.1309 | N6: =M6/L6 -> 286.92099 | O6: =L6-I6 -> 0 | P6: =N6-K6 -> -40.351733 | Q6: =N6/K6 -> 0.87670304 | S6: 0.18611111 | T6: 0.21444444 | U6: 5 | V6: 40.815797 | AA6: =M6-J6 -> -443.86906 | AB6: =M6/J6 -> 0.87670304
B7: 18℃-壽司手卷 | C7: 一配鮭鮪海饌雙手卷 | E7: 29.85 | F7: 2573 | G7: =E7*F7 -> 76804.05 | I7: 11 | J7: 3600 | K7: =J7/I7 -> 327.27273 | L7: 11 | M7: =F7/V7*60 -> 3156.2508 | N7: =M7/L7 -> 286.93189 | O7: =L7-I7 -> 0 | P7: =N7-K7 -> -40.340837 | Q7: =N7/K7 -> 0.87673633 | S7: 0.21736111 | T7: 0.25131944 | U7: 5 | V7: 48.912463 | AA7: =M7-J7 -> -443.74921 | AB7: =M7/J7 -> 0.87673633
B8: 18℃-壽司手卷 | C8: 一配青木瓜雞絲泰泰雙手卷 | E8: 30 | F8: 555 | G8: =E8*F8 -> 16650 | I8: 11 | J8: 3600 | K8: =J8/I8 -> 327.27273 | L8: 11 | M8: =F8/V8*60 -> 3157.8362 | N8: =M8/L8 -> 287.07601 | O8: =L8-I8 -> 0 | P8: =N8-K8 -> -40.196712 | Q8: =N8/K8 -> 0.87717671 | S8: 0.25486111 | T8: 0.26217593 | U8: 5.1 | V8: 10.545196 | AA8: =M8-J8 -> -442.16384 | AB8: =M8/J8 -> 0.87717671
B9: 18℃-飯糰 | C9: 一配兩粒飯糰(鮪魚.焦糖鮭魚) | E9: 28.57 | F9: 884 | G9: =E9*F9 -> 25255.88 | I9: 12 | J9: 3600 | K9: =J9/I9 -> 300 | L9: 12 | M9: =F9/V9*60 -> 3122.2403 | N9: =M9/L9 -> 260.18669 | O9: =L9-I9 -> 0 | P9: =N9-K9 -> -39.81331 | Q9: =N9/K9 -> 0.86728897 | S9: 0.26597222 | T9: 0.2777662 | U9: 5.4666667 | V9: 16.987802 | AA9: =M9-J9 -> -477.75972 | AB9: =M9/J9 -> 0.86728897
B21: 平均 | I21: =AVERAGE(I5:I20) -> 11 | J21: =AVERAGE(J5:J20) -> 3600 | K21: =J21/I21 -> 327.27273 | L21: =AVERAGE(L5:L20) -> 11 | M21: =AVERAGE(M5:M20) -> 3162.0135 | N21: =M21/L21 -> 287.45578 | O21: =L21-I21 -> 0 | P21: =N21-K21 -> -39.81695 | Q21: =N21/K21 -> 0.8783371 | S21: 0.16666667 | T21: 0.43425926 | AA21: =M21-J21 -> -437.98645 | AB21: =M21/J21 -> 0.8783371
A22: (新) 3300型飯糰機 | B22: 18℃-飯糰 | C22: 一配鮭魚奶油醬油飯糰 | E22: 18.53 | F22: 1739 | G22: =E22*F22 -> 32223.67 | I22: 3 | J22: 3300 | K22: =J22/I22 -> 1100 | L22: 3 | M22: =F22/V22*60 -> 3037.0052 | N22: =M22/L22 -> 1012.3351 | O22: =L22-I22 -> 0 | P22: =N22-K22 -> -87.664931 | Q22: =N22/K22 -> 0.92030461 | R22: =Q38 -> 0.92038559 | S22: 0.32222222 | T22: 0.34607639 | V22: 34.356214 | AA22: =M22-J22 -> -262.99479 | AB22: =M22/J22 -> 0.92030461 | AC22: =AB38 -> 0.92038559
B23: 18℃-飯糰 | C23: 一配鹽蔥燒肉飯糰 | E23: 17.89 | F23: 2151 | G23: =E23*F23 -> 38481.39 | I23: 4 | J23: 3300 | K23: =J23/I23 -> 825 | L23: 4 | M23: =F23/V23*60 -> 3036.6148 | N23: =M23/L23 -> 759.15371 | O23: =L23-I23 -> 0 | P23: =N23-K23 -> -65.846295 | Q23: =N23/K23 -> 0.92018631 | S23: 0.34930556 | T23: 0.37881944 | U23: 4.65 | V23: 42.501274 | AA23: =M23-J23 -> -263.38518 | AB23: =M23/J23 -> 0.92018631
B24: 18℃-飯糰 | C24: 一配醬燒炙烤牛飯糰 | E24: 22.32 | F24: 2828 | G24: =E24*F24 -> 63120.96 | I24: 5 | J24: 3300 | K24: =J24/I24 -> 660 | L24: 5 | M24: =F24/V24*60 -> 3038.1973 | N24: =M24/L24 -> 607.63945 | O24: =L24-I24 -> 0 | P24: =N24-K24 -> -52.360545 | Q24: =N24/K24 -> 0.92066584 | S24: 0.38263889 | T24: 0.42141204 | U24: 5.5 | V24: 55.848908 | AA24: =M24-J24 -> -261.80273 | AB24: =M24/J24 -> 0.92066584
B38: 平均 | I38: =AVERAGE(I22:I37) -> 4 | J38: =AVERAGE(J22:J37) -> 3300 | K38: =J38/I38 -> 825 | L38: =AVERAGE(L22:L37) -> 4 | M38: =AVERAGE(M22:M37) -> 3037.2724 | N38: =M38/L38 -> 759.31811 | O38: =L38-I38 -> 0 | P38: =N38-K38 -> -65.681892 | Q38: =N38/K38 -> 0.92038559 | S38: 0.32222222 | T38: 0.42141204 | AA38: =M38-J38 -> -262.72757 | AB38: =M38/J38 -> 0.92038559
A39: GKK3600型 飯糰機 | B39: 18℃-飯糰 | C39: 一配北海道秋鮭親子飯糰 | E39: 24.82 | F39: 794 | G39: =E39*F39 -> 19707.08 | I39: 5 | J39: 3600 | K39: =J39/I39 -> 720 | L39: 5 | M39: =F39/V39*60 -> 3244.9056 | N39: =M39/L39 -> 648.98112 | O39: =L39-I39 -> 0 | P39: =N39-K39 -> -71.018879 | Q39: =N39/K39 -> 0.90136267 | R39: =Q55 -> 0.90815055 | S39: 0.25 | T39: 0.26018519 | V39: 14.681475 | AA39: =M39-J39 -> -355.09439 | AB39: =M39/J39 -> 0.90136267 | AC39: =AB55 -> 0.90815055
B40: 18℃-飯糰 | C40: 一配蔬食鮪魚飯糰 | E40: 18.18 | F40: 853 | G40: =E40*F40 -> 15507.54 | I40: 3 | J40: 3600 | K40: =J40/I40 -> 1200 | L40: 3 | M40: =F40/V40*60 -> 3241.8832 | N40: =M40/L40 -> 1080.6277 | O40: =L40-I40 -> 0 | P40: =N40-K40 -> -119.37225 | Q40: =N40/K40 -> 0.90052312 | S40: 0.27013889 | T40: 0.28109954 | U40: 15 | V40: 15.78712 | AA40: =M40-J40 -> -358.11676 | AB40: =M40/J40 -> 0.90052312
B41: 18℃-飯糰 | C41: 一配黑胡椒洋蔥豬飯糰 | E41: 17.07 | F41: 1364 | G41: =E41*F41 -> 23283.48 | I41: 3 | J41: 3300 | K41: =J41/I41 -> 1100 | L41: 3 | M41: =F41/V41*60 -> 3041.0701 | N41: =M41/L41 -> 1013.69 | O41: =L41-I41 -> 0 | P41: =N41-K41 -> -86.309978 | Q41: =N41/K41 -> 0.92153638 | S41: 0.29097222 | T41: 0.30965278 | U41: 15 | V41: 26.91158 | AA41: =M41-J41 -> -258.92993 | AB41: =M41/J41 -> 0.92153638
B42: 18℃-飯糰 | C42: 一配經典肉鬆飯糰 | E42: 14.03 | F42: 3455 | G42: =E42*F42 -> 48473.65 | I42: 3 | J42: 3000 | K42: =J42/I42 -> 1000 | L42: 3 | M42: =F42/V42*60 -> 2762.6903 | N42: =M42/L42 -> 920.89677 | O42: =L42-I42 -> 0 | P42: =N42-K42 -> -79.103232 | Q42: =N42/K42 -> 0.92089677 | S42: 0.31944444 | T42: 0.37155093 | U42: 15 | V42: 75.035555 | AA42: =M42-J42 -> -237.3097 | AB42: =M42/J42 -> 0.92089677
B43: 18℃-飯糰 | C43: 一配鮪魚飯糰 | E43: 14.28 | F43: 4865 | G43: =E43*F43 -> 69472.2 | I43: 3 | J43: 3600 | K43: =J43/I43 -> 1200 | L43: 3 | M43: =F43/V43*60 -> 3238.8252 | N43: =M43/L43 -> 1079.6084 | O43: =L43-I43 -> 0 | P43: =N43-K43 -> -120.39159 | Q43: =N43/K43 -> 0.89967368 | S43: 0.38194444 | T43: 0.44452546 | U43: 14.966667 | V43: 90.12527 | AA43: =M43-J43 -> -361.17476 | AB43: =M43/J43 -> 0.89967368
B55: 平均 | I55: =AVERAGE(I39:I54) -> 3.4 | J55: =AVERAGE(J39:J54) -> 3420 | K55: =J55/I55 -> 1005.8824 | L55: =AVERAGE(L39:L54) -> 3.4 | M55: =AVERAGE(M39:M54) -> 3105.8749 | N55: =M55/L55 -> 913.49261 | O55: =L55-I55 -> 0 | P55: =N55-K55 -> -92.389738 | Q55: =N55/K55 -> 0.90815055 | S55: 0.25 | T55: 0.44452546 | AA55: =M55-J55 -> -314.12511 | AB55: =M55/J55 -> 0.90815055
A56: GKK3600型 飯糰機2 | B56: 18℃-飯糰 | C56: 一配熟成紅鮭飯糰 | E56: 25.03 | F56: 676 | G56: =E56*F56 -> 16920.28 | I56: 5 | J56: 3600 | K56: =J56/I56 -> 720 | L56: 5 | M56: =F56/V56*60 -> 3244.7502 | N56: =M56/L56 -> 648.95004 | O56: =L56-I56 -> 0 | P56: =N56-K56 -> -71.049955 | Q56: =N56/K56 -> 0.90131951 | R56: =Q72 -> 0.9029685 | S56: 0.25 | T56: 0.25868056 | V56: 12.500192 | AA56: =M56-J56 -> -355.24978 | AB56: =M56/J56 -> 0.90131951 | AC56: =AB72 -> 0.9029685
B57: 18℃-飯糰 | C57: 一配椒鹽檸檬鯖魚飯糰 | E57: 20.72 | F57: 946 | G57: =E57*F57 -> 19601.12 | I57: 3 | J57: 3600 | K57: =J57/I57 -> 1200 | L57: 3 | M57: =F57/V57*60 -> 3241.1561 | N57: =M57/L57 -> 1080.3854 | O57: =L57-I57 -> 0 | P57: =N57-K57 -> -119.61462 | Q57: =N57/K57 -> 0.90032115 | S57: 0.26875 | T57: 0.28090278 | U57: 14.5 | V57: 17.51227 | AA57: =M57-J57 -> -358.84386 | AB57: =M57/J57 -> 0.90032115
B58: 18℃-飯糰 | C58: 一配明太子龍蝦風味沙拉飯糰 | E58: 18.18 | F58: 1492 | G58: =E58*F58 -> 27124.56 | I58: 3 | J58: 3600 | K58: =J58/I58 -> 1200 | L58: 3 | M58: =F58/V58*60 -> 3242.1156 | N58: =M58/L58 -> 1080.7052 | O58: =L58-I58 -> 0 | P58: =N58-K58 -> -119.29479 | Q58: =N58/K58 -> 0.90058768 | S58: 0.29097222 | T58: 0.31013889 | U58: 14.5 | V58: 27.6116 | AA58: =M58-J58 -> -357.88437 | AB58: =M58/J58 -> 0.90058768
B59: 18℃-飯糰 | C59: 一配贅沢鮭魚肚飯糰 | E59: 30 | F59: 1237 | G59: =E59*F59 -> 37110 | I59: 4 | J59: 3600 | K59: =J59/I59 -> 900 | L59: 4 | M59: =F59/V59*60 -> 3240.4578 | N59: =M59/L59 -> 810.11445 | O59: =L59-I59 -> 0 | P59: =N59-K59 -> -89.885554 | Q59: =N59/K59 -> 0.90012716 | S59: 0.32013889 | T59: 0.33604167 | U59: 15 | V59: 22.904171 | AA59: =M59-J59 -> -359.54222 | AB59: =M59/J59 -> 0.90012716
B60: 18℃-飯糰 | C60: 一配筋子銀鮭飯糰 | E60: 30 | F60: 992 | G60: =E60*F60 -> 29760 | I60: 4 | J60: 3300 | K60: =J60/I60 -> 825 | L60: 4 | M60: =F60/V60*60 -> 3037.8679 | N60: =M60/L60 -> 759.46698 | O60: =L60-I60 -> 0 | P60: =N60-K60 -> -65.53302 | Q60: =N60/K60 -> 0.92056604 | S60: 0.34583333 | T60: 0.35943287 | U60: 15 | V60: 19.592689 | AA60: =M60-J60 -> -262.13208 | AB60: =M60/J60 -> 0.92056604
B61: 18℃-飯糰 | C61: 一配鹽蔥生鮭飯糰 | E61: 27.48 | F61: 1556 | G61: =E61*F61 -> 42758.88 | I61: 5 | J61: 3600 | K61: =J61/I61 -> 720 | L61: 5 | M61: =F61/V61*60 -> 3238.6513 | N61: =M61/L61 -> 647.73026 | O61: =L61-I61 -> 0 | P61: =N61-K61 -> -72.269742 | Q61: =N61/K61 -> 0.89962536 | S61: 0.36944444 | T61: 0.38945602 | U61: 15 | V61: 28.826815 | AA61: =M61-J61 -> -361.34871 | AB61: =M61/J61 -> 0.89962536
B62: 18℃-飯糰 | C62: 一配雞肉飯飯糰 | E62: 16.66 | F62: 4020 | G62: =E62*F62 -> 66973.2 | I62: 5 | J62: 3600 | K62: =J62/I62 -> 720 | L62: 5 | M62: =F62/V62*60 -> 3238.9167 | N62: =M62/L62 -> 647.78334 | O62: =L62-I62 -> 0 | P62: =N62-K62 -> -72.216656 | Q62: =N62/K62 -> 0.89969909 | S62: 0.39930556 | T62: 0.45101852 | U62: 15 | V62: 74.469343 | AA62: =M62-J62 -> -361.08328 | AB62: =M62/J62 -> 0.89969909
B72: 平均 | I72: =AVERAGE(I56:I71) -> 4.1428571 | J72: =AVERAGE(J56:J71) -> 3557.1429 | K72: =J72/I72 -> 858.62069 | L72: =AVERAGE(L56:L71) -> 4.1428571 | M72: =AVERAGE(M56:M71) -> 3211.988 | N72: =M72/L72 -> 775.30744 | O72: =L72-I72 -> 0 | P72: =N72-K72 -> -83.313251 | Q72: =N72/K72 -> 0.9029685 | S72: 0.25 | T72: 0.45101852 | AA72: =M72-J72 -> -345.1549 | AB72: =M72/J72 -> 0.9029685
A73: 自動包裝機 (二配) | B73: 18℃-飯糰 | C73: 二配兩粒飯糰(鮪魚.焦糖鮭魚) | E73: 28.57 | F73: 1041 | G73: =E73*F73 -> 29741.37 | I73: 12 | J73: 3600 | K73: =J73/I73 -> 300 | L73: 12 | M73: =F73/V73*60 -> 3122.1279 | N73: =M73/L73 -> 260.17733 | O73: =L73-I73 -> 0 | P73: =N73-K73 -> -39.822672 | Q73: =N73/K73 -> 0.86725776 | R73: =Q89 -> 0.88633005 | S73: 0.70833333 | T73: 0.72222222 | V73: 20.005586 | AA73: =M73-J73 -> -477.87207 | AB73: =M73/J73 -> 0.86725776 | AC73: =AB89 -> 0.88633005
B74: 18℃-飯糰 | C74: 二配柚香雞胸五穀飯糰 | E74: 17.71 | F74: 239 | G74: =E74*F74 -> 4232.69 | I74: 5 | J74: 3600 | K74: =J74/I74 -> 720 | L74: 5 | M74: =F74/V74*60 -> 3259.4484 | N74: =M74/L74 -> 651.88968 | O74: =L74-I74 -> 0 | P74: =N74-K74 -> -68.110317 | Q74: =N74/K74 -> 0.90540234 | S74: 0.72569444 | T74: 0.72873843 | U74: 5 | V74: 4.3995174 | AA74: =M74-J74 -> -340.55159 | AB74: =M74/J74 -> 0.90540234
B89: 平均 | I89: =AVERAGE(I73:I88) -> 8.5 | J89: =AVERAGE(J73:J88) -> 3600 | K89: =J89/I89 -> 423.52941 | L89: =AVERAGE(L73:L88) -> 8.5 | M89: =AVERAGE(M73:M88) -> 3190.7882 | N89: =M89/L89 -> 375.38684 | O89: =L89-I89 -> 0 | P89: =N89-K89 -> -48.142568 | Q89: =N89/K89 -> 0.88633005 | S89: 0.70833333 | T89: 0.72873843 | AA89: =M89-J89 -> -409.21183 | AB89: =M89/J89 -> 0.88633005
A90: (新) 3300型飯糰機 (二配) | B90: 18℃-飯糰 | C90: 二配大飯糰韓式蒜烤豬五花 | E90: 24.54 | F90: 906 | G90: =E90*F90 -> 22233.24 | I90: 4 | J90: 3000 | K90: =J90/I90 -> 750 | L90: 4 | M90: =F90/V90*60 -> 2762.0536 | N90: =M90/L90 -> 690.51339 | O90: =L90-I90 -> 0 | P90: =N90-K90 -> -59.486612 | Q90: =N90/K90 -> 0.92068452 | R90: =Q106 -> 0.92037432 | S90: 0.70833333 | T90: 0.72199074 | V90: 19.681009 | AA90: =M90-J90 -> -237.94645 | AB90: =M90/J90 -> 0.92068452 | AC90: =AB106 -> 0.92037432
B91: 18℃-飯糰 | C91: 二配大飯糰泡菜鮪魚 | E91: 24.33 | F91: 829 | G91: =E91*F91 -> 20169.57 | I91: 4 | J91: 3000 | K91: =J91/I91 -> 750 | L91: 4 | M91: =F91/V91*60 -> 2759.9951 | N91: =M91/L91 -> 689.99877 | O91: =L91-I91 -> 0 | P91: =N91-K91 -> -60.001232 | Q91: =N91/K91 -> 0.91999836 | S91: 0.72569444 | T91: 0.73820602 | U91: 5.3333333 | V91: 18.021771 | AA91: =M91-J91 -> -240.00493 | AB91: =M91/J91 -> 0.91999836
B92: 18℃-飯糰 | C92: 二配醬燒炙烤牛飯糰 | E92: 22.32 | F92: 2225 | G92: =E92*F92 -> 49662 | I92: 5 | J92: 3300 | K92: =J92/I92 -> 660 | L92: 5 | M92: =F92/V92*60 -> 3038.3732 | N92: =M92/L92 -> 607.67465 | O92: =L92-I92 -> 0 | P92: =N92-K92 -> -52.325351 | Q92: =N92/K92 -> 0.92071917 | S92: 0.74236111 | T92: 0.77287037 | U92: 5.9833333 | V92: 43.937986 | AA92: =M92-J92 -> -261.62675 | AB92: =M92/J92 -> 0.92071917
B93: 18℃-飯糰 | C93: 二配鹽蔥燒肉飯糰 | E93: 17.89 | F93: 4125 | G93: =E93*F93 -> 73796.25 | I93: 4 | J93: 3300 | K93: =J93/I93 -> 825 | L93: 4 | M93: =F93/V93*60 -> 3036.2945 | N93: =M93/L93 -> 759.07363 | O93: =L93-I93 -> 0 | P93: =N93-K93 -> -65.926366 | Q93: =N93/K93 -> 0.92008925 | S93: 0.77638889 | T93: 0.83298611 | U93: 5.0666667 | V93: 81.513831 | AA93: =M93-J93 -> -263.70546 | AB93: =M93/J93 -> 0.92008925
B106: 平均 | I106: =AVERAGE(I90:I105) -> 4.25 | J106: =AVERAGE(J90:J105) -> 3150 | K106: =J106/I106 -> 741.17647 | L106: =AVERAGE(L90:L105) -> 4.25 | M106: =AVERAGE(M90:M105) -> 2899.1791 | N106: =M106/L106 -> 682.15979 | O106: =L106-I106 -> 0 | P106: =N106-K106 -> -59.016682 | Q106: =N106/K106 -> 0.92037432 | S106: 0.70833333 | T106: 0.83298611 | AA106: =M106-J106 -> -250.8209 | AB106: =M106/J106 -> 0.92037432
A107: GKK3600型 飯糰機 (二配) | B107: 18℃-飯糰 | C107: 二配芝麻香鬆飯糰 | E107: 18.18 | F107: 653 | G107: =E107*F107 -> 11871.54 | H107: 2 | I107: 3 | J107: 3000 | K107: =J107/I107 -> 1000 | L107: 3 | M107: =F107/V107*60 -> 2762.3514 | N107: =M107/L107 -> 920.7838 | O107: =L107-I107 -> 0 | P107: =N107-K107 -> -79.216196 | Q107: =N107/K107 -> 0.9207838 | R107: =Q123 -> 0.89050443 | S107: 0.72638889 | T107: 0.73623843 | V107: 14.183568 | AA107: =M107-J107 -> -237.64859 | AB107: =M107/J107 -> 0.9207838 | AC107: =AB123 -> 0.89050443
B108: 18℃-飯糰 | C108: 二配蔬食鮪魚飯糰 | E108: 18.18 | F108: 417 | G108: =E108*F108 -> 7581.06 | H108: 2 | I108: 3 | J108: 3600 | K108: =J108/I108 -> 1200 | L108: 3 | M108: =F108/V108*60 -> 3239.4111 | N108: =M108/L108 -> 1079.8037 | O108: =L108-I108 -> 0 | P108: =N108-K108 -> -120.19629 | Q108: =N108/K108 -> 0.89983642 | S108: 0.74652778 | T108: 0.75188657 | U108: 14.816667 | V108: 7.723626 | AA108: =M108-J108 -> -360.58888 | AB108: =M108/J108 -> 0.89983642
B109: 18℃-飯糰 | C109: 二配卵黃牛挽肉飯糰 | E109: 24.76 | F109: 1610 | G109: =E109*F109 -> 39863.6 | H109: 2 | I109: 4 | J109: 3600 | K109: =J109/I109 -> 900 | L109: 4 | M109: =F109/V109*60 -> 2952 | N109: =M109/L109 -> 738 | O109: =L109-I109 -> 0 | P109: =N109-K109 -> -162 | Q109: =N109/K109 -> 0.82 | S109: 0.76180556 | T109: 0.78452546 | U109: 15 | V109: 32.723577 | AA109: =M109-J109 -> -648 | AB109: =M109/J109 -> 0.82
B110: 18℃-飯糰 | C110: 二配鮪魚飯糰 | E110: 14.28 | F110: 2970 | G110: =E110*F110 -> 42411.6 | H110: 2 | I110: 3 | J110: 3600 | K110: =J110/I110 -> 1200 | L110: 3 | M110: =F110/V110*60 -> 3239.5738 | N110: =M110/L110 -> 1079.8579 | O110: =L110-I110 -> 0 | P110: =N110-K110 -> -120.14207 | Q110: =N110/K110 -> 0.89988161 | S110: 0.79444444 | T110: 0.83263889 | U110: 15 | V110: 55.007236 | AA110: =M110-J110 -> -360.4262 | AB110: =M110/J110 -> 0.89988161
...

Sheet 0831(4度C)
A1: 大溪廠日報分析 | C1: 總生產量 | D1: =SUM(F5:F140) -> 91745 | E1: 營業額 | F1: =SUM(G5:G140) -> 4178018.6 | G1: 出勤人數 | H1: =L21+L38+L55+L72+L89+L106+L123+L140 -> 137.54167 | I1: 產線配置圖 | L1: 生產實績 | O1: 人時性差異分析 | S1: 日報登錄 | Y1: 合計次數 | Z1: 合計(時間/分) | AA1: 產線異常 分析說明(5分鐘以上) | AC1: 合計次數 | AD1: 合計(時間/分) | AE1: 產能差異分析
A2: 46265 | C2: 人時性 | D2: =AVERAGE(N21,N38,N55,N72,N89,N106,N123,N140) -> 208.97468 | E2: 平均廠價 | F2: =F1/D1 -> 45.539469 | G2: 多次生產數 | H2: =COUNT(H5:H140) -> 0 | Y2: =SUM(Y21,Y38,Y55,Y72,Y89,Y106,Y123,Y140) -> 0 | Z2: =SUM(Z21,Z38,Z55,Z72,Z89,Z106,Z123,Z140) -> 0 | AC2: =SUM(AC21,AC38,AC55,AC72,AC89,AC106,AC123,AC140) -> 0 | AD2: =SUM(AD21,AD38,AD55,AD72,AD89,AD106,AD123,AD140) -> 0
A3: 線別 | B3: 品類 | C3: 品名 | E3: 廠價 | F3: 生產量 | G3: 營收 | H3: 多次 生產 | I3: 人數 | J3: 產能/時 | K3: 人時性 | L3: 人數 | M3: 產能/時 | N3: 人時性 | O3: 人數 | P3: 人時性 | Q3: 達成率 | R3: 達成率 平均 | S3: 生產時間 | U3: 換線、休息/分 | V3: 稼動時間/分 | W3: 休息時間 | Y3: 產線異常統計(5分鐘以上) | AA3: (屏榮回填) | AC3: 短暫停線統計(5分鐘以下) | AE3: 產能/時 | AF3: 達成率 | AG3: 達成率平均
S4: 開始 | T4: 結束 | W4: 開始 | X4: 結束 | Y4: 次數 | Z4: 時間/分 | AC4: 總次數 | AD4: 設備因素(次數)
A5: 便當二線 | B5: 微波小吃 | C5: 日式茶碗蒸 | E5: 19.7 | F5: 3576 | G5: =E5*F5 -> 70447.2 | I5: 13 | J5: 1200 | K5: =J5/I5 -> 92.307692 | L5: 13 | M5: =F5/V5*60 -> 1084.1673 | N5: =M5/L5 -> 83.397484 | O5: =L5-I5 -> 0 | P5: =N5-K5 -> -8.9102086 | Q5: =N5/K5 -> 0.90347274 | R5: =Q21 -> 0.90304471 | S5: 0.20833333 | T5: 0.34576389 | V5: 197.90304 | AE5: =M5-J5 -> -115.83271 | AF5: =M5/J5 -> 0.90347274 | AG5: =AF21 -> 0.90304471
B6: 微波主食 | C6: 糖燻野郎三十天熟成牛飯 | E6: 56.43 | F6: 5065 | G6: =E6*F6 -> 285817.95 | I6: 24 | J6: 2000 | K6: =J6/I6 -> 83.333333 | L6: 24 | M6: =F6/V6*60 -> 1806.9548 | N6: =M6/L6 -> 75.289784 | O6: =L6-I6 -> 0 | P6: =N6-K6 -> -8.0435491 | Q6: =N6/K6 -> 0.90347741 | S6: 0.34930556 | T6: 0.46609954 | U6: 5.1 | V6: 168.18351 | W6: 0.46609954 | X6: 0.50416667 | AE6: =M6-J6 -> -193.04518 | AF6: =M6/J6 -> 0.90347741
B7: 便當 | C7: 健身G肉餐盒 | E7: 59.52 | F7: 5009 | G7: =E7*F7 -> 298135.68 | I7: 24 | J7: 2000 | K7: =J7/I7 -> 83.333333 | L7: 24 | M7: =F7/V7*60 -> 1804.7104 | N7: =M7/L7 -> 75.196265 | O7: =L7-I7 -> 0 | P7: =N7-K7 -> -8.1370679 | Q7: =N7/K7 -> 0.90235519 | S7: 0.50416667 | T7: 0.61980324 | U7: 54.816667 | V7: 166.53088 | AE7: =M7-J7 -> -195.28963 | AF7: =M7/J7 -> 0.90235519
B21: 平均 | I21: =AVERAGE(I5:I20) -> 20.333333 | J21: =AVERAGE(J5:J20) -> 1733.3333 | K21: =J21/I21 -> 85.245902 | L21: =AVERAGE(L5:L20) -> 20.333333 | M21: =AVERAGE(M5:M20) -> 1565.2775 | N21: =M21/L21 -> 76.98086 | O21: =L21-I21 -> 0 | P21: =N21-K21 -> -8.2650413 | Q21: =N21/K21 -> 0.90304471 | S21: 0.20833333 | T21: 0.61980324 | Y21: =SUM(Y5:Y20) -> 0 | Z21: =SUM(Z5:Z20) -> 0 | AC21: =SUM(AC5:AC20) -> 0 | AD21: =SUM(AD5:AD20) -> 0 | AE21: =M21-J21 -> -168.05584 | AF21: =M21/J21 -> 0.90304471
A22: 涼麵一線 | B22: 4℃-壽司手卷 | C22: 海陸雙拼壽司 | E22: 36.45 | F22: 2384 | G22: =E22*F22 -> 86896.8 | I22: 20 | J22: 2100 | K22: =J22/I22 -> 105 | L22: 20 | M22: =F22/V22*60 -> 1896.6383 | N22: =M22/L22 -> 94.831917 | O22: =L22-I22 -> 0 | P22: =N22-K22 -> -10.168083 | Q22: =N22/K22 -> 0.90316112 | R22: =Q38 -> 0.90376132 | S22: 0.16666667 | T22: 0.21903935 | V22: 75.417646 | AE22: =M22-J22 -> -203.36166 | AF22: =M22/J22 -> 0.90316112 | AG22: =AF38 -> 0.91123042
B23: 微波小吃 | C23: 越式牛肉寬粉 | E23: 51.44 | F23: 1380 | G23: =E23*F23 -> 70987.2 | I23: 19 | J23: 2000 | K23: =J23/I23 -> 105.26316 | L23: 19 | M23: =F23/V23*60 -> 1802.5709 | N23: =M23/L23 -> 94.872153 | O23: =L23-I23 -> 0 | P23: =N23-K23 -> -10.391004 | Q23: =N23/K23 -> 0.90128546 | S23: 0.22222222 | T23: 0.25412037 | U23: 4.5833333 | V23: 45.934393 | AE23: =M23-J23 -> -197.42908 | AF23: =M23/J23 -> 0.90128546
B24: 微波主食 | C24: 日式鮭魚茶泡烤飯 | E24: 43.28 | F24: 1782 | G24: =E24*F24 -> 77124.96 | I24: 21 | J24: 1800 | K24: =J24/I24 -> 85.714286 | L24: 21 | M24: =F24/V24*60 -> 1626.4049 | N24: =M24/L24 -> 77.447854 | O24: =L24-I24 -> 0 | P24: =N24-K24 -> -8.2664322 | Q24: =N24/K24 -> 0.90355829 | S24: 0.25694444 | T24: 0.30259259 | U24: 5 | V24: 65.740086 | AE24: =M24-J24 -> -173.59508 | AF24: =M24/J24 -> 0.90355829
B25: 便當 | C25: 懷舊滷雙拼便當 | E25: 61.09 | F25: 3442 | G25: =E25*F25 -> 210271.78 | I25: 20 | J25: 2000 | K25: =J25/I25 -> 100 | L25: 20 | M25: =F25/V25*60 -> 1806.0208 | N25: =M25/L25 -> 90.301041 | O25: =L25-I25 -> 0 | P25: =N25-K25 -> -9.6989585 | Q25: =N25/K25 -> 0.90301041 | S25: 0.30625 | T25: 0.38565972 | U25: 5.2666667 | V25: 114.35084 | AE25: =M25-J25 -> -193.97917 | AF25: =M25/J25 -> 0.90301041
B26: 便當 | C26: 香腸腿排雙拼便當 | E26: 53.76 | F26: 3411 | G26: =E26*F26 -> 183375.36 | I26: 20 | J26: 2000 | K26: =J26/I26 -> 100 | L26: 20 | M26: =F26/V26*60 -> 1805.2444 | N26: =M26/L26 -> 90.262219 | O26: =L26-I26 -> 0 | P26: =N26-K26 -> -9.7377806 | Q26: =N26/K26 -> 0.90262219 | S26: 0.38888889 | T26: 0.46761574 | U26: 4.65 | V26: 113.36969 | W26: 0.46761574 | X26: 0.50694444 | AE26: =M26-J26 -> -194.75561 | AF26: =M26/J26 -> 0.90262219
B27: 4℃-飯糰 | C27: 麻油雞飯糰 | E27: 29.97 | F27: 2262 | G27: =E27*F27 -> 67792.14 | I27: 21 | J27: 2790 | K27: =J27/I27 -> 132.85714 | L27: 22 | M27: =F27/V27*60 -> 2626.6346 | N27: =M27/L27 -> 119.39248 | O27: =L27-I27 -> 1 | P27: =N27-K27 -> -13.46466 | Q27: =N27/K27 -> 0.89865309 | S27: 0.50694444 | T27: 0.54282407 | U27: 56.633333 | V27: 51.670681 | AE27: =M27-J27 -> -163.36538 | AF27: =M27/J27 -> 0.9414461
B38: 平均 | I38: =AVERAGE(I22:I37) -> 20.166667 | J38: =AVERAGE(J22:J37) -> 2115 | K38: =J38/I38 -> 104.87603 | L38: =AVERAGE(L22:L37) -> 20.333333 | M38: =AVERAGE(M22:M37) -> 1927.2523 | N38: =M38/L38 -> 94.782902 | O38: =L38-I38 -> 0.16666667 | P38: =N38-K38 -> -10.093131 | Q38: =N38/K38 -> 0.90376132 | S38: 0.16666667 | T38: 0.54282407 | Y38: =SUM(Y22:Y37) -> 0 | Z38: =SUM(Z22:Z37) -> 0 | AC38: =SUM(AC22:AC37) -> 0 | AD38: =SUM(AD22:AD37) -> 0 | AE38: =M38-J38 -> -187.74766 | AF38: =M38/J38 -> 0.91123042
A39: 涼麵二線 | B39: 便當 | C39: 蔬活腿排補力餐盒 | E39: 71.55 | F39: 2779 | G39: =E39*F39 -> 198837.45 | I39: 22 | J39: 2000 | K39: =J39/I39 -> 90.909091 | L39: 22 | M39: =F39/V39*60 -> 1804.2186 | N39: =M39/L39 -> 82.009936 | O39: =L39-I39 -> 0 | P39: =N39-K39 -> -8.8991549 | Q39: =N39/K39 -> 0.9021093 | R39: =Q55 -> 0.90282398 | S39: 0.16666667 | T39: 0.23084491 | V39: 92.41674 | AE39: =M39-J39 -> -195.78141 | AF39: =M39/J39 -> 0.9021093 | AG39: =AF55 -> 0.90282398
B40: 便當 | C40: 海陸雙拼肉肉餐盒 | E40: 59.54 | F40: 2955 | G40: =E40*F40 -> 175940.7 | I40: 23 | J40: 2000 | K40: =J40/I40 -> 86.956522 | L40: 23 | M40: =F40/V40*60 -> 1807.6145 | N40: =M40/L40 -> 78.591933 | O40: =L40-I40 -> 0 | P40: =N40-K40 -> -8.3645889 | Q40: =N40/K40 -> 0.90380723 | S40: 0.23472222 | T40: 0.30283565 | U40: 5.5833333 | V40: 98.085075 | AE40: =M40-J40 -> -192.38555 | AF40: =M40/J40 -> 0.90380723
B41: 便當 | C41: 地中海布格麥烤魚餐盒 | E41: 63.92 | F41: 1819 | G41: =E41*F41 -> 116270.48 | I41: 24 | J41: 2000 | K41: =J41/I41 -> 83.333333 | L41: 24 | M41: =F41/V41*60 -> 1809.1666 | N41: =M41/L41 -> 75.381941 | O41: =L41-I41 -> 0 | P41: =N41-K41 -> -7.9513927 | Q41: =N41/K41 -> 0.90458329 | S41: 0.30625 | T41: 0.34813657 | U41: 4.9166667 | V41: 60.32612 | AE41: =M41-J41 -> -190.83343 | AF41: =M41/J41 -> 0.90458329
B42: 便當 | C42: 香烤鱈魚輕蔬餐盒 | E42: 69.26 | F42: 1793 | G42: =E42*F42 -> 124183.18 | I42: 24 | J42: 2000 | K42: =J42/I42 -> 83.333333 | L42: 24 | M42: =F42/V42*60 -> 1801.3884 | N42: =M42/L42 -> 75.057848 | O42: =L42-I42 -> 0 | P42: =N42-K42 -> -8.2754852 | Q42: =N42/K42 -> 0.90069418 | S42: 0.35208333 | T42: 0.39355324 | U42: 5.6833333 | V42: 59.720604 | AE42: =M42-J42 -> -198.61165 | AF42: =M42/J42 -> 0.90069418
B43: 便當 | C43: 益活雞胸補力餐盒 | E43: 69.16 | F43: 2481 | G43: =E43*F43 -> 171585.96 | I43: 24 | J43: 2000 | K43: =J43/I43 -> 83.333333 | L43: 24 | M43: =F43/V43*60 -> 1806.3504 | N43: =M43/L43 -> 75.2646 | O43: =L43-I43 -> 0 | P43: =N43-K43 -> -8.0687334 | Q43: =N43/K43 -> 0.9031752 | S43: 0.39652778 | T43: 0.45375 | U43: 5 | V43: 82.40926 | W43: 0.45375 | X43: 0.49236111 | AE43: =M43-J43 -> -193.6496 | AF43: =M43/J43 -> 0.9031752
B44: 便當 | C44: 烤蛋白餐盒 | E44: 58.67 | F44: 3775 | G44: =E44*F44 -> 221479.25 | I44: 23 | J44: 2000 | K44: =J44/I44 -> 86.956522 | L44: 23 | M44: =F44/V44*60 -> 1805.1494 | N44: =M44/L44 -> 78.484756 | O44: =L44-I44 -> 0 | P44: =N44-K44 -> -8.471766 | Q44: =N44/K44 -> 0.90257469 | S44: 0.49236111 | T44: 0.57949074 | U44: 55.6 | V44: 125.47438 | AE44: =M44-J44 -> -194.85062 | AF44: =M44/J44 -> 0.90257469
B55: 平均 | I55: =AVERAGE(I39:I54) -> 23.333333 | J55: =AVERAGE(J39:J54) -> 2000 | K55: =J55/I55 -> 85.714286 | L55: =AVERAGE(L39:L54) -> 23.333333 | M55: =AVERAGE(M39:M54) -> 1805.648 | N55: =M55/L55 -> 77.384913 | O55: =L55-I55 -> 0 | P55: =N55-K55 -> -8.3293732 | Q55: =N55/K55 -> 0.90282398 | S55: 0.16666667 | T55: 0.57949074 | Y55: =SUM(Y39:Y54) -> 0 | Z55: =SUM(Z39:Z54) -> 0 | AC55: =SUM(AC39:AC54) -> 0 | AD55: =SUM(AD39:AD54) -> 0 | AE55: =M55-J55 -> -194.35204 | AF55: =M55/J55 -> 0.90282398
A56: 涼麵三線 | B56: 季節調理麵 | C56: 和風涓絲冷麵 | E56: 28.86 | F56: 1974 | G56: =E56*F56 -> 56969.64 | I56: 18 | J56: 3600 | K56: =J56/I56 -> 200 | L56: 18 | M56: =F56/V56*60 -> 3193.9229 | N56: =M56/L56 -> 177.44016 | O56: =L56-I56 -> 0 | P56: =N56-K56 -> -22.559838 | Q56: =N56/K56 -> 0.88720081 | R56: =Q72 -> 0.89985846 | S56: 0.20833333 | T56: 0.23407407 | V56: 37.082924 | AE56: =M56-J56 -> -406.07709 | AF56: =M56/J56 -> 0.88720081 | AG56: =AF72 -> 0.89985846
B57: 季節調理麵 | C57: 嘉義崇文白醋涼麵 | E57: 35.89 | F57: 2058 | G57: =E57*F57 -> 73861.62 | I57: 18 | J57: 3600 | K57: =J57/I57 -> 200 | L57: 18 | M57: =F57/V57*60 -> 3191.8691 | N57: =M57/L57 -> 177.32606 | O57: =L57-I57 -> 0 | P57: =N57-K57 -> -22.673941 | Q57: =N57/K57 -> 0.8866303 | S57: 0.2375 | T57: 0.26436343 | U57: 4.9333333 | V57: 38.685797 | AE57: =M57-J57 -> -408.13094 | AF57: =M57/J57 -> 0.8866303
B58: 季節調理麵 | C58: 韓式泡菜冷麵 | E58: 36.73 | F58: 1660 | G58: =E58*F58 -> 60971.8 | I58: 21 | J58: 3600 | K58: =J58/I58 -> 171.42857 | L58: 21 | M58: =F58/V58*60 -> 3194.3857 | N58: =M58/L58 -> 152.11361 | O58: =L58-I58 -> 0 | P58: =N58-K58 -> -19.314966 | Q58: =N58/K58 -> 0.88732936 | S58: 0.26805556 | T58: 0.28969907 | U58: 5.3166667 | V58: 31.179704 | AE58: =M58-J58 -> -405.61429 | AF58: =M58/J58 -> 0.88732936
B59: 季節調理麵 | C59: 招牌雞絲胡麻涼麵 | E59: 43.96 | F59: 2391 | G59: =E59*F59 -> 105108.36 | I59: 23 | J59: 3600 | K59: =J59/I59 -> 156.52174 | L59: 23 | M59: =F59/V59*60 -> 3270.597 | N59: =M59/L59 -> 142.19987 | O59: =L59-I59 -> 0 | P59: =N59-K59 -> -14.321869 | Q59: =N59/K59 -> 0.90849917 | S59: 0.29375 | T59: 0.32420139 | U59: 5.8333333 | V59: 43.863551 | AE59: =M59-J59 -> -329.403 | AF59: =M59/J59 -> 0.90849917
B60: 季節調理麵 | C60: 日式胡麻雞絲冷麵 | E60: 46.93 | F60: 1812 | G60: =E60*F60 -> 85037.16 | I60: 23 | J60: 3600 | K60: =J60/I60 -> 156.52174 | L60: 23 | M60: =F60/V60*60 -> 3262.2108 | N60: =M60/L60 -> 141.83525 | O60: =L60-I60 -> 0 | P60: =N60-K60 -> -14.686487 | Q60: =N60/K60 -> 0.90616967 | S60: 0.32708333 | T60: 0.35021991 | U60: 5 | V60: 33.327092 | AE60: =M60-J60 -> -337.78919 | AF60: =M60/J60 -> 0.90616967
B61: 季節調理麵 | C61: 日式蕎麥沾麵 | E61: 36.73 | F61: 3168 | G61: =E61*F61 -> 116360.64 | I61: 19 | J61: 3600 | K61: =J61/I61 -> 189.47368 | L61: 19 | M61: =F61/V61*60 -> 3264.9782 | N61: =M61/L61 -> 171.84096 | O61: =L61-I61 -> 0 | P61: =N61-K61 -> -17.632727 | Q61: =N61/K61 -> 0.90693839 | S61: 0.35416667 | T61: 0.39459491 | U61: 5.6833333 | V61: 58.217847 | AE61: =M61-J61 -> -335.02181 | AF61: =M61/J61 -> 0.90693839
B62: 季節調理麵 | C62: 大滿足香辣涼麵 | E62: 38.48 | F62: 4513 | G62: =E62*F62 -> 173660.24 | I62: 19 | J62: 3600 | K62: =J62/I62 -> 189.47368 | L62: 19 | M62: =F62/V62*60 -> 3266.64 | N62: =M62/L62 -> 171.92842 | O62: =L62-I62 -> 0 | P62: =N62-K62 -> -17.545263 | Q62: =N62/K62 -> 0.9074 | S62: 0.39861111 | T62: 0.45616898 | U62: 5.7833333 | V62: 82.892513 | W62: 0.45616898 | X62: 0.49513889 | AE62: =M62-J62 -> -333.36 | AF62: =M62/J62 -> 0.9074
B63: 季節調理麵 | C63: 大滿足麻醬涼麵 | E63: 37.8 | F63: 5469 | G63: =E63*F63 -> 206728.2 | I63: 20 | J63: 3600 | K63: =J63/I63 -> 180 | L63: 20 | M63: =F63/V63*60 -> 3271.32 | N63: =M63/L63 -> 163.566 | O63: =L63-I63 -> 0 | P63: =N63-K63 -> -16.434 | Q63: =N63/K63 -> 0.9087 | S63: 0.49513889 | T63: 0.56479167 | U63: 56.116667 | V63: 100.30813 | AE63: =M63-J63 -> -328.68 | AF63: =M63/J63 -> 0.9087
B72: 平均 | I72: =AVERAGE(I56:I71) -> 20.125 | J72: =AVERAGE(J56:J71) -> 3600 | K72: =J72/I72 -> 178.88199 | L72: =AVERAGE(L56:L71) -> 20.125 | M72: =AVERAGE(M56:M71) -> 3239.4905 | N72: =M72/L72 -> 160.96847 | O72: =L72-I72 -> 0 | P72: =N72-K72 -> -17.913518 | Q72: =N72/K72 -> 0.89985846 | S72: 0.20833333 | T72: 0.56479167 | Y72: =SUM(Y56:Y71) -> 0 | Z72: =SUM(Z56:Z71) -> 0 | AC72: =SUM(AC56:AC71) -> 0 | AD72: =SUM(AD56:AD71) -> 0 | AE72: =M72-J72 -> -360.50954 | AF72: =M72/J72 -> 0.89985846
A73: 自動包裝機 | B73: 4℃-壽司手卷 | C73: 醬油生鮭脆卷 | E73: 23.55 | F73: 913 | G73: =E73*F73 -> 21501.15 | I73: 6 | J73: 2500 | K73: =J73/I73 -> 416.66667 | L73: 6 | M73: =F73/V73*60 -> 2259.7202 | N73: =M73/L73 -> 376.62003 | O73: =L73-I73 -> 0 | P73: =N73-K73 -> -40.046639 | Q73: =N73/K73 -> 0.90388807 | R73: =Q89 -> 0.90488781 | S73: 0.28055556 | T73: 0.29738426 | U73: 5 | V73: 24.24194 | AE73: =M73-J73 -> -240.27984 | AF73: =M73/J73 -> 0.90388807 | AG73: =AF89 -> 0.90488781
B74: 4℃-壽司手卷 | C74: 蔥花生鮪魚脆卷 | E74: 23.19 | F74: 2965 | G74: =E74*F74 -> 68758.35 | I74: 6 | J74: 2500 | K74: =J74/I74 -> 416.66667 | L74: 6 | M74: =F74/V74*60 -> 2259.3715 | N74: =M74/L74 -> 376.56191 | O74: =L74-I74 -> 0 | P74: =N74-K74 -> -40.104754 | Q74: =N74/K74 -> 0.90374859 | S74: 0.30069444 | T74: 0.35537037 | U74: 4.7666667 | V74: 78.738712 | AE74: =M74-J74 -> -240.62852 | AF74: =M74/J74 -> 0.90374859
B75: 4℃-壽司手卷 | C75: 香濃明太子嫩雞飯卷 | E75: 35.89 | F75: 4294 | G75: =E75*F75 -> 154111.66 | I75: 6 | J75: 3273 | K75: =J75/I75 -> 545.5 | L75: 6 | M75: =F75/V75*60 -> 2963.5068 | N75: =M75/L75 -> 493.9178 | O75: =L75-I75 -> 0 | P75: =N75-K75 -> -51.582201 | Q75: =N75/K75 -> 0.90544051 | S75: 0.35902778 | T75: 0.41939815 | U75: 5.2666667 | V75: 86.937543 | AE75: =M75-J75 -> -309.4932 | AF75: =M75/J75 -> 0.90544051
B76: 4℃-壽司手卷 | C76: 厚香料優格咖哩烤雞飯卷 | E76: 27.05 | F76: 857 | G76: =E76*F76 -> 23181.85 | I76: 5 | J76: 3273 | K76: =J76/I76 -> 654.6 | L76: 5 | M76: =F76/V76*60 -> 2965.2362 | N76: =M76/L76 -> 593.04724 | O76: =L76-I76 -> 0 | P76: =N76-K76 -> -61.552757 | Q76: =N76/K76 -> 0.9059689 | S76: 0.42222222 | T76: 0.43425926 | U76: 5 | V76: 17.340946 | AE76: =M76-J76 -> -307.76379 | AF76: =M76/J76 -> 0.9059689
B89: 平均 | I89: =AVERAGE(I73:I88) -> 5.75 | J89: =AVERAGE(J73:J88) -> 2886.5 | K89: =J89/I89 -> 502 | L89: =AVERAGE(L73:L88) -> 5.75 | M89: =AVERAGE(M73:M88) -> 2611.9587 | N89: =M89/L89 -> 454.25368 | O89: =L89-I89 -> 0 | P89: =N89-K89 -> -47.74632 | Q89: =N89/K89 -> 0.90488781 | S89: 0.16666667 | T89: 0.43425926 | Y89: =SUM(Y73:Y88) -> 0 | Z89: =SUM(Z73:Z88) -> 0 | AC89: =SUM(AC73:AC88) -> 0 | AD89: =SUM(AD73:AD88) -> 0 | AE89: =M89-J89 -> -274.54134 | AF89: =M89/J89 -> 0.90488781
A90: 自動包裝機2 | B90: 4℃-壽司手卷 | C90: 鮪魚昆布細卷 | E90: 15.51 | F90: 2300 | G90: =E90*F90 -> 35673 | I90: 6 | J90: 4200 | K90: =J90/I90 -> 700 | L90: 6 | M90: =F90/V90*60 -> 3792.6434 | N90: =M90/L90 -> 632.10723 | O90: =L90-I90 -> 0 | P90: =N90-K90 -> -67.892771 | Q90: =N90/K90 -> 0.90301033 | R90: =Q106 -> 0.90318394 | S90: 0.25 | T90: 0.2752662 | V90: 36.386232 | AE90: =M90-J90 -> -407.35663 | AF90: =M90/J90 -> 0.90301033 | AG90: =AF106 -> 0.90318394
B91: 4℃-壽司手卷 | C91: 肉鬆火腿細卷 | E91: 15.01 | F91: 2374 | G91: =E91*F91 -> 35633.74 | I91: 6 | J91: 4200 | K91: =J91/I91 -> 700 | L91: 6 | M91: =F91/V91*60 -> 3794.1017 | N91: =M91/L91 -> 632.35028 | O91: =L91-I91 -> 0 | P91: =N91-K91 -> -67.649716 | Q91: =N91/K91 -> 0.90335755 | S91: 0.27847222 | T91: 0.30453704 | U91: 4.6166667 | V91: 37.542483 | AE91: =M91-J91 -> -405.89829 | AF91: =M91/J91 -> 0.90335755
B106: 平均 | I106: =AVERAGE(I90:I105) -> 6 | J106: =AVERAGE(J90:J105) -> 4200 | K106: =J106/I106 -> 700 | L106: =AVERAGE(L90:L105) -> 6 | M106: =AVERAGE(M90:M105) -> 3793.3725 | N106: =M106/L106 -> 632.22876 | O106: =L106-I106 -> 0 | P106: =N106-K106 -> -67.771243 | Q106: =N106/K106 -> 0.90318394 | S106: 0.25 | T106: 0.30453704 | Y106: =SUM(Y90:Y105) -> 0 | Z106: =SUM(Z90:Z105) -> 0 | AC106: =SUM(AC90:AC105) -> 0 | AD106: =SUM(AD90:AD105) -> 0 | AE106: =M106-J106 -> -406.62746 | AF106: =M106/J106 -> 0.90318394
A107: 便當二線 (二配) | B107: 微波主食 | C107: 二配香烤魚排青醬燉飯 | E107: 58.17 | F107: 1618 | G107: =E107*F107 -> 94119.06 | I107: 18 | J107: 2000 | K107: =J107/I107 -> 111.11111 | L107: 17 | M107: =F107/V107*60 -> 1806.6 | N107: =M107/L107 -> 106.27059 | O107: =L107-I107 -> -1 | P107: =N107-K107 -> -4.8405229 | Q107: =N107/K107 -> 0.95643529 | R107: =Q123 -> 0.95123452 | S107: 0.70833333 | T107: 0.74564815 | V107: 53.7363 | AE107: =M107-J107 -> -193.4 | AF107: =M107/J107 -> 0.9033 | AG107: =AF123 -> 0.90286667
...

Sheet 0830
B1: 屏榮 大溪廠組合室生產人時性分析
B3: 日期 | C3: 115.08.30星期日 | E3: 訂單量 | F3: ='0830(18度C)'!D1+'0830(4度C)'!D1 -> 174500 | H3: 營業額 | I3: ='0830(18度C)'!F1+'0830(4度C)'!F1 -> 5874431.7
B4: 人時性 | C4: 項目 | E4: ➀ | G4: ➁ | I4: ➂ | K4: ④ | M4: ⑤ | O4: 異常停線 | Q4: 短暫停線
C5: 組合室 | E5: 全溫層 | G5: 4度C-各編組展開(一配) | I5: 4度C-各編組展開(二配) | K5: 18度C-各編組展開(一配) | M5: 18度C-各編組展開(二配) | O5: 合計次數 | P5: 時間 | Q5: 合計次數 | R5: 設備次數
C6: 排關平均 | E6: =AVERAGE(D14:O14,D32:X32) -> 501.40794 | F6: =AVERAGE(#REF!,D14:K14) -> #REF! | G6: =AVERAGE(D14:K14) -> 276.1197 | I6: =AVERAGE(L14:O14) -> 94.325718 | K6: =AVERAGE(D32:O32) -> 754.19394 | M6: =AVERAGE(P32:X32) -> 790.09539 | O6: ='0830(4度C)'!Y2 -> 0 | P6: ='0830(4度C)'!Z2 -> 0 | Q6: ='0830(4度C)'!AC2 -> 0 | R6: ='0830(4度C)'!AD2 -> 0
C7: 實績平均 | E7: =AVERAGE(D15:O15,D33:X33) -> 454.23385 | F7: =AVERAGE(#REF!,D15:K15) -> #REF! | G7: =AVERAGE(D15:K15) -> 249.40168 | I7: =AVERAGE(L15:O15) -> 87.579175 | K7: =AVERAGE(D33:O33) -> 683.68617 | M7: =AVERAGE(P33:X33) -> 715.35711
C8: 達成率平均 | E8: =AVERAGE(D16:O16,D34:X34) -> 0.90580505 | F8: =AVERAGE(D16:K16,#REF!) -> #REF! | G8: =AVERAGE(D16:K16) -> 0.90290331 | I8: =AVERAGE(L16:O16) -> 0.92656825 | K8: =AVERAGE(D34:O34) -> 0.90222747 | M8: =AVERAGE(P34:X34) -> 0.90335364
O9: ※現行日本鮮食廠以達成率80%為基本(即為現行KPI)
B11: 溫層 | D11: ➁4度C-各編組展開 | L11: ➂4度C-各編組展開
B12: 編組 | D12: 1 | E12: 2 | F12: 3 | G12: 4 | H12: 5 | I12: 6 | J12: 7 | K12: 8 | L12: 1 | M12: 2 | N12: 3 | O12: 4
D13: 便當一線 | E13: 便當二線 | F13: 涼麵一線 | G13: 涼麵二線 | H13: 涼麵三線 | I13: 自動包裝機 | J13: 自動包裝機2 | K13: 自動包裝機3 | L13: 便當一線 | M13: 便當二線 | N13: 涼麵一線 | O13: 涼麵二線
B14: 人時性 | C14: 排關 | D14: - | E14: 85.245902 | F14: 104.87603 | G14: 85.714286 | H14: 178.88199 | I14: 502 | J14: 700 | K14: - | L14: - | M14: 101.69492 | N14: 86.956522 | O14: -
C15: 實績 | D15: - | E15: 76.970369 | F15: 94.783967 | G15: 77.39777 | H15: 160.99307 | I15: 454.24617 | J15: 632.01876 | K15: - | L15: - | M15: 96.710714 | N15: 78.447635 | O15: -
C16: 達成率 | D16: - | E16: =E15/E14 -> 0.90292163 | F16: =F15/F14 -> 0.90377148 | G16: =G15/G14 -> 0.90297398 | H16: =H15/H14 -> 0.89999596 | I16: =I15/I14 -> 0.90487285 | J16: =J15/J14 -> 0.90288394 | K16: - | L16: - | M16: =M15/M14 -> 0.95098869 | N16: =N15/N14 -> 0.9021478 | O16: -
B17: 作業 時間 | C17: 開始 | D17: - | E17: 0.20833333 | F17: 0.16666667 | G17: 0.16666667 | H17: 0.20833333 | I17: 0.16666667 | J17: 0.25 | K17: - | L17: - | M17: 0.70833333 | N17: 0.70833333 | O17: -
C18: 結束 | D18: - | E18: 0.63134259 | F18: 0.54387731 | G18: 0.57971065 | H18: 0.58755787 | I18: 0.48195602 | J18: 0.30328704 | K18: - | L18: - | M18: 0.8337963 | N18: 0.85800926 | O18: -
B19: 產線異常 (5分鐘以上) | C19: 次數
C20: 時間/分
B21: 短暫停線 (5分鐘以下) | C21: 次數
C22: 設備次數
B23: 配置人數 | D23: - | E23: 20.333333 | F23: 20.333333 | G23: 23.333333 | H23: 20.125 | I23: 5.75 | J23: 6 | K23: - | L23: - | M23: 18.666667 | N23: 23 | O23: -
B24: 主要應用設備 | D24: L型封口機 | E24: ET-55 | F24: ET-55 | G24: ET-55 | H24: ET-600 | I24: 伺服包裝機 | J24: 伺服包裝機 | K24: 伺服包裝機 | L24: L型封口機 | M24: ET-55 | N24: ET-55 | O24: ET-55
B25: 次要應用設備 | D25: 伺服包裝機 | H25: 伺服包裝機
B26: 備註 | H26: 涼麵+烤飯糰 | I26: 大口飯糰線 | K26: 烤飯糰+手卷
B29: 溫層 | D29: ➃18度C-各編組展開 (一配) | P29: ⑤18度C-各編組展開 (二配)
B30: 編組 | D30: 1 | E30: 2 | F30: 3 | G30: 4 | H30: 5 | I30: 6 | J30: 7 | K30: 8 | L30: 9 | M30: 10 | N30: 11 | O30: 12 | P30: 1 | Q30: 2 | R30: 3 | S30: 4 | T30: 5 | U30: 6 | V30: 7 | W30: 8 | X30: 9
D31: 便當一線 | E31: 涼麵一線 | F31: 涼麵三線 | G31: 自動包裝機 | H31: 自動包裝機2 | I31: 自動包裝機3 | J31: 味付飯糰線B | K31: (舊) 3300型飯糰線 | L31: 3000型飯糰線 | M31: (新) 3300型飯糰機 | N31: GKK3600型 飯糰機 | O31: GKK3600型 飯糰機2 | P31: 自動包裝機 | Q31: 自動包裝機2 | R31: 自動包裝機3 | S31: 味付飯糰線B | T31: (舊) 3300型飯糰線 | U31: 3000型飯糰線 | V31: (新) 3300型飯糰機 | W31: GKK3600型 飯糰機 | X31: GKK3600型 飯糰機2
B32: 人時性 | C32: 排關 | D32: - | E32: - | F32: - | G32: 327.27273 | H32: - | I32: - | J32: - | K32: - | L32: - | M32: 825 | N32: 1005.8824 | O32: 858.62069 | P32: 423.52941 | Q32: - | R32: - | S32: - | T32: - | U32: - | V32: 741.17647 | W32: 1120 | X32: 875.67568
C33: 實績 | D33: - | E33: - | F33: - | G33: 287.46232 | H33: - | I33: - | J33: - | K33: - | L33: - | M33: 759.12561 | N33: 913.31261 | O33: 774.84414 | P33: 375.24578 | Q33: - | R33: - | S33: - | T33: - | U33: - | V33: 682.10685 | W33: 1015.965 | X33: 788.11082
C34: 達成率 | D34: - | E34: - | F34: - | G34: =G33/G32 -> 0.8783571 | H34: - | I34: - | J34: - | K34: - | L34: - | M34: =M33/M32 -> 0.92015225 | N34: =N33/N32 -> 0.90797161 | O34: =O33/O32 -> 0.90242891 | P34: =P33/P32 -> 0.88599697 | Q34: - | R34: - | S34: - | T34: - | U34: - | V34: =V33/V32 -> 0.92030289 | W34: =W33/W32 -> 0.90711162 | X34: =X33/X32 -> 0.90000309
B35: 作業 時間 | C35: 開始 | D35: - | E35: - | F35: - | G35: 0.16666667 | H35: - | I35: - | J35: - | K35: - | L35: - | M35: 0.32152778 | N35: 0.25 | O35: 0.25 | P35: 0.70833333 | Q35: - | R35: - | S35: - | T35: - | U35: - | V35: 0.70833333 | W35: 0.72777778 | X35: 0.70833333
C36: 結束 | D36: - | E36: - | F36: - | G36: 0.48195602 | H36: - | I36: - | J36: - | K36: - | L36: - | M36: 0.42641204 | N36: 0.44913194 | O36: 0.4515625 | P36: 0.72920139 | Q36: - | R36: - | S36: - | T36: - | U36: - | V36: 0.83378472 | W36: 0.99479167 | X36: 0.97386574
B37: 配置人數 | D37: - | E37: - | F37: - | G37: 11 | H37: - | I37: - | J37: - | K37: - | L37: - | M37: 4 | N37: 3.4 | O37: 4.1428571 | P37: 8.5 | Q37: - | R37: - | S37: - | T37: - | U37: - | V37: 4.25 | W37: 3 | X37: 4.1111111
B38: 主要應用設備 | D38: 伺服包裝機 | E38: ET-55 | F38: ET-600 | G38: 夾心型 | H38: 伺服包裝機 | I38: 伺服包裝機 | J38: 夾心型 | K38: 3300型 | L38: 3300型 | M38: 3300型 | N38: GKK | O38: GKK | P38: 夾心型 | Q38: 伺服包裝機 | R38: 伺服包裝機 | S38: 夾心型 | T38: 3300型 | U38: 3300型 | V38: 3300型 | W38: GKK | X38: GKK
B39: 次要應用設備
B40: 備註

Sheet 0830(18度C)
A1: 大溪廠日報分析 | C1: 總生產量 | D1: =SUM(F5:F140) -> 77625 | E1: 營業額 | F1: =SUM(G5:G140) -> 1516981.4 | G1: 出勤人數 | H1: =L21+L38+L55+L72+L89+L106+L123+L140 -> 42.403968 | I1: 產線配置圖 | L1: 生產實績 | O1: 人時性差異分析 | S1: 日報登錄 | Y1: 分析說明 | AA1: 產能差異分析
A2: 46264 | C2: 人時性 | D2: =AVERAGE(N21,N38,N55,N72,N89,N106,N123,N140) -> 699.52164 | E2: 平均廠價 | F2: =F1/D1 -> 19.542433 | G2: 多次生產數 | H2: =COUNT(H5:H140) -> 4
A3: 線別 | B3: 品類 | C3: 品名 | E3: 廠價 | F3: 生產量 | G3: 營收 | H3: 多次 生產 | I3: 人數 | J3: 產能/時 | K3: 人時性 | L3: 人數 | M3: 產能/時 | N3: 人時性 | O3: 人數 | P3: 人時性 | Q3: 達成率 | R3: 達成率 平均 | S3: 生產時間 | U3: 換線、休息/分 | V3: 稼動時間/分 | W3: 休息時間 | Y3: (屏榮回填) | AA3: 產能/時 | AB3: 達成率 | AC3: 達成率平均
S4: 開始 | T4: 結束 | W4: 開始 | X4: 結束
A5: 自動包裝機 | B5: 18℃-壽司手卷 | C5: 一配長野稻荷壽司 | E5: 25.64 | F5: 1312 | G5: =E5*F5 -> 33639.68 | I5: 10 | J5: 3600 | K5: =J5/I5 -> 360 | L5: 10 | M5: =F5/V5*60 -> 3217.2496 | N5: =M5/L5 -> 321.72496 | O5: =L5-I5 -> 0 | P5: =N5-K5 -> -38.275045 | Q5: =N5/K5 -> 0.89368043 | R5: =Q21 -> 0.8783571 | S5: 0.16666667 | T5: 0.18365741 | V5: 24.468105 | AA5: =M5-J5 -> -382.75045 | AB5: =M5/J5 -> 0.89368043 | AC5: =AB21 -> 0.8783571
B6: 18℃-壽司手卷 | C6: 一配經典人氣雙手卷 | E6: 29.52 | F6: 2156 | G6: =E6*F6 -> 63645.12 | I6: 11 | J6: 3600 | K6: =J6/I6 -> 327.27273 | L6: 11 | M6: =F6/V6*60 -> 3156.8509 | N6: =M6/L6 -> 286.98645 | O6: =L6-I6 -> 0 | P6: =N6-K6 -> -40.286278 | Q6: =N6/K6 -> 0.87690304 | S6: 0.1875 | T6: 0.21594907 | U6: 5.5333333 | V6: 40.977545 | AA6: =M6-J6 -> -443.14906 | AB6: =M6/J6 -> 0.87690304
B7: 18℃-壽司手卷 | C7: 一配鮭鮪海饌雙手卷 | E7: 29.85 | F7: 2584 | G7: =E7*F7 -> 77132.4 | I7: 11 | J7: 3600 | K7: =J7/I7 -> 327.27273 | L7: 11 | M7: =F7/V7*60 -> 3156.6108 | N7: =M7/L7 -> 286.96462 | O7: =L7-I7 -> 0 | P7: =N7-K7 -> -40.30811 | Q7: =N7/K7 -> 0.87683633 | S7: 0.21875 | T7: 0.25284722 | U7: 5 | V7: 49.11597 | AA7: =M7-J7 -> -443.38921 | AB7: =M7/J7 -> 0.87683633
B8: 18℃-壽司手卷 | C8: 一配青木瓜雞絲泰泰雙手卷 | E8: 30 | F8: 588 | G8: =E8*F8 -> 17640 | I8: 11 | J8: 3600 | K8: =J8/I8 -> 327.27273 | L8: 11 | M8: =F8/V8*60 -> 3158.5562 | N8: =M8/L8 -> 287.14147 | O8: =L8-I8 -> 0 | P8: =N8-K8 -> -40.131258 | Q8: =N8/K8 -> 0.87737671 | S8: 0.25694444 | T8: 0.26469907 | U8: 5.9 | V8: 11.16966 | AA8: =M8-J8 -> -441.44384 | AB8: =M8/J8 -> 0.87737671
B9: 18℃-飯糰 | C9: 一配兩粒飯糰(鮪魚.焦糖鮭魚) | E9: 28.57 | F9: 932 | G9: =E9*F9 -> 26627.24 | I9: 12 | J9: 3600 | K9: =J9/I9 -> 300 | L9: 12 | M9: =F9/V9*60 -> 3121.1603 | N9: =M9/L9 -> 260.09669 | O9: =L9-I9 -> 0 | P9: =N9-K9 -> -39.90331 | Q9: =N9/K9 -> 0.86698897 | S9: 0.26805556 | T9: 0.28048611 | U9: 4.8333333 | V9: 17.916414 | AA9: =M9-J9 -> -478.83972 | AB9: =M9/J9 -> 0.86698897
B21: 平均 | I21: =AVERAGE(I5:I20) -> 11 | J21: =AVERAGE(J5:J20) -> 3600 | K21: =J21/I21 -> 327.27273 | L21: =AVERAGE(L5:L20) -> 11 | M21: =AVERAGE(M5:M20) -> 3162.0855 | N21: =M21/L21 -> 287.46232 | O21: =L21-I21 -> 0 | P21: =N21-K21 -> -39.810405 | Q21: =N21/K21 -> 0.8783571 | S21: 0.16666667 | T21: 0.48195602 | AA21: =M21-J21 -> -437.91445 | AB21: =M21/J21 -> 0.8783571
A22: (新) 3300型飯糰機 | B22: 18℃-飯糰 | C22: 一配鮭魚奶油醬油飯糰 | E22: 18.53 | F22: 1742 | G22: =E22*F22 -> 32279.26 | I22: 3 | J22: 3300 | K22: =J22/I22 -> 1100 | L22: 3 | M22: =F22/V22*60 -> 3036.0152 | N22: =M22/L22 -> 1012.0051 | O22: =L22-I22 -> 0 | P22: =N22-K22 -> -87.994931 | Q22: =N22/K22 -> 0.92000461 | R22: =Q38 -> 0.92015225 | S22: 0.32152778 | T22: 0.34542824 | V22: 34.426705 | AA22: =M22-J22 -> -263.98479 | AB22: =M22/J22 -> 0.92000461 | AC22: =AB38 -> 0.92015225
B23: 18℃-飯糰 | C23: 一配鹽蔥燒肉飯糰 | E23: 17.89 | F23: 2156 | G23: =E23*F23 -> 38570.84 | I23: 4 | J23: 3300 | K23: =J23/I23 -> 825 | L23: 4 | M23: =F23/V23*60 -> 3036.2848 | N23: =M23/L23 -> 759.07121 | O23: =L23-I23 -> 0 | P23: =N23-K23 -> -65.928795 | Q23: =N23/K23 -> 0.92008631 | S23: 0.34930556 | T23: 0.37888889 | U23: 5.5833333 | V23: 42.604699 | AA23: =M23-J23 -> -263.71518 | AB23: =M23/J23 -> 0.92008631
B24: 18℃-飯糰 | C24: 一配醬燒炙烤牛飯糰 | E24: 22.32 | F24: 3191 | G24: =E24*F24 -> 71223.12 | I24: 5 | J24: 3300 | K24: =J24/I24 -> 660 | L24: 5 | M24: =F24/V24*60 -> 3037.2073 | N24: =M24/L24 -> 607.44145 | O24: =L24-I24 -> 0 | P24: =N24-K24 -> -52.558545 | Q24: =N24/K24 -> 0.92036584 | S24: 0.38263889 | T24: 0.42641204 | U24: 5.4 | V24: 63.038174 | AA24: =M24-J24 -> -262.79273 | AB24: =M24/J24 -> 0.92036584
B38: 平均 | I38: =AVERAGE(I22:I37) -> 4 | J38: =AVERAGE(J22:J37) -> 3300 | K38: =J38/I38 -> 825 | L38: =AVERAGE(L22:L37) -> 4 | M38: =AVERAGE(M22:M37) -> 3036.5024 | N38: =M38/L38 -> 759.12561 | O38: =L38-I38 -> 0 | P38: =N38-K38 -> -65.874392 | Q38: =N38/K38 -> 0.92015225 | S38: 0.32152778 | T38: 0.42641204 | AA38: =M38-J38 -> -263.49757 | AB38: =M38/J38 -> 0.92015225
A39: GKK3600型 飯糰機 | B39: 18℃-飯糰 | C39: 一配北海道秋鮭親子飯糰 | E39: 24.82 | F39: 778 | G39: =E39*F39 -> 19309.96 | I39: 5 | J39: 3600 | K39: =J39/I39 -> 720 | L39: 5 | M39: =F39/V39*60 -> 3244.5456 | N39: =M39/L39 -> 648.90912 | O39: =L39-I39 -> 0 | P39: =N39-K39 -> -71.090879 | Q39: =N39/K39 -> 0.90126267 | R39: =Q55 -> 0.90797161 | S39: 0.25 | T39: 0.25998843 | V39: 14.387223 | AA39: =M39-J39 -> -355.45439 | AB39: =M39/J39 -> 0.90126267 | AC39: =AB55 -> 0.90797161
B40: 18℃-飯糰 | C40: 一配蔬食鮪魚飯糰 | E40: 18.18 | F40: 850 | G40: =E40*F40 -> 15453 | I40: 3 | J40: 3600 | K40: =J40/I40 -> 1200 | L40: 3 | M40: =F40/V40*60 -> 3240.8032 | N40: =M40/L40 -> 1080.2677 | O40: =L40-I40 -> 0 | P40: =N40-K40 -> -119.73225 | Q40: =N40/K40 -> 0.90022312 | S40: 0.27013889 | T40: 0.28106481 | U40: 14.616667 | V40: 15.736839 | AA40: =M40-J40 -> -359.19676 | AB40: =M40/J40 -> 0.90022312
B41: 18℃-飯糰 | C41: 一配黑胡椒洋蔥豬飯糰 | E41: 17.07 | F41: 1390 | G41: =E41*F41 -> 23727.3 | I41: 3 | J41: 3300 | K41: =J41/I41 -> 1100 | L41: 3 | M41: =F41/V41*60 -> 3040.4101 | N41: =M41/L41 -> 1013.47 | O41: =L41-I41 -> 0 | P41: =N41-K41 -> -86.529978 | Q41: =N41/K41 -> 0.92133638 | S41: 0.29097222 | T41: 0.31001157 | U41: 15 | V41: 27.43051 | AA41: =M41-J41 -> -259.58993 | AB41: =M41/J41 -> 0.92133638
B42: 18℃-飯糰 | C42: 一配經典肉鬆飯糰 | E42: 14.03 | F42: 3614 | G42: =E42*F42 -> 50704.42 | I42: 3 | J42: 3000 | K42: =J42/I42 -> 1000 | L42: 3 | M42: =F42/V42*60 -> 2762.0903 | N42: =M42/L42 -> 920.69677 | O42: =L42-I42 -> 0 | P42: =N42-K42 -> -79.303232 | Q42: =N42/K42 -> 0.92069677 | S42: 0.32013889 | T42: 0.37465278 | U42: 14.583333 | V42: 78.505761 | AA42: =M42-J42 -> -237.9097 | AB42: =M42/J42 -> 0.92069677
B43: 18℃-飯糰 | C43: 一配鮪魚飯糰 | E43: 14.28 | F43: 5007 | G43: =E43*F43 -> 71499.96 | I43: 3 | J43: 3600 | K43: =J43/I43 -> 1200 | L43: 3 | M43: =F43/V43*60 -> 3238.4652 | N43: =M43/L43 -> 1079.4884 | O43: =L43-I43 -> 0 | P43: =N43-K43 -> -120.51159 | Q43: =N43/K43 -> 0.89957368 | S43: 0.38472222 | T43: 0.44913194 | U43: 14.5 | V43: 92.766165 | AA43: =M43-J43 -> -361.53476 | AB43: =M43/J43 -> 0.89957368
B55: 平均 | I55: =AVERAGE(I39:I54) -> 3.4 | J55: =AVERAGE(J39:J54) -> 3420 | K55: =J55/I55 -> 1005.8824 | L55: =AVERAGE(L39:L54) -> 3.4 | M55: =AVERAGE(M39:M54) -> 3105.2629 | N55: =M55/L55 -> 913.31261 | O55: =L55-I55 -> 0 | P55: =N55-K55 -> -92.569738 | Q55: =N55/K55 -> 0.90797161 | S55: 0.25 | T55: 0.44913194 | AA55: =M55-J55 -> -314.73711 | AB55: =M55/J55 -> 0.90797161
A56: GKK3600型 飯糰機2 | B56: 18℃-飯糰 | C56: 一配熟成紅鮭飯糰 | E56: 25.03 | F56: 620 | G56: =E56*F56 -> 15518.6 | I56: 5 | J56: 3600 | K56: =J56/I56 -> 720 | L56: 5 | M56: =F56/V56*60 -> 3239.567 | N56: =M56/L56 -> 647.9134 | O56: =L56-I56 -> 0 | P56: =N56-K56 -> -72.086601 | Q56: =N56/K56 -> 0.89987972 | R56: =Q72 -> 0.90242891 | S56: 0.25 | T56: 0.25796296 | V56: 11.483016 | AA56: =M56-J56 -> -360.433 | AB56: =M56/J56 -> 0.89987972 | AC56: =AB72 -> 0.90242891
B57: 18℃-飯糰 | C57: 一配椒鹽檸檬鯖魚飯糰 | E57: 20.72 | F57: 948 | G57: =E57*F57 -> 19642.56 | I57: 3 | J57: 3600 | K57: =J57/I57 -> 1200 | L57: 3 | M57: =F57/V57*60 -> 3240.4361 | N57: =M57/L57 -> 1080.1454 | O57: =L57-I57 -> 0 | P57: =N57-K57 -> -119.85462 | Q57: =N57/K57 -> 0.90012115 | S57: 0.26805556 | T57: 0.28024306 | U57: 14.533333 | V57: 17.553193 | AA57: =M57-J57 -> -359.56386 | AB57: =M57/J57 -> 0.90012115
B58: 18℃-飯糰 | C58: 一配明太子龍蝦風味沙拉飯糰 | E58: 18.18 | F58: 1530 | G58: =E58*F58 -> 27815.4 | I58: 3 | J58: 3600 | K58: =J58/I58 -> 1200 | L58: 3 | M58: =F58/V58*60 -> 3241.0356 | N58: =M58/L58 -> 1080.3452 | O58: =L58-I58 -> 0 | P58: =N58-K58 -> -119.65479 | Q58: =N58/K58 -> 0.90028768 | S58: 0.29027778 | T58: 0.30994213 | U58: 15 | V58: 28.32428 | AA58: =M58-J58 -> -358.96437 | AB58: =M58/J58 -> 0.90028768
B59: 18℃-飯糰 | C59: 一配贅沢鮭魚肚飯糰 | E59: 30 | F59: 1238 | G59: =E59*F59 -> 37140 | I59: 4 | J59: 3600 | K59: =J59/I59 -> 900 | L59: 4 | M59: =F59/V59*60 -> 3237.6307 | N59: =M59/L59 -> 809.40767 | O59: =L59-I59 -> 0 | P59: =N59-K59 -> -90.592331 | Q59: =N59/K59 -> 0.89934185 | S59: 0.32013889 | T59: 0.33606481 | U59: 14.683333 | V59: 22.942703 | AA59: =M59-J59 -> -362.36933 | AB59: =M59/J59 -> 0.89934185
B60: 18℃-飯糰 | C60: 一配筋子銀鮭飯糰 | E60: 30 | F60: 977 | G60: =E60*F60 -> 29310 | I60: 4 | J60: 3300 | K60: =J60/I60 -> 825 | L60: 4 | M60: =F60/V60*60 -> 3037.2079 | N60: =M60/L60 -> 759.30198 | O60: =L60-I60 -> 0 | P60: =N60-K60 -> -65.69802 | Q60: =N60/K60 -> 0.92036604 | S60: 0.34583333 | T60: 0.35923611 | U60: 15 | V60: 19.300621 | AA60: =M60-J60 -> -262.79208 | AB60: =M60/J60 -> 0.92036604
B61: 18℃-飯糰 | C61: 一配鹽蔥生鮭飯糰 | E61: 27.48 | F61: 1542 | G61: =E61*F61 -> 42374.16 | I61: 5 | J61: 3600 | K61: =J61/I61 -> 720 | L61: 5 | M61: =F61/V61*60 -> 3235.6859 | N61: =M61/L61 -> 647.13718 | O61: =L61-I61 -> 0 | P61: =N61-K61 -> -72.862825 | Q61: =N61/K61 -> 0.89880163 | S61: 0.36944444 | T61: 0.38929398 | U61: 14.7 | V61: 28.593629 | AA61: =M61-J61 -> -364.31412 | AB61: =M61/J61 -> 0.89880163
B62: 18℃-飯糰 | C62: 一配雞肉飯飯糰 | E62: 16.66 | F62: 4063 | G62: =E62*F62 -> 67689.58 | I62: 5 | J62: 3600 | K62: =J62/I62 -> 720 | L62: 5 | M62: =F62/V62*60 -> 3238.9167 | N62: =M62/L62 -> 647.78334 | O62: =L62-I62 -> 0 | P62: =N62-K62 -> -72.216656 | Q62: =N62/K62 -> 0.89969909 | S62: 0.39930556 | T62: 0.4515625 | U62: 15 | V62: 75.265906 | AA62: =M62-J62 -> -361.08328 | AB62: =M62/J62 -> 0.89969909
B72: 平均 | I72: =AVERAGE(I56:I71) -> 4.1428571 | J72: =AVERAGE(J56:J71) -> 3557.1429 | K72: =J72/I72 -> 858.62069 | L72: =AVERAGE(L56:L71) -> 4.1428571 | M72: =AVERAGE(M56:M71) -> 3210.0686 | N72: =M72/L72 -> 774.84414 | O72: =L72-I72 -> 0 | P72: =N72-K72 -> -83.776553 | Q72: =N72/K72 -> 0.90242891 | S72: 0.25 | T72: 0.4515625 | AA72: =M72-J72 -> -347.07429 | AB72: =M72/J72 -> 0.90242891
A73: 自動包裝機 (二配) | B73: 18℃-飯糰 | C73: 二配兩粒飯糰(鮪魚.焦糖鮭魚) | E73: 28.57 | F73: 1080 | G73: =E73*F73 -> 30855.6 | I73: 12 | J73: 3600 | K73: =J73/I73 -> 300 | L73: 12 | M73: =F73/V73*60 -> 3120.8098 | N73: =M73/L73 -> 260.06748 | O73: =L73-I73 -> 0 | P73: =N73-K73 -> -39.932517 | Q73: =N73/K73 -> 0.86689161 | R73: =Q89 -> 0.88599697 | S73: 0.70833333 | T73: 0.72274306 | V73: 20.763842 | AA73: =M73-J73 -> -479.19021 | AB73: =M73/J73 -> 0.86689161 | AC73: =AB89 -> 0.88599697
B74: 18℃-飯糰 | C74: 二配柚香雞胸五穀飯糰 | E74: 17.71 | F74: 275 | G74: =E74*F74 -> 4870.25 | I74: 5 | J74: 3600 | K74: =J74/I74 -> 720 | L74: 5 | M74: =F74/V74*60 -> 3258.3684 | N74: =M74/L74 -> 651.67368 | O74: =L74-I74 -> 0 | P74: =N74-K74 -> -68.326317 | Q74: =N74/K74 -> 0.90510234 | S74: 0.72569444 | T74: 0.72920139 | U74: 5 | V74: 5.0638841 | AA74: =M74-J74 -> -341.63159 | AB74: =M74/J74 -> 0.90510234
B89: 平均 | I89: =AVERAGE(I73:I88) -> 8.5 | J89: =AVERAGE(J73:J88) -> 3600 | K89: =J89/I89 -> 423.52941 | L89: =AVERAGE(L73:L88) -> 8.5 | M89: =AVERAGE(M73:M88) -> 3189.5891 | N89: =M89/L89 -> 375.24578 | O89: =L89-I89 -> 0 | P89: =N89-K89 -> -48.283635 | Q89: =N89/K89 -> 0.88599697 | S89: 0.70833333 | T89: 0.72920139 | AA89: =M89-J89 -> -410.4109 | AB89: =M89/J89 -> 0.88599697
A90: (新) 3300型飯糰機 (二配) | B90: 18℃-飯糰 | C90: 二配大飯糰韓式蒜烤豬五花 | E90: 24.54 | F90: 918 | G90: =E90*F90 -> 22527.72 | I90: 4 | J90: 3000 | K90: =J90/I90 -> 750 | L90: 4 | M90: =F90/V90*60 -> 2761.7536 | N90: =M90/L90 -> 690.43839 | O90: =L90-I90 -> 0 | P90: =N90-K90 -> -59.561612 | Q90: =N90/K90 -> 0.92058452 | R90: =Q106 -> 0.92030289 | S90: 0.70833333 | T90: 0.72217593 | V90: 19.943851 | AA90: =M90-J90 -> -238.24645 | AB90: =M90/J90 -> 0.92058452 | AC90: =AB106 -> 0.92030289
B91: 18℃-飯糰 | C91: 二配大飯糰泡菜鮪魚 | E91: 24.33 | F91: 861 | G91: =E91*F91 -> 20948.13 | I91: 4 | J91: 3000 | K91: =J91/I91 -> 750 | L91: 4 | M91: =F91/V91*60 -> 2759.3951 | N91: =M91/L91 -> 689.84877 | O91: =L91-I91 -> 0 | P91: =N91-K91 -> -60.151232 | Q91: =N91/K91 -> 0.91979836 | S91: 0.725 | T91: 0.73799769 | U91: 5 | V91: 18.721495 | AA91: =M91-J91 -> -240.60493 | AB91: =M91/J91 -> 0.91979836
B92: 18℃-飯糰 | C92: 二配醬燒炙烤牛飯糰 | E92: 22.32 | F92: 2356 | G92: =E92*F92 -> 52585.92 | I92: 5 | J92: 3300 | K92: =J92/I92 -> 660 | L92: 5 | M92: =F92/V92*60 -> 3038.3732 | N92: =M92/L92 -> 607.67465 | O92: =L92-I92 -> 0 | P92: =N92-K92 -> -52.325351 | Q92: =N92/K92 -> 0.92071917 | S92: 0.74097222 | T92: 0.77327546 | U92: 5 | V92: 46.524896 | AA92: =M92-J92 -> -261.62675 | AB92: =M92/J92 -> 0.92071917
B93: 18℃-飯糰 | C93: 二配鹽蔥燒肉飯糰 | E93: 17.89 | F93: 4183 | G93: =E93*F93 -> 74833.87 | I93: 4 | J93: 3300 | K93: =J93/I93 -> 825 | L93: 4 | M93: =F93/V93*60 -> 3036.2945 | N93: =M93/L93 -> 759.07363 | O93: =L93-I93 -> 0 | P93: =N93-K93 -> -65.926366 | Q93: =N93/K93 -> 0.92008925 | S93: 0.77638889 | T93: 0.83378472 | U93: 5 | V93: 82.659965 | AA93: =M93-J93 -> -263.70546 | AB93: =M93/J93 -> 0.92008925
B106: 平均 | I106: =AVERAGE(I90:I105) -> 4.25 | J106: =AVERAGE(J90:J105) -> 3150 | K106: =J106/I106 -> 741.17647 | L106: =AVERAGE(L90:L105) -> 4.25 | M106: =AVERAGE(M90:M105) -> 2898.9541 | N106: =M106/L106 -> 682.10685 | O106: =L106-I106 -> 0 | P106: =N106-K106 -> -59.069623 | Q106: =N106/K106 -> 0.92030289 | S106: 0.70833333 | T106: 0.83378472 | AA106: =M106-J106 -> -251.0459 | AB106: =M106/J106 -> 0.92030289
A107: GKK3600型 飯糰機 (二配) | B107: 18℃-飯糰 | C107: 二配芝麻香鬆飯糰 | E107: 18.18 | F107: 1508 | G107: =E107*F107 -> 27415.44 | I107: 3 | J107: 3000 | K107: =J107/I107 -> 1000 | L107: 3 | M107: =F107/V107*60 -> 2762.3514 | N107: =M107/L107 -> 920.7838 | O107: =L107-I107 -> 0 | P107: =N107-K107 -> -79.216196 | Q107: =N107/K107 -> 0.9207838 | R107: =Q123 -> 0.90711162 | S107: 0.72777778 | T107: 0.75052083 | V107: 32.754703 | AA107: =M107-J107 -> -237.64859 | AB107: =M107/J107 -> 0.9207838 | AC107: =AB123 -> 0.90711162
B108: 18℃-飯糰 | C108: 二配蔬食鮪魚飯糰 | E108: 18.18 | F108: 954 | G108: =E108*F108 -> 17343.72 | I108: 3 | J108: 3600 | K108: =J108/I108 -> 1200 | L108: 3 | M108: =F108/V108*60 -> 3238.3311 | N108: =M108/L108 -> 1079.4437 | O108: =L108-I108 -> 0 | P108: =N108-K108 -> -120.55629 | Q108: =N108/K108 -> 0.89953642 | S108: 0.76041667 | T108: 0.77268519 | U108: 15 | V108: 17.675771 | AA108: =M108-J108 -> -361.66888 | AB108: =M108/J108 -> 0.89953642
B109: 18℃-飯糰 | C109: 二配鮪魚飯糰 | E109: 14.28 | F109: 2945 | G109: =E109*F109 -> 42054.6 | H109: 2 | I109: 3 | J109: 3600 | K109: =J109/I109 -> 1200 | L109: 3 | M109: =F109/V109*60 -> 3239.2138 | N109: =M109/L109 -> 1079.7379 | O109: =L109-I109 -> 0 | P109: =N109-K109 -> -120.26207 | Q109: =N109/K109 -> 0.89978161 | S109: 0.78263889 | T109: 0.82052083 | U109: 15 | V109: 54.550274 | AA109: =M109-J109 -> -360.7862 | AB109: =M109/J109 -> 0.89978161
B110: 18℃-飯糰 | C110: 二配經典肉鬆飯糰 | E110: 14.03 | F110: 6042 | G110: =E110*F110 -> 84769.26 | I110: 3 | J110: 3000 | K110: =J110/I110 -> 1000 | L110: 3 | M110: =F110/V110*60 -> 2759.8774 | N110: =M110/L110 -> 919.95915 | O110: =L110-I110 -> 0 | P110: =N110-K110 -> -80.040852 | Q110: =N110/K110 -> 0.91995915 | S110: 0.83055556 | T110: 0.92177083 | U110: 15 | V110: 131.35366 | AA110: =M110-J110 -> -240.12255 | AB110: =M110/J110 -> 0.91995915
...

Sheet 0830(4度C)
A1: 大溪廠日報分析 | C1: 總生產量 | D1: =SUM(F5:F140) -> 96875 | E1: 營業額 | F1: =SUM(G5:G140) -> 4357450.3 | G1: 出勤人數 | H1: =L21+L38+L55+L72+L89+L106+L123+L140 -> 137.54167 | I1: 產線配置圖 | L1: 生產實績 | O1: 人時性差異分析 | S1: 日報登錄 | Y1: 合計次數 | Z1: 合計(時間/分) | AA1: 產線異常 分析說明(5分鐘以上) | AC1: 合計次數 | AD1: 合計(時間/分) | AE1: 產能差異分析
A2: 46264 | C2: 人時性 | D2: =AVERAGE(N21,N38,N55,N72,N89,N106,N123,N140) -> 208.94606 | E2: 平均廠價 | F2: =F1/D1 -> 44.980133 | G2: 多次生產數 | H2: =COUNT(H5:H140) -> 0 | Y2: =SUM(Y21,Y38,Y55,Y72,Y89,Y106,Y123,Y140) -> 0 | Z2: =SUM(Z21,Z38,Z55,Z72,Z89,Z106,Z123,Z140) -> 0 | AC2: =SUM(AC21,AC38,AC55,AC72,AC89,AC106,AC123,AC140) -> 0 | AD2: =SUM(AD21,AD38,AD55,AD72,AD89,AD106,AD123,AD140) -> 0
