Workbook

Sheet 0430
B1: 屏榮 大溪廠組合室生產人時性分析
B3: 日期 | C3: 115.04.30星期四 | E3: 訂單量 | F3: ='0430(18度C)'!D1+'0430(4度C)'!D1 -> 150674 | H3: 營業額 | I3: ='0430(18度C)'!F1+'0430(4度C)'!F1 -> 4446498.9
B4: 人時性 | C4: 項目 | E4: ➀ | G4: ➁ | I4: ➂ | K4: ④ | M4: ⑤ | O4: 異常停線 | Q4: 短暫停線
C5: 組合室 | E5: 全溫層 | G5: 4度C-各編組展開(一配) | I5: 4度C-各編組展開(二配) | K5: 18度C-各編組展開(一配) | M5: 18度C-各編組展開(二配) | O5: 合計次數 | P5: 時間 | Q5: 合計次數 | R5: 設備次數
C6: 排關平均 | E6: =AVERAGE(D14:O14,D32:X32) -> 467.18097 | F6: =AVERAGE(#REF!,D14:K14) -> #REF! | G6: =AVERAGE(D14:K14) -> 170.54851 | I6: =AVERAGE(L14:O14) -> 97.878788 | K6: =AVERAGE(D32:O32) -> 715.94326 | M6: =AVERAGE(P32:X32) -> 711.66978 | O6: ='0430(4度C)'!Y2 -> 0 | P6: ='0430(4度C)'!Z2 -> 0 | Q6: ='0430(4度C)'!AC2 -> 55 | R6: ='0430(4度C)'!AD2 -> 0
C7: 實績平均 | E7: =AVERAGE(D15:O15,D33:X33) -> 417.06453 | F7: =AVERAGE(#REF!,D15:K15) -> #REF! | G7: =AVERAGE(D15:K15) -> 152.55672 | I7: =AVERAGE(L15:O15) -> 87.933172 | K7: =AVERAGE(D33:O33) -> 639.21328 | M7: =AVERAGE(P33:X33) -> 634.57904
C8: 達成率平均 | E8: =AVERAGE(D16:O16,D34:X34) -> 0.89355679 | F8: =AVERAGE(D16:K16,#REF!) -> #REF! | G8: =AVERAGE(D16:K16) -> 0.8942261 | I8: =AVERAGE(L16:O16) -> 0.90105421 | K8: =AVERAGE(D34:O34) -> 0.89104462 | M8: =AVERAGE(P34:X34) -> 0.89211166
O9: ※現行日本鮮食廠以達成率80%為基本(即為現行KPI)
B11: 溫層 | D11: ➁4度C-各編組展開 | L11: ➂4度C-各編組展開
B12: 編組 | D12: 1 | E12: 2 | F12: 3 | G12: 4 | H12: 5 | I12: 6 | J12: 7 | K12: 8 | L12: 1 | M12: 2 | N12: 3 | O12: 4
D13: 便當一線 | E13: 便當二線 | F13: 涼麵一線 | G13: 涼麵二線 | H13: 涼麵三線 | I13: 自動包裝機 | J13: 自動包裝機2 | K13: 自動包裝機3 | L13: 便當一線 | M13: 便當二線 | N13: 涼麵一線 | O13: 涼麵二線
B14: 人時性 | C14: 排關 | D14: - | E14: 84.507042 | F14: 100.84112 | G14: 83.72093 | H14: 183.67347 | I14: - | J14: - | K14: 400 | L14: - | M14: 86.666667 | N14: 109.09091 | O14: -
C15: 實績 | D15: - | E15: 75.601162 | F15: 90.545586 | G15: 74.950555 | H15: 162.73183 | I15: - | J15: - | K15: 358.95448 | L15: - | M15: 80.108221 | N15: 95.758123 | O15: -
C16: 達成率 | D16: - | E16: =E15/E14 -> 0.89461375 | F16: =F15/F14 -> 0.8979034 | G16: =G15/G14 -> 0.89524273 | H16: =H15/H14 -> 0.88598443 | I16: - | J16: - | K16: =K15/K14 -> 0.8973862 | L16: - | M16: =M15/M14 -> 0.92432562 | N16: =N15/N14 -> 0.87778279 | O16: -
B17: 作業 時間 | C17: 開始 | D17: - | E17: 0.29166667 | F17: 0.29166667 | G17: 0.29166667 | H17: 0.25 | I17: - | J17: - | K17: 0.29166667 | L17: - | M17: 0.70833333 | N17: 0.70833333 | O17: -
C18: 結束 | D18: - | E18: 0.51590278 | F18: 0.54625 | G18: 0.58618056 | H18: 0.52212963 | I18: - | J18: - | K18: 0.3840162 | L18: - | M18: 0.84270833 | N18: 0.81527778 | O18: -
B19: 產線異常 (5分鐘以上) | C19: 次數
C20: 時間/分
B21: 短暫停線 (5分鐘以下) | C21: 次數 | E21: 9 | F21: 9 | G21: 11 | H21: 11 | K21: 6 | M21: 4 | N21: 5
C22: 設備次數
B23: 配置人數 | D23: - | E23: 23.666667 | F23: 21.6 | G23: 21.5 | H23: 19.6 | I23: - | J23: - | K23: 7.25 | L23: - | M23: 21.75 | N23: 18.666667 | O23: -
B24: 主要應用設備 | D24: L型封口機 | E24: ET-55 | F24: ET-55 | G24: ET-55 | H24: ET-600 | I24: 伺服包裝機 | J24: 伺服包裝機 | K24: 伺服包裝機 | L24: L型封口機 | M24: ET-55 | N24: ET-55 | O24: ET-55
B25: 次要應用設備 | D25: 伺服包裝機 | H25: 伺服包裝機
B26: 備註 | H26: 涼麵+烤飯糰 | I26: 大口飯糰線 | K26: 烤飯糰+手卷
B29: 溫層 | D29: ➃18度C-各編組展開 (一配) | P29: ⑤18度C-各編組展開 (二配)
B30: 編組 | D30: 1 | E30: 2 | F30: 3 | G30: 4 | H30: 5 | I30: 6 | J30: 7 | K30: 8 | L30: 9 | M30: 10 | N30: 11 | O30: 12 | P30: 1 | Q30: 2 | R30: 3 | S30: 4 | T30: 5 | U30: 6 | V30: 7 | W30: 8 | X30: 9
D31: 便當一線 | E31: 涼麵一線 | F31: 涼麵三線 | G31: 自動包裝機 | H31: 自動包裝機2 | I31: 自動包裝機3 | J31: 味付飯糰線B | K31: (舊) 3300型飯糰線 | L31: 3000型飯糰線 | M31: (新) 3300型飯糰機 | N31: GKK3600型 飯糰機 | O31: GKK3600型 飯糰機2 | P31: 自動包裝機 | Q31: 自動包裝機2 | R31: 自動包裝機3 | S31: 味付飯糰線B | T31: (舊) 3300型飯糰線 | U31: 3000型飯糰線 | V31: (新) 3300型飯糰機 | W31: GKK3600型 飯糰機 | X31: GKK3600型 飯糰機2
B32: 人時性 | C32: 排關 | D32: - | E32: - | F32: - | G32: 306.38298 | H32: 433.33333 | I32: - | J32: - | K32: - | L32: - | M32: 1100 | N32: 900 | O32: 840 | P32: 291.89189 | Q32: - | R32: - | S32: - | T32: - | U32: - | V32: 775 | W32: 950 | X32: 829.78723
C33: 實績 | D33: - | E33: - | F33: - | G33: 268.53366 | H33: 390.87096 | I33: - | J33: - | K33: - | L33: - | M33: 993.68422 | N33: 799.82478 | O33: 743.15278 | P33: 260.75268 | Q33: - | R33: - | S33: - | T33: - | U33: - | V33: 696.39295 | W33: 845.64134 | X33: 735.52918
C34: 達成率 | D34: - | E34: - | F34: - | G34: =G33/G32 -> 0.87646403 | H34: =H33/H32 -> 0.90200991 | I34: - | J34: - | K34: - | L34: - | M34: =M33/M32 -> 0.90334929 | N34: =N33/N32 -> 0.8886942 | O34: =O33/O32 -> 0.88470569 | P34: =P33/P32 -> 0.89331937 | Q34: - | R34: - | S34: - | T34: - | U34: - | V34: =V33/V32 -> 0.89857155 | W34: =W33/W32 -> 0.89014878 | X34: =X33/X32 -> 0.88640696
B35: 作業 時間 | C35: 開始 | D35: - | E35: - | F35: - | G35: 0.29166667 | H35: 0.29166667 | I35: - | J35: - | K35: - | L35: - | M35: 0.35416667 | N35: 0.25 | O35: 0.25 | P35: 0.70833333 | Q35: - | R35: - | S35: - | T35: - | U35: - | V35: 0.70833333 | W35: 0.70833333 | X35: 0.70833333
C36: 結束 | D36: - | E36: - | F36: - | G36: 0.40365741 | H36: 0.31631944 | I36: - | J36: - | K36: - | L36: - | M36: 0.38686343 | N36: 0.52420139 | O36: 0.5196412 | P36: 0.75038194 | Q36: - | R36: - | S36: - | T36: - | U36: - | V36: 0.78847222 | W36: 1.0948958 | X36: 1.0823843
B37: 配置人數 | D37: - | E37: - | F37: - | G37: 11.75 | H37: 6 | I37: - | J37: - | K37: - | L37: - | M37: 3 | N37: 3.8333333 | O37: 4.2857143 | P37: 12.333333 | Q37: - | R37: - | S37: - | T37: - | U37: - | V37: 4 | W37: 3.6 | X37: 4.2727273
B38: 主要應用設備 | D38: 伺服包裝機 | E38: ET-55 | F38: ET-600 | G38: 夾心型 | H38: 伺服包裝機 | I38: 伺服包裝機 | J38: 夾心型 | K38: 3300型 | L38: 3300型 | M38: 3300型 | N38: GKK | O38: GKK | P38: 夾心型 | Q38: 伺服包裝機 | R38: 伺服包裝機 | S38: 夾心型 | T38: 3300型 | U38: 3300型 | V38: 3300型 | W38: GKK | X38: GKK
B39: 次要應用設備
B40: 備註

Sheet 0430(18度C)
A1: 大溪廠日報分析 | C1: 總生產量 | D1: =SUM(F5:F157) -> 93443 | E1: 營業額 | F1: =SUM(G5:G157) -> 1887255 | G1: 出勤人數 | H1: =L21+L38+L55+L72+L89+L106+L123+L140+L157 -> 53.075108 | I1: 產線配置圖 | L1: 生產實績 | O1: 人時性差異分析 | S1: 日報登錄 | Y1: 分析說明 | AA1: 產能差異分析
A2: 46142 | C2: 人時性 | D2: =AVERAGE(N21,N38,N55,N72,N89,N106,N123,N140,N157) -> 637.15362 | E2: 平均廠價 | F2: =F1/D1 -> 20.196859 | G2: 多次生產數 | H2: =COUNT(H5:H157) -> 9
A3: 線別 | B3: 品類 | C3: 品名 | E3: 廠價 | F3: 生產量 | G3: 營收 | H3: 多次 生產 | I3: 人數 | J3: 產能/時 | K3: 人時性 | L3: 人數 | M3: 產能/時 | N3: 人時性 | O3: 人數 | P3: 人時性 | Q3: 達成率 | R3: 達成率 平均 | S3: 生產時間 | U3: 換線、休息/分 | V3: 稼動時間/分 | W3: 休息時間 | Y3: (屏榮回填) | AA3: 產能/時 | AB3: 達成率 | AC3: 達成率平均
S4: 開始 | T4: 結束 | W4: 開始 | X4: 結束
A5: 自動包裝機 | B5: 18℃-壽司手卷 | C5: 一配長野稻荷壽司 | E5: 25.64 | F5: 1076 | G5: =E5*F5 -> 27588.64 | I5: 11 | J5: 3600 | K5: =J5/I5 -> 327.27273 | L5: 11 | M5: =F5/V5*60 -> 3181.9957 | N5: =M5/L5 -> 289.27234 | O5: =L5-I5 -> 0 | P5: =N5-K5 -> -38.000387 | Q5: =N5/K5 -> 0.88388771 | R5: =Q21 -> 0.87646403 | S5: 0.29166667 | T5: 0.30575231 | V5: 20.289153 | AA5: =M5-J5 -> -418.00425 | AB5: =M5/J5 -> 0.88388771 | AC5: =AB21 -> 0.87646403
B6: 18℃-壽司手卷 | C6: 一配經典人氣雙手卷 | E6: 29.52 | F6: 2366 | G6: =E6*F6 -> 69844.32 | I6: 12 | J6: 3600 | K6: =J6/I6 -> 300 | L6: 12 | M6: =F6/V6*60 -> 3158.0217 | N6: =M6/L6 -> 263.16848 | O6: =L6-I6 -> 0 | P6: =N6-K6 -> -36.831522 | Q6: =N6/K6 -> 0.87722826 | S6: 0.30972222 | T6: 0.3409375 | U6: 5.7166667 | V6: 44.952192 | AA6: =M6-J6 -> -441.97827 | AB6: =M6/J6 -> 0.87722826
B7: 18℃-壽司手卷 | C7: 一配鮭鮪海饌雙手卷 | E7: 29.85 | F7: 2656 | G7: =E7*F7 -> 79281.6 | I7: 12 | J7: 3600 | K7: =J7/I7 -> 300 | L7: 12 | M7: =F7/V7*60 -> 3157.5698 | N7: =M7/L7 -> 263.13082 | O7: =L7-I7 -> 0 | P7: =N7-K7 -> -36.869182 | Q7: =N7/K7 -> 0.87710273 | S7: 0.34444444 | T7: 0.37949074 | U7: 5.05 | V7: 50.469193 | AA7: =M7-J7 -> -442.43018 | AB7: =M7/J7 -> 0.87710273
B8: 18℃-飯糰 | C8: 一配兩粒飯糰(鮪魚.焦糖鮭魚) | E8: 28.57 | F8: 1576 | G8: =E8*F8 -> 45026.32 | I8: 12 | J8: 3600 | K8: =J8/I8 -> 300 | L8: 12 | M8: =F8/V8*60 -> 3123.4947 | N8: =M8/L8 -> 260.29123 | O8: =L8-I8 -> 0 | P8: =N8-K8 -> -39.708771 | Q8: =N8/K8 -> 0.86763743 | S8: 0.38263889 | T8: 0.40365741 | U8: 4.5333333 | V8: 30.273782 | AA8: =M8-J8 -> -476.50525 | AB8: =M8/J8 -> 0.86763743
B21: 平均 | I21: =AVERAGE(I5:I20) -> 11.75 | J21: =AVERAGE(J5:J20) -> 3600 | K21: =J21/I21 -> 306.38298 | L21: =AVERAGE(L5:L20) -> 11.75 | M21: =AVERAGE(M5:M20) -> 3155.2705 | N21: =M21/L21 -> 268.53366 | O21: =L21-I21 -> 0 | P21: =N21-K21 -> -37.849318 | Q21: =N21/K21 -> 0.87646403 | S21: =S5 -> 0.29166667 | T21: =INDEX(T5:T20,COUNTA(T5:T20)) -> 0.40365741 | AA21: =M21-J21 -> -444.72949 | AB21: =M21/J21 -> 0.87646403
A22: 自動包裝機2 | B22: 18℃-壽司手卷 | C22: 一配雙鬆細卷 | E22: 14.03 | F22: 576 | G22: =E22*F22 -> 8081.28 | I22: 6 | J22: 2600 | K22: =J22/I22 -> 433.33333 | L22: 6 | M22: =F22/V22*60 -> 2346.3268 | N22: =M22/L22 -> 391.05447 | O22: =L22-I22 -> 0 | P22: =N22-K22 -> -42.27886 | Q22: =N22/K22 -> 0.9024334 | R22: =Q38 -> 0.90200991 | S22: 0.29166667 | T22: 0.30188657 | V22: 14.729406 | AA22: =M22-J22 -> -253.67316 | AB22: =M22/J22 -> 0.9024334 | AC22: =AB38 -> 0.90200991
B23: 18℃-壽司手卷 | C23: 一配經典鮪魚沙拉細卷 | E23: 14.49 | F23: 645 | G23: =E23*F23 -> 9346.05 | I23: 6 | J23: 2600 | K23: =J23/I23 -> 433.33333 | L23: 6 | M23: =F23/V23*60 -> 2344.1247 | N23: =M23/L23 -> 390.68745 | O23: =L23-I23 -> 0 | P23: =N23-K23 -> -42.645886 | Q23: =N23/K23 -> 0.90158642 | S23: 0.30486111 | T23: 0.31631944 | U23: 5 | V23: 16.509361 | AA23: =M23-J23 -> -255.87531 | AB23: =M23/J23 -> 0.90158642
B38: 平均 | I38: =AVERAGE(I22:I37) -> 6 | J38: =AVERAGE(J22:J37) -> 2600 | K38: =J38/I38 -> 433.33333 | L38: =AVERAGE(L22:L37) -> 6 | M38: =AVERAGE(M22:M37) -> 2345.2258 | N38: =M38/L38 -> 390.87096 | O38: =L38-I38 -> 0 | P38: =N38-K38 -> -42.462373 | Q38: =N38/K38 -> 0.90200991 | S38: =S22 -> 0.29166667 | T38: =INDEX(T22:T37,COUNTA(T22:T37)) -> 0.31631944 | AA38: =M38-J38 -> -254.77424 | AB38: =M38/J38 -> 0.90200991
A39: (新) 3300型飯糰機 | B39: 18℃-飯糰 | C39: 一配鮭魚奶油醬油飯糰 | E39: 18.53 | F39: 2340 | G39: =E39*F39 -> 43360.2 | I39: 3 | J39: 3300 | K39: =J39/I39 -> 1100 | L39: 3 | M39: =F39/V39*60 -> 2981.0527 | N39: =M39/L39 -> 993.68422 | O39: =L39-I39 -> 0 | P39: =N39-K39 -> -106.31578 | Q39: =N39/K39 -> 0.90334929 | R39: =Q55 -> 0.90334929 | S39: 0.35416667 | T39: 0.38686343 | V39: 47.097457 | AA39: =M39-J39 -> -318.94734 | AB39: =M39/J39 -> 0.90334929 | AC39: =AB55 -> 0.90334929
B55: 平均 | I55: =AVERAGE(I39:I54) -> 3 | J55: =AVERAGE(J39:J54) -> 3300 | K55: =J55/I55 -> 1100 | L55: =AVERAGE(L39:L54) -> 3 | M55: =AVERAGE(M39:M54) -> 2981.0527 | N55: =M55/L55 -> 993.68422 | O55: =L55-I55 -> 0 | P55: =N55-K55 -> -106.31578 | Q55: =N55/K55 -> 0.90334929 | S55: =S39 -> 0.35416667 | T55: =INDEX(T39:T54,COUNTA(T39:T54)) -> 0.38686343 | AA55: =M55-J55 -> -318.94734 | AB55: =M55/J55 -> 0.90334929
A56: GKK3600型 飯糰機 | B56: 18℃-飯糰 | C56: 一配經典肉鬆飯糰 | E56: 14.03 | F56: 3382 | G56: =E56*F56 -> 47449.46 | I56: 3 | J56: 3000 | K56: =J56/I56 -> 1000 | L56: 3 | M56: =F56/V56*60 -> 2706.0987 | N56: =M56/L56 -> 902.0329 | O56: =L56-I56 -> 0 | P56: =N56-K56 -> -97.9671 | Q56: =N56/K56 -> 0.9020329 | R56: =Q72 -> 0.8886942 | S56: 0.25 | T56: 0.30207176 | V56: 74.986178 | AA56: =M56-J56 -> -293.9013 | AB56: =M56/J56 -> 0.9020329 | AC56: =AB72 -> 0.8886942
B57: 18℃-飯糰 | C57: 一配鮪魚飯糰 | E57: 14.28 | F57: 4555 | G57: =E57*F57 -> 65045.4 | I57: 3 | J57: 3600 | K57: =J57/I57 -> 1200 | L57: 3 | M57: =F57/V57*60 -> 3181.5653 | N57: =M57/L57 -> 1060.5218 | O57: =L57-I57 -> 0 | P57: =N57-K57 -> -139.47822 | Q57: =N57/K57 -> 0.88376815 | S57: 0.31180556 | T57: 0.37145833 | U57: 15 | V57: 85.901112 | AA57: =M57-J57 -> -418.43467 | AB57: =M57/J57 -> 0.88376815
B58: 18℃-飯糰 | C58: 一配鹽蔥燒肉飯糰 | E58: 17.89 | F58: 2416 | G58: =E58*F58 -> 43222.24 | I58: 4 | J58: 3600 | K58: =J58/I58 -> 900 | L58: 4 | M58: =F58/V58*60 -> 3184.6142 | N58: =M58/L58 -> 796.15354 | O58: =L58-I58 -> 0 | P58: =N58-K58 -> -103.84646 | Q58: =N58/K58 -> 0.88461504 | S58: 0.38125 | T58: 0.4128588 | U58: 15 | V58: 45.518858 | AA58: =M58-J58 -> -415.38584 | AB58: =M58/J58 -> 0.88461504
B59: 18℃-飯糰 | C59: 一配壹號醬炙烤牛飯糰 | E59: 22.28 | F59: 851 | G59: =E59*F59 -> 18960.28 | I59: 5 | J59: 3300 | K59: =J59/I59 -> 660 | L59: 5 | M59: =F59/V59*60 -> 2951.3575 | N59: =M59/L59 -> 590.27149 | O59: =L59-I59 -> 0 | P59: =N59-K59 -> -69.728505 | Q59: =N59/K59 -> 0.89435075 | S59: 0.42291667 | T59: 0.43493056 | U59: 15 | V59: 17.300514 | AA59: =M59-J59 -> -348.64253 | AB59: =M59/J59 -> 0.89435075
B60: 18℃-飯糰 | C60: 一配明太子龍蝦風味沙拉飯糰 | E60: 18.18 | F60: 1738 | G60: =E60*F60 -> 31596.84 | I60: 3 | J60: 3600 | K60: =J60/I60 -> 1200 | L60: 3 | M60: =F60/V60*60 -> 3184.4383 | N60: =M60/L60 -> 1061.4794 | O60: =L60-I60 -> 0 | P60: =N60-K60 -> -138.52057 | Q60: =N60/K60 -> 0.88456619 | S60: 0.44513889 | T60: 0.46787037 | U60: 14.7 | V60: 32.746749 | AA60: =M60-J60 -> -415.56171 | AB60: =M60/J60 -> 0.88456619
B61: 18℃-飯糰 | C61: 一配鹽蔥生鮭飯糰 | E61: 27.48 | F61: 3552 | G61: =E61*F61 -> 97608.96 | I61: 5 | J61: 3600 | K61: =J61/I61 -> 720 | L61: 5 | M61: =F61/V61*60 -> 3187.8961 | N61: =M61/L61 -> 637.57921 | O61: =L61-I61 -> 0 | P61: =N61-K61 -> -82.420789 | Q61: =N61/K61 -> 0.88552668 | S61: 0.47777778 | T61: 0.52420139 | U61: 15 | V61: 66.85287 | AA61: =M61-J61 -> -412.10395 | AB61: =M61/J61 -> 0.88552668
B72: 平均 | I72: =AVERAGE(I56:I71) -> 3.8333333 | J72: =AVERAGE(J56:J71) -> 3450 | K72: =J72/I72 -> 900 | L72: =AVERAGE(L56:L71) -> 3.8333333 | M72: =AVERAGE(M56:M71) -> 3065.995 | N72: =M72/L72 -> 799.82478 | O72: =L72-I72 -> 0 | P72: =N72-K72 -> -100.17522 | Q72: =N72/K72 -> 0.8886942 | S72: =S56 -> 0.25 | T72: =INDEX(T56:T71,COUNTA(T56:T71)) -> 0.52420139 | AA72: =M72-J72 -> -384.005 | AB72: =M72/J72 -> 0.8886942
A73: GKK3600型 飯糰機2 | B73: 18℃-飯糰 | C73: 一配柚檸海灣貝飯糰 | E73: 23.72 | F73: 2966 | G73: =E73*F73 -> 70353.52 | I73: 5 | J73: 3600 | K73: =J73/I73 -> 720 | L73: 5 | M73: =F73/V73*60 -> 3181.6575 | N73: =M73/L73 -> 636.33151 | O73: =L73-I73 -> 0 | P73: =N73-K73 -> -83.668492 | Q73: =N73/K73 -> 0.88379376 | R73: =Q89 -> 0.88470569 | S73: 0.25 | T73: 0.28883102 | V73: 55.93311 | AA73: =M73-J73 -> -418.34246 | AB73: =M73/J73 -> 0.88379376 | AC73: =AB89 -> 0.88470569
B74: 18℃-飯糰 | C74: 一配雞肉飯飯糰 | E74: 16.66 | F74: 3799 | G74: =E74*F74 -> 63291.34 | I74: 5 | J74: 3600 | K74: =J74/I74 -> 720 | L74: 5 | M74: =F74/V74*60 -> 3184.6958 | N74: =M74/L74 -> 636.93917 | O74: =L74-I74 -> 0 | P74: =N74-K74 -> -83.060834 | Q74: =N74/K74 -> 0.88463773 | S74: 0.29861111 | T74: 0.34831019 | U74: 15 | V74: 71.573554 | AA74: =M74-J74 -> -415.30417 | AB74: =M74/J74 -> 0.88463773
B75: 18℃-飯糰 | C75: 一配蔬食鮪魚飯糰 | E75: 18.18 | F75: 830 | G75: =E75*F75 -> 15089.4 | I75: 3 | J75: 3600 | K75: =J75/I75 -> 1200 | L75: 3 | M75: =F75/V75*60 -> 3182.6659 | N75: =M75/L75 -> 1060.8886 | O75: =L75-I75 -> 0 | P75: =N75-K75 -> -139.11136 | Q75: =N75/K75 -> 0.88407386 | S75: 0.35833333 | T75: 0.36918981 | U75: 15 | V75: 15.64726 | AA75: =M75-J75 -> -417.33409 | AB75: =M75/J75 -> 0.88407386
B76: 18℃-飯糰 | C76: 一配熟成紅鮭飯糰 | E76: 25.03 | F76: 1238 | G76: =E76*F76 -> 30987.14 | I76: 5 | J76: 3600 | K76: =J76/I76 -> 720 | L76: 5 | M76: =F76/V76*60 -> 3187.782 | N76: =M76/L76 -> 637.5564 | O76: =L76-I76 -> 0 | P76: =N76-K76 -> -82.443597 | Q76: =N76/K76 -> 0.885495 | S76: 0.37916667 | T76: 0.39534722 | U76: 15 | V76: 23.301468 | AA76: =M76-J76 -> -412.21799 | AB76: =M76/J76 -> 0.885495
B77: 18℃-飯糰 | C77: 一配北海道秋鮭親子飯糰 | E77: 24.82 | F77: 1588 | G77: =E77*F77 -> 39414.16 | I77: 5 | J77: 3600 | K77: =J77/I77 -> 720 | L77: 5 | M77: =F77/V77*60 -> 3187.4318 | N77: =M77/L77 -> 637.48637 | O77: =L77-I77 -> 0 | P77: =N77-K77 -> -82.513633 | Q77: =N77/K77 -> 0.88539773 | S77: 0.40555556 | T77: 0.42630787 | U77: 14.7 | V77: 29.892404 | AA77: =M77-J77 -> -412.56816 | AB77: =M77/J77 -> 0.88539773
B78: 18℃-飯糰 | C78: 一配贅沢鮭魚肚飯糰 | E78: 30 | F78: 2085 | G78: =E78*F78 -> 62550 | I78: 4 | J78: 3600 | K78: =J78/I78 -> 900 | L78: 4 | M78: =F78/V78*60 -> 3183.48 | N78: =M78/L78 -> 795.87 | O78: =L78-I78 -> 0 | P78: =N78-K78 -> -104.13 | Q78: =N78/K78 -> 0.8843 | S78: 0.43611111 | T78: 0.4633912 | U78: 15 | V78: 39.296619 | AA78: =M78-J78 -> -416.52 | AB78: =M78/J78 -> 0.8843
B79: 18℃-飯糰 | C79: 一配山葵章魚飯糰 | E79: 25.2 | F79: 3521 | G79: =E79*F79 -> 88729.2 | I79: 3 | J79: 3600 | K79: =J79/I79 -> 1200 | L79: 3 | M79: =F79/V79*60 -> 3186.8702 | N79: =M79/L79 -> 1062.2901 | O79: =L79-I79 -> 0 | P79: =N79-K79 -> -137.70995 | Q79: =N79/K79 -> 0.88524171 | S79: 0.47361111 | T79: 0.5196412 | U79: 14.716667 | V79: 66.290746 | AA79: =M79-J79 -> -413.12984 | AB79: =M79/J79 -> 0.88524171
B89: 平均 | I89: =AVERAGE(I73:I88) -> 4.2857143 | J89: =AVERAGE(J73:J88) -> 3600 | K89: =J89/I89 -> 840 | L89: =AVERAGE(L73:L88) -> 4.2857143 | M89: =AVERAGE(M73:M88) -> 3184.9405 | N89: =M89/L89 -> 743.15278 | O89: =L89-I89 -> 0 | P89: =N89-K89 -> -96.847224 | Q89: =N89/K89 -> 0.88470569 | S89: =S73 -> 0.25 | T89: =INDEX(T73:T88,COUNTA(T73:T88)) -> 0.5196412 | AA89: =M89-J89 -> -415.05953 | AB89: =M89/J89 -> 0.88470569
A90: 自動包裝機 (二配) | B90: 18℃-飯糰 | C90: 二配兩粒飯糰(鮪魚.焦糖鮭魚) | E90: 28.57 | F90: 1557 | G90: =E90*F90 -> 44483.49 | I90: 12 | J90: 3600 | K90: =J90/I90 -> 300 | L90: 12 | M90: =F90/V90*60 -> 3125.3338 | N90: =M90/L90 -> 260.44448 | O90: =L90-I90 -> 0 | P90: =N90-K90 -> -39.55552 | Q90: =N90/K90 -> 0.86814827 | R90: =Q106 -> 0.89331937 | S90: 0.70833333 | T90: 0.72908565 | V90: 29.891208 | AA90: =M90-J90 -> -474.66624 | AB90: =M90/J90 -> 0.86814827 | AC90: =AB106 -> 0.89331937
B91: 18℃-飯糰 | C91: 二配鮮蝦旬彩炊飯飯糰 | E91: 20.17 | F91: 106 | G91: =E91*F91 -> 2138.02 | I91: 12 | J91: 3600 | K91: =J91/I91 -> 300 | L91: 12 | M91: =F91/V91*60 -> 3260.6614 | N91: =M91/L91 -> 271.72178 | O91: =L91-I91 -> 0 | P91: =N91-K91 -> -28.278217 | Q91: =N91/K91 -> 0.90573928 | S91: 0.73263889 | T91: 0.73399306 | U91: 5.1166667 | V91: 1.9505245 | AA91: =M91-J91 -> -339.33861 | AB91: =M91/J91 -> 0.90573928
B92: 18℃-飯糰 | C92: 二配溏心蛋五目飯糰 | E92: 20.42 | F92: 1063 | G92: =E92*F92 -> 21706.46 | I92: 13 | J92: 3600 | K92: =J92/I92 -> 276.92308 | L92: 13 | M92: =F92/V92*60 -> 3261.854 | N92: =M92/L92 -> 250.91185 | O92: =L92-I92 -> 0 | P92: =N92-K92 -> -26.011229 | Q92: =N92/K92 -> 0.90607056 | S92: 0.73680556 | T92: 0.75038194 | U92: 5 | V92: 19.553297 | AA92: =M92-J92 -> -338.14597 | AB92: =M92/J92 -> 0.90607056
B106: 平均 | I106: =AVERAGE(I90:I105) -> 12.333333 | J106: =AVERAGE(J90:J105) -> 3600 | K106: =J106/I106 -> 291.89189 | L106: =AVERAGE(L90:L105) -> 12.333333 | M106: =AVERAGE(M90:M105) -> 3215.9497 | N106: =M106/L106 -> 260.75268 | O106: =L106-I106 -> 0 | P106: =N106-K106 -> -31.139211 | Q106: =N106/K106 -> 0.89331937 | S106: =S90 -> 0.70833333 | T106: =INDEX(T90:T105,COUNTA(T90:T105)) -> 0.75038194 | AA106: =M106-J106 -> -384.05027 | AB106: =M106/J106 -> 0.89331937
A107: (新) 3300型飯糰機 (二配) | B107: 18℃-飯糰 | C107: 二配鹽水G絲飯糰 | E107: 17.22 | F107: 1676 | G107: =E107*F107 -> 28860.72 | I107: 3 | J107: 3300 | K107: =J107/I107 -> 1100 | L107: 3 | M107: =F107/V107*60 -> 2980.1956 | N107: =M107/L107 -> 993.39853 | O107: =L107-I107 -> 0 | P107: =N107-K107 -> -106.60147 | Q107: =N107/K107 -> 0.90308957 | R107: =Q123 -> 0.89857155 | S107: 0.70833333 | T107: 0.73175926 | V107: 33.742752 | AA107: =M107-J107 -> -319.80442 | AB107: =M107/J107 -> 0.90308957 | AC107: =AB123 -> 0.89857155
B108: 18℃-飯糰 | C108: 二配大飯糰韓式蒜烤豬五花 | E108: 24.54 | F108: 1556 | G108: =E108*F108 -> 38184.24 | I108: 4 | J108: 3000 | K108: =J108/I108 -> 750 | L108: 4 | M108: =F108/V108*60 -> 2686.8248 | N108: =M108/L108 -> 671.7062 | O108: =L108-I108 -> 0 | P108: =N108-K108 -> -78.293798 | Q108: =N108/K108 -> 0.89560827 | S108: 0.73472222 | T108: 0.75884259 | U108: 5 | V108: 34.747334 | AA108: =M108-J108 -> -313.17519 | AB108: =M108/J108 -> 0.89560827
B109: 18℃-飯糰 | C109: 二配大飯糰乾燒風味鮮蝦 | E109: 23.27 | F109: 1722 | G109: =E109*F109 -> 40070.94 | I109: 5 | J109: 3000 | K109: =J109/I109 -> 600 | L109: 5 | M109: =F109/V109*60 -> 2689.695 | N109: =M109/L109 -> 537.939 | O109: =L109-I109 -> 0 | P109: =N109-K109 -> -62.060997 | Q109: =N109/K109 -> 0.896565 | S109: 0.76180556 | T109: 0.78847222 | U109: 5 | V109: 38.413277 | AA109: =M109-J109 -> -310.30499 | AB109: =M109/J109 -> 0.896565
B123: 平均 | I123: =AVERAGE(I107:I122) -> 4 | J123: =AVERAGE(J107:J122) -> 3100 | K123: =J123/I123 -> 775 | L123: =AVERAGE(L107:L122) -> 4 | M123: =AVERAGE(M107:M122) -> 2785.5718 | N123: =M123/L123 -> 696.39295 | O123: =L123-I123 -> 0 | P123: =N123-K123 -> -78.60705 | Q123: =N123/K123 -> 0.89857155 | S123: =S107 -> 0.70833333 | T123: =INDEX(T107:T122,COUNTA(T107:T122)) -> 0.78847222 | AA123: =M123-J123 -> -314.4282 | AB123: =M123/J123 -> 0.89857155
A124: GKK3600型 飯糰機 (二配) | B124: 18℃-飯糰 | C124: 二配壹號醬炙烤牛飯糰 | E124: 22.28 | F124: 390 | G124: =E124*F124 -> 8689.2 | H124: 2 | I124: 5 | J124: 3300 | K124: =J124/I124 -> 660 | L124: 5 | M124: =F124/V124*60 -> 2949.8805 | N124: =M124/L124 -> 589.9761 | O124: =L124-I124 -> 0 | P124: =N124-K124 -> -70.023897 | Q124: =N124/K124 -> 0.89390319 | R124: =Q140 -> 0.89014878 | S124: 0.70833333 | T124: 0.71383102 | V124: 7.9325247 | AA124: =M124-J124 -> -350.11948 | AB124: =M124/J124 -> 0.89390319 | AC124: =AB140 -> 0.89014878
B125: 18℃-飯糰 | C125: 二配經典肉鬆飯糰 | E125: 14.03 | F125: 1791 | G125: =E125*F125 -> 25127.73 | H125: 2 | I125: 3 | J125: 3000 | K125: =J125/I125 -> 1000 | L125: 3 | M125: =F125/V125*60 -> 2705.7152 | N125: =M125/L125 -> 901.90506 | O125: =L125-I125 -> 0 | P125: =N125-K125 -> -98.094942 | Q125: =N125/K125 -> 0.90190506 | S125: 0.72361111 | T125: 0.75118056 | U125: 15 | V125: 39.715932 | AA125: =M125-J125 -> -294.28483 | AB125: =M125/J125 -> 0.90190506
B126: 18℃-飯糰 | C126: 二配三杯醬爆菇菇飯糰 | E126: 16.7 | F126: 1077 | G126: =E126*F126 -> 17985.9 | I126: 3 | J126: 3600 | K126: =J126/I126 -> 1200 | L126: 3 | M126: =F126/V126*60 -> 3200.0848 | N126: =M126/L126 -> 1066.6949 | O126: =L126-I126 -> 0 | P126: =N126-K126 -> -133.30508 | Q126: =N126/K126 -> 0.88891243 | S126: 0.76111111 | T126: 0.77512731 | U126: 15 | V126: 20.193215 | AA126: =M126-J126 -> -399.91524 | AB126: =M126/J126 -> 0.88891243
...

Sheet 0430(4度C)
A1: 大溪廠日報分析 | C1: 總生產量 | D1: =SUM(F5:F123) -> 57231 | E1: 營業額 | F1: =SUM(G5:G123) -> 2559243.8 | G1: 出勤人數 | H1: =L21+L38+L55+L72+L89+L106+L123 -> 134.03333 | I1: 產線配置圖 | L1: 生產實績 | O1: 人時性差異分析 | S1: 日報登錄 | Y1: 合計次數 | Z1: 合計(時間/分) | AA1: 產線異常 分析說明(5分鐘以上) | AC1: 合計次數 | AD1: 合計(時間/分) | AE1: 產能差異分析
A2: 46142 | C2: 人時性 | D2: =AVERAGE(N21,N38,N55,N72,N89,N106,N123) -> 134.09285 | E2: 平均廠價 | F2: =F1/D1 -> 44.71779 | G2: 多次生產數 | H2: =COUNT(H5:H123) -> 0 | Y2: =SUM(Y21,Y38,Y55,Y72,Y89,Y106,Y123) -> 0 | Z2: =SUM(Z21,Z38,Z55,Z72,Z89,Z106,Z123) -> 0 | AC2: =SUM(AC21,AC38,AC55,AC72,AC89,AC106,AC123) -> 55 | AD2: =SUM(AD21,AD38,AD55,AD72,AD89,AD106,AD123) -> 0
A3: 線別 | B3: 品類 | C3: 品名 | E3: 廠價 | F3: 生產量 | G3: 營收 | H3: 多次 生產 | I3: 人數 | J3: 產能/時 | K3: 人時性 | L3: 人數 | M3: 產能/時 | N3: 人時性 | O3: 人數 | P3: 人時性 | Q3: 達成率 | R3: 達成率 平均 | S3: 生產時間 | U3: 換線、休息/分 | V3: 稼動時間/分 | W3: 休息時間 | Y3: 產線異常統計(5分鐘以上) | AA3: (屏榮回填) | AC3: 短暫停線統計(5分鐘以下) | AE3: 產能/時 | AF3: 達成率 | AG3: 達成率平均
S4: 開始 | T4: 結束 | W4: 開始 | X4: 結束 | Y4: 次數 | Z4: 時間/分 | AC4: 總次數 | AD4: 設備因素(次數)
A5: 便當二線 | B5: 微波主食 | C5: 糖燻野郎三十天熟成牛飯 | E5: 56.77 | F5: 2633 | G5: =E5*F5 -> 149475.41 | I5: 24 | J5: 2000 | K5: =J5/I5 -> 83.333333 | L5: 24 | M5: =F5/V5*60 -> 1788.2186 | N5: =M5/L5 -> 74.509106 | O5: =L5-I5 -> 0 | P5: =N5-K5 -> -8.824227 | Q5: =N5/K5 -> 0.89410928 | R5: =Q21 -> 0.89461375 | S5: 0.29166667 | T5: 0.35300926 | V5: 88.344906 | AC5: 3 | AE5: =M5-J5 -> -211.78145 | AF5: =M5/J5 -> 0.89410928 | AG5: =AF21 -> 0.89461375
B6: 便當 | C6: 健身G肉餐盒 | E6: 59.52 | F6: 3336 | G6: =E6*F6 -> 198558.72 | I6: 24 | J6: 2000 | K6: =J6/I6 -> 83.333333 | L6: 24 | M6: =F6/V6*60 -> 1790.1998 | N6: =M6/L6 -> 74.591657 | O6: =L6-I6 -> 0 | P6: =N6-K6 -> -8.7416765 | Q6: =N6/K6 -> 0.89509988 | S6: 0.35625 | T6: 0.43388889 | U6: 5 | V6: 111.80875 | W6: 0.43388889 | X6: 0.47222222 | AC6: 4 | AE6: =M6-J6 -> -209.80024 | AF6: =M6/J6 -> 0.89509988
B7: 便當 | C7: 嫩烤香料雞胸排蔬滿盒 | E7: 77.34 | F7: 1876 | G7: =E7*F7 -> 145089.84 | I7: 23 | J7: 2000 | K7: =J7/I7 -> 86.956522 | L7: 23 | M7: =F7/V7*60 -> 1789.2642 | N7: =M7/L7 -> 77.794094 | O7: =L7-I7 -> 0 | P7: =N7-K7 -> -9.1624273 | Q7: =N7/K7 -> 0.89463209 | S7: 0.47222222 | T7: 0.51590278 | U7: 55.2 | V7: 62.908542 | AC7: 2 | AE7: =M7-J7 -> -210.73583 | AF7: =M7/J7 -> 0.89463209
B21: 平均 | I21: =AVERAGE(I5:I20) -> 23.666667 | J21: =AVERAGE(J5:J20) -> 2000 | K21: =J21/I21 -> 84.507042 | L21: =AVERAGE(L5:L20) -> 23.666667 | M21: =AVERAGE(M5:M20) -> 1789.2275 | N21: =M21/L21 -> 75.601162 | O21: =L21-I21 -> 0 | P21: =N21-K21 -> -8.9058804 | Q21: =N21/K21 -> 0.89461375 | S21: =S5 -> 0.29166667 | T21: =INDEX(T5:T20,COUNTA(T5:T20)) -> 0.51590278 | Y21: =SUM(Y5:Y20) -> 0 | Z21: =SUM(Z5:Z20) -> 0 | AC21: =SUM(AC5:AC20) -> 9 | AD21: =SUM(AD5:AD20) -> 0 | AE21: =M21-J21 -> -210.7725 | AF21: =M21/J21 -> 0.89461375
A22: 涼麵一線 | B22: 便當 | C22: 香腸腿排雙拼便當 | E22: 53.76 | F22: 2520 | G22: =E22*F22 -> 135475.2 | I22: 20 | J22: 2000 | K22: =J22/I22 -> 100 | L22: 20 | M22: =F22/V22*60 -> 1787.0066 | N22: =M22/L22 -> 89.350328 | O22: =L22-I22 -> 0 | P22: =N22-K22 -> -10.649672 | Q22: =N22/K22 -> 0.89350328 | R22: =Q38 -> 0.8979034 | S22: 0.29166667 | T22: 0.35041667 | V22: 84.61077 | AC22: 3 | AE22: =M22-J22 -> -212.99345 | AF22: =M22/J22 -> 0.89350328 | AG22: =AF38 -> 0.90629502
B23: 便當 | C23: 經典滷肉飯 | E23: 47.37 | F23: 1281 | G23: =E23*F23 -> 60680.97 | I23: 21 | J23: 2000 | K23: =J23/I23 -> 95.238095 | L23: 21 | M23: =F23/V23*60 -> 1787.8 | N23: =M23/L23 -> 85.133333 | O23: =L23-I23 -> 0 | P23: =N23-K23 -> -10.104762 | Q23: =N23/K23 -> 0.8939 | S23: 0.35416667 | T23: 0.3840162 | U23: 5.4 | V23: 42.991386 | AC23: 1 | AE23: =M23-J23 -> -212.2 | AF23: =M23/J23 -> 0.8939
B24: 便當 | C24: 海陸雙拼肉肉餐盒 | E24: 59.54 | F24: 1848 | G24: =E24*F24 -> 110029.92 | I24: 23 | J24: 2000 | K24: =J24/I24 -> 86.956522 | L24: 23 | M24: =F24/V24*60 -> 1790.4495 | N24: =M24/L24 -> 77.845629 | O24: =L24-I24 -> 0 | P24: =N24-K24 -> -9.1108927 | Q24: =N24/K24 -> 0.89522473 | S24: 0.38680556 | T24: 0.42980324 | U24: 5 | V24: 61.928584 | AC24: 2 | AE24: =M24-J24 -> -209.55053 | AF24: =M24/J24 -> 0.89522473
B25: 便當 | C25: 蔬活腿排補力餐盒 | E25: 71.55 | F25: 1650 | G25: =E25*F25 -> 118057.5 | I25: 22 | J25: 2000 | K25: =J25/I25 -> 90.909091 | L25: 22 | M25: =F25/V25*60 -> 1787.0327 | N25: =M25/L25 -> 81.228758 | O25: =L25-I25 -> 0 | P25: =N25-K25 -> -9.680333 | Q25: =N25/K25 -> 0.89351634 | S25: 0.43263889 | T25: 0.47109954 | U25: 5 | V25: 55.399099 | W25: 0.47109954 | X25: 0.50972222 | AC25: 2 | AE25: =M25-J25 -> -212.96732 | AF25: =M25/J25 -> 0.89351634
B26: 4℃-飯糰 | C26: 麻油雞飯糰 | E26: 29.97 | F26: 2303 | G26: =E26*F26 -> 69020.91 | I26: 21 | J26: 2790 | K26: =J26/I26 -> 132.85714 | L26: 22 | M26: =F26/V26*60 -> 2626.6346 | N26: =M26/L26 -> 119.39248 | O26: =L26-I26 -> 1 | P26: =N26-K26 -> -13.46466 | Q26: =N26/K26 -> 0.89865309 | S26: 0.50972222 | T26: 0.54625 | U26: 55.616667 | V26: 52.607241 | AC26: 1 | AE26: =M26-J26 -> -163.36538 | AF26: =M26/J26 -> 0.9414461
B38: 平均 | I38: =AVERAGE(I22:I37) -> 21.4 | J38: =AVERAGE(J22:J37) -> 2158 | K38: =J38/I38 -> 100.84112 | L38: =AVERAGE(L22:L37) -> 21.6 | M38: =AVERAGE(M22:M37) -> 1955.7847 | N38: =M38/L38 -> 90.545586 | O38: =L38-I38 -> 0.2 | P38: =N38-K38 -> -10.295535 | Q38: =N38/K38 -> 0.8979034 | S38: =S22 -> 0.29166667 | T38: =INDEX(T22:T37,COUNTA(T22:T37)) -> 0.54625 | Y38: =SUM(Y22:Y37) -> 0 | Z38: =SUM(Z22:Z37) -> 0 | AC38: =SUM(AC22:AC37) -> 9 | AD38: =SUM(AD22:AD37) -> 0 | AE38: =M38-J38 -> -202.21534 | AF38: =M38/J38 -> 0.90629502
A39: 涼麵二線 | B39: 微波小吃 | C39: 日式茶碗蒸 | E39: 19.7 | F39: 3423 | G39: =E39*F39 -> 67433.1 | I39: 13 | J39: 1200 | K39: =J39/I39 -> 92.307692 | L39: 13 | M39: =F39/V39*60 -> 1080.3619 | N39: =M39/L39 -> 83.104762 | O39: =L39-I39 -> 0 | P39: =N39-K39 -> -9.20293 | Q39: =N39/K39 -> 0.90030159 | R39: =Q55 -> 0.89524273 | S39: 0.29166667 | T39: 0.42368056 | V39: 190.10296 | AC39: 5 | AE39: =M39-J39 -> -119.63809 | AF39: =M39/J39 -> 0.90030159 | AG39: =AF55 -> 0.89524273
B40: 便當 | C40: 香檸奶油魚排蔬滿盒 | E40: 77.35 | F40: 1210 | G40: =E40*F40 -> 93593.5 | I40: 26 | J40: 2000 | K40: =J40/I40 -> 76.923077 | L40: 26 | M40: =F40/V40*60 -> 1791.1662 | N40: =M40/L40 -> 68.891008 | O40: =L40-I40 -> 0 | P40: =N40-K40 -> -8.0320691 | Q40: =N40/K40 -> 0.8955831 | S40: 0.42708333 | T40: 0.45521991 | U40: 4.9 | V40: 40.532252 | AC40: 1 | AE40: =M40-J40 -> -208.8338 | AF40: =M40/J40 -> 0.8955831
B41: 便當 | C41: 美式雞丁餐盒 | E41: 59.34 | F41: 1181 | G41: =E41*F41 -> 70080.54 | I41: 24 | J41: 2000 | K41: =J41/I41 -> 83.333333 | L41: 24 | M41: =F41/V41*60 -> 1787.2165 | N41: =M41/L41 -> 74.467354 | O41: =L41-I41 -> 0 | P41: =N41-K41 -> -8.8659794 | Q41: =N41/K41 -> 0.89360825 | S41: 0.45902778 | T41: 0.48655093 | U41: 5.4833333 | V41: 39.648246 | W41: 0.48655093 | X41: 0.525 | AC41: 2 | AE41: =M41-J41 -> -212.7835 | AF41: =M41/J41 -> 0.89360825
B42: 便當 | C42: 烤蛋白餐盒 | E42: 58.67 | F42: 2624 | G42: =E42*F42 -> 153950.08 | I42: 23 | J42: 2000 | K42: =J42/I42 -> 86.956522 | L42: 23 | M42: =F42/V42*60 -> 1787.0031 | N42: =M42/L42 -> 77.695786 | O42: =L42-I42 -> 0 | P42: =N42-K42 -> -9.2607356 | Q42: =N42/K42 -> 0.89350154 | S42: 0.525 | T42: 0.58618056 | U42: 55.366667 | V42: 88.102814 | AC42: 3 | AE42: =M42-J42 -> -212.99692 | AF42: =M42/J42 -> 0.89350154
B55: 平均 | I55: =AVERAGE(I39:I54) -> 21.5 | J55: =AVERAGE(J39:J54) -> 1800 | K55: =J55/I55 -> 83.72093 | L55: =AVERAGE(L39:L54) -> 21.5 | M55: =AVERAGE(M39:M54) -> 1611.4369 | N55: =M55/L55 -> 74.950555 | O55: =L55-I55 -> 0 | P55: =N55-K55 -> -8.7703757 | Q55: =N55/K55 -> 0.89524273 | S55: =S39 -> 0.29166667 | T55: =INDEX(T39:T54,COUNTA(T39:T54)) -> 0.58618056 | Y55: =SUM(Y39:Y54) -> 0 | Z55: =SUM(Z39:Z54) -> 0 | AC55: =SUM(AC39:AC54) -> 11 | AD55: =SUM(AD39:AD54) -> 0 | AE55: =M55-J55 -> -188.56308 | AF55: =M55/J55 -> 0.89524273
A56: 涼麵三線 | B56: 季節調理麵 | C56: 和風涓絲冷麵 | E56: 28.86 | F56: 2502 | G56: =E56*F56 -> 72207.72 | I56: 19 | J56: 3600 | K56: =J56/I56 -> 189.47368 | L56: 19 | M56: =F56/V56*60 -> 3171.7071 | N56: =M56/L56 -> 166.93195 | O56: =L56-I56 -> 0 | P56: =N56-K56 -> -22.54173 | Q56: =N56/K56 -> 0.88102976 | R56: =Q72 -> 0.88598443 | S56: 0.25 | T56: 0.2828588 | V56: 47.330978 | AC56: 1 | AE56: =M56-J56 -> -428.29287 | AF56: =M56/J56 -> 0.88102976 | AG56: =AF72 -> 0.88598443
B57: 季節調理麵 | C57: 台式麻醬涼麵 | E57: 31.11 | F57: 2684 | G57: =E57*F57 -> 83499.24 | I57: 19 | J57: 3600 | K57: =J57/I57 -> 189.47368 | L57: 19 | M57: =F57/V57*60 -> 3170.7442 | N57: =M57/L57 -> 166.88127 | O57: =L57-I57 -> 0 | P57: =N57-K57 -> -22.592411 | Q57: =N57/K57 -> 0.88076227 | S57: 0.28611111 | T57: 0.32137731 | U57: 4.6833333 | V57: 50.789339 | AC57: 1 | AE57: =M57-J57 -> -429.25581 | AF57: =M57/J57 -> 0.88076227
B58: 季節調理麵 | C58: 鰹魚烏龍冷麵 | E58: 38.99 | F58: 3956 | G58: =E58*F58 -> 154244.44 | I58: 19 | J58: 3600 | K58: =J58/I58 -> 189.47368 | L58: 19 | M58: =F58/V58*60 -> 3089.6543 | N58: =M58/L58 -> 162.61339 | O58: =L58-I58 -> 0 | P58: =N58-K58 -> -26.860298 | Q58: =N58/K58 -> 0.85823731 | S58: 0.32430556 | T58: 0.37765046 | U58: 5 | V58: 76.824128 | AC58: 4 | AE58: =M58-J58 -> -510.34567 | AF58: =M58/J58 -> 0.85823731
B59: 季節調理麵 | C59: 大滿足香辣涼麵 | E59: 38.48 | F59: 3586 | G59: =E59*F59 -> 137989.28 | I59: 20 | J59: 3600 | K59: =J59/I59 -> 180 | L59: 20 | M59: =F59/V59*60 -> 3257.05 | N59: =M59/L59 -> 162.8525 | O59: =L59-I59 -> 0 | P59: =N59-K59 -> -17.147498 | Q59: =N59/K59 -> 0.90473612 | S59: 0.38055556 | T59: 0.42642361 | U59: 5 | V59: 66.059777 | W59: 0.42642361 | X59: 0.46597222 | AC59: 2 | AE59: =M59-J59 -> -342.94995 | AF59: =M59/J59 -> 0.90473612
B60: 季節調理麵 | C60: 大滿足麻醬涼麵 | E60: 37.8 | F60: 4392 | G60: =E60*F60 -> 166017.6 | I60: 21 | J60: 3600 | K60: =J60/I60 -> 171.42857 | L60: 21 | M60: =F60/V60*60 -> 3258.564 | N60: =M60/L60 -> 155.16971 | O60: =L60-I60 -> 0 | P60: =N60-K60 -> -16.258859 | Q60: =N60/K60 -> 0.90515666 | S60: 0.46597222 | T60: 0.52212963 | U60: 56.95 | V60: 80.869979 | AC60: 3 | AE60: =M60-J60 -> -341.43604 | AF60: =M60/J60 -> 0.90515666
B72: 平均 | I72: =AVERAGE(I56:I71) -> 19.6 | J72: =AVERAGE(J56:J71) -> 3600 | K72: =J72/I72 -> 183.67347 | L72: =AVERAGE(L56:L71) -> 19.6 | M72: =AVERAGE(M56:M71) -> 3189.5439 | N72: =M72/L72 -> 162.73183 | O72: =L72-I72 -> 0 | P72: =N72-K72 -> -20.941636 | Q72: =N72/K72 -> 0.88598443 | S72: =S56 -> 0.25 | T72: =INDEX(T56:T71,COUNTA(T56:T71)) -> 0.52212963 | Y72: =SUM(Y56:Y71) -> 0 | Z72: =SUM(Z56:Z71) -> 0 | AC72: =SUM(AC56:AC71) -> 11 | AD72: =SUM(AD56:AD71) -> 0 | AE72: =M72-J72 -> -410.45607 | AF72: =M72/J72 -> 0.88598443
A73: 自動包裝機3 | B73: 4℃-飯糰 | C73: 蟹味可樂餅風炸飯糰 | E73: 21.92 | F73: 706 | G73: =E73*F73 -> 15475.52 | I73: 6 | J73: 3600 | K73: =J73/I73 -> 600 | L73: 6 | M73: =F73/V73*60 -> 3255.9408 | N73: =M73/L73 -> 542.6568 | O73: =L73-I73 -> 0 | P73: =N73-K73 -> -57.343201 | Q73: =N73/K73 -> 0.904428 | R73: =Q89 -> 0.8973862 | S73: 0.29166667 | T73: 0.30069444 | V73: 13.010065 | AC73: 1 | AE73: =M73-J73 -> -344.05921 | AF73: =M73/J73 -> 0.904428 | AG73: =AF89 -> 0.8973862
B74: 4℃-壽司手卷 | C74: 元氣三重稻荷組 | E74: 30.36 | F74: 1137 | G74: =E74*F74 -> 34519.32 | I74: 11 | J74: 3000 | K74: =J74/I74 -> 272.72727 | L74: 11 | M74: =F74/V74*60 -> 2653.018 | N74: =M74/L74 -> 241.18346 | O74: =L74-I74 -> 0 | P74: =N74-K74 -> -31.543817 | Q74: =N74/K74 -> 0.88433934 | S74: 0.30416667 | T74: 0.32201389 | U74: 5 | V74: 25.714111 | AC74: 2 | AE74: =M74-J74 -> -346.98199 | AF74: =M74/J74 -> 0.88433934
B75: 4℃-壽司手卷 | C75: 山葵生鮪魚泥脆卷 | E75: 23.19 | F75: 980 | G75: =E75*F75 -> 22726.2 | I75: 6 | J75: 2500 | K75: =J75/I75 -> 416.66667 | L75: 6 | M75: =F75/V75*60 -> 2250.1519 | N75: =M75/L75 -> 375.02531 | O75: =L75-I75 -> 0 | P75: =N75-K75 -> -41.641353 | Q75: =N75/K75 -> 0.90006075 | S75: 0.325 | T75: 0.34313657 | U75: 5 | V75: 26.131569 | AC75: 1 | AE75: =M75-J75 -> -249.84812 | AF75: =M75/J75 -> 0.90006075
B76: 4℃-壽司手卷 | C76: 醬油生鮭脆卷 | E76: 23.55 | F76: 1988 | G76: =E76*F76 -> 46817.4 | I76: 6 | J76: 2500 | K76: =J76/I76 -> 416.66667 | L76: 6 | M76: =F76/V76*60 -> 2250.5692 | N76: =M76/L76 -> 375.09487 | O76: =L76-I76 -> 0 | P76: =N76-K76 -> -41.571801 | Q76: =N76/K76 -> 0.90022768 | S76: 0.34722222 | T76: 0.3840162 | U76: 5.8833333 | V76: 52.999926 | AC76: 2 | AE76: =M76-J76 -> -249.43081 | AF76: =M76/J76 -> 0.90022768
B89: 平均 | I89: =AVERAGE(I73:I88) -> 7.25 | J89: =AVERAGE(J73:J88) -> 2900 | K89: =J89/I89 -> 400 | L89: =AVERAGE(L73:L88) -> 7.25 | M89: =AVERAGE(M73:M88) -> 2602.42 | N89: =M89/L89 -> 358.95448 | O89: =L89-I89 -> 0 | P89: =N89-K89 -> -41.045521 | Q89: =N89/K89 -> 0.8973862 | S89: =S73 -> 0.29166667 | T89: =INDEX(T73:T88,COUNTA(T73:T88)) -> 0.3840162 | Y89: =SUM(Y73:Y88) -> 0 | Z89: =SUM(Z73:Z88) -> 0 | AC89: =SUM(AC73:AC88) -> 6 | AD89: =SUM(AD73:AD88) -> 0 | AE89: =M89-J89 -> -297.58003 | AF89: =M89/J89 -> 0.8973862
A90: 便當二線 (二配) | B90: 微波主食 | C90: 二配鐵板豆腐燴蛋蓋飯 | E90: 44.98 | F90: 1369 | G90: =E90*F90 -> 61577.62 | I90: 21 | J90: 1800 | K90: =J90/I90 -> 85.714286 | L90: 21 | M90: =F90/V90*60 -> 1606.3751 | N90: =M90/L90 -> 76.494051 | O90: =L90-I90 -> 0 | P90: =N90-K90 -> -9.220235 | Q90: =N90/K90 -> 0.89243059 | R90: =Q106 -> 0.92432562 | S90: 0.70833333 | T90: 0.74384259 | V90: 51.133762 | AC90: 1 | AE90: =M90-J90 -> -193.62494 | AF90: =M90/J90 -> 0.89243059 | AG90: =AF106 -> 0.89351477
B91: 微波主食 | C91: 二配哞哞培根奶香海陸焗飯 | E91: 47.6 | F91: 1288 | G91: =E91*F91 -> 61308.8 | I91: 23 | J91: 2000 | K91: =J91/I91 -> 86.956522 | L91: 22 | M91: =F91/V91*60 -> 1786.2552 | N91: =M91/L91 -> 81.19342 | O91: =L91-I91 -> -1 | P91: =N91-K91 -> -5.7631013 | Q91: =N91/K91 -> 0.93372433 | S91: 0.74791667 | T91: 0.77795139 | U91: 5.8666667 | V91: 43.263694 | AC91: 1 | AE91: =M91-J91 -> -213.74475 | AF91: =M91/J91 -> 0.89312762
B92: 微波主食 | C92: 二配黃金雞排蘑菇白醬歐姆蛋飯 | E92: 56.87 | F92: 1082 | G92: =E92*F92 -> 61533.34 | I92: 23 | J92: 2000 | K92: =J92/I92 -> 86.956522 | L92: 22 | M92: =F92/V92*60 -> 1787.4213 | N92: =M92/L92 -> 81.246423 | O92: =L92-I92 -> -1 | P92: =N92-K92 -> -5.7100992 | Q92: =N92/K92 -> 0.93433386 | S92: 0.78125 | T92: 0.80646991 | U92: 4.75 | V92: 36.32048 | AC92: 1 | AE92: =M92-J92 -> -212.5787 | AF92: =M92/J92 -> 0.89371065
B93: 微波主食 | C93: 二配里肌豬排可可咖哩歐姆蛋飯 | E93: 56.79 | F93: 1387 | G93: =E93*F93 -> 78767.73 | I93: 23 | J93: 2000 | K93: =J93/I93 -> 86.956522 | L93: 22 | M93: =F93/V93*60 -> 1789.3636 | N93: =M93/L93 -> 81.334709 | O93: =L93-I93 -> -1 | P93: =N93-K93 -> -5.6218128 | Q93: =N93/K93 -> 0.93534915 | S93: 0.81041667 | T93: 0.84270833 | U93: 5.6833333 | V93: 46.508155 | AC93: 1 | AE93: =M93-J93 -> -210.6364 | AF93: =M93/J93 -> 0.8946818
B106: 平均 | I106: =AVERAGE(I90:I105) -> 22.5 | J106: =AVERAGE(J90:J105) -> 1950 | K106: =J106/I106 -> 86.666667 | L106: =AVERAGE(L90:L105) -> 21.75 | M106: =AVERAGE(M90:M105) -> 1742.3538 | N106: =M106/L106 -> 80.108221 | O106: =L106-I106 -> -0.75 | P106: =N106-K106 -> -6.5584459 | Q106: =N106/K106 -> 0.92432562 | S106: =S90 -> 0.70833333 | T106: =INDEX(T90:T105,COUNTA(T90:T105)) -> 0.84270833 | Y106: =SUM(Y90:Y105) -> 0 | Z106: =SUM(Z90:Z105) -> 0 | AC106: =SUM(AC90:AC105) -> 4 | AD106: =SUM(AD90:AD105) -> 0 | AE106: =M106-J106 -> -207.6462 | AF106: =M106/J106 -> 0.89351477
A107: 涼麵一線 (二配) | B107: 微波主食 | C107: 二配濃起司燻腸紅醬焗烤飯 | E107: 50.67 | F107: 1284 | G107: =E107*F107 -> 65060.28 | I107: 20 | J107: 2000 | K107: =J107/I107 -> 100 | L107: 20 | M107: =F107/V107*60 -> 1788.8048 | N107: =M107/L107 -> 89.440242 | O107: =L107-I107 -> 0 | P107: =N107-K107 -> -10.559758 | Q107: =N107/K107 -> 0.89440242 | R107: =Q123 -> 0.87778279 | S107: 0.70833333 | T107: 0.73824074 | V107: 43.067862 | AC107: 1 | AE107: =M107-J107 -> -211.19516 | AF107: =M107/J107 -> 0.89440242 | AG107: =AF123 -> 0.89374248
B108: 微波主食 | C108: 二配失控起司薯餅焗飯 | E108: 54.09 | F108: 681 | G108: =E108*F108 -> 36835.29 | I108: 19 | J108: 2000 | K108: =J108/I108 -> 105.26316 | L108: 20 | M108: =F108/V108*60 -> 1786 | N108: =M108/L108 -> 89.3 | O108: =L108-I108 -> 1 | P108: =N108-K108 -> -15.963158 | Q108: =N108/K108 -> 0.84835 | S108: 0.74236111 | T108: 0.75824074 | U108: 5.9333333 | V108: 22.87794 | AC108: 1 | AE108: =M108-J108 -> -214 | AF108: =M108/J108 -> 0.893
B109: 微波主食 | C109: 二配打拋風味豆腐飯 | E109: 38.39 | F109: 2324 | G109: =E109*F109 -> 89218.36 | I109: 16 | J109: 2000 | K109: =J109/I109 -> 125 | L109: 16 | M109: =F109/V109*60 -> 1787.65 | N109: =M109/L109 -> 111.72813 | O109: =L109-I109 -> 0 | P109: =N109-K109 -> -13.271872 | Q109: =N109/K109 -> 0.89382502 | S109: 0.76111111 | T109: 0.81527778 | U109: 5 | V109: 78.001844 | AC109: 3 | AE109: =M109-J109 -> -212.34995 | AF109: =M109/J109 -> 0.89382502
B123: 平均 | I123: =AVERAGE(I107:I122) -> 18.333333 | J123: =AVERAGE(J107:J122) -> 2000 | K123: =J123/I123 -> 109.09091 | L123: =AVERAGE(L107:L122) -> 18.666667 | M123: =AVERAGE(M107:M122) -> 1787.485 | N123: =M123/L123 -> 95.758123 | O123: =L123-I123 -> 0.33333333 | P123: =N123-K123 -> -13.332786 | Q123: =N123/K123 -> 0.87778279 | S123: =S107 -> 0.70833333 | T123: =INDEX(T107:T122,COUNTA(T107:T122)) -> 0.81527778 | Y123: =SUM(Y107:Y122) -> 0 | Z123: =SUM(Z107:Z122) -> 0 | AC123: =SUM(AC107:AC122) -> 5 | AD123: =SUM(AD107:AD122) -> 0 | AE123: =M123-J123 -> -212.51504 | AF123: =M123/J123 -> 0.89374248
AA125: 原因回覆
...

Sheet 0429
B1: 屏榮 大溪廠組合室生產人時性分析
B3: 日期 | C3: 115.04.29星期三 | E3: 訂單量 | F3: ='0429(18度C)'!D1+'0429(4度C)'!D1 -> 189446 | H3: 營業額 | I3: ='0429(18度C)'!F1+'0429(4度C)'!F1 -> 5586966.6
B4: 人時性 | C4: 項目 | E4: ➀ | G4: ➁ | I4: ➂ | K4: ④ | M4: ⑤ | O4: 異常停線 | Q4: 短暫停線
C5: 組合室 | E5: 全溫層 | G5: 4度C-各編組展開(一配) | I5: 4度C-各編組展開(二配) | K5: 18度C-各編組展開(一配) | M5: 18度C-各編組展開(二配) | O5: 合計次數 | P5: 時間 | Q5: 合計次數 | R5: 設備次數
C6: 排關平均 | E6: =AVERAGE(D14:O14,D32:X32) -> 448.12977 | F6: =AVERAGE(#REF!,D14:K14) -> #REF! | G6: =AVERAGE(D14:K14) -> 170.54851 | I6: =AVERAGE(L14:O14) -> 93.920572 | K6: =AVERAGE(D32:O32) -> 718.21912 | M6: =AVERAGE(P32:X32) -> 723.15154 | O6: ='0429(4度C)'!Y2 -> 0 | P6: ='0429(4度C)'!Z2 -> 0 | Q6: ='0429(4度C)'!AC2 -> 59 | R6: ='0429(4度C)'!AD2 -> 0
C7: 實績平均 | E7: =AVERAGE(D15:O15,D33:X33) -> 399.78289 | F7: =AVERAGE(#REF!,D15:K15) -> #REF! | G7: =AVERAGE(D15:K15) -> 152.382 | I7: =AVERAGE(L15:O15) -> 83.293561 | K7: =AVERAGE(D33:O33) -> 641.06803 | M7: =AVERAGE(P33:X33) -> 644.79455
C8: 達成率平均 | E8: =AVERAGE(D16:O16,D34:X34) -> 0.89118769 | F8: =AVERAGE(D16:K16,#REF!) -> #REF! | G8: =AVERAGE(D16:K16) -> 0.89309598 | I8: =AVERAGE(L16:O16) -> 0.88768793 | K8: =AVERAGE(D34:O34) -> 0.89060325 | M8: =AVERAGE(P34:X34) -> 0.8921577
O9: ※現行日本鮮食廠以達成率80%為基本(即為現行KPI)
B11: 溫層 | D11: ➁4度C-各編組展開 | L11: ➂4度C-各編組展開
B12: 編組 | D12: 1 | E12: 2 | F12: 3 | G12: 4 | H12: 5 | I12: 6 | J12: 7 | K12: 8 | L12: 1 | M12: 2 | N12: 3 | O12: 4
D13: 便當一線 | E13: 便當二線 | F13: 涼麵一線 | G13: 涼麵二線 | H13: 涼麵三線 | I13: 自動包裝機 | J13: 自動包裝機2 | K13: 自動包裝機3 | L13: 便當一線 | M13: 便當二線 | N13: 涼麵一線 | O13: 涼麵二線
B14: 人時性 | C14: 排關 | D14: - | E14: 84.507042 | F14: 100.84112 | G14: 83.72093 | H14: 183.67347 | I14: - | J14: - | K14: 400 | L14: - | M14: 85.714286 | N14: 109.09091 | O14: 86.956522
C15: 實績 | D15: - | E15: 75.496091 | F15: 90.532623 | G15: 74.923275 | H15: 162.00771 | I15: - | J15: - | K15: 358.95031 | L15: - | M15: 76.421541 | N15: 95.700425 | O15: 77.758718
C16: 達成率 | D16: - | E16: =E15/E14 -> 0.89337041 | F16: =F15/F14 -> 0.89777486 | G16: =G15/G14 -> 0.8949169 | H16: =H15/H14 -> 0.88204196 | I16: - | J16: - | K16: =K15/K14 -> 0.89737578 | L16: - | M16: =M15/M14 -> 0.89158465 | N16: =N15/N14 -> 0.87725389 | O16: =O15/O14 -> 0.89422526
B17: 作業 時間 | C17: 開始 | D17: - | E17: 0.29166667 | F17: 0.25 | G17: 0.25 | H17: 0.25 | I17: - | J17: - | K17: 0.29166667 | L17: - | M17: 0.70833333 | N17: 0.70833333 | O17: 0.70833333
C18: 結束 | D18: - | E18: 0.56894676 | F18: 0.56069444 | G18: 0.5755787 | H18: 0.55003472 | I18: - | J18: - | K18: 0.41274306 | L18: - | M18: 0.74828704 | N18: 0.82892361 | O18: 0.81357639
B19: 產線異常 (5分鐘以上) | C19: 次數
C20: 時間/分
B21: 短暫停線 (5分鐘以下) | C21: 次數 | E21: 10 | F21: 11 | G21: 10 | H21: 9 | K21: 6 | M21: 2 | N21: 7 | O21: 4
C22: 設備次數
B23: 配置人數 | D23: - | E23: 23.666667 | F23: 21.6 | G23: 21.5 | H23: 19.6 | I23: - | J23: - | K23: 7.25 | L23: - | M23: 21 | N23: 18.666667 | O23: 23
B24: 主要應用設備 | D24: L型封口機 | E24: ET-55 | F24: ET-55 | G24: ET-55 | H24: ET-600 | I24: 伺服包裝機 | J24: 伺服包裝機 | K24: 伺服包裝機 | L24: L型封口機 | M24: ET-55 | N24: ET-55 | O24: ET-55
B25: 次要應用設備 | D25: 伺服包裝機 | H25: 伺服包裝機
B26: 備註 | H26: 涼麵+烤飯糰 | I26: 大口飯糰線 | K26: 烤飯糰+手卷
B29: 溫層 | D29: ➃18度C-各編組展開 (一配) | P29: ⑤18度C-各編組展開 (二配)
B30: 編組 | D30: 1 | E30: 2 | F30: 3 | G30: 4 | H30: 5 | I30: 6 | J30: 7 | K30: 8 | L30: 9 | M30: 10 | N30: 11 | O30: 12 | P30: 1 | Q30: 2 | R30: 3 | S30: 4 | T30: 5 | U30: 6 | V30: 7 | W30: 8 | X30: 9
D31: 便當一線 | E31: 涼麵一線 | F31: 涼麵三線 | G31: 自動包裝機 | H31: 自動包裝機2 | I31: 自動包裝機3 | J31: 味付飯糰線B | K31: (舊) 3300型飯糰線 | L31: 3000型飯糰線 | M31: (新) 3300型飯糰機 | N31: GKK3600型 飯糰機 | O31: GKK3600型 飯糰機2 | P31: 自動包裝機 | Q31: 自動包裝機2 | R31: 自動包裝機3 | S31: 味付飯糰線B | T31: (舊) 3300型飯糰線 | U31: 3000型飯糰線 | V31: (新) 3300型飯糰機 | W31: GKK3600型 飯糰機 | X31: GKK3600型 飯糰機2
B32: 人時性 | C32: 排關 | D32: - | E32: - | F32: - | G32: 306.38298 | H32: 433.33333 | I32: - | J32: - | K32: - | L32: - | M32: 1100 | N32: 941.37931 | O32: 810 | P32: 291.89189 | Q32: - | R32: - | S32: - | T32: - | U32: - | V32: 775 | W32: 985.71429 | X32: 840
C33: 實績 | D33: - | E33: - | F33: - | G33: 268.50302 | H33: 389.92015 | I33: - | J33: - | K33: - | L33: - | M33: 993.24422 | N33: 837.08635 | O33: 716.58642 | P33: 260.76241 | Q33: - | R33: - | S33: - | T33: - | U33: - | V33: 696.26295 | W33: 876.55991 | X33: 745.59292
C34: 達成率 | D34: - | E34: - | F34: - | G34: =G33/G32 -> 0.87636403 | H34: =H33/H32 -> 0.89981573 | I34: - | J34: - | K34: - | L34: - | M34: =M33/M32 -> 0.90294929 | N34: =N33/N32 -> 0.88921261 | O34: =O33/O32 -> 0.88467459 | P34: =P33/P32 -> 0.8933527 | Q34: - | R34: - | S34: - | T34: - | U34: - | V34: =V33/V32 -> 0.89840381 | W34: =W33/W32 -> 0.88926368 | X34: =X33/X32 -> 0.88761062
B35: 作業 時間 | C35: 開始 | D35: - | E35: - | F35: - | G35: 0.29166667 | H35: 0.29166667 | I35: - | J35: - | K35: - | L35: - | M35: 0.35416667 | N35: 0.25 | O35: 0.25 | P35: 0.70833333 | Q35: - | R35: - | S35: - | T35: - | U35: - | V35: 0.70833333 | W35: 0.70833333 | X35: 0.70833333
C36: 結束 | D36: - | E36: - | F36: - | G36: 0.45509259 | H36: 0.32923611 | I36: - | J36: - | K36: - | L36: - | M36: 0.40040509 | N36: 0.64965278 | O36: 0.64619213 | P36: 0.75263889 | Q36: - | R36: - | S36: - | T36: - | U36: - | V36: 0.80289352 | W36: 1.1537153 | X36: 1.1288079
B37: 配置人數 | D37: - | E37: - | F37: - | G37: 11.75 | H37: 6 | I37: - | J37: - | K37: - | L37: - | M37: 3 | N37: 3.625 | O37: 4.4444444 | P37: 12.333333 | Q37: - | R37: - | S37: - | T37: - | U37: - | V37: 4 | W37: 3.5 | X37: 4.1666667
B38: 主要應用設備 | D38: 伺服包裝機 | E38: ET-55 | F38: ET-600 | G38: 夾心型 | H38: 伺服包裝機 | I38: 伺服包裝機 | J38: 夾心型 | K38: 3300型 | L38: 3300型 | M38: 3300型 | N38: GKK | O38: GKK | P38: 夾心型 | Q38: 伺服包裝機 | R38: 伺服包裝機 | S38: 夾心型 | T38: 3300型 | U38: 3300型 | V38: 3300型 | W38: GKK | X38: GKK
B39: 次要應用設備
B40: 備註

Sheet 0429(18度C)
A1: 大溪廠日報分析 | C1: 總生產量 | D1: =SUM(F5:F157) -> 121339 | E1: 營業額 | F1: =SUM(G5:G157) -> 2478860.3 | G1: 出勤人數 | H1: =L21+L38+L55+L72+L89+L106+L123+L140+L157 -> 52.819444 | I1: 產線配置圖 | L1: 生產實績 | O1: 人時性差異分析 | S1: 日報登錄 | Y1: 分析說明 | AA1: 產能差異分析
A2: 46141 | C2: 人時性 | D2: =AVERAGE(N21,N38,N55,N72,N89,N106,N123,N140,N157) -> 642.72426 | E2: 平均廠價 | F2: =F1/D1 -> 20.429213 | G2: 多次生產數 | H2: =COUNT(H5:H157) -> 16
A3: 線別 | B3: 品類 | C3: 品名 | E3: 廠價 | F3: 生產量 | G3: 營收 | H3: 多次 生產 | I3: 人數 | J3: 產能/時 | K3: 人時性 | L3: 人數 | M3: 產能/時 | N3: 人時性 | O3: 人數 | P3: 人時性 | Q3: 達成率 | R3: 達成率 平均 | S3: 生產時間 | U3: 換線、休息/分 | V3: 稼動時間/分 | W3: 休息時間 | Y3: (屏榮回填) | AA3: 產能/時 | AB3: 達成率 | AC3: 達成率平均
S4: 開始 | T4: 結束 | W4: 開始 | X4: 結束
A5: 自動包裝機 | B5: 18℃-壽司手卷 | C5: 一配長野稻荷壽司 | E5: 25.64 | F5: 1572 | G5: =E5*F5 -> 40306.08 | I5: 11 | J5: 3600 | K5: =J5/I5 -> 327.27273 | L5: 11 | M5: =F5/V5*60 -> 3181.6357 | N5: =M5/L5 -> 289.23961 | O5: =L5-I5 -> 0 | P5: =N5-K5 -> -38.033114 | Q5: =N5/K5 -> 0.88378771 | R5: =Q21 -> 0.87636403 | S5: 0.29166667 | T5: 0.31224537 | V5: 29.645128 | AA5: =M5-J5 -> -418.36425 | AB5: =M5/J5 -> 0.88378771 | AC5: =AB21 -> 0.87636403
B6: 18℃-壽司手卷 | C6: 一配經典人氣雙手卷 | E6: 29.52 | F6: 3305 | G6: =E6*F6 -> 97563.6 | I6: 12 | J6: 3600 | K6: =J6/I6 -> 300 | L6: 12 | M6: =F6/V6*60 -> 3158.3817 | N6: =M6/L6 -> 263.19848 | O6: =L6-I6 -> 0 | P6: =N6-K6 -> -36.801522 | Q6: =N6/K6 -> 0.87732826 | S6: 0.31597222 | T6: 0.35957176 | U6: 5.3666667 | V6: 62.785318 | AA6: =M6-J6 -> -441.61827 | AB6: =M6/J6 -> 0.87732826
B7: 18℃-壽司手卷 | C7: 一配鮭鮪海饌雙手卷 | E7: 29.85 | F7: 3657 | G7: =E7*F7 -> 109161.45 | I7: 12 | J7: 3600 | K7: =J7/I7 -> 300 | L7: 12 | M7: =F7/V7*60 -> 3157.5698 | N7: =M7/L7 -> 263.13082 | O7: =L7-I7 -> 0 | P7: =N7-K7 -> -36.869182 | Q7: =N7/K7 -> 0.87710273 | S7: 0.36319444 | T7: 0.41144676 | U7: 5.2166667 | V7: 69.49015 | AA7: =M7-J7 -> -442.43018 | AB7: =M7/J7 -> 0.87710273
B8: 18℃-飯糰 | C8: 一配兩粒飯糰(鮪魚.焦糖鮭魚) | E8: 28.57 | F8: 2984 | G8: =E8*F8 -> 85252.88 | I8: 12 | J8: 3600 | K8: =J8/I8 -> 300 | L8: 12 | M8: =F8/V8*60 -> 3122.0547 | N8: =M8/L8 -> 260.17123 | O8: =L8-I8 -> 0 | P8: =N8-K8 -> -39.828771 | Q8: =N8/K8 -> 0.86723743 | S8: 0.41527778 | T8: 0.45509259 | U8: 5.5166667 | V8: 57.346848 | AA8: =M8-J8 -> -477.94525 | AB8: =M8/J8 -> 0.86723743
B21: 平均 | I21: =AVERAGE(I5:I20) -> 11.75 | J21: =AVERAGE(J5:J20) -> 3600 | K21: =J21/I21 -> 306.38298 | L21: =AVERAGE(L5:L20) -> 11.75 | M21: =AVERAGE(M5:M20) -> 3154.9105 | N21: =M21/L21 -> 268.50302 | O21: =L21-I21 -> 0 | P21: =N21-K21 -> -37.879957 | Q21: =N21/K21 -> 0.87636403 | S21: 0.29166667 | T21: 0.45509259 | AA21: =M21-J21 -> -445.08949 | AB21: =M21/J21 -> 0.87636403
A22: 自動包裝機2 | B22: 18℃-壽司手卷 | C22: 一配雙鬆細卷 | E22: 14.03 | F22: 858 | G22: =E22*F22 -> 12037.74 | I22: 6 | J22: 2600 | K22: =J22/I22 -> 433.33333 | L22: 6 | M22: =F22/V22*60 -> 2339.169 | N22: =M22/L22 -> 389.8615 | O22: =L22-I22 -> 0 | P22: =N22-K22 -> -43.471831 | Q22: =N22/K22 -> 0.89968039 | R22: =Q38 -> 0.89981573 | S22: 0.29166667 | T22: 0.30694444 | V22: 22.007815 | AA22: =M22-J22 -> -260.83099 | AB22: =M22/J22 -> 0.89968039 | AC22: =AB38 -> 0.89981573
B23: 18℃-壽司手卷 | C23: 一配經典鮪魚沙拉細卷 | E23: 14.49 | F23: 1018 | G23: =E23*F23 -> 14750.82 | I23: 6 | J23: 2600 | K23: =J23/I23 -> 433.33333 | L23: 6 | M23: =F23/V23*60 -> 2339.8728 | N23: =M23/L23 -> 389.9788 | O23: =L23-I23 -> 0 | P23: =N23-K23 -> -43.354536 | Q23: =N23/K23 -> 0.89995107 | S23: 0.31111111 | T23: 0.32923611 | U23: 6 | V23: 26.103983 | AA23: =M23-J23 -> -260.12722 | AB23: =M23/J23 -> 0.89995107
B38: 平均 | I38: =AVERAGE(I22:I37) -> 6 | J38: =AVERAGE(J22:J37) -> 2600 | K38: =J38/I38 -> 433.33333 | L38: =AVERAGE(L22:L37) -> 6 | M38: =AVERAGE(M22:M37) -> 2339.5209 | N38: =M38/L38 -> 389.92015 | O38: =L38-I38 -> 0 | P38: =N38-K38 -> -43.413184 | Q38: =N38/K38 -> 0.89981573 | S38: 0.29166667 | T38: 0.32923611 | AA38: =M38-J38 -> -260.4791 | AB38: =M38/J38 -> 0.89981573
A39: (新) 3300型飯糰機 | B39: 18℃-飯糰 | C39: 一配鮭魚奶油醬油飯糰 | E39: 18.53 | F39: 3307 | G39: =E39*F39 -> 61278.71 | I39: 3 | J39: 3300 | K39: =J39/I39 -> 1100 | L39: 3 | M39: =F39/V39*60 -> 2979.7327 | N39: =M39/L39 -> 993.24422 | O39: =L39-I39 -> 0 | P39: =N39-K39 -> -106.75578 | Q39: =N39/K39 -> 0.90294929 | R39: =Q55 -> 0.90294929 | S39: 0.35416667 | T39: 0.40040509 | V39: 66.589866 | AA39: =M39-J39 -> -320.26734 | AB39: =M39/J39 -> 0.90294929 | AC39: =AB55 -> 0.90294929
B55: 平均 | I55: =AVERAGE(I39:I54) -> 3 | J55: =AVERAGE(J39:J54) -> 3300 | K55: =J55/I55 -> 1100 | L55: =AVERAGE(L39:L54) -> 3 | M55: =AVERAGE(M39:M54) -> 2979.7327 | N55: =M55/L55 -> 993.24422 | O55: =L55-I55 -> 0 | P55: =N55-K55 -> -106.75578 | Q55: =N55/K55 -> 0.90294929 | S55: 0.35416667 | T55: 0.40040509 | AA55: =M55-J55 -> -320.26734 | AB55: =M55/J55 -> 0.90294929
A56: GKK3600型 飯糰機 | B56: 18℃-飯糰 | C56: 一配經典肉鬆飯糰 | E56: 14.03 | F56: 1467 | G56: =E56*F56 -> 20582.01 | H56: 2 | I56: 3 | J56: 3000 | K56: =J56/I56 -> 1000 | L56: 3 | M56: =F56/V56*60 -> 2704.8987 | N56: =M56/L56 -> 901.6329 | O56: =L56-I56 -> 0 | P56: =N56-K56 -> -98.3671 | Q56: =N56/K56 -> 0.9016329 | R56: =Q72 -> 0.88921261 | S56: 0.25 | T56: 0.27259259 | V56: 32.54096 | AA56: =M56-J56 -> -295.1013 | AB56: =M56/J56 -> 0.9016329 | AC56: =AB72 -> 0.88921261
B57: 18℃-飯糰 | C57: 一配鮪魚飯糰 | E57: 14.28 | F57: 2058 | G57: =E57*F57 -> 29388.24 | H57: 2 | I57: 3 | J57: 3600 | K57: =J57/I57 -> 1200 | L57: 3 | M57: =F57/V57*60 -> 3181.9253 | N57: =M57/L57 -> 1060.6418 | O57: =L57-I57 -> 0 | P57: =N57-K57 -> -139.35822 | Q57: =N57/K57 -> 0.88386815 | S57: 0.28263889 | T57: 0.30958333 | U57: 15 | V57: 38.806693 | AA57: =M57-J57 -> -418.07467 | AB57: =M57/J57 -> 0.88386815
B58: 18℃-飯糰 | C58: 一配鹽蔥燒肉飯糰 | E58: 17.89 | F58: 3378 | G58: =E58*F58 -> 60432.42 | I58: 4 | J58: 3600 | K58: =J58/I58 -> 900 | L58: 4 | M58: =F58/V58*60 -> 3179.0043 | N58: =M58/L58 -> 794.75108 | O58: =L58-I58 -> 0 | P58: =N58-K58 -> -105.24892 | Q58: =N58/K58 -> 0.88305675 | S58: 0.31944444 | T58: 0.36371528 | U58: 15 | V58: 63.755812 | AA58: =M58-J58 -> -420.9957 | AB58: =M58/J58 -> 0.88305675
B59: 18℃-飯糰 | C59: 一配壹號醬炙烤牛飯糰 | E59: 22.28 | F59: 1216 | G59: =E59*F59 -> 27092.48 | I59: 5 | J59: 3300 | K59: =J59/I59 -> 660 | L59: 5 | M59: =F59/V59*60 -> 2952.6775 | N59: =M59/L59 -> 590.53549 | O59: =L59-I59 -> 0 | P59: =N59-K59 -> -69.464505 | Q59: =N59/K59 -> 0.89475075 | S59: 0.37361111 | T59: 0.39076389 | U59: 15 | V59: 24.709776 | AA59: =M59-J59 -> -347.32253 | AB59: =M59/J59 -> 0.89475075
B60: 18℃-飯糰 | C60: 一配明太子龍蝦風味沙拉飯糰 | E60: 18.18 | F60: 2428 | G60: =E60*F60 -> 44141.04 | I60: 3 | J60: 3600 | K60: =J60/I60 -> 1200 | L60: 3 | M60: =F60/V60*60 -> 3182.9983 | N60: =M60/L60 -> 1060.9994 | O60: =L60-I60 -> 0 | P60: =N60-K60 -> -139.00057 | Q60: =N60/K60 -> 0.88416619 | S60: 0.40069444 | T60: 0.43247685 | U60: 15 | V60: 45.768168 | AA60: =M60-J60 -> -417.00171 | AB60: =M60/J60 -> 0.88416619
B61: 18℃-飯糰 | C61: 一配鹽蔥生鮭飯糰 | E61: 27.48 | F61: 5591 | G61: =E61*F61 -> 153640.68 | I61: 5 | J61: 3600 | K61: =J61/I61 -> 720 | L61: 5 | M61: =F61/V61*60 -> 3187.1761 | N61: =M61/L61 -> 637.43521 | O61: =L61-I61 -> 0 | P61: =N61-K61 -> -82.564789 | Q61: =N61/K61 -> 0.88532668 | S61: 0.44236111 | T61: 0.51545139 | U61: 15 | V61: 105.25305 | AA61: =M61-J61 -> -412.82395 | AB61: =M61/J61 -> 0.88532668
B62: 18℃-飯糰 | C62: 一配經典肉鬆飯糰 | E62: 14.03 | F62: 3333 | G62: =E62*F62 -> 46761.99 | I62: 3 | J62: 3000 | K62: =J62/I62 -> 1000 | L62: 3 | M62: =F62/V62*60 -> 2704.8987 | N62: =M62/L62 -> 901.6329 | O62: =L62-I62 -> 0 | P62: =N62-K62 -> -98.3671 | Q62: =N62/K62 -> 0.9016329 | S62: 0.52569444 | T62: 0.57702546 | U62: 14.75 | V62: 73.932528 | AA62: =M62-J62 -> -295.1013 | AB62: =M62/J62 -> 0.9016329
B63: 18℃-飯糰 | C63: 一配鮪魚飯糰 | E63: 14.28 | F63: 4800 | G63: =E63*F63 -> 68544 | I63: 3 | J63: 3600 | K63: =J63/I63 -> 1200 | L63: 3 | M63: =F63/V63*60 -> 3181.9253 | N63: =M63/L63 -> 1060.6418 | O63: =L63-I63 -> 0 | P63: =N63-K63 -> -139.35822 | Q63: =N63/K63 -> 0.88386815 | S63: 0.58680556 | T63: 0.64965278 | U63: 15 | V63: 90.511238 | AA63: =M63-J63 -> -418.07467 | AB63: =M63/J63 -> 0.88386815
B72: 平均 | I72: =AVERAGE(I56:I71) -> 3.625 | J72: =AVERAGE(J56:J71) -> 3412.5 | K72: =J72/I72 -> 941.37931 | L72: =AVERAGE(L56:L71) -> 3.625 | M72: =AVERAGE(M56:M71) -> 3034.438 | N72: =M72/L72 -> 837.08635 | O72: =L72-I72 -> 0 | P72: =N72-K72 -> -104.29296 | Q72: =N72/K72 -> 0.88921261 | S72: 0.25 | T72: 0.64965278 | AA72: =M72-J72 -> -378.06198 | AB72: =M72/J72 -> 0.88921261
A73: GKK3600型 飯糰機2 | B73: 18℃-飯糰 | C73: 一配柚檸海灣貝飯糰 | E73: 23.72 | F73: 1379 | G73: =E73*F73 -> 32709.88 | H73: 2 | I73: 5 | J73: 3600 | K73: =J73/I73 -> 720 | L73: 5 | M73: =F73/V73*60 -> 3181.6575 | N73: =M73/L73 -> 636.33151 | O73: =L73-I73 -> 0 | P73: =N73-K73 -> -83.668492 | Q73: =N73/K73 -> 0.88379376 | R73: =Q89 -> 0.88467459 | S73: 0.25 | T73: 0.26805556 | V73: 26.005313 | AA73: =M73-J73 -> -418.34246 | AB73: =M73/J73 -> 0.88379376 | AC73: =AB89 -> 0.88467459
B74: 18℃-飯糰 | C74: 一配雞肉飯飯糰 | E74: 16.66 | F74: 1768 | G74: =E74*F74 -> 29454.88 | H74: 2 | I74: 5 | J74: 3600 | K74: =J74/I74 -> 720 | L74: 5 | M74: =F74/V74*60 -> 3184.6958 | N74: =M74/L74 -> 636.93917 | O74: =L74-I74 -> 0 | P74: =N74-K74 -> -83.060834 | Q74: =N74/K74 -> 0.88463773 | S74: 0.27847222 | T74: 0.30159722 | U74: 15 | V74: 33.309304 | AA74: =M74-J74 -> -415.30417 | AB74: =M74/J74 -> 0.88463773
B75: 18℃-飯糰 | C75: 一配蔬食鮪魚飯糰 | E75: 18.18 | F75: 1278 | G75: =E75*F75 -> 23234.04 | I75: 3 | J75: 3600 | K75: =J75/I75 -> 1200 | L75: 3 | M75: =F75/V75*60 -> 3183.3859 | N75: =M75/L75 -> 1061.1286 | O75: =L75-I75 -> 0 | P75: =N75-K75 -> -138.87136 | Q75: =N75/K75 -> 0.88427386 | S75: 0.31180556 | T75: 0.32853009 | U75: 14.7 | V75: 24.08756 | AA75: =M75-J75 -> -416.61409 | AB75: =M75/J75 -> 0.88427386
B76: 18℃-飯糰 | C76: 一配熟成紅鮭飯糰 | E76: 25.03 | F76: 1879 | G76: =E76*F76 -> 47031.37 | I76: 5 | J76: 3600 | K76: =J76/I76 -> 720 | L76: 5 | M76: =F76/V76*60 -> 3185.982 | N76: =M76/L76 -> 637.1964 | O76: =L76-I76 -> 0 | P76: =N76-K76 -> -82.803597 | Q76: =N76/K76 -> 0.884995 | S76: 0.33888889 | T76: 0.36346065 | U76: 14.916667 | V76: 35.386264 | AA76: =M76-J76 -> -414.01799 | AB76: =M76/J76 -> 0.884995
B77: 18℃-飯糰 | C77: 一配北海道秋鮭親子飯糰 | E77: 24.82 | F77: 2245 | G77: =E77*F77 -> 55720.9 | I77: 5 | J77: 3600 | K77: =J77/I77 -> 720 | L77: 5 | M77: =F77/V77*60 -> 3188.5118 | N77: =M77/L77 -> 637.70237 | O77: =L77-I77 -> 0 | P77: =N77-K77 -> -82.297633 | Q77: =N77/K77 -> 0.88569773 | S77: 0.37361111 | T77: 0.40293981 | U77: 14.616667 | V77: 42.245413 | AA77: =M77-J77 -> -411.48816 | AB77: =M77/J77 -> 0.88569773
B78: 18℃-飯糰 | C78: 一配贅沢鮭魚肚飯糰 | E78: 30 | F78: 3206 | G78: =E78*F78 -> 96180 | I78: 4 | J78: 3600 | K78: =J78/I78 -> 900 | L78: 4 | M78: =F78/V78*60 -> 3184.56 | N78: =M78/L78 -> 796.14 | O78: =L78-I78 -> 0 | P78: =N78-K78 -> -103.86 | Q78: =N78/K78 -> 0.8846 | S78: 0.41319444 | T78: 0.45513889 | U78: 14.766667 | V78: 60.403949 | AA78: =M78-J78 -> -415.44 | AB78: =M78/J78 -> 0.8846
B79: 18℃-飯糰 | C79: 一配山葵章魚飯糰 | E79: 25.2 | F79: 4813 | G79: =E79*F79 -> 121287.6 | I79: 3 | J79: 3600 | K79: =J79/I79 -> 1200 | L79: 3 | M79: =F79/V79*60 -> 3188.3102 | N79: =M79/L79 -> 1062.7701 | O79: =L79-I79 -> 0 | P79: =N79-K79 -> -137.22995 | Q79: =N79/K79 -> 0.88564171 | S79: 0.46527778 | T79: 0.5281713 | U79: 14.6 | V79: 90.574626 | AA79: =M79-J79 -> -411.68984 | AB79: =M79/J79 -> 0.88564171
B80: 18℃-飯糰 | C80: 一配柚檸海灣貝飯糰 | E80: 23.72 | F80: 3489 | G80: =E80*F80 -> 82759.08 | I80: 5 | J80: 3600 | K80: =J80/I80 -> 720 | L80: 5 | M80: =F80/V80*60 -> 3181.6575 | N80: =M80/L80 -> 636.33151 | O80: =L80-I80 -> 0 | P80: =N80-K80 -> -83.668492 | Q80: =N80/K80 -> 0.88379376 | S80: 0.53819444 | T80: 0.58387731 | U80: 15 | V80: 65.795893 | AA80: =M80-J80 -> -418.34246 | AB80: =M80/J80 -> 0.88379376
B81: 18℃-飯糰 | C81: 一配雞肉飯飯糰 | E81: 16.66 | F81: 4009 | G81: =E81*F81 -> 66789.94 | I81: 5 | J81: 3600 | K81: =J81/I81 -> 720 | L81: 5 | M81: =F81/V81*60 -> 3184.6958 | N81: =M81/L81 -> 636.93917 | O81: =L81-I81 -> 0 | P81: =N81-K81 -> -83.060834 | Q81: =N81/K81 -> 0.88463773 | S81: 0.59375 | T81: 0.64619213 | U81: 15 | V81: 75.529976 | AA81: =M81-J81 -> -415.30417 | AB81: =M81/J81 -> 0.88463773
B89: 平均 | I89: =AVERAGE(I73:I88) -> 4.4444444 | J89: =AVERAGE(J73:J88) -> 3600 | K89: =J89/I89 -> 810 | L89: =AVERAGE(L73:L88) -> 4.4444444 | M89: =AVERAGE(M73:M88) -> 3184.8285 | N89: =M89/L89 -> 716.58642 | O89: =L89-I89 -> 0 | P89: =N89-K89 -> -93.413583 | Q89: =N89/K89 -> 0.88467459 | S89: 0.25 | T89: 0.64619213 | AA89: =M89-J89 -> -415.17148 | AB89: =M89/J89 -> 0.88467459
A90: 自動包裝機 (二配) | B90: 18℃-飯糰 | C90: 二配兩粒飯糰(鮪魚.焦糖鮭魚) | E90: 28.57 | F90: 1389 | G90: =E90*F90 -> 39683.73 | I90: 12 | J90: 3600 | K90: =J90/I90 -> 300 | L90: 12 | M90: =F90/V90*60 -> 3126.4138 | N90: =M90/L90 -> 260.53448 | O90: =L90-I90 -> 0 | P90: =N90-K90 -> -39.46552 | Q90: =N90/K90 -> 0.86844827 | R90: =Q106 -> 0.8933527 | S90: 0.70833333 | T90: 0.72684028 | V90: 26.65674 | AA90: =M90-J90 -> -473.58624 | AB90: =M90/J90 -> 0.86844827 | AC90: =AB106 -> 0.8933527
B91: 18℃-飯糰 | C91: 二配鮮蝦旬彩炊飯飯糰 | E91: 20.17 | F91: 146 | G91: =E91*F91 -> 2944.82 | I91: 12 | J91: 3600 | K91: =J91/I91 -> 300 | L91: 12 | M91: =F91/V91*60 -> 3261.7414 | N91: =M91/L91 -> 271.81178 | O91: =L91-I91 -> 0 | P91: =N91-K91 -> -28.188217 | Q91: =N91/K91 -> 0.90603928 | S91: 0.73055556 | T91: 0.73241898 | U91: 5.35 | V91: 2.685682 | AA91: =M91-J91 -> -338.25861 | AB91: =M91/J91 -> 0.90603928
B92: 18℃-飯糰 | C92: 二配溏心蛋五目飯糰 | E92: 20.42 | F92: 1294 | G92: =E92*F92 -> 26423.48 | I92: 13 | J92: 3600 | K92: =J92/I92 -> 276.92308 | L92: 13 | M92: =F92/V92*60 -> 3260.054 | N92: =M92/L92 -> 250.77339 | O92: =L92-I92 -> 0 | P92: =N92-K92 -> -26.14969 | Q92: =N92/K92 -> 0.90557056 | S92: 0.73611111 | T92: 0.75263889 | U92: 5.3166667 | V92: 23.815556 | AA92: =M92-J92 -> -339.94597 | AB92: =M92/J92 -> 0.90557056
B106: 平均 | I106: =AVERAGE(I90:I105) -> 12.333333 | J106: =AVERAGE(J90:J105) -> 3600 | K106: =J106/I106 -> 291.89189 | L106: =AVERAGE(L90:L105) -> 12.333333 | M106: =AVERAGE(M90:M105) -> 3216.0697 | N106: =M106/L106 -> 260.76241 | O106: =L106-I106 -> 0 | P106: =N106-K106 -> -31.129482 | Q106: =N106/K106 -> 0.8933527 | S106: 0.70833333 | T106: 0.75263889 | AA106: =M106-J106 -> -383.93027 | AB106: =M106/J106 -> 0.8933527
A107: (新) 3300型飯糰機 (二配) | B107: 18℃-飯糰 | C107: 二配鹽水G絲飯糰 | E107: 17.22 | F107: 2090 | G107: =E107*F107 -> 35989.8 | I107: 3 | J107: 3300 | K107: =J107/I107 -> 1100 | L107: 3 | M107: =F107/V107*60 -> 2979.5356 | N107: =M107/L107 -> 993.17853 | O107: =L107-I107 -> 0 | P107: =N107-K107 -> -106.82147 | Q107: =N107/K107 -> 0.90288957 | R107: =Q123 -> 0.89840381 | S107: 0.70833333 | T107: 0.73755787 | V107: 42.087096 | AA107: =M107-J107 -> -320.46442 | AB107: =M107/J107 -> 0.90288957 | AC107: =AB123 -> 0.89840381
B108: 18℃-飯糰 | C108: 二配大飯糰韓式蒜烤豬五花 | E108: 24.54 | F108: 1732 | G108: =E108*F108 -> 42503.28 | I108: 4 | J108: 3000 | K108: =J108/I108 -> 750 | L108: 4 | M108: =F108/V108*60 -> 2686.8248 | N108: =M108/L108 -> 671.7062 | O108: =L108-I108 -> 0 | P108: =N108-K108 -> -78.293798 | Q108: =N108/K108 -> 0.89560827 | S108: 0.74097222 | T108: 0.76782407 | U108: 4.9166667 | V108: 38.677624 | AA108: =M108-J108 -> -313.17519 | AB108: =M108/J108 -> 0.89560827
