Workbook

Sheet 0930
B1: 屏榮 大溪廠組合室生產人時性分析
B3: 日期 | C3: 115.09.30星期三 | E3: 訂單量 | F3: ='0930(18度C)'!D1+'0930(4度C)'!D1 -> 150408 | H3: 營業額 | I3: ='0930(18度C)'!F1+'0930(4度C)'!F1 -> 4733864.6
B4: 人時性 | C4: 項目 | E4: ➀ | G4: ➁ | I4: ➂ | K4: ④ | M4: ⑤ | O4: 異常停線 | Q4: 短暫停線
C5: 組合室 | E5: 全溫層 | G5: 4度C-各編組展開(一配) | I5: 4度C-各編組展開(二配) | K5: 18度C-各編組展開(一配) | M5: 18度C-各編組展開(二配) | O5: 合計次數 | P5: 時間 | Q5: 合計次數 | R5: 設備次數
C6: 排關平均 | E6: =AVERAGE(D14:O14,D32:X32) -> 473.31811 | F6: =AVERAGE(#REF!,D14:K14) -> #REF! | G6: =AVERAGE(D14:K14) -> 274.37434 | I6: =AVERAGE(L14:O14) -> 94.325718 | K6: =AVERAGE(D32:O32) -> 716.27883 | M6: =AVERAGE(P32:X32) -> 718.26923 | O6: ='0930(4度C)'!Y2 -> 0 | P6: ='0930(4度C)'!Z2 -> 0 | Q6: ='0930(4度C)'!AC2 -> 0 | R6: ='0930(4度C)'!AD2 -> 0
C7: 實績平均 | E7: =AVERAGE(D15:O15,D33:X33) -> 429.4493 | F7: =AVERAGE(#REF!,D15:K15) -> #REF! | G7: =AVERAGE(D15:K15) -> 247.95255 | I7: =AVERAGE(L15:O15) -> 87.604344 | K7: =AVERAGE(D33:O33) -> 646.96494 | M7: =AVERAGE(P33:X33) -> 655.10125
C8: 達成率平均 | E8: =AVERAGE(D16:O16,D34:X34) -> 0.90505684 | F8: =AVERAGE(D16:K16,#REF!) -> #REF! | G8: =AVERAGE(D16:K16) -> 0.90266236 | I8: =AVERAGE(L16:O16) -> 0.92681305 | K8: =AVERAGE(D34:O34) -> 0.897643 | M8: =AVERAGE(P34:X34) -> 0.90518429
O9: ※現行日本鮮食廠以達成率80%為基本(即為現行KPI)
B11: 溫層 | D11: ➁4度C-各編組展開 | L11: ➂4度C-各編組展開
B12: 編組 | D12: 1 | E12: 2 | F12: 3 | G12: 4 | H12: 5 | I12: 6 | J12: 7 | K12: 8 | L12: 1 | M12: 2 | N12: 3 | O12: 4
D13: 便當一線 | E13: 便當二線 | F13: 涼麵一線 | G13: 涼麵二線 | H13: 涼麵三線 | I13: 自動包裝機 | J13: 自動包裝機2 | K13: 自動包裝機3 | L13: 便當一線 | M13: 便當二線 | N13: 涼麵一線 | O13: 涼麵二線
B14: 人時性 | C14: 排關 | D14: - | E14: 85.245902 | F14: 114.5098 | G14: 86.206897 | H14: 173.63636 | I14: 486.64706 | J14: 700 | K14: - | L14: - | M14: 101.69492 | N14: 86.956522 | O14: -
C15: 實績 | D15: - | E15: 76.993316 | F15: 103.41706 | G15: 77.872207 | H15: 155.62769 | I15: 440.751 | J15: 633.05404 | K15: - | L15: - | M15: 96.764286 | N15: 78.444403 | O15: -
C16: 達成率 | D16: - | E16: =E15/E14 -> 0.90319083 | F16: =F15/F14 -> 0.90312847 | G16: =G15/G14 -> 0.9033176 | H16: =H15/H14 -> 0.89628511 | I16: =I15/I14 -> 0.90568923 | J16: =J15/J14 -> 0.90436291 | K16: - | L16: - | M16: =M15/M14 -> 0.95151548 | N16: =N15/N14 -> 0.90211063 | O16: -
B17: 作業 時間 | C17: 開始 | D17: - | E17: 0.20833333 | F17: 0.20833333 | G17: 0.20833333 | H17: 0.25 | I17: 0.20833333 | J17: 0.25 | K17: - | L17: - | M17: 0.70833333 | N17: 0.70833333 | O17: -
C18: 結束 | D18: - | E18: 0.62592593 | F18: 0.58673611 | G18: 0.50041667 | H18: 0.42119213 | I18: 0.42825231 | J18: 0.30111111 | K18: - | L18: - | M18: 0.82678241 | N18: 0.86069444 | O18: -
B19: 產線異常 (5分鐘以上) | C19: 次數
C20: 時間/分
B21: 短暫停線 (5分鐘以下) | C21: 次數
C22: 設備次數
B23: 配置人數 | D23: - | E23: 20.333333 | F23: 20.8 | G23: 23.2 | H23: 19.8 | I23: 5.6666667 | J23: 6 | K23: - | L23: - | M23: 18.666667 | N23: 23 | O23: -
B24: 主要應用設備 | D24: L型封口機 | E24: ET-55 | F24: ET-55 | G24: ET-55 | H24: ET-600 | I24: 伺服包裝機 | J24: 伺服包裝機 | K24: 伺服包裝機 | L24: L型封口機 | M24: ET-55 | N24: ET-55 | O24: ET-55
B25: 次要應用設備 | D25: 伺服包裝機 | H25: 伺服包裝機
B26: 備註 | H26: 涼麵+烤飯糰 | I26: 大口飯糰線 | K26: 烤飯糰+手卷
B29: 溫層 | D29: ➃18度C-各編組展開 (一配) | P29: ⑤18度C-各編組展開 (二配)
B30: 編組 | D30: 1 | E30: 2 | F30: 3 | G30: 4 | H30: 5 | I30: 6 | J30: 7 | K30: 8 | L30: 9 | M30: 10 | N30: 11 | O30: 12 | P30: 1 | Q30: 2 | R30: 3 | S30: 4 | T30: 5 | U30: 6 | V30: 7 | W30: 8 | X30: 9
D31: 便當一線 | E31: 涼麵一線 | F31: 涼麵三線 | G31: 自動包裝機 | H31: 自動包裝機2 | I31: 自動包裝機3 | J31: 味付飯糰線B | K31: (舊) 3300型飯糰線 | L31: 3000型飯糰線 | M31: (新) 3300型飯糰機 | N31: GKK3600型 飯糰機 | O31: GKK3600型 飯糰機2 | P31: 自動包裝機 | Q31: 自動包裝機2 | R31: 自動包裝機3 | S31: 味付飯糰線B | T31: (舊) 3300型飯糰線 | U31: 3000型飯糰線 | V31: (新) 3300型飯糰機 | W31: GKK3600型 飯糰機 | X31: GKK3600型 飯糰機2
B32: 人時性 | C32: 排關 | D32: - | E32: - | F32: - | G32: 322.38806 | H32: - | I32: - | J32: - | K32: - | L32: - | M32: 750 | N32: 920 | O32: 872.72727 | P32: 300 | Q32: - | R32: - | S32: - | T32: - | U32: - | V32: 750 | W32: 923.07692 | X32: 900
C33: 實績 | D33: - | E33: - | F33: - | G33: 280.87263 | H33: - | I33: - | J33: - | K33: - | L33: - | M33: 669.77986 | N33: 843.45222 | O33: 793.75505 | P33: 259.96346 | Q33: - | R33: - | S33: - | T33: - | U33: - | V33: 697.21315 | W33: 844.44486 | X33: 818.78354
C34: 達成率 | D34: - | E34: - | F34: - | G34: =G33/G32 -> 0.8712253 | H34: - | I34: - | J34: - | K34: - | L34: - | M34: =M33/M32 -> 0.89303982 | N34: =N33/N32 -> 0.91679589 | O34: =O33/O32 -> 0.90951099 | P34: =P33/P32 -> 0.86654487 | Q34: - | R34: - | S34: - | T34: - | U34: - | V34: =V33/V32 -> 0.92961753 | W34: =W33/W32 -> 0.91481526 | X34: =X33/X32 -> 0.90975949
B35: 作業 時間 | C35: 開始 | D35: - | E35: - | F35: - | G35: 0.20833333 | H35: - | I35: - | J35: - | K35: - | L35: - | M35: 0.31805556 | N35: 0.25 | O35: 0.25 | P35: 0.73958333 | Q35: - | R35: - | S35: - | T35: - | U35: - | V35: 0.70833333 | W35: 0.73263889 | X35: 0.73263889
C36: 結束 | D36: - | E36: - | F36: - | G36: 0.42825231 | H36: - | I36: - | J36: - | K36: - | L36: - | M36: 0.38787037 | N36: 0.48474537 | O36: 0.47805556 | P36: 0.75303241 | Q36: - | R36: - | S36: - | T36: - | U36: - | V36: 0.72170139 | W36: 1.1123958 | X36: 1.0983218
B37: 配置人數 | D37: - | E37: - | F37: - | G37: 11.166667 | H37: - | I37: - | J37: - | K37: - | L37: - | M37: 4 | N37: 3.75 | O37: 4.125 | P37: 12 | Q37: - | R37: - | S37: - | T37: - | U37: - | V37: 4 | W37: 3.7142857 | X37: 4
B38: 主要應用設備 | D38: 伺服包裝機 | E38: ET-55 | F38: ET-600 | G38: 夾心型 | H38: 伺服包裝機 | I38: 伺服包裝機 | J38: 夾心型 | K38: 3300型 | L38: 3300型 | M38: 3300型 | N38: GKK | O38: GKK | P38: 夾心型 | Q38: 伺服包裝機 | R38: 伺服包裝機 | S38: 夾心型 | T38: 3300型 | U38: 3300型 | V38: 3300型 | W38: GKK | X38: GKK
B39: 次要應用設備
B40: 備註

Sheet 0930(18度C)
A1: 大溪廠日報分析 | C1: 總生產量 | D1: =SUM(F5:F140) -> 77634 | E1: 營業額 | F1: =SUM(G5:G140) -> 1549857.3 | G1: 出勤人數 | H1: =L21+L38+L55+L72+L89+L106+L123+L140 -> 46.755952 | I1: 產線配置圖 | L1: 生產實績 | O1: 人時性差異分析 | S1: 日報登錄 | Y1: 分析說明 | AA1: 產能差異分析
A2: 46295 | C2: 人時性 | D2: =AVERAGE(N21,N38,N55,N72,N89,N106,N123,N140) -> 651.0331 | E2: 平均廠價 | F2: =F1/D1 -> 19.963641 | G2: 多次生產數 | H2: =COUNT(H5:H140) -> 14
A3: 線別 | B3: 品類 | C3: 品名 | E3: 廠價 | F3: 生產量 | G3: 營收 | H3: 多次 生產 | I3: 人數 | J3: 產能/時 | K3: 人時性 | L3: 人數 | M3: 產能/時 | N3: 人時性 | O3: 人數 | P3: 人時性 | Q3: 達成率 | R3: 達成率 平均 | S3: 生產時間 | U3: 換線、休息/分 | V3: 稼動時間/分 | W3: 休息時間 | Y3: (屏榮回填) | AA3: 產能/時 | AB3: 達成率 | AC3: 達成率平均
S4: 開始 | T4: 結束 | W4: 開始 | X4: 結束
A5: 自動包裝機 | B5: 18℃-壽司手卷 | C5: 一配長野稻荷壽司 | E5: 25.64 | F5: 1136 | G5: =E5*F5 -> 29127.04 | I5: 10 | J5: 3600 | K5: =J5/I5 -> 360 | L5: 10 | M5: =F5/V5*60 -> 3215.4496 | N5: =M5/L5 -> 321.54496 | O5: =L5-I5 -> 0 | P5: =N5-K5 -> -38.455045 | Q5: =N5/K5 -> 0.89318043 | R5: =Q21 -> 0.8712253 | S5: 0.20833333 | T5: 0.22304398 | V5: 21.197658 | AA5: =M5-J5 -> -384.55045 | AB5: =M5/J5 -> 0.89318043 | AC5: =AB21 -> 0.8712253
B6: 18℃-壽司手卷 | C6: 一配經典人氣雙手卷 | E6: 29.52 | F6: 1926 | G6: =E6*F6 -> 56855.52 | I6: 11 | J6: 3600 | K6: =J6/I6 -> 327.27273 | L6: 11 | M6: =F6/V6*60 -> 3155.7235 | N6: =M6/L6 -> 286.88395 | O6: =L6-I6 -> 0 | P6: =N6-K6 -> -40.388774 | Q6: =N6/K6 -> 0.87658986 | S6: 0.22638889 | T6: 0.25181713 | U6: 4.8166667 | V6: 36.619178 | AA6: =M6-J6 -> -444.27651 | AB6: =M6/J6 -> 0.87658986
B7: 18℃-壽司手卷 | C7: 一配鮭鮪海饌雙手卷 | E7: 29.85 | F7: 2336 | G7: =E7*F7 -> 69729.6 | I7: 11 | J7: 3600 | K7: =J7/I7 -> 327.27273 | L7: 11 | M7: =F7/V7*60 -> 3156.8314 | N7: =M7/L7 -> 286.98468 | O7: =L7-I7 -> 0 | P7: =N7-K7 -> -40.288051 | Q7: =N7/K7 -> 0.87689762 | S7: 0.25555556 | T7: 0.28637731 | U7: 5.3833333 | V7: 44.39895 | AA7: =M7-J7 -> -443.16856 | AB7: =M7/J7 -> 0.87689762
B8: 18℃-壽司手卷 | C8: 一配青木瓜雞絲泰泰雙手卷 | E8: 30 | F8: 186 | G8: =E8*F8 -> 5580 | I8: 11 | J8: 3600 | K8: =J8/I8 -> 327.27273 | L8: 11 | M8: =F8/V8*60 -> 3156.6273 | N8: =M8/L8 -> 286.96612 | O8: =L8-I8 -> 0 | P8: =N8-K8 -> -40.30661 | Q8: =N8/K8 -> 0.87684091 | S8: 0.29027778 | T8: 0.29273148 | U8: 5.6166667 | V8: 3.535419 | AA8: =M8-J8 -> -443.37271 | AB8: =M8/J8 -> 0.87684091
B9: 18℃-壽司手卷 | C9: 一配陽光蔬彩雙手卷 | E9: 30.95 | F9: 2219 | G9: =E9*F9 -> 68678.05 | I9: 12 | J9: 3600 | K9: =J9/I9 -> 300 | L9: 12 | M9: =F9/V9*60 -> 3011.4072 | N9: =M9/L9 -> 250.9506 | O9: =L9-I9 -> 0 | P9: =N9-K9 -> -49.0494 | Q9: =N9/K9 -> 0.836502 | S9: 0.29652778 | T9: 0.32722222 | U9: 5.4666667 | V9: 44.211889 | AA9: =M9-J9 -> -588.5928 | AB9: =M9/J9 -> 0.836502
B10: 18℃-飯糰 | C10: 一配兩粒飯糰(鮪魚.焦糖鮭魚) | E10: 28.57 | F10: 755 | G10: =E10*F10 -> 21570.35 | I10: 12 | J10: 3600 | K10: =J10/I10 -> 300 | L10: 12 | M10: =F10/V10*60 -> 3122.4275 | N10: =M10/L10 -> 260.20229 | O10: =L10-I10 -> 0 | P10: =N10-K10 -> -39.797712 | Q10: =N10/K10 -> 0.86734096 | S10: 0.33055556 | T10: 0.340625 | U10: 4.8 | V10: 14.507943 | AA10: =M10-J10 -> -477.57254 | AB10: =M10/J10 -> 0.86734096
B21: 平均 | I21: =AVERAGE(I5:I20) -> 11.166667 | J21: =AVERAGE(J5:J20) -> 3600 | K21: =J21/I21 -> 322.38806 | L21: =AVERAGE(L5:L20) -> 11.166667 | M21: =AVERAGE(M5:M20) -> 3136.4111 | N21: =M21/L21 -> 280.87263 | O21: =L21-I21 -> 0 | P21: =N21-K21 -> -41.515427 | Q21: =N21/K21 -> 0.8712253 | S21: 0.20833333 | T21: 0.42825231 | AA21: =M21-J21 -> -463.58893 | AB21: =M21/J21 -> 0.8712253
A22: (新) 3300型飯糰機 | B22: 18℃-飯糰 | C22: 一配鮭魚奶油醬油飯糰 | E22: 18.53 | F22: 1478 | G22: =E22*F22 -> 27387.34 | I22: 3 | J22: 3300 | K22: =J22/I22 -> 1100 | L22: 3 | M22: =F22/V22*60 -> 3072.5272 | N22: =M22/L22 -> 1024.1757 | O22: =L22-I22 -> 0 | P22: =N22-K22 -> -75.824272 | Q22: =N22/K22 -> 0.93106884 | R22: =Q38 -> 0.89303982 | S22: 0.31805556 | T22: 0.33809028 | V22: 28.862234 | AA22: =M22-J22 -> -227.47281 | AB22: =M22/J22 -> 0.93106884 | AC22: =AB38 -> 0.89303982
B23: 18℃-飯糰 | C23: 一配熊本麥味噌雞肉飯糰 | E23: 22.95 | F23: 2573 | G23: =E23*F23 -> 59050.35 | I23: 5 | J23: 2700 | K23: =J23/I23 -> 540 | L23: 5 | M23: =F23/V23*60 -> 2285.7117 | N23: =M23/L23 -> 457.14234 | O23: =L23-I23 -> 0 | P23: =N23-K23 -> -82.857656 | Q23: =N23/K23 -> 0.8465599 | S23: 0.34097222 | T23: 0.38787037 | U23: 5 | V23: 67.541326 | AA23: =M23-J23 -> -414.28828 | AB23: =M23/J23 -> 0.8465599
B38: 平均 | I38: =AVERAGE(I22:I37) -> 4 | J38: =AVERAGE(J22:J37) -> 3000 | K38: =J38/I38 -> 750 | L38: =AVERAGE(L22:L37) -> 4 | M38: =AVERAGE(M22:M37) -> 2679.1195 | N38: =M38/L38 -> 669.77986 | O38: =L38-I38 -> 0 | P38: =N38-K38 -> -80.220137 | Q38: =N38/K38 -> 0.89303982 | S38: 0.31805556 | T38: 0.38787037 | AA38: =M38-J38 -> -320.88055 | AB38: =M38/J38 -> 0.89303982
A39: GKK3600型 飯糰機 | B39: 18℃-飯糰 | C39: 一配北海道秋鮭親子飯糰 | E39: 24.82 | F39: 792 | G39: =E39*F39 -> 19657.44 | I39: 5 | J39: 3600 | K39: =J39/I39 -> 720 | L39: 5 | M39: =F39/V39*60 -> 3274.8115 | N39: =M39/L39 -> 654.9623 | O39: =L39-I39 -> 0 | P39: =N39-K39 -> -65.037701 | Q39: =N39/K39 -> 0.90966986 | R39: =Q55 -> 0.91679589 | S39: 0.25 | T39: 0.26006944 | V39: 14.510759 | AA39: =M39-J39 -> -325.1885 | AB39: =M39/J39 -> 0.90966986 | AC39: =AB55 -> 0.91679589
B40: 18℃-飯糰 | C40: 一配熟成紅鮭飯糰 | E40: 25.03 | F40: 687 | G40: =E40*F40 -> 17195.61 | I40: 5 | J40: 3600 | K40: =J40/I40 -> 720 | L40: 5 | M40: =F40/V40*60 -> 3276.4002 | N40: =M40/L40 -> 655.28004 | O40: =L40-I40 -> 0 | P40: =N40-K40 -> -64.71996 | Q40: =N40/K40 -> 0.91011117 | S40: 0.26944444 | T40: 0.2781713 | U40: 13.5 | V40: 12.580881 | AA40: =M40-J40 -> -323.5998 | AB40: =M40/J40 -> 0.91011117
B41: 18℃-飯糰 | C41: 一配生鱈魚子鮭魚飯糰 | E41: 23.8 | F41: 708 | G41: =E41*F41 -> 16850.4 | I41: 4 | J41: 3600 | K41: =J41/I41 -> 900 | L41: 4 | M41: =F41/V41*60 -> 3272.4672 | N41: =M41/L41 -> 818.11679 | O41: =L41-I41 -> 0 | P41: =N41-K41 -> -81.883208 | Q41: =N41/K41 -> 0.90901866 | S41: 0.2875 | T41: 0.29650463 | U41: 13.433333 | V41: 12.981032 | AA41: =M41-J41 -> -327.53283 | AB41: =M41/J41 -> 0.90901866
B42: 18℃-飯糰 | C42: 一配筋子銀鮭飯糰 | E42: 30 | F42: 651 | G42: =E42*F42 -> 19530 | I42: 4 | J42: 3300 | K42: =J42/I42 -> 825 | L42: 4 | M42: =F42/V42*60 -> 3072.3913 | N42: =M42/L42 -> 768.09782 | O42: =L42-I42 -> 0 | P42: =N42-K42 -> -56.90218 | Q42: =N42/K42 -> 0.93102766 | S42: 0.30555556 | T42: 0.314375 | U42: 13.033333 | V42: 12.713224 | AA42: =M42-J42 -> -227.60872 | AB42: =M42/J42 -> 0.93102766
B43: 18℃-飯糰 | C43: 一配蔬食鮪魚飯糰 | E43: 18.18 | F43: 847 | G43: =E43*F43 -> 15398.46 | I43: 3 | J43: 3600 | K43: =J43/I43 -> 1200 | L43: 3 | M43: =F43/V43*60 -> 3269.5294 | N43: =M43/L43 -> 1089.8431 | O43: =L43-I43 -> 0 | P43: =N43-K43 -> -110.15688 | Q43: =N43/K43 -> 0.9082026 | S43: 0.32361111 | T43: 0.33439815 | U43: 13.3 | V43: 15.543522 | AA43: =M43-J43 -> -330.47065 | AB43: =M43/J43 -> 0.9082026
B44: 18℃-飯糰 | C44: 一配黑胡椒洋蔥豬飯糰 | E44: 17.07 | F44: 1204 | G44: =E44*F44 -> 20552.28 | I44: 3 | J44: 3300 | K44: =J44/I44 -> 1100 | L44: 3 | M44: =F44/V44*60 -> 3071.5426 | N44: =M44/L44 -> 1023.8475 | O44: =L44-I44 -> 0 | P44: =N44-K44 -> -76.152473 | Q44: =N44/K44 -> 0.93077048 | S44: 0.34375 | T44: 0.36008102 | U44: 13.466667 | V44: 23.519127 | AA44: =M44-J44 -> -228.45742 | AB44: =M44/J44 -> 0.93077048
B45: 18℃-飯糰 | C45: 一配經典肉鬆飯糰 | E45: 14.03 | F45: 3210 | G45: =E45*F45 -> 45036.3 | I45: 3 | J45: 3000 | K45: =J45/I45 -> 1000 | L45: 3 | M45: =F45/V45*60 -> 2795.3556 | N45: =M45/L45 -> 931.7852 | O45: =L45-I45 -> 0 | P45: =N45-K45 -> -68.214804 | Q45: =N45/K45 -> 0.9317852 | S45: 0.36944444 | T45: 0.41729167 | U45: 13.483333 | V45: 68.9 | AA45: =M45-J45 -> -204.64441 | AB45: =M45/J45 -> 0.9317852
B46: 18℃-飯糰 | C46: 一配鮪魚飯糰 | E46: 14.28 | F46: 4527 | G46: =E46*F46 -> 64645.56 | I46: 3 | J46: 3600 | K46: =J46/I46 -> 1200 | L46: 3 | M46: =F46/V46*60 -> 3271.069 | N46: =M46/L46 -> 1090.3563 | O46: =L46-I46 -> 0 | P46: =N46-K46 -> -109.64368 | Q46: =N46/K46 -> 0.90863027 | S46: 0.42708333 | T46: 0.48474537 | U46: 14.1 | V46: 83.037075 | AA46: =M46-J46 -> -328.93103 | AB46: =M46/J46 -> 0.90863027
B55: 平均 | I55: =AVERAGE(I39:I54) -> 3.75 | J55: =AVERAGE(J39:J54) -> 3450 | K55: =J55/I55 -> 920 | L55: =AVERAGE(L39:L54) -> 3.75 | M55: =AVERAGE(M39:M54) -> 3162.9458 | N55: =M55/L55 -> 843.45222 | O55: =L55-I55 -> 0 | P55: =N55-K55 -> -76.547779 | Q55: =N55/K55 -> 0.91679589 | S55: 0.25 | T55: 0.48474537 | AA55: =M55-J55 -> -287.05417 | AB55: =M55/J55 -> 0.91679589
A56: GKK3600型 飯糰機2 | B56: 18℃-飯糰 | C56: 一配明太子龍蝦風味沙拉飯糰 | E56: 18.18 | F56: 1376 | G56: =E56*F56 -> 25015.68 | I56: 3 | J56: 3600 | K56: =J56/I56 -> 1200 | L56: 3 | M56: =F56/V56*60 -> 3274.4963 | N56: =M56/L56 -> 1091.4988 | O56: =L56-I56 -> 0 | P56: =N56-K56 -> -108.50122 | Q56: =N56/K56 -> 0.90958232 | R56: =Q72 -> 0.90951099 | S56: 0.25 | T56: 0.2675 | V56: 25.213038 | AA56: =M56-J56 -> -325.50366 | AB56: =M56/J56 -> 0.90958232 | AC56: =AB72 -> 0.90951099
B57: 18℃-飯糰 | C57: 一配椒鹽檸檬鯖魚飯糰 | E57: 20.72 | F57: 714 | G57: =E57*F57 -> 14794.08 | I57: 3 | J57: 3600 | K57: =J57/I57 -> 1200 | L57: 3 | M57: =F57/V57*60 -> 3274.8771 | N57: =M57/L57 -> 1091.6257 | O57: =L57-I57 -> 0 | P57: =N57-K57 -> -108.37429 | Q57: =N57/K57 -> 0.90968809 | S57: 0.27708333 | T57: 0.28615741 | U57: 13.8 | V57: 13.081407 | AA57: =M57-J57 -> -325.12286 | AB57: =M57/J57 -> 0.90968809
B58: 18℃-飯糰 | C58: 一配贅沢鮭魚肚飯糰 | E58: 30 | F58: 1016 | G58: =E58*F58 -> 30480 | I58: 4 | J58: 3600 | K58: =J58/I58 -> 900 | L58: 4 | M58: =F58/V58*60 -> 3274.6715 | N58: =M58/L58 -> 818.66788 | O58: =L58-I58 -> 0 | P58: =N58-K58 -> -81.332122 | Q58: =N58/K58 -> 0.90963098 | S58: 0.29583333 | T58: 0.30875 | U58: 13.933333 | V58: 18.615608 | AA58: =M58-J58 -> -325.32849 | AB58: =M58/J58 -> 0.90963098
B59: 18℃-飯糰 | C59: 一配卵黃牛挽肉飯糰 | E59: 24.76 | F59: 1167 | G59: =E59*F59 -> 28894.92 | I59: 4 | J59: 3600 | K59: =J59/I59 -> 900 | L59: 4 | M59: =F59/V59*60 -> 3275.0234 | N59: =M59/L59 -> 818.75585 | O59: =L59-I59 -> 0 | P59: =N59-K59 -> -81.244155 | Q59: =N59/K59 -> 0.90972872 | S59: 0.31805556 | T59: 0.33289352 | U59: 13.4 | V59: 21.38 | AA59: =M59-J59 -> -324.97662 | AB59: =M59/J59 -> 0.90972872
B60: 18℃-飯糰 | C60: 一配鹽蔥燒肉飯糰 | E60: 17.89 | F60: 2012 | G60: =E60*F60 -> 35994.68 | I60: 4 | J60: 3600 | K60: =J60/I60 -> 900 | L60: 4 | M60: =F60/V60*60 -> 3273.8026 | N60: =M60/L60 -> 818.45066 | O60: =L60-I60 -> 0 | P60: =N60-K60 -> -81.54934 | Q60: =N60/K60 -> 0.90938962 | S60: 0.34236111 | T60: 0.36796296 | U60: 13.633333 | V60: 36.87455 | AA60: =M60-J60 -> -326.19736 | AB60: =M60/J60 -> 0.90938962
B61: 18℃-飯糰 | C61: 一配醬燒炙烤牛飯糰 | E61: 22.32 | F61: 1482 | G61: =E61*F61 -> 33078.24 | I61: 5 | J61: 3600 | K61: =J61/I61 -> 720 | L61: 5 | M61: =F61/V61*60 -> 3272.8731 | N61: =M61/L61 -> 654.57463 | O61: =L61-I61 -> 0 | P61: =N61-K61 -> -65.425372 | Q61: =N61/K61 -> 0.90913143 | S61: 0.37708333 | T61: 0.39594907 | U61: 13.133333 | V61: 27.168789 | AA61: =M61-J61 -> -327.12686 | AB61: =M61/J61 -> 0.90913143
B62: 18℃-飯糰 | C62: 一配鹽蔥生鮭飯糰 | E62: 27.48 | F62: 1204 | G62: =E62*F62 -> 33085.92 | I62: 5 | J62: 3600 | K62: =J62/I62 -> 720 | L62: 5 | M62: =F62/V62*60 -> 3274.5064 | N62: =M62/L62 -> 654.90128 | O62: =L62-I62 -> 0 | P62: =N62-K62 -> -65.098715 | Q62: =N62/K62 -> 0.90958512 | S62: 0.40555556 | T62: 0.42086806 | U62: 13.833333 | V62: 22.06134 | AA62: =M62-J62 -> -325.49358 | AB62: =M62/J62 -> 0.90958512
B63: 18℃-飯糰 | C63: 一配雞肉飯飯糰 | E63: 16.66 | F63: 3732 | G63: =E63*F63 -> 62175.12 | I63: 5 | J63: 3600 | K63: =J63/I63 -> 720 | L63: 5 | M63: =F63/V63*60 -> 3273.666 | N63: =M63/L63 -> 654.73321 | O63: =L63-I63 -> 0 | P63: =N63-K63 -> -65.26679 | Q63: =N63/K63 -> 0.90935168 | S63: 0.43055556 | T63: 0.47805556 | U63: 13.95 | V63: 68.400379 | AA63: =M63-J63 -> -326.33395 | AB63: =M63/J63 -> 0.90935168
B72: 平均 | I72: =AVERAGE(I56:I71) -> 4.125 | J72: =AVERAGE(J56:J71) -> 3600 | K72: =J72/I72 -> 872.72727 | L72: =AVERAGE(L56:L71) -> 4.125 | M72: =AVERAGE(M56:M71) -> 3274.2396 | N72: =M72/L72 -> 793.75505 | O72: =L72-I72 -> 0 | P72: =N72-K72 -> -78.972223 | Q72: =N72/K72 -> 0.90951099 | S72: 0.25 | T72: 0.47805556 | AA72: =M72-J72 -> -325.76042 | AB72: =M72/J72 -> 0.90951099
A73: 自動包裝機 (二配) | B73: 18℃-飯糰 | C73: 二配兩粒飯糰(鮪魚.焦糖鮭魚) | E73: 28.57 | F73: 1007 | G73: =E73*F73 -> 28769.99 | I73: 12 | J73: 3600 | K73: =J73/I73 -> 300 | L73: 12 | M73: =F73/V73*60 -> 3119.5615 | N73: =M73/L73 -> 259.96346 | O73: =L73-I73 -> 0 | P73: =N73-K73 -> -40.03654 | Q73: =N73/K73 -> 0.86654487 | R73: =Q89 -> 0.86654487 | S73: 0.73958333 | T73: 0.75303241 | V73: 19.368107 | AA73: =M73-J73 -> -480.43848 | AB73: =M73/J73 -> 0.86654487 | AC73: =AB89 -> 0.86654487
B89: 平均 | I89: =AVERAGE(I73:I88) -> 12 | J89: =AVERAGE(J73:J88) -> 3600 | K89: =J89/I89 -> 300 | L89: =AVERAGE(L73:L88) -> 12 | M89: =AVERAGE(M73:M88) -> 3119.5615 | N89: =M89/L89 -> 259.96346 | O89: =L89-I89 -> 0 | P89: =N89-K89 -> -40.03654 | Q89: =N89/K89 -> 0.86654487 | S89: 0.73958333 | T89: 0.75303241 | AA89: =M89-J89 -> -480.43848 | AB89: =M89/J89 -> 0.86654487
A90: (新) 3300型飯糰機 (二配) | B90: 18℃-飯糰 | C90: 二配大飯糰韓式蒜烤豬五花 | E90: 24.54 | F90: 895 | G90: =E90*F90 -> 21963.3 | I90: 4 | J90: 3000 | K90: =J90/I90 -> 750 | L90: 4 | M90: =F90/V90*60 -> 2788.8526 | N90: =M90/L90 -> 697.21315 | O90: =L90-I90 -> 0 | P90: =N90-K90 -> -52.786853 | Q90: =N90/K90 -> 0.92961753 | R90: =Q106 -> 0.92961753 | S90: 0.70833333 | T90: 0.72170139 | V90: 19.255231 | AA90: =M90-J90 -> -211.14741 | AB90: =M90/J90 -> 0.92961753 | AC90: =AB106 -> 0.92961753
B106: 平均 | I106: =AVERAGE(I90:I105) -> 4 | J106: =AVERAGE(J90:J105) -> 3000 | K106: =J106/I106 -> 750 | L106: =AVERAGE(L90:L105) -> 4 | M106: =AVERAGE(M90:M105) -> 2788.8526 | N106: =M106/L106 -> 697.21315 | O106: =L106-I106 -> 0 | P106: =N106-K106 -> -52.786853 | Q106: =N106/K106 -> 0.92961753 | S106: 0.70833333 | T106: 0.72170139 | AA106: =M106-J106 -> -211.14741 | AB106: =M106/J106 -> 0.92961753
A107: GKK3600型 飯糰機 (二配) | B107: 18℃-飯糰 | C107: 二配經典肉鬆飯糰 | E107: 14.03 | F107: 335 | G107: =E107*F107 -> 4700.05 | H107: 2 | I107: 3 | J107: 3000 | K107: =J107/I107 -> 1000 | L107: 3 | M107: =F107/V107*60 -> 2792.9931 | N107: =M107/L107 -> 930.9977 | O107: =L107-I107 -> 0 | P107: =N107-K107 -> -69.002301 | Q107: =N107/K107 -> 0.9309977 | R107: =Q123 -> 0.91481526 | S107: 0.73263889 | T107: 0.73762731 | V107: 7.1965806 | AA107: =M107-J107 -> -207.0069 | AB107: =M107/J107 -> 0.9309977 | AC107: =AB123 -> 0.91481526
B108: 18℃-飯糰 | C108: 二配芝麻香鬆飯糰 | E108: 18.18 | F108: 637 | G108: =E108*F108 -> 11580.66 | H108: 2 | I108: 3 | J108: 3000 | K108: =J108/I108 -> 1000 | L108: 3 | M108: =F108/V108*60 -> 2789.4538 | N108: =M108/L108 -> 929.81794 | O108: =L108-I108 -> 0 | P108: =N108-K108 -> -70.18206 | Q108: =N108/K108 -> 0.92981794 | S108: 0.74722222 | T108: 0.75673611 | U108: 13.816667 | V108: 13.701607 | AA108: =M108-J108 -> -210.54618 | AB108: =M108/J108 -> 0.92981794
B109: 18℃-飯糰 | C109: 二配蔬食鮪魚飯糰 | E109: 18.18 | F109: 379 | G109: =E109*F109 -> 6890.22 | H109: 2 | I109: 3 | J109: 3600 | K109: =J109/I109 -> 1200 | L109: 3 | M109: =F109/V109*60 -> 3273.7567 | N109: =M109/L109 -> 1091.2522 | O109: =L109-I109 -> 0 | P109: =N109-K109 -> -108.74775 | Q109: =N109/K109 -> 0.90937687 | S109: 0.76597222 | T109: 0.77078704 | U109: 13.3 | V109: 6.9461483 | AA109: =M109-J109 -> -326.24325 | AB109: =M109/J109 -> 0.90937687
B110: 18℃-飯糰 | C110: 二配三杯醬爆菇菇飯糰 | E110: 16.7 | F110: 1103 | G110: =E110*F110 -> 18420.1 | H110: 2 | I110: 3 | J110: 3600 | K110: =J110/I110 -> 1200 | L110: 3 | M110: =F110/V110*60 -> 3275.1489 | N110: =M110/L110 -> 1091.7163 | O110: =L110-I110 -> 0 | P110: =N110-K110 -> -108.28371 | Q110: =N110/K110 -> 0.90976357 | S110: 0.77986111 | T110: 0.79388889 | U110: 13.066667 | V110: 20.206715 | AA110: =M110-J110 -> -324.85114 | AB110: =M110/J110 -> 0.90976357
...

Sheet 0930(4度C)
A1: 大溪廠日報分析 | C1: 總生產量 | D1: =SUM(F5:F140) -> 72774 | E1: 營業額 | F1: =SUM(G5:G140) -> 3184007.3 | G1: 出勤人數 | H1: =L21+L38+L55+L72+L89+L106+L123+L140 -> 137.46667 | I1: 產線配置圖 | L1: 生產實績 | O1: 人時性差異分析 | S1: 日報登錄 | Y1: 合計次數 | Z1: 合計(時間/分) | AA1: 產線異常 分析說明(5分鐘以上) | AC1: 合計次數 | AD1: 合計(時間/分) | AE1: 產能差異分析
A2: 46295 | C2: 人時性 | D2: =AVERAGE(N21,N38,N55,N72,N89,N106,N123,N140) -> 207.8655 | E2: 平均廠價 | F2: =F1/D1 -> 43.75199 | G2: 多次生產數 | H2: =COUNT(H5:H140) -> 0 | Y2: =SUM(Y21,Y38,Y55,Y72,Y89,Y106,Y123,Y140) -> 0 | Z2: =SUM(Z21,Z38,Z55,Z72,Z89,Z106,Z123,Z140) -> 0 | AC2: =SUM(AC21,AC38,AC55,AC72,AC89,AC106,AC123,AC140) -> 0 | AD2: =SUM(AD21,AD38,AD55,AD72,AD89,AD106,AD123,AD140) -> 0
A3: 線別 | B3: 品類 | C3: 品名 | E3: 廠價 | F3: 生產量 | G3: 營收 | H3: 多次 生產 | I3: 人數 | J3: 產能/時 | K3: 人時性 | L3: 人數 | M3: 產能/時 | N3: 人時性 | O3: 人數 | P3: 人時性 | Q3: 達成率 | R3: 達成率 平均 | S3: 生產時間 | U3: 換線、休息/分 | V3: 稼動時間/分 | W3: 休息時間 | Y3: 產線異常統計(5分鐘以上) | AA3: (屏榮回填) | AC3: 短暫停線統計(5分鐘以下) | AE3: 產能/時 | AF3: 達成率 | AG3: 達成率平均
S4: 開始 | T4: 結束 | W4: 開始 | X4: 結束 | Y4: 次數 | Z4: 時間/分 | AC4: 總次數 | AD4: 設備因素(次數)
A5: 便當二線 | B5: 微波小吃 | C5: 日式茶碗蒸 | E5: 19.7 | F5: 4080 | G5: =E5*F5 -> 80376 | I5: 13 | J5: 1200 | K5: =J5/I5 -> 92.307692 | L5: 13 | M5: =F5/V5*60 -> 1086.8073 | N5: =M5/L5 -> 83.600561 | O5: =L5-I5 -> 0 | P5: =N5-K5 -> -8.7071317 | Q5: =N5/K5 -> 0.90567274 | R5: =Q21 -> 0.90319083 | S5: 0.20833333 | T5: 0.36474537 | V5: 225.24693 | AE5: =M5-J5 -> -113.19271 | AF5: =M5/J5 -> 0.90567274 | AG5: =AF21 -> 0.90319083
B6: 微波主食 | C6: 糖燻野郎三十天熟成牛飯 | E6: 56.43 | F6: 4773 | G6: =E6*F6 -> 269340.39 | I6: 24 | J6: 2000 | K6: =J6/I6 -> 83.333333 | L6: 24 | M6: =F6/V6*60 -> 1804.5548 | N6: =M6/L6 -> 75.189784 | O6: =L6-I6 -> 0 | P6: =N6-K6 -> -8.1435491 | Q6: =N6/K6 -> 0.90227741 | S6: 0.36805556 | T6: 0.47825231 | U6: 4.7666667 | V6: 158.69842 | W6: 0.47825231 | X6: 0.51666667 | AE6: =M6-J6 -> -195.44518 | AF6: =M6/J6 -> 0.90227741
B7: 便當 | C7: 健身G肉餐盒 | E7: 59.52 | F7: 4734 | G7: =E7*F7 -> 281767.68 | I7: 24 | J7: 2000 | K7: =J7/I7 -> 83.333333 | L7: 24 | M7: =F7/V7*60 -> 1805.2302 | N7: =M7/L7 -> 75.217925 | O7: =L7-I7 -> 0 | P7: =N7-K7 -> -8.1154088 | Q7: =N7/K7 -> 0.90261509 | S7: 0.51666667 | T7: 0.62592593 | U7: 55.316667 | V7: 157.34282 | AE7: =M7-J7 -> -194.76981 | AF7: =M7/J7 -> 0.90261509
B21: 平均 | I21: =AVERAGE(I5:I20) -> 20.333333 | J21: =AVERAGE(J5:J20) -> 1733.3333 | K21: =J21/I21 -> 85.245902 | L21: =AVERAGE(L5:L20) -> 20.333333 | M21: =AVERAGE(M5:M20) -> 1565.5308 | N21: =M21/L21 -> 76.993316 | O21: =L21-I21 -> 0 | P21: =N21-K21 -> -8.2525853 | Q21: =N21/K21 -> 0.90319083 | S21: 0.20833333 | T21: 0.62592593 | Y21: =SUM(Y5:Y20) -> 0 | Z21: =SUM(Z5:Z20) -> 0 | AC21: =SUM(AC5:AC20) -> 0 | AD21: =SUM(AD5:AD20) -> 0 | AE21: =M21-J21 -> -167.80257 | AF21: =M21/J21 -> 0.90319083
A22: 涼麵一線 | B22: 4℃-飯糰 | C22: 里肌肉蛋紫米飯糰 | E22: 29.87 | F22: 4774 | G22: =E22*F22 -> 142599.38 | I22: 21 | J22: 2790 | K22: =J22/I22 -> 132.85714 | L22: 22 | M22: =F22/V22*60 -> 2626.6346 | N22: =M22/L22 -> 119.39248 | O22: =L22-I22 -> 1 | P22: =N22-K22 -> -13.46466 | Q22: =N22/K22 -> 0.89865309 | R22: =Q38 -> 0.90312847 | S22: 0.20833333 | T22: 0.2840625 | V22: 109.05209 | AE22: =M22-J22 -> -163.36538 | AF22: =M22/J22 -> 0.9414461 | AG22: =AF38 -> 0.92083687
B23: 4℃-飯糰 | C23: 經典傳統飯糰 | E23: 24.35 | F23: 3548 | G23: =E23*F23 -> 86393.8 | I23: 21 | J23: 2790 | K23: =J23/I23 -> 132.85714 | L23: 22 | M23: =F23/V23*60 -> 2626.6346 | N23: =M23/L23 -> 119.39248 | O23: =L23-I23 -> 1 | P23: =N23-K23 -> -13.46466 | Q23: =N23/K23 -> 0.89865309 | S23: 0.28819444 | T23: 0.34446759 | U23: 5.95 | V23: 81.046674 | AE23: =M23-J23 -> -163.36538 | AF23: =M23/J23 -> 0.9414461
B24: 4℃-壽司手卷 | C24: 海陸雙拼壽司 | E24: 36.45 | F24: 2067 | G24: =E24*F24 -> 75342.15 | I24: 20 | J24: 2100 | K24: =J24/I24 -> 105 | L24: 20 | M24: =F24/V24*60 -> 1892.0183 | N24: =M24/L24 -> 94.600917 | O24: =L24-I24 -> 0 | P24: =N24-K24 -> -10.399083 | Q24: =N24/K24 -> 0.90096112 | S24: 0.34791667 | T24: 0.39342593 | U24: 4.9666667 | V24: 65.549047 | AE24: =M24-J24 -> -207.98166 | AF24: =M24/J24 -> 0.90096112
B25: 便當 | C25: 懷舊滷雙拼便當 | E25: 61.09 | F25: 3272 | G25: =E25*F25 -> 199886.48 | I25: 20 | J25: 2000 | K25: =J25/I25 -> 100 | L25: 20 | M25: =F25/V25*60 -> 1805.2427 | N25: =M25/L25 -> 90.262133 | O25: =L25-I25 -> 0 | P25: =N25-K25 -> -9.7378669 | Q25: =N25/K25 -> 0.90262133 | S25: 0.39652778 | T25: 0.47203704 | U25: 5 | V25: 108.74992 | W25: 0.47203704 | X25: 0.51041667 | AE25: =M25-J25 -> -194.75734 | AF25: =M25/J25 -> 0.90262133
B26: 便當 | C26: 香腸腿排雙拼便當 | E26: 53.76 | F26: 3306 | G26: =E26*F26 -> 177730.56 | I26: 20 | J26: 2000 | K26: =J26/I26 -> 100 | L26: 20 | M26: =F26/V26*60 -> 1804.8444 | N26: =M26/L26 -> 90.242219 | O26: =L26-I26 -> 0 | P26: =N26-K26 -> -9.7577806 | Q26: =N26/K26 -> 0.90242219 | S26: 0.51041667 | T26: 0.58673611 | U26: 55.266667 | V26: 109.90421 | AE26: =M26-J26 -> -195.15561 | AF26: =M26/J26 -> 0.90242219
B38: 平均 | I38: =AVERAGE(I22:I37) -> 20.4 | J38: =AVERAGE(J22:J37) -> 2336 | K38: =J38/I38 -> 114.5098 | L38: =AVERAGE(L22:L37) -> 20.8 | M38: =AVERAGE(M22:M37) -> 2151.0749 | N38: =M38/L38 -> 103.41706 | O38: =L38-I38 -> 0.4 | P38: =N38-K38 -> -11.09274 | Q38: =N38/K38 -> 0.90312847 | S38: 0.20833333 | T38: 0.58673611 | Y38: =SUM(Y22:Y37) -> 0 | Z38: =SUM(Z22:Z37) -> 0 | AC38: =SUM(AC22:AC37) -> 0 | AD38: =SUM(AD22:AD37) -> 0 | AE38: =M38-J38 -> -184.92508 | AF38: =M38/J38 -> 0.92083687
A39: 涼麵二線 | B39: 便當 | C39: 蔬活腿排補力餐盒 | E39: 71.55 | F39: 2509 | G39: =E39*F39 -> 179518.95 | I39: 22 | J39: 2000 | K39: =J39/I39 -> 90.909091 | L39: 22 | M39: =F39/V39*60 -> 1808.2186 | N39: =M39/L39 -> 82.191754 | O39: =L39-I39 -> 0 | P39: =N39-K39 -> -8.7173367 | Q39: =N39/K39 -> 0.9041093 | R39: =Q55 -> 0.9033176 | S39: 0.20833333 | T39: 0.26614583 | V39: 83.253209 | AE39: =M39-J39 -> -191.78141 | AF39: =M39/J39 -> 0.9041093 | AG39: =AF55 -> 0.9033176
B40: 便當 | C40: 海陸雙拼肉肉餐盒 | E40: 59.54 | F40: 2555 | G40: =E40*F40 -> 152124.7 | I40: 23 | J40: 2000 | K40: =J40/I40 -> 86.956522 | L40: 23 | M40: =F40/V40*60 -> 1807.8274 | N40: =M40/L40 -> 78.601191 | O40: =L40-I40 -> 0 | P40: =N40-K40 -> -8.3553309 | Q40: =N40/K40 -> 0.90391369 | S40: 0.26944444 | T40: 0.32832176 | U40: 4.75 | V40: 84.797919 | AE40: =M40-J40 -> -192.17261 | AF40: =M40/J40 -> 0.90391369
B41: 便當 | C41: 烤蛋白餐盒 | E41: 58.67 | F41: 3633 | G41: =E41*F41 -> 213148.11 | I41: 23 | J41: 2000 | K41: =J41/I41 -> 86.956522 | L41: 23 | M41: =F41/V41*60 -> 1804.1094 | N41: =M41/L41 -> 78.439537 | O41: =L41-I41 -> 0 | P41: =N41-K41 -> -8.5169842 | Q41: =N41/K41 -> 0.90205468 | S41: 0.33125 | T41: 0.41515046 | U41: 5 | V41: 120.82416 | AE41: =M41-J41 -> -195.89064 | AF41: =M41/J41 -> 0.90205468
B42: 便當 | C42: 香烤鱈魚輕蔬餐盒 | E42: 69.26 | F42: 629 | G42: =E42*F42 -> 43564.54 | I42: 24 | J42: 2000 | K42: =J42/I42 -> 83.333333 | L42: 24 | M42: =F42/V42*60 -> 1804.7152 | N42: =M42/L42 -> 75.196466 | O42: =L42-I42 -> 0 | P42: =N42-K42 -> -8.1368669 | Q42: =N42/K42 -> 0.9023576 | S42: 0.41805556 | T42: 0.43256944 | U42: 5 | V42: 20.911887 | W42: 0.43256944 | X42: 0.47152778 | AE42: =M42-J42 -> -195.28481 | AF42: =M42/J42 -> 0.9023576
B43: 便當 | C43: 地中海布格麥烤魚餐盒 | E43: 63.92 | F43: 1254 | G43: =E43*F43 -> 80155.68 | I43: 24 | J43: 2000 | K43: =J43/I43 -> 83.333333 | L43: 24 | M43: =F43/V43*60 -> 1808.3054 | N43: =M43/L43 -> 75.34606 | O43: =L43-I43 -> 0 | P43: =N43-K43 -> -7.9872734 | Q43: =N43/K43 -> 0.90415272 | S43: 0.47152778 | T43: 0.50041667 | U43: 56.1 | V43: 41.608015 | AE43: =M43-J43 -> -191.69456 | AF43: =M43/J43 -> 0.90415272
B55: 平均 | I55: =AVERAGE(I39:I54) -> 23.2 | J55: =AVERAGE(J39:J54) -> 2000 | K55: =J55/I55 -> 86.206897 | L55: =AVERAGE(L39:L54) -> 23.2 | M55: =AVERAGE(M39:M54) -> 1806.6352 | N55: =M55/L55 -> 77.872207 | O55: =L55-I55 -> 0 | P55: =N55-K55 -> -8.3346899 | Q55: =N55/K55 -> 0.9033176 | S55: 0.20833333 | T55: 0.50041667 | Y55: =SUM(Y39:Y54) -> 0 | Z55: =SUM(Z39:Z54) -> 0 | AC55: =SUM(AC39:AC54) -> 0 | AD55: =SUM(AD39:AD54) -> 0 | AE55: =M55-J55 -> -193.3648 | AF55: =M55/J55 -> 0.9033176
A56: 涼麵三線 | B56: 季節調理麵 | C56: 和風涓絲冷麵 | E56: 28.86 | F56: 1394 | G56: =E56*F56 -> 40230.84 | I56: 18 | J56: 3600 | K56: =J56/I56 -> 200 | L56: 18 | M56: =F56/V56*60 -> 3195.3135 | N56: =M56/L56 -> 177.51742 | O56: =L56-I56 -> 0 | P56: =N56-K56 -> -22.482585 | Q56: =N56/K56 -> 0.88758708 | R56: =Q72 -> 0.89628511 | S56: 0.25 | T56: 0.2681713 | V56: 26.175836 | AE56: =M56-J56 -> -404.68653 | AF56: =M56/J56 -> 0.88758708 | AG56: =AF72 -> 0.89628511
B57: 季節調理麵 | C57: 韓式泡菜冷麵 | E57: 36.73 | F57: 811 | G57: =E57*F57 -> 29788.03 | I57: 21 | J57: 3600 | K57: =J57/I57 -> 171.42857 | L57: 21 | M57: =F57/V57*60 -> 3196.3256 | N57: =M57/L57 -> 152.20598 | O57: =L57-I57 -> 0 | P57: =N57-K57 -> -19.22259 | Q57: =N57/K57 -> 0.88786822 | S57: 0.27152778 | T57: 0.28209491 | U57: 4.8333333 | V57: 15.223731 | AE57: =M57-J57 -> -403.67439 | AF57: =M57/J57 -> 0.88786822
B58: 季節調理麵 | C58: 大滿足麻醬涼麵 | E58: 37.8 | F58: 4031 | G58: =E58*F58 -> 152371.8 | I58: 20 | J58: 3600 | K58: =J58/I58 -> 180 | L58: 20 | M58: =F58/V58*60 -> 3270.0889 | N58: =M58/L58 -> 163.50445 | O58: =L58-I58 -> 0 | P58: =N58-K58 -> -16.495554 | Q58: =N58/K58 -> 0.90835803 | S58: 0.28611111 | T58: 0.33746528 | U58: 5.7833333 | V58: 73.961292 | AE58: =M58-J58 -> -329.91108 | AF58: =M58/J58 -> 0.90835803
B59: 季節調理麵 | C59: 大滿足香辣涼麵 | E59: 38.48 | F59: 3235 | G59: =E59*F59 -> 124482.8 | I59: 19 | J59: 3600 | K59: =J59/I59 -> 189.47368 | L59: 19 | M59: =F59/V59*60 -> 3261.24 | N59: =M59/L59 -> 171.64421 | O59: =L59-I59 -> 0 | P59: =N59-K59 -> -17.829474 | Q59: =N59/K59 -> 0.9059 | S59: 0.34027778 | T59: 0.3816088 | U59: 5 | V59: 59.517239 | AE59: =M59-J59 -> -338.76 | AF59: =M59/J59 -> 0.9059
B60: 4℃-飯糰 | C60: 麻油雞飯糰 | E60: 29.97 | F60: 2133 | G60: =E60*F60 -> 63926.01 | I60: 21 | J60: 2790 | K60: =J60/I60 -> 132.85714 | L60: 21 | M60: =F60/V60*60 -> 2484.1731 | N60: =M60/L60 -> 118.29396 | O60: =L60-I60 -> 0 | P60: =N60-K60 -> -14.563187 | Q60: =N60/K60 -> 0.89038462 | S60: 0.38541667 | T60: 0.42119213 | U60: 5.4833333 | V60: 51.51815 | AE60: =M60-J60 -> -305.82692 | AF60: =M60/J60 -> 0.89038462
B72: 平均 | I72: =AVERAGE(I56:I71) -> 19.8 | J72: =AVERAGE(J56:J71) -> 3438 | K72: =J72/I72 -> 173.63636 | L72: =AVERAGE(L56:L71) -> 19.8 | M72: =AVERAGE(M56:M71) -> 3081.4282 | N72: =M72/L72 -> 155.62769 | O72: =L72-I72 -> 0 | P72: =N72-K72 -> -18.008676 | Q72: =N72/K72 -> 0.89628511 | S72: 0.25 | T72: 0.42119213 | Y72: =SUM(Y56:Y71) -> 0 | Z72: =SUM(Z56:Z71) -> 0 | AC72: =SUM(AC56:AC71) -> 0 | AD72: =SUM(AD56:AD71) -> 0 | AE72: =M72-J72 -> -356.57179 | AF72: =M72/J72 -> 0.89628511
A73: 自動包裝機 | B73: 4℃-壽司手卷 | C73: 生菜鮮蝦脆卷 | E73: 22.83 | F73: 2204 | G73: =E73*F73 -> 50317.32 | I73: 6 | J73: 2500 | K73: =J73/I73 -> 416.66667 | L73: 6 | M73: =F73/V73*60 -> 2263.1316 | N73: =M73/L73 -> 377.18859 | O73: =L73-I73 -> 0 | P73: =N73-K73 -> -39.478074 | Q73: =N73/K73 -> 0.90525262 | R73: =Q89 -> 0.90568923 | S73: 0.34375 | T73: 0.38431713 | U73: 5 | V73: 58.432308 | AE73: =M73-J73 -> -236.86844 | AF73: =M73/J73 -> 0.90525262 | AG73: =AF89 -> 0.90568923
B74: 4℃-壽司手卷 | C74: 蔥花生鮪魚脆卷 | E74: 23.19 | F74: 668 | G74: =E74*F74 -> 15490.92 | I74: 6 | J74: 2500 | K74: =J74/I74 -> 416.66667 | L74: 6 | M74: =F74/V74*60 -> 2263.8385 | N74: =M74/L74 -> 377.30642 | O74: =L74-I74 -> 0 | P74: =N74-K74 -> -39.360246 | Q74: =N74/K74 -> 0.90553541 | S74: 0.38819444 | T74: 0.40048611 | U74: 5.5833333 | V74: 17.704443 | AE74: =M74-J74 -> -236.16147 | AF74: =M74/J74 -> 0.90553541
B75: 4℃-壽司手卷 | C75: 香濃明太子嫩雞飯卷 | E75: 35.89 | F75: 1715 | G75: =E75*F75 -> 61551.35 | I75: 5 | J75: 3273 | K75: =J75/I75 -> 654.6 | L75: 5 | M75: =F75/V75*60 -> 2965.7969 | N75: =M75/L75 -> 593.15939 | O75: =L75-I75 -> 0 | P75: =N75-K75 -> -61.440612 | Q75: =N75/K75 -> 0.90614022 | S75: 0.40416667 | T75: 0.42825231 | U75: 5.3 | V75: 34.695565 | AE75: =M75-J75 -> -307.20306 | AF75: =M75/J75 -> 0.90614022
B89: 平均 | I89: =AVERAGE(I73:I88) -> 5.6666667 | J89: =AVERAGE(J73:J88) -> 2757.6667 | K89: =J89/I89 -> 486.64706 | L89: =AVERAGE(L73:L88) -> 5.6666667 | M89: =AVERAGE(M73:M88) -> 2497.589 | N89: =M89/L89 -> 440.751 | O89: =L89-I89 -> 0 | P89: =N89-K89 -> -45.896058 | Q89: =N89/K89 -> 0.90568923 | S89: 0.20833333 | T89: 0.42825231 | Y89: =SUM(Y73:Y88) -> 0 | Z89: =SUM(Z73:Z88) -> 0 | AC89: =SUM(AC73:AC88) -> 0 | AD89: =SUM(AD73:AD88) -> 0 | AE89: =M89-J89 -> -260.07766 | AF89: =M89/J89 -> 0.90568923
A90: 自動包裝機2 | B90: 4℃-壽司手卷 | C90: 鮪魚昆布細卷 | E90: 15.51 | F90: 2123 | G90: =E90*F90 -> 32927.73 | I90: 6 | J90: 4200 | K90: =J90/I90 -> 700 | L90: 6 | M90: =F90/V90*60 -> 3796.8829 | N90: =M90/L90 -> 632.81382 | O90: =L90-I90 -> 0 | P90: =N90-K90 -> -67.186176 | Q90: =N90/K90 -> 0.90401975 | R90: =Q106 -> 0.90436291 | S90: 0.25 | T90: 0.27328704 | V90: 33.548572 | AE90: =M90-J90 -> -403.11706 | AF90: =M90/J90 -> 0.90401975 | AG90: =AF106 -> 0.90436291
B91: 4℃-壽司手卷 | C91: 肉鬆火腿細卷 | E91: 15.01 | F91: 2192 | G91: =E91*F91 -> 32901.92 | I91: 6 | J91: 4200 | K91: =J91/I91 -> 700 | L91: 6 | M91: =F91/V91*60 -> 3799.7655 | N91: =M91/L91 -> 633.29425 | O91: =L91-I91 -> 0 | P91: =N91-K91 -> -66.705751 | Q91: =N91/K91 -> 0.90470607 | S91: 0.27708333 | T91: 0.30111111 | U91: 5.4666667 | V91: 34.612662 | AE91: =M91-J91 -> -400.23451 | AF91: =M91/J91 -> 0.90470607
B106: 平均 | I106: =AVERAGE(I90:I105) -> 6 | J106: =AVERAGE(J90:J105) -> 4200 | K106: =J106/I106 -> 700 | L106: =AVERAGE(L90:L105) -> 6 | M106: =AVERAGE(M90:M105) -> 3798.3242 | N106: =M106/L106 -> 633.05404 | O106: =L106-I106 -> 0 | P106: =N106-K106 -> -66.945964 | Q106: =N106/K106 -> 0.90436291 | S106: 0.25 | T106: 0.30111111 | Y106: =SUM(Y90:Y105) -> 0 | Z106: =SUM(Z90:Z105) -> 0 | AC106: =SUM(AC90:AC105) -> 0 | AD106: =SUM(AD90:AD105) -> 0 | AE106: =M106-J106 -> -401.67578 | AF106: =M106/J106 -> 0.90436291
A107: 便當二線 (二配) | B107: 微波主食 | C107: 二配香烤魚排青醬燉飯 | E107: 58.17 | F107: 1636 | G107: =E107*F107 -> 95166.12 | I107: 18 | J107: 2000 | K107: =J107/I107 -> 111.11111 | L107: 17 | M107: =F107/V107*60 -> 1805.6 | N107: =M107/L107 -> 106.21176 | O107: =L107-I107 -> -1 | P107: =N107-K107 -> -4.8993464 | Q107: =N107/K107 -> 0.95590588 | R107: =Q123 -> 0.95151548 | S107: 0.70833333 | T107: 0.74607639 | V107: 54.3642 | AE107: =M107-J107 -> -194.4 | AF107: =M107/J107 -> 0.9028 | AG107: =AF123 -> 0.90313333
B108: 微波主食 | C108: 二配濃起司燻腸紅醬焗烤飯 | E108: 50.67 | F108: 1912 | G108: =E108*F108 -> 96881.04 | I108: 20 | J108: 2000 | K108: =J108/I108 -> 100 | L108: 19 | M108: =F108/V108*60 -> 1806.4 | N108: =M108/L108 -> 95.073684 | O108: =L108-I108 -> -1 | P108: =N108-K108 -> -4.9263158 | Q108: =N108/K108 -> 0.95073684 | S108: 0.74930556 | T108: 0.79340278 | U108: 4.65 | V108: 63.507529 | AE108: =M108-J108 -> -193.6 | AF108: =M108/J108 -> 0.9032
B109: 微波主食 | C109: 二配西班牙風味海鮮燉飯 | E109: 57.3 | F109: 1312 | G109: =E109*F109 -> 75177.6 | I109: 21 | J109: 2000 | K109: =J109/I109 -> 95.238095 | L109: 20 | M109: =F109/V109*60 -> 1806.8 | N109: =M109/L109 -> 90.34 | O109: =L109-I109 -> -1 | P109: =N109-K109 -> -4.8980952 | Q109: =N109/K109 -> 0.94857 | S109: 0.79652778 | T109: 0.82678241 | U109: 5 | V109: 43.56874 | AE109: =M109-J109 -> -193.2 | AF109: =M109/J109 -> 0.9034
B123: 平均 | I123: =AVERAGE(I107:I122) -> 19.666667 | J123: =AVERAGE(J107:J122) -> 2000 | K123: =J123/I123 -> 101.69492 | L123: =AVERAGE(L107:L122) -> 18.666667 | M123: =AVERAGE(M107:M122) -> 1806.2667 | N123: =M123/L123 -> 96.764286 | O123: =L123-I123 -> -1 | P123: =N123-K123 -> -4.9306295 | Q123: =N123/K123 -> 0.95151548 | S123: 0.70833333 | T123: 0.82678241 | Y123: =SUM(Y107:Y122) -> 0 | Z123: =SUM(Z107:Z122) -> 0 | AC123: =SUM(AC107:AC122) -> 0 | AD123: =SUM(AD107:AD122) -> 0 | AE123: =M123-J123 -> -193.73333 | AF123: =M123/J123 -> 0.90313333
A124: 涼麵一線 (二配) | B124: 微波主食 | C124: 二配黃金雞排蘑菇白醬歐姆蛋飯 | E124: 56.87 | F124: 1509 | G124: =E124*F124 -> 85816.83 | I124: 23 | J124: 2000 | K124: =J124/I124 -> 86.956522 | L124: 23 | M124: =F124/V124*60 -> 1803.8186 | N124: =M124/L124 -> 78.426894 | O124: =L124-I124 -> 0 | P124: =N124-K124 -> -8.5296276 | Q124: =N124/K124 -> 0.90190928 | R124: =Q140 -> 0.90211063 | S124: 0.70833333 | T124: 0.74318287 | V124: 50.193518 | AE124: =M124-J124 -> -196.18144 | AF124: =M124/J124 -> 0.90190928 | AG124: =AF140 -> 0.90211063
B125: 微波主食 | C125: 二配里肌豬排可可咖哩歐姆蛋飯 | E125: 56.79 | F125: 1982 | G125: =E125*F125 -> 112557.78 | I125: 23 | J125: 2000 | K125: =J125/I125 -> 86.956522 | L125: 23 | M125: =F125/V125*60 -> 1801.9667 | N125: =M125/L125 -> 78.346379 | O125: =L125-I125 -> 0 | P125: =N125-K125 -> -8.6101426 | Q125: =N125/K125 -> 0.90098336 | S125: 0.74722222 | T125: 0.79304398 | U125: 5.8166667 | V125: 65.99456 | AE125: =M125-J125 -> -198.03328 | AF125: =M125/J125 -> 0.90098336
B126: 微波主食 | C126: 二配起司棉被海陸白醬焗烤飯 | E126: 47.6 | F126: 2783 | G126: =E126*F126 -> 132470.8 | I126: 23 | J126: 2000 | K126: =J126/I126 -> 86.956522 | L126: 23 | M126: =F126/V126*60 -> 1806.8785 | N126: =M126/L126 -> 78.559935 | O126: =L126-I126 -> 0 | P126: =N126-K126 -> -8.3965867 | Q126: =N126/K126 -> 0.90343925 | S126: 0.79652778 | T126: 0.86069444 | U126: 5.0166667 | V126: 92.413518 | AE126: =M126-J126 -> -193.12149 | AF126: =M126/J126 -> 0.90343925
...

Sheet 0929
B1: 屏榮 大溪廠組合室生產人時性分析
B3: 日期 | C3: 115.09.29星期二 | E3: 訂單量 | F3: ='0929(18度C)'!D1+'0929(4度C)'!D1 -> 154969 | H3: 營業額 | I3: ='0929(18度C)'!F1+'0929(4度C)'!F1 -> 4813434.3
B4: 人時性 | C4: 項目 | E4: ➀ | G4: ➁ | I4: ➂ | K4: ④ | M4: ⑤ | O4: 異常停線 | Q4: 短暫停線
C5: 組合室 | E5: 全溫層 | G5: 4度C-各編組展開(一配) | I5: 4度C-各編組展開(二配) | K5: 18度C-各編組展開(一配) | M5: 18度C-各編組展開(二配) | O5: 合計次數 | P5: 時間 | Q5: 合計次數 | R5: 設備次數
C6: 排關平均 | E6: =AVERAGE(D14:O14,D32:X32) -> 473.31811 | F6: =AVERAGE(#REF!,D14:K14) -> #REF! | G6: =AVERAGE(D14:K14) -> 274.37434 | I6: =AVERAGE(L14:O14) -> 94.325718 | K6: =AVERAGE(D32:O32) -> 716.27883 | M6: =AVERAGE(P32:X32) -> 718.26923 | O6: ='0929(4度C)'!Y2 -> 0 | P6: ='0929(4度C)'!Z2 -> 0 | Q6: ='0929(4度C)'!AC2 -> 0 | R6: ='0929(4度C)'!AD2 -> 0
C7: 實績平均 | E7: =AVERAGE(D15:O15,D33:X33) -> 428.77247 | F7: =AVERAGE(#REF!,D15:K15) -> #REF! | G7: =AVERAGE(D15:K15) -> 248.00466 | I7: =AVERAGE(L15:O15) -> 87.580794 | K7: =AVERAGE(D33:O33) -> 644.55583 | M7: =AVERAGE(P33:X33) -> 654.73666
C8: 達成率平均 | E8: =AVERAGE(D16:O16,D34:X34) -> 0.90405811 | F8: =AVERAGE(D16:K16,#REF!) -> #REF! | G8: =AVERAGE(D16:K16) -> 0.9026874 | I8: =AVERAGE(L16:O16) -> 0.92658389 | K8: =AVERAGE(D34:O34) -> 0.89413042 | M8: =AVERAGE(P34:X34) -> 0.90477899
O9: ※現行日本鮮食廠以達成率80%為基本(即為現行KPI)
B11: 溫層 | D11: ➁4度C-各編組展開 | L11: ➂4度C-各編組展開
B12: 編組 | D12: 1 | E12: 2 | F12: 3 | G12: 4 | H12: 5 | I12: 6 | J12: 7 | K12: 8 | L12: 1 | M12: 2 | N12: 3 | O12: 4
D13: 便當一線 | E13: 便當二線 | F13: 涼麵一線 | G13: 涼麵二線 | H13: 涼麵三線 | I13: 自動包裝機 | J13: 自動包裝機2 | K13: 自動包裝機3 | L13: 便當一線 | M13: 便當二線 | N13: 涼麵一線 | O13: 涼麵二線
B14: 人時性 | C14: 排關 | D14: - | E14: 85.245902 | F14: 114.5098 | G14: 86.206897 | H14: 173.63636 | I14: 486.64706 | J14: 700 | K14: - | L14: - | M14: 101.69492 | N14: 86.956522 | O14: -
C15: 實績 | D15: - | E15: 76.97889 | F15: 103.40928 | G15: 77.854965 | H15: 155.65013 | I15: 440.73068 | J15: 633.40404 | K15: - | L15: - | M15: 96.714286 | N15: 78.447301 | O15: -
C16: 達成率 | D16: - | E16: =E15/E14 -> 0.9030216 | F16: =F15/F14 -> 0.90306045 | G16: =G15/G14 -> 0.9031176 | H16: =H15/H14 -> 0.89641436 | I16: =I15/I14 -> 0.90564748 | J16: =J15/J14 -> 0.90486291 | K16: - | L16: - | M16: =M15/M14 -> 0.95102381 | N16: =N15/N14 -> 0.90214397 | O16: -
B17: 作業 時間 | C17: 開始 | D17: - | E17: 0.20833333 | F17: 0.20833333 | G17: 0.20833333 | H17: 0.25 | I17: 0.20833333 | J17: 0.25 | K17: - | L17: - | M17: 0.70833333 | N17: 0.70833333 | O17: -
C18: 結束 | D18: - | E18: 0.60071759 | F18: 0.56211806 | G18: 0.51221065 | H18: 0.43226852 | I18: 0.45108796 | J18: 0.30402778 | K18: - | L18: - | M18: 0.82222222 | N18: 0.86631944 | O18: -
B19: 產線異常 (5分鐘以上) | C19: 次數
C20: 時間/分
B21: 短暫停線 (5分鐘以下) | C21: 次數
C22: 設備次數
B23: 配置人數 | D23: - | E23: 20.333333 | F23: 20.8 | G23: 23.2 | H23: 19.8 | I23: 5.6666667 | J23: 6 | K23: - | L23: - | M23: 18.666667 | N23: 23 | O23: -
B24: 主要應用設備 | D24: L型封口機 | E24: ET-55 | F24: ET-55 | G24: ET-55 | H24: ET-600 | I24: 伺服包裝機 | J24: 伺服包裝機 | K24: 伺服包裝機 | L24: L型封口機 | M24: ET-55 | N24: ET-55 | O24: ET-55
B25: 次要應用設備 | D25: 伺服包裝機 | H25: 伺服包裝機
B26: 備註 | H26: 涼麵+烤飯糰 | I26: 大口飯糰線 | K26: 烤飯糰+手卷
B29: 溫層 | D29: ➃18度C-各編組展開 (一配) | P29: ⑤18度C-各編組展開 (二配)
B30: 編組 | D30: 1 | E30: 2 | F30: 3 | G30: 4 | H30: 5 | I30: 6 | J30: 7 | K30: 8 | L30: 9 | M30: 10 | N30: 11 | O30: 12 | P30: 1 | Q30: 2 | R30: 3 | S30: 4 | T30: 5 | U30: 6 | V30: 7 | W30: 8 | X30: 9
D31: 便當一線 | E31: 涼麵一線 | F31: 涼麵三線 | G31: 自動包裝機 | H31: 自動包裝機2 | I31: 自動包裝機3 | J31: 味付飯糰線B | K31: (舊) 3300型飯糰線 | L31: 3000型飯糰線 | M31: (新) 3300型飯糰機 | N31: GKK3600型 飯糰機 | O31: GKK3600型 飯糰機2 | P31: 自動包裝機 | Q31: 自動包裝機2 | R31: 自動包裝機3 | S31: 味付飯糰線B | T31: (舊) 3300型飯糰線 | U31: 3000型飯糰線 | V31: (新) 3300型飯糰機 | W31: GKK3600型 飯糰機 | X31: GKK3600型 飯糰機2
B32: 人時性 | C32: 排關 | D32: - | E32: - | F32: - | G32: 322.38806 | H32: - | I32: - | J32: - | K32: - | L32: - | M32: 750 | N32: 920 | O32: 872.72727 | P32: 300 | Q32: - | R32: - | S32: - | T32: - | U32: - | V32: 750 | W32: 923.07692 | X32: 900
C33: 實績 | D33: - | E33: - | F33: - | G33: 280.0182 | H33: - | I33: - | J33: - | K33: - | L33: - | M33: 662.43891 | N33: 842.78673 | O33: 792.97948 | P33: 259.96346 | Q33: - | R33: - | S33: - | T33: - | U33: - | V33: 697.13815 | W33: 843.87327 | X33: 817.97175
C34: 達成率 | D34: - | E34: - | F34: - | G34: =G33/G32 -> 0.86857496 | H34: - | I34: - | J34: - | K34: - | L34: - | M34: =M33/M32 -> 0.88325188 | N34: =N33/N32 -> 0.91607253 | O34: =O33/O32 -> 0.90862232 | P34: =P33/P32 -> 0.86654487 | Q34: - | R34: - | S34: - | T34: - | U34: - | V34: =V33/V32 -> 0.92951753 | W34: =W33/W32 -> 0.91419604 | X34: =X33/X32 -> 0.90885751
B35: 作業 時間 | C35: 開始 | D35: - | E35: - | F35: - | G35: 0.20833333 | H35: - | I35: - | J35: - | K35: - | L35: - | M35: 0.32083333 | N35: 0.25 | O35: 0.25 | P35: 0.73958333 | Q35: - | R35: - | S35: - | T35: - | U35: - | V35: 0.70833333 | W35: 0.73263889 | X35: 0.73263889
C36: 結束 | D36: - | E36: - | F36: - | G36: 0.45108796 | H36: - | I36: - | J36: - | K36: - | L36: - | M36: 0.41805556 | N36: 0.49387731 | O36: 0.48483796 | P36: 0.75293981 | Q36: - | R36: - | S36: - | T36: - | U36: - | V36: 0.72189815 | W36: 1.1151852 | X36: 1.107581
B37: 配置人數 | D37: - | E37: - | F37: - | G37: 11.166667 | H37: - | I37: - | J37: - | K37: - | L37: - | M37: 4 | N37: 3.75 | O37: 4.125 | P37: 12 | Q37: - | R37: - | S37: - | T37: - | U37: - | V37: 4 | W37: 3.7142857 | X37: 4
B38: 主要應用設備 | D38: 伺服包裝機 | E38: ET-55 | F38: ET-600 | G38: 夾心型 | H38: 伺服包裝機 | I38: 伺服包裝機 | J38: 夾心型 | K38: 3300型 | L38: 3300型 | M38: 3300型 | N38: GKK | O38: GKK | P38: 夾心型 | Q38: 伺服包裝機 | R38: 伺服包裝機 | S38: 夾心型 | T38: 3300型 | U38: 3300型 | V38: 3300型 | W38: GKK | X38: GKK
B39: 次要應用設備
B40: 備註

Sheet 0929(18度C)
A1: 大溪廠日報分析 | C1: 總生產量 | D1: =SUM(F5:F140) -> 82755 | E1: 營業額 | F1: =SUM(G5:G140) -> 1668399.6 | G1: 出勤人數 | H1: =L21+L38+L55+L72+L89+L106+L123+L140 -> 46.755952 | I1: 產線配置圖 | L1: 生產實績 | O1: 人時性差異分析 | S1: 日報登錄 | Y1: 分析說明 | AA1: 產能差異分析
A2: 46294 | C2: 人時性 | D2: =AVERAGE(N21,N38,N55,N72,N89,N106,N123,N140) -> 649.64624 | E2: 平均廠價 | F2: =F1/D1 -> 20.16071 | G2: 多次生產數 | H2: =COUNT(H5:H140) -> 14
A3: 線別 | B3: 品類 | C3: 品名 | E3: 廠價 | F3: 生產量 | G3: 營收 | H3: 多次 生產 | I3: 人數 | J3: 產能/時 | K3: 人時性 | L3: 人數 | M3: 產能/時 | N3: 人時性 | O3: 人數 | P3: 人時性 | Q3: 達成率 | R3: 達成率 平均 | S3: 生產時間 | U3: 換線、休息/分 | V3: 稼動時間/分 | W3: 休息時間 | Y3: (屏榮回填) | AA3: 產能/時 | AB3: 達成率 | AC3: 達成率平均
S4: 開始 | T4: 結束 | W4: 開始 | X4: 結束
A5: 自動包裝機 | B5: 18℃-壽司手卷 | C5: 一配長野稻荷壽司 | E5: 25.64 | F5: 1162 | G5: =E5*F5 -> 29793.68 | I5: 10 | J5: 3600 | K5: =J5/I5 -> 360 | L5: 10 | M5: =F5/V5*60 -> 3217.2496 | N5: =M5/L5 -> 321.72496 | O5: =L5-I5 -> 0 | P5: =N5-K5 -> -38.275045 | Q5: =N5/K5 -> 0.89368043 | R5: =Q21 -> 0.86857496 | S5: 0.20833333 | T5: 0.22337963 | V5: 21.670685 | AA5: =M5-J5 -> -382.75045 | AB5: =M5/J5 -> 0.89368043 | AC5: =AB21 -> 0.86857496
B6: 18℃-壽司手卷 | C6: 一配經典人氣雙手卷 | E6: 29.52 | F6: 1956 | G6: =E6*F6 -> 57741.12 | I6: 11 | J6: 3600 | K6: =J6/I6 -> 327.27273 | L6: 11 | M6: =F6/V6*60 -> 3155.7235 | N6: =M6/L6 -> 286.88395 | O6: =L6-I6 -> 0 | P6: =N6-K6 -> -40.388774 | Q6: =N6/K6 -> 0.87658986 | S6: 0.22708333 | T6: 0.25290509 | U6: 5.3333333 | V6: 37.18957 | AA6: =M6-J6 -> -444.27651 | AB6: =M6/J6 -> 0.87658986
B7: 18℃-壽司手卷 | C7: 一配鮭鮪海饌雙手卷 | E7: 29.85 | F7: 2357 | G7: =E7*F7 -> 70356.45 | I7: 11 | J7: 3600 | K7: =J7/I7 -> 327.27273 | L7: 11 | M7: =F7/V7*60 -> 3156.8314 | N7: =M7/L7 -> 286.98468 | O7: =L7-I7 -> 0 | P7: =N7-K7 -> -40.288051 | Q7: =N7/K7 -> 0.87689762 | S7: 0.25625 | T7: 0.28734954 | U7: 4.8166667 | V7: 44.798084 | AA7: =M7-J7 -> -443.16856 | AB7: =M7/J7 -> 0.87689762
B8: 18℃-壽司手卷 | C8: 一配青木瓜雞絲泰泰雙手卷 | E8: 30 | F8: 196 | G8: =E8*F8 -> 5880 | I8: 11 | J8: 3600 | K8: =J8/I8 -> 327.27273 | L8: 11 | M8: =F8/V8*60 -> 3155.5473 | N8: =M8/L8 -> 286.86794 | O8: =L8-I8 -> 0 | P8: =N8-K8 -> -40.404792 | Q8: =N8/K8 -> 0.87654091 | S8: 0.29097222 | T8: 0.29355324 | U8: 5.2166667 | V8: 3.7267703 | AA8: =M8-J8 -> -444.45271 | AB8: =M8/J8 -> 0.87654091
B9: 18℃-壽司手卷 | C9: 一配陽光蔬彩雙手卷 | E9: 30.95 | F9: 3534 | G9: =E9*F9 -> 109377.3 | I9: 12 | J9: 3600 | K9: =J9/I9 -> 300 | L9: 12 | M9: =F9/V9*60 -> 2952 | N9: =M9/L9 -> 246 | O9: =L9-I9 -> 0 | P9: =N9-K9 -> -54 | Q9: =N9/K9 -> 0.82 | S9: 0.29652778 | T9: 0.34640046 | U9: 5 | V9: 71.829268 | AA9: =M9-J9 -> -648 | AB9: =M9/J9 -> 0.82
B10: 18℃-飯糰 | C10: 一配兩粒飯糰(鮪魚.焦糖鮭魚) | E10: 28.57 | F10: 790 | G10: =E10*F10 -> 22570.3 | I10: 12 | J10: 3600 | K10: =J10/I10 -> 300 | L10: 12 | M10: =F10/V10*60 -> 3123.8675 | N10: =M10/L10 -> 260.32229 | O10: =L10-I10 -> 0 | P10: =N10-K10 -> -39.677712 | Q10: =N10/K10 -> 0.86774096 | S10: 0.34930556 | T10: 0.35983796 | U10: 5 | V10: 15.173499 | AA10: =M10-J10 -> -476.13254 | AB10: =M10/J10 -> 0.86774096
B21: 平均 | I21: =AVERAGE(I5:I20) -> 11.166667 | J21: =AVERAGE(J5:J20) -> 3600 | K21: =J21/I21 -> 322.38806 | L21: =AVERAGE(L5:L20) -> 11.166667 | M21: =AVERAGE(M5:M20) -> 3126.8699 | N21: =M21/L21 -> 280.0182 | O21: =L21-I21 -> 0 | P21: =N21-K21 -> -42.369862 | Q21: =N21/K21 -> 0.86857496 | S21: 0.20833333 | T21: 0.45108796 | AA21: =M21-J21 -> -473.13013 | AB21: =M21/J21 -> 0.86857496
A22: (新) 3300型飯糰機 | B22: 18℃-飯糰 | C22: 一配鮭魚奶油醬油飯糰 | E22: 18.53 | F22: 1497 | G22: =E22*F22 -> 27739.41 | I22: 3 | J22: 3300 | K22: =J22/I22 -> 1100 | L22: 3 | M22: =F22/V22*60 -> 3069.3369 | N22: =M22/L22 -> 1023.1123 | O22: =L22-I22 -> 0 | P22: =N22-K22 -> -76.887716 | Q22: =N22/K22 -> 0.93010208 | R22: =Q38 -> 0.88325188 | S22: 0.32083333 | T22: 0.34114583 | V22: 29.26365 | AA22: =M22-J22 -> -230.66315 | AB22: =M22/J22 -> 0.93010208 | AC22: =AB38 -> 0.88325188
B23: 18℃-飯糰 | C23: 一配熊本麥味噌雞肉飯糰 | E23: 22.95 | F23: 3940 | G23: =E23*F23 -> 90423 | I23: 5 | J23: 2700 | K23: =J23/I23 -> 540 | L23: 5 | M23: =F23/V23*60 -> 2230.1744 | N23: =M23/L23 -> 446.03488 | O23: =L23-I23 -> 0 | P23: =N23-K23 -> -93.965115 | Q23: =N23/K23 -> 0.82599053 | S23: 0.34444444 | T23: 0.41805556 | U23: 4.75 | V23: 106.00068 | AA23: =M23-J23 -> -469.82558 | AB23: =M23/J23 -> 0.82599053
B38: 平均 | I38: =AVERAGE(I22:I37) -> 4 | J38: =AVERAGE(J22:J37) -> 3000 | K38: =J38/I38 -> 750 | L38: =AVERAGE(L22:L37) -> 4 | M38: =AVERAGE(M22:M37) -> 2649.7556 | N38: =M38/L38 -> 662.43891 | O38: =L38-I38 -> 0 | P38: =N38-K38 -> -87.56109 | Q38: =N38/K38 -> 0.88325188 | S38: 0.32083333 | T38: 0.41805556 | AA38: =M38-J38 -> -350.24436 | AB38: =M38/J38 -> 0.88325188
A39: GKK3600型 飯糰機 | B39: 18℃-飯糰 | C39: 一配北海道秋鮭親子飯糰 | E39: 24.82 | F39: 840 | G39: =E39*F39 -> 20848.8 | I39: 5 | J39: 3600 | K39: =J39/I39 -> 720 | L39: 5 | M39: =F39/V39*60 -> 3274.0915 | N39: =M39/L39 -> 654.8183 | O39: =L39-I39 -> 0 | P39: =N39-K39 -> -65.181701 | Q39: =N39/K39 -> 0.90946986 | R39: =Q55 -> 0.91607253 | S39: 0.25 | T39: 0.26068287 | V39: 15.393583 | AA39: =M39-J39 -> -325.9085 | AB39: =M39/J39 -> 0.90946986 | AC39: =AB55 -> 0.91607253
B40: 18℃-飯糰 | C40: 一配熟成紅鮭飯糰 | E40: 25.03 | F40: 713 | G40: =E40*F40 -> 17846.39 | I40: 5 | J40: 3600 | K40: =J40/I40 -> 720 | L40: 5 | M40: =F40/V40*60 -> 3268.5052 | N40: =M40/L40 -> 653.70104 | O40: =L40-I40 -> 0 | P40: =N40-K40 -> -66.298962 | Q40: =N40/K40 -> 0.90791811 | S40: 0.27013889 | T40: 0.27922454 | U40: 13.616667 | V40: 13.088552 | AA40: =M40-J40 -> -331.49481 | AB40: =M40/J40 -> 0.90791811
B41: 18℃-飯糰 | C41: 一配生鱈魚子鮭魚飯糰 | E41: 23.8 | F41: 756 | G41: =E41*F41 -> 17992.8 | I41: 4 | J41: 3600 | K41: =J41/I41 -> 900 | L41: 4 | M41: =F41/V41*60 -> 3269.5881 | N41: =M41/L41 -> 817.39704 | O41: =L41-I41 -> 0 | P41: =N41-K41 -> -82.602963 | Q41: =N41/K41 -> 0.90821893 | S41: 0.28888889 | T41: 0.29851852 | U41: 13.916667 | V41: 13.873307 | AA41: =M41-J41 -> -330.41185 | AB41: =M41/J41 -> 0.90821893
B42: 18℃-飯糰 | C42: 一配筋子銀鮭飯糰 | E42: 30 | F42: 684 | G42: =E42*F42 -> 20520 | I42: 4 | J42: 3300 | K42: =J42/I42 -> 825 | L42: 4 | M42: =F42/V42*60 -> 3071.7313 | N42: =M42/L42 -> 767.93282 | O42: =L42-I42 -> 0 | P42: =N42-K42 -> -57.06718 | Q42: =N42/K42 -> 0.93082766 | S42: 0.30763889 | T42: 0.31690972 | U42: 13.133333 | V42: 13.360544 | AA42: =M42-J42 -> -228.26872 | AB42: =M42/J42 -> 0.93082766
B43: 18℃-飯糰 | C43: 一配蔬食鮪魚飯糰 | E43: 18.18 | F43: 883 | G43: =E43*F43 -> 16052.94 | I43: 3 | J43: 3600 | K43: =J43/I43 -> 1200 | L43: 3 | M43: =F43/V43*60 -> 3269.1694 | N43: =M43/L43 -> 1089.7231 | O43: =L43-I43 -> 0 | P43: =N43-K43 -> -110.27688 | Q43: =N43/K43 -> 0.9081026 | S43: 0.32638889 | T43: 0.33763889 | U43: 13.65 | V43: 16.205952 | AA43: =M43-J43 -> -330.83065 | AB43: =M43/J43 -> 0.9081026
B44: 18℃-飯糰 | C44: 一配黑胡椒洋蔥豬飯糰 | E44: 17.07 | F44: 1261 | G44: =E44*F44 -> 21525.27 | I44: 3 | J44: 3300 | K44: =J44/I44 -> 1100 | L44: 3 | M44: =F44/V44*60 -> 3071.2126 | N44: =M44/L44 -> 1023.7375 | O44: =L44-I44 -> 0 | P44: =N44-K44 -> -76.262473 | Q44: =N44/K44 -> 0.93067048 | S44: 0.34722222 | T44: 0.3643287 | U44: 13.8 | V44: 24.635221 | AA44: =M44-J44 -> -228.78742 | AB44: =M44/J44 -> 0.93067048
B45: 18℃-飯糰 | C45: 一配經典肉鬆飯糰 | E45: 14.03 | F45: 3351 | G45: =E45*F45 -> 47014.53 | I45: 3 | J45: 3000 | K45: =J45/I45 -> 1000 | L45: 3 | M45: =F45/V45*60 -> 2788.5949 | N45: =M45/L45 -> 929.53163 | O45: =L45-I45 -> 0 | P45: =N45-K45 -> -70.468371 | Q45: =N45/K45 -> 0.92953163 | S45: 0.37361111 | T45: 0.42368056 | U45: 13.366667 | V45: 72.100828 | AA45: =M45-J45 -> -211.40511 | AB45: =M45/J45 -> 0.92953163
B46: 18℃-飯糰 | C46: 一配鮪魚飯糰 | E46: 14.28 | F46: 4753 | G46: =E46*F46 -> 67872.84 | I46: 3 | J46: 3600 | K46: =J46/I46 -> 1200 | L46: 3 | M46: =F46/V46*60 -> 3270.709 | N46: =M46/L46 -> 1090.2363 | O46: =L46-I46 -> 0 | P46: =N46-K46 -> -109.76368 | Q46: =N46/K46 -> 0.90853027 | S46: 0.43333333 | T46: 0.49387731 | U46: 13.9 | V46: 87.192105 | AA46: =M46-J46 -> -329.29103 | AB46: =M46/J46 -> 0.90853027
B55: 平均 | I55: =AVERAGE(I39:I54) -> 3.75 | J55: =AVERAGE(J39:J54) -> 3450 | K55: =J55/I55 -> 920 | L55: =AVERAGE(L39:L54) -> 3.75 | M55: =AVERAGE(M39:M54) -> 3160.4502 | N55: =M55/L55 -> 842.78673 | O55: =L55-I55 -> 0 | P55: =N55-K55 -> -77.21327 | Q55: =N55/K55 -> 0.91607253 | S55: 0.25 | T55: 0.49387731 | AA55: =M55-J55 -> -289.54976 | AB55: =M55/J55 -> 0.91607253
A56: GKK3600型 飯糰機2 | B56: 18℃-飯糰 | C56: 一配明太子龍蝦風味沙拉飯糰 | E56: 18.18 | F56: 1389 | G56: =E56*F56 -> 25252.02 | I56: 3 | J56: 3600 | K56: =J56/I56 -> 1200 | L56: 3 | M56: =F56/V56*60 -> 3272.4781 | N56: =M56/L56 -> 1090.826 | O56: =L56-I56 -> 0 | P56: =N56-K56 -> -109.17396 | Q56: =N56/K56 -> 0.9090217 | R56: =Q72 -> 0.90862232 | S56: 0.25 | T56: 0.26768519 | V56: 25.466939 | AA56: =M56-J56 -> -327.52187 | AB56: =M56/J56 -> 0.9090217 | AC56: =AB72 -> 0.90862232
B57: 18℃-飯糰 | C57: 一配椒鹽檸檬鯖魚飯糰 | E57: 20.72 | F57: 735 | G57: =E57*F57 -> 15229.2 | I57: 3 | J57: 3600 | K57: =J57/I57 -> 1200 | L57: 3 | M57: =F57/V57*60 -> 3273.0771 | N57: =M57/L57 -> 1091.0257 | O57: =L57-I57 -> 0 | P57: =N57-K57 -> -108.97429 | Q57: =N57/K57 -> 0.90918809 | S57: 0.27708333 | T57: 0.28643519 | U57: 13.533333 | V57: 13.47356 | AA57: =M57-J57 -> -326.92286 | AB57: =M57/J57 -> 0.90918809
B58: 18℃-飯糰 | C58: 一配贅沢鮭魚肚飯糰 | E58: 30 | F58: 1047 | G58: =E58*F58 -> 31410 | I58: 4 | J58: 3600 | K58: =J58/I58 -> 900 | L58: 4 | M58: =F58/V58*60 -> 3268.3227 | N58: =M58/L58 -> 817.08068 | O58: =L58-I58 -> 0 | P58: =N58-K58 -> -82.919324 | Q58: =N58/K58 -> 0.90786742 | S58: 0.29583333 | T58: 0.30917824 | U58: 13.533333 | V58: 19.220868 | AA58: =M58-J58 -> -331.6773 | AB58: =M58/J58 -> 0.90786742
B59: 18℃-飯糰 | C59: 一配卵黃牛挽肉飯糰 | E59: 24.76 | F59: 1297 | G59: =E59*F59 -> 32113.72 | I59: 4 | J59: 3600 | K59: =J59/I59 -> 900 | L59: 4 | M59: =F59/V59*60 -> 3269.1951 | N59: =M59/L59 -> 817.29877 | O59: =L59-I59 -> 0 | P59: =N59-K59 -> -82.701226 | Q59: =N59/K59 -> 0.90810975 | S59: 0.31875 | T59: 0.33527778 | U59: 13.783333 | V59: 23.804024 | AA59: =M59-J59 -> -330.80491 | AB59: =M59/J59 -> 0.90810975
B60: 18℃-飯糰 | C60: 一配鹽蔥燒肉飯糰 | E60: 17.89 | F60: 2111 | G60: =E60*F60 -> 37765.79 | I60: 4 | J60: 3600 | K60: =J60/I60 -> 900 | L60: 4 | M60: =F60/V60*60 -> 3272.3626 | N60: =M60/L60 -> 818.09066 | O60: =L60-I60 -> 0 | P60: =N60-K60 -> -81.90934 | Q60: =N60/K60 -> 0.90898962 | S60: 0.34444444 | T60: 0.37131944 | U60: 13.2 | V60: 38.705979 | AA60: =M60-J60 -> -327.63736 | AB60: =M60/J60 -> 0.90898962
B61: 18℃-飯糰 | C61: 一配醬燒炙烤牛飯糰 | E61: 22.32 | F61: 1559 | G61: =E61*F61 -> 34796.88 | I61: 5 | J61: 3600 | K61: =J61/I61 -> 720 | L61: 5 | M61: =F61/V61*60 -> 3269.3856 | N61: =M61/L61 -> 653.87712 | O61: =L61-I61 -> 0 | P61: =N61-K61 -> -66.122876 | Q61: =N61/K61 -> 0.90816267 | S61: 0.38055556 | T61: 0.40041667 | U61: 13.3 | V61: 28.61088 | AA61: =M61-J61 -> -330.61438 | AB61: =M61/J61 -> 0.90816267
B62: 18℃-飯糰 | C62: 一配鹽蔥生鮭飯糰 | E62: 27.48 | F62: 1263 | G62: =E62*F62 -> 34707.24 | I62: 5 | J62: 3600 | K62: =J62/I62 -> 720 | L62: 5 | M62: =F62/V62*60 -> 3272.6628 | N62: =M62/L62 -> 654.53256 | O62: =L62-I62 -> 0 | P62: =N62-K62 -> -65.467436 | Q62: =N62/K62 -> 0.90907301 | S62: 0.40972222 | T62: 0.42579861 | U62: 13.4 | V62: 23.155456 | AA62: =M62-J62 -> -327.33718 | AB62: =M62/J62 -> 0.90907301
B63: 18℃-飯糰 | C63: 一配雞肉飯飯糰 | E63: 16.66 | F63: 3880 | G63: =E63*F63 -> 64640.8 | I63: 5 | J63: 3600 | K63: =J63/I63 -> 720 | L63: 5 | M63: =F63/V63*60 -> 3270.8387 | N63: =M63/L63 -> 654.16774 | O63: =L63-I63 -> 0 | P63: =N63-K63 -> -65.832263 | Q63: =N63/K63 -> 0.9085663 | S63: 0.43541667 | T63: 0.48483796 | U63: 13.85 | V63: 71.174406 | AA63: =M63-J63 -> -329.16131 | AB63: =M63/J63 -> 0.9085663
B72: 平均 | I72: =AVERAGE(I56:I71) -> 4.125 | J72: =AVERAGE(J56:J71) -> 3600 | K72: =J72/I72 -> 872.72727 | L72: =AVERAGE(L56:L71) -> 4.125 | M72: =AVERAGE(M56:M71) -> 3271.0404 | N72: =M72/L72 -> 792.97948 | O72: =L72-I72 -> 0 | P72: =N72-K72 -> -79.747793 | Q72: =N72/K72 -> 0.90862232 | S72: 0.25 | T72: 0.48483796 | AA72: =M72-J72 -> -328.95965 | AB72: =M72/J72 -> 0.90862232
A73: 自動包裝機 (二配) | B73: 18℃-飯糰 | C73: 二配兩粒飯糰(鮪魚.焦糖鮭魚) | E73: 28.57 | F73: 1000 | G73: =E73*F73 -> 28570 | I73: 12 | J73: 3600 | K73: =J73/I73 -> 300 | L73: 12 | M73: =F73/V73*60 -> 3119.5615 | N73: =M73/L73 -> 259.96346 | O73: =L73-I73 -> 0 | P73: =N73-K73 -> -40.03654 | Q73: =N73/K73 -> 0.86654487 | R73: =Q89 -> 0.86654487 | S73: 0.73958333 | T73: 0.75293981 | V73: 19.233472 | AA73: =M73-J73 -> -480.43848 | AB73: =M73/J73 -> 0.86654487 | AC73: =AB89 -> 0.86654487
B89: 平均 | I89: =AVERAGE(I73:I88) -> 12 | J89: =AVERAGE(J73:J88) -> 3600 | K89: =J89/I89 -> 300 | L89: =AVERAGE(L73:L88) -> 12 | M89: =AVERAGE(M73:M88) -> 3119.5615 | N89: =M89/L89 -> 259.96346 | O89: =L89-I89 -> 0 | P89: =N89-K89 -> -40.03654 | Q89: =N89/K89 -> 0.86654487 | S89: 0.73958333 | T89: 0.75293981 | AA89: =M89-J89 -> -480.43848 | AB89: =M89/J89 -> 0.86654487
A90: (新) 3300型飯糰機 (二配) | B90: 18℃-飯糰 | C90: 二配大飯糰韓式蒜烤豬五花 | E90: 24.54 | F90: 908 | G90: =E90*F90 -> 22282.32 | I90: 4 | J90: 3000 | K90: =J90/I90 -> 750 | L90: 4 | M90: =F90/V90*60 -> 2788.5526 | N90: =M90/L90 -> 697.13815 | O90: =L90-I90 -> 0 | P90: =N90-K90 -> -52.861853 | Q90: =N90/K90 -> 0.92951753 | R90: =Q106 -> 0.92951753 | S90: 0.70833333 | T90: 0.72189815 | V90: 19.537017 | AA90: =M90-J90 -> -211.44741 | AB90: =M90/J90 -> 0.92951753 | AC90: =AB106 -> 0.92951753
B106: 平均 | I106: =AVERAGE(I90:I105) -> 4 | J106: =AVERAGE(J90:J105) -> 3000 | K106: =J106/I106 -> 750 | L106: =AVERAGE(L90:L105) -> 4 | M106: =AVERAGE(M90:M105) -> 2788.5526 | N106: =M106/L106 -> 697.13815 | O106: =L106-I106 -> 0 | P106: =N106-K106 -> -52.861853 | Q106: =N106/K106 -> 0.92951753 | S106: 0.70833333 | T106: 0.72189815 | AA106: =M106-J106 -> -211.44741 | AB106: =M106/J106 -> 0.92951753
A107: GKK3600型 飯糰機 (二配) | B107: 18℃-飯糰 | C107: 二配經典肉鬆飯糰 | E107: 14.03 | F107: 321 | G107: =E107*F107 -> 4503.63 | H107: 2 | I107: 3 | J107: 3000 | K107: =J107/I107 -> 1000 | L107: 3 | M107: =F107/V107*60 -> 2791.1931 | N107: =M107/L107 -> 930.3977 | O107: =L107-I107 -> 0 | P107: =N107-K107 -> -69.602301 | Q107: =N107/K107 -> 0.9303977 | R107: =Q123 -> 0.91419604 | S107: 0.73263889 | T107: 0.73743056 | V107: 6.900275 | AA107: =M107-J107 -> -208.8069 | AB107: =M107/J107 -> 0.9303977 | AC107: =AB123 -> 0.91419604
B108: 18℃-飯糰 | C108: 二配芝麻香鬆飯糰 | E108: 18.18 | F108: 649 | G108: =E108*F108 -> 11798.82 | H108: 2 | I108: 3 | J108: 3000 | K108: =J108/I108 -> 1000 | L108: 3 | M108: =F108/V108*60 -> 2788.5538 | N108: =M108/L108 -> 929.51794 | O108: =L108-I108 -> 0 | P108: =N108-K108 -> -70.48206 | Q108: =N108/K108 -> 0.92951794 | S108: 0.74652778 | T108: 0.75621528 | U108: 13.1 | V108: 13.964228 | AA108: =M108-J108 -> -211.44618 | AB108: =M108/J108 -> 0.92951794
B109: 18℃-飯糰 | C109: 二配蔬食鮪魚飯糰 | E109: 18.18 | F109: 408 | G109: =E109*F109 -> 7417.44 | H109: 2 | I109: 3 | J109: 3600 | K109: =J109/I109 -> 1200 | L109: 3 | M109: =F109/V109*60 -> 3273.3967 | N109: =M109/L109 -> 1091.1322 | O109: =L109-I109 -> 0 | P109: =N109-K109 -> -108.86775 | Q109: =N109/K109 -> 0.90927687 | S109: 0.76527778 | T109: 0.77046296 | U109: 13.05 | V109: 7.4784702 | AA109: =M109-J109 -> -326.60325 | AB109: =M109/J109 -> 0.90927687
B110: 18℃-飯糰 | C110: 二配三杯醬爆菇菇飯糰 | E110: 16.7 | F110: 1075 | G110: =E110*F110 -> 17952.5 | H110: 2 | I110: 3 | J110: 3600 | K110: =J110/I110 -> 1200 | L110: 3 | M110: =F110/V110*60 -> 3272.4488 | N110: =M110/L110 -> 1090.8163 | O110: =L110-I110 -> 0 | P110: =N110-K110 -> -109.18372 | Q110: =N110/K110 -> 0.90901357 | S110: 0.77986111 | T110: 0.79354167 | U110: 13.533333 | V110: 19.71001 | AA110: =M110-J110 -> -327.55116 | AB110: =M110/J110 -> 0.90901357
...

Sheet 0929(4度C)
A1: 大溪廠日報分析 | C1: 總生產量 | D1: =SUM(F5:F140) -> 72214 | E1: 營業額 | F1: =SUM(G5:G140) -> 3145034.7 | G1: 出勤人數 | H1: =L21+L38+L55+L72+L89+L106+L123+L140 -> 137.46667 | I1: 產線配置圖 | L1: 生產實績 | O1: 人時性差異分析 | S1: 日報登錄 | Y1: 合計次數 | Z1: 合計(時間/分) | AA1: 產線異常 分析說明(5分鐘以上) | AC1: 合計次數 | AD1: 合計(時間/分) | AE1: 產能差異分析
