Workbook

Sheet 0331
B1: 屏榮 大溪廠組合室生產人時性分析
B3: 日期 | C3: 115.03.31星期二 | E3: 訂單量 | F3: ='0331(18度C)'!D1+'0331(4度C)'!D1 -> 179182 | H3: 營業額 | I3: ='0331(18度C)'!F1+'0331(4度C)'!F1 -> 5566322
B4: 人時性 | C4: 項目 | E4: ➀ | G4: ➁ | I4: ➂ | K4: ④ | M4: ⑤ | O4: 異常停線 | Q4: 短暫停線
C5: 組合室 | E5: 全溫層 | G5: 4度C-各編組展開(一配) | I5: 4度C-各編組展開(二配) | K5: 18度C-各編組展開(一配) | M5: 18度C-各編組展開(二配) | O5: 合計次數 | P5: 時間 | Q5: 合計次數 | R5: 設備次數
C6: 排關平均 | E6: =AVERAGE(D14:O14,D32:X32) -> 460.54537 | F6: =AVERAGE(#REF!,D14:K14) -> #REF! | G6: =AVERAGE(D14:K14) -> 132.89206 | I6: =AVERAGE(L14:O14) -> 93.173541 | K6: =AVERAGE(D32:O32) -> 741.60585 | M6: =AVERAGE(P32:X32) -> 712.40196 | O6: ='0331(4度C)'!Y2 -> 0 | P6: ='0331(4度C)'!Z2 -> 0 | Q6: ='0331(4度C)'!AC2 -> 0 | R6: ='0331(4度C)'!AD2 -> 0
C7: 實績平均 | E7: =AVERAGE(D15:O15,D33:X33) -> 410.20375 | F7: =AVERAGE(#REF!,D15:K15) -> #REF! | G7: =AVERAGE(D15:K15) -> 118.52637 | I7: =AVERAGE(L15:O15) -> 82.460658 | K7: =AVERAGE(D33:O33) -> 661.94081 | M7: =AVERAGE(P33:X33) -> 633.01712
C8: 達成率平均 | E8: =AVERAGE(D16:O16,D34:X34) -> 0.88799655 | F8: =AVERAGE(D16:K16,#REF!) -> #REF! | G8: =AVERAGE(D16:K16) -> 0.88651976 | I8: =AVERAGE(L16:O16) -> 0.88577169 | K8: =AVERAGE(D34:O34) -> 0.89180695 | M8: =AVERAGE(P34:X34) -> 0.88637899
O9: ※現行日本鮮食廠以達成率80%為基本(即為現行KPI)
B11: 溫層 | D11: ➁4度C-各編組展開 | L11: ➂4度C-各編組展開
B12: 編組 | D12: 1 | E12: 2 | F12: 3 | G12: 4 | H12: 5 | I12: 6 | J12: 7 | K12: 8 | L12: 1 | M12: 2 | N12: 3 | O12: 4
D13: 便當一線 | E13: 便當二線 | F13: 涼麵一線 | G13: 涼麵二線 | H13: 涼麵三線 | I13: 自動包裝機 | J13: 自動包裝機2 | K13: 自動包裝機3 | L13: 便當一線 | M13: 便當二線 | N13: 涼麵一線 | O13: 涼麵二線
B14: 人時性 | C14: 排關 | D14: - | E14: 84.507042 | F14: 93.023256 | G14: 82.191781 | H14: 271.84615 | I14: - | J14: - | K14: - | L14: - | M14: 90 | N14: 102.5641 | O14: 86.956522
C15: 實績 | D15: - | E15: 75.482749 | F15: 82.113692 | G15: 71.37622 | H15: 245.13282 | I15: - | J15: - | K15: - | L15: - | M15: 80.310514 | N15: 89.34043 | O15: 77.731029
C16: 達成率 | D16: - | E16: =E15/E14 -> 0.89321253 | F16: =F15/F14 -> 0.88272219 | G16: =G15/G14 -> 0.86841068 | H16: =H15/H14 -> 0.90173364 | I16: - | J16: - | K16: - | L16: - | M16: =M15/M14 -> 0.89233904 | N16: =N15/N14 -> 0.87106919 | O16: =O15/O14 -> 0.89390684
B17: 作業 時間 | C17: 開始 | D17: - | E17: 0.25 | F17: 0.25 | G17: 0.25021991 | H17: 0.25018519 | I17: - | J17: - | K17: - | L17: - | M17: 0.70833333 | N17: 0.70833333 | O17: 0.70833333
C18: 結束 | D18: - | E18: 0.58403935 | F18: 0.56319444 | G18: 0.60486111 | H18: 0.53611111 | I18: - | J18: - | K18: - | L18: - | M18: 0.81875 | N18: 0.79728009 | O18: 0.84614583
B19: 產線異常 (5分鐘以上) | C19: 次數
C20: 時間/分
B21: 短暫停線 (5分鐘以下) | C21: 次數
C22: 設備次數
B23: 配置人數 | D23: - | E23: 23.666667 | F23: 21.75 | G23: 24.333333 | H23: 10.4 | I23: - | J23: - | K23: - | L23: - | M23: 20 | N23: 20 | O23: 23
B24: 主要應用設備 | D24: L型封口機 | E24: ET-55 | F24: ET-55 | G24: ET-55 | H24: ET-600 | I24: 伺服包裝機 | J24: 伺服包裝機 | K24: 伺服包裝機 | L24: L型封口機 | M24: ET-55 | N24: ET-55 | O24: ET-55
B25: 次要應用設備 | D25: 伺服包裝機 | H25: 伺服包裝機
B26: 備註 | H26: 涼麵+烤飯糰 | I26: 大口飯糰線 | K26: 烤飯糰+手卷
B29: 溫層 | D29: ➃18度C-各編組展開 (一配) | P29: ⑤18度C-各編組展開 (二配)
B30: 編組 | D30: 1 | E30: 2 | F30: 3 | G30: 4 | H30: 5 | I30: 6 | J30: 7 | K30: 8 | L30: 9 | M30: 10 | N30: 11 | O30: 12 | P30: 1 | Q30: 2 | R30: 3 | S30: 4 | T30: 5 | U30: 6 | V30: 7 | W30: 8 | X30: 9
D31: 便當一線 | E31: 涼麵一線 | F31: 涼麵三線 | G31: 自動包裝機 | H31: 自動包裝機2 | I31: 自動包裝機3 | J31: 味付飯糰線B | K31: (舊) 3300型飯糰線 | L31: 3000型飯糰線 | M31: (新) 3300型飯糰機 | N31: GKK3600型 飯糰機 | O31: GKK3600型 飯糰機2 | P31: 自動包裝機 | Q31: 自動包裝機2 | R31: 自動包裝機3 | S31: 味付飯糰線B | T31: (舊) 3300型飯糰線 | U31: 3000型飯糰線 | V31: (新) 3300型飯糰機 | W31: GKK3600型 飯糰機 | X31: GKK3600型 飯糰機2
B32: 人時性 | C32: 排關 | D32: - | E32: - | F32: - | G32: 328.81356 | H32: 433.33333 | I32: - | J32: - | K32: - | L32: - | M32: 1100 | N32: 1005.8824 | O32: 840 | P32: 300 | Q32: - | R32: - | S32: - | T32: - | U32: - | V32: 723.52941 | W32: 979.41176 | X32: 846.66667
C33: 實績 | D33: - | E33: - | F33: - | G33: 290.15651 | H33: 390.10581 | I33: - | J33: - | K33: - | L33: - | M33: 990.45465 | N33: 892.56791 | O33: 746.41917 | P33: 262.0813 | Q33: - | R33: - | S33: - | T33: - | U33: - | V33: 648.20866 | W33: 871.26322 | X33: 750.51531
C34: 達成率 | D34: - | E34: - | F34: - | G34: =G33/G32 -> 0.88243476 | H34: =H33/H32 -> 0.90024419 | I34: - | J34: - | K34: - | L34: - | M34: =M33/M32 -> 0.90041332 | N34: =N33/N32 -> 0.88734822 | O34: =O33/O32 -> 0.88859425 | P34: =P33/P32 -> 0.87360434 | Q34: - | R34: - | S34: - | T34: - | U34: - | V34: =V33/V32 -> 0.89589814 | W34: =W33/W32 -> 0.88957806 | X34: =X33/X32 -> 0.8864354
B35: 作業 時間 | C35: 開始 | D35: - | E35: - | F35: - | G35: 0.25 | H35: 0.29166667 | I35: - | J35: - | K35: - | L35: - | M35: 0.35438657 | N35: 0.25 | O35: 0.25 | P35: 0.70855324 | Q35: - | R35: - | S35: - | T35: - | U35: - | V35: 0.70850694 | W35: 0.70833333 | X35: 0.70833333
C36: 結束 | D36: - | E36: - | F36: - | G36: 0.44674769 | H36: 0.33263889 | I36: - | J36: - | K36: - | L36: - | M36: 0.40555556 | N36: 0.53541667 | O36: 0.51944444 | P36: 0.8994213 | Q36: - | R36: - | S36: - | T36: - | U36: - | V36: 0.81189815 | W36: 1.19375 | X36: 1.1722222
B37: 配置人數 | D37: - | E37: - | F37: - | G37: 9.8333333 | H37: 6 | I37: - | J37: - | K37: - | L37: - | M37: 3 | N37: 3.4 | O37: 4 | P37: 12 | Q37: - | R37: - | S37: - | T37: - | U37: - | V37: 4.25 | W37: 3.4 | X37: 4.0909091
B38: 主要應用設備 | D38: 伺服包裝機 | E38: ET-55 | F38: ET-600 | G38: 夾心型 | H38: 伺服包裝機 | I38: 伺服包裝機 | J38: 夾心型 | K38: 3300型 | L38: 3300型 | M38: 3300型 | N38: GKK | O38: GKK | P38: 夾心型 | Q38: 伺服包裝機 | R38: 伺服包裝機 | S38: 夾心型 | T38: 3300型 | U38: 3300型 | V38: 3300型 | W38: GKK | X38: GKK
B39: 次要應用設備
B40: 備註

Sheet 0331(18度C)
A1: 大溪廠日報分析 | C1: 總生產量 | D1: =SUM(F5:F157) -> 118957 | E1: 營業額 | F1: =SUM(G5:G157) -> 2313079.4 | G1: 出勤人數 | H1: =L21+L38+L55+L72+L89+L106+L123+L140+L157 -> 49.974242 | I1: 產線配置圖 | L1: 生產實績 | O1: 人時性差異分析 | S1: 日報登錄 | Y1: 分析說明 | AA1: 產能差異分析
A2: 46112 | C2: 人時性 | D2: =AVERAGE(N21,N38,N55,N72,N89,N106,N123,N140,N157) -> 649.08584 | E2: 平均廠價 | F2: =F1/D1 -> 19.444668 | G2: 多次生產數 | H2: =COUNT(H5:H157) -> 10
A3: 線別 | B3: 品類 | C3: 品名 | E3: 廠價 | F3: 生產量 | G3: 營收 | H3: 多次 生產 | I3: 人數 | J3: 產能/時 | K3: 人時性 | L3: 人數 | M3: 產能/時 | N3: 人時性 | O3: 人數 | P3: 人時性 | Q3: 達成率 | R3: 達成率 平均 | S3: 生產時間 | U3: 換線、休息/分 | V3: 稼動時間/分 | W3: 休息時間 | Y3: (屏榮回填) | AA3: 產能/時 | AB3: 達成率 | AC3: 達成率平均
S4: 開始 | T4: 結束 | W4: 開始 | X4: 結束
A5: 自動包裝機 | B5: 18℃-壽司手卷 | C5: 一配日式鮪魚美乃滋脆卷 | E5: 17.87 | F5: 1372 | G5: =E5*F5 -> 24517.64 | I5: 6 | J5: 2500 | K5: =J5/I5 -> 416.66667 | L5: 6 | M5: =F5/V5*60 -> 2258.4362 | N5: =M5/L5 -> 376.40604 | O5: =L5-I5 -> 0 | P5: =N5-K5 -> -40.260631 | Q5: =N5/K5 -> 0.90337449 | R5: =Q21 -> 0.88243476 | S5: 0.25 | T5: 0.2753125 | V5: 36.45 | AA5: =M5-J5 -> -241.56379 | AB5: =M5/J5 -> 0.90337449 | AC5: =AB21 -> 0.88243476
B6: 18℃-壽司手卷 | C6: 一配銀鮭美乃滋脆卷 | E6: 19.7 | F6: 2787 | G6: =E6*F6 -> 54903.9 | I6: 6 | J6: 2500 | K6: =J6/I6 -> 416.66667 | L6: 6 | M6: =F6/V6*60 -> 2257.6958 | N6: =M6/L6 -> 376.28263 | O6: =L6-I6 -> 0 | P6: =N6-K6 -> -40.384038 | Q6: =N6/K6 -> 0.90307831 | S6: 0.27847222 | T6: 0.32990741 | U6: 4.55 | V6: 74.066667 | AA6: =M6-J6 -> -242.30423 | AB6: =M6/J6 -> 0.90307831
B7: 18℃-壽司手卷 | C7: 一配海饌雙手卷 | E7: 29.85 | F7: 2188 | G7: =E7*F7 -> 65311.8 | I7: 12 | J7: 3600 | K7: =J7/I7 -> 300 | L7: 12 | M7: =F7/V7*60 -> 3146.9437 | N7: =M7/L7 -> 262.24531 | O7: =L7-I7 -> 0 | P7: =N7-K7 -> -37.754694 | Q7: =N7/K7 -> 0.87415102 | S7: 0.33353009 | T7: 0.3625 | U7: 5.2166667 | V7: 41.716667 | AA7: =M7-J7 -> -453.05633 | AB7: =M7/J7 -> 0.87415102
B8: 18℃-壽司手卷 | C8: 一配雙饗雙手卷 | E8: 29.52 | F8: 1977 | G8: =E8*F8 -> 58361.04 | I8: 12 | J8: 3600 | K8: =J8/I8 -> 300 | L8: 12 | M8: =F8/V8*60 -> 3147.8107 | N8: =M8/L8 -> 262.31756 | O8: =L8-I8 -> 0 | P8: =N8-K8 -> -37.682441 | Q8: =N8/K8 -> 0.87439186 | S8: 0.36688657 | T8: 0.39305556 | U8: 6.3166667 | V8: 37.683333 | AA8: =M8-J8 -> -452.1893 | AB8: =M8/J8 -> 0.87439186
B9: 18℃-壽司手卷 | C9: 一配長野稻荷壽司 | E9: 25.64 | F9: 1564 | G9: =E9*F9 -> 40100.96 | I9: 11 | J9: 3600 | K9: =J9/I9 -> 327.27273 | L9: 11 | M9: =F9/V9*60 -> 3182.8151 | N9: =M9/L9 -> 289.34683 | O9: =L9-I9 -> 0 | P9: =N9-K9 -> -37.925895 | Q9: =N9/K9 -> 0.88411532 | S9: 0.39652778 | T9: 0.41700231 | U9: 5 | V9: 29.483333 | AA9: =M9-J9 -> -417.18485 | AB9: =M9/J9 -> 0.88411532
B10: 18℃-飯糰 | C10: 一配兩粒飯糰(鮪魚.焦糖鮭魚) | E10: 28.57 | F10: 1996 | G10: =E10*F10 -> 57025.72 | I10: 12 | J10: 3600 | K10: =J10/I10 -> 300 | L10: 12 | M10: =F10/V10*60 -> 3125.5328 | N10: =M10/L10 -> 260.46107 | O10: =L10-I10 -> 0 | P10: =N10-K10 -> -39.53893 | Q10: =N10/K10 -> 0.86820357 | S10: 0.42013889 | T10: 0.44674769 | U10: 4.5166667 | V10: 38.316667 | AA10: =M10-J10 -> -474.46716 | AB10: =M10/J10 -> 0.86820357
B21: 平均 | I21: =AVERAGE(I5:I20) -> 9.8333333 | J21: =AVERAGE(J5:J20) -> 3233.3333 | K21: =J21/I21 -> 328.81356 | L21: =AVERAGE(L5:L20) -> 9.8333333 | M21: =AVERAGE(M5:M20) -> 2853.2057 | N21: =M21/L21 -> 290.15651 | O21: =L21-I21 -> 0 | P21: =N21-K21 -> -38.657045 | Q21: =N21/K21 -> 0.88243476 | S21: =S5 -> 0.25 | T21: =INDEX(T5:T20,COUNTA(T5:T20)) -> 0.44674769 | AA21: =M21-J21 -> -380.12761 | AB21: =M21/J21 -> 0.88243476
A22: 自動包裝機2 | B22: 18℃-壽司手卷 | C22: 一配雙鬆細卷 | E22: 14.03 | F22: 978 | G22: =E22*F22 -> 13721.34 | I22: 6 | J22: 2600 | K22: =J22/I22 -> 433.33333 | L22: 6 | M22: =F22/V22*60 -> 2340.9574 | N22: =M22/L22 -> 390.15957 | O22: =L22-I22 -> 0 | P22: =N22-K22 -> -43.173759 | Q22: =N22/K22 -> 0.90036825 | R22: =Q38 -> 0.90024419 | S22: 0.29166667 | T22: 0.30907407 | V22: 25.066667 | AA22: =M22-J22 -> -259.04255 | AB22: =M22/J22 -> 0.90036825 | AC22: =AB38 -> 0.90024419
B23: 18℃-壽司手卷 | C23: 一配經典鮪魚沙拉細卷 | E23: 14.49 | F23: 1124 | G23: =E23*F23 -> 16286.76 | I23: 6 | J23: 2600 | K23: =J23/I23 -> 433.33333 | L23: 6 | M23: =F23/V23*60 -> 2340.3123 | N23: =M23/L23 -> 390.05205 | O23: =L23-I23 -> 0 | P23: =N23-K23 -> -43.28128 | Q23: =N23/K23 -> 0.90012012 | S23: 0.31262731 | T23: 0.33263889 | U23: 5.1166667 | V23: 28.816667 | AA23: =M23-J23 -> -259.68768 | AB23: =M23/J23 -> 0.90012012
B38: 平均 | I38: =AVERAGE(I22:I37) -> 6 | J38: =AVERAGE(J22:J37) -> 2600 | K38: =J38/I38 -> 433.33333 | L38: =AVERAGE(L22:L37) -> 6 | M38: =AVERAGE(M22:M37) -> 2340.6349 | N38: =M38/L38 -> 390.10581 | O38: =L38-I38 -> 0 | P38: =N38-K38 -> -43.227519 | Q38: =N38/K38 -> 0.90024419 | S38: =S22 -> 0.29166667 | T38: =INDEX(T22:T37,COUNTA(T22:T37)) -> 0.33263889 | AA38: =M38-J38 -> -259.36512 | AB38: =M38/J38 -> 0.90024419
A39: (新) 3300型飯糰機 | B39: 18℃-飯糰 | C39: 一配鮭魚奶油醬油飯糰 | E39: 18.53 | F39: 3649 | G39: =E39*F39 -> 67615.97 | I39: 3 | J39: 3300 | K39: =J39/I39 -> 1100 | L39: 3 | M39: =F39/V39*60 -> 2971.3639 | N39: =M39/L39 -> 990.45465 | O39: =L39-I39 -> 0 | P39: =N39-K39 -> -109.54535 | Q39: =N39/K39 -> 0.90041332 | R39: =Q55 -> 0.90041332 | S39: 0.35438657 | T39: 0.40555556 | V39: 73.683333 | AA39: =M39-J39 -> -328.63606 | AB39: =M39/J39 -> 0.90041332 | AC39: =AB55 -> 0.90041332
B55: 平均 | I55: =AVERAGE(I39:I54) -> 3 | J55: =AVERAGE(J39:J54) -> 3300 | K55: =J55/I55 -> 1100 | L55: =AVERAGE(L39:L54) -> 3 | M55: =AVERAGE(M39:M54) -> 2971.3639 | N55: =M55/L55 -> 990.45465 | O55: =L55-I55 -> 0 | P55: =N55-K55 -> -109.54535 | Q55: =N55/K55 -> 0.90041332 | S55: =S39 -> 0.35438657 | T55: =INDEX(T39:T54,COUNTA(T39:T54)) -> 0.40555556 | AA55: =M55-J55 -> -328.63606 | AB55: =M55/J55 -> 0.90041332
A56: GKK3600型 飯糰機 | B56: 18℃-飯糰 | C56: 一配蔬食鮪魚飯糰 | E56: 18.18 | F56: 1350 | G56: =E56*F56 -> 24543 | I56: 3 | J56: 3600 | K56: =J56/I56 -> 1200 | L56: 3 | M56: =F56/V56*60 -> 3178.5481 | N56: =M56/L56 -> 1059.516 | O56: =L56-I56 -> 0 | P56: =N56-K56 -> -140.48398 | Q56: =N56/K56 -> 0.88293002 | R56: =Q72 -> 0.88734822 | S56: 0.25 | T56: 0.26769676 | V56: 25.483333 | AA56: =M56-J56 -> -421.45193 | AB56: =M56/J56 -> 0.88293002 | AC56: =AB72 -> 0.88734822
B57: 18℃-飯糰 | C57: 一配明太子龍蝦風味沙拉飯糰 | E57: 18.18 | F57: 2534 | G57: =E57*F57 -> 46068.12 | I57: 3 | J57: 3600 | K57: =J57/I57 -> 1200 | L57: 3 | M57: =F57/V57*60 -> 3175.2175 | N57: =M57/L57 -> 1058.4058 | O57: =L57-I57 -> 0 | P57: =N57-K57 -> -141.59415 | Q57: =N57/K57 -> 0.88200487 | S57: 0.2778588 | T57: 0.31111111 | U57: 14.633333 | V57: 47.883333 | AA57: =M57-J57 -> -424.78246 | AB57: =M57/J57 -> 0.88200487
B58: 18℃-飯糰 | C58: 一配壹號醬炙烤牛飯糰 | E58: 22.28 | F58: 1297 | G58: =E58*F58 -> 28897.16 | I58: 5 | J58: 3300 | K58: =J58/I58 -> 660 | L58: 5 | M58: =F58/V58*60 -> 2947.7273 | N58: =M58/L58 -> 589.54545 | O58: =L58-I58 -> 0 | P58: =N58-K58 -> -70.454545 | Q58: =N58/K58 -> 0.89325069 | S58: 0.32222222 | T58: 0.34055556 | U58: 16 | V58: 26.4 | AA58: =M58-J58 -> -352.27273 | AB58: =M58/J58 -> 0.89325069
B59: 18℃-飯糰 | C59: 一配經典肉鬆飯糰 | E59: 14.03 | F59: 5201 | G59: =E59*F59 -> 72970.03 | I59: 3 | J59: 3000 | K59: =J59/I59 -> 1000 | L59: 3 | M59: =F59/V59*60 -> 2699.0918 | N59: =M59/L59 -> 899.69728 | O59: =L59-I59 -> 0 | P59: =N59-K59 -> -100.30272 | Q59: =N59/K59 -> 0.89969728 | S59: 0.35096065 | T59: 0.43125 | U59: 14.983333 | V59: 115.61667 | AA59: =M59-J59 -> -300.90817 | AB59: =M59/J59 -> 0.89969728
B60: 18℃-飯糰 | C60: 一配鮪魚飯糰 | E60: 14.28 | F60: 7135 | G60: =E60*F60 -> 101887.8 | I60: 3 | J60: 3600 | K60: =J60/I60 -> 1200 | L60: 3 | M60: =F60/V60*60 -> 3173.0698 | N60: =M60/L60 -> 1057.6899 | O60: =L60-I60 -> 0 | P60: =N60-K60 -> -142.31007 | Q60: =N60/K60 -> 0.88140828 | S60: 0.44172454 | T60: 0.53541667 | U60: 15.083333 | V60: 134.91667 | AA60: =M60-J60 -> -426.9302 | AB60: =M60/J60 -> 0.88140828
B72: 平均 | I72: =AVERAGE(I56:I71) -> 3.4 | J72: =AVERAGE(J56:J71) -> 3420 | K72: =J72/I72 -> 1005.8824 | L72: =AVERAGE(L56:L71) -> 3.4 | M72: =AVERAGE(M56:M71) -> 3034.7309 | N72: =M72/L72 -> 892.56791 | O72: =L72-I72 -> 0 | P72: =N72-K72 -> -113.31444 | Q72: =N72/K72 -> 0.88734822 | S72: =S56 -> 0.25 | T72: =INDEX(T56:T71,COUNTA(T56:T71)) -> 0.53541667 | AA72: =M72-J72 -> -385.2691 | AB72: =M72/J72 -> 0.88734822
A73: GKK3600型 飯糰機2 | B73: 18℃-飯糰 | C73: 一配熟成紅鮭飯糰 | E73: 25.03 | F73: 1670 | G73: =E73*F73 -> 41800.1 | I73: 4 | J73: 3300 | K73: =J73/I73 -> 825 | L73: 4 | M73: =F73/V73*60 -> 2941.2916 | N73: =M73/L73 -> 735.3229 | O73: =L73-I73 -> 0 | P73: =N73-K73 -> -89.677104 | Q73: =N73/K73 -> 0.89130048 | R73: =Q89 -> 0.88859425 | S73: 0.25 | T73: 0.27365741 | V73: 34.066667 | AA73: =M73-J73 -> -358.70841 | AB73: =M73/J73 -> 0.89130048 | AC73: =AB89 -> 0.88859425
B74: 18℃-飯糰 | C74: 一配北海道秋鮭親子飯糰 | E74: 24.82 | F74: 2040 | G74: =E74*F74 -> 50632.8 | I74: 4 | J74: 3300 | K74: =J74/I74 -> 825 | L74: 4 | M74: =F74/V74*60 -> 2941.1294 | N74: =M74/L74 -> 735.28234 | O74: =L74-I74 -> 0 | P74: =N74-K74 -> -89.717661 | Q74: =N74/K74 -> 0.89125132 | S74: 0.28429398 | T74: 0.31319444 | U74: 15.316667 | V74: 41.616667 | AA74: =M74-J74 -> -358.87064 | AB74: =M74/J74 -> 0.89125132
B75: 18℃-飯糰 | C75: 一配鹽蔥燒肉飯糰 | E75: 17.89 | F75: 3399 | G75: =E75*F75 -> 60808.11 | I75: 4 | J75: 3600 | K75: =J75/I75 -> 900 | L75: 4 | M75: =F75/V75*60 -> 3172.5175 | N75: =M75/L75 -> 793.12938 | O75: =L75-I75 -> 0 | P75: =N75-K75 -> -106.87062 | Q75: =N75/K75 -> 0.88125486 | S75: 0.32430556 | T75: 0.36894676 | U75: 16 | V75: 64.283333 | AA75: =M75-J75 -> -427.4825 | AB75: =M75/J75 -> 0.88125486
B76: 18℃-飯糰 | C76: 一配贅沢鮭魚肚飯糰 | E76: 30 | F76: 3388 | G76: =E76*F76 -> 101640 | I76: 3 | J76: 3000 | K76: =J76/I76 -> 1000 | L76: 3 | M76: =F76/V76*60 -> 2700.1992 | N76: =M76/L76 -> 900.06642 | O76: =L76-I76 -> 0 | P76: =N76-K76 -> -99.933584 | Q76: =N76/K76 -> 0.90006642 | S76: 0.37916667 | T76: 0.43144676 | U76: 14.716667 | V76: 75.283333 | AA76: =M76-J76 -> -299.80075 | AB76: =M76/J76 -> 0.90006642
B77: 18℃-飯糰 | C77: 一配雞肉飯飯糰 | E77: 16.66 | F77: 5904 | G77: =E77*F77 -> 98360.64 | I77: 5 | J77: 3600 | K77: =J77/I77 -> 720 | L77: 5 | M77: =F77/V77*60 -> 3173.2457 | N77: =M77/L77 -> 634.64915 | O77: =L77-I77 -> 0 | P77: =N77-K77 -> -85.350851 | Q77: =N77/K77 -> 0.88145715 | S77: 0.4419213 | T77: 0.51944444 | U77: 15.083333 | V77: 111.63333 | AA77: =M77-J77 -> -426.75426 | AB77: =M77/J77 -> 0.88145715
B89: 平均 | I89: =AVERAGE(I73:I88) -> 4 | J89: =AVERAGE(J73:J88) -> 3360 | K89: =J89/I89 -> 840 | L89: =AVERAGE(L73:L88) -> 4 | M89: =AVERAGE(M73:M88) -> 2985.6767 | N89: =M89/L89 -> 746.41917 | O89: =L89-I89 -> 0 | P89: =N89-K89 -> -93.580828 | Q89: =N89/K89 -> 0.88859425 | S89: =S73 -> 0.25 | T89: =INDEX(T73:T88,COUNTA(T73:T88)) -> 0.51944444 | AA89: =M89-J89 -> -374.32331 | AB89: =M89/J89 -> 0.88859425
A90: 自動包裝機 (二配) | B90: 18℃-壽司手卷 | C90: 二配長野稻荷壽司 | E90: 25.64 | F90: 1469 | G90: =E90*F90 -> 37665.16 | I90: 11 | J90: 3600 | K90: =J90/I90 -> 327.27273 | L90: 11 | M90: =F90/V90*60 -> 3183.8651 | N90: =M90/L90 -> 289.44229 | O90: =L90-I90 -> 0 | P90: =N90-K90 -> -37.830442 | Q90: =N90/K90 -> 0.88440698 | R90: =Q106 -> 0.87360434 | S90: 0.70855324 | T90: 0.72777778 | V90: 27.683333 | AA90: =M90-J90 -> -416.13486 | AB90: =M90/J90 -> 0.88440698 | AC90: =AB106 -> 0.87360434
B91: 18℃-壽司手卷 | C91: 二配雙饗雙手卷 | E91: 29.52 | F91: 1974 | G91: =E91*F91 -> 58272.48 | I91: 12 | J91: 3600 | K91: =J91/I91 -> 300 | L91: 12 | M91: =F91/V91*60 -> 3147.2099 | N91: =M91/L91 -> 262.26749 | O91: =L91-I91 -> 0 | P91: =N91-K91 -> -37.732507 | Q91: =N91/K91 -> 0.87422498 | S91: 0.73150463 | T91: 0.75763889 | U91: 5.3666667 | V91: 37.633333 | AA91: =M91-J91 -> -452.79008 | AB91: =M91/J91 -> 0.87422498
B92: 18℃-壽司手卷 | C92: 二配海饌雙手卷 | E92: 29.85 | F92: 2089 | G92: =E92*F92 -> 62356.65 | I92: 12 | J92: 3600 | K92: =J92/I92 -> 300 | L92: 12 | M92: =F92/V92*60 -> 3145.2949 | N92: =M92/L92 -> 262.1079 | O92: =L92-I92 -> 0 | P92: =N92-K92 -> -37.892095 | Q92: =N92/K92 -> 0.87369302 | S92: 0.76121528 | T92: 0.78888889 | U92: 5.15 | V92: 39.85 | AA92: =M92-J92 -> -454.70514 | AB92: =M92/J92 -> 0.87369302
B93: 18℃-飯糰 | C93: 二配兩粒飯糰(鮪魚.焦糖鮭魚) | E93: 28.57 | F93: 1550 | G93: =E93*F93 -> 44283.5 | I93: 12 | J93: 3600 | K93: =J93/I93 -> 300 | L93: 12 | M93: =F93/V93*60 -> 3124.3001 | N93: =M93/L93 -> 260.35834 | O93: =L93-I93 -> 0 | P93: =N93-K93 -> -39.641657 | Q93: =N93/K93 -> 0.86786114 | S93: 0.79252315 | T93: 0.81319444 | U93: 5.2333333 | V93: 29.766667 | AA93: =M93-J93 -> -475.69989 | AB93: =M93/J93 -> 0.86786114
B94: 18℃-飯糰 | C94: 二配鮮蝦旬彩炊飯飯糰 | E94: 20.17 | F94: 1254 | G94: =E94*F94 -> 25293.18 | I94: 12 | J94: 3600 | K94: =J94/I94 -> 300 | L94: 12 | M94: =F94/V94*60 -> 3250.108 | N94: =M94/L94 -> 270.84233 | O94: =L94-I94 -> 0 | P94: =N94-K94 -> -29.157667 | Q94: =N94/K94 -> 0.90280778 | S94: 0.81666667 | T94: 0.83274306 | U94: 5 | V94: 23.15 | AA94: =M94-J94 -> -349.89201 | AB94: =M94/J94 -> 0.90280778
B95: 18℃-飯糰 | C95: 二配溏心蛋五目飯糰 | E95: 20.42 | F95: 4537 | G95: =E95*F95 -> 92645.54 | I95: 13 | J95: 3600 | K95: =J95/I95 -> 276.92308 | L95: 13 | M95: =F95/V95*60 -> 3019.0758 | N95: =M95/L95 -> 232.2366 | O95: =L95-I95 -> 0 | P95: =N95-K95 -> -44.686478 | Q95: =N95/K95 -> 0.83863216 | S95: 0.83680556 | T95: 0.8994213 | U95: 5.85 | V95: 90.166667 | AA95: =M95-J95 -> -580.92421 | AB95: =M95/J95 -> 0.83863216
B106: 平均 | I106: =AVERAGE(I90:I105) -> 12 | J106: =AVERAGE(J90:J105) -> 3600 | K106: =J106/I106 -> 300 | L106: =AVERAGE(L90:L105) -> 12 | M106: =AVERAGE(M90:M105) -> 3144.9756 | N106: =M106/L106 -> 262.0813 | O106: =L106-I106 -> 0 | P106: =N106-K106 -> -37.918697 | Q106: =N106/K106 -> 0.87360434 | S106: =S90 -> 0.70855324 | T106: =INDEX(T90:T105,COUNTA(T90:T105)) -> 0.8994213 | AA106: =M106-J106 -> -455.02437 | AB106: =M106/J106 -> 0.87360434
A107: (新) 3300型飯糰機 (二配) | B107: 18℃-飯糰 | C107: 二配油蔥G絲飯糰 | E107: 18.18 | F107: 879 | G107: =E107*F107 -> 15980.22 | I107: 4 | J107: 3300 | K107: =J107/I107 -> 825 | L107: 4 | M107: =F107/V107*60 -> 2971.2676 | N107: =M107/L107 -> 742.8169 | O107: =L107-I107 -> 0 | P107: =N107-K107 -> -82.183099 | Q107: =N107/K107 -> 0.90038412 | R107: =Q123 -> 0.89589814 | S107: 0.70850694 | T107: 0.72083333 | V107: 17.75 | AA107: =M107-J107 -> -328.73239 | AB107: =M107/J107 -> 0.90038412 | AC107: =AB123 -> 0.89589814
B108: 18℃-飯糰 | C108: 二配大飯糰鮪魚昆布 | E108: 22.21 | F108: 1937 | G108: =E108*F108 -> 43020.77 | I108: 4 | J108: 3000 | K108: =J108/I108 -> 750 | L108: 4 | M108: =F108/V108*60 -> 2683.0319 | N108: =M108/L108 -> 670.75798 | O108: =L108-I108 -> 0 | P108: =N108-K108 -> -79.242016 | Q108: =N108/K108 -> 0.89434398 | S108: 0.72430556 | T108: 0.75438657 | U108: 5 | V108: 43.316667 | AA108: =M108-J108 -> -316.96806 | AB108: =M108/J108 -> 0.89434398
B109: 18℃-飯糰 | C109: 二配大飯糰滷肉飯加蛋 | E109: 22.48 | F109: 1190 | G109: =E109*F109 -> 26751.2 | I109: 5 | J109: 3000 | K109: =J109/I109 -> 600 | L109: 5 | M109: =F109/V109*60 -> 2682.5297 | N109: =M109/L109 -> 536.50595 | O109: =L109-I109 -> 0 | P109: =N109-K109 -> -63.494051 | Q109: =N109/K109 -> 0.89417658 | S109: 0.75859954 | T109: 0.77708333 | U109: 6.0666667 | V109: 26.616667 | AA109: =M109-J109 -> -317.47026 | AB109: =M109/J109 -> 0.89417658
B110: 18℃-飯糰 | C110: 二配大飯糰韓式蒜烤豬五花 | E110: 24.54 | F110: 2018 | G110: =E110*F110 -> 49521.72 | I110: 4 | J110: 3000 | K110: =J110/I110 -> 750 | L110: 4 | M110: =F110/V110*60 -> 2682.7179 | N110: =M110/L110 -> 670.67947 | O110: =L110-I110 -> 0 | P110: =N110-K110 -> -79.320532 | Q110: =N110/K110 -> 0.89423929 | S110: 0.78055556 | T110: 0.81189815 | U110: 5 | V110: 45.133333 | AA110: =M110-J110 -> -317.28213 | AB110: =M110/J110 -> 0.89423929
B123: 平均 | I123: =AVERAGE(I107:I122) -> 4.25 | J123: =AVERAGE(J107:J122) -> 3075 | K123: =J123/I123 -> 723.52941 | L123: =AVERAGE(L107:L122) -> 4.25 | M123: =AVERAGE(M107:M122) -> 2754.8868 | N123: =M123/L123 -> 648.20866 | O123: =L123-I123 -> 0 | P123: =N123-K123 -> -75.320755 | Q123: =N123/K123 -> 0.89589814 | S123: =S107 -> 0.70850694 | T123: =INDEX(T107:T122,COUNTA(T107:T122)) -> 0.81189815 | AA123: =M123-J123 -> -320.11321 | AB123: =M123/J123 -> 0.89589814
...

Sheet 0331(4度C)
A1: 大溪廠日報分析 | C1: 總生產量 | D1: =SUM(F5:F123) -> 60225 | E1: 營業額 | F1: =SUM(G5:G123) -> 3253242.6 | G1: 出勤人數 | H1: =L21+L38+L55+L72+L89+L106+L123 -> 143.15 | I1: 產線配置圖 | L1: 生產實績 | O1: 人時性差異分析 | S1: 日報登錄 | Y1: 合計次數 | Z1: 合計(時間/分) | AA1: 產線異常 分析說明(5分鐘以上) | AC1: 合計次數 | AD1: 合計(時間/分) | AE1: 產能差異分析
A2: 46112 | C2: 人時性 | D2: =AVERAGE(N21,N38,N55,N72,N89,N106,N123) -> 103.06964 | E2: 平均廠價 | F2: =F1/D1 -> 54.018142 | G2: 多次生產數 | H2: =COUNT(H5:H123) -> 0 | Y2: =SUM(Y21,Y38,Y55,Y72,Y89,Y106,Y123) -> 0 | Z2: =SUM(Z21,Z38,Z55,Z72,Z89,Z106,Z123) -> 0 | AC2: =SUM(AC21,AC38,AC55,AC72,AC89,AC106,AC123) -> 0 | AD2: =SUM(AD21,AD38,AD55,AD72,AD89,AD106,AD123) -> 0
A3: 線別 | B3: 品類 | C3: 品名 | E3: 廠價 | F3: 生產量 | G3: 營收 | H3: 多次 生產 | I3: 人數 | J3: 產能/時 | K3: 人時性 | L3: 人數 | M3: 產能/時 | N3: 人時性 | O3: 人數 | P3: 人時性 | Q3: 達成率 | R3: 達成率 平均 | S3: 生產時間 | U3: 換線、休息/分 | V3: 稼動時間/分 | W3: 休息時間 | Y3: 產線異常統計(5分鐘以上) | AA3: (屏榮回填) | AC3: 短暫停線統計(5分鐘以下) | AE3: 產能/時 | AF3: 達成率 | AG3: 達成率平均
S4: 開始 | T4: 結束 | W4: 開始 | X4: 結束 | Y4: 次數 | Z4: 時間/分 | AC4: 總次數 | AD4: 設備因素(次數)
A5: 便當二線 | B5: 微波主食 | C5: 糖燻野郎三十天熟成牛飯 | E5: 56.77 | F5: 3703 | G5: =E5*F5 -> 210219.31 | I5: 24 | J5: 2000 | K5: =J5/I5 -> 83.333333 | L5: 24 | M5: =F5/V5*60 -> 1785.2953 | N5: =M5/L5 -> 74.387304 | O5: =L5-I5 -> 0 | P5: =N5-K5 -> -8.9460292 | Q5: =N5/K5 -> 0.89264765 | R5: =Q21 -> 0.89321253 | S5: 0.25 | T5: 0.33642361 | V5: 124.45 | AE5: =M5-J5 -> -214.7047 | AF5: =M5/J5 -> 0.89264765 | AG5: =AF21 -> 0.89321253
B6: 便當 | C6: 健身G肉餐盒 | E6: 59.52 | F6: 6208 | G6: =E6*F6 -> 369500.16 | I6: 24 | J6: 2000 | K6: =J6/I6 -> 83.333333 | L6: 24 | M6: =F6/V6*60 -> 1786.0465 | N6: =M6/L6 -> 74.418605 | O6: =L6-I6 -> 0 | P6: =N6-K6 -> -8.9147287 | Q6: =N6/K6 -> 0.89302326 | S6: 0.33989583 | T6: 0.48472222 | U6: 5 | V6: 208.55 | W6: 0.48472222 | X6: 0.52361111 | AE6: =M6-J6 -> -213.95349 | AF6: =M6/J6 -> 0.89302326
B7: 便當 | C7: 嫩烤香料雞胸排蔬滿盒 | E7: 77.34 | F7: 2593 | G7: =E7*F7 -> 200542.62 | I7: 23 | J7: 2000 | K7: =J7/I7 -> 86.956522 | L7: 23 | M7: =F7/V7*60 -> 1787.9333 | N7: =M7/L7 -> 77.736232 | O7: =L7-I7 -> 0 | P7: =N7-K7 -> -9.2202893 | Q7: =N7/K7 -> 0.89396667 | S7: 0.52361111 | T7: 0.58403935 | U7: 56 | V7: 87.016667 | AE7: =M7-J7 -> -212.06665 | AF7: =M7/J7 -> 0.89396667
B21: 平均 | I21: =AVERAGE(I5:I20) -> 23.666667 | J21: =AVERAGE(J5:J20) -> 2000 | K21: =J21/I21 -> 84.507042 | L21: =AVERAGE(L5:L20) -> 23.666667 | M21: =AVERAGE(M5:M20) -> 1786.4251 | N21: =M21/L21 -> 75.482749 | O21: =L21-I21 -> 0 | P21: =N21-K21 -> -9.0242936 | Q21: =N21/K21 -> 0.89321253 | S21: =S5 -> 0.25 | T21: =INDEX(T5:T20,COUNTA(T5:T20)) -> 0.58403935 | Y21: =SUM(Y5:Y20) -> 0 | Z21: =SUM(Z5:Z20) -> 0 | AC21: =SUM(AC5:AC20) -> 0 | AD21: =SUM(AD5:AD20) -> 0 | AE21: =M21-J21 -> -213.57495 | AF21: =M21/J21 -> 0.89321253
A22: 涼麵一線 | B22: 便當 | C22: 香腸腿排雙拼便當 | E22: 53.76 | F22: 3308 | G22: =E22*F22 -> 177838.08 | I22: 20 | J22: 2000 | K22: =J22/I22 -> 100 | L22: 20 | M22: =F22/V22*60 -> 1786.4986 | N22: =M22/L22 -> 89.324932 | O22: =L22-I22 -> 0 | P22: =N22-K22 -> -10.675068 | Q22: =N22/K22 -> 0.89324932 | R22: =Q38 -> 0.88272219 | S22: 0.25 | T22: 0.32715278 | V22: 111.1 | AE22: =M22-J22 -> -213.50135 | AF22: =M22/J22 -> 0.89324932 | AG22: =AF38 -> 0.8929864
B23: 便當 | C23: 經典滷肉飯 | E23: 47.37 | F23: 1905 | G23: =E23*F23 -> 90239.85 | I23: 21 | J23: 2000 | K23: =J23/I23 -> 95.238095 | L23: 22 | M23: =F23/V23*60 -> 1785.4725 | N23: =M23/L23 -> 81.157842 | O23: =L23-I23 -> 1 | P23: =N23-K23 -> -14.080253 | Q23: =N23/K23 -> 0.85215735 | S23: 0.33055556 | T23: 0.37501157 | U23: 4.9 | V23: 64.016667 | AE23: =M23-J23 -> -214.52747 | AF23: =M23/J23 -> 0.89273627
B24: 便當 | C24: 蔬活腿排補力餐盒 | E24: 71.55 | F24: 2707 | G24: =E24*F24 -> 193685.85 | I24: 22 | J24: 2000 | K24: =J24/I24 -> 90.909091 | L24: 22 | M24: =F24/V24*60 -> 1786.4711 | N24: =M24/L24 -> 81.203233 | O24: =L24-I24 -> 0 | P24: =N24-K24 -> -9.7058578 | Q24: =N24/K24 -> 0.89323556 | S24: 0.37922454 | T24: 0.44236111 | U24: 6.0666667 | V24: 90.916667 | W24: 0.44236111 | X24: 0.48158565 | AE24: =M24-J24 -> -213.52887 | AF24: =M24/J24 -> 0.89323556
B25: 便當 | C25: 海陸雙拼肉肉餐盒 | E25: 59.54 | F25: 3497 | G25: =E25*F25 -> 208211.38 | I25: 23 | J25: 2000 | K25: =J25/I25 -> 86.956522 | L25: 23 | M25: =F25/V25*60 -> 1785.4489 | N25: =M25/L25 -> 77.628212 | O25: =L25-I25 -> 0 | P25: =N25-K25 -> -9.3283099 | Q25: =N25/K25 -> 0.89272444 | S25: 0.48158565 | T25: 0.56319444 | U25: 56.483333 | V25: 117.51667 | AE25: =M25-J25 -> -214.55113 | AF25: =M25/J25 -> 0.89272444
B38: 平均 | I38: =AVERAGE(I22:I37) -> 21.5 | J38: =AVERAGE(J22:J37) -> 2000 | K38: =J38/I38 -> 93.023256 | L38: =AVERAGE(L22:L37) -> 21.75 | M38: =AVERAGE(M22:M37) -> 1785.9728 | N38: =M38/L38 -> 82.113692 | O38: =L38-I38 -> 0.25 | P38: =N38-K38 -> -10.909564 | Q38: =N38/K38 -> 0.88272219 | S38: =S22 -> 0.25 | T38: =INDEX(T22:T37,COUNTA(T22:T37)) -> 0.56319444 | Y38: =SUM(Y22:Y37) -> 0 | Z38: =SUM(Z22:Z37) -> 0 | AC38: =SUM(AC22:AC37) -> 0 | AD38: =SUM(AD22:AD37) -> 0 | AE38: =M38-J38 -> -214.0272 | AF38: =M38/J38 -> 0.8929864
A39: 涼麵二線 | B39: 便當 | C39: 美式雞丁餐盒 | E39: 59.34 | F39: 2284 | G39: =E39*F39 -> 135532.56 | I39: 24 | J39: 2000 | K39: =J39/I39 -> 83.333333 | L39: 24 | M39: =F39/V39*60 -> 1787.0898 | N39: =M39/L39 -> 74.462073 | O39: =L39-I39 -> 0 | P39: =N39-K39 -> -8.8712599 | Q39: =N39/K39 -> 0.89354488 | R39: =Q55 -> 0.86841068 | S39: 0.25021991 | T39: 0.30347222 | V39: 76.683333 | AE39: =M39-J39 -> -212.91024 | AF39: =M39/J39 -> 0.89354488 | AG39: =AF55 -> 0.86841068
B40: 便當 | C40: 烤蛋白餐盒 | E40: 58.67 | F40: 4796 | G40: =E40*F40 -> 281381.32 | I40: 23 | J40: 2000 | K40: =J40/I40 -> 86.956522 | L40: 23 | M40: =F40/V40*60 -> 1786.9592 | N40: =M40/L40 -> 77.693879 | O40: =L40-I40 -> 0 | P40: =N40-K40 -> -9.2626425 | Q40: =N40/K40 -> 0.89347961 | S40: 0.30694444 | T40: 0.41877315 | U40: 5 | V40: 161.03333 | W40: 0.41877315 | X40: 0.45763889 | AE40: =M40-J40 -> -213.04078 | AF40: =M40/J40 -> 0.89347961
B41: 便當 | C41: 香檸奶油魚排蔬滿盒 | E41: 77.35 | F41: 5782 | G41: =E41*F41 -> 447237.7 | I41: 26 | J41: 2000 | K41: =J41/I41 -> 76.923077 | L41: 26 | M41: =F41/V41*60 -> 1636.4151 | N41: =M41/L41 -> 62.939042 | O41: =L41-I41 -> 0 | P41: =N41-K41 -> -13.984035 | Q41: =N41/K41 -> 0.81820755 | S41: 0.45763889 | T41: 0.60486111 | U41: 55.966667 | V41: 212 | AE41: =M41-J41 -> -363.58491 | AF41: =M41/J41 -> 0.81820755
B55: 平均 | I55: =AVERAGE(I39:I54) -> 24.333333 | J55: =AVERAGE(J39:J54) -> 2000 | K55: =J55/I55 -> 82.191781 | L55: =AVERAGE(L39:L54) -> 24.333333 | M55: =AVERAGE(M39:M54) -> 1736.8214 | N55: =M55/L55 -> 71.37622 | O55: =L55-I55 -> 0 | P55: =N55-K55 -> -10.815561 | Q55: =N55/K55 -> 0.86841068 | S55: =S39 -> 0.25021991 | T55: =INDEX(T39:T54,COUNTA(T39:T54)) -> 0.60486111 | Y55: =SUM(Y39:Y54) -> 0 | Z55: =SUM(Z39:Z54) -> 0 | AC55: =SUM(AC39:AC54) -> 0 | AD55: =SUM(AD39:AD54) -> 0 | AE55: =M55-J55 -> -263.17864 | AF55: =M55/J55 -> 0.86841068
A56: 涼麵三線 | B56: 微波小吃 | C56: 日式茶碗蒸 | E56: 19.7 | F56: 3576 | G56: =E56*F56 -> 70447.2 | I56: 13 | J56: 1200 | K56: =J56/I56 -> 92.307692 | L56: 13 | M56: =F56/V56*60 -> 1079.6377 | N56: =M56/L56 -> 83.049054 | O56: =L56-I56 -> 0 | P56: =N56-K56 -> -9.258638 | Q56: =N56/K56 -> 0.89969809 | R56: =Q72 -> 0.90173364 | S56: 0.25018519 | T56: 0.38819444 | V56: 198.73333 | AE56: =M56-J56 -> -120.36229 | AF56: =M56/J56 -> 0.89969809 | AG56: =AF72 -> 0.90173364
B57: 4℃-壽司手卷 | C57: 明太子泡菜牛飯卷 | E57: 27.05 | F57: 630 | G57: =E57*F57 -> 17041.5 | I57: 6 | J57: 3273 | K57: =J57/I57 -> 545.5 | L57: 6 | M57: =F57/V57*60 -> 2960.8355 | N57: =M57/L57 -> 493.47258 | O57: =L57-I57 -> 0 | P57: =N57-K57 -> -52.027415 | Q57: =N57/K57 -> 0.90462435 | S57: 0.3918287 | T57: 0.40069444 | U57: 5.2333333 | V57: 12.766667 | AE57: =M57-J57 -> -312.16449 | AF57: =M57/J57 -> 0.90462435
B58: 4℃-壽司手卷 | C58: 香料咖哩烤雞飯卷 | E58: 26.21 | F58: 1470 | G58: =E58*F58 -> 38528.7 | I58: 6 | J58: 3273 | K58: =J58/I58 -> 545.5 | L58: 6 | M58: =F58/V58*60 -> 2961.3878 | N58: =M58/L58 -> 493.56463 | O58: =L58-I58 -> 0 | P58: =N58-K58 -> -51.935367 | Q58: =N58/K58 -> 0.9047931 | S58: 0.40431713 | T58: 0.425 | U58: 5.2166667 | V58: 29.783333 | AE58: =M58-J58 -> -311.6122 | AF58: =M58/J58 -> 0.9047931
B59: 4℃-飯糰 | C59: 蟹味可樂餅風炸飯糰 | E59: 21.92 | F59: 1355 | G59: =E59*F59 -> 29701.6 | I59: 6 | J59: 3600 | K59: =J59/I59 -> 600 | L59: 6 | M59: =F59/V59*60 -> 3262.8763 | N59: =M59/L59 -> 543.81271 | O59: =L59-I59 -> 0 | P59: =N59-K59 -> -56.187291 | Q59: =N59/K59 -> 0.90635452 | S59: 0.42922454 | T59: 0.44652778 | U59: 6.0833333 | V59: 24.916667 | W59: 0.44652778 | X59: 0.48489583 | AE59: =M59-J59 -> -337.12375 | AF59: =M59/J59 -> 0.90635452
B60: 4℃-飯糰 | C60: 麻油雞飯糰 | E60: 29.97 | F60: 3051 | G60: =E60*F60 -> 91438.47 | I60: 21 | J60: 2790 | K60: =J60/I60 -> 132.85714 | L60: 21 | M60: =F60/V60*60 -> 2482.1695 | N60: =M60/L60 -> 118.19855 | O60: =L60-I60 -> 0 | P60: =N60-K60 -> -14.658596 | Q60: =N60/K60 -> 0.88966648 | S60: 0.48489583 | T60: 0.53611111 | U60: 55.25 | V60: 73.75 | AE60: =M60-J60 -> -307.83051 | AF60: =M60/J60 -> 0.88966648
B72: 平均 | I72: =AVERAGE(I56:I71) -> 10.4 | J72: =AVERAGE(J56:J71) -> 2827.2 | K72: =J72/I72 -> 271.84615 | L72: =AVERAGE(L56:L71) -> 10.4 | M72: =AVERAGE(M56:M71) -> 2549.3814 | N72: =M72/L72 -> 245.13282 | O72: =L72-I72 -> 0 | P72: =N72-K72 -> -26.713332 | Q72: =N72/K72 -> 0.90173364 | S72: =S56 -> 0.25018519 | T72: =INDEX(T56:T71,COUNTA(T56:T71)) -> 0.53611111 | Y72: =SUM(Y56:Y71) -> 0 | Z72: =SUM(Z56:Z71) -> 0 | AC72: =SUM(AC56:AC71) -> 0 | AD72: =SUM(AD56:AD71) -> 0 | AE72: =M72-J72 -> -277.81865 | AF72: =M72/J72 -> 0.90173364
A73: 便當二線 (二配) | B73: 微波主食 | C73: 二配蒙古風味烤肉飯 | E73: 58.17 | F73: 1312 | G73: =E73*F73 -> 76319.04 | I73: 19 | J73: 1800 | K73: =J73/I73 -> 94.736842 | L73: 19 | M73: =F73/V73*60 -> 1605.9844 | N73: =M73/L73 -> 84.525493 | O73: =L73-I73 -> 0 | P73: =N73-K73 -> -10.21135 | Q73: =N73/K73 -> 0.89221353 | R73: =Q89 -> 0.89233904 | S73: 0.70833333 | T73: 0.74237269 | V73: 49.016667 | AE73: =M73-J73 -> -194.01564 | AF73: =M73/J73 -> 0.89221353 | AG73: =AF89 -> 0.89233904
B74: 微波主食 | C74: 二配鐵板豆腐燴蛋蓋飯 | E74: 44.98 | F74: 2801 | G74: =E74*F74 -> 125988.98 | I74: 21 | J74: 1800 | K74: =J74/I74 -> 85.714286 | L74: 21 | M74: =F74/V74*60 -> 1606.4362 | N74: =M74/L74 -> 76.496962 | O74: =L74-I74 -> 0 | P74: =N74-K74 -> -9.217324 | Q74: =N74/K74 -> 0.89246455 | S74: 0.74609954 | T74: 0.81875 | U74: 5.3666667 | V74: 104.61667 | AE74: =M74-J74 -> -193.5638 | AF74: =M74/J74 -> 0.89246455
B89: 平均 | I89: =AVERAGE(I73:I88) -> 20 | J89: =AVERAGE(J73:J88) -> 1800 | K89: =J89/I89 -> 90 | L89: =AVERAGE(L73:L88) -> 20 | M89: =AVERAGE(M73:M88) -> 1606.2103 | N89: =M89/L89 -> 80.310514 | O89: =L89-I89 -> 0 | P89: =N89-K89 -> -9.6894861 | Q89: =N89/K89 -> 0.89233904 | S89: =S73 -> 0.70833333 | T89: =INDEX(T73:T88,COUNTA(T73:T88)) -> 0.81875 | Y89: =SUM(Y73:Y88) -> 0 | Z89: =SUM(Z73:Z88) -> 0 | AC89: =SUM(AC73:AC88) -> 0 | AD89: =SUM(AD73:AD88) -> 0 | AE89: =M89-J89 -> -193.78972 | AF89: =M89/J89 -> 0.89233904
A90: 涼麵一線 (二配) | B90: 微波主食 | C90: 二配失控起司薯餅焗飯 | E90: 54.09 | F90: 1132 | G90: =E90*F90 -> 61229.88 | I90: 19 | J90: 2000 | K90: =J90/I90 -> 105.26316 | L90: 20 | M90: =F90/V90*60 -> 1787.3684 | N90: =M90/L90 -> 89.368421 | O90: =L90-I90 -> 1 | P90: =N90-K90 -> -15.894737 | Q90: =N90/K90 -> 0.849 | R90: =Q106 -> 0.87106919 | S90: 0.70833333 | T90: 0.73472222 | V90: 38 | AE90: =M90-J90 -> -212.63158 | AF90: =M90/J90 -> 0.89368421 | AG90: =AF106 -> 0.8934043
B91: 微波主食 | C91: 二配濃起司燻腸紅醬焗烤飯 | E91: 50.67 | F91: 2533 | G91: =E91*F91 -> 128347.11 | I91: 20 | J91: 2000 | K91: =J91/I91 -> 100 | L91: 20 | M91: =F91/V91*60 -> 1786.2488 | N91: =M91/L91 -> 89.312439 | O91: =L91-I91 -> 0 | P91: =N91-K91 -> -10.687561 | Q91: =N91/K91 -> 0.89312439 | S91: 0.73819444 | T91: 0.79728009 | U91: 5 | V91: 85.083333 | AE91: =M91-J91 -> -213.75122 | AF91: =M91/J91 -> 0.89312439
B106: 平均 | I106: =AVERAGE(I90:I105) -> 19.5 | J106: =AVERAGE(J90:J105) -> 2000 | K106: =J106/I106 -> 102.5641 | L106: =AVERAGE(L90:L105) -> 20 | M106: =AVERAGE(M90:M105) -> 1786.8086 | N106: =M106/L106 -> 89.34043 | O106: =L106-I106 -> 0.5 | P106: =N106-K106 -> -13.223673 | Q106: =N106/K106 -> 0.87106919 | S106: =S90 -> 0.70833333 | T106: =INDEX(T90:T105,COUNTA(T90:T105)) -> 0.79728009 | Y106: =SUM(Y90:Y105) -> 0 | Z106: =SUM(Z90:Z105) -> 0 | AC106: =SUM(AC90:AC105) -> 0 | AD106: =SUM(AD90:AD105) -> 0 | AE106: =M106-J106 -> -213.1914 | AF106: =M106/J106 -> 0.8934043
A107: 涼麵二線 (二配) | B107: 微波主食 | C107: 二配哞哞培根奶香海陸焗飯 | E107: 47.6 | F107: 1885 | G107: =E107*F107 -> 89726 | I107: 23 | J107: 2000 | K107: =J107/I107 -> 86.956522 | L107: 23 | M107: =F107/V107*60 -> 1789.0852 | N107: =M107/L107 -> 77.786311 | O107: =L107-I107 -> 0 | P107: =N107-K107 -> -9.1702106 | Q107: =N107/K107 -> 0.89454258 | R107: =Q123 -> 0.89390684 | S107: 0.70833333 | T107: 0.7522338 | V107: 63.216667 | AE107: =M107-J107 -> -210.91484 | AF107: =M107/J107 -> 0.89454258 | AG107: =AF123 -> 0.89390684
B108: 微波主食 | C108: 二配黃金雞排蘑菇白醬歐姆蛋飯 | E108: 56.87 | F108: 1658 | G108: =E108*F108 -> 94290.46 | I108: 23 | J108: 2000 | K108: =J108/I108 -> 86.956522 | L108: 23 | M108: =F108/V108*60 -> 1787.0659 | N108: =M108/L108 -> 77.698516 | O108: =L108-I108 -> 0 | P108: =N108-K108 -> -9.2580057 | Q108: =N108/K108 -> 0.89353293 | S108: 0.75578704 | T108: 0.79444444 | U108: 5.1166667 | V108: 55.666667 | AE108: =M108-J108 -> -212.93413 | AF108: =M108/J108 -> 0.89353293
B109: 微波主食 | C109: 二配里肌豬排可可咖哩歐姆蛋飯 | E109: 56.79 | F109: 2039 | G109: =E109*F109 -> 115794.81 | I109: 23 | J109: 2000 | K109: =J109/I109 -> 86.956522 | L109: 23 | M109: =F109/V109*60 -> 1787.29 | N109: =M109/L109 -> 77.708261 | O109: =L109-I109 -> 0 | P109: =N109-K109 -> -9.2482612 | Q109: =N109/K109 -> 0.893645 | S109: 0.79861111 | T109: 0.84614583 | U109: 6 | V109: 68.45 | AE109: =M109-J109 -> -212.71001 | AF109: =M109/J109 -> 0.893645
B123: 平均 | I123: =AVERAGE(I107:I122) -> 23 | J123: =AVERAGE(J107:J122) -> 2000 | K123: =J123/I123 -> 86.956522 | L123: =AVERAGE(L107:L122) -> 23 | M123: =AVERAGE(M107:M122) -> 1787.8137 | N123: =M123/L123 -> 77.731029 | O123: =L123-I123 -> 0 | P123: =N123-K123 -> -9.2254925 | Q123: =N123/K123 -> 0.89390684 | S123: =S107 -> 0.70833333 | T123: =INDEX(T107:T122,COUNTA(T107:T122)) -> 0.84614583 | Y123: =SUM(Y107:Y122) -> 0 | Z123: =SUM(Z107:Z122) -> 0 | AC123: =SUM(AC107:AC122) -> 0 | AD123: =SUM(AD107:AD122) -> 0 | AE123: =M123-J123 -> -212.18633 | AF123: =M123/J123 -> 0.89390684
AA125: 原因回覆
AA126: 1.當日出勤人數較多
AA127: 2.當日出勤人數較少
AA128: 3.當日出勤熟手較多
AA129: 4.當日出勤新人較多
AA130: 5.機台夾盒
AA131: 6.封膜不順
...

Sheet 0330
B1: 屏榮 大溪廠組合室生產人時性分析
B3: 日期 | C3: 115.03.30星期一 | E3: 訂單量 | F3: ='0330(18度C)'!D1+'0330(4度C)'!D1 -> 175057 | H3: 營業額 | I3: ='0330(18度C)'!F1+'0330(4度C)'!F1 -> 5101122.3
B4: 人時性 | C4: 項目 | E4: ➀ | G4: ➁ | I4: ➂ | K4: ④ | M4: ⑤ | O4: 異常停線 | Q4: 短暫停線
C5: 組合室 | E5: 全溫層 | G5: 4度C-各編組展開(一配) | I5: 4度C-各編組展開(二配) | K5: 18度C-各編組展開(一配) | M5: 18度C-各編組展開(二配) | O5: 合計次數 | P5: 時間 | Q5: 合計次數 | R5: 設備次數
C6: 排關平均 | E6: =AVERAGE(D14:O14,D32:X32) -> 467.69622 | F6: =AVERAGE(#REF!,D14:K14) -> #REF! | G6: =AVERAGE(D14:K14) -> 160.21605 | I6: =AVERAGE(L14:O14) -> 93.173541 | K6: =AVERAGE(D32:O32) -> 742.62938 | M6: =AVERAGE(P32:X32) -> 712.40196 | O6: ='0330(4度C)'!Y2 -> 0 | P6: ='0330(4度C)'!Z2 -> 0 | Q6: ='0330(4度C)'!AC2 -> 0 | R6: ='0330(4度C)'!AD2 -> 0
C7: 實績平均 | E7: =AVERAGE(D15:O15,D33:X33) -> 416.63274 | F7: =AVERAGE(#REF!,D15:K15) -> #REF! | G7: =AVERAGE(D15:K15) -> 144.01507 | I7: =AVERAGE(L15:O15) -> 82.459435 | K7: =AVERAGE(D33:O33) -> 662.35517 | M7: =AVERAGE(P33:X33) -> 632.72734
C8: 達成率平均 | E8: =AVERAGE(D16:O16,D34:X34) -> 0.88965443 | F8: =AVERAGE(D16:K16,#REF!) -> #REF! | G8: =AVERAGE(D16:K16) -> 0.89466849 | I8: =AVERAGE(L16:O16) -> 0.88575763 | K8: =AVERAGE(D34:O34) -> 0.89125794 | M8: =AVERAGE(P34:X34) -> 0.88555858
O9: ※現行日本鮮食廠以達成率80%為基本(即為現行KPI)
B11: 溫層 | D11: ➁4度C-各編組展開 | L11: ➂4度C-各編組展開
B12: 編組 | D12: 1 | E12: 2 | F12: 3 | G12: 4 | H12: 5 | I12: 6 | J12: 7 | K12: 8 | L12: 1 | M12: 2 | N12: 3 | O12: 4
D13: 便當一線 | E13: 便當二線 | F13: 涼麵一線 | G13: 涼麵二線 | H13: 涼麵三線 | I13: 自動包裝機 | J13: 自動包裝機2 | K13: 自動包裝機3 | L13: 便當一線 | M13: 便當二線 | N13: 涼麵一線 | O13: 涼麵二線
B14: 人時性 | C14: 排關 | D14: - | E14: 84.507042 | F14: 104.64286 | G14: 85.714286 | H14: 366 | I14: - | J14: - | K14: - | L14: - | M14: 90 | N14: 102.5641 | O14: 86.956522
C15: 實績 | D15: - | E15: 75.48412 | F15: 92.859223 | G15: 76.565931 | H15: 331.15099 | I15: - | J15: - | K15: - | L15: - | M15: 80.312496 | N15: 89.339978 | O15: 77.72583
C16: 達成率 | D16: - | E16: =E15/E14 -> 0.89322876 | F16: =F15/F14 -> 0.88739189 | G16: =G15/G14 -> 0.89326919 | H16: =H15/H14 -> 0.90478413 | I16: - | J16: - | K16: - | L16: - | M16: =M15/M14 -> 0.89236107 | N16: =N15/N14 -> 0.87106479 | O16: =O15/O14 -> 0.89384704
B17: 作業 時間 | C17: 開始 | D17: - | E17: 0.25005787 | F17: 0.25011574 | G17: 0.25006944 | H17: 0.25 | I17: - | J17: - | K17: - | L17: - | M17: 0.70855324 | N17: 0.70833333 | O17: 0.70833333
C18: 結束 | D18: - | E18: 0.56527778 | F18: 0.53126157 | G18: 0.48680556 | H18: 0.45277778 | I18: - | J18: - | K18: - | L18: - | M18: 0.82430556 | N18: 0.80013889 | O18: 0.85006944
B19: 產線異常 (5分鐘以上) | C19: 次數
C20: 時間/分
B21: 短暫停線 (5分鐘以下) | C21: 次數
C22: 設備次數
B23: 配置人數 | D23: - | E23: 23.666667 | F23: 21.5 | G23: 23.333333 | H23: 7.75 | I23: - | J23: - | K23: - | L23: - | M23: 20 | N23: 20 | O23: 23
B24: 主要應用設備 | D24: L型封口機 | E24: ET-55 | F24: ET-55 | G24: ET-55 | H24: ET-600 | I24: 伺服包裝機 | J24: 伺服包裝機 | K24: 伺服包裝機 | L24: L型封口機 | M24: ET-55 | N24: ET-55 | O24: ET-55
B25: 次要應用設備 | D25: 伺服包裝機 | H25: 伺服包裝機
B26: 備註 | H26: 涼麵+烤飯糰 | I26: 大口飯糰線 | K26: 烤飯糰+手卷
B29: 溫層 | D29: ➃18度C-各編組展開 (一配) | P29: ⑤18度C-各編組展開 (二配)
B30: 編組 | D30: 1 | E30: 2 | F30: 3 | G30: 4 | H30: 5 | I30: 6 | J30: 7 | K30: 8 | L30: 9 | M30: 10 | N30: 11 | O30: 12 | P30: 1 | Q30: 2 | R30: 3 | S30: 4 | T30: 5 | U30: 6 | V30: 7 | W30: 8 | X30: 9
D31: 便當一線 | E31: 涼麵一線 | F31: 涼麵三線 | G31: 自動包裝機 | H31: 自動包裝機2 | I31: 自動包裝機3 | J31: 味付飯糰線B | K31: (舊) 3300型飯糰線 | L31: 3000型飯糰線 | M31: (新) 3300型飯糰機 | N31: GKK3600型 飯糰機 | O31: GKK3600型 飯糰機2 | P31: 自動包裝機 | Q31: 自動包裝機2 | R31: 自動包裝機3 | S31: 味付飯糰線B | T31: (舊) 3300型飯糰線 | U31: 3000型飯糰線 | V31: (新) 3300型飯糰機 | W31: GKK3600型 飯糰機 | X31: GKK3600型 飯糰機2
B32: 人時性 | C32: 排關 | D32: - | E32: - | F32: - | G32: 328.81356 | H32: 433.33333 | I32: - | J32: - | K32: - | L32: - | M32: 1100 | N32: 1035 | O32: 816 | P32: 300 | Q32: - | R32: - | S32: - | T32: - | U32: - | V32: 723.52941 | W32: 979.41176 | X32: 846.66667
C33: 實績 | D33: - | E33: - | F33: - | G33: 290.13059 | H33: 390.053 | I33: - | J33: - | K33: - | L33: - | M33: 990.3503 | N33: 917.18813 | O33: 724.05384 | P33: 261.18856 | Q33: - | R33: - | S33: - | T33: - | U33: - | V33: 648.18555 | W33: 871.17924 | X33: 750.356
C34: 達成率 | D34: - | E34: - | F34: - | G34: =G33/G32 -> 0.88235592 | H34: =H33/H32 -> 0.90012232 | I34: - | J34: - | K34: - | L34: - | M34: =M33/M32 -> 0.90031845 | N34: =N33/N32 -> 0.88617211 | O34: =O33/O32 -> 0.88732088 | P34: =P33/P32 -> 0.87062854 | Q34: - | R34: - | S34: - | T34: - | U34: - | V34: =V33/V32 -> 0.89586621 | W34: =W33/W32 -> 0.88949232 | X34: =X33/X32 -> 0.88624725
B35: 作業 時間 | C35: 開始 | D35: - | E35: - | F35: - | G35: 0.25001157 | H35: 0.29195602 | I35: - | J35: - | K35: - | L35: - | M35: 0.35440972 | N35: 0.25001157 | O35: 0.25 | P35: 0.70833333 | Q35: - | R35: - | S35: - | T35: - | U35: - | V35: 0.7083912 | W35: 0.70833333 | X35: 0.70833333
C36: 結束 | D36: - | E36: - | F36: - | G36: 0.44791667 | H36: 0.33148148 | I36: - | J36: - | K36: - | L36: - | M36: 0.40694444 | N36: 0.60790509 | O36: 0.59513889 | P36: 0.90902778 | Q36: - | R36: - | S36: - | T36: - | U36: - | V36: 0.81319444 | W36: 1.2013889 | X36: 1.1819792
B37: 配置人數 | D37: - | E37: - | F37: - | G37: 9.8333333 | H37: 6 | I37: - | J37: - | K37: - | L37: - | M37: 3 | N37: 3.3333333 | O37: 4.1666667 | P37: 12 | Q37: - | R37: - | S37: - | T37: - | U37: - | V37: 4.25 | W37: 3.4 | X37: 4.0909091
B38: 主要應用設備 | D38: 伺服包裝機 | E38: ET-55 | F38: ET-600 | G38: 夾心型 | H38: 伺服包裝機 | I38: 伺服包裝機 | J38: 夾心型 | K38: 3300型 | L38: 3300型 | M38: 3300型 | N38: GKK | O38: GKK | P38: 夾心型 | Q38: 伺服包裝機 | R38: 伺服包裝機 | S38: 夾心型 | T38: 3300型 | U38: 3300型 | V38: 3300型 | W38: GKK | X38: GKK
B39: 次要應用設備
B40: 備註

Sheet 0330(18度C)
A1: 大溪廠日報分析 | C1: 總生產量 | D1: =SUM(F5:F157) -> 121289 | E1: 營業額 | F1: =SUM(G5:G157) -> 2353766.5 | G1: 出勤人數 | H1: =L21+L38+L55+L72+L89+L106+L123+L140+L157 -> 50.074242 | I1: 產線配置圖 | L1: 生產實績 | O1: 人時性差異分析 | S1: 日報登錄 | Y1: 分析說明 | AA1: 產能差異分析
A2: 46111 | C2: 人時性 | D2: =AVERAGE(N21,N38,N55,N72,N89,N106,N123,N140,N157) -> 649.18725 | E2: 平均廠價 | F2: =F1/D1 -> 19.406265 | G2: 多次生產數 | H2: =COUNT(H5:H157) -> 12
A3: 線別 | B3: 品類 | C3: 品名 | E3: 廠價 | F3: 生產量 | G3: 營收 | H3: 多次 生產 | I3: 人數 | J3: 產能/時 | K3: 人時性 | L3: 人數 | M3: 產能/時 | N3: 人時性 | O3: 人數 | P3: 人時性 | Q3: 達成率 | R3: 達成率 平均 | S3: 生產時間 | U3: 換線、休息/分 | V3: 稼動時間/分 | W3: 休息時間 | Y3: (屏榮回填) | AA3: 產能/時 | AB3: 達成率 | AC3: 達成率平均
S4: 開始 | T4: 結束 | W4: 開始 | X4: 結束
A5: 自動包裝機 | B5: 18℃-壽司手卷 | C5: 一配日式鮪魚美乃滋脆卷 | E5: 17.87 | F5: 1279 | G5: =E5*F5 -> 22855.73 | I5: 6 | J5: 2500 | K5: =J5/I5 -> 416.66667 | L5: 6 | M5: =F5/V5*60 -> 2258.1658 | N5: =M5/L5 -> 376.36096 | O5: =L5-I5 -> 0 | P5: =N5-K5 -> -40.305705 | Q5: =N5/K5 -> 0.90326631 | R5: =Q21 -> 0.88235592 | S5: 0.25001157 | T5: 0.27361111 | V5: 33.983333 | AA5: =M5-J5 -> -241.83423 | AB5: =M5/J5 -> 0.90326631 | AC5: =AB21 -> 0.88235592
B6: 18℃-壽司手卷 | C6: 一配銀鮭美乃滋脆卷 | E6: 19.7 | F6: 2931 | G6: =E6*F6 -> 57740.7 | I6: 6 | J6: 2500 | K6: =J6/I6 -> 416.66667 | L6: 6 | M6: =F6/V6*60 -> 2257.5096 | N6: =M6/L6 -> 376.2516 | O6: =L6-I6 -> 0 | P6: =N6-K6 -> -40.415062 | Q6: =N6/K6 -> 0.90300385 | S6: 0.27715278 | T6: 0.33125 | U6: 5.1 | V6: 77.9 | AA6: =M6-J6 -> -242.49037 | AB6: =M6/J6 -> 0.90300385
B7: 18℃-壽司手卷 | C7: 一配海饌雙手卷 | E7: 29.85 | F7: 2182 | G7: =E7*F7 -> 65132.7 | I7: 12 | J7: 3600 | K7: =J7/I7 -> 300 | L7: 12 | M7: =F7/V7*60 -> 3147.1154 | N7: =M7/L7 -> 262.25962 | O7: =L7-I7 -> 0 | P7: =N7-K7 -> -37.740385 | Q7: =N7/K7 -> 0.87419872 | S7: 0.33569444 | T7: 0.36458333 | U7: 6.4 | V7: 41.6 | AA7: =M7-J7 -> -452.88462 | AB7: =M7/J7 -> 0.87419872
B8: 18℃-壽司手卷 | C8: 一配雙饗雙手卷 | E8: 29.52 | F8: 1942 | G8: =E8*F8 -> 57327.84 | I8: 12 | J8: 3600 | K8: =J8/I8 -> 300 | L8: 12 | M8: =F8/V8*60 -> 3147.7713 | N8: =M8/L8 -> 262.31427 | O8: =L8-I8 -> 0 | P8: =N8-K8 -> -37.685727 | Q8: =N8/K8 -> 0.87438091 | S8: 0.36805556 | T8: 0.39376157 | U8: 5 | V8: 37.016667 | AA8: =M8-J8 -> -452.22873 | AB8: =M8/J8 -> 0.87438091
B9: 18℃-壽司手卷 | C9: 一配長野稻荷壽司 | E9: 25.64 | F9: 1532 | G9: =E9*F9 -> 39280.48 | I9: 11 | J9: 3600 | K9: =J9/I9 -> 327.27273 | L9: 11 | M9: =F9/V9*60 -> 3180.6228 | N9: =M9/L9 -> 289.14753 | O9: =L9-I9 -> 0 | P9: =N9-K9 -> -38.125197 | Q9: =N9/K9 -> 0.88350634 | S9: 0.39729167 | T9: 0.41736111 | U9: 5.0833333 | V9: 28.9 | AA9: =M9-J9 -> -419.37716 | AB9: =M9/J9 -> 0.88350634
B10: 18℃-飯糰 | C10: 一配兩粒飯糰(鮪魚.焦糖鮭魚) | E10: 28.57 | F10: 2014 | G10: =E10*F10 -> 57539.98 | I10: 12 | J10: 3600 | K10: =J10/I10 -> 300 | L10: 12 | M10: =F10/V10*60 -> 3126.5201 | N10: =M10/L10 -> 260.54334 | O10: =L10-I10 -> 0 | P10: =N10-K10 -> -39.456662 | Q10: =N10/K10 -> 0.86847779 | S10: 0.42107639 | T10: 0.44791667 | U10: 5.35 | V10: 38.65 | AA10: =M10-J10 -> -473.47995 | AB10: =M10/J10 -> 0.86847779
B21: 平均 | I21: =AVERAGE(I5:I20) -> 9.8333333 | J21: =AVERAGE(J5:J20) -> 3233.3333 | K21: =J21/I21 -> 328.81356 | L21: =AVERAGE(L5:L20) -> 9.8333333 | M21: =AVERAGE(M5:M20) -> 2852.9508 | N21: =M21/L21 -> 290.13059 | O21: =L21-I21 -> 0 | P21: =N21-K21 -> -38.682967 | Q21: =N21/K21 -> 0.88235592 | S21: =S5 -> 0.25001157 | T21: =INDEX(T5:T20,COUNTA(T5:T20)) -> 0.44791667 | AA21: =M21-J21 -> -380.38251 | AB21: =M21/J21 -> 0.88235592
A22: 自動包裝機2 | B22: 18℃-壽司手卷 | C22: 一配雙鬆細卷 | E22: 14.03 | F22: 920 | G22: =E22*F22 -> 12907.6 | I22: 6 | J22: 2600 | K22: =J22/I22 -> 433.33333 | L22: 6 | M22: =F22/V22*60 -> 2340.636 | N22: =M22/L22 -> 390.10601 | O22: =L22-I22 -> 0 | P22: =N22-K22 -> -43.227326 | Q22: =N22/K22 -> 0.90024463 | R22: =Q38 -> 0.90012232 | S22: 0.29195602 | T22: 0.30833333 | V22: 23.583333 | AA22: =M22-J22 -> -259.36396 | AB22: =M22/J22 -> 0.90024463 | AC22: =AB38 -> 0.90012232
B23: 18℃-壽司手卷 | C23: 一配經典鮪魚沙拉細卷 | E23: 14.49 | F23: 1105 | G23: =E23*F23 -> 16011.45 | I23: 6 | J23: 2600 | K23: =J23/I23 -> 433.33333 | L23: 6 | M23: =F23/V23*60 -> 2340 | N23: =M23/L23 -> 390 | O23: =L23-I23 -> 0 | P23: =N23-K23 -> -43.333333 | Q23: =N23/K23 -> 0.9 | S23: 0.31180556 | T23: 0.33148148 | U23: 5 | V23: 28.333333 | AA23: =M23-J23 -> -260 | AB23: =M23/J23 -> 0.9
B38: 平均 | I38: =AVERAGE(I22:I37) -> 6 | J38: =AVERAGE(J22:J37) -> 2600 | K38: =J38/I38 -> 433.33333 | L38: =AVERAGE(L22:L37) -> 6 | M38: =AVERAGE(M22:M37) -> 2340.318 | N38: =M38/L38 -> 390.053 | O38: =L38-I38 -> 0 | P38: =N38-K38 -> -43.28033 | Q38: =N38/K38 -> 0.90012232 | S38: =S22 -> 0.29195602 | T38: =INDEX(T22:T37,COUNTA(T22:T37)) -> 0.33148148 | AA38: =M38-J38 -> -259.68198 | AB38: =M38/J38 -> 0.90012232
A39: (新) 3300型飯糰機 | B39: 18℃-飯糰 | C39: 一配鮭魚奶油醬油飯糰 | E39: 18.53 | F39: 3746 | G39: =E39*F39 -> 69413.38 | I39: 3 | J39: 3300 | K39: =J39/I39 -> 1100 | L39: 3 | M39: =F39/V39*60 -> 2971.0509 | N39: =M39/L39 -> 990.3503 | O39: =L39-I39 -> 0 | P39: =N39-K39 -> -109.6497 | Q39: =N39/K39 -> 0.90031845 | R39: =Q55 -> 0.90031845 | S39: 0.35440972 | T39: 0.40694444 | V39: 75.65 | AA39: =M39-J39 -> -328.94911 | AB39: =M39/J39 -> 0.90031845 | AC39: =AB55 -> 0.90031845
B55: 平均 | I55: =AVERAGE(I39:I54) -> 3 | J55: =AVERAGE(J39:J54) -> 3300 | K55: =J55/I55 -> 1100 | L55: =AVERAGE(L39:L54) -> 3 | M55: =AVERAGE(M39:M54) -> 2971.0509 | N55: =M55/L55 -> 990.3503 | O55: =L55-I55 -> 0 | P55: =N55-K55 -> -109.6497 | Q55: =N55/K55 -> 0.90031845 | S55: =S39 -> 0.35440972 | T55: =INDEX(T39:T54,COUNTA(T39:T54)) -> 0.40694444 | AA55: =M55-J55 -> -328.94911 | AB55: =M55/J55 -> 0.90031845
A56: GKK3600型 飯糰機 | B56: 18℃-飯糰 | C56: 一配蔬食鮪魚飯糰 | E56: 18.18 | F56: 1270 | G56: =E56*F56 -> 23088.6 | I56: 3 | J56: 3600 | K56: =J56/I56 -> 1200 | L56: 3 | M56: =F56/V56*60 -> 3177.2064 | N56: =M56/L56 -> 1059.0688 | O56: =L56-I56 -> 0 | P56: =N56-K56 -> -140.9312 | Q56: =N56/K56 -> 0.88255733 | R56: =Q72 -> 0.88617211 | S56: 0.25001157 | T56: 0.26666667 | V56: 23.983333 | AA56: =M56-J56 -> -422.79361 | AB56: =M56/J56 -> 0.88255733 | AC56: =AB72 -> 0.88617211
B57: 18℃-飯糰 | C57: 一配明太子龍蝦風味沙拉飯糰 | E57: 18.18 | F57: 2548 | G57: =E57*F57 -> 46322.64 | I57: 3 | J57: 3600 | K57: =J57/I57 -> 1200 | L57: 3 | M57: =F57/V57*60 -> 3175.0779 | N57: =M57/L57 -> 1058.3593 | O57: =L57-I57 -> 0 | P57: =N57-K57 -> -141.64071 | Q57: =N57/K57 -> 0.88196608 | S57: 0.27708333 | T57: 0.31052083 | U57: 15 | V57: 48.15 | AA57: =M57-J57 -> -424.92212 | AB57: =M57/J57 -> 0.88196608
B58: 18℃-飯糰 | C58: 一配壹號醬炙烤牛飯糰 | E58: 22.28 | F58: 1254 | G58: =E58*F58 -> 27939.12 | I58: 5 | J58: 3300 | K58: =J58/I58 -> 660 | L58: 5 | M58: =F58/V58*60 -> 2946.7363 | N58: =M58/L58 -> 589.34726 | O58: =L58-I58 -> 0 | P58: =N58-K58 -> -70.652742 | Q58: =N58/K58 -> 0.89295039 | S58: 0.32115741 | T58: 0.33888889 | U58: 15.316667 | V58: 25.533333 | AA58: =M58-J58 -> -353.26371 | AB58: =M58/J58 -> 0.89295039
B59: 18℃-飯糰 | C59: 一配經典肉鬆飯糰 | E59: 14.03 | F59: 5059 | G59: =E59*F59 -> 70977.77 | I59: 3 | J59: 3000 | K59: =J59/I59 -> 1000 | L59: 3 | M59: =F59/V59*60 -> 2698.933 | N59: =M59/L59 -> 899.64434 | O59: =L59-I59 -> 0 | P59: =N59-K59 -> -100.35566 | Q59: =N59/K59 -> 0.89964434 | S59: 0.34930556 | T59: 0.42740741 | U59: 15 | V59: 112.46667 | AA59: =M59-J59 -> -301.06698 | AB59: =M59/J59 -> 0.89964434
B60: 18℃-飯糰 | C60: 一配鮪魚飯糰 | E60: 14.28 | F60: 2318 | G60: =E60*F60 -> 33101.04 | H60: 2 | I60: 3 | J60: 3600 | K60: =J60/I60 -> 1200 | L60: 3 | M60: =F60/V60*60 -> 3172.9278 | N60: =M60/L60 -> 1057.6426 | O60: =L60-I60 -> 0 | P60: =N60-K60 -> -142.35741 | Q60: =N60/K60 -> 0.88136882 | S60: 0.43761574 | T60: 0.46805556 | U60: 14.7 | V60: 43.833333 | W60: 0.46805556 | X60: 0.54166667 | AA60: =M60-J60 -> -427.07224 | AB60: =M60/J60 -> 0.88136882
B61: 18℃-飯糰 | C61: 一配鮪魚飯糰 | E61: 14.28 | F61: 5044 | G61: =E61*F61 -> 72028.32 | I61: 3 | J61: 3600 | K61: =J61/I61 -> 1200 | L61: 3 | M61: =F61/V61*60 -> 3172.8814 | N61: =M61/L61 -> 1057.6271 | O61: =L61-I61 -> 0 | P61: =N61-K61 -> -142.37288 | Q61: =N61/K61 -> 0.88135593 | S61: 0.54166667 | T61: 0.60790509 | V61: 95.383333 | AA61: =M61-J61 -> -427.11864 | AB61: =M61/J61 -> 0.88135593
B72: 平均 | I72: =AVERAGE(I56:I71) -> 3.3333333 | J72: =AVERAGE(J56:J71) -> 3450 | K72: =J72/I72 -> 1035 | L72: =AVERAGE(L56:L71) -> 3.3333333 | M72: =AVERAGE(M56:M71) -> 3057.2938 | N72: =M72/L72 -> 917.18813 | O72: =L72-I72 -> 0 | P72: =N72-K72 -> -117.81187 | Q72: =N72/K72 -> 0.88617211 | S72: =S56 -> 0.25001157 | T72: =INDEX(T56:T71,COUNTA(T56:T71)) -> 0.60790509 | AA72: =M72-J72 -> -392.70622 | AB72: =M72/J72 -> 0.88617211
A73: GKK3600型 飯糰機2 | B73: 18℃-飯糰 | C73: 一配熟成紅鮭飯糰 | E73: 25.03 | F73: 1687 | G73: =E73*F73 -> 42225.61 | I73: 4 | J73: 3300 | K73: =J73/I73 -> 825 | L73: 4 | M73: =F73/V73*60 -> 2941.0169 | N73: =M73/L73 -> 735.25424 | O73: =L73-I73 -> 0 | P73: =N73-K73 -> -89.745763 | Q73: =N73/K73 -> 0.89121726 | R73: =Q89 -> 0.88732088 | S73: 0.25 | T73: 0.27390046 | V73: 34.416667 | AA73: =M73-J73 -> -358.98305 | AB73: =M73/J73 -> 0.89121726 | AC73: =AB89 -> 0.88732088
B74: 18℃-飯糰 | C74: 一配北海道秋鮭親子飯糰 | E74: 24.82 | F74: 2047 | G74: =E74*F74 -> 50806.54 | I74: 4 | J74: 3300 | K74: =J74/I74 -> 825 | L74: 4 | M74: =F74/V74*60 -> 2940.6225 | N74: =M74/L74 -> 735.15563 | O74: =L74-I74 -> 0 | P74: =N74-K74 -> -89.844374 | Q74: =N74/K74 -> 0.89109773 | S74: 0.28418981 | T74: 0.31319444 | U74: 14.816667 | V74: 41.766667 | AA74: =M74-J74 -> -359.37749 | AB74: =M74/J74 -> 0.89109773
B75: 18℃-飯糰 | C75: 一配鹽蔥燒肉飯糰 | E75: 17.89 | F75: 3526 | G75: =E75*F75 -> 63080.14 | I75: 4 | J75: 3600 | K75: =J75/I75 -> 900 | L75: 4 | M75: =F75/V75*60 -> 3172.6068 | N75: =M75/L75 -> 793.15171 | O75: =L75-I75 -> 0 | P75: =N75-K75 -> -106.84829 | Q75: =N75/K75 -> 0.88127968 | S75: 0.32383102 | T75: 0.37013889 | U75: 15.316667 | V75: 66.683333 | AA75: =M75-J75 -> -427.39315 | AB75: =M75/J75 -> 0.88127968
B76: 18℃-飯糰 | C76: 一配贅沢鮭魚肚飯糰 | E76: 30 | F76: 3470 | G76: =E76*F76 -> 104100 | I76: 3 | J76: 3000 | K76: =J76/I76 -> 1000 | L76: 3 | M76: =F76/V76*60 -> 2700.3891 | N76: =M76/L76 -> 900.1297 | O76: =L76-I76 -> 0 | P76: =N76-K76 -> -99.870298 | Q76: =N76/K76 -> 0.9001297 | S76: 0.38125 | T76: 0.43479167 | U76: 16 | V76: 77.1 | AA76: =M76-J76 -> -299.61089 | AB76: =M76/J76 -> 0.9001297
B77: 18℃-飯糰 | C77: 一配雞肉飯飯糰 | E77: 16.66 | F77: 1955 | G77: =E77*F77 -> 32570.3 | H77: 2 | I77: 5 | J77: 3600 | K77: =J77/I77 -> 720 | L77: 5 | M77: =F77/V77*60 -> 3173.1289 | N77: =M77/L77 -> 634.62579 | O77: =L77-I77 -> 0 | P77: =N77-K77 -> -85.374211 | Q77: =N77/K77 -> 0.88142471 | S77: 0.44516204 | T77: 0.47083333 | U77: 14.933333 | V77: 36.966667 | W77: 0.47083333 | X77: 0.54168981 | AA77: =M77-J77 -> -426.87106 | AB77: =M77/J77 -> 0.88142471
B78: 18℃-飯糰 | C78: 一配雞肉飯飯糰 | E78: 16.66 | F78: 4071 | G78: =E78*F78 -> 67822.86 | I78: 5 | J78: 3600 | K78: =J78/I78 -> 720 | L78: 5 | M78: =F78/V78*60 -> 3173.5816 | N78: =M78/L78 -> 634.71633 | O78: =L78-I78 -> 0 | P78: =N78-K78 -> -85.283673 | Q78: =N78/K78 -> 0.88155045 | S78: 0.54168981 | T78: 0.59513889 | V78: 76.966667 | AA78: =M78-J78 -> -426.41836 | AB78: =M78/J78 -> 0.88155045
B89: 平均 | I89: =AVERAGE(I73:I88) -> 4.1666667 | J89: =AVERAGE(J73:J88) -> 3400 | K89: =J89/I89 -> 816 | L89: =AVERAGE(L73:L88) -> 4.1666667 | M89: =AVERAGE(M73:M88) -> 3016.891 | N89: =M89/L89 -> 724.05384 | O89: =L89-I89 -> 0 | P89: =N89-K89 -> -91.94616 | Q89: =N89/K89 -> 0.88732088 | S89: =S73 -> 0.25 | T89: =INDEX(T73:T88,COUNTA(T73:T88)) -> 0.59513889 | AA89: =M89-J89 -> -383.109 | AB89: =M89/J89 -> 0.88732088
A90: 自動包裝機 (二配) | B90: 18℃-壽司手卷 | C90: 二配長野稻荷壽司 | E90: 25.64 | F90: 1486 | G90: =E90*F90 -> 38101.04 | I90: 11 | J90: 3600 | K90: =J90/I90 -> 327.27273 | L90: 11 | M90: =F90/V90*60 -> 3182.3914 | N90: =M90/L90 -> 289.30831 | O90: =L90-I90 -> 0 | P90: =N90-K90 -> -37.964415 | Q90: =N90/K90 -> 0.88399762 | R90: =Q106 -> 0.87062854 | S90: 0.70833333 | T90: 0.72778935 | V90: 28.016667 | AA90: =M90-J90 -> -417.60857 | AB90: =M90/J90 -> 0.88399762 | AC90: =AB106 -> 0.87062854
B91: 18℃-壽司手卷 | C91: 二配雙饗雙手卷 | E91: 29.52 | F91: 1909 | G91: =E91*F91 -> 56353.68 | I91: 12 | J91: 3600 | K91: =J91/I91 -> 300 | L91: 12 | M91: =F91/V91*60 -> 3146.7033 | N91: =M91/L91 -> 262.22527 | O91: =L91-I91 -> 0 | P91: =N91-K91 -> -37.774725 | Q91: =N91/K91 -> 0.87408425 | S91: 0.73125 | T91: 0.75652778 | U91: 4.9833333 | V91: 36.4 | AA91: =M91-J91 -> -453.2967 | AB91: =M91/J91 -> 0.87408425
B92: 18℃-壽司手卷 | C92: 二配海饌雙手卷 | E92: 29.85 | F92: 2006 | G92: =E92*F92 -> 59879.1 | I92: 12 | J92: 3600 | K92: =J92/I92 -> 300 | L92: 12 | M92: =F92/V92*60 -> 3145.2962 | N92: =M92/L92 -> 262.10801 | O92: =L92-I92 -> 0 | P92: =N92-K92 -> -37.891986 | Q92: =N92/K92 -> 0.87369338 | S92: 0.75972222 | T92: 0.7862963 | U92: 4.6 | V92: 38.266667 | AA92: =M92-J92 -> -454.70383 | AB92: =M92/J92 -> 0.87369338
B93: 18℃-飯糰 | C93: 二配兩粒飯糰(鮪魚.焦糖鮭魚) | E93: 28.57 | F93: 1479 | G93: =E93*F93 -> 42255.03 | I93: 12 | J93: 3600 | K93: =J93/I93 -> 300 | L93: 12 | M93: =F93/V93*60 -> 3124.6479 | N93: =M93/L93 -> 260.38732 | O93: =L93-I93 -> 0 | P93: =N93-K93 -> -39.612676 | Q93: =N93/K93 -> 0.86795775 | S93: 0.78958333 | T93: 0.80930556 | U93: 4.7333333 | V93: 28.4 | AA93: =M93-J93 -> -475.35211 | AB93: =M93/J93 -> 0.86795775
B94: 18℃-飯糰 | C94: 二配鮮蝦旬彩炊飯飯糰 | E94: 20.17 | F94: 1257 | G94: =E94*F94 -> 25353.69 | I94: 12 | J94: 3600 | K94: =J94/I94 -> 300 | L94: 12 | M94: =F94/V94*60 -> 3250.8621 | N94: =M94/L94 -> 270.90517 | O94: =L94-I94 -> 0 | P94: =N94-K94 -> -29.094828 | Q94: =N94/K94 -> 0.90301724 | S94: 0.8125 | T94: 0.82861111 | U94: 4.6 | V94: 23.2 | AA94: =M94-J94 -> -349.13793 | AB94: =M94/J94 -> 0.90301724
B95: 18℃-飯糰 | C95: 二配溏心蛋五目飯糰 | E95: 20.42 | F95: 5468 | G95: =E95*F95 -> 111656.56 | I95: 13 | J95: 3600 | K95: =J95/I95 -> 276.92308 | L95: 13 | M95: =F95/V95*60 -> 2955.6757 | N95: =M95/L95 -> 227.35967 | O95: =L95-I95 -> 0 | P95: =N95-K95 -> -49.56341 | Q95: =N95/K95 -> 0.82102102 | S95: 0.83194444 | T95: 0.90902778 | U95: 4.8 | V95: 111 | AA95: =M95-J95 -> -644.32432 | AB95: =M95/J95 -> 0.82102102
B106: 平均 | I106: =AVERAGE(I90:I105) -> 12 | J106: =AVERAGE(J90:J105) -> 3600 | K106: =J106/I106 -> 300 | L106: =AVERAGE(L90:L105) -> 12 | M106: =AVERAGE(M90:M105) -> 3134.2628 | N106: =M106/L106 -> 261.18856 | O106: =L106-I106 -> 0 | P106: =N106-K106 -> -38.811437 | Q106: =N106/K106 -> 0.87062854 | S106: =S90 -> 0.70833333 | T106: =INDEX(T90:T105,COUNTA(T90:T105)) -> 0.90902778 | AA106: =M106-J106 -> -465.73725 | AB106: =M106/J106 -> 0.87062854
A107: (新) 3300型飯糰機 (二配) | B107: 18℃-飯糰 | C107: 二配油蔥G絲飯糰 | E107: 18.18 | F107: 788 | G107: =E107*F107 -> 14325.84 | I107: 4 | J107: 3300 | K107: =J107/I107 -> 825 | L107: 4 | M107: =F107/V107*60 -> 2970.4712 | N107: =M107/L107 -> 742.6178 | O107: =L107-I107 -> 0 | P107: =N107-K107 -> -82.382199 | Q107: =N107/K107 -> 0.90014279 | R107: =Q123 -> 0.89586621 | S107: 0.7083912 | T107: 0.71944444 | V107: 15.916667 | AA107: =M107-J107 -> -329.5288 | AB107: =M107/J107 -> 0.90014279 | AC107: =AB123 -> 0.89586621
B108: 18℃-飯糰 | C108: 二配大飯糰鮪魚昆布 | E108: 22.21 | F108: 2077 | G108: =E108*F108 -> 46130.17 | I108: 4 | J108: 3000 | K108: =J108/I108 -> 750 | L108: 4 | M108: =F108/V108*60 -> 2682.8848 | N108: =M108/L108 -> 670.72121 | O108: =L108-I108 -> 0 | P108: =N108-K108 -> -79.278794 | Q108: =N108/K108 -> 0.89429494 | S108: 0.72291667 | T108: 0.75517361 | U108: 5 | V108: 46.45 | AA108: =M108-J108 -> -317.11518 | AB108: =M108/J108 -> 0.89429494
B109: 18℃-飯糰 | C109: 二配大飯糰滷肉飯加蛋 | E109: 22.48 | F109: 1197 | G109: =E109*F109 -> 26908.56 | I109: 5 | J109: 3000 | K109: =J109/I109 -> 600 | L109: 5 | M109: =F109/V109*60 -> 2683.188 | N109: =M109/L109 -> 536.63761 | O109: =L109-I109 -> 0 | P109: =N109-K109 -> -63.362391 | Q109: =N109/K109 -> 0.89439601 | S109: 0.75918981 | T109: 0.77777778 | U109: 5.7833333 | V109: 26.766667 | AA109: =M109-J109 -> -316.81196 | AB109: =M109/J109 -> 0.89439601
...

Sheet 0330(4度C)
A1: 大溪廠日報分析 | C1: 總生產量 | D1: =SUM(F5:F123) -> 53768 | E1: 營業額 | F1: =SUM(G5:G123) -> 2747355.8 | G1: 出勤人數 | H1: =L21+L38+L55+L72+L89+L106+L123 -> 139.25 | I1: 產線配置圖 | L1: 生產實績 | O1: 人時性差異分析 | S1: 日報登錄 | Y1: 合計次數 | Z1: 合計(時間/分) | AA1: 產線異常 分析說明(5分鐘以上) | AC1: 合計次數 | AD1: 合計(時間/分) | AE1: 產能差異分析
A2: 46111 | C2: 人時性 | D2: =AVERAGE(N21,N38,N55,N72,N89,N106,N123) -> 117.63408 | E2: 平均廠價 | F2: =F1/D1 -> 51.096485 | G2: 多次生產數 | H2: =COUNT(H5:H123) -> 0 | Y2: =SUM(Y21,Y38,Y55,Y72,Y89,Y106,Y123) -> 0 | Z2: =SUM(Z21,Z38,Z55,Z72,Z89,Z106,Z123) -> 0 | AC2: =SUM(AC21,AC38,AC55,AC72,AC89,AC106,AC123) -> 0 | AD2: =SUM(AD21,AD38,AD55,AD72,AD89,AD106,AD123) -> 0
A3: 線別 | B3: 品類 | C3: 品名 | E3: 廠價 | F3: 生產量 | G3: 營收 | H3: 多次 生產 | I3: 人數 | J3: 產能/時 | K3: 人時性 | L3: 人數 | M3: 產能/時 | N3: 人時性 | O3: 人數 | P3: 人時性 | Q3: 達成率 | R3: 達成率 平均 | S3: 生產時間 | U3: 換線、休息/分 | V3: 稼動時間/分 | W3: 休息時間 | Y3: 產線異常統計(5分鐘以上) | AA3: (屏榮回填) | AC3: 短暫停線統計(5分鐘以下) | AE3: 產能/時 | AF3: 達成率 | AG3: 達成率平均
S4: 開始 | T4: 結束 | W4: 開始 | X4: 結束 | Y4: 次數 | Z4: 時間/分 | AC4: 總次數 | AD4: 設備因素(次數)
A5: 便當二線 | B5: 微波主食 | C5: 糖燻野郎三十天熟成牛飯 | E5: 56.77 | F5: 3955 | G5: =E5*F5 -> 224525.35 | I5: 24 | J5: 2000 | K5: =J5/I5 -> 83.333333 | L5: 24 | M5: =F5/V5*60 -> 1785.3292 | N5: =M5/L5 -> 74.388715 | O5: =L5-I5 -> 0 | P5: =N5-K5 -> -8.9446186 | Q5: =N5/K5 -> 0.89266458 | R5: =Q21 -> 0.89322876 | S5: 0.25005787 | T5: 0.34236111 | V5: 132.91667 | AE5: =M5-J5 -> -214.67085 | AF5: =M5/J5 -> 0.89266458 | AG5: =AF21 -> 0.89322876
B6: 便當 | C6: 健身G肉餐盒 | E6: 59.52 | F6: 5118 | G6: =E6*F6 -> 304623.36 | I6: 24 | J6: 2000 | K6: =J6/I6 -> 83.333333 | L6: 24 | M6: =F6/V6*60 -> 1786.0411 | N6: =M6/L6 -> 74.418379 | O6: =L6-I6 -> 0 | P6: =N6-K6 -> -8.9149541 | Q6: =N6/K6 -> 0.89302055 | S6: 0.34587963 | T6: 0.46527778 | U6: 5.0666667 | V6: 171.93333 | W6: 0.46527778 | X6: 0.50450231 | AE6: =M6-J6 -> -213.9589 | AF6: =M6/J6 -> 0.89302055
B7: 便當 | C7: 嫩烤香料雞胸排蔬滿盒 | E7: 77.34 | F7: 2608 | G7: =E7*F7 -> 201702.72 | I7: 23 | J7: 2000 | K7: =J7/I7 -> 86.956522 | L7: 23 | M7: =F7/V7*60 -> 1788.0023 | N7: =M7/L7 -> 77.73923 | O7: =L7-I7 -> 0 | P7: =N7-K7 -> -9.2172919 | Q7: =N7/K7 -> 0.89400114 | S7: 0.50450231 | T7: 0.56527778 | U7: 56.483333 | V7: 87.516667 | AE7: =M7-J7 -> -211.99771 | AF7: =M7/J7 -> 0.89400114
