Workbook

Sheet 0806
B1: 屏榮 大溪廠組合室生產人時性分析
B3: 日期 | C3: 115.08.06星期四 | E3: 訂單量 | F3: ='0806(18度C)'!D1+'0806(4度C)'!D1 -> 188918 | H3: 營業額 | I3: ='0806(18度C)'!F1+'0806(4度C)'!F1 -> 5817645.9
B4: 人時性 | C4: 項目 | E4: ➀ | G4: ➁ | I4: ➂ | K4: ④ | M4: ⑤ | O4: 異常停線 | Q4: 短暫停線
C5: 組合室 | E5: 全溫層 | G5: 4度C-各編組展開(一配) | I5: 4度C-各編組展開(二配) | K5: 18度C-各編組展開(一配) | M5: 18度C-各編組展開(二配) | O5: 合計次數 | P5: 時間 | Q5: 合計次數 | R5: 設備次數
C6: 排關平均 | E6: =AVERAGE(D14:O14,D32:X32) -> 494.89434 | F6: =AVERAGE(#REF!,D14:K14) -> #REF! | G6: =AVERAGE(D14:K14) -> 271.35686 | I6: =AVERAGE(L14:O14) -> 94.325718 | K6: =AVERAGE(D32:O32) -> 737.95063 | M6: =AVERAGE(P32:X32) -> 787.42857 | O6: ='0806(4度C)'!Y2 -> 0 | P6: ='0806(4度C)'!Z2 -> 0 | Q6: ='0806(4度C)'!AC2 -> 0 | R6: ='0806(4度C)'!AD2 -> 0
C7: 實績平均 | E7: =AVERAGE(D15:O15,D33:X33) -> 444.39754 | F7: =AVERAGE(#REF!,D15:K15) -> #REF! | G7: =AVERAGE(D15:K15) -> 239.95088 | I7: =AVERAGE(L15:O15) -> 87.472802 | K7: =AVERAGE(D33:O33) -> 664.11577 | M7: =AVERAGE(P33:X33) -> 709.81168
C8: 達成率平均 | E8: =AVERAGE(D16:O16,D34:X34) -> 0.89993664 | F8: =AVERAGE(D16:K16,#REF!) -> #REF! | G8: =AVERAGE(D16:K16) -> 0.89289181 | I8: =AVERAGE(L16:O16) -> 0.92546698 | K8: =AVERAGE(D34:O34) -> 0.89674145 | M8: =AVERAGE(P34:X34) -> 0.90093391
O9: ※現行日本鮮食廠以達成率80%為基本(即為現行KPI)
B11: 溫層 | D11: ➁4度C-各編組展開 | L11: ➂4度C-各編組展開
B12: 編組 | D12: 1 | E12: 2 | F12: 3 | G12: 4 | H12: 5 | I12: 6 | J12: 7 | K12: 8 | L12: 1 | M12: 2 | N12: 3 | O12: 4
D13: 便當一線 | E13: 便當二線 | F13: 涼麵一線 | G13: 涼麵二線 | H13: 涼麵三線 | I13: 自動包裝機 | J13: 自動包裝機2 | K13: 自動包裝機3 | L13: 便當一線 | M13: 便當二線 | N13: 涼麵一線 | O13: 涼麵二線
B14: 人時性 | C14: 排關 | D14: - | E14: 83.72093 | F14: 117.52 | G14: 90.909091 | H14: 170.61611 | I14: 565.375 | J14: 600 | K14: - | L14: - | M14: 101.69492 | N14: 86.956522 | O14: -
C15: 實績 | D15: - | E15: 75.481559 | F15: 106.08884 | G15: 81.904163 | H15: 153.19727 | I15: 481.30953 | J15: 541.72395 | K15: - | L15: - | M15: 96.564286 | N15: 78.381318 | O15: -
C16: 達成率 | D16: - | E16: =E15/E14 -> 0.90158529 | F16: =F15/F14 -> 0.90273007 | G16: =G15/G14 -> 0.9009458 | H16: =H15/H14 -> 0.8979062 | I16: =I15/I14 -> 0.85131024 | J16: =J15/J14 -> 0.90287325 | K16: - | L16: - | M16: =M15/M14 -> 0.94954881 | N16: =N15/N14 -> 0.90138516 | O16: -
B17: 作業 時間 | C17: 開始 | D17: - | E17: 0.20833333 | F17: 0.16666667 | G17: 0.16666667 | H17: 0.16666667 | I17: 0.20833333 | J17: 0.25 | K17: - | L17: - | M17: 0.70833333 | N17: 0.70833333 | O17: -
C18: 結束 | D18: - | E18: 0.59616898 | F18: 0.52952546 | G18: 0.57861111 | H18: 0.62271991 | I18: 0.44814815 | J18: 0.31082176 | K18: - | L18: - | M18: 0.79366898 | N18: 0.81310185 | O18: -
B19: 產線異常 (5分鐘以上) | C19: 次數
C20: 時間/分
B21: 短暫停線 (5分鐘以下) | C21: 次數
C22: 設備次數
B23: 配置人數 | D23: - | E23: 21.5 | F23: 18 | G23: 22 | H23: 21.1 | I23: 5.6666667 | J23: 6 | K23: - | L23: - | M23: 18.666667 | N23: 23 | O23: -
B24: 主要應用設備 | D24: L型封口機 | E24: ET-55 | F24: ET-55 | G24: ET-55 | H24: ET-600 | I24: 伺服包裝機 | J24: 伺服包裝機 | K24: 伺服包裝機 | L24: L型封口機 | M24: ET-55 | N24: ET-55 | O24: ET-55
B25: 次要應用設備 | D25: 伺服包裝機 | H25: 伺服包裝機
B26: 備註 | H26: 涼麵+烤飯糰 | I26: 大口飯糰線 | K26: 烤飯糰+手卷
B29: 溫層 | D29: ➃18度C-各編組展開 (一配) | P29: ⑤18度C-各編組展開 (二配)
B30: 編組 | D30: 1 | E30: 2 | F30: 3 | G30: 4 | H30: 5 | I30: 6 | J30: 7 | K30: 8 | L30: 9 | M30: 10 | N30: 11 | O30: 12 | P30: 1 | Q30: 2 | R30: 3 | S30: 4 | T30: 5 | U30: 6 | V30: 7 | W30: 8 | X30: 9
D31: 便當一線 | E31: 涼麵一線 | F31: 涼麵三線 | G31: 自動包裝機 | H31: 自動包裝機2 | I31: 自動包裝機3 | J31: 味付飯糰線B | K31: (舊) 3300型飯糰線 | L31: 3000型飯糰線 | M31: (新) 3300型飯糰機 | N31: GKK3600型 飯糰機 | O31: GKK3600型 飯糰機2 | P31: 自動包裝機 | Q31: 自動包裝機2 | R31: 自動包裝機3 | S31: 味付飯糰線B | T31: (舊) 3300型飯糰線 | U31: 3000型飯糰線 | V31: (新) 3300型飯糰機 | W31: GKK3600型 飯糰機 | X31: GKK3600型 飯糰機2
B32: 人時性 | C32: 排關 | D32: - | E32: - | F32: - | G32: 327.27273 | H32: - | I32: - | J32: - | K32: - | L32: - | M32: 825 | N32: 940.90909 | O32: 858.62069 | P32: 490.90909 | Q32: - | R32: - | S32: - | T32: - | U32: - | V32: 709.09091 | W32: 1085.7143 | X32: 864
C33: 實績 | D33: - | E33: - | F33: - | G33: 287.46361 | H33: - | I33: - | J33: - | K33: - | L33: - | M33: 753.19135 | N33: 846.47637 | O33: 769.33175 | P33: 438.7366 | Q33: - | R33: - | S33: - | T33: - | U33: - | V33: 647.19086 | W33: 981.56182 | X33: 771.75745
C34: 達成率 | D34: - | E34: - | F34: - | G34: =G33/G32 -> 0.87836102 | H34: - | I34: - | J34: - | K34: - | L34: - | M34: =M33/M32 -> 0.91295921 | N34: =N33/N32 -> 0.89963672 | O34: =O33/O32 -> 0.89600886 | P34: =P33/P32 -> 0.8937227 | Q34: - | R34: - | S34: - | T34: - | U34: - | V34: =V33/V32 -> 0.91270506 | W34: =W33/W32 -> 0.90407009 | X34: =X33/X32 -> 0.89323779
B35: 作業 時間 | C35: 開始 | D35: - | E35: - | F35: - | G35: 0.20833333 | H35: - | I35: - | J35: - | K35: - | L35: - | M35: 0.32847222 | N35: 0.25 | O35: 0.25 | P35: 0.70833333 | Q35: - | R35: - | S35: - | T35: - | U35: - | V35: 0.70833333 | W35: 0.73194444 | X35: 0.7375
C36: 結束 | D36: - | E36: - | F36: - | G36: 0.44814815 | H36: - | I36: - | J36: - | K36: - | L36: - | M36: 0.41982639 | N36: 0.52556713 | O36: 0.53013889 | P36: 0.75503472 | Q36: - | R36: - | S36: - | T36: - | U36: - | V36: 0.86011574 | W36: 1.0679282 | X36: 1.0795833
B37: 配置人數 | D37: - | E37: - | F37: - | G37: 11 | H37: - | I37: - | J37: - | K37: - | L37: - | M37: 4 | N37: 3.6666667 | O37: 4.1428571 | P37: 7.3333333 | Q37: - | R37: - | S37: - | T37: - | U37: - | V37: 4.4 | W37: 3 | X37: 4.1666667
B38: 主要應用設備 | D38: 伺服包裝機 | E38: ET-55 | F38: ET-600 | G38: 夾心型 | H38: 伺服包裝機 | I38: 伺服包裝機 | J38: 夾心型 | K38: 3300型 | L38: 3300型 | M38: 3300型 | N38: GKK | O38: GKK | P38: 夾心型 | Q38: 伺服包裝機 | R38: 伺服包裝機 | S38: 夾心型 | T38: 3300型 | U38: 3300型 | V38: 3300型 | W38: GKK | X38: GKK
B39: 次要應用設備
B40: 備註

Sheet 0806(18度C)
A1: 大溪廠日報分析 | C1: 總生產量 | D1: =SUM(F5:F140) -> 101071 | E1: 營業額 | F1: =SUM(G5:G140) -> 2021623 | G1: 出勤人數 | H1: =L21+L38+L55+L72+L89+L106+L123+L140 -> 41.709524 | I1: 產線配置圖 | L1: 生產實績 | O1: 人時性差異分析 | S1: 日報登錄 | Y1: 分析說明 | AA1: 產能差異分析
A2: 46240 | C2: 人時性 | D2: =AVERAGE(N21,N38,N55,N72,N89,N106,N123,N140) -> 686.96372 | E2: 平均廠價 | F2: =F1/D1 -> 20.002008 | G2: 多次生產數 | H2: =COUNT(H5:H140) -> 9
A3: 線別 | B3: 品類 | C3: 品名 | E3: 廠價 | F3: 生產量 | G3: 營收 | H3: 多次 生產 | I3: 人數 | J3: 產能/時 | K3: 人時性 | L3: 人數 | M3: 產能/時 | N3: 人時性 | O3: 人數 | P3: 人時性 | Q3: 達成率 | R3: 達成率 平均 | S3: 生產時間 | U3: 換線、休息/分 | V3: 稼動時間/分 | W3: 休息時間 | Y3: (屏榮回填) | AA3: 產能/時 | AB3: 達成率 | AC3: 達成率平均
S4: 開始 | T4: 結束 | W4: 開始 | X4: 結束
A5: 自動包裝機 | B5: 18℃-壽司手卷 | C5: 一配長野稻荷壽司 | E5: 25.64 | F5: 1843 | G5: =E5*F5 -> 47254.52 | I5: 10 | J5: 3600 | K5: =J5/I5 -> 360 | L5: 10 | M5: =F5/V5*60 -> 3219.0496 | N5: =M5/L5 -> 321.90496 | O5: =L5-I5 -> 0 | P5: =N5-K5 -> -38.095045 | Q5: =N5/K5 -> 0.89418043 | R5: =Q21 -> 0.87836102 | S5: 0.20833333 | T5: 0.2321875 | V5: 34.351755 | AA5: =M5-J5 -> -380.95045 | AB5: =M5/J5 -> 0.89418043 | AC5: =AB21 -> 0.87836102
B6: 18℃-壽司手卷 | C6: 一配經典人氣雙手卷 | E6: 29.52 | F6: 2882 | G6: =E6*F6 -> 85076.64 | I6: 11 | J6: 3600 | K6: =J6/I6 -> 327.27273 | L6: 11 | M6: =F6/V6*60 -> 3157.5433 | N6: =M6/L6 -> 287.04939 | O6: =L6-I6 -> 0 | P6: =N6-K6 -> -40.223333 | Q6: =N6/K6 -> 0.87709537 | S6: 0.23611111 | T6: 0.27413194 | U6: 5.65 | V6: 54.764094 | AA6: =M6-J6 -> -442.45666 | AB6: =M6/J6 -> 0.87709537
B7: 18℃-壽司手卷 | C7: 一配鮭鮪海饌雙手卷 | E7: 29.85 | F7: 3417 | G7: =E7*F7 -> 101997.45 | I7: 11 | J7: 3600 | K7: =J7/I7 -> 327.27273 | L7: 11 | M7: =F7/V7*60 -> 3156.5719 | N7: =M7/L7 -> 286.96108 | O7: =L7-I7 -> 0 | P7: =N7-K7 -> -40.311645 | Q7: =N7/K7 -> 0.87682553 | S7: 0.27777778 | T7: 0.32288194 | U7: 5.25 | V7: 64.950207 | AA7: =M7-J7 -> -443.42809 | AB7: =M7/J7 -> 0.87682553
B8: 18℃-壽司手卷 | C8: 一配青木瓜雞絲泰泰雙手卷 | E8: 30 | F8: 2009 | G8: =E8*F8 -> 60270 | I8: 11 | J8: 3600 | K8: =J8/I8 -> 327.27273 | L8: 11 | M8: =F8/V8*60 -> 3157.3112 | N8: =M8/L8 -> 287.02829 | O8: =L8-I8 -> 0 | P8: =N8-K8 -> -40.244439 | Q8: =N8/K8 -> 0.87703088 | S8: 0.32638889 | T8: 0.35289352 | U8: 5.05 | V8: 38.178055 | AA8: =M8-J8 -> -442.68883 | AB8: =M8/J8 -> 0.87703088
B9: 18℃-飯糰 | C9: 一配兩粒飯糰(鮪魚.焦糖鮭魚) | E9: 28.57 | F9: 1423 | G9: =E9*F9 -> 40655.11 | I9: 12 | J9: 3600 | K9: =J9/I9 -> 300 | L9: 12 | M9: =F9/V9*60 -> 3120.0223 | N9: =M9/L9 -> 260.00186 | O9: =L9-I9 -> 0 | P9: =N9-K9 -> -39.998141 | Q9: =N9/K9 -> 0.86667286 | S9: 0.35625 | T9: 0.37524306 | U9: 4.8333333 | V9: 27.365189 | AA9: =M9-J9 -> -479.97769 | AB9: =M9/J9 -> 0.86667286
B21: 平均 | I21: =AVERAGE(I5:I20) -> 11 | J21: =AVERAGE(J5:J20) -> 3600 | K21: =J21/I21 -> 327.27273 | L21: =AVERAGE(L5:L20) -> 11 | M21: =AVERAGE(M5:M20) -> 3162.0997 | N21: =M21/L21 -> 287.46361 | O21: =L21-I21 -> 0 | P21: =N21-K21 -> -39.809122 | Q21: =N21/K21 -> 0.87836102 | S21: 0.20833333 | T21: 0.44814815 | AA21: =M21-J21 -> -437.90034 | AB21: =M21/J21 -> 0.87836102
A22: (新) 3300型飯糰機 | B22: 18℃-飯糰 | C22: 一配鮭魚奶油醬油飯糰 | E22: 18.53 | F22: 2441 | G22: =E22*F22 -> 45231.73 | I22: 3 | J22: 3300 | K22: =J22/I22 -> 1100 | L22: 3 | M22: =F22/V22*60 -> 3011.1134 | N22: =M22/L22 -> 1003.7045 | O22: =L22-I22 -> 0 | P22: =N22-K22 -> -96.29552 | Q22: =N22/K22 -> 0.91245862 | R22: =Q38 -> 0.91295921 | S22: 0.32847222 | T22: 0.36224537 | V22: 48.639815 | AA22: =M22-J22 -> -288.88656 | AB22: =M22/J22 -> 0.91245862 | AC22: =AB38 -> 0.91295921
B23: 18℃-飯糰 | C23: 一配壹號醬炙烤牛飯糰 | E23: 22.28 | F23: 781 | G23: =E23*F23 -> 17400.68 | I23: 5 | J23: 3300 | K23: =J23/I23 -> 660 | L23: 5 | M23: =F23/V23*60 -> 3014.7198 | N23: =M23/L23 -> 602.94396 | O23: =L23-I23 -> 0 | P23: =N23-K23 -> -57.056039 | Q23: =N23/K23 -> 0.91355146 | S23: 0.36527778 | T23: 0.37606481 | U23: 5 | V23: 15.543733 | AA23: =M23-J23 -> -285.28019 | AB23: =M23/J23 -> 0.91355146
B24: 18℃-飯糰 | C24: 一配鹽蔥燒肉飯糰 | E24: 17.89 | F24: 2940 | G24: =E24*F24 -> 52596.6 | I24: 4 | J24: 3300 | K24: =J24/I24 -> 825 | L24: 4 | M24: =F24/V24*60 -> 3012.463 | N24: =M24/L24 -> 753.11574 | O24: =L24-I24 -> 0 | P24: =N24-K24 -> -71.884261 | Q24: =N24/K24 -> 0.91286756 | S24: 0.37916667 | T24: 0.41982639 | U24: 5 | V24: 58.556737 | AA24: =M24-J24 -> -287.53704 | AB24: =M24/J24 -> 0.91286756
B38: 平均 | I38: =AVERAGE(I22:I37) -> 4 | J38: =AVERAGE(J22:J37) -> 3300 | K38: =J38/I38 -> 825 | L38: =AVERAGE(L22:L37) -> 4 | M38: =AVERAGE(M22:M37) -> 3012.7654 | N38: =M38/L38 -> 753.19135 | O38: =L38-I38 -> 0 | P38: =N38-K38 -> -71.80865 | Q38: =N38/K38 -> 0.91295921 | S38: 0.32847222 | T38: 0.41982639 | AA38: =M38-J38 -> -287.2346 | AB38: =M38/J38 -> 0.91295921
A39: GKK3600型 飯糰機 | B39: 18℃-飯糰 | C39: 一配熟成紅鮭飯糰 | E39: 25.03 | F39: 955 | G39: =E39*F39 -> 23903.65 | I39: 5 | J39: 3600 | K39: =J39/I39 -> 720 | L39: 5 | M39: =F39/V39*60 -> 3217.4296 | N39: =M39/L39 -> 643.48591 | O39: =L39-I39 -> 0 | P39: =N39-K39 -> -76.51409 | Q39: =N39/K39 -> 0.89373043 | R39: =Q55 -> 0.89963672 | S39: 0.25 | T39: 0.26236111 | V39: 17.809248 | AA39: =M39-J39 -> -382.57045 | AB39: =M39/J39 -> 0.89373043 | AC39: =AB55 -> 0.89963672
B40: 18℃-飯糰 | C40: 一配蔬食鮪魚飯糰 | E40: 18.18 | F40: 1204 | G40: =E40*F40 -> 21888.72 | I40: 3 | J40: 3600 | K40: =J40/I40 -> 1200 | L40: 3 | M40: =F40/V40*60 -> 3216.3618 | N40: =M40/L40 -> 1072.1206 | O40: =L40-I40 -> 0 | P40: =N40-K40 -> -127.8794 | Q40: =N40/K40 -> 0.89343384 | S40: 0.27222222 | T40: 0.2878125 | U40: 15 | V40: 22.46016 | AA40: =M40-J40 -> -383.63819 | AB40: =M40/J40 -> 0.89343384
B41: 18℃-飯糰 | C41: 一配北海道秋鮭親子飯糰 | E41: 24.82 | F41: 1269 | G41: =E41*F41 -> 31496.58 | I41: 5 | J41: 3600 | K41: =J41/I41 -> 720 | L41: 5 | M41: =F41/V41*60 -> 3217.1202 | N41: =M41/L41 -> 643.42403 | O41: =L41-I41 -> 0 | P41: =N41-K41 -> -76.575968 | Q41: =N41/K41 -> 0.89364449 | S41: 0.29791667 | T41: 0.31435185 | U41: 14.55 | V41: 23.66713 | AA41: =M41-J41 -> -382.87984 | AB41: =M41/J41 -> 0.89364449
B42: 18℃-飯糰 | C42: 一配黑胡椒洋蔥豬飯糰 | E42: 17.07 | F42: 2079 | G42: =E42*F42 -> 35488.53 | I42: 3 | J42: 3300 | K42: =J42/I42 -> 1100 | L42: 3 | M42: =F42/V42*60 -> 3015.6672 | N42: =M42/L42 -> 1005.2224 | O42: =L42-I42 -> 0 | P42: =N42-K42 -> -94.777606 | Q42: =N42/K42 -> 0.91383854 | S42: 0.32430556 | T42: 0.35302083 | U42: 15 | V42: 41.363981 | AA42: =M42-J42 -> -284.33282 | AB42: =M42/J42 -> 0.91383854
B43: 18℃-飯糰 | C43: 一配經典肉鬆飯糰 | E43: 14.03 | F43: 4525 | G43: =E43*F43 -> 63485.75 | I43: 3 | J43: 3000 | K43: =J43/I43 -> 1000 | L43: 3 | M43: =F43/V43*60 -> 2741.9161 | N43: =M43/L43 -> 913.97204 | O43: =L43-I43 -> 0 | P43: =N43-K43 -> -86.027962 | Q43: =N43/K43 -> 0.91397204 | S43: 0.36319444 | T43: 0.43195602 | U43: 14.65 | V43: 99.018347 | AA43: =M43-J43 -> -258.08389 | AB43: =M43/J43 -> 0.91397204
B44: 18℃-飯糰 | C44: 一配鮪魚飯糰 | E44: 14.28 | F44: 6419 | G44: =E44*F44 -> 91663.32 | I44: 3 | J44: 3600 | K44: =J44/I44 -> 1200 | L44: 3 | M44: =F44/V44*60 -> 3213.9852 | N44: =M44/L44 -> 1071.3284 | O44: =L44-I44 -> 0 | P44: =N44-K44 -> -128.67159 | Q44: =N44/K44 -> 0.89277368 | S44: 0.44236111 | T44: 0.52556713 | U44: 14.983333 | V44: 119.83254 | AA44: =M44-J44 -> -386.01476 | AB44: =M44/J44 -> 0.89277368
B55: 平均 | I55: =AVERAGE(I39:I54) -> 3.6666667 | J55: =AVERAGE(J39:J54) -> 3450 | K55: =J55/I55 -> 940.90909 | L55: =AVERAGE(L39:L54) -> 3.6666667 | M55: =AVERAGE(M39:M54) -> 3103.7467 | N55: =M55/L55 -> 846.47637 | O55: =L55-I55 -> 0 | P55: =N55-K55 -> -94.432725 | Q55: =N55/K55 -> 0.89963672 | S55: 0.25 | T55: 0.52556713 | AA55: =M55-J55 -> -346.25332 | AB55: =M55/J55 -> 0.89963672
A56: GKK3600型 飯糰機2 | B56: 18℃-飯糰 | C56: 一配椒鹽檸檬鯖魚飯糰 | E56: 20.72 | F56: 1603 | G56: =E56*F56 -> 33214.16 | I56: 3 | J56: 3600 | K56: =J56/I56 -> 1200 | L56: 3 | M56: =F56/V56*60 -> 3217.2784 | N56: =M56/L56 -> 1072.4261 | O56: =L56-I56 -> 0 | P56: =N56-K56 -> -127.57388 | Q56: =N56/K56 -> 0.89368843 | R56: =Q72 -> 0.89600886 | S56: 0.25 | T56: 0.27075231 | V56: 29.894833 | AA56: =M56-J56 -> -382.72164 | AB56: =M56/J56 -> 0.89368843 | AC56: =AB72 -> 0.89600886
B57: 18℃-飯糰 | C57: 一配柚檸海灣貝飯糰 | E57: 23.72 | F57: 699 | G57: =E57*F57 -> 16580.28 | I57: 5 | J57: 3600 | K57: =J57/I57 -> 720 | L57: 5 | M57: =F57/V57*60 -> 3216.4311 | N57: =M57/L57 -> 643.28623 | O57: =L57-I57 -> 0 | P57: =N57-K57 -> -76.71377 | Q57: =N57/K57 -> 0.8934531 | S57: 0.28055556 | T57: 0.28960648 | U57: 15 | V57: 13.039297 | AA57: =M57-J57 -> -383.56885 | AB57: =M57/J57 -> 0.8934531
B58: 18℃-飯糰 | C58: 一配贅沢鮭魚肚飯糰 | E58: 30 | F58: 1852 | G58: =E58*F58 -> 55560 | I58: 4 | J58: 3600 | K58: =J58/I58 -> 900 | L58: 4 | M58: =F58/V58*60 -> 3216.7507 | N58: =M58/L58 -> 804.18767 | O58: =L58-I58 -> 0 | P58: =N58-K58 -> -95.812331 | Q58: =N58/K58 -> 0.89354185 | S58: 0.3 | T58: 0.32398148 | U58: 14.966667 | V58: 34.544176 | AA58: =M58-J58 -> -383.24933 | AB58: =M58/J58 -> 0.89354185
B59: 18℃-飯糰 | C59: 一配筋子銀鮭飯糰 | E59: 30 | F59: 2131 | G59: =E59*F59 -> 63930 | I59: 4 | J59: 3300 | K59: =J59/I59 -> 825 | L59: 4 | M59: =F59/V59*60 -> 3016.4409 | N59: =M59/L59 -> 754.11023 | O59: =L59-I59 -> 0 | P59: =N59-K59 -> -70.889775 | Q59: =N59/K59 -> 0.914073 | S59: 0.33402778 | T59: 0.36346065 | U59: 15 | V59: 42.387703 | AA59: =M59-J59 -> -283.5591 | AB59: =M59/J59 -> 0.914073
B60: 18℃-飯糰 | C60: 一配鹽蔥生鮭飯糰 | E60: 27.48 | F60: 3144 | G60: =E60*F60 -> 86397.12 | I60: 5 | J60: 3600 | K60: =J60/I60 -> 720 | L60: 5 | M60: =F60/V60*60 -> 3216.9659 | N60: =M60/L60 -> 643.39318 | O60: =L60-I60 -> 0 | P60: =N60-K60 -> -76.606825 | Q60: =N60/K60 -> 0.89360163 | S60: 0.37361111 | T60: 0.4143287 | U60: 14.616667 | V60: 58.639105 | AA60: =M60-J60 -> -383.03412 | AB60: =M60/J60 -> 0.89360163
B61: 18℃-飯糰 | C61: 一配明太子龍蝦風味沙拉飯糰 | E61: 18.18 | F61: 2102 | G61: =E61*F61 -> 38214.36 | I61: 3 | J61: 3600 | K61: =J61/I61 -> 1200 | L61: 3 | M61: =F61/V61*60 -> 3213.3663 | N61: =M61/L61 -> 1071.1221 | O61: =L61-I61 -> 0 | P61: =N61-K61 -> -128.87791 | Q61: =N61/K61 -> 0.89260174 | S61: 0.42430556 | T61: 0.45155093 | U61: 15 | V61: 39.24856 | AA61: =M61-J61 -> -386.63372 | AB61: =M61/J61 -> 0.89260174
B62: 18℃-飯糰 | C62: 一配雞肉飯飯糰 | E62: 16.66 | F62: 5270 | G62: =E62*F62 -> 87798.2 | I62: 5 | J62: 3600 | K62: =J62/I62 -> 720 | L62: 5 | M62: =F62/V62*60 -> 3213.3874 | N62: =M62/L62 -> 642.67747 | O62: =L62-I62 -> 0 | P62: =N62-K62 -> -77.322527 | Q62: =N62/K62 -> 0.8926076 | S62: 0.46180556 | T62: 0.53013889 | U62: 14.766667 | V62: 98.400835 | AA62: =M62-J62 -> -386.61263 | AB62: =M62/J62 -> 0.8926076
B72: 平均 | I72: =AVERAGE(I56:I71) -> 4.1428571 | J72: =AVERAGE(J56:J71) -> 3557.1429 | K72: =J72/I72 -> 858.62069 | L72: =AVERAGE(L56:L71) -> 4.1428571 | M72: =AVERAGE(M56:M71) -> 3187.2315 | N72: =M72/L72 -> 769.33175 | O72: =L72-I72 -> 0 | P72: =N72-K72 -> -89.288945 | Q72: =N72/K72 -> 0.89600886 | S72: 0.25 | T72: 0.53013889 | AA72: =M72-J72 -> -369.91134 | AB72: =M72/J72 -> 0.89600886
A73: 自動包裝機 (二配) | B73: 18℃-飯糰 | C73: 二配兩粒飯糰(鮪魚.焦糖鮭魚) | E73: 28.57 | F73: 1478 | G73: =E73*F73 -> 42226.46 | I73: 12 | J73: 3600 | K73: =J73/I73 -> 300 | L73: 12 | M73: =F73/V73*60 -> 3120.1541 | N73: =M73/L73 -> 260.01284 | O73: =L73-I73 -> 0 | P73: =N73-K73 -> -39.987159 | Q73: =N73/K73 -> 0.86670947 | R73: =Q89 -> 0.8937227 | S73: 0.70833333 | T73: 0.72806713 | V73: 28.421673 | AA73: =M73-J73 -> -479.84591 | AB73: =M73/J73 -> 0.86670947 | AC73: =AB89 -> 0.8937227
B74: 18℃-飯糰 | C74: 二配柚香雞胸五穀飯糰 | E74: 17.71 | F74: 506 | G74: =E74*F74 -> 8961.26 | I74: 5 | J74: 3600 | K74: =J74/I74 -> 720 | L74: 5 | M74: =F74/V74*60 -> 3266.7813 | N74: =M74/L74 -> 653.35626 | O74: =L74-I74 -> 0 | P74: =N74-K74 -> -66.64374 | Q74: =N74/K74 -> 0.90743925 | S74: 0.73194444 | T74: 0.7383912 | U74: 5.5833333 | V74: 9.2935514 | AA74: =M74-J74 -> -333.2187 | AB74: =M74/J74 -> 0.90743925
B75: 18℃-飯糰 | C75: 二配鮭魚毛豆炊飯飯糰 | E75: 18.92 | F75: 1048 | G75: =E75*F75 -> 19828.16 | I75: 5 | J75: 3600 | K75: =J75/I75 -> 720 | L75: 5 | M75: =F75/V75*60 -> 3265.2698 | N75: =M75/L75 -> 653.05395 | O75: =L75-I75 -> 0 | P75: =N75-K75 -> -66.946047 | Q75: =N75/K75 -> 0.90701938 | S75: 0.74166667 | T75: 0.75503472 | U75: 4.7166667 | V75: 19.257214 | AA75: =M75-J75 -> -334.73023 | AB75: =M75/J75 -> 0.90701938
B89: 平均 | I89: =AVERAGE(I73:I88) -> 7.3333333 | J89: =AVERAGE(J73:J88) -> 3600 | K89: =J89/I89 -> 490.90909 | L89: =AVERAGE(L73:L88) -> 7.3333333 | M89: =AVERAGE(M73:M88) -> 3217.4017 | N89: =M89/L89 -> 438.7366 | O89: =L89-I89 -> 0 | P89: =N89-K89 -> -52.172493 | Q89: =N89/K89 -> 0.8937227 | S89: 0.70833333 | T89: 0.75503472 | AA89: =M89-J89 -> -382.59828 | AB89: =M89/J89 -> 0.8937227
A90: (新) 3300型飯糰機 (二配) | B90: 18℃-飯糰 | C90: 二配大飯糰乾燒風味鮮蝦 | E90: 23.27 | F90: 514 | G90: =E90*F90 -> 11960.78 | I90: 5 | J90: 3000 | K90: =J90/I90 -> 600 | L90: 5 | M90: =F90/V90*60 -> 2739.0771 | N90: =M90/L90 -> 547.81543 | O90: =L90-I90 -> 0 | P90: =N90-K90 -> -52.184572 | Q90: =N90/K90 -> 0.91302571 | R90: =Q106 -> 0.91270506 | S90: 0.70833333 | T90: 0.71614583 | V90: 11.259267 | AA90: =M90-J90 -> -260.92286 | AB90: =M90/J90 -> 0.91302571 | AC90: =AB106 -> 0.91270506
B91: 18℃-飯糰 | C91: 二配大飯糰韓式蒜烤豬五花 | E91: 24.54 | F91: 1307 | G91: =E91*F91 -> 32073.78 | I91: 4 | J91: 3000 | K91: =J91/I91 -> 750 | L91: 4 | M91: =F91/V91*60 -> 2739.3099 | N91: =M91/L91 -> 684.82748 | O91: =L91-I91 -> 0 | P91: =N91-K91 -> -65.172523 | Q91: =N91/K91 -> 0.9131033 | S91: 0.71944444 | T91: 0.73931713 | U91: 4.75 | V91: 28.627648 | AA91: =M91-J91 -> -260.69009 | AB91: =M91/J91 -> 0.9131033
B92: 18℃-飯糰 | C92: 二配大飯糰泡菜鮪魚 | E92: 24.33 | F92: 1367 | G92: =E92*F92 -> 33259.11 | I92: 4 | J92: 3000 | K92: =J92/I92 -> 750 | L92: 4 | M92: =F92/V92*60 -> 2737.2851 | N92: =M92/L92 -> 684.32127 | O92: =L92-I92 -> 0 | P92: =N92-K92 -> -65.678727 | Q92: =N92/K92 -> 0.91242836 | S92: 0.74305556 | T92: 0.76385417 | U92: 5.3833333 | V92: 29.963996 | AA92: =M92-J92 -> -262.71491 | AB92: =M92/J92 -> 0.91242836
B93: 18℃-飯糰 | C93: 二配壹號醬炙烤牛飯糰 | E93: 22.28 | F93: 1512 | G93: =E93*F93 -> 33687.36 | I93: 5 | J93: 3300 | K93: =J93/I93 -> 660 | L93: 5 | M93: =F93/V93*60 -> 3011.2888 | N93: =M93/L93 -> 602.25775 | O93: =L93-I93 -> 0 | P93: =N93-K93 -> -57.742245 | Q93: =N93/K93 -> 0.91251175 | S93: 0.76666667 | T93: 0.78758102 | U93: 5 | V93: 30.126636 | AA93: =M93-J93 -> -288.71123 | AB93: =M93/J93 -> 0.91251175
B94: 18℃-飯糰 | C94: 二配鹽蔥燒肉飯糰 | E94: 17.89 | F94: 4947 | G94: =E94*F94 -> 88501.83 | I94: 4 | J94: 3300 | K94: =J94/I94 -> 825 | L94: 4 | M94: =F94/V94*60 -> 3011.2381 | N94: =M94/L94 -> 752.80952 | O94: =L94-I94 -> 0 | P94: =N94-K94 -> -72.190481 | Q94: =N94/K94 -> 0.91249639 | S94: 0.79166667 | T94: 0.86011574 | U94: 5.8833333 | V94: 98.570751 | AA94: =M94-J94 -> -288.76192 | AB94: =M94/J94 -> 0.91249639
B106: 平均 | I106: =AVERAGE(I90:I105) -> 4.4 | J106: =AVERAGE(J90:J105) -> 3120 | K106: =J106/I106 -> 709.09091 | L106: =AVERAGE(L90:L105) -> 4.4 | M106: =AVERAGE(M90:M105) -> 2847.6398 | N106: =M106/L106 -> 647.19086 | O106: =L106-I106 -> 0 | P106: =N106-K106 -> -61.900046 | Q106: =N106/K106 -> 0.91270506 | S106: 0.70833333 | T106: 0.86011574 | AA106: =M106-J106 -> -272.3602 | AB106: =M106/J106 -> 0.91270506
A107: GKK3600型 飯糰機 (二配) | B107: 18℃-飯糰 | C107: 二配芝麻香鬆飯糰 | E107: 18.18 | F107: 598 | G107: =E107*F107 -> 10871.64 | H107: 2 | I107: 3 | J107: 3000 | K107: =J107/I107 -> 1000 | L107: 3 | M107: =F107/V107*60 -> 2740.6541 | N107: =M107/L107 -> 913.55137 | O107: =L107-I107 -> 0 | P107: =N107-K107 -> -86.448628 | Q107: =N107/K107 -> 0.91355137 | R107: =Q123 -> 0.90407009 | S107: 0.73194444 | T107: 0.74103009 | V107: 13.091765 | AA107: =M107-J107 -> -259.34588 | AB107: =M107/J107 -> 0.91355137 | AC107: =AB123 -> 0.90407009
...

Sheet 0806(4度C)
A1: 大溪廠日報分析 | C1: 總生產量 | D1: =SUM(F5:F140) -> 87847 | E1: 營業額 | F1: =SUM(G5:G140) -> 3796022.9 | G1: 出勤人數 | H1: =L21+L38+L55+L72+L89+L106+L123+L140 -> 135.93333 | I1: 產線配置圖 | L1: 生產實績 | O1: 人時性差異分析 | S1: 日報登錄 | Y1: 合計次數 | Z1: 合計(時間/分) | AA1: 產線異常 分析說明(5分鐘以上) | AC1: 合計次數 | AD1: 合計(時間/分) | AE1: 產能差異分析
A2: 46240 | C2: 人時性 | D2: =AVERAGE(N21,N38,N55,N72,N89,N106,N123,N140) -> 201.83136 | E2: 平均廠價 | F2: =F1/D1 -> 43.211754 | G2: 多次生產數 | H2: =COUNT(H5:H140) -> 1 | Y2: =SUM(Y21,Y38,Y55,Y72,Y89,Y106,Y123,Y140) -> 0 | Z2: =SUM(Z21,Z38,Z55,Z72,Z89,Z106,Z123,Z140) -> 0 | AC2: =SUM(AC21,AC38,AC55,AC72,AC89,AC106,AC123,AC140) -> 0 | AD2: =SUM(AD21,AD38,AD55,AD72,AD89,AD106,AD123,AD140) -> 0
A3: 線別 | B3: 品類 | C3: 品名 | E3: 廠價 | F3: 生產量 | G3: 營收 | H3: 多次 生產 | I3: 人數 | J3: 產能/時 | K3: 人時性 | L3: 人數 | M3: 產能/時 | N3: 人時性 | O3: 人數 | P3: 人時性 | Q3: 達成率 | R3: 達成率 平均 | S3: 生產時間 | U3: 換線、休息/分 | V3: 稼動時間/分 | W3: 休息時間 | Y3: 產線異常統計(5分鐘以上) | AA3: (屏榮回填) | AC3: 短暫停線統計(5分鐘以下) | AE3: 產能/時 | AF3: 達成率 | AG3: 達成率平均
S4: 開始 | T4: 結束 | W4: 開始 | X4: 結束 | Y4: 次數 | Z4: 時間/分 | AC4: 總次數 | AD4: 設備因素(次數)
A5: 便當二線 | B5: 微波小吃 | C5: 日式茶碗蒸 | E5: 19.7 | F5: 3846 | G5: =E5*F5 -> 75766.2 | I5: 13 | J5: 1200 | K5: =J5/I5 -> 92.307692 | L5: 13 | M5: =F5/V5*60 -> 1082.7273 | N5: =M5/L5 -> 83.286714 | O5: =L5-I5 -> 0 | P5: =N5-K5 -> -9.0209778 | Q5: =N5/K5 -> 0.90227274 | R5: =Q21 -> 0.90158529 | S5: 0.20833333 | T5: 0.35633102 | V5: 213.12846 | AE5: =M5-J5 -> -117.27271 | AF5: =M5/J5 -> 0.90227274 | AG5: =AF21 -> 0.90158529
B6: 微波主食 | C6: 糖燻野郎三十天熟成牛飯 | E6: 56.43 | F6: 3709 | G6: =E6*F6 -> 209298.87 | I6: 24 | J6: 2000 | K6: =J6/I6 -> 83.333333 | L6: 24 | M6: =F6/V6*60 -> 1803.7548 | N6: =M6/L6 -> 75.156451 | O6: =L6-I6 -> 0 | P6: =N6-K6 -> -8.1768824 | Q6: =N6/K6 -> 0.90187741 | S6: 0.35972222 | T6: 0.44539352 | U6: 4.8833333 | V6: 123.37597 | AE6: =M6-J6 -> -196.24518 | AF6: =M6/J6 -> 0.90187741
B7: 便當 | C7: 香檸奶油魚排蔬滿盒 | E7: 77.35 | F7: 912 | G7: =E7*F7 -> 70543.2 | I7: 25 | J7: 2000 | K7: =J7/I7 -> 80 | L7: 25 | M7: =F7/V7*60 -> 1802.0216 | N7: =M7/L7 -> 72.080864 | O7: =L7-I7 -> 0 | P7: =N7-K7 -> -7.9191358 | Q7: =N7/K7 -> 0.9010108 | S7: 0.44930556 | T7: 0.47038194 | U7: 5.6333333 | V7: 30.365896 | W7: 0.47038194 | X7: 0.50972222 | AE7: =M7-J7 -> -197.9784 | AF7: =M7/J7 -> 0.9010108
B8: 便當 | C8: 健身G肉餐盒 | E8: 59.52 | F8: 3741 | G8: =E8*F8 -> 222664.32 | I8: 24 | J8: 2000 | K8: =J8/I8 -> 83.333333 | L8: 24 | M8: =F8/V8*60 -> 1802.9104 | N8: =M8/L8 -> 75.121265 | O8: =L8-I8 -> 0 | P8: =N8-K8 -> -8.2120679 | Q8: =N8/K8 -> 0.90145519 | S8: 0.50972222 | T8: 0.59616898 | U8: 56.65 | V8: 124.4987 | AE8: =M8-J8 -> -197.08963 | AF8: =M8/J8 -> 0.90145519
B21: 平均 | I21: =AVERAGE(I5:I20) -> 21.5 | J21: =AVERAGE(J5:J20) -> 1800 | K21: =J21/I21 -> 83.72093 | L21: =AVERAGE(L5:L20) -> 21.5 | M21: =AVERAGE(M5:M20) -> 1622.8535 | N21: =M21/L21 -> 75.481559 | O21: =L21-I21 -> 0 | P21: =N21-K21 -> -8.2393711 | Q21: =N21/K21 -> 0.90158529 | S21: 0.20833333 | T21: 0.59616898 | Y21: =SUM(Y5:Y20) -> 0 | Z21: =SUM(Z5:Z20) -> 0 | AC21: =SUM(AC5:AC20) -> 0 | AD21: =SUM(AD5:AD20) -> 0 | AE21: =M21-J21 -> -177.14648 | AF21: =M21/J21 -> 0.90158529
A22: 涼麵一線 | B22: 4℃-壽司手卷 | C22: 海陸雙拼壽司 | E22: 36.45 | F22: 2438 | G22: =E22*F22 -> 88865.1 | I22: 20 | J22: 2100 | K22: =J22/I22 -> 105 | L22: 20 | M22: =F22/V22*60 -> 1892.2283 | N22: =M22/L22 -> 94.611417 | O22: =L22-I22 -> 0 | P22: =N22-K22 -> -10.388583 | Q22: =N22/K22 -> 0.90106112 | R22: =Q38 -> 0.90273007 | S22: 0.16666667 | T22: 0.22034722 | V22: 77.305681 | AE22: =M22-J22 -> -207.77166 | AF22: =M22/J22 -> 0.90106112 | AG22: =AF38 -> 0.90995192
B23: 微波小吃 | C23: 馬鈴薯玉米濃湯 | E23: 31.72 | F23: 1420 | G23: =E23*F23 -> 45042.4 | I23: 22 | J23: 2000 | K23: =J23/I23 -> 90.909091 | L23: 22 | M23: =F23/V23*60 -> 1804.0275 | N23: =M23/L23 -> 82.001251 | O23: =L23-I23 -> 0 | P23: =N23-K23 -> -8.9078403 | Q23: =N23/K23 -> 0.90201376 | S23: 0.22361111 | T23: 0.25640046 | U23: 4.7 | V23: 47.227661 | AE23: =M23-J23 -> -195.97249 | AF23: =M23/J23 -> 0.90201376
B24: 微波小吃 | C24: 三合一味噌湯 | E24: 34.79 | F24: 1546 | G24: =E24*F24 -> 53785.34 | I24: 11 | J24: 2000 | K24: =J24/I24 -> 181.81818 | L24: 11 | M24: =F24/V24*60 -> 1808.928 | N24: =M24/L24 -> 164.448 | O24: =L24-I24 -> 0 | P24: =N24-K24 -> -17.370182 | Q24: =N24/K24 -> 0.904464 | S24: 0.26041667 | T24: 0.29601852 | U24: 5.7833333 | V24: 51.27899 | AE24: =M24-J24 -> -191.072 | AF24: =M24/J24 -> 0.904464
B25: 微波小吃 | C25: 蒸蛋湯 | E25: 33.2 | F25: 2541 | G25: =E25*F25 -> 84361.2 | I25: 11 | J25: 2000 | K25: =J25/I25 -> 181.81818 | L25: 11 | M25: =F25/V25*60 -> 1808.1993 | N25: =M25/L25 -> 164.38176 | O25: =L25-I25 -> 0 | P25: =N25-K25 -> -17.436424 | Q25: =N25/K25 -> 0.90409967 | S25: 0.29930556 | T25: 0.35784722 | U25: 4.7333333 | V25: 84.315925 | AE25: =M25-J25 -> -191.80067 | AF25: =M25/J25 -> 0.90409967
B26: 微波小吃 | C26: 越式牛肉寬粉 | E26: 51.44 | F26: 1554 | G26: =E26*F26 -> 79937.76 | I26: 19 | J26: 2000 | K26: =J26/I26 -> 105.26316 | L26: 19 | M26: =F26/V26*60 -> 1804.3709 | N26: =M26/L26 -> 94.96689 | O26: =L26-I26 -> 0 | P26: =N26-K26 -> -10.296268 | Q26: =N26/K26 -> 0.90218546 | S26: 0.36180556 | T26: 0.39768519 | U26: 5.7 | V26: 51.674519 | AE26: =M26-J26 -> -195.62908 | AF26: =M26/J26 -> 0.90218546
B27: 微波主食 | C27: 日式鮭魚茶泡烤飯 | E27: 46.34 | F27: 2162 | G27: =E27*F27 -> 100187.08 | I27: 21 | J27: 1800 | K27: =J27/I27 -> 85.714286 | L27: 21 | M27: =F27/V27*60 -> 1622.8049 | N27: =M27/L27 -> 77.276425 | O27: =L27-I27 -> 0 | P27: =N27-K27 -> -8.4378607 | Q27: =N27/K27 -> 0.90155829 | S27: 0.40138889 | T27: 0.45689815 | U27: 5.3333333 | V27: 79.935671 | W27: 0.45689815 | X27: 0.49513889 | AE27: =M27-J27 -> -177.19508 | AF27: =M27/J27 -> 0.90155829
B28: 4℃-飯糰 | C28: 麻油雞飯糰 | E28: 29.97 | F28: 2168 | G28: =E28*F28 -> 64974.96 | I28: 21 | J28: 2790 | K28: =J28/I28 -> 132.85714 | L28: 22 | M28: =F28/V28*60 -> 2626.6346 | N28: =M28/L28 -> 119.39248 | O28: =L28-I28 -> 1 | P28: =N28-K28 -> -13.46466 | Q28: =N28/K28 -> 0.89865309 | S28: 0.49513889 | T28: 0.52952546 | U28: 55.066667 | V28: 49.523447 | AE28: =M28-J28 -> -163.36538 | AF28: =M28/J28 -> 0.9414461
B38: 平均 | I38: =AVERAGE(I22:I37) -> 17.857143 | J38: =AVERAGE(J22:J37) -> 2098.5714 | K38: =J38/I38 -> 117.52 | L38: =AVERAGE(L22:L37) -> 18 | M38: =AVERAGE(M22:M37) -> 1909.5991 | N38: =M38/L38 -> 106.08884 | O38: =L38-I38 -> 0.14285714 | P38: =N38-K38 -> -11.431162 | Q38: =N38/K38 -> 0.90273007 | S38: 0.16666667 | T38: 0.52952546 | Y38: =SUM(Y22:Y37) -> 0 | Z38: =SUM(Z22:Z37) -> 0 | AC38: =SUM(AC22:AC37) -> 0 | AD38: =SUM(AD22:AD37) -> 0 | AE38: =M38-J38 -> -188.97234 | AF38: =M38/J38 -> 0.90995192
A39: 涼麵二線 | B39: 便當 | C39: 香腸腿排雙拼便當 | E39: 53.76 | F39: 2846 | G39: =E39*F39 -> 153000.96 | I39: 20 | J39: 2000 | K39: =J39/I39 -> 100 | L39: 20 | M39: =F39/V39*60 -> 1801.3482 | N39: =M39/L39 -> 90.067411 | O39: =L39-I39 -> 0 | P39: =N39-K39 -> -9.9325893 | Q39: =N39/K39 -> 0.90067411 | R39: =Q55 -> 0.9009458 | S39: 0.16666667 | T39: 0.23248843 | V39: 94.795664 | AE39: =M39-J39 -> -198.65179 | AF39: =M39/J39 -> 0.90067411 | AG39: =AF55 -> 0.9009458
B40: 便當 | C40: 蔬活腿排補力餐盒 | E40: 71.55 | F40: 2586 | G40: =E40*F40 -> 185028.3 | I40: 22 | J40: 2000 | K40: =J40/I40 -> 90.909091 | L40: 22 | M40: =F40/V40*60 -> 1802.0138 | N40: =M40/L40 -> 81.909718 | O40: =L40-I40 -> 0 | P40: =N40-K40 -> -8.9993724 | Q40: =N40/K40 -> 0.9010069 | S40: 0.23541667 | T40: 0.29520833 | U40: 5 | V40: 86.103669 | AE40: =M40-J40 -> -197.98619 | AF40: =M40/J40 -> 0.9010069
B41: 便當 | C41: 地中海布格麥烤魚餐盒 | E41: 63.92 | F41: 2163 | G41: =E41*F41 -> 138258.96 | I41: 24 | J41: 2000 | K41: =J41/I41 -> 83.333333 | L41: 24 | M41: =F41/V41*60 -> 1803.7666 | N41: =M41/L41 -> 75.156941 | O41: =L41-I41 -> 0 | P41: =N41-K41 -> -8.1763927 | Q41: =N41/K41 -> 0.90188329 | S41: 0.29861111 | T41: 0.34856481 | U41: 4.9 | V41: 71.949443 | AE41: =M41-J41 -> -196.23343 | AF41: =M41/J41 -> 0.90188329
B42: 便當 | C42: 烤蛋白餐盒 | E42: 58.67 | F42: 2637 | G42: =E42*F42 -> 154712.79 | I42: 23 | J42: 2000 | K42: =J42/I42 -> 86.956522 | L42: 23 | M42: =F42/V42*60 -> 1801.2616 | N42: =M42/L42 -> 78.315721 | O42: =L42-I42 -> 0 | P42: =N42-K42 -> -8.6408009 | Q42: =N42/K42 -> 0.90063079 | S42: 0.35208333 | T42: 0.4130787 | U42: 5.0666667 | V42: 87.838436 | AE42: =M42-J42 -> -198.73842 | AF42: =M42/J42 -> 0.90063079
B43: 便當 | C43: 海陸雙拼肉肉餐盒 | E43: 59.54 | F43: 2444 | G43: =E43*F43 -> 145515.76 | I43: 23 | J43: 2000 | K43: =J43/I43 -> 86.956522 | L43: 23 | M43: =F43/V43*60 -> 1801.3797 | N43: =M43/L43 -> 78.320856 | O43: =L43-I43 -> 0 | P43: =N43-K43 -> -8.6356662 | Q43: =N43/K43 -> 0.90068984 | S43: 0.41597222 | T43: 0.4725 | U43: 5 | V43: 81.404271 | W43: 0.4725 | X43: 0.51041667 | AE43: =M43-J43 -> -198.62032 | AF43: =M43/J43 -> 0.90068984
B44: 便當 | C44: 懷舊滷雙拼便當 | E44: 61.09 | F44: 2949 | G44: =E44*F44 -> 180154.41 | I44: 20 | J44: 2000 | K44: =J44/I44 -> 100 | L44: 20 | M44: =F44/V44*60 -> 1801.5797 | N44: =M44/L44 -> 90.078985 | O44: =L44-I44 -> 0 | P44: =N44-K44 -> -9.9210153 | Q44: =N44/K44 -> 0.90078985 | S44: 0.51041667 | T44: 0.57861111 | U44: 54.6 | V44: 98.213807 | AE44: =M44-J44 -> -198.42031 | AF44: =M44/J44 -> 0.90078985
B55: 平均 | I55: =AVERAGE(I39:I54) -> 22 | J55: =AVERAGE(J39:J54) -> 2000 | K55: =J55/I55 -> 90.909091 | L55: =AVERAGE(L39:L54) -> 22 | M55: =AVERAGE(M39:M54) -> 1801.8916 | N55: =M55/L55 -> 81.904163 | O55: =L55-I55 -> 0 | P55: =N55-K55 -> -9.0049277 | Q55: =N55/K55 -> 0.9009458 | S55: 0.16666667 | T55: 0.57861111 | Y55: =SUM(Y39:Y54) -> 0 | Z55: =SUM(Z39:Z54) -> 0 | AC55: =SUM(AC39:AC54) -> 0 | AD55: =SUM(AD39:AD54) -> 0 | AE55: =M55-J55 -> -198.10841 | AF55: =M55/J55 -> 0.9009458
A56: 涼麵三線 | B56: 季節調理麵 | C56: 和風涓絲冷麵 | E56: 28.86 | F56: 2324 | G56: =E56*F56 -> 67070.64 | I56: 19 | J56: 3600 | K56: =J56/I56 -> 189.47368 | L56: 19 | M56: =F56/V56*60 -> 3194.5087 | N56: =M56/L56 -> 168.13204 | O56: =L56-I56 -> 0 | P56: =N56-K56 -> -21.341645 | Q56: =N56/K56 -> 0.88736354 | R56: =Q72 -> 0.8979062 | S56: 0.16666667 | T56: 0.19696759 | V56: 43.649904 | AE56: =M56-J56 -> -405.49126 | AF56: =M56/J56 -> 0.88736354 | AG56: =AF72 -> 0.8979062
B57: 季節調理麵 | C57: 嘉義崇文白醋涼麵 | E57: 35.89 | F57: 2862 | G57: =E57*F57 -> 102717.18 | I57: 19 | J57: 3600 | K57: =J57/I57 -> 189.47368 | L57: 19 | M57: =F57/V57*60 -> 3191.8478 | N57: =M57/L57 -> 167.99199 | O57: =L57-I57 -> 0 | P57: =N57-K57 -> -21.481697 | Q57: =N57/K57 -> 0.88662438 | S57: 0.2 | T57: 0.23734954 | U57: 5 | V57: 53.799558 | AE57: =M57-J57 -> -408.15224 | AF57: =M57/J57 -> 0.88662438
B58: 季節調理麵 | C58: 韓式泡菜冷麵 | E58: 36.73 | F58: 3891 | G58: =E58*F58 -> 142916.43 | I58: 21 | J58: 3600 | K58: =J58/I58 -> 171.42857 | L58: 21 | M58: =F58/V58*60 -> 3074.3441 | N58: =M58/L58 -> 146.39734 | O58: =L58-I58 -> 0 | P58: =N58-K58 -> -25.031232 | Q58: =N58/K58 -> 0.85398448 | S58: 0.24027778 | T58: 0.29300926 | U58: 5 | V58: 75.938148 | AE58: =M58-J58 -> -525.65588 | AF58: =M58/J58 -> 0.85398448
B59: 季節調理麵 | C59: 招牌雞絲胡麻涼麵 | E59: 43.96 | F59: 1637 | G59: =E59*F59 -> 71962.52 | I59: 24 | J59: 3600 | K59: =J59/I59 -> 150 | L59: 24 | M59: =F59/V59*60 -> 3267.6283 | N59: =M59/L59 -> 136.15118 | O59: =L59-I59 -> 0 | P59: =N59-K59 -> -13.84882 | Q59: =N59/K59 -> 0.90767453 | S59: 0.29652778 | T59: 0.31739583 | U59: 5.0666667 | V59: 30.058498 | AE59: =M59-J59 -> -332.37169 | AF59: =M59/J59 -> 0.90767453
B60: 季節調理麵 | C60: 日式胡麻雞絲冷麵 | E60: 46.93 | F60: 1328 | G60: =E60*F60 -> 62323.04 | I60: 24 | J60: 3600 | K60: =J60/I60 -> 150 | L60: 24 | M60: =F60/V60*60 -> 3268.4643 | N60: =M60/L60 -> 136.18601 | O60: =L60-I60 -> 0 | P60: =N60-K60 -> -13.813988 | Q60: =N60/K60 -> 0.90790675 | S60: 0.32083333 | T60: 0.33775463 | U60: 4.95 | V60: 24.378421 | AE60: =M60-J60 -> -331.53571 | AF60: =M60/J60 -> 0.90790675
B61: 季節調理麵 | C61: 日式蕎麥沾麵 | E61: 36.73 | F61: 3474 | G61: =E61*F61 -> 127600.02 | I61: 20 | J61: 3600 | K61: =J61/I61 -> 180 | L61: 20 | M61: =F61/V61*60 -> 3261.1767 | N61: =M61/L61 -> 163.05884 | O61: =L61-I61 -> 0 | P61: =N61-K61 -> -16.941164 | Q61: =N61/K61 -> 0.90588242 | S61: 0.34097222 | T61: 0.38534722 | U61: 4.6333333 | V61: 63.91558 | AE61: =M61-J61 -> -338.82329 | AF61: =M61/J61 -> 0.90588242
B62: 季節調理麵 | C62: 月見烏龍冷麵 | E62: 48.4 | F62: 2572 | G62: =E62*F62 -> 124484.8 | I62: 22 | J62: 3600 | K62: =J62/I62 -> 163.63636 | L62: 22 | M62: =F62/V62*60 -> 3263.3452 | N62: =M62/L62 -> 148.33387 | O62: =L62-I62 -> 0 | P62: =N62-K62 -> -15.30249 | Q62: =N62/K62 -> 0.90648478 | S62: 0.38819444 | T62: 0.42103009 | U62: 5 | V62: 47.288898 | AE62: =M62-J62 -> -336.65479 | AF62: =M62/J62 -> 0.90648478
B63: 季節調理麵 | C63: 大滿足麻醬涼麵 | E63: 37.8 | F63: 1887 | G63: =E63*F63 -> 71328.6 | H63: 2 | I63: 21 | J63: 3600 | K63: =J63/I63 -> 171.42857 | L63: 21 | M63: =F63/V63*60 -> 3268.572 | N63: =M63/L63 -> 155.64629 | O63: =L63-I63 -> 0 | P63: =N63-K63 -> -15.782284 | Q63: =N63/K63 -> 0.90793668 | S63: 0.42430556 | T63: 0.44835648 | U63: 4.7166667 | V63: 34.63898 | W63: 0.44835648 | X63: 0.48680556 | AE63: =M63-J63 -> -331.42796 | AF63: =M63/J63 -> 0.90793668
B64: 季節調理麵 | C64: 大滿足香辣涼麵 | E64: 38.48 | F64: 5394 | G64: =E64*F64 -> 207561.12 | I64: 20 | J64: 3600 | K64: =J64/I64 -> 180 | L64: 20 | M64: =F64/V64*60 -> 3266.1641 | N64: =M64/L64 -> 163.30821 | O64: =L64-I64 -> 0 | P64: =N64-K64 -> -16.691794 | Q64: =N64/K64 -> 0.90726781 | S64: 0.48680556 | T64: 0.55561343 | U64: 55.366667 | V64: 99.088713 | AE64: =M64-J64 -> -333.83588 | AF64: =M64/J64 -> 0.90726781
B65: 季節調理麵 | C65: 大滿足麻醬涼麵 | E65: 37.8 | F65: 4997 | G65: =E65*F65 -> 188886.6 | I65: 21 | J65: 3600 | K65: =J65/I65 -> 171.42857 | L65: 21 | M65: =F65/V65*60 -> 3268.572 | N65: =M65/L65 -> 155.64629 | O65: =L65-I65 -> 0 | P65: =N65-K65 -> -15.782284 | Q65: =N65/K65 -> 0.90793668 | S65: 0.55902778 | T65: 0.62271991 | U65: 4.9166667 | V65: 91.72813 | AE65: =M65-J65 -> -331.42796 | AF65: =M65/J65 -> 0.90793668
B72: 平均 | I72: =AVERAGE(I56:I71) -> 21.1 | J72: =AVERAGE(J56:J71) -> 3600 | K72: =J72/I72 -> 170.61611 | L72: =AVERAGE(L56:L71) -> 21.1 | M72: =AVERAGE(M56:M71) -> 3232.4623 | N72: =M72/L72 -> 153.19727 | O72: =L72-I72 -> 0 | P72: =N72-K72 -> -17.418847 | Q72: =N72/K72 -> 0.8979062 | S72: 0.16666667 | T72: 0.62271991 | Y72: =SUM(Y56:Y71) -> 0 | Z72: =SUM(Z56:Z71) -> 0 | AC72: =SUM(AC56:AC71) -> 0 | AD72: =SUM(AD56:AD71) -> 0 | AE72: =M72-J72 -> -367.53767 | AF72: =M72/J72 -> 0.8979062
A73: 自動包裝機 | B73: 4℃-壽司手卷 | C73: 醬油生鮭脆卷 | E73: 23.55 | F73: 2142 | G73: =E73*F73 -> 50444.1 | I73: 6 | J73: 2500 | K73: =J73/I73 -> 416.66667 | L73: 6 | M73: =F73/V73*60 -> 2257.5793 | N73: =M73/L73 -> 376.26322 | O73: =L73-I73 -> 0 | P73: =N73-K73 -> -40.403445 | Q73: =N73/K73 -> 0.90303173 | R73: =Q89 -> 0.85131024 | S73: 0.37916667 | T73: 0.41869213 | U73: 5.65 | V73: 56.928232 | AE73: =M73-J73 -> -242.42067 | AF73: =M73/J73 -> 0.90303173 | AG73: =AF89 -> 0.90451713
B74: 4℃-壽司手卷 | C74: 韓式辣炒豬肉飯卷 | E74: 27.05 | F74: 709 | G74: =E74*F74 -> 19178.45 | I74: 5 | J74: 3273 | K74: =J74/I74 -> 654.6 | L74: 6 | M74: =F74/V74*60 -> 2963.2784 | N74: =M74/L74 -> 493.87973 | O74: =L74-I74 -> 1 | P74: =N74-K74 -> -160.72027 | Q74: =N74/K74 -> 0.7544756 | S74: 0.42222222 | T74: 0.4321875 | U74: 5.0833333 | V74: 14.355722 | AE74: =M74-J74 -> -309.72162 | AF74: =M74/J74 -> 0.90537072
B75: 4℃-壽司手卷 | C75: 厚香料優格咖哩烤雞飯卷 | E75: 27.05 | F75: 856 | G75: =E75*F75 -> 23154.8 | I75: 5 | J75: 3273 | K75: =J75/I75 -> 654.6 | L75: 5 | M75: =F75/V75*60 -> 2961.4042 | N75: =M75/L75 -> 592.28084 | O75: =L75-I75 -> 0 | P75: =N75-K75 -> -62.319155 | Q75: =N75/K75 -> 0.90479811 | S75: 0.43611111 | T75: 0.44814815 | U75: 5.65 | V75: 17.343124 | AE75: =M75-J75 -> -311.59578 | AF75: =M75/J75 -> 0.90479811
B89: 平均 | I89: =AVERAGE(I73:I88) -> 5.3333333 | J89: =AVERAGE(J73:J88) -> 3015.3333 | K89: =J89/I89 -> 565.375 | L89: =AVERAGE(L73:L88) -> 5.6666667 | M89: =AVERAGE(M73:M88) -> 2727.4206 | N89: =M89/L89 -> 481.30953 | O89: =L89-I89 -> 0.33333333 | P89: =N89-K89 -> -84.065474 | Q89: =N89/K89 -> 0.85131024 | S89: 0.20833333 | T89: 0.44814815 | Y89: =SUM(Y73:Y88) -> 0 | Z89: =SUM(Z73:Z88) -> 0 | AC89: =SUM(AC73:AC88) -> 0 | AD89: =SUM(AD73:AD88) -> 0 | AE89: =M89-J89 -> -287.91269 | AF89: =M89/J89 -> 0.90451713
A90: 自動包裝機2 | B90: 4℃-壽司手卷 | C90: 鮪魚昆布細卷 | E90: 15.51 | F90: 2174 | G90: =E90*F90 -> 33718.74 | I90: 6 | J90: 3600 | K90: =J90/I90 -> 600 | L90: 6 | M90: =F90/V90*60 -> 3250.44 | N90: =M90/L90 -> 541.74 | O90: =L90-I90 -> 0 | P90: =N90-K90 -> -58.26 | Q90: =N90/K90 -> 0.9029 | R90: =Q106 -> 0.90287325 | S90: 0.25 | T90: 0.2778588 | V90: 40.129952 | AE90: =M90-J90 -> -349.56 | AF90: =M90/J90 -> 0.9029 | AG90: =AF106 -> 0.90287325
...

Sheet 0805
B1: 屏榮 大溪廠組合室生產人時性分析
B3: 日期 | C3: 115.08.05星期三 | E3: 訂單量 | F3: ='0805(18度C)'!D1+'0805(4度C)'!D1 -> 203649 | H3: 營業額 | I3: ='0805(18度C)'!F1+'0805(4度C)'!F1 -> 6359056
B4: 人時性 | C4: 項目 | E4: ➀ | G4: ➁ | I4: ➂ | K4: ④ | M4: ⑤ | O4: 異常停線 | Q4: 短暫停線
C5: 組合室 | E5: 全溫層 | G5: 4度C-各編組展開(一配) | I5: 4度C-各編組展開(二配) | K5: 18度C-各編組展開(一配) | M5: 18度C-各編組展開(二配) | O5: 合計次數 | P5: 時間 | Q5: 合計次數 | R5: 設備次數
C6: 排關平均 | E6: =AVERAGE(D14:O14,D32:X32) -> 495.82986 | F6: =AVERAGE(#REF!,D14:K14) -> #REF! | G6: =AVERAGE(D14:K14) -> 271.47065 | I6: =AVERAGE(L14:O14) -> 94.325718 | K6: =AVERAGE(D32:O32) -> 737.95063 | M6: =AVERAGE(P32:X32) -> 791 | O6: ='0805(4度C)'!Y2 -> 0 | P6: ='0805(4度C)'!Z2 -> 0 | Q6: ='0805(4度C)'!AC2 -> 0 | R6: ='0805(4度C)'!AD2 -> 0
C7: 實績平均 | E7: =AVERAGE(D15:O15,D33:X33) -> 444.99873 | F7: =AVERAGE(#REF!,D15:K15) -> #REF! | G7: =AVERAGE(D15:K15) -> 239.98708 | I7: =AVERAGE(L15:O15) -> 87.458252 | K7: =AVERAGE(D33:O33) -> 663.95988 | M7: =AVERAGE(P33:X33) -> 712.32531
C8: 達成率平均 | E8: =AVERAGE(D16:O16,D34:X34) -> 0.89956546 | F8: =AVERAGE(D16:K16,#REF!) -> #REF! | G8: =AVERAGE(D16:K16) -> 0.89251533 | I8: =AVERAGE(L16:O16) -> 0.92530941 | K8: =AVERAGE(D34:O34) -> 0.89660956 | M8: =AVERAGE(P34:X34) -> 0.90022457
O9: ※現行日本鮮食廠以達成率80%為基本(即為現行KPI)
B11: 溫層 | D11: ➁4度C-各編組展開 | L11: ➂4度C-各編組展開
B12: 編組 | D12: 1 | E12: 2 | F12: 3 | G12: 4 | H12: 5 | I12: 6 | J12: 7 | K12: 8 | L12: 1 | M12: 2 | N12: 3 | O12: 4
D13: 便當一線 | E13: 便當二線 | F13: 涼麵一線 | G13: 涼麵二線 | H13: 涼麵三線 | I13: 自動包裝機 | J13: 自動包裝機2 | K13: 自動包裝機3 | L13: 便當一線 | M13: 便當二線 | N13: 涼麵一線 | O13: 涼麵二線
B14: 人時性 | C14: 排關 | D14: - | E14: 84.40367 | F14: 117.52 | G14: 90.909091 | H14: 170.61611 | I14: 565.375 | J14: 600 | K14: - | L14: - | M14: 101.69492 | N14: 86.956522 | O14: -
C15: 實績 | D15: - | E15: 76.081106 | F15: 106.08226 | G15: 81.892042 | H15: 152.89357 | I15: 481.30953 | J15: 541.66395 | K15: - | L15: - | M15: 96.552577 | N15: 78.363927 | O15: -
C16: 達成率 | D16: - | E16: =E15/E14 -> 0.90139571 | F16: =F15/F14 -> 0.9026741 | G16: =G15/G14 -> 0.90081246 | H16: =H15/H14 -> 0.8961262 | I16: =I15/I14 -> 0.85131024 | J16: =J15/J14 -> 0.90277325 | K16: - | L16: - | M16: =M15/M14 -> 0.94943367 | N16: =N15/N14 -> 0.90118516 | O16: -
B17: 作業 時間 | C17: 開始 | D17: - | E17: 0.16666667 | F17: 0.16666667 | G17: 0.16666667 | H17: 0.16666667 | I17: 0.16666667 | J17: 0.25 | K17: - | L17: - | M17: 0.70833333 | N17: 0.70833333 | O17: -
C18: 結束 | D18: - | E18: 0.61082176 | F18: 0.5341088 | G18: 0.5925 | H18: 0.64075231 | I18: 0.42038194 | J18: 0.31085648 | K18: - | L18: - | M18: 0.82533565 | N18: 0.83608796 | O18: -
B19: 產線異常 (5分鐘以上) | C19: 次數
C20: 時間/分
B21: 短暫停線 (5分鐘以下) | C21: 次數
C22: 設備次數
B23: 配置人數 | D23: - | E23: 21.8 | F23: 18 | G23: 22 | H23: 21.1 | I23: 5.6666667 | J23: 6 | K23: - | L23: - | M23: 18.666667 | N23: 23 | O23: -
B24: 主要應用設備 | D24: L型封口機 | E24: ET-55 | F24: ET-55 | G24: ET-55 | H24: ET-600 | I24: 伺服包裝機 | J24: 伺服包裝機 | K24: 伺服包裝機 | L24: L型封口機 | M24: ET-55 | N24: ET-55 | O24: ET-55
B25: 次要應用設備 | D25: 伺服包裝機 | H25: 伺服包裝機
B26: 備註 | H26: 涼麵+烤飯糰 | I26: 大口飯糰線 | K26: 烤飯糰+手卷
B29: 溫層 | D29: ➃18度C-各編組展開 (一配) | P29: ⑤18度C-各編組展開 (二配)
B30: 編組 | D30: 1 | E30: 2 | F30: 3 | G30: 4 | H30: 5 | I30: 6 | J30: 7 | K30: 8 | L30: 9 | M30: 10 | N30: 11 | O30: 12 | P30: 1 | Q30: 2 | R30: 3 | S30: 4 | T30: 5 | U30: 6 | V30: 7 | W30: 8 | X30: 9
D31: 便當一線 | E31: 涼麵一線 | F31: 涼麵三線 | G31: 自動包裝機 | H31: 自動包裝機2 | I31: 自動包裝機3 | J31: 味付飯糰線B | K31: (舊) 3300型飯糰線 | L31: 3000型飯糰線 | M31: (新) 3300型飯糰機 | N31: GKK3600型 飯糰機 | O31: GKK3600型 飯糰機2 | P31: 自動包裝機 | Q31: 自動包裝機2 | R31: 自動包裝機3 | S31: 味付飯糰線B | T31: (舊) 3300型飯糰線 | U31: 3000型飯糰線 | V31: (新) 3300型飯糰機 | W31: GKK3600型 飯糰機 | X31: GKK3600型 飯糰機2
B32: 人時性 | C32: 排關 | D32: - | E32: - | F32: - | G32: 327.27273 | H32: - | I32: - | J32: - | K32: - | L32: - | M32: 825 | N32: 940.90909 | O32: 858.62069 | P32: 490.90909 | Q32: - | R32: - | S32: - | T32: - | U32: - | V32: 709.09091 | W32: 1100 | X32: 864
C33: 實績 | D33: - | E33: - | F33: - | G33: 287.56179 | H33: - | I33: - | J33: - | K33: - | L33: - | M33: 752.94385 | N33: 846.23364 | O33: 769.10026 | P33: 438.68751 | Q33: - | R33: - | S33: - | T33: - | U33: - | V33: 646.96314 | W33: 992.16349 | X33: 771.48708
C34: 達成率 | D34: - | E34: - | F34: - | G34: =G33/G32 -> 0.87866102 | H34: - | I34: - | J34: - | K34: - | L34: - | M34: =M33/M32 -> 0.91265921 | N34: =N33/N32 -> 0.89937875 | O34: =O33/O32 -> 0.89573926 | P34: =P33/P32 -> 0.8936227 | Q34: - | R34: - | S34: - | T34: - | U34: - | V34: =V33/V32 -> 0.91238391 | W34: =W33/W32 -> 0.90196681 | X34: =X33/X32 -> 0.89292487
B35: 作業 時間 | C35: 開始 | D35: - | E35: - | F35: - | G35: 0.16666667 | H35: - | I35: - | J35: - | K35: - | L35: - | M35: 0.32847222 | N35: 0.25 | O35: 0.25 | P35: 0.70833333 | Q35: - | R35: - | S35: - | T35: - | U35: - | V35: 0.70833333 | W35: 0.73263889 | X35: 0.74236111
C36: 結束 | D36: - | E36: - | F36: - | G36: 0.42038194 | H36: - | I36: - | J36: - | K36: - | L36: - | M36: 0.42358796 | N36: 0.5331713 | O36: 0.5425 | P36: 0.76065972 | Q36: - | R36: - | S36: - | T36: - | U36: - | V36: 0.87319444 | W36: 1.1083565 | X36: 1.1091551
B37: 配置人數 | D37: - | E37: - | F37: - | G37: 11 | H37: - | I37: - | J37: - | K37: - | L37: - | M37: 4 | N37: 3.6666667 | O37: 4.1428571 | P37: 7.3333333 | Q37: - | R37: - | S37: - | T37: - | U37: - | V37: 4.4 | W37: 3 | X37: 4.1666667
B38: 主要應用設備 | D38: 伺服包裝機 | E38: ET-55 | F38: ET-600 | G38: 夾心型 | H38: 伺服包裝機 | I38: 伺服包裝機 | J38: 夾心型 | K38: 3300型 | L38: 3300型 | M38: 3300型 | N38: GKK | O38: GKK | P38: 夾心型 | Q38: 伺服包裝機 | R38: 伺服包裝機 | S38: 夾心型 | T38: 3300型 | U38: 3300型 | V38: 3300型 | W38: GKK | X38: GKK
B39: 次要應用設備
B40: 備註

Sheet 0805(18度C)
A1: 大溪廠日報分析 | C1: 總生產量 | D1: =SUM(F5:F140) -> 108896 | E1: 營業額 | F1: =SUM(G5:G140) -> 2177372.8 | G1: 出勤人數 | H1: =#REF!+#REF!+#REF!+#REF!+L21+#REF!+L38+L55+L72+#REF!+#REF!+L89+L106+L123+L140 -> #REF! | I1: 產線配置圖 | L1: 生產實績 | O1: 人時性差異分析 | S1: 日報登錄 | Y1: 分析說明 | AA1: 產能差異分析
A2: 46239 | C2: 人時性 | D2: =AVERAGE(#REF!,#REF!,#REF!,#REF!,N21,#REF!,N38,N55,N72,#REF!,#REF!,N89,N106,N123,N140) -> #REF! | E2: 平均廠價 | F2: =F1/D1 -> 19.994975 | G2: 多次生產數 | H2: =COUNT(H5:H140) -> 10
A3: 線別 | B3: 品類 | C3: 品名 | E3: 廠價 | F3: 生產量 | G3: 營收 | H3: 多次 生產 | I3: 人數 | J3: 產能/時 | K3: 人時性 | L3: 人數 | M3: 產能/時 | N3: 人時性 | O3: 人數 | P3: 人時性 | Q3: 達成率 | R3: 達成率 平均 | S3: 生產時間 | U3: 換線、休息/分 | V3: 稼動時間/分 | W3: 休息時間 | Y3: (屏榮回填) | AA3: 產能/時 | AB3: 達成率 | AC3: 達成率平均
S4: 開始 | T4: 結束 | W4: 開始 | X4: 結束
A5: 自動包裝機 | B5: 18℃-壽司手卷 | C5: 一配長野稻荷壽司 | E5: 25.64 | F5: 1877 | G5: =E5*F5 -> 48126.28 | I5: 10 | J5: 3600 | K5: =J5/I5 -> 360 | L5: 10 | M5: =F5/V5*60 -> 3219.0496 | N5: =M5/L5 -> 321.90496 | O5: =L5-I5 -> 0 | P5: =N5-K5 -> -38.095045 | Q5: =N5/K5 -> 0.89418043 | R5: =Q21 -> 0.87866102 | S5: 0.16666667 | T5: 0.19096065 | V5: 34.985482 | AA5: =M5-J5 -> -380.95045 | AB5: =M5/J5 -> 0.89418043 | AC5: =AB21 -> 0.87866102
B6: 18℃-壽司手卷 | C6: 一配經典人氣雙手卷 | E6: 29.52 | F6: 2937 | G6: =E6*F6 -> 86700.24 | I6: 11 | J6: 3600 | K6: =J6/I6 -> 327.27273 | L6: 11 | M6: =F6/V6*60 -> 3158.6233 | N6: =M6/L6 -> 287.14758 | O6: =L6-I6 -> 0 | P6: =N6-K6 -> -40.125151 | Q6: =N6/K6 -> 0.87739537 | S6: 0.19375 | T6: 0.23248843 | U6: 5 | V6: 55.790128 | AA6: =M6-J6 -> -441.37666 | AB6: =M6/J6 -> 0.87739537
B7: 18℃-壽司手卷 | C7: 一配鮭鮪海饌雙手卷 | E7: 29.85 | F7: 3478 | G7: =E7*F7 -> 103818.3 | I7: 11 | J7: 3600 | K7: =J7/I7 -> 327.27273 | L7: 11 | M7: =F7/V7*60 -> 3157.6519 | N7: =M7/L7 -> 287.05926 | O7: =L7-I7 -> 0 | P7: =N7-K7 -> -40.213463 | Q7: =N7/K7 -> 0.87712553 | S7: 0.23541667 | T7: 0.28130787 | U7: 5 | V7: 66.087082 | AA7: =M7-J7 -> -442.34809 | AB7: =M7/J7 -> 0.87712553
B8: 18℃-壽司手卷 | C8: 一配青木瓜雞絲泰泰雙手卷 | E8: 30 | F8: 2447 | G8: =E8*F8 -> 73410 | I8: 11 | J8: 3600 | K8: =J8/I8 -> 327.27273 | L8: 11 | M8: =F8/V8*60 -> 3158.7512 | N8: =M8/L8 -> 287.1592 | O8: =L8-I8 -> 0 | P8: =N8-K8 -> -40.11353 | Q8: =N8/K8 -> 0.87743088 | S8: 0.28541667 | T8: 0.31768519 | U8: 5.9166667 | V8: 46.480394 | AA8: =M8-J8 -> -441.24883 | AB8: =M8/J8 -> 0.87743088
B9: 18℃-飯糰 | C9: 一配兩粒飯糰(鮪魚.焦糖鮭魚) | E9: 28.57 | F9: 1479 | G9: =E9*F9 -> 42255.03 | I9: 12 | J9: 3600 | K9: =J9/I9 -> 300 | L9: 12 | M9: =F9/V9*60 -> 3121.8223 | N9: =M9/L9 -> 260.15186 | O9: =L9-I9 -> 0 | P9: =N9-K9 -> -39.848141 | Q9: =N9/K9 -> 0.86717286 | S9: 0.32152778 | T9: 0.34126157 | U9: 5.5333333 | V9: 28.425705 | AA9: =M9-J9 -> -478.17769 | AB9: =M9/J9 -> 0.86717286
B21: 平均 | I21: =AVERAGE(I5:I20) -> 11 | J21: =AVERAGE(J5:J20) -> 3600 | K21: =J21/I21 -> 327.27273 | L21: =AVERAGE(L5:L20) -> 11 | M21: =AVERAGE(M5:M20) -> 3163.1797 | N21: =M21/L21 -> 287.56179 | O21: =L21-I21 -> 0 | P21: =N21-K21 -> -39.71094 | Q21: =N21/K21 -> 0.87866102 | S21: 0.16666667 | T21: 0.42038194 | AA21: =M21-J21 -> -436.82034 | AB21: =M21/J21 -> 0.87866102
A22: (新) 3300型飯糰機 | B22: 18℃-飯糰 | C22: 一配鮭魚奶油醬油飯糰 | E22: 18.53 | F22: 2510 | G22: =E22*F22 -> 46510.3 | I22: 3 | J22: 3300 | K22: =J22/I22 -> 1100 | L22: 3 | M22: =F22/V22*60 -> 3010.1234 | N22: =M22/L22 -> 1003.3745 | O22: =L22-I22 -> 0 | P22: =N22-K22 -> -96.62552 | Q22: =N22/K22 -> 0.91215862 | R22: =Q38 -> 0.91265921 | S22: 0.32847222 | T22: 0.36320602 | V22: 50.031171 | AA22: =M22-J22 -> -289.87656 | AB22: =M22/J22 -> 0.91215862 | AC22: =AB38 -> 0.91265921
B23: 18℃-飯糰 | C23: 一配壹號醬炙烤牛飯糰 | E23: 22.28 | F23: 809 | G23: =E23*F23 -> 18024.52 | I23: 5 | J23: 3300 | K23: =J23/I23 -> 660 | L23: 5 | M23: =F23/V23*60 -> 3013.7298 | N23: =M23/L23 -> 602.74596 | O23: =L23-I23 -> 0 | P23: =N23-K23 -> -57.254039 | Q23: =N23/K23 -> 0.91325146 | S23: 0.36666667 | T23: 0.37784722 | U23: 4.9833333 | V23: 16.106288 | AA23: =M23-J23 -> -286.27019 | AB23: =M23/J23 -> 0.91325146
B24: 18℃-飯糰 | C24: 一配鹽蔥燒肉飯糰 | E24: 17.89 | F24: 3010 | G24: =E24*F24 -> 53848.9 | I24: 4 | J24: 3300 | K24: =J24/I24 -> 825 | L24: 4 | M24: =F24/V24*60 -> 3011.473 | N24: =M24/L24 -> 752.86824 | O24: =L24-I24 -> 0 | P24: =N24-K24 -> -72.131761 | Q24: =N24/K24 -> 0.91256756 | S24: 0.38194444 | T24: 0.42358796 | U24: 5.9 | V24: 59.970653 | AA24: =M24-J24 -> -288.52704 | AB24: =M24/J24 -> 0.91256756
B38: 平均 | I38: =AVERAGE(I22:I37) -> 4 | J38: =AVERAGE(J22:J37) -> 3300 | K38: =J38/I38 -> 825 | L38: =AVERAGE(L22:L37) -> 4 | M38: =AVERAGE(M22:M37) -> 3011.7754 | N38: =M38/L38 -> 752.94385 | O38: =L38-I38 -> 0 | P38: =N38-K38 -> -72.05615 | Q38: =N38/K38 -> 0.91265921 | S38: 0.32847222 | T38: 0.42358796 | AA38: =M38-J38 -> -288.2246 | AB38: =M38/J38 -> 0.91265921
A39: GKK3600型 飯糰機 | B39: 18℃-飯糰 | C39: 一配熟成紅鮭飯糰 | E39: 25.03 | F39: 1014 | G39: =E39*F39 -> 25380.42 | I39: 5 | J39: 3600 | K39: =J39/I39 -> 720 | L39: 5 | M39: =F39/V39*60 -> 3216.3496 | N39: =M39/L39 -> 643.26991 | O39: =L39-I39 -> 0 | P39: =N39-K39 -> -76.73009 | Q39: =N39/K39 -> 0.89343043 | R39: =Q55 -> 0.89937875 | S39: 0.25 | T39: 0.263125 | V39: 18.915854 | AA39: =M39-J39 -> -383.65045 | AB39: =M39/J39 -> 0.89343043 | AC39: =AB55 -> 0.89937875
B40: 18℃-飯糰 | C40: 一配蔬食鮪魚飯糰 | E40: 18.18 | F40: 1221 | G40: =E40*F40 -> 22197.78 | I40: 3 | J40: 3600 | K40: =J40/I40 -> 1200 | L40: 3 | M40: =F40/V40*60 -> 3215.6418 | N40: =M40/L40 -> 1071.8806 | O40: =L40-I40 -> 0 | P40: =N40-K40 -> -128.1194 | Q40: =N40/K40 -> 0.89323384 | S40: 0.27291667 | T40: 0.28872685 | U40: 15 | V40: 22.782388 | AA40: =M40-J40 -> -384.35819 | AB40: =M40/J40 -> 0.89323384
B41: 18℃-飯糰 | C41: 一配北海道秋鮭親子飯糰 | E41: 24.82 | F41: 1321 | G41: =E41*F41 -> 32787.22 | I41: 5 | J41: 3600 | K41: =J41/I41 -> 720 | L41: 5 | M41: =F41/V41*60 -> 3216.7602 | N41: =M41/L41 -> 643.35203 | O41: =L41-I41 -> 0 | P41: =N41-K41 -> -76.647968 | Q41: =N41/K41 -> 0.89354449 | S41: 0.29861111 | T41: 0.31571759 | U41: 15 | V41: 24.639698 | AA41: =M41-J41 -> -383.23984 | AB41: =M41/J41 -> 0.89354449
B42: 18℃-飯糰 | C42: 一配黑胡椒洋蔥豬飯糰 | E42: 17.07 | F42: 2183 | G42: =E42*F42 -> 37263.81 | I42: 3 | J42: 3300 | K42: =J42/I42 -> 1100 | L42: 3 | M42: =F42/V42*60 -> 3015.0072 | N42: =M42/L42 -> 1005.0024 | O42: =L42-I42 -> 0 | P42: =N42-K42 -> -94.997606 | Q42: =N42/K42 -> 0.91363854 | S42: 0.32569444 | T42: 0.35585648 | U42: 15 | V42: 43.442683 | AA42: =M42-J42 -> -284.99282 | AB42: =M42/J42 -> 0.91363854
B43: 18℃-飯糰 | C43: 一配經典肉鬆飯糰 | E43: 14.03 | F43: 4674 | G43: =E43*F43 -> 65576.22 | I43: 3 | J43: 3000 | K43: =J43/I43 -> 1000 | L43: 3 | M43: =F43/V43*60 -> 2740.1161 | N43: =M43/L43 -> 913.37204 | O43: =L43-I43 -> 0 | P43: =N43-K43 -> -86.627962 | Q43: =N43/K43 -> 0.91337204 | S43: 0.36597222 | T43: 0.43703704 | U43: 14.566667 | V43: 102.34603 | AA43: =M43-J43 -> -259.88389 | AB43: =M43/J43 -> 0.91337204
B44: 18℃-飯糰 | C44: 一配鮪魚飯糰 | E44: 14.28 | F44: 6629 | G44: =E44*F44 -> 94662.12 | I44: 3 | J44: 3600 | K44: =J44/I44 -> 1200 | L44: 3 | M44: =F44/V44*60 -> 3213.2652 | N44: =M44/L44 -> 1071.0884 | O44: =L44-I44 -> 0 | P44: =N44-K44 -> -128.91159 | Q44: =N44/K44 -> 0.89257368 | S44: 0.44722222 | T44: 0.5331713 | U44: 14.666667 | V44: 123.78063 | AA44: =M44-J44 -> -386.73476 | AB44: =M44/J44 -> 0.89257368
B55: 平均 | I55: =AVERAGE(I39:I54) -> 3.6666667 | J55: =AVERAGE(J39:J54) -> 3450 | K55: =J55/I55 -> 940.90909 | L55: =AVERAGE(L39:L54) -> 3.6666667 | M55: =AVERAGE(M39:M54) -> 3102.8567 | N55: =M55/L55 -> 846.23364 | O55: =L55-I55 -> 0 | P55: =N55-K55 -> -94.675452 | Q55: =N55/K55 -> 0.89937875 | S55: 0.25 | T55: 0.5331713 | AA55: =M55-J55 -> -347.14332 | AB55: =M55/J55 -> 0.89937875
A56: GKK3600型 飯糰機2 | B56: 18℃-飯糰 | C56: 一配椒鹽檸檬鯖魚飯糰 | E56: 20.72 | F56: 1704 | G56: =E56*F56 -> 35306.88 | I56: 3 | J56: 3600 | K56: =J56/I56 -> 1200 | L56: 3 | M56: =F56/V56*60 -> 3216.5584 | N56: =M56/L56 -> 1072.1861 | O56: =L56-I56 -> 0 | P56: =N56-K56 -> -127.81388 | Q56: =N56/K56 -> 0.89348843 | R56: =Q72 -> 0.89573926 | S56: 0.25 | T56: 0.27207176 | V56: 31.785526 | AA56: =M56-J56 -> -383.44164 | AB56: =M56/J56 -> 0.89348843 | AC56: =AB72 -> 0.89573926
B57: 18℃-飯糰 | C57: 一配柚檸海灣貝飯糰 | E57: 23.72 | F57: 757 | G57: =E57*F57 -> 17956.04 | I57: 5 | J57: 3600 | K57: =J57/I57 -> 720 | L57: 5 | M57: =F57/V57*60 -> 3216.0711 | N57: =M57/L57 -> 643.21423 | O57: =L57-I57 -> 0 | P57: =N57-K57 -> -76.78577 | Q57: =N57/K57 -> 0.8933531 | S57: 0.28194444 | T57: 0.29174769 | U57: 15 | V57: 14.122822 | AA57: =M57-J57 -> -383.92885 | AB57: =M57/J57 -> 0.8933531
B58: 18℃-飯糰 | C58: 一配贅沢鮭魚肚飯糰 | E58: 30 | F58: 1934 | G58: =E58*F58 -> 58020 | I58: 4 | J58: 3600 | K58: =J58/I58 -> 900 | L58: 4 | M58: =F58/V58*60 -> 3214.9507 | N58: =M58/L58 -> 803.73767 | O58: =L58-I58 -> 0 | P58: =N58-K58 -> -96.262331 | Q58: =N58/K58 -> 0.89304185 | S58: 0.30208333 | T58: 0.3271412 | U58: 14.883333 | V58: 36.093866 | AA58: =M58-J58 -> -385.04933 | AB58: =M58/J58 -> 0.89304185
B59: 18℃-飯糰 | C59: 一配筋子銀鮭飯糰 | E59: 30 | F59: 2236 | G59: =E59*F59 -> 67080 | I59: 4 | J59: 3300 | K59: =J59/I59 -> 825 | L59: 4 | M59: =F59/V59*60 -> 3015.7809 | N59: =M59/L59 -> 753.94523 | O59: =L59-I59 -> 0 | P59: =N59-K59 -> -71.054775 | Q59: =N59/K59 -> 0.913873 | S59: 0.3375 | T59: 0.3683912 | U59: 14.916667 | V59: 44.48599 | AA59: =M59-J59 -> -284.2191 | AB59: =M59/J59 -> 0.913873
B60: 18℃-飯糰 | C60: 一配鹽蔥生鮭飯糰 | E60: 27.48 | F60: 3518 | G60: =E60*F60 -> 96674.64 | I60: 5 | J60: 3600 | K60: =J60/I60 -> 720 | L60: 5 | M60: =F60/V60*60 -> 3215.8859 | N60: =M60/L60 -> 643.17718 | O60: =L60-I60 -> 0 | P60: =N60-K60 -> -76.822825 | Q60: =N60/K60 -> 0.89330163 | S60: 0.37847222 | T60: 0.42405093 | U60: 14.516667 | V60: 65.636658 | AA60: =M60-J60 -> -384.11412 | AB60: =M60/J60 -> 0.89330163
B61: 18℃-飯糰 | C61: 一配明太子龍蝦風味沙拉飯糰 | E61: 18.18 | F61: 2201 | G61: =E61*F61 -> 40014.18 | I61: 3 | J61: 3600 | K61: =J61/I61 -> 1200 | L61: 3 | M61: =F61/V61*60 -> 3211.9263 | N61: =M61/L61 -> 1070.6421 | O61: =L61-I61 -> 0 | P61: =N61-K61 -> -129.35791 | Q61: =N61/K61 -> 0.89220174 | S61: 0.43402778 | T61: 0.46256944 | U61: 15 | V61: 41.115514 | AA61: =M61-J61 -> -388.07372 | AB61: =M61/J61 -> 0.89220174
B62: 18℃-飯糰 | C62: 一配雞肉飯飯糰 | E62: 16.66 | F62: 5366 | G62: =E62*F62 -> 89397.56 | I62: 5 | J62: 3600 | K62: =J62/I62 -> 720 | L62: 5 | M62: =F62/V62*60 -> 3212.7344 | N62: =M62/L62 -> 642.54688 | O62: =L62-I62 -> 0 | P62: =N62-K62 -> -77.453124 | Q62: =N62/K62 -> 0.89242622 | S62: 0.47291667 | T62: 0.5425 | U62: 14.9 | V62: 100.2137 | AA62: =M62-J62 -> -387.26562 | AB62: =M62/J62 -> 0.89242622
B72: 平均 | I72: =AVERAGE(I56:I71) -> 4.1428571 | J72: =AVERAGE(J56:J71) -> 3557.1429 | K72: =J72/I72 -> 858.62069 | L72: =AVERAGE(L56:L71) -> 4.1428571 | M72: =AVERAGE(M56:M71) -> 3186.2725 | N72: =M72/L72 -> 769.10026 | O72: =L72-I72 -> 0 | P72: =N72-K72 -> -89.520427 | Q72: =N72/K72 -> 0.89573926 | S72: 0.25 | T72: 0.5425 | AA72: =M72-J72 -> -370.87034 | AB72: =M72/J72 -> 0.89573926
A73: 自動包裝機 (二配) | B73: 18℃-飯糰 | C73: 二配兩粒飯糰(鮪魚.焦糖鮭魚) | E73: 28.57 | F73: 1591 | G73: =E73*F73 -> 45454.87 | I73: 12 | J73: 3600 | K73: =J73/I73 -> 300 | L73: 12 | M73: =F73/V73*60 -> 3121.5941 | N73: =M73/L73 -> 260.13284 | O73: =L73-I73 -> 0 | P73: =N73-K73 -> -39.867159 | Q73: =N73/K73 -> 0.86710947 | R73: =Q89 -> 0.8936227 | S73: 0.70833333 | T73: 0.72956019 | V73: 30.580529 | AA73: =M73-J73 -> -478.40591 | AB73: =M73/J73 -> 0.86710947 | AC73: =AB89 -> 0.8936227
B74: 18℃-飯糰 | C74: 二配柚香雞胸五穀飯糰 | E74: 17.71 | F74: 632 | G74: =E74*F74 -> 11192.72 | I74: 5 | J74: 3600 | K74: =J74/I74 -> 720 | L74: 5 | M74: =F74/V74*60 -> 3265.3413 | N74: =M74/L74 -> 653.06826 | O74: =L74-I74 -> 0 | P74: =N74-K74 -> -66.93174 | Q74: =N74/K74 -> 0.90703925 | S74: 0.73333333 | T74: 0.74138889 | U74: 5.4333333 | V74: 11.612875 | AA74: =M74-J74 -> -334.6587 | AB74: =M74/J74 -> 0.90703925
B75: 18℃-飯糰 | C75: 二配鮭魚毛豆炊飯飯糰 | E75: 18.92 | F75: 1216 | G75: =E75*F75 -> 23006.72 | I75: 5 | J75: 3600 | K75: =J75/I75 -> 720 | L75: 5 | M75: =F75/V75*60 -> 3264.1898 | N75: =M75/L75 -> 652.83795 | O75: =L75-I75 -> 0 | P75: =N75-K75 -> -67.162047 | Q75: =N75/K75 -> 0.90671938 | S75: 0.74513889 | T75: 0.76065972 | U75: 5.4 | V75: 22.351642 | AA75: =M75-J75 -> -335.81023 | AB75: =M75/J75 -> 0.90671938
B89: 平均 | I89: =AVERAGE(I73:I88) -> 7.3333333 | J89: =AVERAGE(J73:J88) -> 3600 | K89: =J89/I89 -> 490.90909 | L89: =AVERAGE(L73:L88) -> 7.3333333 | M89: =AVERAGE(M73:M88) -> 3217.0417 | N89: =M89/L89 -> 438.68751 | O89: =L89-I89 -> 0 | P89: =N89-K89 -> -52.221584 | Q89: =N89/K89 -> 0.8936227 | S89: 0.70833333 | T89: 0.76065972 | AA89: =M89-J89 -> -382.95828 | AB89: =M89/J89 -> 0.8936227
A90: (新) 3300型飯糰機 (二配) | B90: 18℃-飯糰 | C90: 二配大飯糰乾燒風味鮮蝦 | E90: 23.27 | F90: 581 | G90: =E90*F90 -> 13519.87 | I90: 5 | J90: 3000 | K90: =J90/I90 -> 600 | L90: 5 | M90: =F90/V90*60 -> 2737.5771 | N90: =M90/L90 -> 547.51543 | O90: =L90-I90 -> 0 | P90: =N90-K90 -> -52.484572 | Q90: =N90/K90 -> 0.91252571 | R90: =Q106 -> 0.91238391 | S90: 0.70833333 | T90: 0.71717593 | V90: 12.733888 | AA90: =M90-J90 -> -262.42286 | AB90: =M90/J90 -> 0.91252571 | AC90: =AB106 -> 0.91238391
B91: 18℃-飯糰 | C91: 二配大飯糰韓式蒜烤豬五花 | E91: 24.54 | F91: 1423 | G91: =E91*F91 -> 34920.42 | I91: 4 | J91: 3000 | K91: =J91/I91 -> 750 | L91: 4 | M91: =F91/V91*60 -> 2738.7099 | N91: =M91/L91 -> 684.67748 | O91: =L91-I91 -> 0 | P91: =N91-K91 -> -65.322523 | Q91: =N91/K91 -> 0.9129033 | S91: 0.72013889 | T91: 0.74178241 | U91: 5 | V91: 31.175262 | AA91: =M91-J91 -> -261.29009 | AB91: =M91/J91 -> 0.9129033
B92: 18℃-飯糰 | C92: 二配大飯糰泡菜鮪魚 | E92: 24.33 | F92: 1533 | G92: =E92*F92 -> 37297.89 | I92: 4 | J92: 3000 | K92: =J92/I92 -> 750 | L92: 4 | M92: =F92/V92*60 -> 2736.6851 | N92: =M92/L92 -> 684.17127 | O92: =L92-I92 -> 0 | P92: =N92-K92 -> -65.828727 | Q92: =N92/K92 -> 0.91222836 | S92: 0.74583333 | T92: 0.76916667 | U92: 5.8333333 | V92: 33.610005 | AA92: =M92-J92 -> -263.31491 | AB92: =M92/J92 -> 0.91222836
B93: 18℃-飯糰 | C93: 二配壹號醬炙烤牛飯糰 | E93: 22.28 | F93: 1642 | G93: =E93*F93 -> 36583.76 | I93: 5 | J93: 3300 | K93: =J93/I93 -> 660 | L93: 5 | M93: =F93/V93*60 -> 3009.9688 | N93: =M93/L93 -> 601.99375 | O93: =L93-I93 -> 0 | P93: =N93-K93 -> -58.006245 | Q93: =N93/K93 -> 0.91211175 | S93: 0.77222222 | T93: 0.79494213 | U93: 5 | V93: 32.731237 | AA93: =M93-J93 -> -290.03123 | AB93: =M93/J93 -> 0.91211175
B94: 18℃-飯糰 | C94: 二配鹽蔥燒肉飯糰 | E94: 17.89 | F94: 5389 | G94: =E94*F94 -> 96409.21 | I94: 4 | J94: 3300 | K94: =J94/I94 -> 825 | L94: 4 | M94: =F94/V94*60 -> 3010.2481 | N94: =M94/L94 -> 752.56202 | O94: =L94-I94 -> 0 | P94: =N94-K94 -> -72.437981 | Q94: =N94/K94 -> 0.91219639 | S94: 0.79861111 | T94: 0.87319444 | U94: 5.2833333 | V94: 107.41307 | AA94: =M94-J94 -> -289.75192 | AB94: =M94/J94 -> 0.91219639
B106: 平均 | I106: =AVERAGE(I90:I105) -> 4.4 | J106: =AVERAGE(J90:J105) -> 3120 | K106: =J106/I106 -> 709.09091 | L106: =AVERAGE(L90:L105) -> 4.4 | M106: =AVERAGE(M90:M105) -> 2846.6378 | N106: =M106/L106 -> 646.96314 | O106: =L106-I106 -> 0 | P106: =N106-K106 -> -62.127773 | Q106: =N106/K106 -> 0.91238391 | S106: 0.70833333 | T106: 0.87319444 | AA106: =M106-J106 -> -273.3622 | AB106: =M106/J106 -> 0.91238391
A107: GKK3600型 飯糰機 (二配) | B107: 18℃-飯糰 | C107: 二配芝麻香鬆飯糰 | E107: 18.18 | F107: 688 | G107: =E107*F107 -> 12507.84 | H107: 2 | I107: 3 | J107: 3000 | K107: =J107/I107 -> 1000 | L107: 3 | M107: =F107/V107*60 -> 2740.0541 | N107: =M107/L107 -> 913.35137 | O107: =L107-I107 -> 0 | P107: =N107-K107 -> -86.648628 | Q107: =N107/K107 -> 0.91335137 | R107: =Q123 -> 0.90196681 | S107: 0.73263889 | T107: 0.74309028 | V107: 15.065396 | AA107: =M107-J107 -> -259.94588 | AB107: =M107/J107 -> 0.91335137 | AC107: =AB123 -> 0.90196681
...

Sheet 0805(4度C)
A1: 大溪廠日報分析 | C1: 總生產量 | D1: =SUM(F5:F140) -> 94753 | E1: 營業額 | F1: =SUM(G5:G140) -> 4181683.2 | G1: 出勤人數 | H1: =L21+L38+L55+L72+L89+L106+L123+L140 -> 136.23333 | I1: 產線配置圖 | L1: 生產實績 | O1: 人時性差異分析 | S1: 日報登錄 | Y1: 合計次數 | Z1: 合計(時間/分) | AA1: 產線異常 分析說明(5分鐘以上) | AC1: 合計次數 | AD1: 合計(時間/分) | AE1: 產能差異分析
A2: 46239 | C2: 人時性 | D2: =AVERAGE(N21,N38,N55,N72,N89,N106,N123,N140) -> 201.85487 | E2: 平均廠價 | F2: =F1/D1 -> 44.132463 | G2: 多次生產數 | H2: =COUNT(H5:H140) -> 1 | Y2: =SUM(Y21,Y38,Y55,Y72,Y89,Y106,Y123,Y140) -> 0 | Z2: =SUM(Z21,Z38,Z55,Z72,Z89,Z106,Z123,Z140) -> 0 | AC2: =SUM(AC21,AC38,AC55,AC72,AC89,AC106,AC123,AC140) -> 0 | AD2: =SUM(AD21,AD38,AD55,AD72,AD89,AD106,AD123,AD140) -> 0
A3: 線別 | B3: 品類 | C3: 品名 | E3: 廠價 | F3: 生產量 | G3: 營收 | H3: 多次 生產 | I3: 人數 | J3: 產能/時 | K3: 人時性 | L3: 人數 | M3: 產能/時 | N3: 人時性 | O3: 人數 | P3: 人時性 | Q3: 達成率 | R3: 達成率 平均 | S3: 生產時間 | U3: 換線、休息/分 | V3: 稼動時間/分 | W3: 休息時間 | Y3: 產線異常統計(5分鐘以上) | AA3: (屏榮回填) | AC3: 短暫停線統計(5分鐘以下) | AE3: 產能/時 | AF3: 達成率 | AG3: 達成率平均
S4: 開始 | T4: 結束 | W4: 開始 | X4: 結束 | Y4: 次數 | Z4: 時間/分 | AC4: 總次數 | AD4: 設備因素(次數)
