Workbook

Sheet 0131
B1: 屏榮 大溪廠組合室生產人時性分析
B3: 日期 | C3: 115.01.31星期六 | E3: 訂單量 | F3: ='0131(18度C)'!D1+'0131(4度C)'!D1 -> 129053 | H3: 營業額 | I3: ='0131(18度C)'!F1+'0131(4度C)'!F1 -> 4007768.4
B4: 人時性 | C4: 項目 | E4: ➀ | G4: ➁ | I4: ➂ | K4: ④ | M4: ⑤ | O4: 異常停線 | Q4: 短暫停線
C5: 組合室 | E5: 全溫層 | G5: 4度C-各編組展開(一配) | I5: 4度C-各編組展開(二配) | K5: 18度C-各編組展開(一配) | M5: 18度C-各編組展開(二配) | O5: 合計次數 | P5: 時間 | Q5: 合計次數 | R5: 設備次數
C6: 排關平均 | E6: =AVERAGE(D14:O14,D32:X32) -> 546.8859 | F6: =AVERAGE(#REF!,D14:K14) -> #REF! | G6: =AVERAGE(D14:K14) -> 214.62898 | I6: =AVERAGE(L14:O14) -> 94.096363 | K6: =AVERAGE(D32:O32) -> 735.8217 | M6: =AVERAGE(P32:X32) -> 767.08429 | O6: ='0131(4度C)'!Y2 -> 0 | P6: ='0131(4度C)'!Z2 -> 0 | Q6: ='0131(4度C)'!AC2 -> 39 | R6: ='0131(4度C)'!AD2 -> 0
C7: 實績平均 | E7: =AVERAGE(D15:O15,D33:X33) -> 485.65869 | F7: =AVERAGE(#REF!,D15:K15) -> #REF! | G7: =AVERAGE(D15:K15) -> 193.30086 | I7: =AVERAGE(L15:O15) -> 83.696864 | K7: =AVERAGE(D33:O33) -> 652.57145 | M7: =AVERAGE(P33:X33) -> 680.03438
C8: 達成率平均 | E8: =AVERAGE(D16:O16,D34:X34) -> 0.88927064 | F8: =AVERAGE(D16:K16,#REF!) -> #REF! | G8: =AVERAGE(D16:K16) -> 0.89737591 | I8: =AVERAGE(L16:O16) -> 0.88947642 | K8: =AVERAGE(D34:O34) -> 0.88709046 | M8: =AVERAGE(P34:X34) -> 0.88532032
O9: ※現行日本鮮食廠以達成率80%為基本(即為現行KPI)
B11: 溫層 | D11: ➁4度C-各編組展開 | L11: ➂4度C-各編組展開
B12: 編組 | D12: 1 | E12: 2 | F12: 3 | G12: 4 | H12: 5 | I12: 6 | J12: 7 | K12: 8 | L12: 1 | M12: 2 | N12: 3 | O12: 4
D13: 便當一線 | E13: 便當二線 | F13: 涼麵一線 | G13: 涼麵二線 | H13: 涼麵三線 | I13: 自動包裝機 | J13: 自動包裝機2 | K13: 自動包裝機3 | L13: 便當一線 | M13: 便當二線 | N13: 涼麵一線 | O13: 涼麵二線
B14: 人時性 | C14: 排關 | D14: - | E14: 81.967213 | F14: - | G14: 102.5 | H14: 101.2987 | I14: 572.75 | J14: - | K14: - | L14: - | M14: 98.305085 | N14: - | O14: 89.88764
C15: 實績 | D15: - | E15: 72.944956 | F15: - | G15: 92.738396 | H15: 90.341887 | I15: 517.17821 | J15: - | K15: - | L15: - | M15: 87.448657 | N15: - | O15: 79.945071
C16: 達成率 | D16: - | E16: =E15/E14 -> 0.88992846 | F16: - | G16: =G15/G14 -> 0.90476483 | H16: =H15/H14 -> 0.89183658 | I16: =I15/I14 -> 0.90297375 | J16: - | K16: - | L16: - | M16: =M15/M14 -> 0.88956392 | N16: - | O16: =O15/O14 -> 0.88938891
B17: 作業 時間 | C17: 開始 | D17: - | E17: 0.29166667 | F17: - | G17: 0.29178241 | H17: 0.20833333 | I17: 0.4265625 | J17: - | K17: - | L17: - | M17: 0.70833333 | N17: - | O17: 0.70833333
C18: 結束 | D18: - | E18: 0.6049537 | F18: - | G18: 0.61142361 | H18: 0.56875 | I18: 0.45 | J18: - | K18: - | L18: - | M18: 0.83055556 | N18: - | O18: 0.83194444
B19: 產線異常 (5分鐘以上) | C19: 次數
C20: 時間/分
B21: 短暫停線 (5分鐘以下) | C21: 次數 | E21: 9 | G21: 9 | H21: 12 | I21: 2 | M21: 3 | O21: 4
C22: 設備次數
B23: 配置人數 | D23: - | E23: 24.4 | F23: - | G23: 22.285714 | H23: 19.25 | I23: 6 | J23: - | K23: - | L23: - | M23: 19.666667 | N23: - | O23: 22.25
B24: 主要應用設備 | D24: L型封口機 | E24: ET-55 | F24: ET-55 | G24: ET-55 | H24: ET-600 | I24: 伺服包裝機 | J24: 伺服包裝機 | K24: 伺服包裝機 | L24: L型封口機 | M24: ET-55 | N24: ET-55 | O24: ET-55
B25: 次要應用設備 | D25: 伺服包裝機 | H25: 伺服包裝機
B26: 備註 | H26: 涼麵+烤飯糰 | I26: 大口飯糰線 | K26: 烤飯糰+手卷
B29: 溫層 | D29: ➃18度C-各編組展開 (一配) | P29: ⑤18度C-各編組展開 (二配)
B30: 編組 | D30: 1 | E30: 2 | F30: 3 | G30: 4 | H30: 5 | I30: 6 | J30: 7 | K30: 8 | L30: 9 | M30: 10 | N30: 11 | O30: 12 | P30: 1 | Q30: 2 | R30: 3 | S30: 4 | T30: 5 | U30: 6 | V30: 7 | W30: 8 | X30: 9
D31: 便當一線 | E31: 涼麵一線 | F31: 涼麵三線 | G31: 自動包裝機 | H31: 自動包裝機2 | I31: 自動包裝機3 | J31: 味付飯糰線B | K31: (舊) 3300型飯糰線 | L31: 3000型飯糰線 | M31: (新) 3300型飯糰機 | N31: GKK3600型 飯糰機 | O31: GKK3600型 飯糰機2 | P31: 自動包裝機 | Q31: 自動包裝機2 | R31: 自動包裝機3 | S31: 味付飯糰線B | T31: (舊) 3300型飯糰線 | U31: 3000型飯糰線 | V31: (新) 3300型飯糰機 | W31: GKK3600型 飯糰機 | X31: GKK3600型 飯糰機2
B32: 人時性 | C32: 排關 | D32: - | E32: - | F32: - | G32: 318.86792 | H32: 433.33333 | I32: - | J32: - | K32: 825 | L32: - | M32: 761.53846 | N32: 1133.3333 | O32: 942.85714 | P32: 306.38298 | Q32: - | R32: - | S32: - | T32: 787.5 | U32: - | V32: 761.53846 | W32: 1100 | X32: 880
C33: 實績 | D33: - | E33: - | F33: - | G33: 279.84522 | H33: 386.61582 | I33: - | J33: - | K33: 738.81415 | L33: - | M33: 681.84668 | N33: 994.47645 | O33: 833.83038 | P33: 267.32423 | Q33: - | R33: - | S33: - | T33: 702.77189 | U33: - | V33: 682.32281 | W33: 969.6989 | X33: 778.05408
C34: 達成率 | D34: - | E34: - | F34: - | G34: =G33/G32 -> 0.87762112 | H34: =H33/H32 -> 0.89219035 | I34: - | J34: - | K34: =K33/K32 -> 0.8955323 | L34: - | M34: =M33/M32 -> 0.89535423 | N34: =N33/N32 -> 0.87747922 | O34: =O33/O32 -> 0.88436556 | P34: =P33/P32 -> 0.87251659 | Q34: - | R34: - | S34: - | T34: =T33/T32 -> 0.89240875 | U34: - | V34: =V33/V32 -> 0.89597945 | W34: =W33/W32 -> 0.88154445 | X34: =X33/X32 -> 0.88415237
B35: 作業 時間 | C35: 開始 | D35: - | E35: - | F35: - | G35: 0.33541667 | H35: 0.29186343 | I35: - | J35: - | K35: 0.29199074 | L35: - | M35: 0.29166667 | N35: 0.29166667 | O35: 0.291875 | P35: 0.70833333 | Q35: - | R35: - | S35: - | T35: 0.70833333 | U35: - | V35: 0.70833333 | W35: 0.70851852 | X35: 0.70833333
C36: 結束 | D36: - | E36: - | F36: - | G36: 0.42238426 | H36: 0.31875 | I36: - | J36: - | K36: 0.39236111 | L36: - | M36: 0.3875463 | N36: 0.42916667 | O36: 0.41111111 | P36: 0.78961806 | Q36: - | R36: - | S36: - | T36: 0.861875 | U36: - | V36: 0.8433912 | W36: 1.0190856 | X36: 0.86961806
B37: 配置人數 | D37: - | E37: - | F37: - | G37: 10.6 | H37: 6 | I37: - | J37: - | K37: 4 | L37: - | M37: 4.3333333 | N37: 3 | O37: 3.5 | P37: 11.75 | Q37: - | R37: - | S37: - | T37: 4 | U37: - | V37: 4.3333333 | W37: 3 | X37: 3.75
B38: 主要應用設備 | D38: 伺服包裝機 | E38: ET-55 | F38: ET-600 | G38: 夾心型 | H38: 伺服包裝機 | I38: 伺服包裝機 | J38: 夾心型 | K38: 3300型 | L38: 3300型 | M38: 3300型 | N38: GKK | O38: GKK | P38: 夾心型 | Q38: 伺服包裝機 | R38: 伺服包裝機 | S38: 夾心型 | T38: 3300型 | U38: 3300型 | V38: 3300型 | W38: GKK | X38: GKK
B39: 次要應用設備
B40: 備註

Sheet 0131(18度C)
A1: 大溪廠日報分析 | C1: 總生產量 | D1: =SUM(F5:F191) -> 84115 | E1: 營業額 | F1: =SUM(G5:G191) -> 1651398.7 | G1: 出勤人數 | H1: =L21+L38+L55+L72+L89+L106+L123+L140+L157+L174+L191 -> 58.266667 | I1: 產線配置圖 | L1: 生產實績 | O1: 人時性差異分析 | S1: 日報登錄 | Y1: 分析說明 | AA1: 產能差異分析
A2: 46053 | C2: 人時性 | D2: =AVERAGE(N21,N38,N55,N72,N89,N106,N123,N140,N157,N174,N191) -> 665.0546 | E2: 平均廠價 | F2: =F1/D1 -> 19.63263 | G2: 多次生產數 | H2: =COUNT(H5:H191) -> 1
A3: 線別 | B3: 品類 | C3: 品名 | E3: 廠價 | F3: 生產量 | G3: 營收 | H3: 多次 生產 | I3: 人數 | J3: 產能/時 | K3: 人時性 | L3: 人數 | M3: 產能/時 | N3: 人時性 | O3: 人數 | P3: 人時性 | Q3: 達成率 | R3: 達成率 平均 | S3: 生產時間 | U3: 換線、休息/分 | V3: 稼動時間/分 | W3: 休息時間 | Y3: (屏榮回填) | AA3: 產能/時 | AB3: 達成率 | AC3: 達成率平均
S4: 開始 | T4: 結束 | W4: 開始 | X4: 結束
A5: 自動包裝機 | B5: 18℃-壽司手卷 | C5: 一配明太子玉子脆卷 | E5: 19.7 | F5: 191 | G5: =E5*F5 -> 3762.7 | I5: 6 | J5: 2500 | K5: =J5/I5 -> 416.66667 | L5: 6 | M5: =F5/V5*60 -> 2261.8421 | N5: =M5/L5 -> 376.97368 | O5: =L5-I5 -> 0 | P5: =N5-K5 -> -39.692982 | Q5: =N5/K5 -> 0.90473684 | R5: =Q21 -> 0.87762112 | S5: 0.33541667 | T5: 0.33893519 | V5: 5.0666667 | AA5: =M5-J5 -> -238.15789 | AB5: =M5/J5 -> 0.90473684 | AC5: =AB21 -> 0.87762112
B6: 18℃-飯糰 | C6: 一配兩粒飯糰(鮪魚.焦糖鮭魚) | E6: 28.57 | F6: 1626 | G6: =E6*F6 -> 46454.82 | I6: 12 | J6: 3600 | K6: =J6/I6 -> 300 | L6: 12 | M6: =F6/V6*60 -> 3123.5859 | N6: =M6/L6 -> 260.29883 | O6: =L6-I6 -> 0 | P6: =N6-K6 -> -39.701174 | Q6: =N6/K6 -> 0.86766275 | S6: 0.34236111 | T6: 0.36405093 | U6: 4.9333333 | V6: 31.233333 | AA6: =M6-J6 -> -476.41409 | AB6: =M6/J6 -> 0.86766275
B7: 18℃-壽司手卷 | C7: 一配海饌雙手卷 | E7: 29.85 | F7: 1342 | G7: =E7*F7 -> 40058.7 | I7: 12 | J7: 3600 | K7: =J7/I7 -> 300 | L7: 12 | M7: =F7/V7*60 -> 3137.1429 | N7: =M7/L7 -> 261.42857 | O7: =L7-I7 -> 0 | P7: =N7-K7 -> -38.571429 | Q7: =N7/K7 -> 0.87142857 | S7: 0.36759259 | T7: 0.38541667 | U7: 5.1 | V7: 25.666667 | AA7: =M7-J7 -> -462.85714 | AB7: =M7/J7 -> 0.87142857
B8: 18℃-壽司手卷 | C8: 一配雙饗雙手卷 | E8: 29.52 | F8: 1259 | G8: =E8*F8 -> 37165.68 | I8: 12 | J8: 3600 | K8: =J8/I8 -> 300 | L8: 12 | M8: =F8/V8*60 -> 3136.609 | N8: =M8/L8 -> 261.38408 | O8: =L8-I8 -> 0 | P8: =N8-K8 -> -38.615917 | Q8: =N8/K8 -> 0.87128028 | S8: 0.38888889 | T8: 0.40561343 | U8: 5 | V8: 24.083333 | AA8: =M8-J8 -> -463.391 | AB8: =M8/J8 -> 0.87128028
B9: 18℃-壽司手卷 | C9: 一配長野稻荷壽司 | E9: 25.64 | F9: 1017 | G9: =E9*F9 -> 26075.88 | I9: 11 | J9: 3600 | K9: =J9/I9 -> 327.27273 | L9: 11 | M9: =F9/V9*60 -> 3172.617 | N9: =M9/L9 -> 288.41973 | O9: =L9-I9 -> 0 | P9: =N9-K9 -> -38.853001 | Q9: =N9/K9 -> 0.8812825 | S9: 0.40902778 | T9: 0.42238426 | U9: 4.9166667 | V9: 19.233333 | AA9: =M9-J9 -> -427.38302 | AB9: =M9/J9 -> 0.8812825
B21: 平均 | I21: =AVERAGE(I5:I20) -> 10.6 | J21: =AVERAGE(J5:J20) -> 3380 | K21: =J21/I21 -> 318.86792 | L21: =AVERAGE(L5:L20) -> 10.6 | M21: =AVERAGE(M5:M20) -> 2966.3594 | N21: =M21/L21 -> 279.84522 | O21: =L21-I21 -> 0 | P21: =N21-K21 -> -39.022701 | Q21: =N21/K21 -> 0.87762112 | S21: =S5 -> 0.33541667 | T21: =INDEX(T5:T20,COUNTA(T5:T20)) -> 0.42238426 | AA21: =M21-J21 -> -413.64063 | AB21: =M21/J21 -> 0.87762112
A22: 自動包裝機2 | B22: 18℃-壽司手卷 | C22: 一配雙鬆細卷 | E22: 14.03 | F22: 569 | G22: =E22*F22 -> 7983.07 | I22: 6 | J22: 2600 | K22: =J22/I22 -> 433.33333 | L22: 6 | M22: =F22/V22*60 -> 2319.8188 | N22: =M22/L22 -> 386.63647 | O22: =L22-I22 -> 0 | P22: =N22-K22 -> -46.696867 | Q22: =N22/K22 -> 0.892238 | R22: =Q38 -> 0.89219035 | S22: 0.29186343 | T22: 0.30208333 | V22: 14.716667 | AA22: =M22-J22 -> -280.1812 | AB22: =M22/J22 -> 0.892238 | AC22: =AB38 -> 0.89219035
B23: 18℃-壽司手卷 | C23: 一配經典鮪魚沙拉細卷 | E23: 14.49 | F23: 721 | G23: =E23*F23 -> 10447.29 | I23: 6 | J23: 2600 | K23: =J23/I23 -> 433.33333 | L23: 6 | M23: =F23/V23*60 -> 2319.571 | N23: =M23/L23 -> 386.59517 | O23: =L23-I23 -> 0 | P23: =N23-K23 -> -46.738159 | Q23: =N23/K23 -> 0.89214271 | S23: 0.30579861 | T23: 0.31875 | U23: 5.35 | V23: 18.65 | AA23: =M23-J23 -> -280.42895 | AB23: =M23/J23 -> 0.89214271
B38: 平均 | I38: =AVERAGE(I22:I37) -> 6 | J38: =AVERAGE(J22:J37) -> 2600 | K38: =J38/I38 -> 433.33333 | L38: =AVERAGE(L22:L37) -> 6 | M38: =AVERAGE(M22:M37) -> 2319.6949 | N38: =M38/L38 -> 386.61582 | O38: =L38-I38 -> 0 | P38: =N38-K38 -> -46.717513 | Q38: =N38/K38 -> 0.89219035 | S38: =S22 -> 0.29186343 | T38: =INDEX(T22:T37,COUNTA(T22:T37)) -> 0.31875 | AA38: =M38-J38 -> -280.30508 | AB38: =M38/J38 -> 0.89219035
A39: (舊) 3300型飯糰線 | B39: 18℃-飯糰 | C39: 一配鹽蔥燒肉飯糰 | E39: 17.89 | F39: 2144 | G39: =E39*F39 -> 38356.16 | I39: 4 | J39: 3300 | K39: =J39/I39 -> 825 | L39: 4 | M39: =F39/V39*60 -> 2954.977 | N39: =M39/L39 -> 738.74426 | O39: =L39-I39 -> 0 | P39: =N39-K39 -> -86.255743 | Q39: =N39/K39 -> 0.89544758 | R39: =Q55 -> 0.8955323 | S39: 0.29199074 | T39: 0.32222222 | V39: 43.533333 | AA39: =M39-J39 -> -345.02297 | AB39: =M39/J39 -> 0.89544758 | AC39: =AB55 -> 0.8955323
B40: 18℃-飯糰 | C40: 一配照燒雞肉飯糰 | E40: 21.45 | F40: 1076 | G40: =E40*F40 -> 23080.2 | I40: 4 | J40: 3300 | K40: =J40/I40 -> 825 | L40: 4 | M40: =F40/V40*60 -> 2956.9466 | N40: =M40/L40 -> 739.23664 | O40: =L40-I40 -> 0 | P40: =N40-K40 -> -85.763359 | Q40: =N40/K40 -> 0.89604441 | S40: 0.32581019 | T40: 0.34097222 | U40: 5.1666667 | V40: 21.833333 | AA40: =M40-J40 -> -343.05344 | AB40: =M40/J40 -> 0.89604441
B41: 18℃-飯糰 | C41: 一配雞肉飯飯糰 | E41: 16.66 | F41: 3392 | G41: =E41*F41 -> 56510.72 | I41: 4 | J41: 3300 | K41: =J41/I41 -> 825 | L41: 4 | M41: =F41/V41*60 -> 2953.8462 | N41: =M41/L41 -> 738.46154 | O41: =L41-I41 -> 0 | P41: =N41-K41 -> -86.538462 | Q41: =N41/K41 -> 0.8951049 | S41: 0.34451389 | T41: 0.39236111 | U41: 5.1 | V41: 68.9 | AA41: =M41-J41 -> -346.15385 | AB41: =M41/J41 -> 0.8951049
B55: 平均 | I55: =AVERAGE(I39:I54) -> 4 | J55: =AVERAGE(J39:J54) -> 3300 | K55: =J55/I55 -> 825 | L55: =AVERAGE(L39:L54) -> 4 | M55: =AVERAGE(M39:M54) -> 2955.2566 | N55: =M55/L55 -> 738.81415 | O55: =L55-I55 -> 0 | P55: =N55-K55 -> -86.185854 | Q55: =N55/K55 -> 0.8955323 | S55: =S39 -> 0.29199074 | T55: =INDEX(T39:T54,COUNTA(T39:T54)) -> 0.39236111 | AA55: =M55-J55 -> -344.74342 | AB55: =M55/J55 -> 0.8955323
A56: (新) 3300型飯糰機 | B56: 18℃-飯糰 | C56: 一配壹號醬炙烤牛飯糰 | E56: 22.28 | F56: 844 | G56: =E56*F56 -> 18804.32 | I56: 5 | J56: 3300 | K56: =J56/I56 -> 660 | L56: 5 | M56: =F56/V56*60 -> 2955.642 | N56: =M56/L56 -> 591.1284 | O56: =L56-I56 -> 0 | P56: =N56-K56 -> -68.871595 | Q56: =N56/K56 -> 0.8956491 | R56: =Q72 -> 0.89535423 | S56: 0.29166667 | T56: 0.30356481 | V56: 17.133333 | AA56: =M56-J56 -> -344.35798 | AB56: =M56/J56 -> 0.8956491 | AC56: =AB72 -> 0.89535423
B57: 18℃-飯糰 | C57: 一配紅運烏魚子紹興飯糰 | E57: 27.27 | F57: 2680 | G57: =E57*F57 -> 73083.6 | I57: 5 | J57: 3300 | K57: =J57/I57 -> 660 | L57: 5 | M57: =F57/V57*60 -> 2954.977 | N57: =M57/L57 -> 590.99541 | O57: =L57-I57 -> 0 | P57: =N57-K57 -> -69.004594 | Q57: =N57/K57 -> 0.89544758 | S57: 0.30694444 | T57: 0.3447338 | U57: 4.8666667 | V57: 54.416667 | AA57: =M57-J57 -> -345.02297 | AB57: =M57/J57 -> 0.89544758
B58: 18℃-飯糰 | C58: 一配鮭魚奶油醬油飯糰 | E58: 18.53 | F58: 2809 | G58: =E58*F58 -> 52050.77 | I58: 3 | J58: 3300 | K58: =J58/I58 -> 1100 | L58: 3 | M58: =F58/V58*60 -> 2953.3879 | N58: =M58/L58 -> 984.46262 | O58: =L58-I58 -> 0 | P58: =N58-K58 -> -115.53738 | Q58: =N58/K58 -> 0.89496602 | S58: 0.34791667 | T58: 0.3875463 | U58: 4.5833333 | V58: 57.066667 | AA58: =M58-J58 -> -346.61215 | AB58: =M58/J58 -> 0.89496602
B72: 平均 | I72: =AVERAGE(I56:I71) -> 4.3333333 | J72: =AVERAGE(J56:J71) -> 3300 | K72: =J72/I72 -> 761.53846 | L72: =AVERAGE(L56:L71) -> 4.3333333 | M72: =AVERAGE(M56:M71) -> 2954.669 | N72: =M72/L72 -> 681.84668 | O72: =L72-I72 -> 0 | P72: =N72-K72 -> -79.691777 | Q72: =N72/K72 -> 0.89535423 | S72: =S56 -> 0.29166667 | T72: =INDEX(T56:T71,COUNTA(T56:T71)) -> 0.3875463 | AA72: =M72-J72 -> -345.33103 | AB72: =M72/J72 -> 0.89535423
A73: GKK3600型 飯糰機 | B73: 18℃-飯糰 | C73: 一配蔬食鮪魚飯糰 | E73: 18.18 | F73: 799 | G73: =E73*F73 -> 14525.82 | I73: 3 | J73: 3600 | K73: =J73/I73 -> 1200 | L73: 3 | M73: =F73/V73*60 -> 3133.3333 | N73: =M73/L73 -> 1044.4444 | O73: =L73-I73 -> 0 | P73: =N73-K73 -> -155.55556 | Q73: =N73/K73 -> 0.87037037 | R73: =Q89 -> 0.87747922 | S73: 0.29166667 | T73: 0.30229167 | V73: 15.3 | AA73: =M73-J73 -> -466.66667 | AB73: =M73/J73 -> 0.87037037 | AC73: =AB89 -> 0.87747922
B74: 18℃-飯糰 | C74: 一配經典肉鬆飯糰 | E74: 14.03 | F74: 3317 | G74: =E74*F74 -> 46537.51 | I74: 3 | J74: 3000 | K74: =J74/I74 -> 1000 | L74: 3 | M74: =F74/V74*60 -> 2689.4595 | N74: =M74/L74 -> 896.48649 | O74: =L74-I74 -> 0 | P74: =N74-K74 -> -103.51351 | Q74: =N74/K74 -> 0.89648649 | S74: 0.3125 | T74: 0.36388889 | U74: 14.7 | V74: 74 | AA74: =M74-J74 -> -310.54054 | AB74: =M74/J74 -> 0.89648649
B75: 18℃-飯糰 | C75: 一配鮪魚飯糰 | E75: 14.28 | F75: 4117 | G75: =E75*F75 -> 58790.76 | I75: 3 | J75: 3600 | K75: =J75/I75 -> 1200 | L75: 3 | M75: =F75/V75*60 -> 3127.4953 | N75: =M75/L75 -> 1042.4984 | O75: =L75-I75 -> 0 | P75: =N75-K75 -> -157.50158 | Q75: =N75/K75 -> 0.86874868 | S75: 0.37431713 | T75: 0.42916667 | U75: 15.016667 | V75: 78.983333 | AA75: =M75-J75 -> -472.50475 | AB75: =M75/J75 -> 0.86874868
B89: 平均 | I89: =AVERAGE(I73:I88) -> 3 | J89: =AVERAGE(J73:J88) -> 3400 | K89: =J89/I89 -> 1133.3333 | L89: =AVERAGE(L73:L88) -> 3 | M89: =AVERAGE(M73:M88) -> 2983.4293 | N89: =M89/L89 -> 994.47645 | O89: =L89-I89 -> 0 | P89: =N89-K89 -> -138.85688 | Q89: =N89/K89 -> 0.87747922 | S89: =S73 -> 0.29166667 | T89: =INDEX(T73:T88,COUNTA(T73:T88)) -> 0.42916667 | AA89: =M89-J89 -> -416.57065 | AB89: =M89/J89 -> 0.87747922
A90: GKK3600型 飯糰機2 | B90: 18℃-飯糰 | C90: 一配熟成紅鮭飯糰 | E90: 25.03 | F90: 1059 | G90: =E90*F90 -> 26506.77 | I90: 4 | J90: 3300 | K90: =J90/I90 -> 825 | L90: 4 | M90: =F90/V90*60 -> 2928.1106 | N90: =M90/L90 -> 732.02765 | O90: =L90-I90 -> 0 | P90: =N90-K90 -> -92.97235 | Q90: =N90/K90 -> 0.88730624 | R90: =Q106 -> 0.88436556 | S90: 0.291875 | T90: 0.30694444 | V90: 21.7 | AA90: =M90-J90 -> -371.8894 | AB90: =M90/J90 -> 0.88730624 | AC90: =AB106 -> 0.88436556
B91: 18℃-飯糰 | C91: 一配北海道秋鮭親子飯糰 | E91: 24.82 | F91: 1319 | G91: =E91*F91 -> 32737.58 | I91: 4 | J91: 3300 | K91: =J91/I91 -> 825 | L91: 4 | M91: =F91/V91*60 -> 2927.4969 | N91: =M91/L91 -> 731.87423 | O91: =L91-I91 -> 0 | P91: =N91-K91 -> -93.125771 | Q91: =N91/K91 -> 0.88712028 | S91: 0.31736111 | T91: 0.33613426 | U91: 15 | V91: 27.033333 | AA91: =M91-J91 -> -372.50308 | AB91: =M91/J91 -> 0.88712028
B92: 18℃-飯糰 | C92: 一配贅沢鮭魚肚飯糰 | E92: 30 | F92: 2074 | G92: =E92*F92 -> 62220 | I92: 3 | J92: 3000 | K92: =J92/I92 -> 1000 | L92: 3 | M92: =F92/V92*60 -> 2689.6254 | N92: =M92/L92 -> 896.54179 | O92: =L92-I92 -> 0 | P92: =N92-K92 -> -103.45821 | Q92: =N92/K92 -> 0.89654179 | S92: 0.34652778 | T92: 0.37865741 | U92: 14.966667 | V92: 46.266667 | AA92: =M92-J92 -> -310.37464 | AB92: =M92/J92 -> 0.89654179
B93: 18℃-飯糰 | C93: 一配明太子龍蝦風味沙拉飯糰 | E93: 18.18 | F93: 1665 | G93: =E93*F93 -> 30269.7 | I93: 3 | J93: 3600 | K93: =J93/I93 -> 1200 | L93: 3 | M93: =F93/V93*60 -> 3128.3925 | N93: =M93/L93 -> 1042.7975 | O93: =L93-I93 -> 0 | P93: =N93-K93 -> -157.20251 | Q93: =N93/K93 -> 0.86899791 | S93: 0.38893519 | T93: 0.41111111 | U93: 14.8 | V93: 31.933333 | AA93: =M93-J93 -> -471.60752 | AB93: =M93/J93 -> 0.86899791
B106: 平均 | I106: =AVERAGE(I90:I105) -> 3.5 | J106: =AVERAGE(J90:J105) -> 3300 | K106: =J106/I106 -> 942.85714 | L106: =AVERAGE(L90:L105) -> 3.5 | M106: =AVERAGE(M90:M105) -> 2918.4063 | N106: =M106/L106 -> 833.83038 | O106: =L106-I106 -> 0 | P106: =N106-K106 -> -109.02676 | Q106: =N106/K106 -> 0.88436556 | S106: =S90 -> 0.291875 | T106: =INDEX(T90:T105,COUNTA(T90:T105)) -> 0.41111111 | AA106: =M106-J106 -> -381.59366 | AB106: =M106/J106 -> 0.88436556
A107: 自動包裝機 (二配) | B107: 18℃-壽司手卷 | C107: 二配長野稻荷壽司 | E107: 25.64 | F107: 1130 | G107: =E107*F107 -> 28973.2 | I107: 11 | J107: 3600 | K107: =J107/I107 -> 327.27273 | L107: 11 | M107: =F107/V107*60 -> 3170.6937 | N107: =M107/L107 -> 288.24488 | O107: =L107-I107 -> 0 | P107: =N107-K107 -> -39.027847 | Q107: =N107/K107 -> 0.88074825 | R107: =Q123 -> 0.87251659 | S107: 0.70833333 | T107: 0.72318287 | V107: 21.383333 | AA107: =M107-J107 -> -429.30631 | AB107: =M107/J107 -> 0.88074825 | AC107: =AB123 -> 0.87251659
B108: 18℃-壽司手卷 | C108: 二配雙饗雙手卷 | E108: 29.52 | F108: 1368 | G108: =E108*F108 -> 40383.36 | I108: 12 | J108: 3600 | K108: =J108/I108 -> 300 | L108: 12 | M108: =F108/V108*60 -> 3134.8186 | N108: =M108/L108 -> 261.23488 | O108: =L108-I108 -> 0 | P108: =N108-K108 -> -38.765118 | Q108: =N108/K108 -> 0.87078294 | S108: 0.72638889 | T108: 0.74457176 | U108: 4.6166667 | V108: 26.183333 | AA108: =M108-J108 -> -465.18141 | AB108: =M108/J108 -> 0.87078294
B109: 18℃-壽司手卷 | C109: 二配海饌雙手卷 | E109: 29.85 | F109: 1472 | G109: =E109*F109 -> 43939.2 | I109: 12 | J109: 3600 | K109: =J109/I109 -> 300 | L109: 12 | M109: =F109/V109*60 -> 3135.6213 | N109: =M109/L109 -> 261.30178 | O109: =L109-I109 -> 0 | P109: =N109-K109 -> -38.698225 | Q109: =N109/K109 -> 0.87100592 | S109: 0.74791667 | T109: 0.76747685 | U109: 4.8166667 | V109: 28.166667 | AA109: =M109-J109 -> -464.3787 | AB109: =M109/J109 -> 0.87100592
B110: 18℃-飯糰 | C110: 二配兩粒飯糰(鮪魚.焦糖鮭魚) | E110: 28.57 | F110: 1408 | G110: =E110*F110 -> 40226.56 | I110: 12 | J110: 3600 | K110: =J110/I110 -> 300 | L110: 12 | M110: =F110/V110*60 -> 3123.1054 | N110: =M110/L110 -> 260.25878 | O110: =L110-I110 -> 0 | P110: =N110-K110 -> -39.74122 | Q110: =N110/K110 -> 0.86752927 | S110: 0.77083333 | T110: 0.78961806 | U110: 4.8333333 | V110: 27.05 | AA110: =M110-J110 -> -476.89464 | AB110: =M110/J110 -> 0.86752927
B123: 平均 | I123: =AVERAGE(I107:I122) -> 11.75 | J123: =AVERAGE(J107:J122) -> 3600 | K123: =J123/I123 -> 306.38298 | L123: =AVERAGE(L107:L122) -> 11.75 | M123: =AVERAGE(M107:M122) -> 3141.0597 | N123: =M123/L123 -> 267.32423 | O123: =L123-I123 -> 0 | P123: =N123-K123 -> -39.058746 | Q123: =N123/K123 -> 0.87251659 | S123: =S107 -> 0.70833333 | T123: =INDEX(T107:T122,COUNTA(T107:T122)) -> 0.78961806 | AA123: =M123-J123 -> -458.94027 | AB123: =M123/J123 -> 0.87251659
A124: (舊) 3300型飯糰線 (二配) | B124: 18℃-飯糰 | C124: 二配大飯糰滷肉飯加蛋 | E124: 22.48 | F124: 1738 | G124: =E124*F124 -> 39070.24 | I124: 5 | J124: 3000 | K124: =J124/I124 -> 600 | L124: 5 | M124: =F124/V124*60 -> 2663.6015 | N124: =M124/L124 -> 532.72031 | O124: =L124-I124 -> 0 | P124: =N124-K124 -> -67.279693 | Q124: =N124/K124 -> 0.88786718 | R124: =Q140 -> 0.89240875 | S124: 0.70833333 | T124: 0.73552083 | V124: 39.15 | AA124: =M124-J124 -> -336.39847 | AB124: =M124/J124 -> 0.88786718 | AC124: =AB140 -> 0.89240875
B125: 18℃-飯糰 | C125: 二配大飯糰韓式蒜烤豬五花 | E125: 24.54 | F125: 2054 | G125: =E125*F125 -> 50405.16 | I125: 4 | J125: 3000 | K125: =J125/I125 -> 750 | L125: 4 | M125: =F125/V125*60 -> 2664.6486 | N125: =M125/L125 -> 666.16216 | O125: =L125-I125 -> 0 | P125: =N125-K125 -> -83.837838 | Q125: =N125/K125 -> 0.88821622 | S125: 0.73888889 | T125: 0.77100694 | U125: 4.85 | V125: 46.25 | AA125: =M125-J125 -> -335.35135 | AB125: =M125/J125 -> 0.88821622
B126: 18℃-飯糰 | C126: 二配三杯醬爆菇菇飯糰 | E126: 16.7 | F126: 1312 | G126: =E126*F126 -> 21910.4 | I126: 3 | J126: 3300 | K126: =J126/I126 -> 1100 | L126: 3 | M126: =F126/V126*60 -> 2957.5454 | N126: =M126/L126 -> 985.84847 | O126: =L126-I126 -> 0 | P126: =N126-K126 -> -114.15153 | Q126: =N126/K126 -> 0.89622588 | S126: 0.77457176 | T126: 0.79305556 | U126: 5.1333333 | V126: 26.616667 | AA126: =M126-J126 -> -342.4546 | AB126: =M126/J126 -> 0.89622588
B127: 18℃-飯糰 | C127: 二配鹽蔥燒肉飯糰 | E127: 17.89 | F127: 4640 | G127: =E127*F127 -> 83009.6 | I127: 4 | J127: 3300 | K127: =J127/I127 -> 825 | L127: 4 | M127: =F127/V127*60 -> 2958.5547 | N127: =M127/L127 -> 739.63868 | O127: =L127-I127 -> 0 | P127: =N127-K127 -> -85.361318 | Q127: =N127/K127 -> 0.89653174 | S127: 0.79652778 | T127: 0.861875 | U127: 5 | V127: 94.1 | AA127: =M127-J127 -> -341.44527 | AB127: =M127/J127 -> 0.89653174
B140: 平均 | I140: =AVERAGE(I124:I139) -> 4 | J140: =AVERAGE(J124:J139) -> 3150 | K140: =J140/I140 -> 787.5 | L140: =AVERAGE(L124:L139) -> 4 | M140: =AVERAGE(M124:M139) -> 2811.0876 | N140: =M140/L140 -> 702.77189 | O140: =L140-I140 -> 0 | P140: =N140-K140 -> -84.728106 | Q140: =N140/K140 -> 0.89240875 | S140: =S124 -> 0.70833333 | T140: =INDEX(T124:T139,COUNTA(T124:T139)) -> 0.861875 | AA140: =M140-J140 -> -338.91242 | AB140: =M140/J140 -> 0.89240875
...

Sheet 0131(4度C)
A1: 大溪廠日報分析 | C1: 總生產量 | D1: =SUM(F5:F106) -> 44938 | E1: 營業額 | F1: =SUM(G5:G106) -> 2356369.7 | G1: 出勤人數 | H1: =L21+L38+L55+L72+L89+L106 -> 113.85238 | I1: 產線配置圖 | L1: 生產實績 | O1: 人時性差異分析 | S1: 日報登錄 | Y1: 合計次數 | Z1: 合計(時間/分) | AA1: 產線異常 分析說明(5分鐘以上) | AC1: 合計次數 | AD1: 合計(時間/分) | AE1: 產能差異分析
A2: 46053 | C2: 人時性 | D2: =AVERAGE(N21,N38,N55,N72,N89,N106) -> 156.7662 | E2: 平均廠價 | F2: =F1/D1 -> 52.436016 | G2: 多次生產數 | H2: =COUNT(H5:H106) -> 0 | Y2: =SUM(Y21,Y38,Y55,Y72,Y89,Y106) -> 0 | Z2: =SUM(Z21,Z38,Z55,Z72,Z89,Z106) -> 0 | AC2: =SUM(AC21,AC38,AC55,AC72,AC89,AC106) -> 39 | AD2: =SUM(AD21,AD38,AD55,AD72,AD89,AD106) -> 0
A3: 線別 | B3: 品類 | C3: 品名 | E3: 廠價 | F3: 生產量 | G3: 營收 | H3: 多次 生產 | I3: 人數 | J3: 產能/時 | K3: 人時性 | L3: 人數 | M3: 產能/時 | N3: 人時性 | O3: 人數 | P3: 人時性 | Q3: 達成率 | R3: 達成率 平均 | S3: 生產時間 | U3: 換線、休息/分 | V3: 稼動時間/分 | W3: 休息時間 | Y3: 產線異常統計(5分鐘以上) | AA3: (屏榮回填) | AC3: 短暫停線統計(5分鐘以下) | AE3: 產能/時 | AF3: 達成率 | AG3: 達成率平均
S4: 開始 | T4: 結束 | W4: 開始 | X4: 結束 | Y4: 次數 | Z4: 時間/分 | AC4: 總次數 | AD4: 設備因素(次數)
A5: 便當二線 | B5: 便當 | C5: 福氣魚四喜開運便當 | E5: 65.4 | F5: 685 | G5: =E5*F5 -> 44799 | I5: 24 | J5: 2000 | K5: =J5/I5 -> 83.333333 | L5: 24 | M5: =F5/V5*60 -> 1780.5054 | N5: =M5/L5 -> 74.187726 | O5: =L5-I5 -> 0 | P5: =N5-K5 -> -9.1456077 | Q5: =N5/K5 -> 0.89025271 | R5: =Q21 -> 0.88992846 | S5: 0.29166667 | T5: 0.30769676 | V5: 23.083333 | AC5: 1 | AE5: =M5-J5 -> -219.49458 | AF5: =M5/J5 -> 0.89025271 | AG5: =AF21 -> 0.88992846
B6: 微波主食 | C6: 糖燻野郎三十天熟成牛飯 | E6: 56.77 | F6: 3413 | G6: =E6*F6 -> 193756.01 | I6: 25 | J6: 2000 | K6: =J6/I6 -> 80 | L6: 25 | M6: =F6/V6*60 -> 1777.8614 | N6: =M6/L6 -> 71.114455 | O6: =L6-I6 -> 0 | P6: =N6-K6 -> -8.8855448 | Q6: =N6/K6 -> 0.88893069 | S6: 0.31111111 | T6: 0.39109954 | U6: 4.9166667 | V6: 115.18333 | AC6: 3 | AE6: =M6-J6 -> -222.13862 | AF6: =M6/J6 -> 0.88893069
B7: 便當 | C7: 嫩烤香料雞胸排蔬滿盒 | E7: 77.34 | F7: 1591 | G7: =E7*F7 -> 123047.94 | I7: 25 | J7: 2000 | K7: =J7/I7 -> 80 | L7: 25 | M7: =F7/V7*60 -> 1779.8633 | N7: =M7/L7 -> 71.194531 | O7: =L7-I7 -> 0 | P7: =N7-K7 -> -8.8054692 | Q7: =N7/K7 -> 0.88993163 | S7: 0.39469907 | T7: 0.43194444 | U7: 5.1833333 | V7: 53.633333 | AC7: 1 | AE7: =M7-J7 -> -220.13673 | AF7: =M7/J7 -> 0.88993163
B8: 便當 | C8: 海陸雙拼肉肉餐盒 | E8: 59.54 | F8: 2195 | G8: =E8*F8 -> 130690.3 | I8: 23 | J8: 2000 | K8: =J8/I8 -> 86.956522 | L8: 23 | M8: =F8/V8*60 -> 1778.9284 | N8: =M8/L8 -> 77.344714 | O8: =L8-I8 -> 0 | P8: =N8-K8 -> -9.6118082 | Q8: =N8/K8 -> 0.88946421 | S8: 0.43541667 | T8: 0.4868287 | U8: 5 | V8: 74.033333 | W8: 0.4868287 | X8: 0.52569444 | AC8: 1 | AE8: =M8-J8 -> -221.07159 | AF8: =M8/J8 -> 0.88946421
B9: 便當 | C9: 健身G肉餐盒 | E9: 59.52 | F9: 3390 | G9: =E9*F9 -> 201772.8 | I9: 25 | J9: 2000 | K9: =J9/I9 -> 80 | L9: 25 | M9: =F9/V9*60 -> 1782.1262 | N9: =M9/L9 -> 71.285047 | O9: =L9-I9 -> 0 | P9: =N9-K9 -> -8.7149533 | Q9: =N9/K9 -> 0.89106308 | S9: 0.52569444 | T9: 0.6049537 | U9: 55.966667 | V9: 114.13333 | AC9: 3 | AE9: =M9-J9 -> -217.87383 | AF9: =M9/J9 -> 0.89106308
B21: 平均 | I21: =AVERAGE(I5:I20) -> 24.4 | J21: =AVERAGE(J5:J20) -> 2000 | K21: =J21/I21 -> 81.967213 | L21: =AVERAGE(L5:L20) -> 24.4 | M21: =AVERAGE(M5:M20) -> 1779.8569 | N21: =M21/L21 -> 72.944956 | O21: =L21-I21 -> 0 | P21: =N21-K21 -> -9.022257 | Q21: =N21/K21 -> 0.88992846 | S21: =S5 -> 0.29166667 | T21: =INDEX(T5:T20,COUNTA(T5:T20)) -> 0.6049537 | Y21: =SUM(Y5:Y20) -> 0 | Z21: =SUM(Z5:Z20) -> 0 | AC21: =SUM(AC5:AC20) -> 9 | AD21: =SUM(AD5:AD20) -> 0 | AE21: =M21-J21 -> -220.14307 | AF21: =M21/J21 -> 0.88992846
A22: 涼麵二線 | B22: 便當 | C22: 香腸腿排雙拼便當 | E22: 53.76 | F22: 2514 | G22: =E22*F22 -> 135152.64 | I22: 20 | J22: 2000 | K22: =J22/I22 -> 100 | L22: 20 | M22: =F22/V22*60 -> 1778.0747 | N22: =M22/L22 -> 88.903733 | O22: =L22-I22 -> 0 | P22: =N22-K22 -> -11.096267 | Q22: =N22/K22 -> 0.88903733 | R22: =Q38 -> 0.90476483 | S22: 0.29178241 | T22: 0.35069444 | V22: 84.833333 | AC22: 2 | AE22: =M22-J22 -> -221.92534 | AF22: =M22/J22 -> 0.88903733 | AG22: =AF38 -> 0.92857444
B23: 便當 | C23: 經典滷肉飯 | E23: 47.37 | F23: 1825 | G23: =E23*F23 -> 86450.25 | I23: 21 | J23: 2000 | K23: =J23/I23 -> 95.238095 | L23: 21 | M23: =F23/V23*60 -> 1778.5598 | N23: =M23/L23 -> 84.693325 | O23: =L23-I23 -> 0 | P23: =N23-K23 -> -10.54477 | Q23: =N23/K23 -> 0.88927991 | S23: 0.35446759 | T23: 0.39722222 | U23: 5.4333333 | V23: 61.566667 | AC23: 1 | AE23: =M23-J23 -> -221.44017 | AF23: =M23/J23 -> 0.88927991
B24: 便當 | C24: 蔬活腿排補力餐盒 | E24: 71.55 | F24: 1603 | G24: =E24*F24 -> 114694.65 | I24: 22 | J24: 2000 | K24: =J24/I24 -> 90.909091 | L24: 22 | M24: =F24/V24*60 -> 1777.2713 | N24: =M24/L24 -> 80.78506 | O24: =L24-I24 -> 0 | P24: =N24-K24 -> -10.124031 | Q24: =N24/K24 -> 0.88863566 | S24: 0.40069444 | T24: 0.43827546 | U24: 5 | V24: 54.116667 | AC24: 1 | AE24: =M24-J24 -> -222.72867 | AF24: =M24/J24 -> 0.88863566
B25: 便當 | C25: 美式雞丁餐盒 | E25: 59.34 | F25: 1118 | G25: =E25*F25 -> 66342.12 | I25: 24 | J25: 2000 | K25: =J25/I25 -> 83.333333 | L25: 24 | M25: =F25/V25*60 -> 1779.3103 | N25: =M25/L25 -> 74.137931 | O25: =L25-I25 -> 0 | P25: =N25-K25 -> -9.1954023 | Q25: =N25/K25 -> 0.88965517 | S25: 0.441875 | T25: 0.46805556 | U25: 5.1833333 | V25: 37.7 | AC25: 1 | AE25: =M25-J25 -> -220.68966 | AF25: =M25/J25 -> 0.88965517
B26: 4℃-飯糰 | C26: 韓素燒若飯糰 | E26: 24.07 | F26: 432 | G26: =E26*F26 -> 10398.24 | I26: 21 | J26: 2790 | K26: =J26/I26 -> 132.85714 | L26: 23 | M26: =F26/V26*60 -> 2787.0968 | N26: =M26/L26 -> 121.17812 | O26: =L26-I26 -> 2 | P26: =N26-K26 -> -11.679022 | Q26: =N26/K26 -> 0.91209338 | S26: 0.47222222 | T26: 0.47868056 | U26: 6 | V26: 9.3 | W26: 0.47868056 | X26: 0.51666667 | AC26: 1 | AE26: =M26-J26 -> -2.9032258 | AF26: =M26/J26 -> 0.99895942
B27: 4℃-飯糰 | C27: 麻油雞飯糰 | E27: 29.97 | F27: 2190 | G27: =E27*F27 -> 65634.3 | I27: 21 | J27: 2790 | K27: =J27/I27 -> 132.85714 | L27: 23 | M27: =F27/V27*60 -> 2787.8359 | N27: =M27/L27 -> 121.21026 | O27: =L27-I27 -> 2 | P27: =N27-K27 -> -11.646885 | Q27: =N27/K27 -> 0.91233527 | S27: 0.51666667 | T27: 0.54939815 | U27: 54.7 | V27: 47.133333 | AC27: 1 | AE27: =M27-J27 -> -2.1640736 | AF27: =M27/J27 -> 0.99922435
B28: 便當 | C28: 烤蛋白餐盒 | E28: 58.67 | F28: 2504 | G28: =E28*F28 -> 146909.68 | I28: 23 | J28: 2000 | K28: =J28/I28 -> 86.956522 | L28: 23 | M28: =F28/V28*60 -> 1779.0409 | N28: =M28/L28 -> 77.349602 | O28: =L28-I28 -> 0 | P28: =N28-K28 -> -9.6069195 | Q28: =N28/K28 -> 0.88952043 | S28: 0.55277778 | T28: 0.61142361 | U28: 4.8666667 | V28: 84.45 | AC28: 2 | AE28: =M28-J28 -> -220.95915 | AF28: =M28/J28 -> 0.88952043
B38: 平均 | I38: =AVERAGE(I22:I37) -> 21.714286 | J38: =AVERAGE(J22:J37) -> 2225.7143 | K38: =J38/I38 -> 102.5 | L38: =AVERAGE(L22:L37) -> 22.285714 | M38: =AVERAGE(M22:M37) -> 2066.7414 | N38: =M38/L38 -> 92.738396 | O38: =L38-I38 -> 0.57142857 | P38: =N38-K38 -> -9.7616044 | Q38: =N38/K38 -> 0.90476483 | S38: =S22 -> 0.29178241 | T38: =INDEX(T22:T37,COUNTA(T22:T37)) -> 0.61142361 | Y38: =SUM(Y22:Y37) -> 0 | Z38: =SUM(Z22:Z37) -> 0 | AC38: =SUM(AC22:AC37) -> 9 | AD38: =SUM(AD22:AD37) -> 0 | AE38: =M38-J38 -> -158.9729 | AF38: =M38/J38 -> 0.92857444
A39: 涼麵三線 | B39: 微波小吃 | C39: 日式茶碗蒸 | E39: 19.7 | F39: 3240 | G39: =E39*F39 -> 63828 | I39: 13 | J39: 1200 | K39: =J39/I39 -> 92.307692 | L39: 13 | M39: =F39/V39*60 -> 1078.3027 | N39: =M39/L39 -> 82.946359 | O39: =L39-I39 -> 0 | P39: =N39-K39 -> -9.3613329 | Q39: =N39/K39 -> 0.89858556 | R39: =Q55 -> 0.89183658 | S39: 0.20833333 | T39: 0.33353009 | V39: 180.28333 | AC39: 5 | AE39: =M39-J39 -> -121.69733 | AF39: =M39/J39 -> 0.89858556 | AG39: =AF55 -> 0.89183658
B40: 季節調理麵 | C40: 醬油叉燒拉麵 | E40: 72.4 | F40: 542 | G40: =E40*F40 -> 39240.8 | I40: 18 | J40: 1800 | K40: =J40/I40 -> 100 | L40: 18 | M40: =F40/V40*60 -> 1605.9259 | N40: =M40/L40 -> 89.218107 | O40: =L40-I40 -> 0 | P40: =N40-K40 -> -10.781893 | Q40: =N40/K40 -> 0.89218107 | S40: 0.33680556 | T40: 0.35086806 | U40: 4.7166667 | V40: 20.25 | AC40: 1 | AE40: =M40-J40 -> -194.07407 | AF40: =M40/J40 -> 0.89218107
B41: 季節調理麵 | C41: 東京豚骨風味拉麵 | E41: 71.84 | F41: 990 | G41: =E41*F41 -> 71121.6 | I41: 19 | J41: 1800 | K41: =J41/I41 -> 94.736842 | L41: 19 | M41: =F41/V41*60 -> 1606.1289 | N41: =M41/L41 -> 84.533099 | O41: =L41-I41 -> 0 | P41: =N41-K41 -> -10.203743 | Q41: =N41/K41 -> 0.89229383 | S41: 0.35417824 | T41: 0.37986111 | U41: 4.7666667 | V41: 36.983333 | AC41: 1 | AE41: =M41-J41 -> -193.87111 | AF41: =M41/J41 -> 0.89229383
B42: 熱食義麵 | C42: 焗烤蕃茄起司四方麵 | E42: 57.3 | F42: 1519 | G42: =E42*F42 -> 87038.7 | I42: 22 | J42: 1800 | K42: =J42/I42 -> 81.818182 | L42: 22 | M42: =F42/V42*60 -> 1604.1068 | N42: =M42/L42 -> 72.913944 | O42: =L42-I42 -> 0 | P42: =N42-K42 -> -8.9042374 | Q42: =N42/K42 -> 0.89117043 | S42: 0.38346065 | T42: 0.42291667 | U42: 5.1833333 | V42: 56.816667 | AC42: 1 | AE42: =M42-J42 -> -195.89322 | AF42: =M42/J42 -> 0.89117043
B43: 微波小吃 | C43: 日式壽喜燒 | E43: 57.73 | F43: 963 | G43: =E43*F43 -> 55593.99 | I43: 22 | J43: 1800 | K43: =J43/I43 -> 81.818182 | L43: 22 | M43: =F43/V43*60 -> 1605 | N43: =M43/L43 -> 72.954545 | O43: =L43-I43 -> 0 | P43: =N43-K43 -> -8.8636364 | Q43: =N43/K43 -> 0.89166667 | S43: 0.42638889 | T43: 0.45138889 | U43: 5 | V43: 36 | AC43: 1 | AE43: =M43-J43 -> -195 | AF43: =M43/J43 -> 0.89166667
B44: 微波小吃 | C44: 韓式部隊鍋 | E44: 57.73 | F44: 774 | G44: =E44*F44 -> 44683.02 | I44: 22 | J44: 1800 | K44: =J44/I44 -> 81.818182 | L44: 22 | M44: =F44/V44*60 -> 1603.2221 | N44: =M44/L44 -> 72.873732 | O44: =L44-I44 -> 0 | P44: =N44-K44 -> -8.9444503 | Q44: =N44/K44 -> 0.89067894 | S44: 0.45488426 | T44: 0.475 | U44: 5.0333333 | V44: 28.966667 | AC44: 1 | AE44: =M44-J44 -> -196.77791 | AF44: =M44/J44 -> 0.89067894
B45: 季節調理麵 | C45: 和風匠製胡麻涼麵 | E45: 32.06 | F45: 977 | G45: =E45*F45 -> 31322.62 | I45: 19 | J45: 3600 | K45: =J45/I45 -> 189.47368 | L45: 19 | M45: =F45/V45*60 -> 3206.1987 | N45: =M45/L45 -> 168.7473 | O45: =L45-I45 -> 0 | P45: =N45-K45 -> -20.726383 | Q45: =N45/K45 -> 0.89061076 | S45: 0.47916667 | T45: 0.49186343 | U45: 6 | V45: 18.283333 | W45: 0.49186343 | X45: 0.53063657 | AC45: 1 | AE45: =M45-J45 -> -393.80128 | AF45: =M45/J45 -> 0.89061076
B46: 季節調理麵 | C46: 鴻運番茄湯麵 | E46: 56.43 | F46: 1467 | G46: =E46*F46 -> 82782.81 | I46: 19 | J46: 1800 | K46: =J46/I46 -> 94.736842 | L46: 19 | M46: =F46/V46*60 -> 1603.7656 | N46: =M46/L46 -> 84.408714 | O46: =L46-I46 -> 0 | P46: =N46-K46 -> -10.328128 | Q46: =N46/K46 -> 0.89098087 | S46: 0.53063657 | T46: 0.56875 | U46: 55.833333 | V46: 54.883333 | AC46: 1 | AE46: =M46-J46 -> -196.23444 | AF46: =M46/J46 -> 0.89098087
B55: 平均 | I55: =AVERAGE(I39:I54) -> 19.25 | J55: =AVERAGE(J39:J54) -> 1950 | K55: =J55/I55 -> 101.2987 | L55: =AVERAGE(L39:L54) -> 19.25 | M55: =AVERAGE(M39:M54) -> 1739.0813 | N55: =M55/L55 -> 90.341887 | O55: =L55-I55 -> 0 | P55: =N55-K55 -> -10.956814 | Q55: =N55/K55 -> 0.89183658 | S55: =S39 -> 0.20833333 | T55: =INDEX(T39:T54,COUNTA(T39:T54)) -> 0.56875 | Y55: =SUM(Y39:Y54) -> 0 | Z55: =SUM(Z39:Z54) -> 0 | AC55: =SUM(AC39:AC54) -> 12 | AD55: =SUM(AD39:AD54) -> 0 | AE55: =M55-J55 -> -210.91867 | AF55: =M55/J55 -> 0.89183658
A56: 自動包裝機 | B56: 4℃-飯糰 | C56: 和風牛肉咖哩炸飯糰 | E56: 21.74 | F56: 474 | G56: =E56*F56 -> 10304.76 | I56: 6 | J56: 3600 | K56: =J56/I56 -> 600 | L56: 6 | M56: =F56/V56*60 -> 3250.2857 | N56: =M56/L56 -> 541.71429 | O56: =L56-I56 -> 0 | P56: =N56-K56 -> -58.285714 | Q56: =N56/K56 -> 0.90285714 | R56: =Q72 -> 0.90297375 | S56: 0.4265625 | T56: 0.43263889 | U56: 6.0166667 | V56: 8.75 | AC56: 1 | AE56: =M56-J56 -> -349.71429 | AF56: =M56/J56 -> 0.90285714 | AG56: =AF72 -> 0.90297375
B57: 4℃-壽司手卷 | C57: 明太子泡菜牛飯卷 | E57: 27.05 | F57: 982 | G57: =E57*F57 -> 26563.1 | I57: 6 | J57: 3273 | K57: =J57/I57 -> 545.5 | L57: 6 | M57: =F57/V57*60 -> 2955.8528 | N57: =M57/L57 -> 492.64214 | O57: =L57-I57 -> 0 | P57: =N57-K57 -> -52.85786 | Q57: =N57/K57 -> 0.903102 | S57: 0.43615741 | T57: 0.45 | U57: 5.0666667 | V57: 19.933333 | AC57: 1 | AE57: =M57-J57 -> -317.14716 | AF57: =M57/J57 -> 0.903102
B72: 平均 | I72: =AVERAGE(I56:I71) -> 6 | J72: =AVERAGE(J56:J71) -> 3436.5 | K72: =J72/I72 -> 572.75 | L72: =AVERAGE(L56:L71) -> 6 | M72: =AVERAGE(M56:M71) -> 3103.0693 | N72: =M72/L72 -> 517.17821 | O72: =L72-I72 -> 0 | P72: =N72-K72 -> -55.571787 | Q72: =N72/K72 -> 0.90297375 | S72: =S56 -> 0.4265625 | T72: =INDEX(T56:T71,COUNTA(T56:T71)) -> 0.45 | Y72: =SUM(Y56:Y71) -> 0 | Z72: =SUM(Z56:Z71) -> 0 | AC72: =SUM(AC56:AC71) -> 2 | AD72: =SUM(AD56:AD71) -> 0 | AE72: =M72-J72 -> -333.43072 | AF72: =M72/J72 -> 0.90297375
A73: 便當二線 (二配) | B73: 微波主食 | C73: 二配西班牙風味海鮮燉飯 | E73: 57.3 | F73: 1194 | G73: =E73*F73 -> 68416.2 | I73: 21 | J73: 2000 | K73: =J73/I73 -> 95.238095 | L73: 21 | M73: =F73/V73*60 -> 1780.6131 | N73: =M73/L73 -> 84.7911 | O73: =L73-I73 -> 0 | P73: =N73-K73 -> -10.446996 | Q73: =N73/K73 -> 0.89030655 | R73: =Q89 -> 0.88956392 | S73: 0.70833333 | T73: 0.73627315 | V73: 40.233333 | AC73: 1 | AE73: =M73-J73 -> -219.38691 | AF73: =M73/J73 -> 0.89030655 | AG73: =AF89 -> 0.88956392
B74: 微波主食 | C74: 二配失控起司薯餅焗飯 | E74: 54.09 | F74: 1714 | G74: =E74*F74 -> 92710.26 | I74: 19 | J74: 2000 | K74: =J74/I74 -> 105.26316 | L74: 19 | M74: =F74/V74*60 -> 1777.1889 | N74: =M74/L74 -> 93.53626 | O74: =L74-I74 -> 0 | P74: =N74-K74 -> -11.726898 | Q74: =N74/K74 -> 0.88859447 | S74: 0.73967593 | T74: 0.77986111 | U74: 4.9 | V74: 57.866667 | AC74: 1 | AE74: =M74-J74 -> -222.81106 | AF74: =M74/J74 -> 0.88859447
B75: 微波主食 | C75: 二配蒙古風味烤肉飯 | E75: 58.17 | F75: 1813 | G75: =E75*F75 -> 105462.21 | I75: 19 | J75: 1800 | K75: =J75/I75 -> 94.736842 | L75: 19 | M75: =F75/V75*60 -> 1601.6687 | N75: =M75/L75 -> 84.298353 | O75: =L75-I75 -> 0 | P75: =N75-K75 -> -10.438489 | Q75: =N75/K75 -> 0.88981595 | S75: 0.7833912 | T75: 0.83055556 | U75: 5.0833333 | V75: 67.916667 | AC75: 1 | AE75: =M75-J75 -> -198.33129 | AF75: =M75/J75 -> 0.88981595
B89: 平均 | I89: =AVERAGE(I73:I88) -> 19.666667 | J89: =AVERAGE(J73:J88) -> 1933.3333 | K89: =J89/I89 -> 98.305085 | L89: =AVERAGE(L73:L88) -> 19.666667 | M89: =AVERAGE(M73:M88) -> 1719.8236 | N89: =M89/L89 -> 87.448657 | O89: =L89-I89 -> 0 | P89: =N89-K89 -> -10.856428 | Q89: =N89/K89 -> 0.88956392 | S89: =S73 -> 0.70833333 | T89: =INDEX(T73:T88,COUNTA(T73:T88)) -> 0.83055556 | Y89: =SUM(Y73:Y88) -> 0 | Z89: =SUM(Z73:Z88) -> 0 | AC89: =SUM(AC73:AC88) -> 3 | AD89: =SUM(AD73:AD88) -> 0 | AE89: =M89-J89 -> -213.50975 | AF89: =M89/J89 -> 0.88956392
A90: 涼麵二線 (二配) | B90: 微波主食 | C90: 二配乳酪燻腸紅醬焗飯 | E90: 50.67 | F90: 427 | G90: =E90*F90 -> 21636.09 | I90: 20 | J90: 2000 | K90: =J90/I90 -> 100 | L90: 20 | M90: =F90/V90*60 -> 1779.1667 | N90: =M90/L90 -> 88.958333 | O90: =L90-I90 -> 0 | P90: =N90-K90 -> -11.041667 | Q90: =N90/K90 -> 0.88958333 | R90: =Q106 -> 0.88938891 | S90: 0.70833333 | T90: 0.71833333 | V90: 14.4 | AC90: 1 | AE90: =M90-J90 -> -220.83333 | AF90: =M90/J90 -> 0.88958333 | AG90: =AF106 -> 0.88938891
B91: 微波主食 | C91: 二配里肌豬排可可咖哩歐姆蛋飯 | E91: 56.79 | F91: 1647 | G91: =E91*F91 -> 93533.13 | I91: 23 | J91: 2000 | K91: =J91/I91 -> 86.956522 | L91: 23 | M91: =F91/V91*60 -> 1778.9379 | N91: =M91/L91 -> 77.345126 | O91: =L91-I91 -> 0 | P91: =N91-K91 -> -9.6113959 | Q91: =N91/K91 -> 0.88946895 | S91: 0.72184028 | T91: 0.76041667 | U91: 5.05 | V91: 55.55 | AC91: 1 | AE91: =M91-J91 -> -221.06211 | AF91: =M91/J91 -> 0.88946895
B92: 微波主食 | C92: 二配黃金雞排蘑菇白醬歐姆蛋飯 | E92: 56.87 | F92: 1224 | G92: =E92*F92 -> 69608.88 | I92: 23 | J92: 2000 | K92: =J92/I92 -> 86.956522 | L92: 23 | M92: =F92/V92*60 -> 1779.6446 | N92: =M92/L92 -> 77.375852 | O92: =L92-I92 -> 0 | P92: =N92-K92 -> -9.5806701 | Q92: =N92/K92 -> 0.88982229 | S92: 0.76388889 | T92: 0.7925463 | U92: 5 | V92: 41.266667 | AC92: 1 | AE92: =M92-J92 -> -220.35541 | AF92: =M92/J92 -> 0.88982229
B93: 微波主食 | C93: 二配哞哞培根奶香海陸焗飯 | E93: 47.6 | F93: 1531 | G93: =E93*F93 -> 72875.6 | I93: 23 | J93: 2000 | K93: =J93/I93 -> 86.956522 | L93: 23 | M93: =F93/V93*60 -> 1777.3621 | N93: =M93/L93 -> 77.276615 | O93: =L93-I93 -> 0 | P93: =N93-K93 -> -9.6799069 | Q93: =N93/K93 -> 0.88868107 | S93: 0.79605324 | T93: 0.83194444 | U93: 5.05 | V93: 51.683333 | AC93: 1 | AE93: =M93-J93 -> -222.63786 | AF93: =M93/J93 -> 0.88868107
B106: 平均 | I106: =AVERAGE(I90:I105) -> 22.25 | J106: =AVERAGE(J90:J105) -> 2000 | K106: =J106/I106 -> 89.88764 | L106: =AVERAGE(L90:L105) -> 22.25 | M106: =AVERAGE(M90:M105) -> 1778.7778 | N106: =M106/L106 -> 79.945071 | O106: =L106-I106 -> 0 | P106: =N106-K106 -> -9.9425698 | Q106: =N106/K106 -> 0.88938891 | S106: =S90 -> 0.70833333 | T106: =INDEX(T90:T105,COUNTA(T90:T105)) -> 0.83194444 | Y106: =SUM(Y90:Y105) -> 0 | Z106: =SUM(Z90:Z105) -> 0 | AC106: =SUM(AC90:AC105) -> 4 | AD106: =SUM(AD90:AD105) -> 0 | AE106: =M106-J106 -> -221.22218 | AF106: =M106/J106 -> 0.88938891
AA108: 原因回覆
...

Sheet 0130
B1: 屏榮 大溪廠組合室生產人時性分析
B3: 日期 | C3: 115.01.30星期五 | E3: 訂單量 | F3: ='0130(18度C)'!D1+'0130(4度C)'!D1 -> 121636 | H3: 營業額 | I3: ='0130(18度C)'!F1+'0130(4度C)'!F1 -> 3724978
B4: 人時性 | C4: 項目 | E4: ➀ | G4: ➁ | I4: ➂ | K4: ④ | M4: ⑤ | O4: 異常停線 | Q4: 短暫停線
C5: 組合室 | E5: 全溫層 | G5: 4度C-各編組展開(一配) | I5: 4度C-各編組展開(二配) | K5: 18度C-各編組展開(一配) | M5: 18度C-各編組展開(二配) | O5: 合計次數 | P5: 時間 | Q5: 合計次數 | R5: 設備次數
C6: 排關平均 | E6: =AVERAGE(D14:O14,D32:X32) -> 546.8859 | F6: =AVERAGE(#REF!,D14:K14) -> #REF! | G6: =AVERAGE(D14:K14) -> 214.62898 | I6: =AVERAGE(L14:O14) -> 94.096363 | K6: =AVERAGE(D32:O32) -> 735.8217 | M6: =AVERAGE(P32:X32) -> 767.08429 | O6: ='0130(4度C)'!Y2 -> 0 | P6: ='0130(4度C)'!Z2 -> 0 | Q6: ='0130(4度C)'!AC2 -> 35 | R6: ='0130(4度C)'!AD2 -> 0
C7: 實績平均 | E7: =AVERAGE(D15:O15,D33:X33) -> 485.61792 | F7: =AVERAGE(#REF!,D15:K15) -> #REF! | G7: =AVERAGE(D15:K15) -> 193.29428 | I7: =AVERAGE(L15:O15) -> 83.690393 | K7: =AVERAGE(D33:O33) -> 652.50283 | M7: =AVERAGE(P33:X33) -> 679.98595
C8: 達成率平均 | E8: =AVERAGE(D16:O16,D34:X34) -> 0.88917486 | F8: =AVERAGE(D16:K16,#REF!) -> #REF! | G8: =AVERAGE(D16:K16) -> 0.89723386 | I8: =AVERAGE(L16:O16) -> 0.88940587 | K8: =AVERAGE(D34:O34) -> 0.88697921 | M8: =AVERAGE(P34:X34) -> 0.88527006
O9: ※現行日本鮮食廠以達成率80%為基本(即為現行KPI)
B11: 溫層 | D11: ➁4度C-各編組展開 | L11: ➂4度C-各編組展開
B12: 編組 | D12: 1 | E12: 2 | F12: 3 | G12: 4 | H12: 5 | I12: 6 | J12: 7 | K12: 8 | L12: 1 | M12: 2 | N12: 3 | O12: 4
D13: 便當一線 | E13: 便當二線 | F13: 涼麵一線 | G13: 涼麵二線 | H13: 涼麵三線 | I13: 自動包裝機 | J13: 自動包裝機2 | K13: 自動包裝機3 | L13: 便當一線 | M13: 便當二線 | N13: 涼麵一線 | O13: 涼麵二線
B14: 人時性 | C14: 排關 | D14: - | E14: 81.967213 | F14: - | G14: 102.5 | H14: 101.2987 | I14: 572.75 | J14: - | K14: - | L14: - | M14: 98.305085 | N14: - | O14: 89.88764
C15: 實績 | D15: - | E15: 72.939475 | F15: - | G15: 92.679562 | H15: 90.342666 | I15: 517.21542 | J15: - | K15: - | L15: - | M15: 87.445636 | N15: - | O15: 79.93515
C16: 達成率 | D16: - | E16: =E15/E14 -> 0.88986159 | F16: - | G16: =G15/G14 -> 0.90419085 | H16: =H15/H14 -> 0.89184427 | I16: =I15/I14 -> 0.90303872 | J16: - | K16: - | L16: - | M16: =M15/M14 -> 0.88953319 | N16: - | O16: =O15/O14 -> 0.88927854
B17: 作業 時間 | C17: 開始 | D17: - | E17: 0.29166667 | F17: - | G17: 0.29166667 | H17: 0.20833333 | I17: 0.43611111 | J17: - | K17: - | L17: - | M17: 0.70866898 | N17: - | O17: 0.70833333
C18: 結束 | D18: - | E18: 0.58680556 | F18: - | G18: 0.58498843 | H18: 0.54305556 | I18: 0.45725694 | J18: - | K18: - | L18: - | M18: 0.81349537 | N18: - | O18: 0.82384259
B19: 產線異常 (5分鐘以上) | C19: 次數
C20: 時間/分
B21: 短暫停線 (5分鐘以下) | C21: 次數 | E21: 7 | G21: 8 | H21: 11 | I21: 2 | M21: 3 | O21: 4
C22: 設備次數
B23: 配置人數 | D23: - | E23: 24.4 | F23: - | G23: 22.285714 | H23: 19.25 | I23: 6 | J23: - | K23: - | L23: - | M23: 19.666667 | N23: - | O23: 22.25
B24: 主要應用設備 | D24: L型封口機 | E24: ET-55 | F24: ET-55 | G24: ET-55 | H24: ET-600 | I24: 伺服包裝機 | J24: 伺服包裝機 | K24: 伺服包裝機 | L24: L型封口機 | M24: ET-55 | N24: ET-55 | O24: ET-55
B25: 次要應用設備 | D25: 伺服包裝機 | H25: 伺服包裝機
B26: 備註 | H26: 涼麵+烤飯糰 | I26: 大口飯糰線 | K26: 烤飯糰+手卷
B29: 溫層 | D29: ➃18度C-各編組展開 (一配) | P29: ⑤18度C-各編組展開 (二配)
B30: 編組 | D30: 1 | E30: 2 | F30: 3 | G30: 4 | H30: 5 | I30: 6 | J30: 7 | K30: 8 | L30: 9 | M30: 10 | N30: 11 | O30: 12 | P30: 1 | Q30: 2 | R30: 3 | S30: 4 | T30: 5 | U30: 6 | V30: 7 | W30: 8 | X30: 9
D31: 便當一線 | E31: 涼麵一線 | F31: 涼麵三線 | G31: 自動包裝機 | H31: 自動包裝機2 | I31: 自動包裝機3 | J31: 味付飯糰線B | K31: (舊) 3300型飯糰線 | L31: 3000型飯糰線 | M31: (新) 3300型飯糰機 | N31: GKK3600型 飯糰機 | O31: GKK3600型 飯糰機2 | P31: 自動包裝機 | Q31: 自動包裝機2 | R31: 自動包裝機3 | S31: 味付飯糰線B | T31: (舊) 3300型飯糰線 | U31: 3000型飯糰線 | V31: (新) 3300型飯糰機 | W31: GKK3600型 飯糰機 | X31: GKK3600型 飯糰機2
B32: 人時性 | C32: 排關 | D32: - | E32: - | F32: - | G32: 318.86792 | H32: 433.33333 | I32: - | J32: - | K32: 825 | L32: - | M32: 761.53846 | N32: 1133.3333 | O32: 942.85714 | P32: 306.38298 | Q32: - | R32: - | S32: - | T32: 787.5 | U32: - | V32: 761.53846 | W32: 1100 | X32: 880
C33: 實績 | D33: - | E33: - | F33: - | G33: 279.75752 | H33: 386.55788 | I33: - | J33: - | K33: 738.56992 | L33: - | M33: 681.95977 | N33: 994.29753 | O33: 833.87435 | P33: 267.30854 | Q33: - | R33: - | S33: - | T33: 702.74053 | U33: - | V33: 682.3557 | W33: 969.45403 | X33: 778.07093
C34: 達成率 | D34: - | E34: - | F34: - | G34: =G33/G32 -> 0.87734607 | H34: =H33/H32 -> 0.89205664 | I34: - | J34: - | K34: =K33/K32 -> 0.89523627 | L34: - | M34: =M33/M32 -> 0.89550273 | N34: =N33/N32 -> 0.87732135 | O34: =O33/O32 -> 0.88441218 | P34: =P33/P32 -> 0.87246537 | Q34: - | R34: - | S34: - | T34: =T33/T32 -> 0.89236893 | U34: - | V34: =V33/V32 -> 0.89602264 | W34: =W33/W32 -> 0.88132185 | X34: =X33/X32 -> 0.88417151
B35: 作業 時間 | C35: 開始 | D35: - | E35: - | F35: - | G35: 0.34166667 | H35: 0.29166667 | I35: - | J35: - | K35: 0.29168981 | L35: - | M35: 0.29166667 | N35: 0.29171296 | O35: 0.29168981 | P35: 0.7084838 | Q35: - | R35: - | S35: - | T35: 0.70833333 | U35: - | V35: 0.70859954 | W35: 0.70833333 | X35: 0.70833333
C36: 結束 | D36: - | E36: - | F36: - | G36: 0.4322338 | H36: 0.32083333 | I36: - | J36: - | K36: 0.39652778 | L36: - | M36: 0.39331019 | N36: 0.43541667 | O36: 0.41619213 | P36: 0.79166667 | Q36: - | R36: - | S36: - | T36: 0.84583333 | U36: - | V36: 0.8315162 | W36: 0.99126157 | X36: 0.85640046
B37: 配置人數 | D37: - | E37: - | F37: - | G37: 10.6 | H37: 6 | I37: - | J37: - | K37: 4 | L37: - | M37: 4.3333333 | N37: 3 | O37: 3.5 | P37: 11.75 | Q37: - | R37: - | S37: - | T37: 4 | U37: - | V37: 4.3333333 | W37: 3 | X37: 3.75
B38: 主要應用設備 | D38: 伺服包裝機 | E38: ET-55 | F38: ET-600 | G38: 夾心型 | H38: 伺服包裝機 | I38: 伺服包裝機 | J38: 夾心型 | K38: 3300型 | L38: 3300型 | M38: 3300型 | N38: GKK | O38: GKK | P38: 夾心型 | Q38: 伺服包裝機 | R38: 伺服包裝機 | S38: 夾心型 | T38: 3300型 | U38: 3300型 | V38: 3300型 | W38: GKK | X38: GKK
B39: 次要應用設備
B40: 備註

Sheet 0130(18度C)
A1: 大溪廠日報分析 | C1: 總生產量 | D1: =SUM(F5:F191) -> 80954 | E1: 營業額 | F1: =SUM(G5:G191) -> 1603243.3 | G1: 出勤人數 | H1: =L21+L38+L55+L72+L89+L106+L123+L140+L157+L174+L191 -> 58.266667 | I1: 產線配置圖 | L1: 生產實績 | O1: 人時性差異分析 | S1: 日報登錄 | Y1: 分析說明 | AA1: 產能差異分析
A2: 46052 | C2: 人時性 | D2: =AVERAGE(N21,N38,N55,N72,N89,N106,N123,N140,N157,N174,N191) -> 664.99515 | E2: 平均廠價 | F2: =F1/D1 -> 19.804374 | G2: 多次生產數 | H2: =COUNT(H5:H191) -> 1
A3: 線別 | B3: 品類 | C3: 品名 | E3: 廠價 | F3: 生產量 | G3: 營收 | H3: 多次 生產 | I3: 人數 | J3: 產能/時 | K3: 人時性 | L3: 人數 | M3: 產能/時 | N3: 人時性 | O3: 人數 | P3: 人時性 | Q3: 達成率 | R3: 達成率 平均 | S3: 生產時間 | U3: 換線、休息/分 | V3: 稼動時間/分 | W3: 休息時間 | Y3: (屏榮回填) | AA3: 產能/時 | AB3: 達成率 | AC3: 達成率平均
S4: 開始 | T4: 結束 | W4: 開始 | X4: 結束
A5: 自動包裝機 | B5: 18℃-壽司手卷 | C5: 一配明太子玉子脆卷 | E5: 19.7 | F5: 231 | G5: =E5*F5 -> 4550.7 | I5: 6 | J5: 2500 | K5: =J5/I5 -> 416.66667 | L5: 6 | M5: =F5/V5*60 -> 2259.7826 | N5: =M5/L5 -> 376.63043 | O5: =L5-I5 -> 0 | P5: =N5-K5 -> -40.036232 | Q5: =N5/K5 -> 0.90391304 | R5: =Q21 -> 0.87734607 | S5: 0.34166667 | T5: 0.34592593 | V5: 6.1333333 | AA5: =M5-J5 -> -240.21739 | AB5: =M5/J5 -> 0.90391304 | AC5: =AB21 -> 0.87734607
B6: 18℃-飯糰 | C6: 一配兩粒飯糰(鮪魚.焦糖鮭魚) | E6: 28.57 | F6: 1705 | G6: =E6*F6 -> 48711.85 | I6: 12 | J6: 3600 | K6: =J6/I6 -> 300 | L6: 12 | M6: =F6/V6*60 -> 3123.6641 | N6: =M6/L6 -> 260.30534 | O6: =L6-I6 -> 0 | P6: =N6-K6 -> -39.694656 | Q6: =N6/K6 -> 0.86768448 | S6: 0.34947917 | T6: 0.37222222 | U6: 5.1166667 | V6: 32.75 | AA6: =M6-J6 -> -476.33588 | AB6: =M6/J6 -> 0.86768448
B7: 18℃-壽司手卷 | C7: 一配海饌雙手卷 | E7: 29.85 | F7: 1380 | G7: =E7*F7 -> 41193 | I7: 12 | J7: 3600 | K7: =J7/I7 -> 300 | L7: 12 | M7: =F7/V7*60 -> 3136.3636 | N7: =M7/L7 -> 261.36364 | O7: =L7-I7 -> 0 | P7: =N7-K7 -> -38.636364 | Q7: =N7/K7 -> 0.87121212 | S7: 0.37569444 | T7: 0.39402778 | U7: 5 | V7: 26.4 | AA7: =M7-J7 -> -463.63636 | AB7: =M7/J7 -> 0.87121212
B8: 18℃-壽司手卷 | C8: 一配雙饗雙手卷 | E8: 29.52 | F8: 1326 | G8: =E8*F8 -> 39143.52 | I8: 12 | J8: 3600 | K8: =J8/I8 -> 300 | L8: 12 | M8: =F8/V8*60 -> 3136.3995 | N8: =M8/L8 -> 261.36662 | O8: =L8-I8 -> 0 | P8: =N8-K8 -> -38.633377 | Q8: =N8/K8 -> 0.87122208 | S8: 0.39722222 | T8: 0.41483796 | U8: 4.6 | V8: 25.366667 | AA8: =M8-J8 -> -463.60053 | AB8: =M8/J8 -> 0.87122208
B9: 18℃-壽司手卷 | C9: 一配長野稻荷壽司 | E9: 25.64 | F9: 1079 | G9: =E9*F9 -> 27665.56 | I9: 11 | J9: 3600 | K9: =J9/I9 -> 327.27273 | L9: 11 | M9: =F9/V9*60 -> 3170.9388 | N9: =M9/L9 -> 288.26716 | O9: =L9-I9 -> 0 | P9: =N9-K9 -> -39.005566 | Q9: =N9/K9 -> 0.88081633 | S9: 0.41805556 | T9: 0.4322338 | U9: 4.6333333 | V9: 20.416667 | AA9: =M9-J9 -> -429.06122 | AB9: =M9/J9 -> 0.88081633
B21: 平均 | I21: =AVERAGE(I5:I20) -> 10.6 | J21: =AVERAGE(J5:J20) -> 3380 | K21: =J21/I21 -> 318.86792 | L21: =AVERAGE(L5:L20) -> 10.6 | M21: =AVERAGE(M5:M20) -> 2965.4297 | N21: =M21/L21 -> 279.75752 | O21: =L21-I21 -> 0 | P21: =N21-K21 -> -39.110403 | Q21: =N21/K21 -> 0.87734607 | S21: =S5 -> 0.34166667 | T21: =INDEX(T5:T20,COUNTA(T5:T20)) -> 0.4322338 | AA21: =M21-J21 -> -414.57028 | AB21: =M21/J21 -> 0.87734607
A22: 自動包裝機2 | B22: 18℃-壽司手卷 | C22: 一配雙鬆細卷 | E22: 14.03 | F22: 666 | G22: =E22*F22 -> 9343.98 | I22: 6 | J22: 2600 | K22: =J22/I22 -> 433.33333 | L22: 6 | M22: =F22/V22*60 -> 2318.7621 | N22: =M22/L22 -> 386.46035 | O22: =L22-I22 -> 0 | P22: =N22-K22 -> -46.872985 | Q22: =N22/K22 -> 0.89183157 | R22: =Q38 -> 0.89205664 | S22: 0.29166667 | T22: 0.30363426 | V22: 17.233333 | AA22: =M22-J22 -> -281.23791 | AB22: =M22/J22 -> 0.89183157 | AC22: =AB38 -> 0.89205664
B23: 18℃-壽司手卷 | C23: 一配經典鮪魚沙拉細卷 | E23: 14.49 | F23: 763 | G23: =E23*F23 -> 11055.87 | I23: 6 | J23: 2600 | K23: =J23/I23 -> 433.33333 | L23: 6 | M23: =F23/V23*60 -> 2319.9324 | N23: =M23/L23 -> 386.65541 | O23: =L23-I23 -> 0 | P23: =N23-K23 -> -46.677928 | Q23: =N23/K23 -> 0.8922817 | S23: 0.30712963 | T23: 0.32083333 | U23: 5.0333333 | V23: 19.733333 | AA23: =M23-J23 -> -280.06757 | AB23: =M23/J23 -> 0.8922817
B38: 平均 | I38: =AVERAGE(I22:I37) -> 6 | J38: =AVERAGE(J22:J37) -> 2600 | K38: =J38/I38 -> 433.33333 | L38: =AVERAGE(L22:L37) -> 6 | M38: =AVERAGE(M22:M37) -> 2319.3473 | N38: =M38/L38 -> 386.55788 | O38: =L38-I38 -> 0 | P38: =N38-K38 -> -46.775457 | Q38: =N38/K38 -> 0.89205664 | S38: =S22 -> 0.29166667 | T38: =INDEX(T22:T37,COUNTA(T22:T37)) -> 0.32083333 | AA38: =M38-J38 -> -280.65274 | AB38: =M38/J38 -> 0.89205664
A39: (舊) 3300型飯糰線 | B39: 18℃-飯糰 | C39: 一配鹽蔥燒肉飯糰 | E39: 17.89 | F39: 2214 | G39: =E39*F39 -> 39608.46 | I39: 4 | J39: 3300 | K39: =J39/I39 -> 825 | L39: 4 | M39: =F39/V39*60 -> 2954.1883 | N39: =M39/L39 -> 738.54707 | O39: =L39-I39 -> 0 | P39: =N39-K39 -> -86.452928 | Q39: =N39/K39 -> 0.89520857 | R39: =Q55 -> 0.89523627 | S39: 0.29168981 | T39: 0.32291667 | V39: 44.966667 | AA39: =M39-J39 -> -345.81171 | AB39: =M39/J39 -> 0.89520857 | AC39: =AB55 -> 0.89523627
B40: 18℃-飯糰 | C40: 一配照燒雞肉飯糰 | E40: 21.45 | F40: 1201 | G40: =E40*F40 -> 25761.45 | I40: 4 | J40: 3300 | K40: =J40/I40 -> 825 | L40: 4 | M40: =F40/V40*60 -> 2955.2973 | N40: =M40/L40 -> 738.82433 | O40: =L40-I40 -> 0 | P40: =N40-K40 -> -86.175666 | Q40: =N40/K40 -> 0.89554465 | S40: 0.32638889 | T40: 0.34332176 | U40: 5 | V40: 24.383333 | AA40: =M40-J40 -> -344.70267 | AB40: =M40/J40 -> 0.89554465
B41: 18℃-飯糰 | C41: 一配雞肉飯飯糰 | E41: 16.66 | F41: 3535 | G41: =E41*F41 -> 58893.1 | I41: 4 | J41: 3300 | K41: =J41/I41 -> 825 | L41: 4 | M41: =F41/V41*60 -> 2953.3534 | N41: =M41/L41 -> 738.33836 | O41: =L41-I41 -> 0 | P41: =N41-K41 -> -86.661638 | Q41: =N41/K41 -> 0.89495559 | S41: 0.34665509 | T41: 0.39652778 | U41: 4.8 | V41: 71.816667 | AA41: =M41-J41 -> -346.64655 | AB41: =M41/J41 -> 0.89495559
B55: 平均 | I55: =AVERAGE(I39:I54) -> 4 | J55: =AVERAGE(J39:J54) -> 3300 | K55: =J55/I55 -> 825 | L55: =AVERAGE(L39:L54) -> 4 | M55: =AVERAGE(M39:M54) -> 2954.2797 | N55: =M55/L55 -> 738.56992 | O55: =L55-I55 -> 0 | P55: =N55-K55 -> -86.430078 | Q55: =N55/K55 -> 0.89523627 | S55: =S39 -> 0.29168981 | T55: =INDEX(T39:T54,COUNTA(T39:T54)) -> 0.39652778 | AA55: =M55-J55 -> -345.72031 | AB55: =M55/J55 -> 0.89523627
A56: (新) 3300型飯糰機 | B56: 18℃-飯糰 | C56: 一配壹號醬炙烤牛飯糰 | E56: 22.28 | F56: 898 | G56: =E56*F56 -> 20007.44 | I56: 5 | J56: 3300 | K56: =J56/I56 -> 660 | L56: 5 | M56: =F56/V56*60 -> 2957.731 | N56: =M56/L56 -> 591.5462 | O56: =L56-I56 -> 0 | P56: =N56-K56 -> -68.453797 | Q56: =N56/K56 -> 0.89628213 | R56: =Q72 -> 0.89550273 | S56: 0.29166667 | T56: 0.30431713 | V56: 18.216667 | AA56: =M56-J56 -> -342.26898 | AB56: =M56/J56 -> 0.89628213 | AC56: =AB72 -> 0.89550273
B57: 18℃-飯糰 | C57: 一配紅運烏魚子紹興飯糰 | E57: 27.27 | F57: 2916 | G57: =E57*F57 -> 79519.32 | I57: 5 | J57: 3300 | K57: =J57/I57 -> 660 | L57: 5 | M57: =F57/V57*60 -> 2954.5736 | N57: =M57/L57 -> 590.91472 | O57: =L57-I57 -> 0 | P57: =N57-K57 -> -69.08528 | Q57: =N57/K57 -> 0.89532533 | S57: 0.30763889 | T57: 0.34876157 | U57: 4.7833333 | V57: 59.216667 | AA57: =M57-J57 -> -345.4264 | AB57: =M57/J57 -> 0.89532533
B58: 18℃-飯糰 | C58: 一配鮭魚奶油醬油飯糰 | E58: 18.53 | F58: 2922 | G58: =E58*F58 -> 54144.66 | I58: 3 | J58: 3300 | K58: =J58/I58 -> 1100 | L58: 3 | M58: =F58/V58*60 -> 2953.1724 | N58: =M58/L58 -> 984.39079 | O58: =L58-I58 -> 0 | P58: =N58-K58 -> -115.60921 | Q58: =N58/K58 -> 0.89490072 | S58: 0.35208333 | T58: 0.39331019 | U58: 4.7833333 | V58: 59.366667 | AA58: =M58-J58 -> -346.82762 | AB58: =M58/J58 -> 0.89490072
B72: 平均 | I72: =AVERAGE(I56:I71) -> 4.3333333 | J72: =AVERAGE(J56:J71) -> 3300 | K72: =J72/I72 -> 761.53846 | L72: =AVERAGE(L56:L71) -> 4.3333333 | M72: =AVERAGE(M56:M71) -> 2955.159 | N72: =M72/L72 -> 681.95977 | O72: =L72-I72 -> 0 | P72: =N72-K72 -> -79.578693 | Q72: =N72/K72 -> 0.89550273 | S72: =S56 -> 0.29166667 | T72: =INDEX(T56:T71,COUNTA(T56:T71)) -> 0.39331019 | AA72: =M72-J72 -> -344.841 | AB72: =M72/J72 -> 0.89550273
A73: GKK3600型 飯糰機 | B73: 18℃-飯糰 | C73: 一配蔬食鮪魚飯糰 | E73: 18.18 | F73: 884 | G73: =E73*F73 -> 16071.12 | I73: 3 | J73: 3600 | K73: =J73/I73 -> 1200 | L73: 3 | M73: =F73/V73*60 -> 3132.2835 | N73: =M73/L73 -> 1044.0945 | O73: =L73-I73 -> 0 | P73: =N73-K73 -> -155.90551 | Q73: =N73/K73 -> 0.87007874 | R73: =Q89 -> 0.87732135 | S73: 0.29171296 | T73: 0.30347222 | V73: 16.933333 | AA73: =M73-J73 -> -467.71654 | AB73: =M73/J73 -> 0.87007874 | AC73: =AB89 -> 0.87732135
B74: 18℃-飯糰 | C74: 一配經典肉鬆飯糰 | E74: 14.03 | F74: 3446 | G74: =E74*F74 -> 48347.38 | I74: 3 | J74: 3000 | K74: =J74/I74 -> 1000 | L74: 3 | M74: =F74/V74*60 -> 2689.2695 | N74: =M74/L74 -> 896.42315 | O74: =L74-I74 -> 0 | P74: =N74-K74 -> -103.57685 | Q74: =N74/K74 -> 0.89642315 | S74: 0.31396991 | T74: 0.36736111 | U74: 15.116667 | V74: 76.883333 | AA74: =M74-J74 -> -310.73054 | AB74: =M74/J74 -> 0.89642315
B75: 18℃-飯糰 | C75: 一配鮪魚飯糰 | E75: 14.28 | F75: 4272 | G75: =E75*F75 -> 61004.16 | I75: 3 | J75: 3600 | K75: =J75/I75 -> 1200 | L75: 3 | M75: =F75/V75*60 -> 3127.1248 | N75: =M75/L75 -> 1042.3749 | O75: =L75-I75 -> 0 | P75: =N75-K75 -> -157.62505 | Q75: =N75/K75 -> 0.86864579 | S75: 0.37849537 | T75: 0.43541667 | U75: 16.033333 | V75: 81.966667 | AA75: =M75-J75 -> -472.87515 | AB75: =M75/J75 -> 0.86864579
B89: 平均 | I89: =AVERAGE(I73:I88) -> 3 | J89: =AVERAGE(J73:J88) -> 3400 | K89: =J89/I89 -> 1133.3333 | L89: =AVERAGE(L73:L88) -> 3 | M89: =AVERAGE(M73:M88) -> 2982.8926 | N89: =M89/L89 -> 994.29753 | O89: =L89-I89 -> 0 | P89: =N89-K89 -> -139.0358 | Q89: =N89/K89 -> 0.87732135 | S89: =S73 -> 0.29171296 | T89: =INDEX(T73:T88,COUNTA(T73:T88)) -> 0.43541667 | AA89: =M89-J89 -> -417.10741 | AB89: =M89/J89 -> 0.87732135
A90: GKK3600型 飯糰機2 | B90: 18℃-飯糰 | C90: 一配熟成紅鮭飯糰 | E90: 25.03 | F90: 1121 | G90: =E90*F90 -> 28058.63 | I90: 4 | J90: 3300 | K90: =J90/I90 -> 825 | L90: 4 | M90: =F90/V90*60 -> 2928.5922 | N90: =M90/L90 -> 732.14804 | O90: =L90-I90 -> 0 | P90: =N90-K90 -> -92.851959 | Q90: =N90/K90 -> 0.88745217 | R90: =Q106 -> 0.88441218 | S90: 0.29168981 | T90: 0.30763889 | V90: 22.966667 | AA90: =M90-J90 -> -371.40784 | AB90: =M90/J90 -> 0.88745217 | AC90: =AB106 -> 0.88441218
B91: 18℃-飯糰 | C91: 一配北海道秋鮭親子飯糰 | E91: 24.82 | F91: 1428 | G91: =E91*F91 -> 35442.96 | I91: 4 | J91: 3300 | K91: =J91/I91 -> 825 | L91: 4 | M91: =F91/V91*60 -> 2927.5626 | N91: =M91/L91 -> 731.89066 | O91: =L91-I91 -> 0 | P91: =N91-K91 -> -93.109339 | Q91: =N91/K91 -> 0.88714019 | S91: 0.31805556 | T91: 0.33837963 | U91: 15 | V91: 29.266667 | AA91: =M91-J91 -> -372.43736 | AB91: =M91/J91 -> 0.88714019
B92: 18℃-飯糰 | C92: 一配贅沢鮭魚肚飯糰 | E92: 30 | F92: 2202 | G92: =E92*F92 -> 66060 | I92: 3 | J92: 3000 | K92: =J92/I92 -> 1000 | L92: 3 | M92: =F92/V92*60 -> 2689.922 | N92: =M92/L92 -> 896.64065 | O92: =L92-I92 -> 0 | P92: =N92-K92 -> -103.35935 | Q92: =N92/K92 -> 0.89664065 | S92: 0.34861111 | T92: 0.38271991 | U92: 14.733333 | V92: 49.116667 | AA92: =M92-J92 -> -310.07805 | AB92: =M92/J92 -> 0.89664065
B93: 18℃-飯糰 | C93: 一配明太子龍蝦風味沙拉飯糰 | E93: 18.18 | F93: 1737 | G93: =E93*F93 -> 31578.66 | I93: 3 | J93: 3600 | K93: =J93/I93 -> 1200 | L93: 3 | M93: =F93/V93*60 -> 3128.1641 | N93: =M93/L93 -> 1042.7214 | O93: =L93-I93 -> 0 | P93: =N93-K93 -> -157.27864 | Q93: =N93/K93 -> 0.86893447 | S93: 0.39305556 | T93: 0.41619213 | U93: 14.883333 | V93: 33.316667 | AA93: =M93-J93 -> -471.83592 | AB93: =M93/J93 -> 0.86893447
B106: 平均 | I106: =AVERAGE(I90:I105) -> 3.5 | J106: =AVERAGE(J90:J105) -> 3300 | K106: =J106/I106 -> 942.85714 | L106: =AVERAGE(L90:L105) -> 3.5 | M106: =AVERAGE(M90:M105) -> 2918.5602 | N106: =M106/L106 -> 833.87435 | O106: =L106-I106 -> 0 | P106: =N106-K106 -> -108.9828 | Q106: =N106/K106 -> 0.88441218 | S106: =S90 -> 0.29168981 | T106: =INDEX(T90:T105,COUNTA(T90:T105)) -> 0.41619213 | AA106: =M106-J106 -> -381.43979 | AB106: =M106/J106 -> 0.88441218
A107: 自動包裝機 (二配) | B107: 18℃-壽司手卷 | C107: 二配長野稻荷壽司 | E107: 25.64 | F107: 1151 | G107: =E107*F107 -> 29511.64 | I107: 11 | J107: 3600 | K107: =J107/I107 -> 327.27273 | L107: 11 | M107: =F107/V107*60 -> 3170.3137 | N107: =M107/L107 -> 288.21034 | O107: =L107-I107 -> 0 | P107: =N107-K107 -> -39.062391 | Q107: =N107/K107 -> 0.88064269 | R107: =Q123 -> 0.87246537 | S107: 0.7084838 | T107: 0.72361111 | V107: 21.783333 | AA107: =M107-J107 -> -429.6863 | AB107: =M107/J107 -> 0.88064269 | AC107: =AB123 -> 0.87246537
B108: 18℃-壽司手卷 | C108: 二配雙饗雙手卷 | E108: 29.52 | F108: 1450 | G108: =E108*F108 -> 42804 | I108: 12 | J108: 3600 | K108: =J108/I108 -> 300 | L108: 12 | M108: =F108/V108*60 -> 3135.1351 | N108: =M108/L108 -> 261.26126 | O108: =L108-I108 -> 0 | P108: =N108-K108 -> -38.738739 | Q108: =N108/K108 -> 0.87087087 | S108: 0.72795139 | T108: 0.74722222 | U108: 6.25 | V108: 27.75 | AA108: =M108-J108 -> -464.86486 | AB108: =M108/J108 -> 0.87087087
B109: 18℃-壽司手卷 | C109: 二配海饌雙手卷 | E109: 29.85 | F109: 1563 | G109: =E109*F109 -> 46655.55 | I109: 12 | J109: 3600 | K109: =J109/I109 -> 300 | L109: 12 | M109: =F109/V109*60 -> 3134.7075 | N109: =M109/L109 -> 261.22563 | O109: =L109-I109 -> 0 | P109: =N109-K109 -> -38.774373 | Q109: =N109/K109 -> 0.87075209 | S109: 0.75075231 | T109: 0.77152778 | U109: 5.0833333 | V109: 29.916667 | AA109: =M109-J109 -> -465.29248 | AB109: =M109/J109 -> 0.87075209
B110: 18℃-飯糰 | C110: 二配兩粒飯糰(鮪魚.焦糖鮭魚) | E110: 28.57 | F110: 1245 | G110: =E110*F110 -> 35569.65 | I110: 12 | J110: 3600 | K110: =J110/I110 -> 300 | L110: 12 | M110: =F110/V110*60 -> 3123.3449 | N110: =M110/L110 -> 260.27875 | O110: =L110-I110 -> 0 | P110: =N110-K110 -> -39.721254 | Q110: =N110/K110 -> 0.86759582 | S110: 0.77505787 | T110: 0.79166667 | U110: 5.0833333 | V110: 23.916667 | AA110: =M110-J110 -> -476.65505 | AB110: =M110/J110 -> 0.86759582
B123: 平均 | I123: =AVERAGE(I107:I122) -> 11.75 | J123: =AVERAGE(J107:J122) -> 3600 | K123: =J123/I123 -> 306.38298 | L123: =AVERAGE(L107:L122) -> 11.75 | M123: =AVERAGE(M107:M122) -> 3140.8753 | N123: =M123/L123 -> 267.30854 | O123: =L123-I123 -> 0 | P123: =N123-K123 -> -39.07444 | Q123: =N123/K123 -> 0.87246537 | S123: =S107 -> 0.7084838 | T123: =INDEX(T107:T122,COUNTA(T107:T122)) -> 0.79166667 | AA123: =M123-J123 -> -459.12468 | AB123: =M123/J123 -> 0.87246537
A124: (舊) 3300型飯糰線 (二配) | B124: 18℃-飯糰 | C124: 二配大飯糰滷肉飯加蛋 | E124: 22.48 | F124: 1514 | G124: =E124*F124 -> 34034.72 | I124: 5 | J124: 3000 | K124: =J124/I124 -> 600 | L124: 5 | M124: =F124/V124*60 -> 2662.6282 | N124: =M124/L124 -> 532.52565 | O124: =L124-I124 -> 0 | P124: =N124-K124 -> -67.474353 | Q124: =N124/K124 -> 0.88754275 | R124: =Q140 -> 0.89236893 | S124: 0.70833333 | T124: 0.73202546 | V124: 34.116667 | AA124: =M124-J124 -> -337.37176 | AB124: =M124/J124 -> 0.88754275 | AC124: =AB140 -> 0.89236893
B125: 18℃-飯糰 | C125: 二配大飯糰韓式蒜烤豬五花 | E125: 24.54 | F125: 1894 | G125: =E125*F125 -> 46478.76 | I125: 4 | J125: 3000 | K125: =J125/I125 -> 750 | L125: 4 | M125: =F125/V125*60 -> 2664.4783 | N125: =M125/L125 -> 666.11958 | O125: =L125-I125 -> 0 | P125: =N125-K125 -> -83.880422 | Q125: =N125/K125 -> 0.88815944 | S125: 0.73565972 | T125: 0.76527778 | U125: 5.2333333 | V125: 42.65 | AA125: =M125-J125 -> -335.52169 | AB125: =M125/J125 -> 0.88815944
B126: 18℃-飯糰 | C126: 二配三杯醬爆菇菇飯糰 | E126: 16.7 | F126: 1120 | G126: =E126*F126 -> 18704 | I126: 3 | J126: 3300 | K126: =J126/I126 -> 1100 | L126: 3 | M126: =F126/V126*60 -> 2958.1805 | N126: =M126/L126 -> 986.06016 | O126: =L126-I126 -> 0 | P126: =N126-K126 -> -113.93984 | Q126: =N126/K126 -> 0.89641833 | S126: 0.76894676 | T126: 0.78472222 | U126: 5.2833333 | V126: 22.716667 | AA126: =M126-J126 -> -341.81952 | AB126: =M126/J126 -> 0.89641833
B127: 18℃-飯糰 | C127: 二配鹽蔥燒肉飯糰 | E127: 17.89 | F127: 4022 | G127: =E127*F127 -> 71953.58 | I127: 4 | J127: 3300 | K127: =J127/I127 -> 825 | L127: 4 | M127: =F127/V127*60 -> 2958.5615 | N127: =M127/L127 -> 739.64038 | O127: =L127-I127 -> 0 | P127: =N127-K127 -> -85.359624 | Q127: =N127/K127 -> 0.89653379 | S127: 0.78918981 | T127: 0.84583333 | U127: 6.4333333 | V127: 81.566667 | AA127: =M127-J127 -> -341.4385 | AB127: =M127/J127 -> 0.89653379
